ts_recv,ts_event,rtype,publisher_id,instrument_id,action,side,price,size,channel_id,order_id,flags,ts_in_delta,sequence,symbol,bid_px_00,bid_sz_00,bid_ct_00,bid_px_01,bid_sz_01,bid_ct_01,bid_px_02,bid_sz_02,bid_ct_02,bid_px_03,bid_sz_03,bid_ct_03,bid_px_04,bid_sz_04,bid_ct_04,bid_px_05,bid_sz_05,bid_ct_05,bid_px_06,bid_sz_06,bid_ct_06,bid_px_07,bid_sz_07,bid_ct_07,bid_px_08,bid_sz_08,bid_ct_08,bid_px_09,bid_sz_09,bid_ct_09,ask_px_00,ask_sz_00,ask_ct_00,ask_px_01,ask_sz_01,ask_ct_01,ask_px_02,ask_sz_02,ask_ct_02,ask_px_03,ask_sz_03,ask_ct_03,ask_px_04,ask_sz_04,ask_ct_04,ask_px_05,ask_sz_05,ask_ct_05,ask_px_06,ask_sz_06,ask_ct_06,ask_px_07,ask_sz_07,ask_ct_07,ask_px_08,ask_sz_08,ask_ct_08,ask_px_09,ask_sz_09,ask_ct_09,symbol,order_id
2025-07-17T15:43:48.787766907Z,2025-07-17T15:43:48.787601640Z,160,2,1108,A,A,13.840000000,100,0,301746949,130,165267,253027924,ARL,,13.26,100,1,13.04,2,1,13.03,100,1,12.73,100,1,12.71,100,1,12.5,700,1,12.46,200,1,12.43,700,1,12.42,700,1,12.37,700,1,13.83,15,1,13.84,100,1,13.88,15,1,14.07,2,1,14.17,100,1,14.4,100,1,14.56,900,1,14.6,700,1,14.68,1400,1,14.77,200,1,2,301746949
2025-07-17T15:43:48.788512022Z,2025-07-17T15:43:48.788345787Z,160,2,1108,C,A,14.970000000,100,0,301451077,0,166235,253027959,ARL,,13.26,100,1,13.04,2,1,13.03,100,1,12.73,100,1,12.71,100,1,12.5,700,1,12.46,200,1,12.43,700,1,12.42,700,1,12.37,700,1,13.83,15,1,13.84,100,1,13.88,15,1,14.07,2,1,14.17,100,1,14.4,100,1,14.56,900,1,14.6,700,1,14.68,1400,1,14.77,200,1,2,301451077
2025-07-17T15:43:48.788512022Z,2025-07-17T15:43:48.788345787Z,160,2,1108,A,A,14.910000000,100,0,301746969,128,166235,253027959,ARL,,13.26,100,1,13.04,2,1,13.03,100,1,12.73,100,1,12.71,100,1,12.5,700,1,12.46,200,1,12.43,700,1,12.42,700,1,12.37,700,1,13.83,15,1,13.84,100,1,13.88,15,1,14.07,2,1,14.17,100,1,14.4,100,1,14.56,900,1,14.6,700,1,14.68,1400,1,14.77,200,1,2,301746969
2025-07-17T15:43:48.790573820Z,2025-07-17T15:43:48.790408191Z,160,2,1108,C,A,14.960000000,100,0,300280777,0,165629,253028026,ARL,,13.26,100,1,13.04,2,1,13.03,100,1,12.73,100,1,12.71,100,1,12.5,700,1,12.46,200,1,12.43,700,1,12.42,700,1,12.37,700,1,13.83,15,1,13.84,100,1,13.88,15,1,14.07,2,1,14.17,100,1,14.4,100,1,14.56,900,1,14.6,700,1,14.68,1400,1,14.77,200,1,2,300280777
2025-07-17T15:43:48.790573820Z,2025-07-17T15:43:48.790408191Z,160,2,1108,A,A,14.810000000,100,0,301747001,130,165629,253028026,ARL,,13.26,100,1,13.04,2,1,13.03,100,1,12.73,100,1,12.71,100,1,12.5,700,1,12.46,200,1,12.43,700,1,12.42,700,1,12.37,700,1,13.83,15,1,13.84,100,1,13.88,15,1,14.07,2,1,14.17,100,1,14.4,100,1,14.56,900,1,14.6,700,1,14.68,1400,1,14.77,200,1,2,301747001
2025-07-17T15:43:48.790600546Z,2025-07-17T15:43:48.790434947Z,160,2,1108,C,A,14.780000000,100,0,300280825,0,165599,253028027,ARL,,13.26,100,1,13.04,2,1,13.03,100,1,12.73,100,1,12.71,100,1,12.5,700,1,12.46,200,1,12.43,700,1,12.42,700,1,12.37,700,1,13.83,15,1,13.84,100,1,13.88,15,1,14.07,2,1,14.17,100,1,14.4,100,1,14.56,900,1,14.6,700,1,14.68,1400,1,14.77,200,1,2,300280825
2025-07-17T15:43:48.790600546Z,2025-07-17T15:43:48.790434947Z,160,2,1108,A,A,14.640000000,100,0,301747005,130,165599,253028027,ARL,,13.26,100,1,13.04,2,1,13.03,100,1,12.73,100,1,12.71,100,1,12.5,700,1,12.46,200,1,12.43,700,1,12.42,700,1,12.37,700,1,13.83,15,1,13.84,100,1,13.88,15,1,14.07,2,1,14.17,100,1,14.4,100,1,14.56,900,1,14.6,700,1,14.64,100,1,14.68,1400,1,2,301747005
2025-07-17T15:43:48.800959598Z,2025-07-17T15:43:48.800794196Z,160,2,1108,C,A,17.760000000,100,0,300280797,0,165402,253028707,ARL,,13.26,100,1,13.04,2,1,13.03,100,1,12.73,100,1,12.71,100,1,12.5,700,1,12.46,200,1,12.43,700,1,12.42,700,1,12.37,700,1,13.83,15,1,13.84,100,1,13.88,15,1,14.07,2,1,14.17,100,1,14.4,100,1,14.56,900,1,14.6,700,1,14.64,100,1,14.68,1400,1,2,300280797
2025-07-17T15:43:48.800959598Z,2025-07-17T15:43:48.800794196Z,160,2,1108,A,A,17.580000000,100,0,301747261,130,165402,253028707,ARL,,13.26,100,1,13.04,2,1,13.03,100,1,12.73,100,1,12.71,100,1,12.5,700,1,12.46,200,1,12.43,700,1,12.42,700,1,12.37,700,1,13.83,15,1,13.84,100,1,13.88,15,1,14.07,2,1,14.17,100,1,14.4,100,1,14.56,900,1,14.6,700,1,14.64,100,1,14.68,1400,1,2,301747261
2025-07-17T15:43:48.806845249Z,2025-07-17T15:43:48.806679708Z,160,2,1108,C,A,16.080000000,100,0,300280773,0,165541,253028803,ARL,,13.26,100,1,13.04,2,1,13.03,100,1,12.73,100,1,12.71,100,1,12.5,700,1,12.46,200,1,12.43,700,1,12.42,700,1,12.37,700,1,13.83,15,1,13.84,100,1,13.88,15,1,14.07,2,1,14.17,100,1,14.4,100,1,14.56,900,1,14.6,700,1,14.64,100,1,14.68,1400,1,2,300280773
2025-07-17T15:43:48.806845249Z,2025-07-17T15:43:48.806679708Z,160,2,1108,A,A,15.920000000,100,0,301747301,130,165541,253028803,ARL,,13.26,100,1,13.04,2,1,13.03,100,1,12.73,100,1,12.71,100,1,12.5,700,1,12.46,200,1,12.43,700,1,12.42,700,1,12.37,700,1,13.83,15,1,13.84,100,1,13.88,15,1,14.07,2,1,14.17,100,1,14.4,100,1,14.56,900,1,14.6,700,1,14.64,100,1,14.68,1400,1,2,301747301
2025-07-17T15:43:48.852570853Z,2025-07-17T15:43:48.852405047Z,160,2,1108,C,A,14.960000000,100,0,300280873,0,165806,253029437,ARL,,13.26,100,1,13.04,2,1,13.03,100,1,12.73,100,1,12.71,100,1,12.5,700,1,12.46,200,1,12.43,700,1,12.42,700,1,12.37,700,1,13.83,15,1,13.84,100,1,13.88,15,1,14.07,2,1,14.17,100,1,14.4,100,1,14.56,900,1,14.6,700,1,14.64,100,1,14.68,1400,1,2,300280873
2025-07-17T15:43:48.852570853Z,2025-07-17T15:43:48.852405047Z,160,2,1108,A,A,14.810000000,100,0,301747957,130,165806,253029437,ARL,,13.26,100,1,13.04,2,1,13.03,100,1,12.73,100,1,12.71,100,1,12.5,700,1,12.46,200,1,12.43,700,1,12.42,700,1,12.37,700,1,13.83,15,1,13.84,100,1,13.88,15,1,14.07,2,1,14.17,100,1,14.4,100,1,14.56,900,1,14.6,700,1,14.64,100,1,14.68,1400,1,2,301747957
2025-07-17T15:43:53.123817759Z,2025-07-17T15:43:53.123652480Z,160,2,1108,C,A,13.880000000,15,0,301451057,130,165279,253100941,ARL,,13.26,100,1,13.04,2,1,13.03,100,1,12.73,100,1,12.71,100,1,12.5,700,1,12.46,200,1,12.43,700,1,12.42,700,1,12.37,700,1,13.83,15,1,13.84,100,1,14.07,2,1,14.17,100,1,14.4,100,1,14.56,900,1,14.6,700,1,14.64,100,1,14.68,1400,1,14.77,200,1,2,301451057
2025-07-17T15:43:54.126276976Z,2025-07-17T15:43:54.126111293Z,160,2,1108,A,A,13.810000000,15,0,301867541,130,165683,253121467,ARL,,13.26,100,1,13.04,2,1,13.03,100,1,12.73,100,1,12.71,100,1,12.5,700,1,12.46,200,1,12.43,700,1,12.42,700,1,12.37,700,1,13.81,15,1,13.83,15,1,13.84,100,1,14.07,2,1,14.17,100,1,14.4,100,1,14.56,900,1,14.6,700,1,14.64,100,1,14.68,1400,1,2,301867541
2025-07-17T15:43:54.998238933Z,2025-07-17T15:43:54.998073317Z,160,2,1108,C,A,13.840000000,100,0,301746949,0,165616,253137948,ARL,,13.26,100,1,13.04,2,1,13.03,100,1,12.73,100,1,12.71,100,1,12.5,700,1,12.46,200,1,12.43,700,1,12.42,700,1,12.37,700,1,13.81,15,1,13.83,15,1,14.07,2,1,14.17,100,1,14.4,100,1,14.56,900,1,14.6,700,1,14.64,100,1,14.68,1400,1,14.77,200,1,2,301746949
2025-07-17T15:43:54.998238933Z,2025-07-17T15:43:54.998073317Z,160,2,1108,A,A,13.820000000,100,0,301885353,130,165616,253137948,ARL,,13.26,100,1,13.04,2,1,13.03,100,1,12.73,100,1,12.71,100,1,12.5,700,1,12.46,200,1,12.43,700,1,12.42,700,1,12.37,700,1,13.81,15,1,13.82,100,1,13.83,15,1,14.07,2,1,14.17,100,1,14.4,100,1,14.56,900,1,14.6,700,1,14.64,100,1,14.68,1400,1,2,301885353
2025-07-17T15:43:55.019172741Z,2025-07-17T15:43:55.019007300Z,160,2,1108,C,A,14.170000000,100,0,301452785,130,165441,253138492,ARL,,13.26,100,1,13.04,2,1,13.03,100,1,12.73,100,1,12.71,100,1,12.5,700,1,12.46,200,1,12.43,700,1,12.42,700,1,12.37,700,1,13.81,15,1,13.82,100,1,13.83,15,1,14.07,2,1,14.4,100,1,14.56,900,1,14.6,700,1,14.64,100,1,14.68,1400,1,14.77,200,1,2,301452785
2025-07-17T15:43:55.019225935Z,2025-07-17T15:43:55.019060515Z,160,2,1108,A,A,14.100000000,100,0,301886057,130,165420,253138493,ARL,,13.26,100,1,13.04,2,1,13.03,100,1,12.73,100,1,12.71,100,1,12.5,700,1,12.46,200,1,12.43,700,1,12.42,700,1,12.37,700,1,13.81,15,1,13.82,100,1,13.83,15,1,14.07,2,1,14.1,100,1,14.4,100,1,14.56,900,1,14.6,700,1,14.64,100,1,14.68,1400,1,2,301886057
2025-07-17T15:44:01.698791467Z,2025-07-17T15:44:01.698626200Z,160,2,1108,C,A,13.830000000,15,0,301746941,130,165267,253246317,ARL,,13.26,100,1,13.04,2,1,13.03,100,1,12.73,100,1,12.71,100,1,12.5,700,1,12.46,200,1,12.43,700,1,12.42,700,1,12.37,700,1,13.81,15,1,13.82,100,1,14.07,2,1,14.1,100,1,14.4,100,1,14.56,900,1,14.6,700,1,14.64,100,1,14.68,1400,1,14.77,200,1,2,301746941
2025-07-17T15:44:04.014878156Z,2025-07-17T15:44:04.014712730Z,160,2,1108,A,A,13.830000000,100,0,302078553,130,165426,253292355,ARL,,13.26,100,1,13.04,2,1,13.03,100,1,12.73,100,1,12.71,100,1,12.5,700,1,12.46,200,1,12.43,700,1,12.42,700,1,12.37,700,1,13.81,15,1,13.82,100,1,13.83,100,1,14.07,2,1,14.1,100,1,14.4,100,1,14.56,900,1,14.6,700,1,14.64,100,1,14.68,1400,1,2,302078553
2025-07-17T15:44:05.055626948Z,2025-07-17T15:44:05.055461574Z,160,2,1108,A,A,13.810000000,100,0,302100649,130,165374,253307083,ARL,,13.26,100,1,13.04,2,1,13.03,100,1,12.73,100,1,12.71,100,1,12.5,700,1,12.46,200,1,12.43,700,1,12.42,700,1,12.37,700,1,13.81,115,1,13.82,100,1,13.83,100,1,14.07,2,1,14.1,100,1,14.4,100,1,14.56,900,1,14.6,700,1,14.64,100,1,14.68,1400,1,2,302100649
2025-07-17T15:44:05.062431949Z,2025-07-17T15:44:05.062266845Z,160,2,1108,C,A,13.830000000,100,0,302078553,130,165104,253307147,ARL,,13.26,100,1,13.04,2,1,13.03,100,1,12.73,100,1,12.71,100,1,12.5,700,1,12.46,200,1,12.43,700,1,12.42,700,1,12.37,700,1,13.81,115,1,13.82,100,1,14.07,2,1,14.1,100,1,14.4,100,1,14.56,900,1,14.6,700,1,14.64,100,1,14.68,1400,1,14.77,200,1,2,302078553
2025-07-17T15:44:09.389713730Z,2025-07-17T15:44:09.389548394Z,160,2,1108,A,A,13.760000000,15,0,302205249,130,165336,253384422,ARL,,13.26,100,1,13.04,2,1,13.03,100,1,12.73,100,1,12.71,100,1,12.5,700,1,12.46,200,1,12.43,700,1,12.42,700,1,12.37,700,1,13.76,15,1,13.81,115,1,13.82,100,1,14.07,2,1,14.1,100,1,14.4,100,1,14.56,900,1,14.6,700,1,14.64,100,1,14.68,1400,1,2,302205249
2025-07-17T15:44:09.390496140Z,2025-07-17T15:44:09.390329935Z,160,2,1108,C,A,14.770000000,100,0,301671709,0,166205,253384438,ARL,,13.26,100,1,13.04,2,1,13.03,100,1,12.73,100,1,12.71,100,1,12.5,700,1,12.46,200,1,12.43,700,1,12.42,700,1,12.37,700,1,13.76,15,1,13.81,115,1,13.82,100,1,14.07,2,1,14.1,100,1,14.4,100,1,14.56,900,1,14.6,700,1,14.64,100,1,14.68,1400,1,2,301671709
2025-07-17T15:44:09.390496140Z,2025-07-17T15:44:09.390329935Z,160,2,1108,A,A,14.660000000,100,0,302205289,128,166205,253384438,ARL,,13.26,100,1,13.04,2,1,13.03,100,1,12.73,100,1,12.71,100,1,12.5,700,1,12.46,200,1,12.43,700,1,12.42,700,1,12.37,700,1,13.76,15,1,13.81,115,1,13.82,100,1,14.07,2,1,14.1,100,1,14.4,100,1,14.56,900,1,14.6,700,1,14.64,100,1,14.66,100,1,2,302205289
2025-07-17T15:44:09.391058486Z,2025-07-17T15:44:09.390893172Z,160,2,1108,C,A,14.770000000,100,0,301671713,0,165314,253384456,ARL,,13.26,100,1,13.04,2,1,13.03,100,1,12.73,100,1,12.71,100,1,12.5,700,1,12.46,200,1,12.43,700,1,12.42,700,1,12.37,700,1,13.76,15,1,13.81,115,1,13.82,100,1,14.07,2,1,14.1,100,1,14.4,100,1,14.56,900,1,14.6,700,1,14.64,100,1,14.66,100,1,2,301671713
2025-07-17T15:44:09.391058486Z,2025-07-17T15:44:09.390893172Z,160,2,1108,A,A,14.660000000,100,0,302205309,130,165314,253384456,ARL,,13.26,100,1,13.04,2,1,13.03,100,1,12.73,100,1,12.71,100,1,12.5,700,1,12.46,200,1,12.43,700,1,12.42,700,1,12.37,700,1,13.76,15,1,13.81,115,1,13.82,100,1,14.07,2,1,14.1,100,1,14.4,100,1,14.56,900,1,14.6,700,1,14.64,100,1,14.66,200,1,2,302205309
2025-07-17T15:44:09.395447612Z,2025-07-17T15:44:09.395281780Z,160,2,1108,C,A,13.820000000,100,0,301885353,0,165832,253384698,ARL,,13.26,100,1,13.04,2,1,13.03,100,1,12.73,100,1,12.71,100,1,12.5,700,1,12.46,200,1,12.43,700,1,12.42,700,1,12.37,700,1,13.76,15,1,13.81,115,1,14.07,2,1,14.1,100,1,14.4,100,1,14.56,900,1,14.6,700,1,14.64,100,1,14.66,200,1,14.68,1400,1,2,301885353
2025-07-17T15:44:09.395447612Z,2025-07-17T15:44:09.395281780Z,160,2,1108,A,A,13.770000000,100,0,302205493,130,165832,253384698,ARL,,13.26,100,1,13.04,2,1,13.03,100,1,12.73,100,1,12.71,100,1,12.5,700,1,12.46,200,1,12.43,700,1,12.42,700,1,12.37,700,1,13.76,15,1,13.77,100,1,13.81,115,1,14.07,2,1,14.1,100,1,14.4,100,1,14.56,900,1,14.6,700,1,14.64,100,1,14.66,200,1,2,302205493
2025-07-17T15:44:09.396195647Z,2025-07-17T15:44:09.396030225Z,160,2,1108,C,A,14.910000000,100,0,301746969,0,165422,253384731,ARL,,13.26,100,1,13.04,2,1,13.03,100,1,12.73,100,1,12.71,100,1,12.5,700,1,12.46,200,1,12.43,700,1,12.42,700,1,12.37,700,1,13.76,15,1,13.77,100,1,13.81,115,1,14.07,2,1,14.1,100,1,14.4,100,1,14.56,900,1,14.6,700,1,14.64,100,1,14.66,200,1,2,301746969
2025-07-17T15:44:09.396195647Z,2025-07-17T15:44:09.396030225Z,160,2,1108,A,A,14.840000000,100,0,302205537,130,165422,253384731,ARL,,13.26,100,1,13.04,2,1,13.03,100,1,12.73,100,1,12.71,100,1,12.5,700,1,12.46,200,1,12.43,700,1,12.42,700,1,12.37,700,1,13.76,15,1,13.77,100,1,13.81,115,1,14.07,2,1,14.1,100,1,14.4,100,1,14.56,900,1,14.6,700,1,14.64,100,1,14.66,200,1,2,302205537
2025-07-17T15:44:09.398011186Z,2025-07-17T15:44:09.397845986Z,160,2,1108,A,A,13.790000000,100,0,302205561,130,165200,253384788,ARL,,13.26,100,1,13.04,2,1,13.03,100,1,12.73,100,1,12.71,100,1,12.5,700,1,12.46,200,1,12.43,700,1,12.42,700,1,12.37,700,1,13.76,15,1,13.77,100,1,13.79,100,1,13.81,115,1,14.07,2,1,14.1,100,1,14.4,100,1,14.56,900,1,14.6,700,1,14.64,100,1,2,302205561
2025-07-17T15:44:09.404828956Z,2025-07-17T15:44:09.404663816Z,160,2,1108,C,A,13.810000000,100,0,302100649,130,165140,253385013,ARL,,13.26,100,1,13.04,2,1,13.03,100,1,12.73,100,1,12.71,100,1,12.5,700,1,12.46,200,1,12.43,700,1,12.42,700,1,12.37,700,1,13.76,15,1,13.77,100,1,13.79,100,1,13.81,15,1,14.07,2,1,14.1,100,1,14.4,100,1,14.56,900,1,14.6,700,1,14.64,100,1,2,302100649
2025-07-17T15:44:20.402535831Z,2025-07-17T15:44:20.402370565Z,160,2,1108,C,A,13.810000000,15,0,301867541,130,165266,253562230,ARL,,13.26,100,1,13.04,2,1,13.03,100,1,12.73,100,1,12.71,100,1,12.5,700,1,12.46,200,1,12.43,700,1,12.42,700,1,12.37,700,1,13.76,15,1,13.77,100,1,13.79,100,1,14.07,2,1,14.1,100,1,14.4,100,1,14.56,900,1,14.6,700,1,14.64,100,1,14.66,200,1,2,301867541
2025-07-17T15:44:21.405486122Z,2025-07-17T15:44:21.405320730Z,160,2,1108,A,A,13.740000000,15,0,302458113,130,165392,253582427,ARL,,13.26,100,1,13.04,2,1,13.03,100,1,12.73,100,1,12.71,100,1,12.5,700,1,12.46,200,1,12.43,700,1,12.42,700,1,12.37,700,1,13.74,15,1,13.76,15,1,13.77,100,1,13.79,100,1,14.07,2,1,14.1,100,1,14.4,100,1,14.56,900,1,14.6,700,1,14.64,100,1,2,302458113
2025-07-17T15:44:21.843235911Z,2025-07-17T15:44:21.843070079Z,160,2,1108,C,A,13.770000000,100,0,302205493,0,165832,253590641,ARL,,13.26,100,1,13.04,2,1,13.03,100,1,12.73,100,1,12.71,100,1,12.5,700,1,12.46,200,1,12.43,700,1,12.42,700,1,12.37,700,1,13.74,15,1,13.76,15,1,13.79,100,1,14.07,2,1,14.1,100,1,14.4,100,1,14.56,900,1,14.6,700,1,14.64,100,1,14.66,200,1,2,302205493
2025-07-17T15:44:21.843235911Z,2025-07-17T15:44:21.843070079Z,160,2,1108,A,A,13.750000000,100,0,302466045,130,165832,253590641,ARL,,13.26,100,1,13.04,2,1,13.03,100,1,12.73,100,1,12.71,100,1,12.5,700,1,12.46,200,1,12.43,700,1,12.42,700,1,12.37,700,1,13.74,15,1,13.75,100,1,13.76,15,1,13.79,100,1,14.07,2,1,14.1,100,1,14.4,100,1,14.56,900,1,14.6,700,1,14.64,100,1,2,302466045
2025-07-17T15:44:21.855416093Z,2025-07-17T15:44:21.855250804Z,160,2,1108,C,A,14.100000000,100,0,301886057,130,165289,253590837,ARL,,13.26,100,1,13.04,2,1,13.03,100,1,12.73,100,1,12.71,100,1,12.5,700,1,12.46,200,1,12.43,700,1,12.42,700,1,12.37,700,1,13.74,15,1,13.75,100,1,13.76,15,1,13.79,100,1,14.07,2,1,14.4,100,1,14.56,900,1,14.6,700,1,14.64,100,1,14.66,200,1,2,301886057
2025-07-17T15:44:21.855471158Z,2025-07-17T15:44:21.855305995Z,160,2,1108,A,A,14.030000000,100,0,302466157,130,165163,253590838,ARL,,13.26,100,1,13.04,2,1,13.03,100,1,12.73,100,1,12.71,100,1,12.5,700,1,12.46,200,1,12.43,700,1,12.42,700,1,12.37,700,1,13.74,15,1,13.75,100,1,13.76,15,1,13.79,100,1,14.03,100,1,14.07,2,1,14.4,100,1,14.56,900,1,14.6,700,1,14.64,100,1,2,302466157
2025-07-17T15:44:24.447075532Z,2025-07-17T15:44:24.446910206Z,160,2,1108,A,A,13.770000000,100,0,302500469,130,165326,253614407,ARL,,13.26,100,1,13.04,2,1,13.03,100,1,12.73,100,1,12.71,100,1,12.5,700,1,12.46,200,1,12.43,700,1,12.42,700,1,12.37,700,1,13.74,15,1,13.75,100,1,13.76,15,1,13.77,100,1,13.79,100,1,14.03,100,1,14.07,2,1,14.4,100,1,14.56,900,1,14.6,700,1,2,302500469
2025-07-17T15:44:24.465555818Z,2025-07-17T15:44:24.465390625Z,160,2,1108,C,A,13.790000000,100,0,302205561,130,165193,253614591,ARL,,13.26,100,1,13.04,2,1,13.03,100,1,12.73,100,1,12.71,100,1,12.5,700,1,12.46,200,1,12.43,700,1,12.42,700,1,12.37,700,1,13.74,15,1,13.75,100,1,13.76,15,1,13.77,100,1,14.03,100,1,14.07,2,1,14.4,100,1,14.56,900,1,14.6,700,1,14.64,100,1,2,302205561
2025-07-17T15:44:30.846822983Z,2025-07-17T15:44:30.846657613Z,160,2,1108,C,A,13.760000000,15,0,302205249,130,165370,253704439,ARL,,13.26,100,1,13.04,2,1,13.03,100,1,12.73,100,1,12.71,100,1,12.5,700,1,12.46,200,1,12.43,700,1,12.42,700,1,12.37,700,1,13.74,15,1,13.75,100,1,13.77,100,1,14.03,100,1,14.07,2,1,14.4,100,1,14.56,900,1,14.6,700,1,14.64,100,1,14.66,200,1,2,302205249
2025-07-17T15:44:31.849784693Z,2025-07-17T15:44:31.849618640Z,160,2,1108,A,A,13.720000000,15,0,302649021,130,166053,253721156,ARL,,13.26,100,1,13.04,2,1,13.03,100,1,12.73,100,1,12.71,100,1,12.5,700,1,12.46,200,1,12.43,700,1,12.42,700,1,12.37,700,1,13.72,15,1,13.74,15,1,13.75,100,1,13.77,100,1,14.03,100,1,14.07,2,1,14.4,100,1,14.56,900,1,14.6,700,1,14.64,100,1,2,302649021
2025-07-17T15:44:31.849921857Z,2025-07-17T15:44:31.849756452Z,160,2,1108,A,A,13.750000000,100,0,302649029,130,165405,253721157,ARL,,13.26,100,1,13.04,2,1,13.03,100,1,12.73,100,1,12.71,100,1,12.5,700,1,12.46,200,1,12.43,700,1,12.42,700,1,12.37,700,1,13.72,15,1,13.74,15,1,13.75,200,1,13.77,100,1,14.03,100,1,14.07,2,1,14.4,100,1,14.56,900,1,14.6,700,1,14.64,100,1,2,302649029
2025-07-17T15:44:31.910124978Z,2025-07-17T15:44:31.909959614Z,160,2,1108,C,A,13.770000000,100,0,302500469,130,165364,253722140,ARL,,13.26,100,1,13.04,2,1,13.03,100,1,12.73,100,1,12.71,100,1,12.5,700,1,12.46,200,1,12.43,700,1,12.42,700,1,12.37,700,1,13.72,15,1,13.74,15,1,13.75,200,1,14.03,100,1,14.07,2,1,14.4,100,1,14.56,900,1,14.6,700,1,14.64,100,1,14.66,200,1,2,302500469
2025-07-17T15:44:32.484497230Z,2025-07-17T15:44:32.484331764Z,160,2,1108,C,A,13.750000000,100,0,302466045,0,165466,253730877,ARL,,13.26,100,1,13.04,2,1,13.03,100,1,12.73,100,1,12.71,100,1,12.5,700,1,12.46,200,1,12.43,700,1,12.42,700,1,12.37,700,1,13.72,15,1,13.74,15,1,13.75,100,1,14.03,100,1,14.07,2,1,14.4,100,1,14.56,900,1,14.6,700,1,14.64,100,1,14.66,200,1,2,302466045
2025-07-17T15:44:32.484497230Z,2025-07-17T15:44:32.484331764Z,160,2,1108,A,A,13.730000000,100,0,302662769,130,165466,253730877,ARL,,13.26,100,1,13.04,2,1,13.03,100,1,12.73,100,1,12.71,100,1,12.5,700,1,12.46,200,1,12.43,700,1,12.42,700,1,12.37,700,1,13.72,15,1,13.73,100,1,13.74,15,1,13.75,100,1,14.03,100,1,14.07,2,1,14.4,100,1,14.56,900,1,14.6,700,1,14.64,100,1,2,302662769
2025-07-17T15:44:32.485238209Z,2025-07-17T15:44:32.485072552Z,160,2,1108,C,A,14.840000000,100,0,302205537,0,165657,253730907,ARL,,13.26,100,1,13.04,2,1,13.03,100,1,12.73,100,1,12.71,100,1,12.5,700,1,12.46,200,1,12.43,700,1,12.42,700,1,12.37,700,1,13.72,15,1,13.73,100,1,13.74,15,1,13.75,100,1,14.03,100,1,14.07,2,1,14.4,100,1,14.56,900,1,14.6,700,1,14.64,100,1,2,302205537
2025-07-17T15:44:32.485238209Z,2025-07-17T15:44:32.485072552Z,160,2,1108,A,A,14.790000000,100,0,302662821,130,165657,253730907,ARL,,13.26,100,1,13.04,2,1,13.03,100,1,12.73,100,1,12.71,100,1,12.5,700,1,12.46,200,1,12.43,700,1,12.42,700,1,12.37,700,1,13.72,15,1,13.73,100,1,13.74,15,1,13.75,100,1,14.03,100,1,14.07,2,1,14.4,100,1,14.56,900,1,14.6,700,1,14.64,100,1,2,302662821
2025-07-17T15:44:33.389387814Z,2025-07-17T15:44:33.389222513Z,160,2,1108,A,A,14.280000000,100,0,302681357,130,165301,253745665,ARL,,13.26,100,1,13.04,2,1,13.03,100,1,12.73,100,1,12.71,100,1,12.5,700,1,12.46,200,1,12.43,700,1,12.42,700,1,12.37,700,1,13.72,15,1,13.73,100,1,13.74,15,1,13.75,100,1,14.03,100,1,14.07,2,1,14.28,100,1,14.4,100,1,14.56,900,1,14.6,700,1,2,302681357
2025-07-17T15:44:33.389389030Z,2025-07-17T15:44:33.389223581Z,160,2,1108,C,A,14.560000000,100,0,146960005,130,165449,253745666,ARL,,13.26,100,1,13.04,2,1,13.03,100,1,12.73,100,1,12.71,100,1,12.5,700,1,12.46,200,1,12.43,700,1,12.42,700,1,12.37,700,1,13.72,15,1,13.73,100,1,13.74,15,1,13.75,100,1,14.03,100,1,14.07,2,1,14.28,100,1,14.4,100,1,14.56,800,1,14.6,700,1,2,146960005
2025-07-17T15:44:36.362187673Z,2025-07-17T15:44:36.362022168Z,160,2,1108,C,A,13.740000000,15,0,302458113,130,165505,253783635,ARL,,13.26,100,1,13.04,2,1,13.03,100,1,12.73,100,1,12.71,100,1,12.5,700,1,12.46,200,1,12.43,700,1,12.42,700,1,12.37,700,1,13.72,15,1,13.73,100,1,13.75,100,1,14.03,100,1,14.07,2,1,14.28,100,1,14.4,100,1,14.56,800,1,14.6,700,1,14.64,100,1,2,302458113
2025-07-17T15:44:37.364377419Z,2025-07-17T15:44:37.364212109Z,160,2,1108,A,A,13.700000000,15,0,302750929,130,165310,253797506,ARL,,13.26,100,1,13.04,2,1,13.03,100,1,12.73,100,1,12.71,100,1,12.5,700,1,12.46,200,1,12.43,700,1,12.42,700,1,12.37,700,1,13.7,15,1,13.72,15,1,13.73,100,1,13.75,100,1,14.03,100,1,14.07,2,1,14.28,100,1,14.4,100,1,14.56,800,1,14.6,700,1,2,302750929
2025-07-17T15:44:37.364519067Z,2025-07-17T15:44:37.364353897Z,160,2,1108,A,A,13.730000000,100,0,302750937,130,165170,253797510,ARL,,13.26,100,1,13.04,2,1,13.03,100,1,12.73,100,1,12.71,100,1,12.5,700,1,12.46,200,1,12.43,700,1,12.42,700,1,12.37,700,1,13.7,15,1,13.72,15,1,13.73,200,1,13.75,100,1,14.03,100,1,14.07,2,1,14.28,100,1,14.4,100,1,14.56,800,1,14.6,700,1,2,302750937
2025-07-17T15:44:37.458119494Z,2025-07-17T15:44:37.457954350Z,160,2,1108,C,A,13.750000000,100,0,302649029,130,165144,253798432,ARL,,13.26,100,1,13.04,2,1,13.03,100,1,12.73,100,1,12.71,100,1,12.5,700,1,12.46,200,1,12.43,700,1,12.42,700,1,12.37,700,1,13.7,15,1,13.72,15,1,13.73,200,1,14.03,100,1,14.07,2,1,14.28,100,1,14.4,100,1,14.56,800,1,14.6,700,1,14.64,100,1,2,302649029
2025-07-17T15:44:38.432460509Z,2025-07-17T15:44:38.432294362Z,160,2,1108,C,A,13.730000000,100,0,302662769,0,166147,253807786,ARL,,13.26,100,1,13.04,2,1,13.03,100,1,12.73,100,1,12.71,100,1,12.5,700,1,12.46,200,1,12.43,700,1,12.42,700,1,12.37,700,1,13.7,15,1,13.72,15,1,13.73,100,1,14.03,100,1,14.07,2,1,14.28,100,1,14.4,100,1,14.56,800,1,14.6,700,1,14.64,100,1,2,302662769
2025-07-17T15:44:38.432460509Z,2025-07-17T15:44:38.432294362Z,160,2,1108,A,A,13.710000000,100,0,302763889,130,166147,253807786,ARL,,13.26,100,1,13.04,2,1,13.03,100,1,12.73,100,1,12.71,100,1,12.5,700,1,12.46,200,1,12.43,700,1,12.42,700,1,12.37,700,1,13.7,15,1,13.71,100,1,13.72,15,1,13.73,100,1,14.03,100,1,14.07,2,1,14.28,100,1,14.4,100,1,14.56,800,1,14.6,700,1,2,302763889
2025-07-17T15:44:38.439253975Z,2025-07-17T15:44:38.439088042Z,160,2,1108,C,A,15.920000000,100,0,301747301,0,165933,253808105,ARL,,13.26,100,1,13.04,2,1,13.03,100,1,12.73,100,1,12.71,100,1,12.5,700,1,12.46,200,1,12.43,700,1,12.42,700,1,12.37,700,1,13.7,15,1,13.71,100,1,13.72,15,1,13.73,100,1,14.03,100,1,14.07,2,1,14.28,100,1,14.4,100,1,14.56,800,1,14.6,700,1,2,301747301
2025-07-17T15:44:38.439253975Z,2025-07-17T15:44:38.439088042Z,160,2,1108,A,A,15.770000000,100,0,302764121,130,165933,253808105,ARL,,13.26,100,1,13.04,2,1,13.03,100,1,12.73,100,1,12.71,100,1,12.5,700,1,12.46,200,1,12.43,700,1,12.42,700,1,12.37,700,1,13.7,15,1,13.71,100,1,13.72,15,1,13.73,100,1,14.03,100,1,14.07,2,1,14.28,100,1,14.4,100,1,14.56,800,1,14.6,700,1,2,302764121
2025-07-17T15:44:38.440321697Z,2025-07-17T15:44:38.440156077Z,160,2,1108,C,A,17.580000000,100,0,301747261,0,165620,253808122,ARL,,13.26,100,1,13.04,2,1,13.03,100,1,12.73,100,1,12.71,100,1,12.5,700,1,12.46,200,1,12.43,700,1,12.42,700,1,12.37,700,1,13.7,15,1,13.71,100,1,13.72,15,1,13.73,100,1,14.03,100,1,14.07,2,1,14.28,100,1,14.4,100,1,14.56,800,1,14.6,700,1,2,301747261
2025-07-17T15:44:38.440321697Z,2025-07-17T15:44:38.440156077Z,160,2,1108,A,A,17.420000000,100,0,302764137,130,165620,253808122,ARL,,13.26,100,1,13.04,2,1,13.03,100,1,12.73,100,1,12.71,100,1,12.5,700,1,12.46,200,1,12.43,700,1,12.42,700,1,12.37,700,1,13.7,15,1,13.71,100,1,13.72,15,1,13.73,100,1,14.03,100,1,14.07,2,1,14.28,100,1,14.4,100,1,14.56,800,1,14.6,700,1,2,302764137
2025-07-17T15:44:43.019262217Z,2025-07-17T15:44:43.019083502Z,160,2,1108,C,A,13.700000000,15,0,302750929,128,178715,253875920,ARL,,13.26,100,1,13.04,2,1,13.03,100,1,12.73,100,1,12.71,100,1,12.5,700,1,12.46,200,1,12.43,700,1,12.42,700,1,12.37,700,1,13.71,100,1,13.72,15,1,13.73,100,1,14.03,100,1,14.07,2,1,14.28,100,1,14.4,100,1,14.56,800,1,14.6,700,1,14.64,100,1,2,302750929
2025-07-17T15:44:43.019352658Z,2025-07-17T15:44:43.019184132Z,160,2,1108,C,A,13.720000000,15,0,302649021,128,168526,253876010,ARL,,13.26,100,1,13.04,2,1,13.03,100,1,12.73,100,1,12.71,100,1,12.5,700,1,12.46,200,1,12.43,700,1,12.42,700,1,12.37,700,1,13.71,100,1,13.73,100,1,14.03,100,1,14.07,2,1,14.28,100,1,14.4,100,1,14.56,800,1,14.6,700,1,14.64,100,1,14.66,200,1,2,302649021
2025-07-17T15:44:44.076009999Z,2025-07-17T15:44:44.075843113Z,160,2,1108,A,A,13.700000000,15,0,302867209,128,166886,253892869,ARL,,13.26,100,1,13.04,2,1,13.03,100,1,12.73,100,1,12.71,100,1,12.5,700,1,12.46,200,1,12.43,700,1,12.42,700,1,12.37,700,1,13.7,15,1,13.71,100,1,13.73,100,1,14.03,100,1,14.07,2,1,14.28,100,1,14.4,100,1,14.56,800,1,14.6,700,1,14.64,100,1,2,302867209
2025-07-17T15:44:44.781630732Z,2025-07-17T15:44:44.781464821Z,160,2,1108,C,A,13.700000000,15,0,302867209,130,165911,253901222,ARL,,13.26,100,1,13.04,2,1,13.03,100,1,12.73,100,1,12.71,100,1,12.5,700,1,12.46,200,1,12.43,700,1,12.42,700,1,12.37,700,1,13.71,100,1,13.73,100,1,14.03,100,1,14.07,2,1,14.28,100,1,14.4,100,1,14.56,800,1,14.6,700,1,14.64,100,1,14.66,200,1,2,302867209
2025-07-17T15:44:53.143249270Z,2025-07-17T15:44:53.143083969Z,160,2,1108,C,A,13.730000000,100,0,302750937,130,165301,254011871,ARL,,13.26,100,1,13.04,2,1,13.03,100,1,12.73,100,1,12.71,100,1,12.5,700,1,12.46,200,1,12.43,700,1,12.42,700,1,12.37,700,1,13.71,100,1,14.03,100,1,14.07,2,1,14.28,100,1,14.4,100,1,14.56,800,1,14.6,700,1,14.64,100,1,14.66,200,1,14.68,1400,1,2,302750937
2025-07-17T15:44:57.191188470Z,2025-07-17T15:44:57.191023026Z,160,2,1108,A,A,13.750000000,100,0,303118785,130,165444,254079162,ARL,,13.26,100,1,13.04,2,1,13.03,100,1,12.73,100,1,12.71,100,1,12.5,700,1,12.46,200,1,12.43,700,1,12.42,700,1,12.37,700,1,13.71,100,1,13.75,100,1,14.03,100,1,14.07,2,1,14.28,100,1,14.4,100,1,14.56,800,1,14.6,700,1,14.64,100,1,14.66,200,1,2,303118785
2025-07-17T15:45:07.065756574Z,2025-07-17T15:45:07.065587919Z,160,2,1108,C,A,13.710000000,100,0,302763889,128,168655,254244597,ARL,,13.26,100,1,13.04,2,1,13.03,100,1,12.73,100,1,12.71,100,1,12.5,700,1,12.46,200,1,12.43,700,1,12.42,700,1,12.37,700,1,13.75,100,1,14.03,100,1,14.07,2,1,14.28,100,1,14.4,100,1,14.56,800,1,14.6,700,1,14.64,100,1,14.66,200,1,14.68,1400,1,2,302763889
2025-07-17T15:45:07.080131505Z,2025-07-17T15:45:07.079966224Z,160,2,1108,C,A,13.750000000,100,0,303118785,130,165281,254245492,ARL,,13.26,100,1,13.04,2,1,13.03,100,1,12.73,100,1,12.71,100,1,12.5,700,1,12.46,200,1,12.43,700,1,12.42,700,1,12.37,700,1,14.03,100,1,14.07,2,1,14.28,100,1,14.4,100,1,14.56,800,1,14.6,700,1,14.64,100,1,14.66,200,1,14.68,1400,1,14.79,100,1,2,303118785
2025-07-17T15:45:07.080687215Z,2025-07-17T15:45:07.080521807Z,160,2,1108,C,A,14.660000000,100,0,302205289,0,165408,254245505,ARL,,13.26,100,1,13.04,2,1,13.03,100,1,12.73,100,1,12.71,100,1,12.5,700,1,12.46,200,1,12.43,700,1,12.42,700,1,12.37,700,1,14.03,100,1,14.07,2,1,14.28,100,1,14.4,100,1,14.56,800,1,14.6,700,1,14.64,100,1,14.66,100,1,14.68,1400,1,14.79,100,1,2,302205289
2025-07-17T15:45:07.080687215Z,2025-07-17T15:45:07.080521807Z,160,2,1108,A,A,14.890000000,100,0,303330477,130,165408,254245505,ARL,,13.26,100,1,13.04,2,1,13.03,100,1,12.73,100,1,12.71,100,1,12.5,700,1,12.46,200,1,12.43,700,1,12.42,700,1,12.37,700,1,14.03,100,1,14.07,2,1,14.28,100,1,14.4,100,1,14.56,800,1,14.6,700,1,14.64,100,1,14.66,100,1,14.68,1400,1,14.79,100,1,2,303330477
2025-07-17T15:45:07.080872245Z,2025-07-17T15:45:07.080706110Z,160,2,1108,C,A,14.790000000,100,0,302662821,0,166135,254245511,ARL,,13.26,100,1,13.04,2,1,13.03,100,1,12.73,100,1,12.71,100,1,12.5,700,1,12.46,200,1,12.43,700,1,12.42,700,1,12.37,700,1,14.03,100,1,14.07,2,1,14.28,100,1,14.4,100,1,14.56,800,1,14.6,700,1,14.64,100,1,14.66,100,1,14.68,1400,1,14.81,200,1,2,302662821
2025-07-17T15:45:07.080872245Z,2025-07-17T15:45:07.080706110Z,160,2,1108,A,A,15.060000000,100,0,303330485,130,166135,254245511,ARL,,13.26,100,1,13.04,2,1,13.03,100,1,12.73,100,1,12.71,100,1,12.5,700,1,12.46,200,1,12.43,700,1,12.42,700,1,12.37,700,1,14.03,100,1,14.07,2,1,14.28,100,1,14.4,100,1,14.56,800,1,14.6,700,1,14.64,100,1,14.66,100,1,14.68,1400,1,14.81,200,1,2,303330485
2025-07-17T15:45:07.081578064Z,2025-07-17T15:45:07.081407507Z,160,2,1108,C,A,14.810000000,100,0,301747001,0,170557,254245568,ARL,,13.26,100,1,13.04,2,1,13.03,100,1,12.73,100,1,12.71,100,1,12.5,700,1,12.46,200,1,12.43,700,1,12.42,700,1,12.37,700,1,14.03,100,1,14.07,2,1,14.28,100,1,14.4,100,1,14.56,800,1,14.6,700,1,14.64,100,1,14.66,100,1,14.68,1400,1,14.81,100,1,2,301747001
2025-07-17T15:45:07.081578064Z,2025-07-17T15:45:07.081407507Z,160,2,1108,A,A,14.960000000,100,0,303330509,128,170557,254245568,ARL,,13.26,100,1,13.04,2,1,13.03,100,1,12.73,100,1,12.71,100,1,12.5,700,1,12.46,200,1,12.43,700,1,12.42,700,1,12.37,700,1,14.03,100,1,14.07,2,1,14.28,100,1,14.4,100,1,14.56,800,1,14.6,700,1,14.64,100,1,14.66,100,1,14.68,1400,1,14.81,100,1,2,303330509
2025-07-17T15:45:07.081607970Z,2025-07-17T15:45:07.081441134Z,160,2,1108,C,A,14.660000000,100,0,302205309,0,166836,254245576,ARL,,13.26,100,1,13.04,2,1,13.03,100,1,12.73,100,1,12.71,100,1,12.5,700,1,12.46,200,1,12.43,700,1,12.42,700,1,12.37,700,1,14.03,100,1,14.07,2,1,14.28,100,1,14.4,100,1,14.56,800,1,14.6,700,1,14.64,100,1,14.68,1400,1,14.81,100,1,14.89,100,1,2,302205309
2025-07-17T15:45:07.081607970Z,2025-07-17T15:45:07.081441134Z,160,2,1108,A,A,14.890000000,100,0,303330521,130,166836,254245576,ARL,,13.26,100,1,13.04,2,1,13.03,100,1,12.73,100,1,12.71,100,1,12.5,700,1,12.46,200,1,12.43,700,1,12.42,700,1,12.37,700,1,14.03,100,1,14.07,2,1,14.28,100,1,14.4,100,1,14.56,800,1,14.6,700,1,14.64,100,1,14.68,1400,1,14.81,100,1,14.89,200,1,2,303330521
2025-07-17T15:45:07.083898999Z,2025-07-17T15:45:07.083732443Z,160,2,1108,C,A,17.420000000,100,0,302764137,0,166556,254246327,ARL,,13.26,100,1,13.04,2,1,13.03,100,1,12.73,100,1,12.71,100,1,12.5,700,1,12.46,200,1,12.43,700,1,12.42,700,1,12.37,700,1,14.03,100,1,14.07,2,1,14.28,100,1,14.4,100,1,14.56,800,1,14.6,700,1,14.64,100,1,14.68,1400,1,14.81,100,1,14.89,200,1,2,302764137
2025-07-17T15:45:07.083898999Z,2025-07-17T15:45:07.083732443Z,160,2,1108,A,A,17.760000000,100,0,303331309,130,166556,254246327,ARL,,13.26,100,1,13.04,2,1,13.03,100,1,12.73,100,1,12.71,100,1,12.5,700,1,12.46,200,1,12.43,700,1,12.42,700,1,12.37,700,1,14.03,100,1,14.07,2,1,14.28,100,1,14.4,100,1,14.56,800,1,14.6,700,1,14.64,100,1,14.68,1400,1,14.81,100,1,14.89,200,1,2,303331309
2025-07-17T15:45:07.085222525Z,2025-07-17T15:45:07.085057258Z,160,2,1108,C,A,14.030000000,100,0,302466157,130,165267,254246434,ARL,,13.26,100,1,13.04,2,1,13.03,100,1,12.73,100,1,12.71,100,1,12.5,700,1,12.46,200,1,12.43,700,1,12.42,700,1,12.37,700,1,14.07,2,1,14.28,100,1,14.4,100,1,14.56,800,1,14.6,700,1,14.64,100,1,14.68,1400,1,14.81,100,1,14.89,200,1,14.96,100,1,2,302466157
2025-07-17T15:45:07.085274852Z,2025-07-17T15:45:07.085109545Z,160,2,1108,A,A,14.260000000,100,0,303331401,130,165307,254246437,ARL,,13.26,100,1,13.04,2,1,13.03,100,1,12.73,100,1,12.71,100,1,12.5,700,1,12.46,200,1,12.43,700,1,12.42,700,1,12.37,700,1,14.07,2,1,14.26,100,1,14.28,100,1,14.4,100,1,14.56,800,1,14.6,700,1,14.64,100,1,14.68,1400,1,14.81,100,1,14.89,200,1,2,303331401
2025-07-17T15:45:07.086534700Z,2025-07-17T15:45:07.086368957Z,160,2,1108,C,A,14.640000000,100,0,301747005,130,165743,254246501,ARL,,13.26,100,1,13.04,2,1,13.03,100,1,12.73,100,1,12.71,100,1,12.5,700,1,12.46,200,1,12.43,700,1,12.42,700,1,12.37,700,1,14.07,2,1,14.26,100,1,14.28,100,1,14.4,100,1,14.56,800,1,14.6,700,1,14.68,1400,1,14.81,100,1,14.89,200,1,14.96,100,1,2,301747005
2025-07-17T15:45:07.086660325Z,2025-07-17T15:45:07.086494745Z,160,2,1108,A,A,14.780000000,100,0,303331425,130,165580,254246502,ARL,,13.26,100,1,13.04,2,1,13.03,100,1,12.73,100,1,12.71,100,1,12.5,700,1,12.46,200,1,12.43,700,1,12.42,700,1,12.37,700,1,14.07,2,1,14.26,100,1,14.28,100,1,14.4,100,1,14.56,800,1,14.6,700,1,14.68,1400,1,14.78,100,1,14.81,100,1,14.89,200,1,2,303331425
2025-07-17T15:45:07.087389466Z,2025-07-17T15:45:07.087223859Z,160,2,1108,C,A,15.770000000,100,0,302764121,0,165607,254246529,ARL,,13.26,100,1,13.04,2,1,13.03,100,1,12.73,100,1,12.71,100,1,12.5,700,1,12.46,200,1,12.43,700,1,12.42,700,1,12.37,700,1,14.07,2,1,14.26,100,1,14.28,100,1,14.4,100,1,14.56,800,1,14.6,700,1,14.68,1400,1,14.78,100,1,14.81,100,1,14.89,200,1,2,302764121
2025-07-17T15:45:07.087389466Z,2025-07-17T15:45:07.087223859Z,160,2,1108,A,A,16.080000000,100,0,303331429,130,165607,254246529,ARL,,13.26,100,1,13.04,2,1,13.03,100,1,12.73,100,1,12.71,100,1,12.5,700,1,12.46,200,1,12.43,700,1,12.42,700,1,12.37,700,1,14.07,2,1,14.26,100,1,14.28,100,1,14.4,100,1,14.56,800,1,14.6,700,1,14.68,1400,1,14.78,100,1,14.81,100,1,14.89,200,1,2,303331429
2025-07-17T15:45:07.133978488Z,2025-07-17T15:45:07.133812895Z,160,2,1108,C,A,14.810000000,100,0,301747957,0,165593,254250625,ARL,,13.26,100,1,13.04,2,1,13.03,100,1,12.73,100,1,12.71,100,1,12.5,700,1,12.46,200,1,12.43,700,1,12.42,700,1,12.37,700,1,14.07,2,1,14.26,100,1,14.28,100,1,14.4,100,1,14.56,800,1,14.6,700,1,14.68,1400,1,14.78,100,1,14.89,200,1,14.96,100,1,2,301747957
2025-07-17T15:45:07.133978488Z,2025-07-17T15:45:07.133812895Z,160,2,1108,A,A,14.960000000,100,0,303334253,130,165593,254250625,ARL,,13.26,100,1,13.04,2,1,13.03,100,1,12.73,100,1,12.71,100,1,12.5,700,1,12.46,200,1,12.43,700,1,12.42,700,1,12.37,700,1,14.07,2,1,14.26,100,1,14.28,100,1,14.4,100,1,14.56,800,1,14.6,700,1,14.68,1400,1,14.78,100,1,14.89,200,1,14.96,200,1,2,303334253
2025-07-17T15:45:07.469961302Z,2025-07-17T15:45:07.469796155Z,160,2,1108,A,A,14.080000000,100,0,303340405,130,165147,254258029,ARL,,13.26,100,1,13.04,2,1,13.03,100,1,12.73,100,1,12.71,100,1,12.5,700,1,12.46,200,1,12.43,700,1,12.42,700,1,12.37,700,1,14.07,2,1,14.08,100,1,14.26,100,1,14.28,100,1,14.4,100,1,14.56,800,1,14.6,700,1,14.68,1400,1,14.78,100,1,14.89,200,1,2,303340405
2025-07-17T15:45:08.094768552Z,2025-07-17T15:45:08.094603115Z,160,2,1108,C,A,14.890000000,100,0,303330521,0,165437,254266885,ARL,,13.26,100,1,13.04,2,1,13.03,100,1,12.73,100,1,12.71,100,1,12.5,700,1,12.46,200,1,12.43,700,1,12.42,700,1,12.37,700,1,14.07,2,1,14.08,100,1,14.26,100,1,14.28,100,1,14.4,100,1,14.56,800,1,14.6,700,1,14.68,1400,1,14.78,100,1,14.89,100,1,2,303330521
2025-07-17T15:45:08.094768552Z,2025-07-17T15:45:08.094603115Z,160,2,1108,A,A,15.100000000,100,0,303349309,130,165437,254266885,ARL,,13.26,100,1,13.04,2,1,13.03,100,1,12.73,100,1,12.71,100,1,12.5,700,1,12.46,200,1,12.43,700,1,12.42,700,1,12.37,700,1,14.07,2,1,14.08,100,1,14.26,100,1,14.28,100,1,14.4,100,1,14.56,800,1,14.6,700,1,14.68,1400,1,14.78,100,1,14.89,100,1,2,303349309
2025-07-17T15:45:08.103306644Z,2025-07-17T15:45:08.103141155Z,160,2,1108,C,A,14.890000000,100,0,303330477,0,165489,254266971,ARL,,13.26,100,1,13.04,2,1,13.03,100,1,12.73,100,1,12.71,100,1,12.5,700,1,12.46,200,1,12.43,700,1,12.42,700,1,12.37,700,1,14.07,2,1,14.08,100,1,14.26,100,1,14.28,100,1,14.4,100,1,14.56,800,1,14.6,700,1,14.68,1400,1,14.78,100,1,14.96,200,1,2,303330477
2025-07-17T15:45:08.103306644Z,2025-07-17T15:45:08.103141155Z,160,2,1108,A,A,15.100000000,100,0,303349377,130,165489,254266971,ARL,,13.26,100,1,13.04,2,1,13.03,100,1,12.73,100,1,12.71,100,1,12.5,700,1,12.46,200,1,12.43,700,1,12.42,700,1,12.37,700,1,14.07,2,1,14.08,100,1,14.26,100,1,14.28,100,1,14.4,100,1,14.56,800,1,14.6,700,1,14.68,1400,1,14.78,100,1,14.96,200,1,2,303349377
2025-07-17T15:45:24.187008278Z,2025-07-17T15:45:24.186842413Z,160,2,1108,C,A,15.100000000,100,0,303349309,0,165865,254547413,ARL,,13.26,100,1,13.04,2,1,13.03,100,1,12.73,100,1,12.71,100,1,12.5,700,1,12.46,200,1,12.43,700,1,12.42,700,1,12.37,700,1,14.07,2,1,14.08,100,1,14.26,100,1,14.28,100,1,14.4,100,1,14.56,800,1,14.6,700,1,14.68,1400,1,14.78,100,1,14.96,200,1,2,303349309
2025-07-17T15:45:24.187008278Z,2025-07-17T15:45:24.186842413Z,160,2,1108,A,A,14.880000000,100,0,303682385,130,165865,254547413,ARL,,13.26,100,1,13.04,2,1,13.03,100,1,12.73,100,1,12.71,100,1,12.5,700,1,12.46,200,1,12.43,700,1,12.42,700,1,12.37,700,1,14.07,2,1,14.08,100,1,14.26,100,1,14.28,100,1,14.4,100,1,14.56,800,1,14.6,700,1,14.68,1400,1,14.78,100,1,14.88,100,1,2,303682385
2025-07-17T15:45:24.187441892Z,2025-07-17T15:45:24.187276389Z,160,2,1108,C,A,15.100000000,100,0,303349377,0,165503,254547415,ARL,,13.26,100,1,13.04,2,1,13.03,100,1,12.73,100,1,12.71,100,1,12.5,700,1,12.46,200,1,12.43,700,1,12.42,700,1,12.37,700,1,14.07,2,1,14.08,100,1,14.26,100,1,14.28,100,1,14.4,100,1,14.56,800,1,14.6,700,1,14.68,1400,1,14.78,100,1,14.88,100,1,2,303349377
2025-07-17T15:45:24.187441892Z,2025-07-17T15:45:24.187276389Z,160,2,1108,A,A,14.880000000,100,0,303682389,130,165503,254547415,ARL,,13.26,100,1,13.04,2,1,13.03,100,1,12.73,100,1,12.71,100,1,12.5,700,1,12.46,200,1,12.43,700,1,12.42,700,1,12.37,700,1,14.07,2,1,14.08,100,1,14.26,100,1,14.28,100,1,14.4,100,1,14.56,800,1,14.6,700,1,14.68,1400,1,14.78,100,1,14.88,200,1,2,303682389
2025-07-17T15:45:37.509454888Z,2025-07-17T15:45:37.509289536Z,160,2,1108,A,A,13.940000000,15,0,304056997,130,165352,254851462,ARL,,13.26,100,1,13.04,2,1,13.03,100,1,12.73,100,1,12.71,100,1,12.5,700,1,12.46,200,1,12.43,700,1,12.42,700,1,12.37,700,1,13.94,15,1,14.07,2,1,14.08,100,1,14.26,100,1,14.28,100,1,14.4,100,1,14.56,800,1,14.6,700,1,14.68,1400,1,14.78,100,1,2,304056997
2025-07-17T15:45:37.998133497Z,2025-07-17T15:45:37.997967775Z,160,2,1108,C,A,14.080000000,100,0,303340405,0,165722,254864588,ARL,,13.26,100,1,13.04,2,1,13.03,100,1,12.73,100,1,12.71,100,1,12.5,700,1,12.46,200,1,12.43,700,1,12.42,700,1,12.37,700,1,13.94,15,1,14.07,2,1,14.26,100,1,14.28,100,1,14.4,100,1,14.56,800,1,14.6,700,1,14.68,1400,1,14.78,100,1,14.88,200,1,2,303340405
2025-07-17T15:45:37.998133497Z,2025-07-17T15:45:37.997967775Z,160,2,1108,A,A,13.950000000,100,0,304072245,130,165722,254864588,ARL,,13.26,100,1,13.04,2,1,13.03,100,1,12.73,100,1,12.71,100,1,12.5,700,1,12.46,200,1,12.43,700,1,12.42,700,1,12.37,700,1,13.94,15,1,13.95,100,1,14.07,2,1,14.26,100,1,14.28,100,1,14.4,100,1,14.56,800,1,14.6,700,1,14.68,1400,1,14.78,100,1,2,304072245
2025-07-17T15:45:44.700593408Z,2025-07-17T15:45:44.700428155Z,160,2,1108,A,A,13.890000000,15,0,304238913,130,165253,254999429,ARL,,13.26,100,1,13.04,2,1,13.03,100,1,12.73,100,1,12.71,100,1,12.5,700,1,12.46,200,1,12.43,700,1,12.42,700,1,12.37,700,1,13.89,15,1,13.94,15,1,13.95,100,1,14.07,2,1,14.26,100,1,14.28,100,1,14.4,100,1,14.56,800,1,14.6,700,1,14.68,1400,1,2,304238913
2025-07-17T15:45:45.262537122Z,2025-07-17T15:45:45.262371701Z,160,2,1108,C,A,13.950000000,100,0,304072245,0,165421,255010979,ARL,,13.26,100,1,13.04,2,1,13.03,100,1,12.73,100,1,12.71,100,1,12.5,700,1,12.46,200,1,12.43,700,1,12.42,700,1,12.37,700,1,13.89,15,1,13.94,15,1,14.07,2,1,14.26,100,1,14.28,100,1,14.4,100,1,14.56,800,1,14.6,700,1,14.68,1400,1,14.78,100,1,2,304072245
2025-07-17T15:45:45.262537122Z,2025-07-17T15:45:45.262371701Z,160,2,1108,A,A,13.900000000,100,0,304252313,130,165421,255010979,ARL,,13.26,100,1,13.04,2,1,13.03,100,1,12.73,100,1,12.71,100,1,12.5,700,1,12.46,200,1,12.43,700,1,12.42,700,1,12.37,700,1,13.89,15,1,13.9,100,1,13.94,15,1,14.07,2,1,14.26,100,1,14.28,100,1,14.4,100,1,14.56,800,1,14.6,700,1,14.68,1400,1,2,304252313
2025-07-17T15:45:45.263289023Z,2025-07-17T15:45:45.263123432Z,160,2,1108,C,A,15.060000000,100,0,303330485,0,165591,255010987,ARL,,13.26,100,1,13.04,2,1,13.03,100,1,12.73,100,1,12.71,100,1,12.5,700,1,12.46,200,1,12.43,700,1,12.42,700,1,12.37,700,1,13.89,15,1,13.9,100,1,13.94,15,1,14.07,2,1,14.26,100,1,14.28,100,1,14.4,100,1,14.56,800,1,14.6,700,1,14.68,1400,1,2,303330485
2025-07-17T15:45:45.263289023Z,2025-07-17T15:45:45.263123432Z,160,2,1108,A,A,14.980000000,100,0,304252333,130,165591,255010987,ARL,,13.26,100,1,13.04,2,1,13.03,100,1,12.73,100,1,12.71,100,1,12.5,700,1,12.46,200,1,12.43,700,1,12.42,700,1,12.37,700,1,13.89,15,1,13.9,100,1,13.94,15,1,14.07,2,1,14.26,100,1,14.28,100,1,14.4,100,1,14.56,800,1,14.6,700,1,14.68,1400,1,2,304252333
2025-07-17T15:45:45.274360382Z,2025-07-17T15:45:45.274194870Z,160,2,1108,C,A,14.260000000,100,0,303331401,130,165512,255011158,ARL,,13.26,100,1,13.04,2,1,13.03,100,1,12.73,100,1,12.71,100,1,12.5,700,1,12.46,200,1,12.43,700,1,12.42,700,1,12.37,700,1,13.89,15,1,13.9,100,1,13.94,15,1,14.07,2,1,14.28,100,1,14.4,100,1,14.56,800,1,14.6,700,1,14.68,1400,1,14.78,100,1,2,303331401
2025-07-17T15:45:45.274410721Z,2025-07-17T15:45:45.274245387Z,160,2,1108,A,A,14.180000000,100,0,304252469,130,165334,255011161,ARL,,13.26,100,1,13.04,2,1,13.03,100,1,12.73,100,1,12.71,100,1,12.5,700,1,12.46,200,1,12.43,700,1,12.42,700,1,12.37,700,1,13.89,15,1,13.9,100,1,13.94,15,1,14.07,2,1,14.18,100,1,14.28,100,1,14.4,100,1,14.56,800,1,14.6,700,1,14.68,1400,1,2,304252469
2025-07-17T15:45:58.419783333Z,2025-07-17T15:45:58.419617935Z,160,2,1108,C,A,13.940000000,15,0,304056997,130,165398,255183198,ARL,,13.26,100,1,13.04,2,1,13.03,100,1,12.73,100,1,12.71,100,1,12.5,700,1,12.46,200,1,12.43,700,1,12.42,700,1,12.37,700,1,13.89,15,1,13.9,100,1,14.07,2,1,14.18,100,1,14.28,100,1,14.4,100,1,14.56,800,1,14.6,700,1,14.68,1400,1,14.78,100,1,2,304056997
2025-07-17T15:45:58.420278691Z,2025-07-17T15:45:58.420113307Z,160,2,1108,C,A,14.880000000,100,0,303682389,0,165384,255183203,ARL,,13.26,100,1,13.04,2,1,13.03,100,1,12.73,100,1,12.71,100,1,12.5,700,1,12.46,200,1,12.43,700,1,12.42,700,1,12.37,700,1,13.89,15,1,13.9,100,1,14.07,2,1,14.18,100,1,14.28,100,1,14.4,100,1,14.56,800,1,14.6,700,1,14.68,1400,1,14.78,100,1,2,303682389
2025-07-17T15:45:58.420278691Z,2025-07-17T15:45:58.420113307Z,160,2,1108,A,A,14.770000000,100,0,304503585,130,165384,255183203,ARL,,13.26,100,1,13.04,2,1,13.03,100,1,12.73,100,1,12.71,100,1,12.5,700,1,12.46,200,1,12.43,700,1,12.42,700,1,12.37,700,1,13.89,15,1,13.9,100,1,14.07,2,1,14.18,100,1,14.28,100,1,14.4,100,1,14.56,800,1,14.6,700,1,14.68,1400,1,14.77,100,1,2,304503585
2025-07-17T15:45:58.420755889Z,2025-07-17T15:45:58.420590199Z,160,2,1108,C,A,14.880000000,100,0,303682385,0,165690,255183204,ARL,,13.26,100,1,13.04,2,1,13.03,100,1,12.73,100,1,12.71,100,1,12.5,700,1,12.46,200,1,12.43,700,1,12.42,700,1,12.37,700,1,13.89,15,1,13.9,100,1,14.07,2,1,14.18,100,1,14.28,100,1,14.4,100,1,14.56,800,1,14.6,700,1,14.68,1400,1,14.77,100,1,2,303682385
2025-07-17T15:45:58.420755889Z,2025-07-17T15:45:58.420590199Z,160,2,1108,A,A,14.770000000,100,0,304503593,130,165690,255183204,ARL,,13.26,100,1,13.04,2,1,13.03,100,1,12.73,100,1,12.71,100,1,12.5,700,1,12.46,200,1,12.43,700,1,12.42,700,1,12.37,700,1,13.89,15,1,13.9,100,1,14.07,2,1,14.18,100,1,14.28,100,1,14.4,100,1,14.56,800,1,14.6,700,1,14.68,1400,1,14.77,200,1,2,304503593
2025-07-17T15:45:58.782892109Z,2025-07-17T15:45:58.782726994Z,160,2,1108,C,A,13.890000000,15,0,304238913,130,165115,255189425,ARL,,13.26,100,1,13.04,2,1,13.03,100,1,12.73,100,1,12.71,100,1,12.5,700,1,12.46,200,1,12.43,700,1,12.42,700,1,12.37,700,1,13.9,100,1,14.07,2,1,14.18,100,1,14.28,100,1,14.4,100,1,14.56,800,1,14.6,700,1,14.68,1400,1,14.77,200,1,14.78,100,1,2,304238913
2025-07-17T15:46:16.783057616Z,2025-07-17T15:46:16.782892334Z,160,2,1108,A,A,13.880000000,15,0,304949689,130,165282,255552962,ARL,,13.26,100,1,13.04,2,1,13.03,100,1,12.73,100,1,12.71,100,1,12.5,700,1,12.46,200,1,12.43,700,1,12.42,700,1,12.37,700,1,13.88,15,1,13.9,100,1,14.07,2,1,14.18,100,1,14.28,100,1,14.4,100,1,14.56,800,1,14.6,700,1,14.68,1400,1,14.77,200,1,2,304949689
2025-07-17T15:46:16.783326241Z,2025-07-17T15:46:16.783160795Z,160,2,1108,C,A,13.900000000,100,0,304252313,0,165446,255552970,ARL,,13.26,100,1,13.04,2,1,13.03,100,1,12.73,100,1,12.71,100,1,12.5,700,1,12.46,200,1,12.43,700,1,12.42,700,1,12.37,700,1,13.88,15,1,14.07,2,1,14.18,100,1,14.28,100,1,14.4,100,1,14.56,800,1,14.6,700,1,14.68,1400,1,14.77,200,1,14.78,100,1,2,304252313
2025-07-17T15:46:16.783326241Z,2025-07-17T15:46:16.783160795Z,160,2,1108,A,A,13.890000000,100,0,304949697,130,165446,255552970,ARL,,13.26,100,1,13.04,2,1,13.03,100,1,12.73,100,1,12.71,100,1,12.5,700,1,12.46,200,1,12.43,700,1,12.42,700,1,12.37,700,1,13.88,15,1,13.89,100,1,14.07,2,1,14.18,100,1,14.28,100,1,14.4,100,1,14.56,800,1,14.6,700,1,14.68,1400,1,14.77,200,1,2,304949697
2025-07-17T15:46:18.782897570Z,2025-07-17T15:46:18.782732218Z,160,2,1108,C,A,13.880000000,15,0,304949689,130,165352,255587336,ARL,,13.26,100,1,13.04,2,1,13.03,100,1,12.73,100,1,12.71,100,1,12.5,700,1,12.46,200,1,12.43,700,1,12.42,700,1,12.37,700,1,13.89,100,1,14.07,2,1,14.18,100,1,14.28,100,1,14.4,100,1,14.56,800,1,14.6,700,1,14.68,1400,1,14.77,200,1,14.78,100,1,2,304949689
2025-07-17T15:46:28.474166897Z,2025-07-17T15:46:28.474001551Z,160,2,1108,C,A,13.890000000,100,0,304949697,130,165346,255746167,ARL,,13.26,100,1,13.04,2,1,13.03,100,1,12.73,100,1,12.71,100,1,12.5,700,1,12.46,200,1,12.43,700,1,12.42,700,1,12.37,700,1,14.07,2,1,14.18,100,1,14.28,100,1,14.4,100,1,14.56,800,1,14.6,700,1,14.68,1400,1,14.77,200,1,14.78,100,1,14.96,200,1,2,304949697
2025-07-17T15:46:28.474726594Z,2025-07-17T15:46:28.474561156Z,160,2,1108,C,A,14.770000000,100,0,304503593,0,165438,255746173,ARL,,13.26,100,1,13.04,2,1,13.03,100,1,12.73,100,1,12.71,100,1,12.5,700,1,12.46,200,1,12.43,700,1,12.42,700,1,12.37,700,1,14.07,2,1,14.18,100,1,14.28,100,1,14.4,100,1,14.56,800,1,14.6,700,1,14.68,1400,1,14.77,100,1,14.78,100,1,14.96,200,1,2,304503593
2025-07-17T15:46:28.474726594Z,2025-07-17T15:46:28.474561156Z,160,2,1108,A,A,14.880000000,100,0,305184937,130,165438,255746173,ARL,,13.26,100,1,13.04,2,1,13.03,100,1,12.73,100,1,12.71,100,1,12.5,700,1,12.46,200,1,12.43,700,1,12.42,700,1,12.37,700,1,14.07,2,1,14.18,100,1,14.28,100,1,14.4,100,1,14.56,800,1,14.6,700,1,14.68,1400,1,14.77,100,1,14.78,100,1,14.88,100,1,2,305184937
2025-07-17T15:46:28.474896460Z,2025-07-17T15:46:28.474730225Z,160,2,1108,C,A,14.770000000,100,0,304503585,0,166235,255746176,ARL,,13.26,100,1,13.04,2,1,13.03,100,1,12.73,100,1,12.71,100,1,12.5,700,1,12.46,200,1,12.43,700,1,12.42,700,1,12.37,700,1,14.07,2,1,14.18,100,1,14.28,100,1,14.4,100,1,14.56,800,1,14.6,700,1,14.68,1400,1,14.78,100,1,14.88,100,1,14.96,200,1,2,304503585
2025-07-17T15:46:28.474896460Z,2025-07-17T15:46:28.474730225Z,160,2,1108,A,A,14.880000000,100,0,305184953,130,166235,255746176,ARL,,13.26,100,1,13.04,2,1,13.03,100,1,12.73,100,1,12.71,100,1,12.5,700,1,12.46,200,1,12.43,700,1,12.42,700,1,12.37,700,1,14.07,2,1,14.18,100,1,14.28,100,1,14.4,100,1,14.56,800,1,14.6,700,1,14.68,1400,1,14.78,100,1,14.88,200,1,14.96,200,1,2,305184953
2025-07-17T15:46:28.474902154Z,2025-07-17T15:46:28.474736101Z,160,2,1108,C,A,14.980000000,100,0,304252333,0,166053,255746178,ARL,,13.26,100,1,13.04,2,1,13.03,100,1,12.73,100,1,12.71,100,1,12.5,700,1,12.46,200,1,12.43,700,1,12.42,700,1,12.37,700,1,14.07,2,1,14.18,100,1,14.28,100,1,14.4,100,1,14.56,800,1,14.6,700,1,14.68,1400,1,14.78,100,1,14.88,200,1,14.96,200,1,2,304252333
2025-07-17T15:46:28.474902154Z,2025-07-17T15:46:28.474736101Z,160,2,1108,A,A,15.030000000,100,0,305184957,128,166053,255746178,ARL,,13.26,100,1,13.04,2,1,13.03,100,1,12.73,100,1,12.71,100,1,12.5,700,1,12.46,200,1,12.43,700,1,12.42,700,1,12.37,700,1,14.07,2,1,14.18,100,1,14.28,100,1,14.4,100,1,14.56,800,1,14.6,700,1,14.68,1400,1,14.78,100,1,14.88,200,1,14.96,200,1,2,305184957
2025-07-17T15:46:28.492881980Z,2025-07-17T15:46:28.492716775Z,160,2,1108,C,A,14.180000000,100,0,304252469,130,165205,255746619,ARL,,13.26,100,1,13.04,2,1,13.03,100,1,12.73,100,1,12.71,100,1,12.5,700,1,12.46,200,1,12.43,700,1,12.42,700,1,12.37,700,1,14.07,2,1,14.28,100,1,14.4,100,1,14.56,800,1,14.6,700,1,14.68,1400,1,14.78,100,1,14.88,200,1,14.96,200,1,15.03,100,1,2,304252469
2025-07-17T15:46:28.492931279Z,2025-07-17T15:46:28.492765859Z,160,2,1108,A,A,14.260000000,100,0,305185529,130,165420,255746621,ARL,,13.26,100,1,13.04,2,1,13.03,100,1,12.73,100,1,12.71,100,1,12.5,700,1,12.46,200,1,12.43,700,1,12.42,700,1,12.37,700,1,14.07,2,1,14.26,100,1,14.28,100,1,14.4,100,1,14.56,800,1,14.6,700,1,14.68,1400,1,14.78,100,1,14.88,200,1,14.96,200,1,2,305185529
2025-07-17T15:46:28.646273467Z,2025-07-17T15:46:28.646108242Z,160,2,1108,A,A,14.080000000,100,0,305187077,130,165225,255748568,ARL,,13.26,100,1,13.04,2,1,13.03,100,1,12.73,100,1,12.71,100,1,12.5,700,1,12.46,200,1,12.43,700,1,12.42,700,1,12.37,700,1,14.07,2,1,14.08,100,1,14.26,100,1,14.28,100,1,14.4,100,1,14.56,800,1,14.6,700,1,14.68,1400,1,14.78,100,1,14.88,200,1,2,305187077
2025-07-17T15:46:57.524024658Z,2025-07-17T15:46:57.523859388Z,160,2,1108,A,A,13.920000000,15,0,305862145,130,165270,256268482,ARL,,13.26,100,1,13.04,2,1,13.03,100,1,12.73,100,1,12.71,100,1,12.5,700,1,12.46,200,1,12.43,700,1,12.42,700,1,12.37,700,1,13.92,15,1,14.07,2,1,14.08,100,1,14.26,100,1,14.28,100,1,14.4,100,1,14.56,800,1,14.6,700,1,14.68,1400,1,14.78,100,1,2,305862145
2025-07-17T15:46:57.932842994Z,2025-07-17T15:46:57.932677299Z,160,2,1108,C,A,14.080000000,100,0,305187077,0,165695,256280751,ARL,,13.26,100,1,13.04,2,1,13.03,100,1,12.73,100,1,12.71,100,1,12.5,700,1,12.46,200,1,12.43,700,1,12.42,700,1,12.37,700,1,13.92,15,1,14.07,2,1,14.26,100,1,14.28,100,1,14.4,100,1,14.56,800,1,14.6,700,1,14.68,1400,1,14.78,100,1,14.88,200,1,2,305187077
2025-07-17T15:46:57.932842994Z,2025-07-17T15:46:57.932677299Z,160,2,1108,A,A,13.930000000,100,0,305878881,130,165695,256280751,ARL,,13.26,100,1,13.04,2,1,13.03,100,1,12.73,100,1,12.71,100,1,12.5,700,1,12.46,200,1,12.43,700,1,12.42,700,1,12.37,700,1,13.92,15,1,13.93,100,1,14.07,2,1,14.26,100,1,14.28,100,1,14.4,100,1,14.56,800,1,14.6,700,1,14.68,1400,1,14.78,100,1,2,305878881
2025-07-17T15:47:06.609456251Z,2025-07-17T15:47:06.609290857Z,160,2,1108,A,A,13.880000000,15,0,306121113,130,165394,256488374,ARL,,13.26,100,1,13.04,2,1,13.03,100,1,12.73,100,1,12.71,100,1,12.5,700,1,12.46,200,1,12.43,700,1,12.42,700,1,12.37,700,1,13.88,15,1,13.92,15,1,13.93,100,1,14.07,2,1,14.26,100,1,14.28,100,1,14.4,100,1,14.56,800,1,14.6,700,1,14.68,1400,1,2,306121113
2025-07-17T15:47:08.787695144Z,2025-07-17T15:47:08.787529505Z,160,2,1108,C,A,13.930000000,100,0,305878881,0,165639,256532991,ARL,,13.26,100,1,13.04,2,1,13.03,100,1,12.73,100,1,12.71,100,1,12.5,700,1,12.46,200,1,12.43,700,1,12.42,700,1,12.37,700,1,13.88,15,1,13.92,15,1,14.07,2,1,14.26,100,1,14.28,100,1,14.4,100,1,14.56,800,1,14.6,700,1,14.68,1400,1,14.78,100,1,2,305878881
2025-07-17T15:47:08.787695144Z,2025-07-17T15:47:08.787529505Z,160,2,1108,A,A,13.890000000,100,0,306170837,130,165639,256532991,ARL,,13.26,100,1,13.04,2,1,13.03,100,1,12.73,100,1,12.71,100,1,12.5,700,1,12.46,200,1,12.43,700,1,12.42,700,1,12.37,700,1,13.88,15,1,13.89,100,1,13.92,15,1,14.07,2,1,14.26,100,1,14.28,100,1,14.4,100,1,14.56,800,1,14.6,700,1,14.68,1400,1,2,306170837
2025-07-17T15:47:08.788440762Z,2025-07-17T15:47:08.788275184Z,160,2,1108,C,A,15.030000000,100,0,305184957,0,165578,256533005,ARL,,13.26,100,1,13.04,2,1,13.03,100,1,12.73,100,1,12.71,100,1,12.5,700,1,12.46,200,1,12.43,700,1,12.42,700,1,12.37,700,1,13.88,15,1,13.89,100,1,13.92,15,1,14.07,2,1,14.26,100,1,14.28,100,1,14.4,100,1,14.56,800,1,14.6,700,1,14.68,1400,1,2,305184957
2025-07-17T15:47:08.788440762Z,2025-07-17T15:47:08.788275184Z,160,2,1108,A,A,14.970000000,100,0,306170869,130,165578,256533005,ARL,,13.26,100,1,13.04,2,1,13.03,100,1,12.73,100,1,12.71,100,1,12.5,700,1,12.46,200,1,12.43,700,1,12.42,700,1,12.37,700,1,13.88,15,1,13.89,100,1,13.92,15,1,14.07,2,1,14.26,100,1,14.28,100,1,14.4,100,1,14.56,800,1,14.6,700,1,14.68,1400,1,2,306170869
2025-07-17T15:47:08.805983406Z,2025-07-17T15:47:08.805818249Z,160,2,1108,C,A,14.260000000,100,0,305185529,130,165157,256533442,ARL,,13.26,100,1,13.04,2,1,13.03,100,1,12.73,100,1,12.71,100,1,12.5,700,1,12.46,200,1,12.43,700,1,12.42,700,1,12.37,700,1,13.88,15,1,13.89,100,1,13.92,15,1,14.07,2,1,14.28,100,1,14.4,100,1,14.56,800,1,14.6,700,1,14.68,1400,1,14.78,100,1,2,305185529
2025-07-17T15:47:08.806033773Z,2025-07-17T15:47:08.805868059Z,160,2,1108,A,A,14.170000000,100,0,306171457,130,165714,256533443,ARL,,13.26,100,1,13.04,2,1,13.03,100,1,12.73,100,1,12.71,100,1,12.5,700,1,12.46,200,1,12.43,700,1,12.42,700,1,12.37,700,1,13.88,15,1,13.89,100,1,13.92,15,1,14.07,2,1,14.17,100,1,14.28,100,1,14.4,100,1,14.56,800,1,14.6,700,1,14.68,1400,1,2,306171457
2025-07-17T15:47:13.121454355Z,2025-07-17T15:47:13.121288953Z,160,2,1108,C,A,13.880000000,15,0,306121113,130,165402,256612694,ARL,,13.26,100,1,13.04,2,1,13.03,100,1,12.73,100,1,12.71,100,1,12.5,700,1,12.46,200,1,12.43,700,1,12.42,700,1,12.37,700,1,13.89,100,1,13.92,15,1,14.07,2,1,14.17,100,1,14.28,100,1,14.4,100,1,14.56,800,1,14.6,700,1,14.68,1400,1,14.78,100,1,2,306121113
2025-07-17T15:47:13.122562533Z,2025-07-17T15:47:13.122396816Z,160,2,1108,C,A,13.920000000,15,0,305862145,130,165717,256612757,ARL,,13.26,100,1,13.04,2,1,13.03,100,1,12.73,100,1,12.71,100,1,12.5,700,1,12.46,200,1,12.43,700,1,12.42,700,1,12.37,700,1,13.89,100,1,14.07,2,1,14.17,100,1,14.28,100,1,14.4,100,1,14.56,800,1,14.6,700,1,14.68,1400,1,14.78,100,1,14.88,200,1,2,305862145
2025-07-17T15:47:24.786476266Z,2025-07-17T15:47:24.786310694Z,160,2,1108,A,A,13.870000000,15,0,306519385,130,165572,256812416,ARL,,13.26,100,1,13.04,2,1,13.03,100,1,12.73,100,1,12.71,100,1,12.5,700,1,12.46,200,1,12.43,700,1,12.42,700,1,12.37,700,1,13.87,15,1,13.89,100,1,14.07,2,1,14.17,100,1,14.28,100,1,14.4,100,1,14.56,800,1,14.6,700,1,14.68,1400,1,14.78,100,1,2,306519385
2025-07-17T15:47:24.786745657Z,2025-07-17T15:47:24.786580061Z,160,2,1108,C,A,13.890000000,100,0,306170837,0,165596,256812420,ARL,,13.26,100,1,13.04,2,1,13.03,100,1,12.73,100,1,12.71,100,1,12.5,700,1,12.46,200,1,12.43,700,1,12.42,700,1,12.37,700,1,13.87,15,1,14.07,2,1,14.17,100,1,14.28,100,1,14.4,100,1,14.56,800,1,14.6,700,1,14.68,1400,1,14.78,100,1,14.88,200,1,2,306170837
2025-07-17T15:47:24.786745657Z,2025-07-17T15:47:24.786580061Z,160,2,1108,A,A,13.880000000,100,0,306519397,130,165596,256812420,ARL,,13.26,100,1,13.04,2,1,13.03,100,1,12.73,100,1,12.71,100,1,12.5,700,1,12.46,200,1,12.43,700,1,12.42,700,1,12.37,700,1,13.87,15,1,13.88,100,1,14.07,2,1,14.17,100,1,14.28,100,1,14.4,100,1,14.56,800,1,14.6,700,1,14.68,1400,1,14.78,100,1,2,306519397
2025-07-17T15:47:24.786925729Z,2025-07-17T15:47:24.786759805Z,160,2,1108,C,A,14.880000000,100,0,305184937,0,165924,256812422,ARL,,13.26,100,1,13.04,2,1,13.03,100,1,12.73,100,1,12.71,100,1,12.5,700,1,12.46,200,1,12.43,700,1,12.42,700,1,12.37,700,1,13.87,15,1,13.88,100,1,14.07,2,1,14.17,100,1,14.28,100,1,14.4,100,1,14.56,800,1,14.6,700,1,14.68,1400,1,14.78,100,1,2,305184937
2025-07-17T15:47:24.786925729Z,2025-07-17T15:47:24.786759805Z,160,2,1108,A,A,14.770000000,100,0,306519409,130,165924,256812422,ARL,,13.26,100,1,13.04,2,1,13.03,100,1,12.73,100,1,12.71,100,1,12.5,700,1,12.46,200,1,12.43,700,1,12.42,700,1,12.37,700,1,13.87,15,1,13.88,100,1,14.07,2,1,14.17,100,1,14.28,100,1,14.4,100,1,14.56,800,1,14.6,700,1,14.68,1400,1,14.77,100,1,2,306519409
2025-07-17T15:47:24.800616004Z,2025-07-17T15:47:24.800449950Z,160,2,1108,C,A,14.880000000,100,0,305184953,0,166054,256812578,ARL,,13.26,100,1,13.04,2,1,13.03,100,1,12.73,100,1,12.71,100,1,12.5,700,1,12.46,200,1,12.43,700,1,12.42,700,1,12.37,700,1,13.87,15,1,13.88,100,1,14.07,2,1,14.17,100,1,14.28,100,1,14.4,100,1,14.56,800,1,14.6,700,1,14.68,1400,1,14.77,100,1,2,305184953
2025-07-17T15:47:24.800616004Z,2025-07-17T15:47:24.800449950Z,160,2,1108,A,A,14.750000000,100,0,306519741,130,166054,256812578,ARL,,13.26,100,1,13.04,2,1,13.03,100,1,12.73,100,1,12.71,100,1,12.5,700,1,12.46,200,1,12.43,700,1,12.42,700,1,12.37,700,1,13.87,15,1,13.88,100,1,14.07,2,1,14.17,100,1,14.28,100,1,14.4,100,1,14.56,800,1,14.6,700,1,14.68,1400,1,14.75,100,1,2,306519741
2025-07-17T15:47:27.860272892Z,2025-07-17T15:47:27.860107552Z,160,2,1108,A,A,13.830000000,15,0,306587393,130,165340,256866835,ARL,,13.26,100,1,13.04,2,1,13.03,100,1,12.73,100,1,12.71,100,1,12.5,700,1,12.46,200,1,12.43,700,1,12.42,700,1,12.37,700,1,13.83,15,1,13.87,15,1,13.88,100,1,14.07,2,1,14.17,100,1,14.28,100,1,14.4,100,1,14.56,800,1,14.6,700,1,14.68,1400,1,2,306587393
2025-07-17T15:47:31.407029312Z,2025-07-17T15:47:31.406863918Z,160,2,1108,C,A,13.880000000,100,0,306519397,0,165394,256910124,ARL,,13.26,100,1,13.04,2,1,13.03,100,1,12.73,100,1,12.71,100,1,12.5,700,1,12.46,200,1,12.43,700,1,12.42,700,1,12.37,700,1,13.83,15,1,13.87,15,1,14.07,2,1,14.17,100,1,14.28,100,1,14.4,100,1,14.56,800,1,14.6,700,1,14.68,1400,1,14.75,100,1,2,306519397
2025-07-17T15:47:31.407029312Z,2025-07-17T15:47:31.406863918Z,160,2,1108,A,A,13.840000000,100,0,306647425,130,165394,256910124,ARL,,13.26,100,1,13.04,2,1,13.03,100,1,12.73,100,1,12.71,100,1,12.5,700,1,12.46,200,1,12.43,700,1,12.42,700,1,12.37,700,1,13.83,15,1,13.84,100,1,13.87,15,1,14.07,2,1,14.17,100,1,14.28,100,1,14.4,100,1,14.56,800,1,14.6,700,1,14.68,1400,1,2,306647425
2025-07-17T15:47:31.407771110Z,2025-07-17T15:47:31.407605685Z,160,2,1108,C,A,14.970000000,100,0,306170869,0,165425,256910129,ARL,,13.26,100,1,13.04,2,1,13.03,100,1,12.73,100,1,12.71,100,1,12.5,700,1,12.46,200,1,12.43,700,1,12.42,700,1,12.37,700,1,13.83,15,1,13.84,100,1,13.87,15,1,14.07,2,1,14.17,100,1,14.28,100,1,14.4,100,1,14.56,800,1,14.6,700,1,14.68,1400,1,2,306170869
2025-07-17T15:47:31.407771110Z,2025-07-17T15:47:31.407605685Z,160,2,1108,A,A,14.910000000,100,0,306647445,130,165425,256910129,ARL,,13.26,100,1,13.04,2,1,13.03,100,1,12.73,100,1,12.71,100,1,12.5,700,1,12.46,200,1,12.43,700,1,12.42,700,1,12.37,700,1,13.83,15,1,13.84,100,1,13.87,15,1,14.07,2,1,14.17,100,1,14.28,100,1,14.4,100,1,14.56,800,1,14.6,700,1,14.68,1400,1,2,306647445
2025-07-17T15:47:31.413491477Z,2025-07-17T15:47:31.413325908Z,160,2,1108,C,A,14.780000000,100,0,303331425,0,165569,256910184,ARL,,13.26,100,1,13.04,2,1,13.03,100,1,12.73,100,1,12.71,100,1,12.5,700,1,12.46,200,1,12.43,700,1,12.42,700,1,12.37,700,1,13.83,15,1,13.84,100,1,13.87,15,1,14.07,2,1,14.17,100,1,14.28,100,1,14.4,100,1,14.56,800,1,14.6,700,1,14.68,1400,1,2,303331425
2025-07-17T15:47:31.413491477Z,2025-07-17T15:47:31.413325908Z,160,2,1108,A,A,14.640000000,100,0,306647521,130,165569,256910184,ARL,,13.26,100,1,13.04,2,1,13.03,100,1,12.73,100,1,12.71,100,1,12.5,700,1,12.46,200,1,12.43,700,1,12.42,700,1,12.37,700,1,13.83,15,1,13.84,100,1,13.87,15,1,14.07,2,1,14.17,100,1,14.28,100,1,14.4,100,1,14.56,800,1,14.6,700,1,14.64,100,1,2,306647521
2025-07-17T15:47:31.433486283Z,2025-07-17T15:47:31.433320466Z,160,2,1108,C,A,14.960000000,100,0,303330509,0,165817,256910721,ARL,,13.26,100,1,13.04,2,1,13.03,100,1,12.73,100,1,12.71,100,1,12.5,700,1,12.46,200,1,12.43,700,1,12.42,700,1,12.37,700,1,13.83,15,1,13.84,100,1,13.87,15,1,14.07,2,1,14.17,100,1,14.28,100,1,14.4,100,1,14.56,800,1,14.6,700,1,14.64,100,1,2,303330509
2025-07-17T15:47:31.433486283Z,2025-07-17T15:47:31.433320466Z,160,2,1108,A,A,14.810000000,100,0,306649913,130,165817,256910721,ARL,,13.26,100,1,13.04,2,1,13.03,100,1,12.73,100,1,12.71,100,1,12.5,700,1,12.46,200,1,12.43,700,1,12.42,700,1,12.37,700,1,13.83,15,1,13.84,100,1,13.87,15,1,14.07,2,1,14.17,100,1,14.28,100,1,14.4,100,1,14.56,800,1,14.6,700,1,14.64,100,1,2,306649913
2025-07-17T15:47:31.574128504Z,2025-07-17T15:47:31.573963059Z,160,2,1108,C,A,16.080000000,100,0,303331429,0,165445,256912087,ARL,,13.26,100,1,13.04,2,1,13.03,100,1,12.73,100,1,12.71,100,1,12.5,700,1,12.46,200,1,12.43,700,1,12.42,700,1,12.37,700,1,13.83,15,1,13.84,100,1,13.87,15,1,14.07,2,1,14.17,100,1,14.28,100,1,14.4,100,1,14.56,800,1,14.6,700,1,14.64,100,1,2,303331429
2025-07-17T15:47:31.574128504Z,2025-07-17T15:47:31.573963059Z,160,2,1108,A,A,15.920000000,100,0,306652001,130,165445,256912087,ARL,,13.26,100,1,13.04,2,1,13.03,100,1,12.73,100,1,12.71,100,1,12.5,700,1,12.46,200,1,12.43,700,1,12.42,700,1,12.37,700,1,13.83,15,1,13.84,100,1,13.87,15,1,14.07,2,1,14.17,100,1,14.28,100,1,14.4,100,1,14.56,800,1,14.6,700,1,14.64,100,1,2,306652001
2025-07-17T15:47:31.575374481Z,2025-07-17T15:47:31.575209032Z,160,2,1108,C,A,17.760000000,100,0,303331309,0,165449,256912094,ARL,,13.26,100,1,13.04,2,1,13.03,100,1,12.73,100,1,12.71,100,1,12.5,700,1,12.46,200,1,12.43,700,1,12.42,700,1,12.37,700,1,13.83,15,1,13.84,100,1,13.87,15,1,14.07,2,1,14.17,100,1,14.28,100,1,14.4,100,1,14.56,800,1,14.6,700,1,14.64,100,1,2,303331309
2025-07-17T15:47:31.575374481Z,2025-07-17T15:47:31.575209032Z,160,2,1108,A,A,17.580000000,100,0,306652017,130,165449,256912094,ARL,,13.26,100,1,13.04,2,1,13.03,100,1,12.73,100,1,12.71,100,1,12.5,700,1,12.46,200,1,12.43,700,1,12.42,700,1,12.37,700,1,13.83,15,1,13.84,100,1,13.87,15,1,14.07,2,1,14.17,100,1,14.28,100,1,14.4,100,1,14.56,800,1,14.6,700,1,14.64,100,1,2,306652017
2025-07-17T15:47:31.740095714Z,2025-07-17T15:47:31.739930142Z,160,2,1108,C,A,14.960000000,100,0,303334253,0,165572,256914067,ARL,,13.26,100,1,13.04,2,1,13.03,100,1,12.73,100,1,12.71,100,1,12.5,700,1,12.46,200,1,12.43,700,1,12.42,700,1,12.37,700,1,13.83,15,1,13.84,100,1,13.87,15,1,14.07,2,1,14.17,100,1,14.28,100,1,14.4,100,1,14.56,800,1,14.6,700,1,14.64,100,1,2,303334253
2025-07-17T15:47:31.740095714Z,2025-07-17T15:47:31.739930142Z,160,2,1108,A,A,14.810000000,100,0,306653713,130,165572,256914067,ARL,,13.26,100,1,13.04,2,1,13.03,100,1,12.73,100,1,12.71,100,1,12.5,700,1,12.46,200,1,12.43,700,1,12.42,700,1,12.37,700,1,13.83,15,1,13.84,100,1,13.87,15,1,14.07,2,1,14.17,100,1,14.28,100,1,14.4,100,1,14.56,800,1,14.6,700,1,14.64,100,1,2,306653713
2025-07-17T15:47:37.159589804Z,2025-07-17T15:47:37.159424166Z,160,2,1108,C,A,13.870000000,15,0,306519385,130,165638,256983942,ARL,,13.26,100,1,13.04,2,1,13.03,100,1,12.73,100,1,12.71,100,1,12.5,700,1,12.46,200,1,12.43,700,1,12.42,700,1,12.37,700,1,13.83,15,1,13.84,100,1,14.07,2,1,14.17,100,1,14.28,100,1,14.4,100,1,14.56,800,1,14.6,700,1,14.64,100,1,14.68,1400,1,2,306519385
2025-07-17T15:47:37.172000440Z,2025-07-17T15:47:37.171834941Z,160,2,1108,A,A,13.850000000,100,0,306749753,130,165499,256984053,ARL,,13.26,100,1,13.04,2,1,13.03,100,1,12.73,100,1,12.71,100,1,12.5,700,1,12.46,200,1,12.43,700,1,12.42,700,1,12.37,700,1,13.83,15,1,13.84,100,1,13.85,100,1,14.07,2,1,14.17,100,1,14.28,100,1,14.4,100,1,14.56,800,1,14.6,700,1,14.64,100,1,2,306749753
2025-07-17T15:47:38.161181283Z,2025-07-17T15:47:38.161015969Z,160,2,1108,A,A,13.790000000,15,0,306770041,130,165314,256998606,ARL,,13.26,100,1,13.04,2,1,13.03,100,1,12.73,100,1,12.71,100,1,12.5,700,1,12.46,200,1,12.43,700,1,12.42,700,1,12.37,700,1,13.79,15,1,13.83,15,1,13.84,100,1,13.85,100,1,14.07,2,1,14.17,100,1,14.28,100,1,14.4,100,1,14.56,800,1,14.6,700,1,2,306770041
2025-07-17T15:47:38.794962245Z,2025-07-17T15:47:38.794795887Z,160,2,1108,C,A,13.840000000,100,0,306647425,0,166358,257010989,ARL,,13.26,100,1,13.04,2,1,13.03,100,1,12.73,100,1,12.71,100,1,12.5,700,1,12.46,200,1,12.43,700,1,12.42,700,1,12.37,700,1,13.79,15,1,13.83,15,1,13.85,100,1,14.07,2,1,14.17,100,1,14.28,100,1,14.4,100,1,14.56,800,1,14.6,700,1,14.64,100,1,2,306647425
2025-07-17T15:47:38.794962245Z,2025-07-17T15:47:38.794795887Z,160,2,1108,A,A,13.800000000,100,0,306784133,128,166358,257010989,ARL,,13.26,100,1,13.04,2,1,13.03,100,1,12.73,100,1,12.71,100,1,12.5,700,1,12.46,200,1,12.43,700,1,12.42,700,1,12.37,700,1,13.79,15,1,13.8,100,1,13.83,15,1,13.85,100,1,14.07,2,1,14.17,100,1,14.28,100,1,14.4,100,1,14.56,800,1,14.6,700,1,2,306784133
2025-07-17T15:47:38.795723570Z,2025-07-17T15:47:38.795557785Z,160,2,1108,C,A,14.910000000,100,0,306647445,0,165785,257011058,ARL,,13.26,100,1,13.04,2,1,13.03,100,1,12.73,100,1,12.71,100,1,12.5,700,1,12.46,200,1,12.43,700,1,12.42,700,1,12.37,700,1,13.79,15,1,13.8,100,1,13.83,15,1,13.85,100,1,14.07,2,1,14.17,100,1,14.28,100,1,14.4,100,1,14.56,800,1,14.6,700,1,2,306647445
2025-07-17T15:47:38.795723570Z,2025-07-17T15:47:38.795557785Z,160,2,1108,A,A,14.870000000,100,0,306784201,130,165785,257011058,ARL,,13.26,100,1,13.04,2,1,13.03,100,1,12.73,100,1,12.71,100,1,12.5,700,1,12.46,200,1,12.43,700,1,12.42,700,1,12.37,700,1,13.79,15,1,13.8,100,1,13.83,15,1,13.85,100,1,14.07,2,1,14.17,100,1,14.28,100,1,14.4,100,1,14.56,800,1,14.6,700,1,2,306784201
2025-07-17T15:47:38.804624258Z,2025-07-17T15:47:38.804458744Z,160,2,1108,C,A,14.170000000,100,0,306171457,130,165514,257011716,ARL,,13.26,100,1,13.04,2,1,13.03,100,1,12.73,100,1,12.71,100,1,12.5,700,1,12.46,200,1,12.43,700,1,12.42,700,1,12.37,700,1,13.79,15,1,13.8,100,1,13.83,15,1,13.85,100,1,14.07,2,1,14.28,100,1,14.4,100,1,14.56,800,1,14.6,700,1,14.64,100,1,2,306171457
2025-07-17T15:47:38.804679592Z,2025-07-17T15:47:38.804513793Z,160,2,1108,A,A,14.080000000,100,0,306784853,130,165799,257011717,ARL,,13.26,100,1,13.04,2,1,13.03,100,1,12.73,100,1,12.71,100,1,12.5,700,1,12.46,200,1,12.43,700,1,12.42,700,1,12.37,700,1,13.79,15,1,13.8,100,1,13.83,15,1,13.85,100,1,14.07,2,1,14.08,100,1,14.28,100,1,14.4,100,1,14.56,800,1,14.6,700,1,2,306784853
2025-07-17T15:47:39.092472059Z,2025-07-17T15:47:39.092305947Z,160,2,1108,C,A,13.790000000,15,0,306770041,130,166112,257018687,ARL,,13.26,100,1,13.04,2,1,13.03,100,1,12.73,100,1,12.71,100,1,12.5,700,1,12.46,200,1,12.43,700,1,12.42,700,1,12.37,700,1,13.8,100,1,13.83,15,1,13.85,100,1,14.07,2,1,14.08,100,1,14.28,100,1,14.4,100,1,14.56,800,1,14.6,700,1,14.64,100,1,2,306770041
2025-07-17T15:47:39.095920859Z,2025-07-17T15:47:39.095755335Z,160,2,1108,C,A,13.830000000,15,0,306587393,130,165524,257018796,ARL,,13.26,100,1,13.04,2,1,13.03,100,1,12.73,100,1,12.71,100,1,12.5,700,1,12.46,200,1,12.43,700,1,12.42,700,1,12.37,700,1,13.8,100,1,13.85,100,1,14.07,2,1,14.08,100,1,14.28,100,1,14.4,100,1,14.56,800,1,14.6,700,1,14.64,100,1,14.68,1400,1,2,306587393
2025-07-17T15:48:08.909366905Z,2025-07-17T15:48:08.909201576Z,160,2,1108,A,A,13.830000000,100,0,307567929,130,165329,257603755,ARL,,13.26,100,1,13.04,2,1,13.03,100,1,12.73,100,1,12.71,100,1,12.5,700,1,12.46,200,1,12.43,700,1,12.42,700,1,12.37,700,1,13.8,100,1,13.83,100,1,13.85,100,1,14.07,2,1,14.08,100,1,14.28,100,1,14.4,100,1,14.56,800,1,14.6,700,1,14.64,100,1,2,307567929
2025-07-17T15:48:08.916721098Z,2025-07-17T15:48:08.916555821Z,160,2,1108,C,A,13.850000000,100,0,306749753,130,165277,257604057,ARL,,13.26,100,1,13.04,2,1,13.03,100,1,12.73,100,1,12.71,100,1,12.5,700,1,12.46,200,1,12.43,700,1,12.42,700,1,12.37,700,1,13.8,100,1,13.83,100,1,14.07,2,1,14.08,100,1,14.28,100,1,14.4,100,1,14.56,800,1,14.6,700,1,14.64,100,1,14.68,1400,1,2,306749753
2025-07-17T15:48:09.653473465Z,2025-07-17T15:48:09.653308042Z,160,2,1108,A,A,13.780000000,15,0,307587873,130,165423,257621095,ARL,,13.26,100,1,13.04,2,1,13.03,100,1,12.73,100,1,12.71,100,1,12.5,700,1,12.46,200,1,12.43,700,1,12.42,700,1,12.37,700,1,13.78,15,1,13.8,100,1,13.83,100,1,14.07,2,1,14.08,100,1,14.28,100,1,14.4,100,1,14.56,800,1,14.6,700,1,14.64,100,1,2,307587873
2025-07-17T15:48:11.166689254Z,2025-07-17T15:48:11.166517494Z,160,2,1108,C,A,13.780000000,15,0,307587873,128,171760,257644020,ARL,,13.26,100,1,13.04,2,1,13.03,100,1,12.73,100,1,12.71,100,1,12.5,700,1,12.46,200,1,12.43,700,1,12.42,700,1,12.37,700,1,13.8,100,1,13.83,100,1,14.07,2,1,14.08,100,1,14.28,100,1,14.4,100,1,14.56,800,1,14.6,700,1,14.64,100,1,14.68,1400,1,2,307587873
2025-07-17T15:48:13.509078553Z,2025-07-17T15:48:13.508913083Z,160,2,1108,A,A,13.780000000,15,0,307714769,130,165470,257727039,ARL,,13.26,100,1,13.04,2,1,13.03,100,1,12.73,100,1,12.71,100,1,12.5,700,1,12.46,200,1,12.43,700,1,12.42,700,1,12.37,700,1,13.78,15,1,13.8,100,1,13.83,100,1,14.07,2,1,14.08,100,1,14.28,100,1,14.4,100,1,14.56,800,1,14.6,700,1,14.64,100,1,2,307714769
2025-07-17T15:48:13.525953545Z,2025-07-17T15:48:13.525788139Z,160,2,1108,A,A,13.810000000,100,0,307715101,130,165406,257727301,ARL,,13.26,100,1,13.04,2,1,13.03,100,1,12.73,100,1,12.71,100,1,12.5,700,1,12.46,200,1,12.43,700,1,12.42,700,1,12.37,700,1,13.78,15,1,13.8,100,1,13.81,100,1,13.83,100,1,14.07,2,1,14.08,100,1,14.28,100,1,14.4,100,1,14.56,800,1,14.6,700,1,2,307715101
2025-07-17T15:48:13.532608874Z,2025-07-17T15:48:13.532443045Z,160,2,1108,C,A,13.830000000,100,0,307567929,130,165829,257727457,ARL,,13.26,100,1,13.04,2,1,13.03,100,1,12.73,100,1,12.71,100,1,12.5,700,1,12.46,200,1,12.43,700,1,12.42,700,1,12.37,700,1,13.78,15,1,13.8,100,1,13.81,100,1,14.07,2,1,14.08,100,1,14.28,100,1,14.4,100,1,14.56,800,1,14.6,700,1,14.64,100,1,2,307567929
2025-07-17T15:48:15.568544154Z,2025-07-17T15:48:15.568378275Z,160,2,1108,C,A,13.800000000,100,0,306784133,0,165879,257757458,ARL,,13.26,100,1,13.04,2,1,13.03,100,1,12.73,100,1,12.71,100,1,12.5,700,1,12.46,200,1,12.43,700,1,12.42,700,1,12.37,700,1,13.78,15,1,13.81,100,1,14.07,2,1,14.08,100,1,14.28,100,1,14.4,100,1,14.56,800,1,14.6,700,1,14.64,100,1,14.68,1400,1,2,306784133
2025-07-17T15:48:15.568544154Z,2025-07-17T15:48:15.568378275Z,160,2,1108,A,A,13.790000000,100,0,307753241,130,165879,257757458,ARL,,13.26,100,1,13.04,2,1,13.03,100,1,12.73,100,1,12.71,100,1,12.5,700,1,12.46,200,1,12.43,700,1,12.42,700,1,12.37,700,1,13.78,15,1,13.79,100,1,13.81,100,1,14.07,2,1,14.08,100,1,14.28,100,1,14.4,100,1,14.56,800,1,14.6,700,1,14.64,100,1,2,307753241
2025-07-17T15:48:24.009355346Z,2025-07-17T15:48:24.009190157Z,160,2,1108,A,A,13.750000000,15,0,307964605,130,165189,257928318,ARL,,13.26,100,1,13.04,2,1,13.03,100,1,12.73,100,1,12.71,100,1,12.5,700,1,12.46,200,1,12.43,700,1,12.42,700,1,12.37,700,1,13.75,15,1,13.78,15,1,13.79,100,1,13.81,100,1,14.07,2,1,14.08,100,1,14.28,100,1,14.4,100,1,14.56,800,1,14.6,700,1,2,307964605
2025-07-17T15:48:24.009522633Z,2025-07-17T15:48:24.009357442Z,160,2,1108,A,A,13.790000000,100,0,307964609,130,165191,257928319,ARL,,13.26,100,1,13.04,2,1,13.03,100,1,12.73,100,1,12.71,100,1,12.5,700,1,12.46,200,1,12.43,700,1,12.42,700,1,12.37,700,1,13.75,15,1,13.78,15,1,13.79,200,1,13.81,100,1,14.07,2,1,14.08,100,1,14.28,100,1,14.4,100,1,14.56,800,1,14.6,700,1,2,307964609
2025-07-17T15:48:24.009944381Z,2025-07-17T15:48:24.009778967Z,160,2,1108,C,A,13.790000000,100,0,307753241,0,165414,257928325,ARL,,13.26,100,1,13.04,2,1,13.03,100,1,12.73,100,1,12.71,100,1,12.5,700,1,12.46,200,1,12.43,700,1,12.42,700,1,12.37,700,1,13.75,15,1,13.78,15,1,13.79,100,1,13.81,100,1,14.07,2,1,14.08,100,1,14.28,100,1,14.4,100,1,14.56,800,1,14.6,700,1,2,307753241
2025-07-17T15:48:24.009944381Z,2025-07-17T15:48:24.009778967Z,160,2,1108,A,A,13.760000000,100,0,307964621,130,165414,257928325,ARL,,13.26,100,1,13.04,2,1,13.03,100,1,12.73,100,1,12.71,100,1,12.5,700,1,12.46,200,1,12.43,700,1,12.42,700,1,12.37,700,1,13.75,15,1,13.76,100,1,13.78,15,1,13.79,100,1,13.81,100,1,14.07,2,1,14.08,100,1,14.28,100,1,14.4,100,1,14.56,800,1,2,307964621
2025-07-17T15:48:24.009974166Z,2025-07-17T15:48:24.009808793Z,160,2,1108,C,A,13.810000000,100,0,307715101,130,165373,257928326,ARL,,13.26,100,1,13.04,2,1,13.03,100,1,12.73,100,1,12.71,100,1,12.5,700,1,12.46,200,1,12.43,700,1,12.42,700,1,12.37,700,1,13.75,15,1,13.76,100,1,13.78,15,1,13.79,100,1,14.07,2,1,14.08,100,1,14.28,100,1,14.4,100,1,14.56,800,1,14.6,700,1,2,307715101
2025-07-17T15:48:24.010555416Z,2025-07-17T15:48:24.010390029Z,160,2,1108,C,A,14.770000000,100,0,306519409,0,165387,257928333,ARL,,13.26,100,1,13.04,2,1,13.03,100,1,12.73,100,1,12.71,100,1,12.5,700,1,12.46,200,1,12.43,700,1,12.42,700,1,12.37,700,1,13.75,15,1,13.76,100,1,13.78,15,1,13.79,100,1,14.07,2,1,14.08,100,1,14.28,100,1,14.4,100,1,14.56,800,1,14.6,700,1,2,306519409
2025-07-17T15:48:24.010555416Z,2025-07-17T15:48:24.010390029Z,160,2,1108,A,A,14.650000000,100,0,307964661,130,165387,257928333,ARL,,13.26,100,1,13.04,2,1,13.03,100,1,12.73,100,1,12.71,100,1,12.5,700,1,12.46,200,1,12.43,700,1,12.42,700,1,12.37,700,1,13.75,15,1,13.76,100,1,13.78,15,1,13.79,100,1,14.07,2,1,14.08,100,1,14.28,100,1,14.4,100,1,14.56,800,1,14.6,700,1,2,307964661
2025-07-17T15:48:24.010677522Z,2025-07-17T15:48:24.010512050Z,160,2,1108,C,A,14.870000000,100,0,306784201,0,165472,257928340,ARL,,13.26,100,1,13.04,2,1,13.03,100,1,12.73,100,1,12.71,100,1,12.5,700,1,12.46,200,1,12.43,700,1,12.42,700,1,12.37,700,1,13.75,15,1,13.76,100,1,13.78,15,1,13.79,100,1,14.07,2,1,14.08,100,1,14.28,100,1,14.4,100,1,14.56,800,1,14.6,700,1,2,306784201
2025-07-17T15:48:24.010677522Z,2025-07-17T15:48:24.010512050Z,160,2,1108,A,A,14.830000000,100,0,307964665,130,165472,257928340,ARL,,13.26,100,1,13.04,2,1,13.03,100,1,12.73,100,1,12.71,100,1,12.5,700,1,12.46,200,1,12.43,700,1,12.42,700,1,12.37,700,1,13.75,15,1,13.76,100,1,13.78,15,1,13.79,100,1,14.07,2,1,14.08,100,1,14.28,100,1,14.4,100,1,14.56,800,1,14.6,700,1,2,307964665
2025-07-17T15:48:42.009954046Z,2025-07-17T15:48:42.009788565Z,160,2,1108,C,A,13.780000000,15,0,307714769,130,165481,258199397,ARL,,13.26,100,1,13.04,2,1,13.03,100,1,12.73,100,1,12.71,100,1,12.5,700,1,12.46,200,1,12.43,700,1,12.42,700,1,12.37,700,1,13.75,15,1,13.76,100,1,13.79,100,1,14.07,2,1,14.08,100,1,14.28,100,1,14.4,100,1,14.56,800,1,14.6,700,1,14.64,100,1,2,307714769
2025-07-17T15:48:42.011846392Z,2025-07-17T15:48:42.011680742Z,160,2,1108,C,A,14.750000000,100,0,306519741,0,165650,258199535,ARL,,13.26,100,1,13.04,2,1,13.03,100,1,12.73,100,1,12.71,100,1,12.5,700,1,12.46,200,1,12.43,700,1,12.42,700,1,12.37,700,1,13.75,15,1,13.76,100,1,13.79,100,1,14.07,2,1,14.08,100,1,14.28,100,1,14.4,100,1,14.56,800,1,14.6,700,1,14.64,100,1,2,306519741
2025-07-17T15:48:42.011846392Z,2025-07-17T15:48:42.011680742Z,160,2,1108,A,A,14.640000000,100,0,308296381,130,165650,258199535,ARL,,13.26,100,1,13.04,2,1,13.03,100,1,12.73,100,1,12.71,100,1,12.5,700,1,12.46,200,1,12.43,700,1,12.42,700,1,12.37,700,1,13.75,15,1,13.76,100,1,13.79,100,1,14.07,2,1,14.08,100,1,14.28,100,1,14.4,100,1,14.56,800,1,14.6,700,1,14.64,200,1,2,308296381
2025-07-17T15:48:42.016761374Z,2025-07-17T15:48:42.016595806Z,160,2,1108,A,A,13.770000000,100,0,308296741,130,165568,258199787,ARL,,13.26,100,1,13.04,2,1,13.03,100,1,12.73,100,1,12.71,100,1,12.5,700,1,12.46,200,1,12.43,700,1,12.42,700,1,12.37,700,1,13.75,15,1,13.76,100,1,13.77,100,1,13.79,100,1,14.07,2,1,14.08,100,1,14.28,100,1,14.4,100,1,14.56,800,1,14.6,700,1,2,308296741
2025-07-17T15:48:42.023432407Z,2025-07-17T15:48:42.023266760Z,160,2,1108,C,A,13.790000000,100,0,307964609,130,165647,258199990,ARL,,13.26,100,1,13.04,2,1,13.03,100,1,12.73,100,1,12.71,100,1,12.5,700,1,12.46,200,1,12.43,700,1,12.42,700,1,12.37,700,1,13.75,15,1,13.76,100,1,13.77,100,1,14.07,2,1,14.08,100,1,14.28,100,1,14.4,100,1,14.56,800,1,14.6,700,1,14.64,200,1,2,307964609
2025-07-17T15:48:46.750088490Z,2025-07-17T15:48:46.749922127Z,160,2,1108,A,A,13.730000000,15,0,308374537,128,166363,258260871,ARL,,13.26,100,1,13.04,2,1,13.03,100,1,12.73,100,1,12.71,100,1,12.5,700,1,12.46,200,1,12.43,700,1,12.42,700,1,12.37,700,1,13.73,15,1,13.75,15,1,13.76,100,1,13.77,100,1,14.07,2,1,14.08,100,1,14.28,100,1,14.4,100,1,14.56,800,1,14.6,700,1,2,308374537
2025-07-17T15:48:46.758551033Z,2025-07-17T15:48:46.758385367Z,160,2,1108,C,A,13.760000000,100,0,307964621,0,165666,258261154,ARL,,13.26,100,1,13.04,2,1,13.03,100,1,12.73,100,1,12.71,100,1,12.5,700,1,12.46,200,1,12.43,700,1,12.42,700,1,12.37,700,1,13.73,15,1,13.75,15,1,13.77,100,1,14.07,2,1,14.08,100,1,14.28,100,1,14.4,100,1,14.56,800,1,14.6,700,1,14.64,200,1,2,307964621
2025-07-17T15:48:46.758551033Z,2025-07-17T15:48:46.758385367Z,160,2,1108,A,A,13.740000000,100,0,308374881,130,165666,258261154,ARL,,13.26,100,1,13.04,2,1,13.03,100,1,12.73,100,1,12.71,100,1,12.5,700,1,12.46,200,1,12.43,700,1,12.42,700,1,12.37,700,1,13.73,15,1,13.74,100,1,13.75,15,1,13.77,100,1,14.07,2,1,14.08,100,1,14.28,100,1,14.4,100,1,14.56,800,1,14.6,700,1,2,308374881
2025-07-17T15:48:46.773668988Z,2025-07-17T15:48:46.773503306Z,160,2,1108,C,A,14.080000000,100,0,306784853,130,165682,258261538,ARL,,13.26,100,1,13.04,2,1,13.03,100,1,12.73,100,1,12.71,100,1,12.5,700,1,12.46,200,1,12.43,700,1,12.42,700,1,12.37,700,1,13.73,15,1,13.74,100,1,13.75,15,1,13.77,100,1,14.07,2,1,14.28,100,1,14.4,100,1,14.56,800,1,14.6,700,1,14.64,200,1,2,306784853
2025-07-17T15:48:46.773720726Z,2025-07-17T15:48:46.773555566Z,160,2,1108,A,A,14.010000000,100,0,308375185,130,165160,258261539,ARL,,13.26,100,1,13.04,2,1,13.03,100,1,12.73,100,1,12.71,100,1,12.5,700,1,12.46,200,1,12.43,700,1,12.42,700,1,12.37,700,1,13.73,15,1,13.74,100,1,13.75,15,1,13.77,100,1,14.01,100,1,14.07,2,1,14.28,100,1,14.4,100,1,14.56,800,1,14.6,700,1,2,308375185
2025-07-17T15:49:02.010494480Z,2025-07-17T15:49:02.010329052Z,160,2,1108,A,A,13.750000000,100,0,308705489,130,165428,258502869,ARL,,13.26,100,1,13.04,2,1,13.03,100,1,12.73,100,1,12.71,100,1,12.5,700,1,12.46,200,1,12.43,700,1,12.42,700,1,12.37,700,1,13.73,15,1,13.74,100,1,13.75,115,1,13.77,100,1,14.01,100,1,14.07,2,1,14.28,100,1,14.4,100,1,14.56,800,1,14.6,700,1,2,308705489
2025-07-17T15:49:02.019989567Z,2025-07-17T15:49:02.019824230Z,160,2,1108,C,A,13.770000000,100,0,308296741,130,165337,258502929,ARL,,13.26,100,1,13.04,2,1,13.03,100,1,12.73,100,1,12.71,100,1,12.5,700,1,12.46,200,1,12.43,700,1,12.42,700,1,12.37,700,1,13.73,15,1,13.74,100,1,13.75,115,1,14.01,100,1,14.07,2,1,14.28,100,1,14.4,100,1,14.56,800,1,14.6,700,1,14.64,200,1,2,308296741
2025-07-17T15:49:03.406005590Z,2025-07-17T15:49:03.405840358Z,160,2,1108,C,A,13.750000000,15,0,307964605,130,165232,258527308,ARL,,13.26,100,1,13.04,2,1,13.03,100,1,12.73,100,1,12.71,100,1,12.5,700,1,12.46,200,1,12.43,700,1,12.42,700,1,12.37,700,1,13.73,15,1,13.74,100,1,13.75,100,1,14.01,100,1,14.07,2,1,14.28,100,1,14.4,100,1,14.56,800,1,14.6,700,1,14.64,200,1,2,307964605
2025-07-17T15:49:04.713997925Z,2025-07-17T15:49:04.713831675Z,160,2,1108,A,A,13.710000000,15,0,308763065,128,166250,258547335,ARL,,13.26,100,1,13.04,2,1,13.03,100,1,12.73,100,1,12.71,100,1,12.5,700,1,12.46,200,1,12.43,700,1,12.42,700,1,12.37,700,1,13.71,15,1,13.73,15,1,13.74,100,1,13.75,100,1,14.01,100,1,14.07,2,1,14.28,100,1,14.4,100,1,14.56,800,1,14.6,700,1,2,308763065
2025-07-17T15:49:06.013111941Z,2025-07-17T15:49:06.012946379Z,160,2,1108,A,A,13.730000000,100,0,308786185,130,165562,258567259,ARL,,13.26,100,1,13.04,2,1,13.03,100,1,12.73,100,1,12.71,100,1,12.5,700,1,12.46,200,1,12.43,700,1,12.42,700,1,12.37,700,1,13.71,15,1,13.73,115,1,13.74,100,1,13.75,100,1,14.01,100,1,14.07,2,1,14.28,100,1,14.4,100,1,14.56,800,1,14.6,700,1,2,308786185
2025-07-17T15:49:06.023292147Z,2025-07-17T15:49:06.023126600Z,160,2,1108,C,A,13.750000000,100,0,308705489,130,165547,258567405,ARL,,13.26,100,1,13.04,2,1,13.03,100,1,12.73,100,1,12.71,100,1,12.5,700,1,12.46,200,1,12.43,700,1,12.42,700,1,12.37,700,1,13.71,15,1,13.73,115,1,13.74,100,1,14.01,100,1,14.07,2,1,14.28,100,1,14.4,100,1,14.56,800,1,14.6,700,1,14.64,200,1,2,308705489
2025-07-17T15:49:06.344356890Z,2025-07-17T15:49:06.344191321Z,160,2,1108,C,A,13.740000000,100,0,308374881,0,165569,258574949,ARL,,13.26,100,1,13.04,2,1,13.03,100,1,12.73,100,1,12.71,100,1,12.5,700,1,12.46,200,1,12.43,700,1,12.42,700,1,12.37,700,1,13.71,15,1,13.73,115,1,14.01,100,1,14.07,2,1,14.28,100,1,14.4,100,1,14.56,800,1,14.6,700,1,14.64,200,1,14.65,100,1,2,308374881
2025-07-17T15:49:06.344356890Z,2025-07-17T15:49:06.344191321Z,160,2,1108,A,A,13.720000000,100,0,308797069,130,165569,258574949,ARL,,13.26,100,1,13.04,2,1,13.03,100,1,12.73,100,1,12.71,100,1,12.5,700,1,12.46,200,1,12.43,700,1,12.42,700,1,12.37,700,1,13.71,15,1,13.72,100,1,13.73,115,1,14.01,100,1,14.07,2,1,14.28,100,1,14.4,100,1,14.56,800,1,14.6,700,1,14.64,200,1,2,308797069
2025-07-17T15:49:06.345104491Z,2025-07-17T15:49:06.344938975Z,160,2,1108,C,A,14.830000000,100,0,307964665,0,165516,258575013,ARL,,13.26,100,1,13.04,2,1,13.03,100,1,12.73,100,1,12.71,100,1,12.5,700,1,12.46,200,1,12.43,700,1,12.42,700,1,12.37,700,1,13.71,15,1,13.72,100,1,13.73,115,1,14.01,100,1,14.07,2,1,14.28,100,1,14.4,100,1,14.56,800,1,14.6,700,1,14.64,200,1,2,307964665
2025-07-17T15:49:06.345104491Z,2025-07-17T15:49:06.344938975Z,160,2,1108,A,A,14.780000000,100,0,308797245,130,165516,258575013,ARL,,13.26,100,1,13.04,2,1,13.03,100,1,12.73,100,1,12.71,100,1,12.5,700,1,12.46,200,1,12.43,700,1,12.42,700,1,12.37,700,1,13.71,15,1,13.72,100,1,13.73,115,1,14.01,100,1,14.07,2,1,14.28,100,1,14.4,100,1,14.56,800,1,14.6,700,1,14.64,200,1,2,308797245
2025-07-17T15:49:06.362945410Z,2025-07-17T15:49:06.362779870Z,160,2,1108,C,A,17.580000000,100,0,306652017,0,165540,258575963,ARL,,13.26,100,1,13.04,2,1,13.03,100,1,12.73,100,1,12.71,100,1,12.5,700,1,12.46,200,1,12.43,700,1,12.42,700,1,12.37,700,1,13.71,15,1,13.72,100,1,13.73,115,1,14.01,100,1,14.07,2,1,14.28,100,1,14.4,100,1,14.56,800,1,14.6,700,1,14.64,200,1,2,306652017
2025-07-17T15:49:06.362945410Z,2025-07-17T15:49:06.362779870Z,160,2,1108,A,A,17.430000000,100,0,308799373,130,165540,258575963,ARL,,13.26,100,1,13.04,2,1,13.03,100,1,12.73,100,1,12.71,100,1,12.5,700,1,12.46,200,1,12.43,700,1,12.42,700,1,12.37,700,1,13.71,15,1,13.72,100,1,13.73,115,1,14.01,100,1,14.07,2,1,14.28,100,1,14.4,100,1,14.56,800,1,14.6,700,1,14.64,200,1,2,308799373
2025-07-17T15:49:10.459317885Z,2025-07-17T15:49:10.459152457Z,160,2,1108,C,A,13.730000000,15,0,308374537,130,165428,258636400,ARL,,13.26,100,1,13.04,2,1,13.03,100,1,12.73,100,1,12.71,100,1,12.5,700,1,12.46,200,1,12.43,700,1,12.42,700,1,12.37,700,1,13.71,15,1,13.72,100,1,13.73,100,1,14.01,100,1,14.07,2,1,14.28,100,1,14.4,100,1,14.56,800,1,14.6,700,1,14.64,200,1,2,308374537
2025-07-17T15:49:11.460597600Z,2025-07-17T15:49:11.460432218Z,160,2,1108,A,A,13.690000000,15,0,308893737,130,165382,258650544,ARL,,13.26,100,1,13.04,2,1,13.03,100,1,12.73,100,1,12.71,100,1,12.5,700,1,12.46,200,1,12.43,700,1,12.42,700,1,12.37,700,1,13.69,15,1,13.71,15,1,13.72,100,1,13.73,100,1,14.01,100,1,14.07,2,1,14.28,100,1,14.4,100,1,14.56,800,1,14.6,700,1,2,308893737
2025-07-17T15:49:11.891643099Z,2025-07-17T15:49:11.891477604Z,160,2,1108,C,A,13.720000000,100,0,308797069,0,165495,258658721,ARL,,13.26,100,1,13.04,2,1,13.03,100,1,12.73,100,1,12.71,100,1,12.5,700,1,12.46,200,1,12.43,700,1,12.42,700,1,12.37,700,1,13.69,15,1,13.71,15,1,13.73,100,1,14.01,100,1,14.07,2,1,14.28,100,1,14.4,100,1,14.56,800,1,14.6,700,1,14.64,200,1,2,308797069
2025-07-17T15:49:11.891643099Z,2025-07-17T15:49:11.891477604Z,160,2,1108,A,A,13.700000000,100,0,308901793,130,165495,258658721,ARL,,13.26,100,1,13.04,2,1,13.03,100,1,12.73,100,1,12.71,100,1,12.5,700,1,12.46,200,1,12.43,700,1,12.42,700,1,12.37,700,1,13.69,15,1,13.7,100,1,13.71,15,1,13.73,100,1,14.01,100,1,14.07,2,1,14.28,100,1,14.4,100,1,14.56,800,1,14.6,700,1,2,308901793
2025-07-17T15:49:11.893989071Z,2025-07-17T15:49:11.893823458Z,160,2,1108,C,A,14.810000000,100,0,306649913,0,165613,258658835,ARL,,13.26,100,1,13.04,2,1,13.03,100,1,12.73,100,1,12.71,100,1,12.5,700,1,12.46,200,1,12.43,700,1,12.42,700,1,12.37,700,1,13.69,15,1,13.7,100,1,13.71,15,1,13.73,100,1,14.01,100,1,14.07,2,1,14.28,100,1,14.4,100,1,14.56,800,1,14.6,700,1,2,306649913
2025-07-17T15:49:11.893989071Z,2025-07-17T15:49:11.893823458Z,160,2,1108,A,A,14.660000000,100,0,308901981,130,165613,258658835,ARL,,13.26,100,1,13.04,2,1,13.03,100,1,12.73,100,1,12.71,100,1,12.5,700,1,12.46,200,1,12.43,700,1,12.42,700,1,12.37,700,1,13.69,15,1,13.7,100,1,13.71,15,1,13.73,100,1,14.01,100,1,14.07,2,1,14.28,100,1,14.4,100,1,14.56,800,1,14.6,700,1,2,308901981
2025-07-17T15:49:11.904231149Z,2025-07-17T15:49:11.904065674Z,160,2,1108,C,A,15.920000000,100,0,306652001,0,165475,258659039,ARL,,13.26,100,1,13.04,2,1,13.03,100,1,12.73,100,1,12.71,100,1,12.5,700,1,12.46,200,1,12.43,700,1,12.42,700,1,12.37,700,1,13.69,15,1,13.7,100,1,13.71,15,1,13.73,100,1,14.01,100,1,14.07,2,1,14.28,100,1,14.4,100,1,14.56,800,1,14.6,700,1,2,306652001
2025-07-17T15:49:11.904231149Z,2025-07-17T15:49:11.904065674Z,160,2,1108,A,A,15.760000000,100,0,308902229,130,165475,258659039,ARL,,13.26,100,1,13.04,2,1,13.03,100,1,12.73,100,1,12.71,100,1,12.5,700,1,12.46,200,1,12.43,700,1,12.42,700,1,12.37,700,1,13.69,15,1,13.7,100,1,13.71,15,1,13.73,100,1,14.01,100,1,14.07,2,1,14.28,100,1,14.4,100,1,14.56,800,1,14.6,700,1,2,308902229
2025-07-17T15:49:11.935521687Z,2025-07-17T15:49:11.935356090Z,160,2,1108,C,A,14.810000000,100,0,306653713,0,165597,258659320,ARL,,13.26,100,1,13.04,2,1,13.03,100,1,12.73,100,1,12.71,100,1,12.5,700,1,12.46,200,1,12.43,700,1,12.42,700,1,12.37,700,1,13.69,15,1,13.7,100,1,13.71,15,1,13.73,100,1,14.01,100,1,14.07,2,1,14.28,100,1,14.4,100,1,14.56,800,1,14.6,700,1,2,306653713
2025-07-17T15:49:11.935521687Z,2025-07-17T15:49:11.935356090Z,160,2,1108,A,A,14.660000000,100,0,308903001,130,165597,258659320,ARL,,13.26,100,1,13.04,2,1,13.03,100,1,12.73,100,1,12.71,100,1,12.5,700,1,12.46,200,1,12.43,700,1,12.42,700,1,12.37,700,1,13.69,15,1,13.7,100,1,13.71,15,1,13.73,100,1,14.01,100,1,14.07,2,1,14.28,100,1,14.4,100,1,14.56,800,1,14.6,700,1,2,308903001
2025-07-17T15:49:11.948701049Z,2025-07-17T15:49:11.948535655Z,160,2,1108,C,A,14.640000000,100,0,306647521,130,165394,258659496,ARL,,13.26,100,1,13.04,2,1,13.03,100,1,12.73,100,1,12.71,100,1,12.5,700,1,12.46,200,1,12.43,700,1,12.42,700,1,12.37,700,1,13.69,15,1,13.7,100,1,13.71,15,1,13.73,100,1,14.01,100,1,14.07,2,1,14.28,100,1,14.4,100,1,14.56,800,1,14.6,700,1,2,306647521
2025-07-17T15:49:11.948829112Z,2025-07-17T15:49:11.948663655Z,160,2,1108,A,A,14.500000000,100,0,308903349,130,165457,258659499,ARL,,13.26,100,1,13.04,2,1,13.03,100,1,12.73,100,1,12.71,100,1,12.5,700,1,12.46,200,1,12.43,700,1,12.42,700,1,12.37,700,1,13.69,15,1,13.7,100,1,13.71,15,1,13.73,100,1,14.01,100,1,14.07,2,1,14.28,100,1,14.4,100,1,14.5,100,1,14.56,800,1,2,308903349
2025-07-17T15:49:12.221221367Z,2025-07-17T15:49:12.221056085Z,160,2,1108,A,A,13.710000000,100,0,308909249,130,165282,258663292,ARL,,13.26,100,1,13.04,2,1,13.03,100,1,12.73,100,1,12.71,100,1,12.5,700,1,12.46,200,1,12.43,700,1,12.42,700,1,12.37,700,1,13.69,15,1,13.7,100,1,13.71,115,1,13.73,100,1,14.01,100,1,14.07,2,1,14.28,100,1,14.4,100,1,14.5,100,1,14.56,800,1,2,308909249
2025-07-17T15:49:12.227986905Z,2025-07-17T15:49:12.227821500Z,160,2,1108,C,A,13.730000000,100,0,308786185,130,165405,258663378,ARL,,13.26,100,1,13.04,2,1,13.03,100,1,12.73,100,1,12.71,100,1,12.5,700,1,12.46,200,1,12.43,700,1,12.42,700,1,12.37,700,1,13.69,15,1,13.7,100,1,13.71,115,1,14.01,100,1,14.07,2,1,14.28,100,1,14.4,100,1,14.5,100,1,14.56,800,1,14.6,700,1,2,308786185
2025-07-17T15:49:14.463229121Z,2025-07-17T15:49:14.463063539Z,160,2,1108,C,A,13.710000000,15,0,308763065,130,165582,258702625,ARL,,13.26,100,1,13.04,2,1,13.03,100,1,12.73,100,1,12.71,100,1,12.5,700,1,12.46,200,1,12.43,700,1,12.42,700,1,12.37,700,1,13.69,15,1,13.7,100,1,13.71,100,1,14.01,100,1,14.07,2,1,14.28,100,1,14.4,100,1,14.5,100,1,14.56,800,1,14.6,700,1,2,308763065
2025-07-17T15:49:15.466365122Z,2025-07-17T15:49:15.466199239Z,160,2,1108,A,A,13.670000000,15,0,308980305,130,165883,258716863,ARL,,13.26,100,1,13.04,2,1,13.03,100,1,12.73,100,1,12.71,100,1,12.5,700,1,12.46,200,1,12.43,700,1,12.42,700,1,12.37,700,1,13.67,15,1,13.69,15,1,13.7,100,1,13.71,100,1,14.01,100,1,14.07,2,1,14.28,100,1,14.4,100,1,14.5,100,1,14.56,800,1,2,308980305
2025-07-17T15:49:16.351024588Z,2025-07-17T15:49:16.350859152Z,160,2,1108,C,A,13.700000000,100,0,308901793,0,165436,258727929,ARL,,13.26,100,1,13.04,2,1,13.03,100,1,12.73,100,1,12.71,100,1,12.5,700,1,12.46,200,1,12.43,700,1,12.42,700,1,12.37,700,1,13.67,15,1,13.69,15,1,13.71,100,1,14.01,100,1,14.07,2,1,14.28,100,1,14.4,100,1,14.5,100,1,14.56,800,1,14.6,700,1,2,308901793
2025-07-17T15:49:16.351024588Z,2025-07-17T15:49:16.350859152Z,160,2,1108,A,A,13.680000000,100,0,308998225,130,165436,258727929,ARL,,13.26,100,1,13.04,2,1,13.03,100,1,12.73,100,1,12.71,100,1,12.5,700,1,12.46,200,1,12.43,700,1,12.42,700,1,12.37,700,1,13.67,15,1,13.68,100,1,13.69,15,1,13.71,100,1,14.01,100,1,14.07,2,1,14.28,100,1,14.4,100,1,14.5,100,1,14.56,800,1,2,308998225
2025-07-17T15:49:16.351759618Z,2025-07-17T15:49:16.351594042Z,160,2,1108,C,A,14.780000000,100,0,308797245,0,165576,258727956,ARL,,13.26,100,1,13.04,2,1,13.03,100,1,12.73,100,1,12.71,100,1,12.5,700,1,12.46,200,1,12.43,700,1,12.42,700,1,12.37,700,1,13.67,15,1,13.68,100,1,13.69,15,1,13.71,100,1,14.01,100,1,14.07,2,1,14.28,100,1,14.4,100,1,14.5,100,1,14.56,800,1,2,308797245
2025-07-17T15:49:16.351759618Z,2025-07-17T15:49:16.351594042Z,160,2,1108,A,A,14.740000000,100,0,308998341,130,165576,258727956,ARL,,13.26,100,1,13.04,2,1,13.03,100,1,12.73,100,1,12.71,100,1,12.5,700,1,12.46,200,1,12.43,700,1,12.42,700,1,12.37,700,1,13.67,15,1,13.68,100,1,13.69,15,1,13.71,100,1,14.01,100,1,14.07,2,1,14.28,100,1,14.4,100,1,14.5,100,1,14.56,800,1,2,308998341
2025-07-17T15:49:16.494111490Z,2025-07-17T15:49:16.493946243Z,160,2,1108,A,A,13.690000000,100,0,309001525,130,165247,258729266,ARL,,13.26,100,1,13.04,2,1,13.03,100,1,12.73,100,1,12.71,100,1,12.5,700,1,12.46,200,1,12.43,700,1,12.42,700,1,12.37,700,1,13.67,15,1,13.68,100,1,13.69,115,1,13.71,100,1,14.01,100,1,14.07,2,1,14.28,100,1,14.4,100,1,14.5,100,1,14.56,800,1,2,309001525
2025-07-17T15:49:16.557924863Z,2025-07-17T15:49:16.557759633Z,160,2,1108,C,A,13.710000000,100,0,308909249,130,165230,258730034,ARL,,13.26,100,1,13.04,2,1,13.03,100,1,12.73,100,1,12.71,100,1,12.5,700,1,12.46,200,1,12.43,700,1,12.42,700,1,12.37,700,1,13.67,15,1,13.68,100,1,13.69,115,1,14.01,100,1,14.07,2,1,14.28,100,1,14.4,100,1,14.5,100,1,14.56,800,1,14.6,700,1,2,308909249
2025-07-17T15:49:21.186150487Z,2025-07-17T15:49:21.185984774Z,160,2,1108,C,A,14.070000000,2,0,296478973,0,165713,258786552,ARL,,13.26,100,1,13.04,2,1,13.03,100,1,12.73,100,1,12.71,100,1,12.5,700,1,12.46,200,1,12.43,700,1,12.42,700,1,12.37,700,1,13.67,15,1,13.68,100,1,13.69,115,1,14.01,100,1,14.28,100,1,14.4,100,1,14.5,100,1,14.56,800,1,14.6,700,1,14.64,100,1,2,296478973
2025-07-17T15:49:21.186150487Z,2025-07-17T15:49:21.185984774Z,160,2,1108,A,A,13.980000000,2,0,309091513,130,165713,258786552,ARL,,13.26,100,1,13.04,2,1,13.03,100,1,12.73,100,1,12.71,100,1,12.5,700,1,12.46,200,1,12.43,700,1,12.42,700,1,12.37,700,1,13.67,15,1,13.68,100,1,13.69,115,1,13.98,2,1,14.01,100,1,14.28,100,1,14.4,100,1,14.5,100,1,14.56,800,1,14.6,700,1,2,309091513
2025-07-17T15:49:24.283152112Z,2025-07-17T15:49:24.282985894Z,160,2,1108,C,A,13.690000000,15,0,308893737,130,166218,258838460,ARL,,13.26,100,1,13.04,2,1,13.03,100,1,12.73,100,1,12.71,100,1,12.5,700,1,12.46,200,1,12.43,700,1,12.42,700,1,12.37,700,1,13.67,15,1,13.68,100,1,13.69,100,1,13.98,2,1,14.01,100,1,14.28,100,1,14.4,100,1,14.5,100,1,14.56,800,1,14.6,700,1,2,308893737
2025-07-17T15:49:34.570197134Z,2025-07-17T15:49:34.570031718Z,160,2,1108,C,A,13.670000000,15,0,308980305,130,165416,258980876,ARL,,13.26,100,1,13.04,2,1,13.03,100,1,12.73,100,1,12.71,100,1,12.5,700,1,12.46,200,1,12.43,700,1,12.42,700,1,12.37,700,1,13.68,100,1,13.69,100,1,13.98,2,1,14.01,100,1,14.28,100,1,14.4,100,1,14.5,100,1,14.56,800,1,14.6,700,1,14.64,100,1,2,308980305
2025-07-17T15:49:34.591512915Z,2025-07-17T15:49:34.591347169Z,160,2,1108,C,A,13.690000000,100,0,309001525,130,165746,258983321,ARL,,13.26,100,1,13.04,2,1,13.03,100,1,12.73,100,1,12.71,100,1,12.5,700,1,12.46,200,1,12.43,700,1,12.42,700,1,12.37,700,1,13.68,100,1,13.98,2,1,14.01,100,1,14.28,100,1,14.4,100,1,14.5,100,1,14.56,800,1,14.6,700,1,14.64,100,1,14.65,100,1,2,309001525
2025-07-17T15:49:38.610017394Z,2025-07-17T15:49:38.609851985Z,160,2,1108,A,A,13.720000000,100,0,309410565,130,165409,259031220,ARL,,13.26,100,1,13.04,2,1,13.03,100,1,12.73,100,1,12.71,100,1,12.5,700,1,12.46,200,1,12.43,700,1,12.42,700,1,12.37,700,1,13.68,100,1,13.72,100,1,13.98,2,1,14.01,100,1,14.28,100,1,14.4,100,1,14.5,100,1,14.56,800,1,14.6,700,1,14.64,100,1,2,309410565
2025-07-17T15:49:38.610073334Z,2025-07-17T15:49:38.609907720Z,160,2,1108,C,B,13.260000000,100,0,291975017,130,165614,259031221,ARL,,13.04,2,1,13.03,100,1,12.73,100,1,12.71,100,1,12.5,700,1,12.46,200,1,12.43,700,1,12.42,700,1,12.37,700,1,12.36,200,1,13.68,100,1,13.72,100,1,13.98,2,1,14.01,100,1,14.28,100,1,14.4,100,1,14.5,100,1,14.56,800,1,14.6,700,1,14.64,100,1,2,291975017
2025-07-17T15:49:39.068515005Z,2025-07-17T15:49:39.068349660Z,160,2,1108,A,B,13.020000000,100,0,309415429,130,165345,259035032,ARL,,13.04,2,1,13.03,100,1,13.02,100,1,12.73,100,1,12.71,100,1,12.5,700,1,12.46,200,1,12.43,700,1,12.42,700,1,12.37,700,1,13.68,100,1,13.72,100,1,13.98,2,1,14.01,100,1,14.28,100,1,14.4,100,1,14.5,100,1,14.56,800,1,14.6,700,1,14.64,100,1,2,309415429
2025-07-17T15:49:44.788414401Z,2025-07-17T15:49:44.788249210Z,160,2,1108,A,A,13.670000000,15,0,309524921,130,165191,259105347,ARL,,13.04,2,1,13.03,100,1,13.02,100,1,12.73,100,1,12.71,100,1,12.5,700,1,12.46,200,1,12.43,700,1,12.42,700,1,12.37,700,1,13.67,15,1,13.68,100,1,13.72,100,1,13.98,2,1,14.01,100,1,14.28,100,1,14.4,100,1,14.5,100,1,14.56,800,1,14.6,700,1,2,309524921
2025-07-17T15:49:44.789020757Z,2025-07-17T15:49:44.788855587Z,160,2,1108,A,A,13.700000000,100,0,309524933,130,165170,259105361,ARL,,13.04,2,1,13.03,100,1,13.02,100,1,12.73,100,1,12.71,100,1,12.5,700,1,12.46,200,1,12.43,700,1,12.42,700,1,12.37,700,1,13.67,15,1,13.68,100,1,13.7,100,1,13.72,100,1,13.98,2,1,14.01,100,1,14.28,100,1,14.4,100,1,14.5,100,1,14.56,800,1,2,309524933
2025-07-17T15:49:44.789702916Z,2025-07-17T15:49:44.789537536Z,160,2,1108,C,A,13.720000000,100,0,309410565,130,165380,259105380,ARL,,13.04,2,1,13.03,100,1,13.02,100,1,12.73,100,1,12.71,100,1,12.5,700,1,12.46,200,1,12.43,700,1,12.42,700,1,12.37,700,1,13.67,15,1,13.68,100,1,13.7,100,1,13.98,2,1,14.01,100,1,14.28,100,1,14.4,100,1,14.5,100,1,14.56,800,1,14.6,700,1,2,309410565
2025-07-17T15:49:54.788658841Z,2025-07-17T15:49:54.788493605Z,160,2,1108,A,A,13.650000000,15,0,309707269,130,165236,259253294,ARL,,13.04,2,1,13.03,100,1,13.02,100,1,12.73,100,1,12.71,100,1,12.5,700,1,12.46,200,1,12.43,700,1,12.42,700,1,12.37,700,1,13.65,15,1,13.67,15,1,13.68,100,1,13.7,100,1,13.98,2,1,14.01,100,1,14.28,100,1,14.4,100,1,14.5,100,1,14.56,800,1,2,309707269
2025-07-17T15:49:54.799535744Z,2025-07-17T15:49:54.799370442Z,160,2,1108,A,A,13.680000000,100,0,309707413,130,165302,259253527,ARL,,13.04,2,1,13.03,100,1,13.02,100,1,12.73,100,1,12.71,100,1,12.5,700,1,12.46,200,1,12.43,700,1,12.42,700,1,12.37,700,1,13.65,15,1,13.67,15,1,13.68,200,1,13.7,100,1,13.98,2,1,14.01,100,1,14.28,100,1,14.4,100,1,14.5,100,1,14.56,800,1,2,309707413
2025-07-17T15:49:54.820634917Z,2025-07-17T15:49:54.820469390Z,160,2,1108,C,A,13.700000000,100,0,309524933,130,165527,259253732,ARL,,13.04,2,1,13.03,100,1,13.02,100,1,12.73,100,1,12.71,100,1,12.5,700,1,12.46,200,1,12.43,700,1,12.42,700,1,12.37,700,1,13.65,15,1,13.67,15,1,13.68,200,1,13.98,2,1,14.01,100,1,14.28,100,1,14.4,100,1,14.5,100,1,14.56,800,1,14.6,700,1,2,309524933
2025-07-17T15:49:59.512104064Z,2025-07-17T15:49:59.511938438Z,160,2,1108,C,A,13.680000000,100,0,308998225,0,165626,259313537,ARL,,13.04,2,1,13.03,100,1,13.02,100,1,12.73,100,1,12.71,100,1,12.5,700,1,12.46,200,1,12.43,700,1,12.42,700,1,12.37,700,1,13.65,15,1,13.67,15,1,13.68,100,1,13.98,2,1,14.01,100,1,14.28,100,1,14.4,100,1,14.5,100,1,14.56,800,1,14.6,700,1,2,308998225
2025-07-17T15:49:59.512104064Z,2025-07-17T15:49:59.511938438Z,160,2,1108,A,A,13.660000000,100,0,309782481,130,165626,259313537,ARL,,13.04,2,1,13.03,100,1,13.02,100,1,12.73,100,1,12.71,100,1,12.5,700,1,12.46,200,1,12.43,700,1,12.42,700,1,12.37,700,1,13.65,15,1,13.66,100,1,13.67,15,1,13.68,100,1,13.98,2,1,14.01,100,1,14.28,100,1,14.4,100,1,14.5,100,1,14.56,800,1,2,309782481
2025-07-17T15:49:59.534062634Z,2025-07-17T15:49:59.533897369Z,160,2,1108,C,A,14.010000000,100,0,308375185,130,165265,259314032,ARL,,13.04,2,1,13.03,100,1,13.02,100,1,12.73,100,1,12.71,100,1,12.5,700,1,12.46,200,1,12.43,700,1,12.42,700,1,12.37,700,1,13.65,15,1,13.66,100,1,13.67,15,1,13.68,100,1,13.98,2,1,14.28,100,1,14.4,100,1,14.5,100,1,14.56,800,1,14.6,700,1,2,308375185
2025-07-17T15:49:59.534115275Z,2025-07-17T15:49:59.533948952Z,160,2,1108,A,A,13.930000000,100,0,309782973,130,166323,259314033,ARL,,13.04,2,1,13.03,100,1,13.02,100,1,12.73,100,1,12.71,100,1,12.5,700,1,12.46,200,1,12.43,700,1,12.42,700,1,12.37,700,1,13.65,15,1,13.66,100,1,13.67,15,1,13.68,100,1,13.93,100,1,13.98,2,1,14.28,100,1,14.4,100,1,14.5,100,1,14.56,800,1,2,309782973
2025-07-17T15:50:00.547404972Z,2025-07-17T15:50:00.547239401Z,160,2,1108,C,A,13.670000000,15,0,309524921,130,165571,259349868,ARL,,13.04,2,1,13.03,100,1,13.02,100,1,12.73,100,1,12.71,100,1,12.5,700,1,12.46,200,1,12.43,700,1,12.42,700,1,12.37,700,1,13.65,15,1,13.66,100,1,13.68,100,1,13.93,100,1,13.98,2,1,14.28,100,1,14.4,100,1,14.5,100,1,14.56,800,1,14.6,700,1,2,309524921
2025-07-17T15:50:00.555536688Z,2025-07-17T15:50:00.555363249Z,160,2,1108,C,A,14.650000000,100,0,307964661,0,173439,259353226,ARL,,13.04,2,1,13.03,100,1,13.02,100,1,12.73,100,1,12.71,100,1,12.5,700,1,12.46,200,1,12.43,700,1,12.42,700,1,12.37,700,1,13.65,15,1,13.66,100,1,13.68,100,1,13.93,100,1,13.98,2,1,14.28,100,1,14.4,100,1,14.5,100,1,14.56,800,1,14.6,700,1,2,307964661
2025-07-17T15:50:00.555536688Z,2025-07-17T15:50:00.555363249Z,160,2,1108,A,A,14.540000000,100,0,309823025,128,173439,259353226,ARL,,13.04,2,1,13.03,100,1,13.02,100,1,12.73,100,1,12.71,100,1,12.5,700,1,12.46,200,1,12.43,700,1,12.42,700,1,12.37,700,1,13.65,15,1,13.66,100,1,13.68,100,1,13.93,100,1,13.98,2,1,14.28,100,1,14.4,100,1,14.5,100,1,14.54,100,1,14.56,800,1,2,309823025
2025-07-17T15:50:03.412422880Z,2025-07-17T15:50:03.412257475Z,160,2,1108,A,A,13.630000000,15,0,309899025,130,165405,259413272,ARL,,13.04,2,1,13.03,100,1,13.02,100,1,12.73,100,1,12.71,100,1,12.5,700,1,12.46,200,1,12.43,700,1,12.42,700,1,12.37,700,1,13.63,15,1,13.65,15,1,13.66,100,1,13.68,100,1,13.93,100,1,13.98,2,1,14.28,100,1,14.4,100,1,14.5,100,1,14.54,100,1,2,309899025
2025-07-17T15:50:03.415527372Z,2025-07-17T15:50:03.415361851Z,160,2,1108,C,A,14.640000000,100,0,308296381,0,165521,259413427,ARL,,13.04,2,1,13.03,100,1,13.02,100,1,12.73,100,1,12.71,100,1,12.5,700,1,12.46,200,1,12.43,700,1,12.42,700,1,12.37,700,1,13.63,15,1,13.65,15,1,13.66,100,1,13.68,100,1,13.93,100,1,13.98,2,1,14.28,100,1,14.4,100,1,14.5,100,1,14.54,100,1,2,308296381
2025-07-17T15:50:03.415527372Z,2025-07-17T15:50:03.415361851Z,160,2,1108,A,A,14.530000000,100,0,309899141,130,165521,259413427,ARL,,13.04,2,1,13.03,100,1,13.02,100,1,12.73,100,1,12.71,100,1,12.5,700,1,12.46,200,1,12.43,700,1,12.42,700,1,12.37,700,1,13.63,15,1,13.65,15,1,13.66,100,1,13.68,100,1,13.93,100,1,13.98,2,1,14.28,100,1,14.4,100,1,14.5,100,1,14.53,100,1,2,309899141
2025-07-17T15:50:03.824292152Z,2025-07-17T15:50:03.824126753Z,160,2,1108,C,A,13.660000000,100,0,309782481,0,165399,259418661,ARL,,13.04,2,1,13.03,100,1,13.02,100,1,12.73,100,1,12.71,100,1,12.5,700,1,12.46,200,1,12.43,700,1,12.42,700,1,12.37,700,1,13.63,15,1,13.65,15,1,13.68,100,1,13.93,100,1,13.98,2,1,14.28,100,1,14.4,100,1,14.5,100,1,14.53,100,1,14.54,100,1,2,309782481
2025-07-17T15:50:03.824292152Z,2025-07-17T15:50:03.824126753Z,160,2,1108,A,A,13.640000000,100,0,309903973,130,165399,259418661,ARL,,13.04,2,1,13.03,100,1,13.02,100,1,12.73,100,1,12.71,100,1,12.5,700,1,12.46,200,1,12.43,700,1,12.42,700,1,12.37,700,1,13.63,15,1,13.64,100,1,13.65,15,1,13.68,100,1,13.93,100,1,13.98,2,1,14.28,100,1,14.4,100,1,14.5,100,1,14.53,100,1,2,309903973
2025-07-17T15:50:03.825028460Z,2025-07-17T15:50:03.824863026Z,160,2,1108,C,A,14.740000000,100,0,308998341,0,165434,259418664,ARL,,13.04,2,1,13.03,100,1,13.02,100,1,12.73,100,1,12.71,100,1,12.5,700,1,12.46,200,1,12.43,700,1,12.42,700,1,12.37,700,1,13.63,15,1,13.64,100,1,13.65,15,1,13.68,100,1,13.93,100,1,13.98,2,1,14.28,100,1,14.4,100,1,14.5,100,1,14.53,100,1,2,308998341
2025-07-17T15:50:03.825028460Z,2025-07-17T15:50:03.824863026Z,160,2,1108,A,A,14.700000000,100,0,309903993,130,165434,259418664,ARL,,13.04,2,1,13.03,100,1,13.02,100,1,12.73,100,1,12.71,100,1,12.5,700,1,12.46,200,1,12.43,700,1,12.42,700,1,12.37,700,1,13.63,15,1,13.64,100,1,13.65,15,1,13.68,100,1,13.93,100,1,13.98,2,1,14.28,100,1,14.4,100,1,14.5,100,1,14.53,100,1,2,309903993
2025-07-17T15:50:04.484898759Z,2025-07-17T15:50:04.484733438Z,160,2,1108,A,A,13.660000000,100,0,309922345,130,165321,259433904,ARL,,13.04,2,1,13.03,100,1,13.02,100,1,12.73,100,1,12.71,100,1,12.5,700,1,12.46,200,1,12.43,700,1,12.42,700,1,12.37,700,1,13.63,15,1,13.64,100,1,13.65,15,1,13.66,100,1,13.68,100,1,13.93,100,1,13.98,2,1,14.28,100,1,14.4,100,1,14.5,100,1,2,309922345
2025-07-17T15:50:04.524729039Z,2025-07-17T15:50:04.524563568Z,160,2,1108,C,A,13.680000000,100,0,309707413,130,165471,259434652,ARL,,13.04,2,1,13.03,100,1,13.02,100,1,12.73,100,1,12.71,100,1,12.5,700,1,12.46,200,1,12.43,700,1,12.42,700,1,12.37,700,1,13.63,15,1,13.64,100,1,13.65,15,1,13.66,100,1,13.93,100,1,13.98,2,1,14.28,100,1,14.4,100,1,14.5,100,1,14.53,100,1,2,309707413
2025-07-17T15:50:06.787826975Z,2025-07-17T15:50:06.787661846Z,160,2,1108,C,A,13.630000000,15,0,309899025,130,165129,259472951,ARL,,13.04,2,1,13.03,100,1,13.02,100,1,12.73,100,1,12.71,100,1,12.5,700,1,12.46,200,1,12.43,700,1,12.42,700,1,12.37,700,1,13.64,100,1,13.65,15,1,13.66,100,1,13.93,100,1,13.98,2,1,14.28,100,1,14.4,100,1,14.5,100,1,14.53,100,1,14.54,100,1,2,309899025
2025-07-17T15:50:09.185499367Z,2025-07-17T15:50:09.185334126Z,160,2,1108,A,A,13.610000000,15,0,310030465,130,165241,259516855,ARL,,13.04,2,1,13.03,100,1,13.02,100,1,12.73,100,1,12.71,100,1,12.5,700,1,12.46,200,1,12.43,700,1,12.42,700,1,12.37,700,1,13.61,15,1,13.64,100,1,13.65,15,1,13.66,100,1,13.93,100,1,13.98,2,1,14.28,100,1,14.4,100,1,14.5,100,1,14.53,100,1,2,310030465
2025-07-17T15:50:09.198476437Z,2025-07-17T15:50:09.198311198Z,160,2,1108,A,A,13.640000000,100,0,310031625,130,165239,259517754,ARL,,13.04,2,1,13.03,100,1,13.02,100,1,12.73,100,1,12.71,100,1,12.5,700,1,12.46,200,1,12.43,700,1,12.42,700,1,12.37,700,1,13.61,15,1,13.64,200,1,13.65,15,1,13.66,100,1,13.93,100,1,13.98,2,1,14.28,100,1,14.4,100,1,14.5,100,1,14.53,100,1,2,310031625
2025-07-17T15:50:09.205487416Z,2025-07-17T15:50:09.205322092Z,160,2,1108,C,A,13.660000000,100,0,309922345,130,165324,259517973,ARL,,13.04,2,1,13.03,100,1,13.02,100,1,12.73,100,1,12.71,100,1,12.5,700,1,12.46,200,1,12.43,700,1,12.42,700,1,12.37,700,1,13.61,15,1,13.64,200,1,13.65,15,1,13.93,100,1,13.98,2,1,14.28,100,1,14.4,100,1,14.5,100,1,14.53,100,1,14.54,100,1,2,309922345
2025-07-17T15:50:09.330738153Z,2025-07-17T15:50:09.330572653Z,160,2,1108,C,A,13.640000000,100,0,309903973,0,165500,259522708,ARL,,13.04,2,1,13.03,100,1,13.02,100,1,12.73,100,1,12.71,100,1,12.5,700,1,12.46,200,1,12.43,700,1,12.42,700,1,12.37,700,1,13.61,15,1,13.64,100,1,13.65,15,1,13.93,100,1,13.98,2,1,14.28,100,1,14.4,100,1,14.5,100,1,14.53,100,1,14.54,100,1,2,309903973
2025-07-17T15:50:09.330738153Z,2025-07-17T15:50:09.330572653Z,160,2,1108,A,A,13.620000000,100,0,310037965,130,165500,259522708,ARL,,13.04,2,1,13.03,100,1,13.02,100,1,12.73,100,1,12.71,100,1,12.5,700,1,12.46,200,1,12.43,700,1,12.42,700,1,12.37,700,1,13.61,15,1,13.62,100,1,13.64,100,1,13.65,15,1,13.93,100,1,13.98,2,1,14.28,100,1,14.4,100,1,14.5,100,1,14.53,100,1,2,310037965
2025-07-17T15:50:20.204539185Z,2025-07-17T15:50:20.204373858Z,160,2,1108,C,A,13.650000000,15,0,309707269,130,165327,259737768,ARL,,13.04,2,1,13.03,100,1,13.02,100,1,12.73,100,1,12.71,100,1,12.5,700,1,12.46,200,1,12.43,700,1,12.42,700,1,12.37,700,1,13.61,15,1,13.62,100,1,13.64,100,1,13.93,100,1,13.98,2,1,14.28,100,1,14.4,100,1,14.5,100,1,14.53,100,1,14.54,100,1,2,309707269
2025-07-17T15:50:25.935579034Z,2025-07-17T15:50:25.935412900Z,160,2,1108,A,A,13.590000000,15,0,310424077,128,166134,259828644,ARL,,13.04,2,1,13.03,100,1,13.02,100,1,12.73,100,1,12.71,100,1,12.5,700,1,12.46,200,1,12.43,700,1,12.42,700,1,12.37,700,1,13.59,15,1,13.61,15,1,13.62,100,1,13.64,100,1,13.93,100,1,13.98,2,1,14.28,100,1,14.4,100,1,14.5,100,1,14.53,100,1,2,310424077
2025-07-17T15:50:26.954828150Z,2025-07-17T15:50:26.954662143Z,160,2,1108,C,A,13.620000000,100,0,310037965,0,166007,259847181,ARL,,13.04,2,1,13.03,100,1,13.02,100,1,12.73,100,1,12.71,100,1,12.5,700,1,12.46,200,1,12.43,700,1,12.42,700,1,12.37,700,1,13.59,15,1,13.61,15,1,13.64,100,1,13.93,100,1,13.98,2,1,14.28,100,1,14.4,100,1,14.5,100,1,14.53,100,1,14.54,100,1,2,310037965
2025-07-17T15:50:26.954828150Z,2025-07-17T15:50:26.954662143Z,160,2,1108,A,A,13.600000000,100,0,310446249,130,166007,259847181,ARL,,13.04,2,1,13.03,100,1,13.02,100,1,12.73,100,1,12.71,100,1,12.5,700,1,12.46,200,1,12.43,700,1,12.42,700,1,12.37,700,1,13.59,15,1,13.6,100,1,13.61,15,1,13.64,100,1,13.93,100,1,13.98,2,1,14.28,100,1,14.4,100,1,14.5,100,1,14.53,100,1,2,310446249
2025-07-17T15:50:26.955565904Z,2025-07-17T15:50:26.955400327Z,160,2,1108,C,A,14.700000000,100,0,309903993,0,165577,259847190,ARL,,13.04,2,1,13.03,100,1,13.02,100,1,12.73,100,1,12.71,100,1,12.5,700,1,12.46,200,1,12.43,700,1,12.42,700,1,12.37,700,1,13.59,15,1,13.6,100,1,13.61,15,1,13.64,100,1,13.93,100,1,13.98,2,1,14.28,100,1,14.4,100,1,14.5,100,1,14.53,100,1,2,309903993
2025-07-17T15:50:26.955565904Z,2025-07-17T15:50:26.955400327Z,160,2,1108,A,A,14.650000000,100,0,310446269,130,165577,259847190,ARL,,13.04,2,1,13.03,100,1,13.02,100,1,12.73,100,1,12.71,100,1,12.5,700,1,12.46,200,1,12.43,700,1,12.42,700,1,12.37,700,1,13.59,15,1,13.6,100,1,13.61,15,1,13.64,100,1,13.93,100,1,13.98,2,1,14.28,100,1,14.4,100,1,14.5,100,1,14.53,100,1,2,310446269
2025-07-17T15:50:26.956259508Z,2025-07-17T15:50:26.956094101Z,160,2,1108,C,A,17.430000000,100,0,308799373,0,165407,259847199,ARL,,13.04,2,1,13.03,100,1,13.02,100,1,12.73,100,1,12.71,100,1,12.5,700,1,12.46,200,1,12.43,700,1,12.42,700,1,12.37,700,1,13.59,15,1,13.6,100,1,13.61,15,1,13.64,100,1,13.93,100,1,13.98,2,1,14.28,100,1,14.4,100,1,14.5,100,1,14.53,100,1,2,308799373
2025-07-17T15:50:26.956259508Z,2025-07-17T15:50:26.956094101Z,160,2,1108,A,A,17.280000000,100,0,310446293,130,165407,259847199,ARL,,13.04,2,1,13.03,100,1,13.02,100,1,12.73,100,1,12.71,100,1,12.5,700,1,12.46,200,1,12.43,700,1,12.42,700,1,12.37,700,1,13.59,15,1,13.6,100,1,13.61,15,1,13.64,100,1,13.93,100,1,13.98,2,1,14.28,100,1,14.4,100,1,14.5,100,1,14.53,100,1,2,310446293
2025-07-17T15:50:26.983044736Z,2025-07-17T15:50:26.982879448Z,160,2,1108,A,A,15.510000000,100,0,310447441,130,165288,259847556,ARL,,13.04,2,1,13.03,100,1,13.02,100,1,12.73,100,1,12.71,100,1,12.5,700,1,12.46,200,1,12.43,700,1,12.42,700,1,12.37,700,1,13.59,15,1,13.6,100,1,13.61,15,1,13.64,100,1,13.93,100,1,13.98,2,1,14.28,100,1,14.4,100,1,14.5,100,1,14.53,100,1,2,310447441
2025-07-17T15:50:26.983057675Z,2025-07-17T15:50:26.982892468Z,160,2,1108,C,A,15.780000000,100,0,282776733,130,165207,259847557,ARL,,13.04,2,1,13.03,100,1,13.02,100,1,12.73,100,1,12.71,100,1,12.5,700,1,12.46,200,1,12.43,700,1,12.42,700,1,12.37,700,1,13.59,15,1,13.6,100,1,13.61,15,1,13.64,100,1,13.93,100,1,13.98,2,1,14.28,100,1,14.4,100,1,14.5,100,1,14.53,100,1,2,282776733
2025-07-17T15:50:30.046879569Z,2025-07-17T15:50:30.046714265Z,160,2,1108,C,A,13.590000000,15,0,310424077,130,165304,259916670,ARL,,13.04,2,1,13.03,100,1,13.02,100,1,12.73,100,1,12.71,100,1,12.5,700,1,12.46,200,1,12.43,700,1,12.42,700,1,12.37,700,1,13.6,100,1,13.61,15,1,13.64,100,1,13.93,100,1,13.98,2,1,14.28,100,1,14.4,100,1,14.5,100,1,14.53,100,1,14.54,100,1,2,310424077
2025-07-17T15:50:30.047015114Z,2025-07-17T15:50:30.046849726Z,160,2,1108,C,A,13.610000000,15,0,310030465,130,165388,259916674,ARL,,13.04,2,1,13.03,100,1,13.02,100,1,12.73,100,1,12.71,100,1,12.5,700,1,12.46,200,1,12.43,700,1,12.42,700,1,12.37,700,1,13.6,100,1,13.64,100,1,13.93,100,1,13.98,2,1,14.28,100,1,14.4,100,1,14.5,100,1,14.53,100,1,14.54,100,1,14.56,800,1,2,310030465
2025-07-17T15:51:37.986158330Z,2025-07-17T15:51:37.985992174Z,160,2,1108,C,A,13.980000000,2,0,309091513,0,166156,261130345,ARL,,13.04,2,1,13.03,100,1,13.02,100,1,12.73,100,1,12.71,100,1,12.5,700,1,12.46,200,1,12.43,700,1,12.42,700,1,12.37,700,1,13.6,100,1,13.64,100,1,13.93,100,1,14.28,100,1,14.4,100,1,14.5,100,1,14.53,100,1,14.54,100,1,14.56,800,1,14.6,700,1,2,309091513
2025-07-17T15:51:37.986158330Z,2025-07-17T15:51:37.985992174Z,160,2,1108,A,A,13.890000000,2,0,311979125,130,166156,261130345,ARL,,13.04,2,1,13.03,100,1,13.02,100,1,12.73,100,1,12.71,100,1,12.5,700,1,12.46,200,1,12.43,700,1,12.42,700,1,12.37,700,1,13.6,100,1,13.64,100,1,13.89,2,1,13.93,100,1,14.28,100,1,14.4,100,1,14.5,100,1,14.53,100,1,14.54,100,1,14.56,800,1,2,311979125
2025-07-17T15:52:16.372434625Z,2025-07-17T15:52:16.372269170Z,160,2,1108,C,A,13.600000000,100,0,310446249,130,165455,261713790,ARL,,13.04,2,1,13.03,100,1,13.02,100,1,12.73,100,1,12.71,100,1,12.5,700,1,12.46,200,1,12.43,700,1,12.42,700,1,12.37,700,1,13.64,100,1,13.89,2,1,13.93,100,1,14.28,100,1,14.4,100,1,14.5,100,1,14.53,100,1,14.54,100,1,14.56,800,1,14.6,700,1,2,310446249
2025-07-17T15:52:16.373188791Z,2025-07-17T15:52:16.373023186Z,160,2,1108,C,A,14.650000000,100,0,310446269,0,165605,261713830,ARL,,13.04,2,1,13.03,100,1,13.02,100,1,12.73,100,1,12.71,100,1,12.5,700,1,12.46,200,1,12.43,700,1,12.42,700,1,12.37,700,1,13.64,100,1,13.89,2,1,13.93,100,1,14.28,100,1,14.4,100,1,14.5,100,1,14.53,100,1,14.54,100,1,14.56,800,1,14.6,700,1,2,310446269
2025-07-17T15:52:16.373188791Z,2025-07-17T15:52:16.373023186Z,160,2,1108,A,A,14.700000000,100,0,312771573,130,165605,261713830,ARL,,13.04,2,1,13.03,100,1,13.02,100,1,12.73,100,1,12.71,100,1,12.5,700,1,12.46,200,1,12.43,700,1,12.42,700,1,12.37,700,1,13.64,100,1,13.89,2,1,13.93,100,1,14.28,100,1,14.4,100,1,14.5,100,1,14.53,100,1,14.54,100,1,14.56,800,1,14.6,700,1,2,312771573
2025-07-17T15:52:16.374353159Z,2025-07-17T15:52:16.374186508Z,160,2,1108,C,A,13.640000000,100,0,310031625,130,166651,261713870,ARL,,13.04,2,1,13.03,100,1,13.02,100,1,12.73,100,1,12.71,100,1,12.5,700,1,12.46,200,1,12.43,700,1,12.42,700,1,12.37,700,1,13.89,2,1,13.93,100,1,14.28,100,1,14.4,100,1,14.5,100,1,14.53,100,1,14.54,100,1,14.56,800,1,14.6,700,1,14.66,200,1,2,310031625
2025-07-17T15:52:16.374480183Z,2025-07-17T15:52:16.374312976Z,160,2,1108,A,A,15.860000000,100,0,312771645,128,167207,261713880,ARL,,13.04,2,1,13.03,100,1,13.02,100,1,12.73,100,1,12.71,100,1,12.5,700,1,12.46,200,1,12.43,700,1,12.42,700,1,12.37,700,1,13.89,2,1,13.93,100,1,14.28,100,1,14.4,100,1,14.5,100,1,14.53,100,1,14.54,100,1,14.56,800,1,14.6,700,1,14.66,200,1,2,312771645
2025-07-17T15:52:16.374493650Z,2025-07-17T15:52:16.374327668Z,160,2,1108,C,A,15.510000000,100,0,310447441,130,165982,261713884,ARL,,13.04,2,1,13.03,100,1,13.02,100,1,12.73,100,1,12.71,100,1,12.5,700,1,12.46,200,1,12.43,700,1,12.42,700,1,12.37,700,1,13.89,2,1,13.93,100,1,14.28,100,1,14.4,100,1,14.5,100,1,14.53,100,1,14.54,100,1,14.56,800,1,14.6,700,1,14.66,200,1,2,310447441
2025-07-17T15:52:16.375388285Z,2025-07-17T15:52:16.375222836Z,160,2,1108,C,A,14.540000000,100,0,309823025,0,165449,261713944,ARL,,13.04,2,1,13.03,100,1,13.02,100,1,12.73,100,1,12.71,100,1,12.5,700,1,12.46,200,1,12.43,700,1,12.42,700,1,12.37,700,1,13.89,2,1,13.93,100,1,14.28,100,1,14.4,100,1,14.5,100,1,14.53,100,1,14.56,800,1,14.6,700,1,14.66,200,1,14.68,1400,1,2,309823025
2025-07-17T15:52:16.375388285Z,2025-07-17T15:52:16.375222836Z,160,2,1108,A,A,14.810000000,100,0,312771781,130,165449,261713944,ARL,,13.04,2,1,13.03,100,1,13.02,100,1,12.73,100,1,12.71,100,1,12.5,700,1,12.46,200,1,12.43,700,1,12.42,700,1,12.37,700,1,13.89,2,1,13.93,100,1,14.28,100,1,14.4,100,1,14.5,100,1,14.53,100,1,14.56,800,1,14.6,700,1,14.66,200,1,14.68,1400,1,2,312771781
2025-07-17T15:52:16.375414247Z,2025-07-17T15:52:16.375248654Z,160,2,1108,C,A,14.660000000,100,0,308901981,0,165593,261713945,ARL,,13.04,2,1,13.03,100,1,13.02,100,1,12.73,100,1,12.71,100,1,12.5,700,1,12.46,200,1,12.43,700,1,12.42,700,1,12.37,700,1,13.89,2,1,13.93,100,1,14.28,100,1,14.4,100,1,14.5,100,1,14.53,100,1,14.56,800,1,14.6,700,1,14.66,100,1,14.68,1400,1,2,308901981
2025-07-17T15:52:16.375414247Z,2025-07-17T15:52:16.375248654Z,160,2,1108,A,A,14.890000000,100,0,312771785,130,165593,261713945,ARL,,13.04,2,1,13.03,100,1,13.02,100,1,12.73,100,1,12.71,100,1,12.5,700,1,12.46,200,1,12.43,700,1,12.42,700,1,12.37,700,1,13.89,2,1,13.93,100,1,14.28,100,1,14.4,100,1,14.5,100,1,14.53,100,1,14.56,800,1,14.6,700,1,14.66,100,1,14.68,1400,1,2,312771785
2025-07-17T15:52:16.375828154Z,2025-07-17T15:52:16.375662552Z,160,2,1108,C,A,14.530000000,100,0,309899141,0,165602,261713959,ARL,,13.04,2,1,13.03,100,1,13.02,100,1,12.73,100,1,12.71,100,1,12.5,700,1,12.46,200,1,12.43,700,1,12.42,700,1,12.37,700,1,13.89,2,1,13.93,100,1,14.28,100,1,14.4,100,1,14.5,100,1,14.56,800,1,14.6,700,1,14.66,100,1,14.68,1400,1,14.7,100,1,2,309899141
2025-07-17T15:52:16.375828154Z,2025-07-17T15:52:16.375662552Z,160,2,1108,A,A,14.760000000,100,0,312771829,130,165602,261713959,ARL,,13.04,2,1,13.03,100,1,13.02,100,1,12.73,100,1,12.71,100,1,12.5,700,1,12.46,200,1,12.43,700,1,12.42,700,1,12.37,700,1,13.89,2,1,13.93,100,1,14.28,100,1,14.4,100,1,14.5,100,1,14.56,800,1,14.6,700,1,14.66,100,1,14.68,1400,1,14.7,100,1,2,312771829
2025-07-17T15:52:16.377345053Z,2025-07-17T15:52:16.377179230Z,160,2,1108,C,A,17.280000000,100,0,310446293,0,165823,261714104,ARL,,13.04,2,1,13.03,100,1,13.02,100,1,12.73,100,1,12.71,100,1,12.5,700,1,12.46,200,1,12.43,700,1,12.42,700,1,12.37,700,1,13.89,2,1,13.93,100,1,14.28,100,1,14.4,100,1,14.5,100,1,14.56,800,1,14.6,700,1,14.66,100,1,14.68,1400,1,14.7,100,1,2,310446293
2025-07-17T15:52:16.377345053Z,2025-07-17T15:52:16.377179230Z,160,2,1108,A,A,17.700000000,100,0,312772009,130,165823,261714104,ARL,,13.04,2,1,13.03,100,1,13.02,100,1,12.73,100,1,12.71,100,1,12.5,700,1,12.46,200,1,12.43,700,1,12.42,700,1,12.37,700,1,13.89,2,1,13.93,100,1,14.28,100,1,14.4,100,1,14.5,100,1,14.56,800,1,14.6,700,1,14.66,100,1,14.68,1400,1,14.7,100,1,2,312772009
2025-07-17T15:52:16.378239114Z,2025-07-17T15:52:16.378073674Z,160,2,1108,C,A,15.760000000,100,0,308902229,0,165440,261714140,ARL,,13.04,2,1,13.03,100,1,13.02,100,1,12.73,100,1,12.71,100,1,12.5,700,1,12.46,200,1,12.43,700,1,12.42,700,1,12.37,700,1,13.89,2,1,13.93,100,1,14.28,100,1,14.4,100,1,14.5,100,1,14.56,800,1,14.6,700,1,14.66,100,1,14.68,1400,1,14.7,100,1,2,308902229
2025-07-17T15:52:16.378239114Z,2025-07-17T15:52:16.378073674Z,160,2,1108,A,A,16.020000000,100,0,312772057,130,165440,261714140,ARL,,13.04,2,1,13.03,100,1,13.02,100,1,12.73,100,1,12.71,100,1,12.5,700,1,12.46,200,1,12.43,700,1,12.42,700,1,12.37,700,1,13.89,2,1,13.93,100,1,14.28,100,1,14.4,100,1,14.5,100,1,14.56,800,1,14.6,700,1,14.66,100,1,14.68,1400,1,14.7,100,1,2,312772057
2025-07-17T15:52:16.378385943Z,2025-07-17T15:52:16.378220434Z,160,2,1108,C,A,14.500000000,100,0,308903349,0,165509,261714145,ARL,,13.04,2,1,13.03,100,1,13.02,100,1,12.73,100,1,12.71,100,1,12.5,700,1,12.46,200,1,12.43,700,1,12.42,700,1,12.37,700,1,13.89,2,1,13.93,100,1,14.28,100,1,14.4,100,1,14.56,800,1,14.6,700,1,14.66,100,1,14.68,1400,1,14.7,100,1,14.76,100,1,2,308903349
2025-07-17T15:52:16.378385943Z,2025-07-17T15:52:16.378220434Z,160,2,1108,A,A,14.720000000,100,0,312772061,130,165509,261714145,ARL,,13.04,2,1,13.03,100,1,13.02,100,1,12.73,100,1,12.71,100,1,12.5,700,1,12.46,200,1,12.43,700,1,12.42,700,1,12.37,700,1,13.89,2,1,13.93,100,1,14.28,100,1,14.4,100,1,14.56,800,1,14.6,700,1,14.66,100,1,14.68,1400,1,14.7,100,1,14.72,100,1,2,312772061
2025-07-17T15:52:16.378870638Z,2025-07-17T15:52:16.378705201Z,160,2,1108,A,B,13.270000000,10,0,312772069,130,165437,261714171,ARL,,13.27,10,1,13.04,2,1,13.03,100,1,13.02,100,1,12.73,100,1,12.71,100,1,12.5,700,1,12.46,200,1,12.43,700,1,12.42,700,1,13.89,2,1,13.93,100,1,14.28,100,1,14.4,100,1,14.56,800,1,14.6,700,1,14.66,100,1,14.68,1400,1,14.7,100,1,14.72,100,1,2,312772069
2025-07-17T15:52:16.378872385Z,2025-07-17T15:52:16.378707041Z,160,2,1108,A,A,13.860000000,15,0,312772073,130,165344,261714172,ARL,,13.27,10,1,13.04,2,1,13.03,100,1,13.02,100,1,12.73,100,1,12.71,100,1,12.5,700,1,12.46,200,1,12.43,700,1,12.42,700,1,13.86,15,1,13.89,2,1,13.93,100,1,14.28,100,1,14.4,100,1,14.56,800,1,14.6,700,1,14.66,100,1,14.68,1400,1,14.7,100,1,2,312772073
2025-07-17T15:52:16.379127782Z,2025-07-17T15:52:16.378962330Z,160,2,1108,C,B,13.020000000,100,0,309415429,0,165452,261714185,ARL,,13.27,10,1,13.04,2,1,13.03,100,1,12.73,100,1,12.71,100,1,12.5,700,1,12.46,200,1,12.43,700,1,12.42,700,1,12.37,700,1,13.86,15,1,13.89,2,1,13.93,100,1,14.28,100,1,14.4,100,1,14.56,800,1,14.6,700,1,14.66,100,1,14.68,1400,1,14.7,100,1,2,309415429
2025-07-17T15:52:16.379127782Z,2025-07-17T15:52:16.378962330Z,160,2,1108,A,B,13.260000000,100,0,312772077,130,165452,261714185,ARL,,13.27,10,1,13.26,100,1,13.04,2,1,13.03,100,1,12.73,100,1,12.71,100,1,12.5,700,1,12.46,200,1,12.43,700,1,12.42,700,1,13.86,15,1,13.89,2,1,13.93,100,1,14.28,100,1,14.4,100,1,14.56,800,1,14.6,700,1,14.66,100,1,14.68,1400,1,14.7,100,1,2,312772077
2025-07-17T15:52:16.389025469Z,2025-07-17T15:52:16.388859982Z,160,2,1108,C,A,13.930000000,100,0,309782973,130,165487,261714477,ARL,,13.27,10,1,13.26,100,1,13.04,2,1,13.03,100,1,12.73,100,1,12.71,100,1,12.5,700,1,12.46,200,1,12.43,700,1,12.42,700,1,13.86,15,1,13.89,2,1,14.28,100,1,14.4,100,1,14.56,800,1,14.6,700,1,14.66,100,1,14.68,1400,1,14.7,100,1,14.72,100,1,2,309782973
2025-07-17T15:52:16.389082451Z,2025-07-17T15:52:16.388917108Z,160,2,1108,A,A,14.190000000,100,0,312772501,130,165343,261714481,ARL,,13.27,10,1,13.26,100,1,13.04,2,1,13.03,100,1,12.73,100,1,12.71,100,1,12.5,700,1,12.46,200,1,12.43,700,1,12.42,700,1,13.86,15,1,13.89,2,1,14.19,100,1,14.28,100,1,14.4,100,1,14.56,800,1,14.6,700,1,14.66,100,1,14.68,1400,1,14.7,100,1,2,312772501
2025-07-17T15:52:16.396174502Z,2025-07-17T15:52:16.396008715Z,160,2,1108,C,A,14.660000000,100,0,308903001,0,165787,261714603,ARL,,13.27,10,1,13.26,100,1,13.04,2,1,13.03,100,1,12.73,100,1,12.71,100,1,12.5,700,1,12.46,200,1,12.43,700,1,12.42,700,1,13.86,15,1,13.89,2,1,14.19,100,1,14.28,100,1,14.4,100,1,14.56,800,1,14.6,700,1,14.68,1400,1,14.7,100,1,14.72,100,1,2,308903001
2025-07-17T15:52:16.396174502Z,2025-07-17T15:52:16.396008715Z,160,2,1108,A,A,14.960000000,100,0,312772869,130,165787,261714603,ARL,,13.27,10,1,13.26,100,1,13.04,2,1,13.03,100,1,12.73,100,1,12.71,100,1,12.5,700,1,12.46,200,1,12.43,700,1,12.42,700,1,13.86,15,1,13.89,2,1,14.19,100,1,14.28,100,1,14.4,100,1,14.56,800,1,14.6,700,1,14.68,1400,1,14.7,100,1,14.72,100,1,2,312772869
2025-07-17T15:52:16.397677681Z,2025-07-17T15:52:16.397512710Z,160,2,1108,C,A,14.190000000,100,0,312772501,130,164971,261714619,ARL,,13.27,10,1,13.26,100,1,13.04,2,1,13.03,100,1,12.73,100,1,12.71,100,1,12.5,700,1,12.46,200,1,12.43,700,1,12.42,700,1,13.86,15,1,13.89,2,1,14.28,100,1,14.4,100,1,14.56,800,1,14.6,700,1,14.68,1400,1,14.7,100,1,14.72,100,1,14.76,100,1,2,312772501
2025-07-17T15:52:16.397727042Z,2025-07-17T15:52:16.397561691Z,160,2,1108,A,A,14.260000000,100,0,312772901,130,165351,261714620,ARL,,13.27,10,1,13.26,100,1,13.04,2,1,13.03,100,1,12.73,100,1,12.71,100,1,12.5,700,1,12.46,200,1,12.43,700,1,12.42,700,1,13.86,15,1,13.89,2,1,14.26,100,1,14.28,100,1,14.4,100,1,14.56,800,1,14.6,700,1,14.68,1400,1,14.7,100,1,14.72,100,1,2,312772901
2025-07-17T15:52:16.424137423Z,2025-07-17T15:52:16.423972000Z,160,2,1108,C,A,14.700000000,100,0,312771573,0,165423,261714976,ARL,,13.27,10,1,13.26,100,1,13.04,2,1,13.03,100,1,12.73,100,1,12.71,100,1,12.5,700,1,12.46,200,1,12.43,700,1,12.42,700,1,13.86,15,1,13.89,2,1,14.26,100,1,14.28,100,1,14.4,100,1,14.56,800,1,14.6,700,1,14.68,1400,1,14.72,100,1,14.76,100,1,2,312771573
2025-07-17T15:52:16.424137423Z,2025-07-17T15:52:16.423972000Z,160,2,1108,A,A,15.060000000,100,0,312773353,130,165423,261714976,ARL,,13.27,10,1,13.26,100,1,13.04,2,1,13.03,100,1,12.73,100,1,12.71,100,1,12.5,700,1,12.46,200,1,12.43,700,1,12.42,700,1,13.86,15,1,13.89,2,1,14.26,100,1,14.28,100,1,14.4,100,1,14.56,800,1,14.6,700,1,14.68,1400,1,14.72,100,1,14.76,100,1,2,312773353
2025-07-17T15:52:16.464781343Z,2025-07-17T15:52:16.464616142Z,160,2,1108,A,A,13.870000000,100,0,312773881,130,165201,261715303,ARL,,13.27,10,1,13.26,100,1,13.04,2,1,13.03,100,1,12.73,100,1,12.71,100,1,12.5,700,1,12.46,200,1,12.43,700,1,12.42,700,1,13.86,15,1,13.87,100,1,13.89,2,1,14.26,100,1,14.28,100,1,14.4,100,1,14.56,800,1,14.6,700,1,14.68,1400,1,14.72,100,1,2,312773881
2025-07-17T15:52:16.473556948Z,2025-07-17T15:52:16.473391480Z,160,2,1108,C,A,15.060000000,100,0,312773353,0,165468,261715409,ARL,,13.27,10,1,13.26,100,1,13.04,2,1,13.03,100,1,12.73,100,1,12.71,100,1,12.5,700,1,12.46,200,1,12.43,700,1,12.42,700,1,13.86,15,1,13.87,100,1,13.89,2,1,14.26,100,1,14.28,100,1,14.4,100,1,14.56,800,1,14.6,700,1,14.68,1400,1,14.72,100,1,2,312773353
2025-07-17T15:52:16.473556948Z,2025-07-17T15:52:16.473391480Z,160,2,1108,A,A,14.950000000,100,0,312774001,130,165468,261715409,ARL,,13.27,10,1,13.26,100,1,13.04,2,1,13.03,100,1,12.73,100,1,12.71,100,1,12.5,700,1,12.46,200,1,12.43,700,1,12.42,700,1,13.86,15,1,13.87,100,1,13.89,2,1,14.26,100,1,14.28,100,1,14.4,100,1,14.56,800,1,14.6,700,1,14.68,1400,1,14.72,100,1,2,312774001
2025-07-17T15:52:16.480090894Z,2025-07-17T15:52:16.479925781Z,160,2,1108,C,A,14.260000000,100,0,312772901,130,165113,261715467,ARL,,13.27,10,1,13.26,100,1,13.04,2,1,13.03,100,1,12.73,100,1,12.71,100,1,12.5,700,1,12.46,200,1,12.43,700,1,12.42,700,1,13.86,15,1,13.87,100,1,13.89,2,1,14.28,100,1,14.4,100,1,14.56,800,1,14.6,700,1,14.68,1400,1,14.72,100,1,14.76,100,1,2,312772901
2025-07-17T15:52:16.480140131Z,2025-07-17T15:52:16.479974840Z,160,2,1108,A,A,14.150000000,100,0,312774033,130,165291,261715468,ARL,,13.27,10,1,13.26,100,1,13.04,2,1,13.03,100,1,12.73,100,1,12.71,100,1,12.5,700,1,12.46,200,1,12.43,700,1,12.42,700,1,13.86,15,1,13.87,100,1,13.89,2,1,14.15,100,1,14.28,100,1,14.4,100,1,14.56,800,1,14.6,700,1,14.68,1400,1,14.72,100,1,2,312774033
2025-07-17T15:52:28.787316865Z,2025-07-17T15:52:28.787151494Z,160,2,1108,C,B,13.270000000,10,0,312772069,130,165371,261883294,ARL,,13.26,100,1,13.04,2,1,13.03,100,1,12.73,100,1,12.71,100,1,12.5,700,1,12.46,200,1,12.43,700,1,12.42,700,1,12.37,700,1,13.86,15,1,13.87,100,1,13.89,2,1,14.15,100,1,14.28,100,1,14.4,100,1,14.56,800,1,14.6,700,1,14.68,1400,1,14.72,100,1,2,312772069
2025-07-17T15:52:28.787317827Z,2025-07-17T15:52:28.787152437Z,160,2,1108,C,A,13.860000000,15,0,312772073,130,165390,261883295,ARL,,13.26,100,1,13.04,2,1,13.03,100,1,12.73,100,1,12.71,100,1,12.5,700,1,12.46,200,1,12.43,700,1,12.42,700,1,12.37,700,1,13.87,100,1,13.89,2,1,14.15,100,1,14.28,100,1,14.4,100,1,14.56,800,1,14.6,700,1,14.68,1400,1,14.72,100,1,14.76,100,1,2,312772073
2025-07-17T15:52:43.128371033Z,2025-07-17T15:52:43.128203357Z,160,2,1108,C,A,13.890000000,2,0,311979125,0,167676,262115170,ARL,,13.26,100,1,13.04,2,1,13.03,100,1,12.73,100,1,12.71,100,1,12.5,700,1,12.46,200,1,12.43,700,1,12.42,700,1,12.37,700,1,13.87,100,1,14.15,100,1,14.28,100,1,14.4,100,1,14.56,800,1,14.6,700,1,14.68,1400,1,14.72,100,1,14.76,100,1,14.81,100,1,2,311979125
2025-07-17T15:52:43.128371033Z,2025-07-17T15:52:43.128203357Z,160,2,1108,A,A,13.990000000,2,0,313336713,128,167676,262115170,ARL,,13.26,100,1,13.04,2,1,13.03,100,1,12.73,100,1,12.71,100,1,12.5,700,1,12.46,200,1,12.43,700,1,12.42,700,1,12.37,700,1,13.87,100,1,13.99,2,1,14.15,100,1,14.28,100,1,14.4,100,1,14.56,800,1,14.6,700,1,14.68,1400,1,14.72,100,1,14.76,100,1,2,313336713
2025-07-17T15:54:24.908483782Z,2025-07-17T15:54:24.908318259Z,160,2,1108,A,B,13.290000000,10,0,315581981,130,165523,263863872,ARL,,13.29,10,1,13.26,100,1,13.04,2,1,13.03,100,1,12.73,100,1,12.71,100,1,12.5,700,1,12.46,200,1,12.43,700,1,12.42,700,1,13.87,100,1,13.99,2,1,14.15,100,1,14.28,100,1,14.4,100,1,14.56,800,1,14.6,700,1,14.68,1400,1,14.72,100,1,14.76,100,1,2,315581981
2025-07-17T15:54:26.792478456Z,2025-07-17T15:54:26.792313320Z,160,2,1108,C,B,13.290000000,10,0,315581981,130,165136,263895481,ARL,,13.26,100,1,13.04,2,1,13.03,100,1,12.73,100,1,12.71,100,1,12.5,700,1,12.46,200,1,12.43,700,1,12.42,700,1,12.37,700,1,13.87,100,1,13.99,2,1,14.15,100,1,14.28,100,1,14.4,100,1,14.56,800,1,14.6,700,1,14.68,1400,1,14.72,100,1,14.76,100,1,2,315581981
2025-07-17T15:54:52.986116083Z,2025-07-17T15:54:52.985950259Z,160,2,1108,C,A,13.990000000,2,0,313336713,0,165824,264262615,ARL,,13.26,100,1,13.04,2,1,13.03,100,1,12.73,100,1,12.71,100,1,12.5,700,1,12.46,200,1,12.43,700,1,12.42,700,1,12.37,700,1,13.87,100,1,14.15,100,1,14.28,100,1,14.4,100,1,14.56,800,1,14.6,700,1,14.68,1400,1,14.72,100,1,14.76,100,1,14.81,100,1,2,313336713
2025-07-17T15:54:52.986116083Z,2025-07-17T15:54:52.985950259Z,160,2,1108,A,A,14.100000000,2,0,316098525,130,165824,264262615,ARL,,13.26,100,1,13.04,2,1,13.03,100,1,12.73,100,1,12.71,100,1,12.5,700,1,12.46,200,1,12.43,700,1,12.42,700,1,12.37,700,1,13.87,100,1,14.1,2,1,14.15,100,1,14.28,100,1,14.4,100,1,14.56,800,1,14.6,700,1,14.68,1400,1,14.72,100,1,14.76,100,1,2,316098525
2025-07-17T15:55:33.673598252Z,2025-07-17T15:55:33.673432762Z,160,2,1108,A,B,13.290000000,10,0,316911465,130,165490,264905534,ARL,,13.29,10,1,13.26,100,1,13.04,2,1,13.03,100,1,12.73,100,1,12.71,100,1,12.5,700,1,12.46,200,1,12.43,700,1,12.42,700,1,13.87,100,1,14.1,2,1,14.15,100,1,14.28,100,1,14.4,100,1,14.56,800,1,14.6,700,1,14.68,1400,1,14.72,100,1,14.76,100,1,2,316911465
2025-07-17T15:55:34.257417204Z,2025-07-17T15:55:34.257251787Z,160,2,1108,C,B,13.260000000,100,0,312772077,0,165417,264919835,ARL,,13.29,10,1,13.04,2,1,13.03,100,1,12.73,100,1,12.71,100,1,12.5,700,1,12.46,200,1,12.43,700,1,12.42,700,1,12.37,700,1,13.87,100,1,14.1,2,1,14.15,100,1,14.28,100,1,14.4,100,1,14.56,800,1,14.6,700,1,14.68,1400,1,14.72,100,1,14.76,100,1,2,312772077
2025-07-17T15:55:34.257417204Z,2025-07-17T15:55:34.257251787Z,160,2,1108,A,B,13.280000000,100,0,316924721,130,165417,264919835,ARL,,13.29,10,1,13.28,100,1,13.04,2,1,13.03,100,1,12.73,100,1,12.71,100,1,12.5,700,1,12.46,200,1,12.43,700,1,12.42,700,1,13.87,100,1,14.1,2,1,14.15,100,1,14.28,100,1,14.4,100,1,14.56,800,1,14.6,700,1,14.68,1400,1,14.72,100,1,14.76,100,1,2,316924721
2025-07-17T15:55:40.197750400Z,2025-07-17T15:55:40.197584524Z,160,2,1108,C,B,13.290000000,10,0,316911465,130,165876,265015966,ARL,,13.28,100,1,13.04,2,1,13.03,100,1,12.73,100,1,12.71,100,1,12.5,700,1,12.46,200,1,12.43,700,1,12.42,700,1,12.37,700,1,13.87,100,1,14.1,2,1,14.15,100,1,14.28,100,1,14.4,100,1,14.56,800,1,14.6,700,1,14.68,1400,1,14.72,100,1,14.76,100,1,2,316911465
2025-07-17T15:57:51.328863560Z,2025-07-17T15:57:51.328698198Z,160,2,1108,C,A,13.870000000,100,0,312773881,130,165362,267272430,ARL,,13.28,100,1,13.04,2,1,13.03,100,1,12.73,100,1,12.71,100,1,12.5,700,1,12.46,200,1,12.43,700,1,12.42,700,1,12.37,700,1,14.1,2,1,14.15,100,1,14.28,100,1,14.4,100,1,14.56,800,1,14.6,700,1,14.68,1400,1,14.72,100,1,14.76,100,1,14.81,100,1,2,312773881
2025-07-17T15:57:51.329613584Z,2025-07-17T15:57:51.329447325Z,160,2,1108,C,A,14.950000000,100,0,312774001,0,166259,267272438,ARL,,13.28,100,1,13.04,2,1,13.03,100,1,12.73,100,1,12.71,100,1,12.5,700,1,12.46,200,1,12.43,700,1,12.42,700,1,12.37,700,1,14.1,2,1,14.15,100,1,14.28,100,1,14.4,100,1,14.56,800,1,14.6,700,1,14.68,1400,1,14.72,100,1,14.76,100,1,14.81,100,1,2,312774001
2025-07-17T15:57:51.329613584Z,2025-07-17T15:57:51.329447325Z,160,2,1108,A,A,15.000000000,100,0,319985021,130,166259,267272438,ARL,,13.28,100,1,13.04,2,1,13.03,100,1,12.73,100,1,12.71,100,1,12.5,700,1,12.46,200,1,12.43,700,1,12.42,700,1,12.37,700,1,14.1,2,1,14.15,100,1,14.28,100,1,14.4,100,1,14.56,800,1,14.6,700,1,14.68,1400,1,14.72,100,1,14.76,100,1,14.81,100,1,2,319985021
2025-07-17T15:57:51.329857672Z,2025-07-17T15:57:51.329692071Z,160,2,1108,C,A,14.760000000,100,0,312771829,0,165601,267272442,ARL,,13.28,100,1,13.04,2,1,13.03,100,1,12.73,100,1,12.71,100,1,12.5,700,1,12.46,200,1,12.43,700,1,12.42,700,1,12.37,700,1,14.1,2,1,14.15,100,1,14.28,100,1,14.4,100,1,14.56,800,1,14.6,700,1,14.68,1400,1,14.72,100,1,14.81,100,1,14.89,100,1,2,312771829
2025-07-17T15:57:51.329857672Z,2025-07-17T15:57:51.329692071Z,160,2,1108,A,A,14.890000000,100,0,319985025,130,165601,267272442,ARL,,13.28,100,1,13.04,2,1,13.03,100,1,12.73,100,1,12.71,100,1,12.5,700,1,12.46,200,1,12.43,700,1,12.42,700,1,12.37,700,1,14.1,2,1,14.15,100,1,14.28,100,1,14.4,100,1,14.56,800,1,14.6,700,1,14.68,1400,1,14.72,100,1,14.81,100,1,14.89,200,1,2,319985025
2025-07-17T15:57:51.339328219Z,2025-07-17T15:57:51.339162512Z,160,2,1108,C,A,14.150000000,100,0,312774033,130,165707,267272660,ARL,,13.28,100,1,13.04,2,1,13.03,100,1,12.73,100,1,12.71,100,1,12.5,700,1,12.46,200,1,12.43,700,1,12.42,700,1,12.37,700,1,14.1,2,1,14.28,100,1,14.4,100,1,14.56,800,1,14.6,700,1,14.68,1400,1,14.72,100,1,14.81,100,1,14.89,200,1,14.96,100,1,2,312774033
2025-07-17T15:57:51.339382098Z,2025-07-17T15:57:51.339216923Z,160,2,1108,A,A,14.260000000,100,0,319985165,130,165175,267272665,ARL,,13.28,100,1,13.04,2,1,13.03,100,1,12.73,100,1,12.71,100,1,12.5,700,1,12.46,200,1,12.43,700,1,12.42,700,1,12.37,700,1,14.1,2,1,14.26,100,1,14.28,100,1,14.4,100,1,14.56,800,1,14.6,700,1,14.68,1400,1,14.72,100,1,14.81,100,1,14.89,200,1,2,319985165
2025-07-17T15:57:51.379736852Z,2025-07-17T15:57:51.379570470Z,160,2,1108,C,A,15.000000000,100,0,319985021,0,166382,267273071,ARL,,13.28,100,1,13.04,2,1,13.03,100,1,12.73,100,1,12.71,100,1,12.5,700,1,12.46,200,1,12.43,700,1,12.42,700,1,12.37,700,1,14.1,2,1,14.26,100,1,14.28,100,1,14.4,100,1,14.56,800,1,14.6,700,1,14.68,1400,1,14.72,100,1,14.81,100,1,14.89,200,1,2,319985021
2025-07-17T15:57:51.379736852Z,2025-07-17T15:57:51.379570470Z,160,2,1108,A,A,15.060000000,100,0,319985497,128,166382,267273071,ARL,,13.28,100,1,13.04,2,1,13.03,100,1,12.73,100,1,12.71,100,1,12.5,700,1,12.46,200,1,12.43,700,1,12.42,700,1,12.37,700,1,14.1,2,1,14.26,100,1,14.28,100,1,14.4,100,1,14.56,800,1,14.6,700,1,14.68,1400,1,14.72,100,1,14.81,100,1,14.89,200,1,2,319985497
2025-07-17T15:57:52.378369524Z,2025-07-17T15:57:52.378204338Z,160,2,1108,A,A,14.110000000,100,0,320000233,130,165186,267283873,ARL,,13.28,100,1,13.04,2,1,13.03,100,1,12.73,100,1,12.71,100,1,12.5,700,1,12.46,200,1,12.43,700,1,12.42,700,1,12.37,700,1,14.1,2,1,14.11,100,1,14.26,100,1,14.28,100,1,14.4,100,1,14.56,800,1,14.6,700,1,14.68,1400,1,14.72,100,1,14.81,100,1,2,320000233
2025-07-17T15:58:14.483909354Z,2025-07-17T15:58:14.483743947Z,160,2,1108,A,A,13.760000000,4,0,320484625,130,165407,267657011,ARL,,13.28,100,1,13.04,2,1,13.03,100,1,12.73,100,1,12.71,100,1,12.5,700,1,12.46,200,1,12.43,700,1,12.42,700,1,12.37,700,1,13.76,4,1,14.1,2,1,14.11,100,1,14.26,100,1,14.28,100,1,14.4,100,1,14.56,800,1,14.6,700,1,14.68,1400,1,14.72,100,1,2,320484625
2025-07-17T15:58:14.484164551Z,2025-07-17T15:58:14.483999049Z,160,2,1108,C,A,14.110000000,100,0,320000233,0,165502,267657013,ARL,,13.28,100,1,13.04,2,1,13.03,100,1,12.73,100,1,12.71,100,1,12.5,700,1,12.46,200,1,12.43,700,1,12.42,700,1,12.37,700,1,13.76,4,1,14.1,2,1,14.26,100,1,14.28,100,1,14.4,100,1,14.56,800,1,14.6,700,1,14.68,1400,1,14.72,100,1,14.81,100,1,2,320000233
2025-07-17T15:58:14.484164551Z,2025-07-17T15:58:14.483999049Z,160,2,1108,A,A,13.770000000,100,0,320484637,130,165502,267657013,ARL,,13.28,100,1,13.04,2,1,13.03,100,1,12.73,100,1,12.71,100,1,12.5,700,1,12.46,200,1,12.43,700,1,12.42,700,1,12.37,700,1,13.76,4,1,13.77,100,1,14.1,2,1,14.26,100,1,14.28,100,1,14.4,100,1,14.56,800,1,14.6,700,1,14.68,1400,1,14.72,100,1,2,320484637
2025-07-17T15:58:14.484183413Z,2025-07-17T15:58:14.484017806Z,160,2,1108,C,B,13.280000000,100,0,316924721,130,165607,267657014,ARL,,13.04,2,1,13.03,100,1,12.73,100,1,12.71,100,1,12.5,700,1,12.46,200,1,12.43,700,1,12.42,700,1,12.37,700,1,12.36,200,1,13.76,4,1,13.77,100,1,14.1,2,1,14.26,100,1,14.28,100,1,14.4,100,1,14.56,800,1,14.6,700,1,14.68,1400,1,14.72,100,1,2,316924721
2025-07-17T15:58:14.484312532Z,2025-07-17T15:58:14.484147359Z,160,2,1108,A,A,13.790000000,100,0,320484661,130,165173,267657020,ARL,,13.04,2,1,13.03,100,1,12.73,100,1,12.71,100,1,12.5,700,1,12.46,200,1,12.43,700,1,12.42,700,1,12.37,700,1,12.36,200,1,13.76,4,1,13.77,100,1,13.79,100,1,14.1,2,1,14.26,100,1,14.28,100,1,14.4,100,1,14.56,800,1,14.6,700,1,14.68,1400,1,2,320484661
2025-07-17T15:58:14.484902175Z,2025-07-17T15:58:14.484736787Z,160,2,1108,C,A,15.060000000,100,0,319985497,0,165388,267657063,ARL,,13.04,2,1,13.03,100,1,12.73,100,1,12.71,100,1,12.5,700,1,12.46,200,1,12.43,700,1,12.42,700,1,12.37,700,1,12.36,200,1,13.76,4,1,13.77,100,1,13.79,100,1,14.1,2,1,14.26,100,1,14.28,100,1,14.4,100,1,14.56,800,1,14.6,700,1,14.68,1400,1,2,319985497
2025-07-17T15:58:14.484902175Z,2025-07-17T15:58:14.484736787Z,160,2,1108,A,A,14.840000000,100,0,320484709,130,165388,267657063,ARL,,13.04,2,1,13.03,100,1,12.73,100,1,12.71,100,1,12.5,700,1,12.46,200,1,12.43,700,1,12.42,700,1,12.37,700,1,12.36,200,1,13.76,4,1,13.77,100,1,13.79,100,1,14.1,2,1,14.26,100,1,14.28,100,1,14.4,100,1,14.56,800,1,14.6,700,1,14.68,1400,1,2,320484709
2025-07-17T15:58:14.484927848Z,2025-07-17T15:58:14.484761664Z,160,2,1108,C,A,13.760000000,4,0,320484625,128,166184,267657070,ARL,,13.04,2,1,13.03,100,1,12.73,100,1,12.71,100,1,12.5,700,1,12.46,200,1,12.43,700,1,12.42,700,1,12.37,700,1,12.36,200,1,13.77,100,1,13.79,100,1,14.1,2,1,14.26,100,1,14.28,100,1,14.4,100,1,14.56,800,1,14.6,700,1,14.68,1400,1,14.72,100,1,2,320484625
2025-07-17T15:58:14.484963870Z,2025-07-17T15:58:14.484798779Z,160,2,1108,C,A,13.770000000,100,0,320484637,130,165091,267657073,ARL,,13.04,2,1,13.03,100,1,12.73,100,1,12.71,100,1,12.5,700,1,12.46,200,1,12.43,700,1,12.42,700,1,12.37,700,1,12.36,200,1,13.79,100,1,14.1,2,1,14.26,100,1,14.28,100,1,14.4,100,1,14.56,800,1,14.6,700,1,14.68,1400,1,14.72,100,1,14.81,100,1,2,320484637
2025-07-17T15:58:14.485392903Z,2025-07-17T15:58:14.485227487Z,160,2,1108,C,A,14.810000000,100,0,312771781,0,165416,267657092,ARL,,13.04,2,1,13.03,100,1,12.73,100,1,12.71,100,1,12.5,700,1,12.46,200,1,12.43,700,1,12.42,700,1,12.37,700,1,12.36,200,1,13.79,100,1,14.1,2,1,14.26,100,1,14.28,100,1,14.4,100,1,14.56,800,1,14.6,700,1,14.68,1400,1,14.72,100,1,14.84,100,1,2,312771781
2025-07-17T15:58:14.485392903Z,2025-07-17T15:58:14.485227487Z,160,2,1108,A,A,14.680000000,100,0,320484781,130,165416,267657092,ARL,,13.04,2,1,13.03,100,1,12.73,100,1,12.71,100,1,12.5,700,1,12.46,200,1,12.43,700,1,12.42,700,1,12.37,700,1,12.36,200,1,13.79,100,1,14.1,2,1,14.26,100,1,14.28,100,1,14.4,100,1,14.56,800,1,14.6,700,1,14.68,1500,1,14.72,100,1,14.84,100,1,2,320484781
2025-07-17T15:58:14.485831602Z,2025-07-17T15:58:14.485666254Z,160,2,1108,C,A,16.020000000,100,0,312772057,0,165348,267657097,ARL,,13.04,2,1,13.03,100,1,12.73,100,1,12.71,100,1,12.5,700,1,12.46,200,1,12.43,700,1,12.42,700,1,12.37,700,1,12.36,200,1,13.79,100,1,14.1,2,1,14.26,100,1,14.28,100,1,14.4,100,1,14.56,800,1,14.6,700,1,14.68,1500,1,14.72,100,1,14.84,100,1,2,312772057
2025-07-17T15:58:14.485831602Z,2025-07-17T15:58:14.485666254Z,160,2,1108,A,A,15.860000000,100,0,320484817,130,165348,267657097,ARL,,13.04,2,1,13.03,100,1,12.73,100,1,12.71,100,1,12.5,700,1,12.46,200,1,12.43,700,1,12.42,700,1,12.37,700,1,12.36,200,1,13.79,100,1,14.1,2,1,14.26,100,1,14.28,100,1,14.4,100,1,14.56,800,1,14.6,700,1,14.68,1500,1,14.72,100,1,14.84,100,1,2,320484817
2025-07-17T15:58:14.485850874Z,2025-07-17T15:58:14.485685308Z,160,2,1108,C,A,14.960000000,100,0,312772869,0,165566,267657098,ARL,,13.04,2,1,13.03,100,1,12.73,100,1,12.71,100,1,12.5,700,1,12.46,200,1,12.43,700,1,12.42,700,1,12.37,700,1,12.36,200,1,13.79,100,1,14.1,2,1,14.26,100,1,14.28,100,1,14.4,100,1,14.56,800,1,14.6,700,1,14.68,1500,1,14.72,100,1,14.84,100,1,2,312772869
2025-07-17T15:58:14.485850874Z,2025-07-17T15:58:14.485685308Z,160,2,1108,A,A,14.760000000,100,0,320484821,130,165566,267657098,ARL,,13.04,2,1,13.03,100,1,12.73,100,1,12.71,100,1,12.5,700,1,12.46,200,1,12.43,700,1,12.42,700,1,12.37,700,1,12.36,200,1,13.79,100,1,14.1,2,1,14.26,100,1,14.28,100,1,14.4,100,1,14.56,800,1,14.6,700,1,14.68,1500,1,14.72,100,1,14.76,100,1,2,320484821
2025-07-17T15:58:14.485989643Z,2025-07-17T15:58:14.485824228Z,160,2,1108,C,A,14.890000000,100,0,319985025,0,165415,267657101,ARL,,13.04,2,1,13.03,100,1,12.73,100,1,12.71,100,1,12.5,700,1,12.46,200,1,12.43,700,1,12.42,700,1,12.37,700,1,12.36,200,1,13.79,100,1,14.1,2,1,14.26,100,1,14.28,100,1,14.4,100,1,14.56,800,1,14.6,700,1,14.68,1500,1,14.72,100,1,14.76,100,1,2,319985025
2025-07-17T15:58:14.485989643Z,2025-07-17T15:58:14.485824228Z,160,2,1108,A,A,14.690000000,100,0,320484825,130,165415,267657101,ARL,,13.04,2,1,13.03,100,1,12.73,100,1,12.71,100,1,12.5,700,1,12.46,200,1,12.43,700,1,12.42,700,1,12.37,700,1,12.36,200,1,13.79,100,1,14.1,2,1,14.26,100,1,14.28,100,1,14.4,100,1,14.56,800,1,14.6,700,1,14.68,1500,1,14.69,100,1,14.72,100,1,2,320484825
2025-07-17T15:58:14.486406355Z,2025-07-17T15:58:14.486240860Z,160,2,1108,C,A,17.700000000,100,0,312772009,0,165495,267657116,ARL,,13.04,2,1,13.03,100,1,12.73,100,1,12.71,100,1,12.5,700,1,12.46,200,1,12.43,700,1,12.42,700,1,12.37,700,1,12.36,200,1,13.79,100,1,14.1,2,1,14.26,100,1,14.28,100,1,14.4,100,1,14.56,800,1,14.6,700,1,14.68,1500,1,14.69,100,1,14.72,100,1,2,312772009
2025-07-17T15:58:14.486406355Z,2025-07-17T15:58:14.486240860Z,160,2,1108,A,A,17.520000000,100,0,320484837,130,165495,267657116,ARL,,13.04,2,1,13.03,100,1,12.73,100,1,12.71,100,1,12.5,700,1,12.46,200,1,12.43,700,1,12.42,700,1,12.37,700,1,12.36,200,1,13.79,100,1,14.1,2,1,14.26,100,1,14.28,100,1,14.4,100,1,14.56,800,1,14.6,700,1,14.68,1500,1,14.69,100,1,14.72,100,1,2,320484837
2025-07-17T15:58:14.508177256Z,2025-07-17T15:58:14.508012098Z,160,2,1108,C,A,14.260000000,100,0,319985165,130,165158,267657330,ARL,,13.04,2,1,13.03,100,1,12.73,100,1,12.71,100,1,12.5,700,1,12.46,200,1,12.43,700,1,12.42,700,1,12.37,700,1,12.36,200,1,13.79,100,1,14.1,2,1,14.28,100,1,14.4,100,1,14.56,800,1,14.6,700,1,14.68,1500,1,14.69,100,1,14.72,100,1,14.76,100,1,2,319985165
2025-07-17T15:58:14.508227890Z,2025-07-17T15:58:14.508062605Z,160,2,1108,A,A,14.050000000,100,0,320484985,130,165285,267657333,ARL,,13.04,2,1,13.03,100,1,12.73,100,1,12.71,100,1,12.5,700,1,12.46,200,1,12.43,700,1,12.42,700,1,12.37,700,1,12.36,200,1,13.79,100,1,14.05,100,1,14.1,2,1,14.28,100,1,14.4,100,1,14.56,800,1,14.6,700,1,14.68,1500,1,14.69,100,1,14.72,100,1,2,320484985
2025-07-17T15:58:14.529557108Z,2025-07-17T15:58:14.529391743Z,160,2,1108,A,B,13.020000000,100,0,320485385,130,165365,267657561,ARL,,13.04,2,1,13.03,100,1,13.02,100,1,12.73,100,1,12.71,100,1,12.5,700,1,12.46,200,1,12.43,700,1,12.42,700,1,12.37,700,1,13.79,100,1,14.05,100,1,14.1,2,1,14.28,100,1,14.4,100,1,14.56,800,1,14.6,700,1,14.68,1500,1,14.69,100,1,14.72,100,1,2,320485385
2025-07-17T15:58:14.529578291Z,2025-07-17T15:58:14.529413184Z,160,2,1108,A,A,13.800000000,100,0,320485389,130,165107,267657562,ARL,,13.04,2,1,13.03,100,1,13.02,100,1,12.73,100,1,12.71,100,1,12.5,700,1,12.46,200,1,12.43,700,1,12.42,700,1,12.37,700,1,13.79,100,1,13.8,100,1,14.05,100,1,14.1,2,1,14.28,100,1,14.4,100,1,14.56,800,1,14.6,700,1,14.68,1500,1,14.69,100,1,2,320485389
2025-07-17T15:58:14.659899426Z,2025-07-17T15:58:14.659734381Z,160,2,1108,C,A,13.790000000,100,0,320484661,130,165045,267658873,ARL,,13.04,2,1,13.03,100,1,13.02,100,1,12.73,100,1,12.71,100,1,12.5,700,1,12.46,200,1,12.43,700,1,12.42,700,1,12.37,700,1,13.8,100,1,14.05,100,1,14.1,2,1,14.28,100,1,14.4,100,1,14.56,800,1,14.6,700,1,14.68,1500,1,14.69,100,1,14.72,100,1,2,320484661
2025-07-17T15:58:14.659939230Z,2025-07-17T15:58:14.659773896Z,160,2,1108,C,A,13.800000000,100,0,320485389,130,165334,267658879,ARL,,13.04,2,1,13.03,100,1,13.02,100,1,12.73,100,1,12.71,100,1,12.5,700,1,12.46,200,1,12.43,700,1,12.42,700,1,12.37,700,1,14.05,100,1,14.1,2,1,14.28,100,1,14.4,100,1,14.56,800,1,14.6,700,1,14.68,1500,1,14.69,100,1,14.72,100,1,14.76,100,1,2,320485389
2025-07-17T15:58:14.660667636Z,2025-07-17T15:58:14.660502341Z,160,2,1108,C,A,14.840000000,100,0,320484709,0,165295,267658892,ARL,,13.04,2,1,13.03,100,1,13.02,100,1,12.73,100,1,12.71,100,1,12.5,700,1,12.46,200,1,12.43,700,1,12.42,700,1,12.37,700,1,14.05,100,1,14.1,2,1,14.28,100,1,14.4,100,1,14.56,800,1,14.6,700,1,14.68,1500,1,14.69,100,1,14.72,100,1,14.76,100,1,2,320484709
2025-07-17T15:58:14.660667636Z,2025-07-17T15:58:14.660502341Z,160,2,1108,A,A,14.910000000,100,0,320486925,130,165295,267658892,ARL,,13.04,2,1,13.03,100,1,13.02,100,1,12.73,100,1,12.71,100,1,12.5,700,1,12.46,200,1,12.43,700,1,12.42,700,1,12.37,700,1,14.05,100,1,14.1,2,1,14.28,100,1,14.4,100,1,14.56,800,1,14.6,700,1,14.68,1500,1,14.69,100,1,14.72,100,1,14.76,100,1,2,320486925
2025-07-17T15:58:14.664378962Z,2025-07-17T15:58:14.664213722Z,160,2,1108,C,A,17.520000000,100,0,320484837,0,165240,267658928,ARL,,13.04,2,1,13.03,100,1,13.02,100,1,12.73,100,1,12.71,100,1,12.5,700,1,12.46,200,1,12.43,700,1,12.42,700,1,12.37,700,1,14.05,100,1,14.1,2,1,14.28,100,1,14.4,100,1,14.56,800,1,14.6,700,1,14.68,1500,1,14.69,100,1,14.72,100,1,14.76,100,1,2,320484837
2025-07-17T15:58:14.664378962Z,2025-07-17T15:58:14.664213722Z,160,2,1108,A,A,17.760000000,100,0,320486937,130,165240,267658928,ARL,,13.04,2,1,13.03,100,1,13.02,100,1,12.73,100,1,12.71,100,1,12.5,700,1,12.46,200,1,12.43,700,1,12.42,700,1,12.37,700,1,14.05,100,1,14.1,2,1,14.28,100,1,14.4,100,1,14.56,800,1,14.6,700,1,14.68,1500,1,14.69,100,1,14.72,100,1,14.76,100,1,2,320486937
2025-07-17T15:58:14.664939310Z,2025-07-17T15:58:14.664774078Z,160,2,1108,C,A,15.860000000,100,0,320484817,0,165232,267658931,ARL,,13.04,2,1,13.03,100,1,13.02,100,1,12.73,100,1,12.71,100,1,12.5,700,1,12.46,200,1,12.43,700,1,12.42,700,1,12.37,700,1,14.05,100,1,14.1,2,1,14.28,100,1,14.4,100,1,14.56,800,1,14.6,700,1,14.68,1500,1,14.69,100,1,14.72,100,1,14.76,100,1,2,320484817
2025-07-17T15:58:14.664939310Z,2025-07-17T15:58:14.664774078Z,160,2,1108,A,A,16.080000000,100,0,320486945,130,165232,267658931,ARL,,13.04,2,1,13.03,100,1,13.02,100,1,12.73,100,1,12.71,100,1,12.5,700,1,12.46,200,1,12.43,700,1,12.42,700,1,12.37,700,1,14.05,100,1,14.1,2,1,14.28,100,1,14.4,100,1,14.56,800,1,14.6,700,1,14.68,1500,1,14.69,100,1,14.72,100,1,14.76,100,1,2,320486945
2025-07-17T15:58:14.672315806Z,2025-07-17T15:58:14.672150755Z,160,2,1108,C,A,14.050000000,100,0,320484985,130,165051,267658982,ARL,,13.04,2,1,13.03,100,1,13.02,100,1,12.73,100,1,12.71,100,1,12.5,700,1,12.46,200,1,12.43,700,1,12.42,700,1,12.37,700,1,14.1,2,1,14.28,100,1,14.4,100,1,14.56,800,1,14.6,700,1,14.68,1500,1,14.69,100,1,14.72,100,1,14.76,100,1,14.89,100,1,2,320484985
2025-07-17T15:58:14.672365974Z,2025-07-17T15:58:14.672200872Z,160,2,1108,A,A,14.120000000,100,0,320487017,130,165102,267658983,ARL,,13.04,2,1,13.03,100,1,13.02,100,1,12.73,100,1,12.71,100,1,12.5,700,1,12.46,200,1,12.43,700,1,12.42,700,1,12.37,700,1,14.1,2,1,14.12,100,1,14.28,100,1,14.4,100,1,14.56,800,1,14.6,700,1,14.68,1500,1,14.69,100,1,14.72,100,1,14.76,100,1,2,320487017
2025-07-17T15:58:14.673184116Z,2025-07-17T15:58:14.673019194Z,160,2,1108,C,A,14.120000000,100,0,320487017,130,164922,267658989,ARL,,13.04,2,1,13.03,100,1,13.02,100,1,12.73,100,1,12.71,100,1,12.5,700,1,12.46,200,1,12.43,700,1,12.42,700,1,12.37,700,1,14.1,2,1,14.28,100,1,14.4,100,1,14.56,800,1,14.6,700,1,14.68,1500,1,14.69,100,1,14.72,100,1,14.76,100,1,14.89,100,1,2,320487017
2025-07-17T15:58:14.673230480Z,2025-07-17T15:58:14.673065320Z,160,2,1108,A,A,14.260000000,100,0,320487025,130,165160,267658990,ARL,,13.04,2,1,13.03,100,1,13.02,100,1,12.73,100,1,12.71,100,1,12.5,700,1,12.46,200,1,12.43,700,1,12.42,700,1,12.37,700,1,14.1,2,1,14.26,100,1,14.28,100,1,14.4,100,1,14.56,800,1,14.6,700,1,14.68,1500,1,14.69,100,1,14.72,100,1,14.76,100,1,2,320487025
2025-07-17T15:58:14.682945541Z,2025-07-17T15:58:14.682780396Z,160,2,1108,C,A,14.760000000,100,0,320484821,0,165145,267659018,ARL,,13.04,2,1,13.03,100,1,13.02,100,1,12.73,100,1,12.71,100,1,12.5,700,1,12.46,200,1,12.43,700,1,12.42,700,1,12.37,700,1,14.1,2,1,14.26,100,1,14.28,100,1,14.4,100,1,14.56,800,1,14.6,700,1,14.68,1500,1,14.69,100,1,14.72,100,1,14.89,100,1,2,320484821
2025-07-17T15:58:14.682945541Z,2025-07-17T15:58:14.682780396Z,160,2,1108,A,A,14.960000000,100,0,320487105,130,165145,267659018,ARL,,13.04,2,1,13.03,100,1,13.02,100,1,12.73,100,1,12.71,100,1,12.5,700,1,12.46,200,1,12.43,700,1,12.42,700,1,12.37,700,1,14.1,2,1,14.26,100,1,14.28,100,1,14.4,100,1,14.56,800,1,14.6,700,1,14.68,1500,1,14.69,100,1,14.72,100,1,14.89,100,1,2,320487105
2025-07-17T15:58:14.710787891Z,2025-07-17T15:58:14.710622495Z,160,2,1108,C,A,14.910000000,100,0,320486925,0,165396,267659178,ARL,,13.04,2,1,13.03,100,1,13.02,100,1,12.73,100,1,12.71,100,1,12.5,700,1,12.46,200,1,12.43,700,1,12.42,700,1,12.37,700,1,14.1,2,1,14.26,100,1,14.28,100,1,14.4,100,1,14.56,800,1,14.6,700,1,14.68,1500,1,14.69,100,1,14.72,100,1,14.89,100,1,2,320486925
2025-07-17T15:58:14.710787891Z,2025-07-17T15:58:14.710622495Z,160,2,1108,A,A,15.060000000,100,0,320487357,130,165396,267659178,ARL,,13.04,2,1,13.03,100,1,13.02,100,1,12.73,100,1,12.71,100,1,12.5,700,1,12.46,200,1,12.43,700,1,12.42,700,1,12.37,700,1,14.1,2,1,14.26,100,1,14.28,100,1,14.4,100,1,14.56,800,1,14.6,700,1,14.68,1500,1,14.69,100,1,14.72,100,1,14.89,100,1,2,320487357
2025-07-17T15:58:15.564070256Z,2025-07-17T15:58:15.563904700Z,160,2,1108,C,A,14.680000000,100,0,320484781,0,165556,267672469,ARL,,13.04,2,1,13.03,100,1,13.02,100,1,12.73,100,1,12.71,100,1,12.5,700,1,12.46,200,1,12.43,700,1,12.42,700,1,12.37,700,1,14.1,2,1,14.26,100,1,14.28,100,1,14.4,100,1,14.56,800,1,14.6,700,1,14.68,1400,1,14.69,100,1,14.72,100,1,14.89,100,1,2,320484781
2025-07-17T15:58:15.564070256Z,2025-07-17T15:58:15.563904700Z,160,2,1108,A,A,14.870000000,100,0,320504473,130,165556,267672469,ARL,,13.04,2,1,13.03,100,1,13.02,100,1,12.73,100,1,12.71,100,1,12.5,700,1,12.46,200,1,12.43,700,1,12.42,700,1,12.37,700,1,14.1,2,1,14.26,100,1,14.28,100,1,14.4,100,1,14.56,800,1,14.6,700,1,14.68,1400,1,14.69,100,1,14.72,100,1,14.87,100,1,2,320504473
2025-07-17T15:58:15.577719796Z,2025-07-17T15:58:15.577554368Z,160,2,1108,C,A,14.690000000,100,0,320484825,0,165428,267672549,ARL,,13.04,2,1,13.03,100,1,13.02,100,1,12.73,100,1,12.71,100,1,12.5,700,1,12.46,200,1,12.43,700,1,12.42,700,1,12.37,700,1,14.1,2,1,14.26,100,1,14.28,100,1,14.4,100,1,14.56,800,1,14.6,700,1,14.68,1400,1,14.72,100,1,14.87,100,1,14.89,100,1,2,320484825
2025-07-17T15:58:15.577719796Z,2025-07-17T15:58:15.577554368Z,160,2,1108,A,A,14.880000000,100,0,320504609,130,165428,267672549,ARL,,13.04,2,1,13.03,100,1,13.02,100,1,12.73,100,1,12.71,100,1,12.5,700,1,12.46,200,1,12.43,700,1,12.42,700,1,12.37,700,1,14.1,2,1,14.26,100,1,14.28,100,1,14.4,100,1,14.56,800,1,14.6,700,1,14.68,1400,1,14.72,100,1,14.87,100,1,14.88,100,1,2,320504609
2025-07-17T15:58:16.502080515Z,2025-07-17T15:58:16.501915292Z,160,2,1108,A,A,14.110000000,100,0,320519893,130,165223,267685252,ARL,,13.04,2,1,13.03,100,1,13.02,100,1,12.73,100,1,12.71,100,1,12.5,700,1,12.46,200,1,12.43,700,1,12.42,700,1,12.37,700,1,14.1,2,1,14.11,100,1,14.26,100,1,14.28,100,1,14.4,100,1,14.56,800,1,14.6,700,1,14.68,1400,1,14.72,100,1,14.87,100,1,2,320519893
2025-07-17T15:58:19.965200980Z,2025-07-17T15:58:19.965034325Z,160,2,1108,A,A,13.940000000,15,0,320588689,130,166655,267738403,ARL,,13.04,2,1,13.03,100,1,13.02,100,1,12.73,100,1,12.71,100,1,12.5,700,1,12.46,200,1,12.43,700,1,12.42,700,1,12.37,700,1,13.94,15,1,14.1,2,1,14.11,100,1,14.26,100,1,14.28,100,1,14.4,100,1,14.56,800,1,14.6,700,1,14.68,1400,1,14.72,100,1,2,320588689
2025-07-17T15:58:20.237833402Z,2025-07-17T15:58:20.237668047Z,160,2,1108,C,A,14.110000000,100,0,320519893,0,165355,267745213,ARL,,13.04,2,1,13.03,100,1,13.02,100,1,12.73,100,1,12.71,100,1,12.5,700,1,12.46,200,1,12.43,700,1,12.42,700,1,12.37,700,1,13.94,15,1,14.1,2,1,14.26,100,1,14.28,100,1,14.4,100,1,14.56,800,1,14.6,700,1,14.68,1400,1,14.72,100,1,14.87,100,1,2,320519893
2025-07-17T15:58:20.237833402Z,2025-07-17T15:58:20.237668047Z,160,2,1108,A,A,13.950000000,100,0,320595817,130,165355,267745213,ARL,,13.04,2,1,13.03,100,1,13.02,100,1,12.73,100,1,12.71,100,1,12.5,700,1,12.46,200,1,12.43,700,1,12.42,700,1,12.37,700,1,13.94,15,1,13.95,100,1,14.1,2,1,14.26,100,1,14.28,100,1,14.4,100,1,14.56,800,1,14.6,700,1,14.68,1400,1,14.72,100,1,2,320595817
2025-07-17T15:58:20.705512171Z,2025-07-17T15:58:20.705344578Z,160,2,1108,C,A,13.940000000,15,0,320588689,128,167593,267754327,ARL,,13.04,2,1,13.03,100,1,13.02,100,1,12.73,100,1,12.71,100,1,12.5,700,1,12.46,200,1,12.43,700,1,12.42,700,1,12.37,700,1,13.95,100,1,14.1,2,1,14.26,100,1,14.28,100,1,14.4,100,1,14.56,800,1,14.6,700,1,14.68,1400,1,14.72,100,1,14.87,100,1,2,320588689
2025-07-17T15:58:30.800053062Z,2025-07-17T15:58:30.799887713Z,160,2,1108,A,A,13.890000000,15,0,320833897,130,165349,267913947,ARL,,13.04,2,1,13.03,100,1,13.02,100,1,12.73,100,1,12.71,100,1,12.5,700,1,12.46,200,1,12.43,700,1,12.42,700,1,12.37,700,1,13.89,15,1,13.95,100,1,14.1,2,1,14.26,100,1,14.28,100,1,14.4,100,1,14.56,800,1,14.6,700,1,14.68,1400,1,14.72,100,1,2,320833897
2025-07-17T15:58:30.905657319Z,2025-07-17T15:58:30.905491759Z,160,2,1108,C,A,13.950000000,100,0,320595817,0,165560,267919515,ARL,,13.04,2,1,13.03,100,1,13.02,100,1,12.73,100,1,12.71,100,1,12.5,700,1,12.46,200,1,12.43,700,1,12.42,700,1,12.37,700,1,13.89,15,1,14.1,2,1,14.26,100,1,14.28,100,1,14.4,100,1,14.56,800,1,14.6,700,1,14.68,1400,1,14.72,100,1,14.87,100,1,2,320595817
2025-07-17T15:58:30.905657319Z,2025-07-17T15:58:30.905491759Z,160,2,1108,A,A,13.900000000,100,0,320839125,130,165560,267919515,ARL,,13.04,2,1,13.03,100,1,13.02,100,1,12.73,100,1,12.71,100,1,12.5,700,1,12.46,200,1,12.43,700,1,12.42,700,1,12.37,700,1,13.89,15,1,13.9,100,1,14.1,2,1,14.26,100,1,14.28,100,1,14.4,100,1,14.56,800,1,14.6,700,1,14.68,1400,1,14.72,100,1,2,320839125
2025-07-17T15:58:30.906412286Z,2025-07-17T15:58:30.906246950Z,160,2,1108,C,A,15.060000000,100,0,320487357,0,165336,267919540,ARL,,13.04,2,1,13.03,100,1,13.02,100,1,12.73,100,1,12.71,100,1,12.5,700,1,12.46,200,1,12.43,700,1,12.42,700,1,12.37,700,1,13.89,15,1,13.9,100,1,14.1,2,1,14.26,100,1,14.28,100,1,14.4,100,1,14.56,800,1,14.6,700,1,14.68,1400,1,14.72,100,1,2,320487357
2025-07-17T15:58:30.906412286Z,2025-07-17T15:58:30.906246950Z,160,2,1108,A,A,14.980000000,100,0,320839149,130,165336,267919540,ARL,,13.04,2,1,13.03,100,1,13.02,100,1,12.73,100,1,12.71,100,1,12.5,700,1,12.46,200,1,12.43,700,1,12.42,700,1,12.37,700,1,13.89,15,1,13.9,100,1,14.1,2,1,14.26,100,1,14.28,100,1,14.4,100,1,14.56,800,1,14.6,700,1,14.68,1400,1,14.72,100,1,2,320839149
2025-07-17T15:58:30.916726353Z,2025-07-17T15:58:30.916561264Z,160,2,1108,C,A,14.260000000,100,0,320487025,130,165089,267919917,ARL,,13.04,2,1,13.03,100,1,13.02,100,1,12.73,100,1,12.71,100,1,12.5,700,1,12.46,200,1,12.43,700,1,12.42,700,1,12.37,700,1,13.89,15,1,13.9,100,1,14.1,2,1,14.28,100,1,14.4,100,1,14.56,800,1,14.6,700,1,14.68,1400,1,14.72,100,1,14.87,100,1,2,320487025
2025-07-17T15:58:30.916784278Z,2025-07-17T15:58:30.916619122Z,160,2,1108,A,A,14.180000000,100,0,320839577,130,165156,267919919,ARL,,13.04,2,1,13.03,100,1,13.02,100,1,12.73,100,1,12.71,100,1,12.5,700,1,12.46,200,1,12.43,700,1,12.42,700,1,12.37,700,1,13.89,15,1,13.9,100,1,14.1,2,1,14.18,100,1,14.28,100,1,14.4,100,1,14.56,800,1,14.6,700,1,14.68,1400,1,14.72,100,1,2,320839577
2025-07-17T15:58:31.124388717Z,2025-07-17T15:58:31.124222733Z,160,2,1108,C,A,14.870000000,100,0,320504473,0,165984,267925564,ARL,,13.04,2,1,13.03,100,1,13.02,100,1,12.73,100,1,12.71,100,1,12.5,700,1,12.46,200,1,12.43,700,1,12.42,700,1,12.37,700,1,13.89,15,1,13.9,100,1,14.1,2,1,14.18,100,1,14.28,100,1,14.4,100,1,14.56,800,1,14.6,700,1,14.68,1400,1,14.72,100,1,2,320504473
2025-07-17T15:58:31.124388717Z,2025-07-17T15:58:31.124222733Z,160,2,1108,A,A,14.760000000,100,0,320845893,130,165984,267925564,ARL,,13.04,2,1,13.03,100,1,13.02,100,1,12.73,100,1,12.71,100,1,12.5,700,1,12.46,200,1,12.43,700,1,12.42,700,1,12.37,700,1,13.89,15,1,13.9,100,1,14.1,2,1,14.18,100,1,14.28,100,1,14.4,100,1,14.56,800,1,14.6,700,1,14.68,1400,1,14.72,100,1,2,320845893
2025-07-17T15:58:31.136439248Z,2025-07-17T15:58:31.136273403Z,160,2,1108,C,A,14.880000000,100,0,320504609,0,165845,267925951,ARL,,13.04,2,1,13.03,100,1,13.02,100,1,12.73,100,1,12.71,100,1,12.5,700,1,12.46,200,1,12.43,700,1,12.42,700,1,12.37,700,1,13.89,15,1,13.9,100,1,14.1,2,1,14.18,100,1,14.28,100,1,14.4,100,1,14.56,800,1,14.6,700,1,14.68,1400,1,14.72,100,1,2,320504609
2025-07-17T15:58:31.136439248Z,2025-07-17T15:58:31.136273403Z,160,2,1108,A,A,14.770000000,100,0,320846429,130,165845,267925951,ARL,,13.04,2,1,13.03,100,1,13.02,100,1,12.73,100,1,12.71,100,1,12.5,700,1,12.46,200,1,12.43,700,1,12.42,700,1,12.37,700,1,13.89,15,1,13.9,100,1,14.1,2,1,14.18,100,1,14.28,100,1,14.4,100,1,14.56,800,1,14.6,700,1,14.68,1400,1,14.72,100,1,2,320846429
2025-07-17T15:58:40.799952243Z,2025-07-17T15:58:40.799787018Z,160,2,1108,A,A,13.830000000,15,0,321038033,130,165225,268074431,ARL,,13.04,2,1,13.03,100,1,13.02,100,1,12.73,100,1,12.71,100,1,12.5,700,1,12.46,200,1,12.43,700,1,12.42,700,1,12.37,700,1,13.83,15,1,13.89,15,1,13.9,100,1,14.1,2,1,14.18,100,1,14.28,100,1,14.4,100,1,14.56,800,1,14.6,700,1,14.68,1400,1,2,321038033
2025-07-17T15:58:43.690244473Z,2025-07-17T15:58:43.690078924Z,160,2,1108,C,A,13.900000000,100,0,320839125,0,165549,268115228,ARL,,13.04,2,1,13.03,100,1,13.02,100,1,12.73,100,1,12.71,100,1,12.5,700,1,12.46,200,1,12.43,700,1,12.42,700,1,12.37,700,1,13.83,15,1,13.89,15,1,14.1,2,1,14.18,100,1,14.28,100,1,14.4,100,1,14.56,800,1,14.6,700,1,14.68,1400,1,14.72,100,1,2,320839125
2025-07-17T15:58:43.690244473Z,2025-07-17T15:58:43.690078924Z,160,2,1108,A,A,13.840000000,100,0,321096769,130,165549,268115228,ARL,,13.04,2,1,13.03,100,1,13.02,100,1,12.73,100,1,12.71,100,1,12.5,700,1,12.46,200,1,12.43,700,1,12.42,700,1,12.37,700,1,13.83,15,1,13.84,100,1,13.89,15,1,14.1,2,1,14.18,100,1,14.28,100,1,14.4,100,1,14.56,800,1,14.6,700,1,14.68,1400,1,2,321096769
2025-07-17T15:58:43.690988921Z,2025-07-17T15:58:43.690823184Z,160,2,1108,C,A,14.980000000,100,0,320839149,0,165737,268115235,ARL,,13.04,2,1,13.03,100,1,13.02,100,1,12.73,100,1,12.71,100,1,12.5,700,1,12.46,200,1,12.43,700,1,12.42,700,1,12.37,700,1,13.83,15,1,13.84,100,1,13.89,15,1,14.1,2,1,14.18,100,1,14.28,100,1,14.4,100,1,14.56,800,1,14.6,700,1,14.68,1400,1,2,320839149
2025-07-17T15:58:43.690988921Z,2025-07-17T15:58:43.690823184Z,160,2,1108,A,A,14.910000000,100,0,321096793,130,165737,268115235,ARL,,13.04,2,1,13.03,100,1,13.02,100,1,12.73,100,1,12.71,100,1,12.5,700,1,12.46,200,1,12.43,700,1,12.42,700,1,12.37,700,1,13.83,15,1,13.84,100,1,13.89,15,1,14.1,2,1,14.18,100,1,14.28,100,1,14.4,100,1,14.56,800,1,14.6,700,1,14.68,1400,1,2,321096793
2025-07-17T15:58:43.693394500Z,2025-07-17T15:58:43.693228946Z,160,2,1108,C,A,17.760000000,100,0,320486937,0,165554,268115265,ARL,,13.04,2,1,13.03,100,1,13.02,100,1,12.73,100,1,12.71,100,1,12.5,700,1,12.46,200,1,12.43,700,1,12.42,700,1,12.37,700,1,13.83,15,1,13.84,100,1,13.89,15,1,14.1,2,1,14.18,100,1,14.28,100,1,14.4,100,1,14.56,800,1,14.6,700,1,14.68,1400,1,2,320486937
2025-07-17T15:58:43.693394500Z,2025-07-17T15:58:43.693228946Z,160,2,1108,A,A,17.580000000,100,0,321096825,130,165554,268115265,ARL,,13.04,2,1,13.03,100,1,13.02,100,1,12.73,100,1,12.71,100,1,12.5,700,1,12.46,200,1,12.43,700,1,12.42,700,1,12.37,700,1,13.83,15,1,13.84,100,1,13.89,15,1,14.1,2,1,14.18,100,1,14.28,100,1,14.4,100,1,14.56,800,1,14.6,700,1,14.68,1400,1,2,321096825
2025-07-17T15:58:43.695055785Z,2025-07-17T15:58:43.694890264Z,160,2,1108,C,A,16.080000000,100,0,320486945,0,165521,268115287,ARL,,13.04,2,1,13.03,100,1,13.02,100,1,12.73,100,1,12.71,100,1,12.5,700,1,12.46,200,1,12.43,700,1,12.42,700,1,12.37,700,1,13.83,15,1,13.84,100,1,13.89,15,1,14.1,2,1,14.18,100,1,14.28,100,1,14.4,100,1,14.56,800,1,14.6,700,1,14.68,1400,1,2,320486945
2025-07-17T15:58:43.695055785Z,2025-07-17T15:58:43.694890264Z,160,2,1108,A,A,15.920000000,100,0,321096889,130,165521,268115287,ARL,,13.04,2,1,13.03,100,1,13.02,100,1,12.73,100,1,12.71,100,1,12.5,700,1,12.46,200,1,12.43,700,1,12.42,700,1,12.37,700,1,13.83,15,1,13.84,100,1,13.89,15,1,14.1,2,1,14.18,100,1,14.28,100,1,14.4,100,1,14.56,800,1,14.6,700,1,14.68,1400,1,2,321096889
2025-07-17T15:58:43.716437124Z,2025-07-17T15:58:43.716271172Z,160,2,1108,C,A,14.960000000,100,0,320487105,0,165952,268115456,ARL,,13.04,2,1,13.03,100,1,13.02,100,1,12.73,100,1,12.71,100,1,12.5,700,1,12.46,200,1,12.43,700,1,12.42,700,1,12.37,700,1,13.83,15,1,13.84,100,1,13.89,15,1,14.1,2,1,14.18,100,1,14.28,100,1,14.4,100,1,14.56,800,1,14.6,700,1,14.68,1400,1,2,320487105
2025-07-17T15:58:43.716437124Z,2025-07-17T15:58:43.716271172Z,160,2,1108,A,A,14.810000000,100,0,321097197,130,165952,268115456,ARL,,13.04,2,1,13.03,100,1,13.02,100,1,12.73,100,1,12.71,100,1,12.5,700,1,12.46,200,1,12.43,700,1,12.42,700,1,12.37,700,1,13.83,15,1,13.84,100,1,13.89,15,1,14.1,2,1,14.18,100,1,14.28,100,1,14.4,100,1,14.56,800,1,14.6,700,1,14.68,1400,1,2,321097197
2025-07-17T15:58:44.903740109Z,2025-07-17T15:58:44.903574654Z,160,2,1108,A,A,13.830000000,100,0,321114473,130,165455,268129040,ARL,,13.04,2,1,13.03,100,1,13.02,100,1,12.73,100,1,12.71,100,1,12.5,700,1,12.46,200,1,12.43,700,1,12.42,700,1,12.37,700,1,13.83,115,1,13.84,100,1,13.89,15,1,14.1,2,1,14.18,100,1,14.28,100,1,14.4,100,1,14.56,800,1,14.6,700,1,14.68,1400,1,2,321114473
2025-07-17T15:58:44.924114268Z,2025-07-17T15:58:44.923948853Z,160,2,1108,C,A,14.180000000,100,0,320839577,130,165415,268129217,ARL,,13.04,2,1,13.03,100,1,13.02,100,1,12.73,100,1,12.71,100,1,12.5,700,1,12.46,200,1,12.43,700,1,12.42,700,1,12.37,700,1,13.83,115,1,13.84,100,1,13.89,15,1,14.1,2,1,14.28,100,1,14.4,100,1,14.56,800,1,14.6,700,1,14.68,1400,1,14.72,100,1,2,320839577
2025-07-17T15:58:44.924165875Z,2025-07-17T15:58:44.924000519Z,160,2,1108,A,A,14.110000000,100,0,321114729,130,165356,268129218,ARL,,13.04,2,1,13.03,100,1,13.02,100,1,12.73,100,1,12.71,100,1,12.5,700,1,12.46,200,1,12.43,700,1,12.42,700,1,12.37,700,1,13.83,115,1,13.84,100,1,13.89,15,1,14.1,2,1,14.11,100,1,14.28,100,1,14.4,100,1,14.56,800,1,14.6,700,1,14.68,1400,1,2,321114729
2025-07-17T15:58:51.241342265Z,2025-07-17T15:58:51.241176997Z,160,2,1108,C,A,13.890000000,15,0,320833897,130,165268,268212338,ARL,,13.04,2,1,13.03,100,1,13.02,100,1,12.73,100,1,12.71,100,1,12.5,700,1,12.46,200,1,12.43,700,1,12.42,700,1,12.37,700,1,13.83,115,1,13.84,100,1,14.1,2,1,14.11,100,1,14.28,100,1,14.4,100,1,14.56,800,1,14.6,700,1,14.68,1400,1,14.72,100,1,2,320833897
2025-07-17T15:58:51.254127339Z,2025-07-17T15:58:51.253961905Z,160,2,1108,A,A,13.800000000,100,0,321225725,130,165434,268212497,ARL,,13.04,2,1,13.03,100,1,13.02,100,1,12.73,100,1,12.71,100,1,12.5,700,1,12.46,200,1,12.43,700,1,12.42,700,1,12.37,700,1,13.8,100,1,13.83,115,1,13.84,100,1,14.1,2,1,14.11,100,1,14.28,100,1,14.4,100,1,14.56,800,1,14.6,700,1,14.68,1400,1,2,321225725
2025-07-17T15:58:51.254871890Z,2025-07-17T15:58:51.254706004Z,160,2,1108,C,A,14.910000000,100,0,321096793,0,165886,268212499,ARL,,13.04,2,1,13.03,100,1,13.02,100,1,12.73,100,1,12.71,100,1,12.5,700,1,12.46,200,1,12.43,700,1,12.42,700,1,12.37,700,1,13.8,100,1,13.83,115,1,13.84,100,1,14.1,2,1,14.11,100,1,14.28,100,1,14.4,100,1,14.56,800,1,14.6,700,1,14.68,1400,1,2,321096793
2025-07-17T15:58:51.254871890Z,2025-07-17T15:58:51.254706004Z,160,2,1108,A,A,14.870000000,100,0,321225745,130,165886,268212499,ARL,,13.04,2,1,13.03,100,1,13.02,100,1,12.73,100,1,12.71,100,1,12.5,700,1,12.46,200,1,12.43,700,1,12.42,700,1,12.37,700,1,13.8,100,1,13.83,115,1,13.84,100,1,14.1,2,1,14.11,100,1,14.28,100,1,14.4,100,1,14.56,800,1,14.6,700,1,14.68,1400,1,2,321225745
2025-07-17T15:58:51.260753179Z,2025-07-17T15:58:51.260587778Z,160,2,1108,C,A,13.830000000,100,0,321114473,130,165401,268212534,ARL,,13.04,2,1,13.03,100,1,13.02,100,1,12.73,100,1,12.71,100,1,12.5,700,1,12.46,200,1,12.43,700,1,12.42,700,1,12.37,700,1,13.8,100,1,13.83,15,1,13.84,100,1,14.1,2,1,14.11,100,1,14.28,100,1,14.4,100,1,14.56,800,1,14.6,700,1,14.68,1400,1,2,321114473
2025-07-17T15:58:53.579628288Z,2025-07-17T15:58:53.579462029Z,160,2,1108,C,A,13.830000000,15,0,321038033,130,166259,268250290,ARL,,13.04,2,1,13.03,100,1,13.02,100,1,12.73,100,1,12.71,100,1,12.5,700,1,12.46,200,1,12.43,700,1,12.42,700,1,12.37,700,1,13.8,100,1,13.84,100,1,14.1,2,1,14.11,100,1,14.28,100,1,14.4,100,1,14.56,800,1,14.6,700,1,14.68,1400,1,14.72,100,1,2,321038033
2025-07-17T15:58:53.580217445Z,2025-07-17T15:58:53.580052014Z,160,2,1108,C,A,13.840000000,100,0,321096769,0,165431,268250346,ARL,,13.04,2,1,13.03,100,1,13.02,100,1,12.73,100,1,12.71,100,1,12.5,700,1,12.46,200,1,12.43,700,1,12.42,700,1,12.37,700,1,13.8,100,1,14.1,2,1,14.11,100,1,14.28,100,1,14.4,100,1,14.56,800,1,14.6,700,1,14.68,1400,1,14.72,100,1,14.76,100,1,2,321096769
2025-07-17T15:58:53.580217445Z,2025-07-17T15:58:53.580052014Z,160,2,1108,A,A,13.810000000,100,0,321272581,130,165431,268250346,ARL,,13.04,2,1,13.03,100,1,13.02,100,1,12.73,100,1,12.71,100,1,12.5,700,1,12.46,200,1,12.43,700,1,12.42,700,1,12.37,700,1,13.8,100,1,13.81,100,1,14.1,2,1,14.11,100,1,14.28,100,1,14.4,100,1,14.56,800,1,14.6,700,1,14.68,1400,1,14.72,100,1,2,321272581
2025-07-17T15:58:54.584124215Z,2025-07-17T15:58:54.583958582Z,160,2,1108,C,A,14.770000000,100,0,320846429,0,165633,268265585,ARL,,13.04,2,1,13.03,100,1,13.02,100,1,12.73,100,1,12.71,100,1,12.5,700,1,12.46,200,1,12.43,700,1,12.42,700,1,12.37,700,1,13.8,100,1,13.81,100,1,14.1,2,1,14.11,100,1,14.28,100,1,14.4,100,1,14.56,800,1,14.6,700,1,14.68,1400,1,14.72,100,1,2,320846429
2025-07-17T15:58:54.584124215Z,2025-07-17T15:58:54.583958582Z,160,2,1108,A,A,14.650000000,100,0,321293737,130,165633,268265585,ARL,,13.04,2,1,13.03,100,1,13.02,100,1,12.73,100,1,12.71,100,1,12.5,700,1,12.46,200,1,12.43,700,1,12.42,700,1,12.37,700,1,13.8,100,1,13.81,100,1,14.1,2,1,14.11,100,1,14.28,100,1,14.4,100,1,14.56,800,1,14.6,700,1,14.65,100,1,14.68,1400,1,2,321293737
2025-07-17T15:58:54.584260712Z,2025-07-17T15:58:54.584094980Z,160,2,1108,C,A,14.760000000,100,0,320845893,0,165732,268265586,ARL,,13.04,2,1,13.03,100,1,13.02,100,1,12.73,100,1,12.71,100,1,12.5,700,1,12.46,200,1,12.43,700,1,12.42,700,1,12.37,700,1,13.8,100,1,13.81,100,1,14.1,2,1,14.11,100,1,14.28,100,1,14.4,100,1,14.56,800,1,14.6,700,1,14.65,100,1,14.68,1400,1,2,320845893
2025-07-17T15:58:54.584260712Z,2025-07-17T15:58:54.584094980Z,160,2,1108,A,A,14.640000000,100,0,321293741,130,165732,268265586,ARL,,13.04,2,1,13.03,100,1,13.02,100,1,12.73,100,1,12.71,100,1,12.5,700,1,12.46,200,1,12.43,700,1,12.42,700,1,12.37,700,1,13.8,100,1,13.81,100,1,14.1,2,1,14.11,100,1,14.28,100,1,14.4,100,1,14.56,800,1,14.6,700,1,14.64,100,1,14.65,100,1,2,321293741
2025-07-17T15:58:55.305104029Z,2025-07-17T15:58:55.304938318Z,160,2,1108,A,A,13.780000000,100,0,321309865,130,165711,268277940,ARL,,13.04,2,1,13.03,100,1,13.02,100,1,12.73,100,1,12.71,100,1,12.5,700,1,12.46,200,1,12.43,700,1,12.42,700,1,12.37,700,1,13.78,100,1,13.8,100,1,13.81,100,1,14.1,2,1,14.11,100,1,14.28,100,1,14.4,100,1,14.56,800,1,14.6,700,1,14.64,100,1,2,321309865
2025-07-17T15:58:55.307508305Z,2025-07-17T15:58:55.307342971Z,160,2,1108,C,A,14.720000000,100,0,312772061,130,165334,268277999,ARL,,13.04,2,1,13.03,100,1,13.02,100,1,12.73,100,1,12.71,100,1,12.5,700,1,12.46,200,1,12.43,700,1,12.42,700,1,12.37,700,1,13.78,100,1,13.8,100,1,13.81,100,1,14.1,2,1,14.11,100,1,14.28,100,1,14.4,100,1,14.56,800,1,14.6,700,1,14.64,100,1,2,312772061
2025-07-17T15:58:55.307637209Z,2025-07-17T15:58:55.307472032Z,160,2,1108,A,A,14.580000000,100,0,321309941,130,165177,268278004,ARL,,13.04,2,1,13.03,100,1,13.02,100,1,12.73,100,1,12.71,100,1,12.5,700,1,12.46,200,1,12.43,700,1,12.42,700,1,12.37,700,1,13.78,100,1,13.8,100,1,13.81,100,1,14.1,2,1,14.11,100,1,14.28,100,1,14.4,100,1,14.56,800,1,14.58,100,1,14.6,700,1,2,321309941
2025-07-17T15:58:55.311899965Z,2025-07-17T15:58:55.311734700Z,160,2,1108,C,A,13.800000000,100,0,321225725,130,165265,268278030,ARL,,13.04,2,1,13.03,100,1,13.02,100,1,12.73,100,1,12.71,100,1,12.5,700,1,12.46,200,1,12.43,700,1,12.42,700,1,12.37,700,1,13.78,100,1,13.81,100,1,14.1,2,1,14.11,100,1,14.28,100,1,14.4,100,1,14.56,800,1,14.58,100,1,14.6,700,1,14.64,100,1,2,321225725
2025-07-17T15:58:58.668252306Z,2025-07-17T15:58:58.668086788Z,160,2,1108,C,A,13.810000000,100,0,321272581,0,165518,268321684,ARL,,13.04,2,1,13.03,100,1,13.02,100,1,12.73,100,1,12.71,100,1,12.5,700,1,12.46,200,1,12.43,700,1,12.42,700,1,12.37,700,1,13.78,100,1,14.1,2,1,14.11,100,1,14.28,100,1,14.4,100,1,14.56,800,1,14.58,100,1,14.6,700,1,14.64,100,1,14.65,100,1,2,321272581
2025-07-17T15:58:58.668252306Z,2025-07-17T15:58:58.668086788Z,160,2,1108,A,A,13.790000000,100,0,321364281,130,165518,268321684,ARL,,13.04,2,1,13.03,100,1,13.02,100,1,12.73,100,1,12.71,100,1,12.5,700,1,12.46,200,1,12.43,700,1,12.42,700,1,12.37,700,1,13.78,100,1,13.79,100,1,14.1,2,1,14.11,100,1,14.28,100,1,14.4,100,1,14.56,800,1,14.58,100,1,14.6,700,1,14.64,100,1,2,321364281
2025-07-17T15:59:03.613692913Z,2025-07-17T15:59:03.613527621Z,160,2,1108,A,A,13.720000000,15,0,321500117,130,165292,268437919,ARL,,13.04,2,1,13.03,100,1,13.02,100,1,12.73,100,1,12.71,100,1,12.5,700,1,12.46,200,1,12.43,700,1,12.42,700,1,12.37,700,1,13.72,15,1,13.78,100,1,13.79,100,1,14.1,2,1,14.11,100,1,14.28,100,1,14.4,100,1,14.56,800,1,14.58,100,1,14.6,700,1,2,321500117
2025-07-17T15:59:03.626346616Z,2025-07-17T15:59:03.626181384Z,160,2,1108,A,A,13.760000000,100,0,321500317,130,165232,268438110,ARL,,13.04,2,1,13.03,100,1,13.02,100,1,12.73,100,1,12.71,100,1,12.5,700,1,12.46,200,1,12.43,700,1,12.42,700,1,12.37,700,1,13.72,15,1,13.76,100,1,13.78,100,1,13.79,100,1,14.1,2,1,14.11,100,1,14.28,100,1,14.4,100,1,14.56,800,1,14.58,100,1,2,321500317
2025-07-17T15:59:03.627086888Z,2025-07-17T15:59:03.626920954Z,160,2,1108,C,A,14.870000000,100,0,321225745,0,165934,268438112,ARL,,13.04,2,1,13.03,100,1,13.02,100,1,12.73,100,1,12.71,100,1,12.5,700,1,12.46,200,1,12.43,700,1,12.42,700,1,12.37,700,1,13.72,15,1,13.76,100,1,13.78,100,1,13.79,100,1,14.1,2,1,14.11,100,1,14.28,100,1,14.4,100,1,14.56,800,1,14.58,100,1,2,321225745
2025-07-17T15:59:03.627086888Z,2025-07-17T15:59:03.626920954Z,160,2,1108,A,A,14.830000000,100,0,321500333,130,165934,268438112,ARL,,13.04,2,1,13.03,100,1,13.02,100,1,12.73,100,1,12.71,100,1,12.5,700,1,12.46,200,1,12.43,700,1,12.42,700,1,12.37,700,1,13.72,15,1,13.76,100,1,13.78,100,1,13.79,100,1,14.1,2,1,14.11,100,1,14.28,100,1,14.4,100,1,14.56,800,1,14.58,100,1,2,321500333
2025-07-17T15:59:03.628945278Z,2025-07-17T15:59:03.628779364Z,160,2,1108,C,A,14.890000000,100,0,312771785,0,165914,268438129,ARL,,13.04,2,1,13.03,100,1,13.02,100,1,12.73,100,1,12.71,100,1,12.5,700,1,12.46,200,1,12.43,700,1,12.42,700,1,12.37,700,1,13.72,15,1,13.76,100,1,13.78,100,1,13.79,100,1,14.1,2,1,14.11,100,1,14.28,100,1,14.4,100,1,14.56,800,1,14.58,100,1,2,312771785
2025-07-17T15:59:03.628945278Z,2025-07-17T15:59:03.628779364Z,160,2,1108,A,A,14.730000000,100,0,321500349,130,165914,268438129,ARL,,13.04,2,1,13.03,100,1,13.02,100,1,12.73,100,1,12.71,100,1,12.5,700,1,12.46,200,1,12.43,700,1,12.42,700,1,12.37,700,1,13.72,15,1,13.76,100,1,13.78,100,1,13.79,100,1,14.1,2,1,14.11,100,1,14.28,100,1,14.4,100,1,14.56,800,1,14.58,100,1,2,321500349
2025-07-17T15:59:03.633093258Z,2025-07-17T15:59:03.632928023Z,160,2,1108,C,A,13.780000000,100,0,321309865,130,165235,268438149,ARL,,13.04,2,1,13.03,100,1,13.02,100,1,12.73,100,1,12.71,100,1,12.5,700,1,12.46,200,1,12.43,700,1,12.42,700,1,12.37,700,1,13.72,15,1,13.76,100,1,13.79,100,1,14.1,2,1,14.11,100,1,14.28,100,1,14.4,100,1,14.56,800,1,14.58,100,1,14.6,700,1,2,321309865
2025-07-17T15:59:03.649282063Z,2025-07-17T15:59:03.649116452Z,160,2,1108,C,A,14.110000000,100,0,321114729,130,165611,268438330,ARL,,13.04,2,1,13.03,100,1,13.02,100,1,12.73,100,1,12.71,100,1,12.5,700,1,12.46,200,1,12.43,700,1,12.42,700,1,12.37,700,1,13.72,15,1,13.76,100,1,13.79,100,1,14.1,2,1,14.28,100,1,14.4,100,1,14.56,800,1,14.58,100,1,14.6,700,1,14.64,100,1,2,321114729
2025-07-17T15:59:03.649332873Z,2025-07-17T15:59:03.649167617Z,160,2,1108,A,A,14.040000000,100,0,321500957,130,165256,268438331,ARL,,13.04,2,1,13.03,100,1,13.02,100,1,12.73,100,1,12.71,100,1,12.5,700,1,12.46,200,1,12.43,700,1,12.42,700,1,12.37,700,1,13.72,15,1,13.76,100,1,13.79,100,1,14.04,100,1,14.1,2,1,14.28,100,1,14.4,100,1,14.56,800,1,14.58,100,1,14.6,700,1,2,321500957
2025-07-17T15:59:04.224000805Z,2025-07-17T15:59:04.223835151Z,160,2,1108,C,A,13.790000000,100,0,321364281,0,165654,268447989,ARL,,13.04,2,1,13.03,100,1,13.02,100,1,12.73,100,1,12.71,100,1,12.5,700,1,12.46,200,1,12.43,700,1,12.42,700,1,12.37,700,1,13.72,15,1,13.76,100,1,14.04,100,1,14.1,2,1,14.28,100,1,14.4,100,1,14.56,800,1,14.58,100,1,14.6,700,1,14.64,100,1,2,321364281
2025-07-17T15:59:04.224000805Z,2025-07-17T15:59:04.223835151Z,160,2,1108,A,A,13.730000000,100,0,321511377,130,165654,268447989,ARL,,13.04,2,1,13.03,100,1,13.02,100,1,12.73,100,1,12.71,100,1,12.5,700,1,12.46,200,1,12.43,700,1,12.42,700,1,12.37,700,1,13.72,15,1,13.73,100,1,13.76,100,1,14.04,100,1,14.1,2,1,14.28,100,1,14.4,100,1,14.56,800,1,14.58,100,1,14.6,700,1,2,321511377
2025-07-17T15:59:04.224749333Z,2025-07-17T15:59:04.224583946Z,160,2,1108,C,A,14.830000000,100,0,321500333,0,165387,268448014,ARL,,13.04,2,1,13.03,100,1,13.02,100,1,12.73,100,1,12.71,100,1,12.5,700,1,12.46,200,1,12.43,700,1,12.42,700,1,12.37,700,1,13.72,15,1,13.73,100,1,13.76,100,1,14.04,100,1,14.1,2,1,14.28,100,1,14.4,100,1,14.56,800,1,14.58,100,1,14.6,700,1,2,321500333
2025-07-17T15:59:04.224749333Z,2025-07-17T15:59:04.224583946Z,160,2,1108,A,A,14.790000000,100,0,321511477,130,165387,268448014,ARL,,13.04,2,1,13.03,100,1,13.02,100,1,12.73,100,1,12.71,100,1,12.5,700,1,12.46,200,1,12.43,700,1,12.42,700,1,12.37,700,1,13.72,15,1,13.73,100,1,13.76,100,1,14.04,100,1,14.1,2,1,14.28,100,1,14.4,100,1,14.56,800,1,14.58,100,1,14.6,700,1,2,321511477
2025-07-17T15:59:04.799998642Z,2025-07-17T15:59:04.799833206Z,160,2,1108,C,A,13.720000000,15,0,321500117,130,165436,268457531,ARL,,13.04,2,1,13.03,100,1,13.02,100,1,12.73,100,1,12.71,100,1,12.5,700,1,12.46,200,1,12.43,700,1,12.42,700,1,12.37,700,1,13.73,100,1,13.76,100,1,14.04,100,1,14.1,2,1,14.28,100,1,14.4,100,1,14.56,800,1,14.58,100,1,14.6,700,1,14.64,100,1,2,321500117
2025-07-17T16:00:13.989937414Z,2025-07-17T16:00:13.989771852Z,160,2,1108,C,A,14.100000000,2,0,316098525,0,165562,269514876,ARL,,13.04,2,1,13.03,100,1,13.02,100,1,12.73,100,1,12.71,100,1,12.5,700,1,12.46,200,1,12.43,700,1,12.42,700,1,12.37,700,1,13.73,100,1,13.76,100,1,14.04,100,1,14.28,100,1,14.4,100,1,14.56,800,1,14.58,100,1,14.6,700,1,14.64,100,1,14.65,100,1,2,316098525
2025-07-17T16:00:13.989937414Z,2025-07-17T16:00:13.989771852Z,160,2,1108,A,A,14.010000000,2,0,322898193,130,165562,269514876,ARL,,13.04,2,1,13.03,100,1,13.02,100,1,12.73,100,1,12.71,100,1,12.5,700,1,12.46,200,1,12.43,700,1,12.42,700,1,12.37,700,1,13.73,100,1,13.76,100,1,14.01,2,1,14.04,100,1,14.28,100,1,14.4,100,1,14.56,800,1,14.58,100,1,14.6,700,1,14.64,100,1,2,322898193
2025-07-17T16:00:28.803015930Z,2025-07-17T16:00:28.802849928Z,160,2,1108,A,A,13.720000000,15,0,323238809,130,166002,269765653,ARL,,13.04,2,1,13.03,100,1,13.02,100,1,12.73,100,1,12.71,100,1,12.5,700,1,12.46,200,1,12.43,700,1,12.42,700,1,12.37,700,1,13.72,15,1,13.73,100,1,13.76,100,1,14.01,2,1,14.04,100,1,14.28,100,1,14.4,100,1,14.56,800,1,14.58,100,1,14.6,700,1,2,323238809
2025-07-17T16:00:32.549412616Z,2025-07-17T16:00:32.549247168Z,160,2,1108,A,A,13.740000000,100,0,323370569,130,165448,269878282,ARL,,13.04,2,1,13.03,100,1,13.02,100,1,12.73,100,1,12.71,100,1,12.5,700,1,12.46,200,1,12.43,700,1,12.42,700,1,12.37,700,1,13.72,15,1,13.73,100,1,13.74,100,1,13.76,100,1,14.01,2,1,14.04,100,1,14.28,100,1,14.4,100,1,14.56,800,1,14.58,100,1,2,323370569
2025-07-17T16:00:32.560989093Z,2025-07-17T16:00:32.560823786Z,160,2,1108,C,A,13.760000000,100,0,321500317,130,165307,269878639,ARL,,13.04,2,1,13.03,100,1,13.02,100,1,12.73,100,1,12.71,100,1,12.5,700,1,12.46,200,1,12.43,700,1,12.42,700,1,12.37,700,1,13.72,15,1,13.73,100,1,13.74,100,1,14.01,2,1,14.04,100,1,14.28,100,1,14.4,100,1,14.56,800,1,14.58,100,1,14.6,700,1,2,321500317
2025-07-17T16:00:35.513164458Z,2025-07-17T16:00:35.512999155Z,160,2,1108,A,A,13.690000000,15,0,323455221,130,165303,269940539,ARL,,13.04,2,1,13.03,100,1,13.02,100,1,12.73,100,1,12.71,100,1,12.5,700,1,12.46,200,1,12.43,700,1,12.42,700,1,12.37,700,1,13.69,15,1,13.72,15,1,13.73,100,1,13.74,100,1,14.01,2,1,14.04,100,1,14.28,100,1,14.4,100,1,14.56,800,1,14.58,100,1,2,323455221
2025-07-17T16:00:42.614229184Z,2025-07-17T16:00:42.614063415Z,160,2,1108,C,A,13.730000000,100,0,321511377,0,165769,270051089,ARL,,13.04,2,1,13.03,100,1,13.02,100,1,12.73,100,1,12.71,100,1,12.5,700,1,12.46,200,1,12.43,700,1,12.42,700,1,12.37,700,1,13.69,15,1,13.72,15,1,13.74,100,1,14.01,2,1,14.04,100,1,14.28,100,1,14.4,100,1,14.56,800,1,14.58,100,1,14.6,700,1,2,321511377
2025-07-17T16:00:42.614229184Z,2025-07-17T16:00:42.614063415Z,160,2,1108,A,A,13.700000000,100,0,323599605,130,165769,270051089,ARL,,13.04,2,1,13.03,100,1,13.02,100,1,12.73,100,1,12.71,100,1,12.5,700,1,12.46,200,1,12.43,700,1,12.42,700,1,12.37,700,1,13.69,15,1,13.7,100,1,13.72,15,1,13.74,100,1,14.01,2,1,14.04,100,1,14.28,100,1,14.4,100,1,14.56,800,1,14.58,100,1,2,323599605
2025-07-17T16:00:42.614254199Z,2025-07-17T16:00:42.614088947Z,160,2,1108,A,A,13.720000000,100,0,323599609,130,165252,270051090,ARL,,13.04,2,1,13.03,100,1,13.02,100,1,12.73,100,1,12.71,100,1,12.5,700,1,12.46,200,1,12.43,700,1,12.42,700,1,12.37,700,1,13.69,15,1,13.7,100,1,13.72,115,1,13.74,100,1,14.01,2,1,14.04,100,1,14.28,100,1,14.4,100,1,14.56,800,1,14.58,100,1,2,323599609
2025-07-17T16:00:42.614396214Z,2025-07-17T16:00:42.614231125Z,160,2,1108,C,A,13.740000000,100,0,323370569,130,165089,270051092,ARL,,13.04,2,1,13.03,100,1,13.02,100,1,12.73,100,1,12.71,100,1,12.5,700,1,12.46,200,1,12.43,700,1,12.42,700,1,12.37,700,1,13.69,15,1,13.7,100,1,13.72,115,1,14.01,2,1,14.04,100,1,14.28,100,1,14.4,100,1,14.56,800,1,14.58,100,1,14.6,700,1,2,323370569
2025-07-17T16:00:42.616178962Z,2025-07-17T16:00:42.616013371Z,160,2,1108,C,A,14.810000000,100,0,321097197,0,165591,270051093,ARL,,13.04,2,1,13.03,100,1,13.02,100,1,12.73,100,1,12.71,100,1,12.5,700,1,12.46,200,1,12.43,700,1,12.42,700,1,12.37,700,1,13.69,15,1,13.7,100,1,13.72,115,1,14.01,2,1,14.04,100,1,14.28,100,1,14.4,100,1,14.56,800,1,14.58,100,1,14.6,700,1,2,321097197
2025-07-17T16:00:42.616178962Z,2025-07-17T16:00:42.616013371Z,160,2,1108,A,A,14.660000000,100,0,323599625,130,165591,270051093,ARL,,13.04,2,1,13.03,100,1,13.02,100,1,12.73,100,1,12.71,100,1,12.5,700,1,12.46,200,1,12.43,700,1,12.42,700,1,12.37,700,1,13.69,15,1,13.7,100,1,13.72,115,1,14.01,2,1,14.04,100,1,14.28,100,1,14.4,100,1,14.56,800,1,14.58,100,1,14.6,700,1,2,323599625
2025-07-17T16:00:42.616321879Z,2025-07-17T16:00:42.616156310Z,160,2,1108,C,A,15.920000000,100,0,321096889,0,165569,270051094,ARL,,13.04,2,1,13.03,100,1,13.02,100,1,12.73,100,1,12.71,100,1,12.5,700,1,12.46,200,1,12.43,700,1,12.42,700,1,12.37,700,1,13.69,15,1,13.7,100,1,13.72,115,1,14.01,2,1,14.04,100,1,14.28,100,1,14.4,100,1,14.56,800,1,14.58,100,1,14.6,700,1,2,321096889
2025-07-17T16:00:42.616321879Z,2025-07-17T16:00:42.616156310Z,160,2,1108,A,A,15.760000000,100,0,323599629,130,165569,270051094,ARL,,13.04,2,1,13.03,100,1,13.02,100,1,12.73,100,1,12.71,100,1,12.5,700,1,12.46,200,1,12.43,700,1,12.42,700,1,12.37,700,1,13.69,15,1,13.7,100,1,13.72,115,1,14.01,2,1,14.04,100,1,14.28,100,1,14.4,100,1,14.56,800,1,14.58,100,1,14.6,700,1,2,323599629
2025-07-17T16:00:42.616352247Z,2025-07-17T16:00:42.616186901Z,160,2,1108,C,A,17.580000000,100,0,321096825,0,165346,270051095,ARL,,13.04,2,1,13.03,100,1,13.02,100,1,12.73,100,1,12.71,100,1,12.5,700,1,12.46,200,1,12.43,700,1,12.42,700,1,12.37,700,1,13.69,15,1,13.7,100,1,13.72,115,1,14.01,2,1,14.04,100,1,14.28,100,1,14.4,100,1,14.56,800,1,14.58,100,1,14.6,700,1,2,321096825
2025-07-17T16:00:42.616352247Z,2025-07-17T16:00:42.616186901Z,160,2,1108,A,A,17.400000000,100,0,323599633,130,165346,270051095,ARL,,13.04,2,1,13.03,100,1,13.02,100,1,12.73,100,1,12.71,100,1,12.5,700,1,12.46,200,1,12.43,700,1,12.42,700,1,12.37,700,1,13.69,15,1,13.7,100,1,13.72,115,1,14.01,2,1,14.04,100,1,14.28,100,1,14.4,100,1,14.56,800,1,14.58,100,1,14.6,700,1,2,323599633
2025-07-17T16:00:42.636761176Z,2025-07-17T16:00:42.636595817Z,160,2,1108,C,A,14.040000000,100,0,321500957,130,165359,270051179,ARL,,13.04,2,1,13.03,100,1,13.02,100,1,12.73,100,1,12.71,100,1,12.5,700,1,12.46,200,1,12.43,700,1,12.42,700,1,12.37,700,1,13.69,15,1,13.7,100,1,13.72,115,1,14.01,2,1,14.28,100,1,14.4,100,1,14.56,800,1,14.58,100,1,14.6,700,1,14.64,100,1,2,321500957
2025-07-17T16:00:42.636814704Z,2025-07-17T16:00:42.636649389Z,160,2,1108,A,A,13.970000000,100,0,323599765,130,165315,270051181,ARL,,13.04,2,1,13.03,100,1,13.02,100,1,12.73,100,1,12.71,100,1,12.5,700,1,12.46,200,1,12.43,700,1,12.42,700,1,12.37,700,1,13.69,15,1,13.7,100,1,13.72,115,1,13.97,100,1,14.01,2,1,14.28,100,1,14.4,100,1,14.56,800,1,14.58,100,1,14.6,700,1,2,323599765
2025-07-17T16:00:46.803262460Z,2025-07-17T16:00:46.803097192Z,160,2,1108,C,A,13.720000000,15,0,323238809,130,165268,270102799,ARL,,13.04,2,1,13.03,100,1,13.02,100,1,12.73,100,1,12.71,100,1,12.5,700,1,12.46,200,1,12.43,700,1,12.42,700,1,12.37,700,1,13.69,15,1,13.7,100,1,13.72,100,1,13.97,100,1,14.01,2,1,14.28,100,1,14.4,100,1,14.56,800,1,14.58,100,1,14.6,700,1,2,323238809
2025-07-17T16:00:49.255631264Z,2025-07-17T16:00:49.255465939Z,160,2,1108,A,A,13.660000000,15,0,323720189,130,165325,270140405,ARL,,13.04,2,1,13.03,100,1,13.02,100,1,12.73,100,1,12.71,100,1,12.5,700,1,12.46,200,1,12.43,700,1,12.42,700,1,12.37,700,1,13.66,15,1,13.69,15,1,13.7,100,1,13.72,100,1,13.97,100,1,14.01,2,1,14.28,100,1,14.4,100,1,14.56,800,1,14.58,100,1,2,323720189
2025-07-17T16:00:49.739644604Z,2025-07-17T16:00:49.739479408Z,160,2,1108,A,A,13.700000000,100,0,323730309,130,165196,270146528,ARL,,13.04,2,1,13.03,100,1,13.02,100,1,12.73,100,1,12.71,100,1,12.5,700,1,12.46,200,1,12.43,700,1,12.42,700,1,12.37,700,1,13.66,15,1,13.69,15,1,13.7,200,1,13.72,100,1,13.97,100,1,14.01,2,1,14.28,100,1,14.4,100,1,14.56,800,1,14.58,100,1,2,323730309
2025-07-17T16:00:49.745038261Z,2025-07-17T16:00:49.744872763Z,160,2,1108,C,A,13.700000000,100,0,323599605,0,165498,270146577,ARL,,13.04,2,1,13.03,100,1,13.02,100,1,12.73,100,1,12.71,100,1,12.5,700,1,12.46,200,1,12.43,700,1,12.42,700,1,12.37,700,1,13.66,15,1,13.69,15,1,13.7,100,1,13.72,100,1,13.97,100,1,14.01,2,1,14.28,100,1,14.4,100,1,14.56,800,1,14.58,100,1,2,323599605
2025-07-17T16:00:49.745038261Z,2025-07-17T16:00:49.744872763Z,160,2,1108,A,A,13.670000000,100,0,323730353,130,165498,270146577,ARL,,13.04,2,1,13.03,100,1,13.02,100,1,12.73,100,1,12.71,100,1,12.5,700,1,12.46,200,1,12.43,700,1,12.42,700,1,12.37,700,1,13.66,15,1,13.67,100,1,13.69,15,1,13.7,100,1,13.72,100,1,13.97,100,1,14.01,2,1,14.28,100,1,14.4,100,1,14.56,800,1,2,323730353
2025-07-17T16:00:49.745778725Z,2025-07-17T16:00:49.745613051Z,160,2,1108,C,A,14.790000000,100,0,321511477,0,165674,270146581,ARL,,13.04,2,1,13.03,100,1,13.02,100,1,12.73,100,1,12.71,100,1,12.5,700,1,12.46,200,1,12.43,700,1,12.42,700,1,12.37,700,1,13.66,15,1,13.67,100,1,13.69,15,1,13.7,100,1,13.72,100,1,13.97,100,1,14.01,2,1,14.28,100,1,14.4,100,1,14.56,800,1,2,321511477
2025-07-17T16:00:49.745778725Z,2025-07-17T16:00:49.745613051Z,160,2,1108,A,A,14.730000000,100,0,323730369,130,165674,270146581,ARL,,13.04,2,1,13.03,100,1,13.02,100,1,12.73,100,1,12.71,100,1,12.5,700,1,12.46,200,1,12.43,700,1,12.42,700,1,12.37,700,1,13.66,15,1,13.67,100,1,13.69,15,1,13.7,100,1,13.72,100,1,13.97,100,1,14.01,2,1,14.28,100,1,14.4,100,1,14.56,800,1,2,323730369
2025-07-17T16:00:49.746422142Z,2025-07-17T16:00:49.746256906Z,160,2,1108,C,A,13.720000000,100,0,323599609,130,165236,270146586,ARL,,13.04,2,1,13.03,100,1,13.02,100,1,12.73,100,1,12.71,100,1,12.5,700,1,12.46,200,1,12.43,700,1,12.42,700,1,12.37,700,1,13.66,15,1,13.67,100,1,13.69,15,1,13.7,100,1,13.97,100,1,14.01,2,1,14.28,100,1,14.4,100,1,14.56,800,1,14.58,100,1,2,323599609
2025-07-17T16:00:49.772631967Z,2025-07-17T16:00:49.772466772Z,160,2,1108,A,A,15.590000000,100,0,323730697,130,165195,270146838,ARL,,13.04,2,1,13.03,100,1,13.02,100,1,12.73,100,1,12.71,100,1,12.5,700,1,12.46,200,1,12.43,700,1,12.42,700,1,12.37,700,1,13.66,15,1,13.67,100,1,13.69,15,1,13.7,100,1,13.97,100,1,14.01,2,1,14.28,100,1,14.4,100,1,14.56,800,1,14.58,100,1,2,323730697
2025-07-17T16:00:49.772645303Z,2025-07-17T16:00:49.772479921Z,160,2,1108,C,A,15.860000000,100,0,312771645,130,165382,270146839,ARL,,13.04,2,1,13.03,100,1,13.02,100,1,12.73,100,1,12.71,100,1,12.5,700,1,12.46,200,1,12.43,700,1,12.42,700,1,12.37,700,1,13.66,15,1,13.67,100,1,13.69,15,1,13.7,100,1,13.97,100,1,14.01,2,1,14.28,100,1,14.4,100,1,14.56,800,1,14.58,100,1,2,312771645
2025-07-17T16:00:51.624811889Z,2025-07-17T16:00:51.624646272Z,160,2,1108,C,A,14.650000000,100,0,321293737,0,165617,270181394,ARL,,13.04,2,1,13.03,100,1,13.02,100,1,12.73,100,1,12.71,100,1,12.5,700,1,12.46,200,1,12.43,700,1,12.42,700,1,12.37,700,1,13.66,15,1,13.67,100,1,13.69,15,1,13.7,100,1,13.97,100,1,14.01,2,1,14.28,100,1,14.4,100,1,14.56,800,1,14.58,100,1,2,321293737
2025-07-17T16:00:51.624811889Z,2025-07-17T16:00:51.624646272Z,160,2,1108,A,A,14.540000000,100,0,323775433,130,165617,270181394,ARL,,13.04,2,1,13.03,100,1,13.02,100,1,12.73,100,1,12.71,100,1,12.5,700,1,12.46,200,1,12.43,700,1,12.42,700,1,12.37,700,1,13.66,15,1,13.67,100,1,13.69,15,1,13.7,100,1,13.97,100,1,14.01,2,1,14.28,100,1,14.4,100,1,14.54,100,1,14.56,800,1,2,323775433
2025-07-17T16:00:51.625372516Z,2025-07-17T16:00:51.625206675Z,160,2,1108,C,A,14.640000000,100,0,321293741,0,165841,270181399,ARL,,13.04,2,1,13.03,100,1,13.02,100,1,12.73,100,1,12.71,100,1,12.5,700,1,12.46,200,1,12.43,700,1,12.42,700,1,12.37,700,1,13.66,15,1,13.67,100,1,13.69,15,1,13.7,100,1,13.97,100,1,14.01,2,1,14.28,100,1,14.4,100,1,14.54,100,1,14.56,800,1,2,321293741
2025-07-17T16:00:51.625372516Z,2025-07-17T16:00:51.625206675Z,160,2,1108,A,A,14.530000000,100,0,323775457,130,165841,270181399,ARL,,13.04,2,1,13.03,100,1,13.02,100,1,12.73,100,1,12.71,100,1,12.5,700,1,12.46,200,1,12.43,700,1,12.42,700,1,12.37,700,1,13.66,15,1,13.67,100,1,13.69,15,1,13.7,100,1,13.97,100,1,14.01,2,1,14.28,100,1,14.4,100,1,14.53,100,1,14.54,100,1,2,323775457
2025-07-17T16:00:53.749335010Z,2025-07-17T16:00:53.749169565Z,160,2,1108,A,A,13.670000000,100,0,323803301,130,165445,270204567,ARL,,13.04,2,1,13.03,100,1,13.02,100,1,12.73,100,1,12.71,100,1,12.5,700,1,12.46,200,1,12.43,700,1,12.42,700,1,12.37,700,1,13.66,15,1,13.67,200,1,13.69,15,1,13.7,100,1,13.97,100,1,14.01,2,1,14.28,100,1,14.4,100,1,14.53,100,1,14.54,100,1,2,323803301
2025-07-17T16:00:53.755966680Z,2025-07-17T16:00:53.755801462Z,160,2,1108,C,A,13.700000000,100,0,323730309,130,165218,270204616,ARL,,13.04,2,1,13.03,100,1,13.02,100,1,12.73,100,1,12.71,100,1,12.5,700,1,12.46,200,1,12.43,700,1,12.42,700,1,12.37,700,1,13.66,15,1,13.67,200,1,13.69,15,1,13.97,100,1,14.01,2,1,14.28,100,1,14.4,100,1,14.53,100,1,14.54,100,1,14.56,800,1,2,323730309
2025-07-17T16:01:00.801342739Z,2025-07-17T16:01:00.801177403Z,160,2,1108,C,A,13.690000000,15,0,323455221,130,165336,270319932,ARL,,13.04,2,1,13.03,100,1,13.02,100,1,12.73,100,1,12.71,100,1,12.5,700,1,12.46,200,1,12.43,700,1,12.42,700,1,12.37,700,1,13.66,15,1,13.67,200,1,13.97,100,1,14.01,2,1,14.28,100,1,14.4,100,1,14.53,100,1,14.54,100,1,14.56,800,1,14.58,100,1,2,323455221
2025-07-17T16:01:10.802877570Z,2025-07-17T16:01:10.802712247Z,160,2,1108,A,A,13.620000000,15,0,324161541,130,165323,270493149,ARL,,13.04,2,1,13.03,100,1,13.02,100,1,12.73,100,1,12.71,100,1,12.5,700,1,12.46,200,1,12.43,700,1,12.42,700,1,12.37,700,1,13.62,15,1,13.66,15,1,13.67,200,1,13.97,100,1,14.01,2,1,14.28,100,1,14.4,100,1,14.53,100,1,14.54,100,1,14.56,800,1,2,324161541
2025-07-17T16:01:11.418837472Z,2025-07-17T16:01:11.418671671Z,160,2,1108,A,A,13.650000000,100,0,324175569,130,165801,270503944,ARL,,13.04,2,1,13.03,100,1,13.02,100,1,12.73,100,1,12.71,100,1,12.5,700,1,12.46,200,1,12.43,700,1,12.42,700,1,12.37,700,1,13.62,15,1,13.65,100,1,13.66,15,1,13.67,200,1,13.97,100,1,14.01,2,1,14.28,100,1,14.4,100,1,14.53,100,1,14.54,100,1,2,324175569
2025-07-17T16:01:11.425922184Z,2025-07-17T16:01:11.425757014Z,160,2,1108,C,A,13.670000000,100,0,323803301,130,165170,270504009,ARL,,13.04,2,1,13.03,100,1,13.02,100,1,12.73,100,1,12.71,100,1,12.5,700,1,12.46,200,1,12.43,700,1,12.42,700,1,12.37,700,1,13.62,15,1,13.65,100,1,13.66,15,1,13.67,100,1,13.97,100,1,14.01,2,1,14.28,100,1,14.4,100,1,14.53,100,1,14.54,100,1,2,323803301
2025-07-17T16:01:11.820753616Z,2025-07-17T16:01:11.820588141Z,160,2,1108,C,A,13.670000000,100,0,323730353,0,165475,270509970,ARL,,13.04,2,1,13.03,100,1,13.02,100,1,12.73,100,1,12.71,100,1,12.5,700,1,12.46,200,1,12.43,700,1,12.42,700,1,12.37,700,1,13.62,15,1,13.65,100,1,13.66,15,1,13.97,100,1,14.01,2,1,14.28,100,1,14.4,100,1,14.53,100,1,14.54,100,1,14.56,800,1,2,323730353
2025-07-17T16:01:11.820753616Z,2025-07-17T16:01:11.820588141Z,160,2,1108,A,A,13.630000000,100,0,324186213,130,165475,270509970,ARL,,13.04,2,1,13.03,100,1,13.02,100,1,12.73,100,1,12.71,100,1,12.5,700,1,12.46,200,1,12.43,700,1,12.42,700,1,12.37,700,1,13.62,15,1,13.63,100,1,13.65,100,1,13.66,15,1,13.97,100,1,14.01,2,1,14.28,100,1,14.4,100,1,14.53,100,1,14.54,100,1,2,324186213
2025-07-17T16:01:11.821515043Z,2025-07-17T16:01:11.821349600Z,160,2,1108,C,A,14.730000000,100,0,323730369,0,165443,270509983,ARL,,13.04,2,1,13.03,100,1,13.02,100,1,12.73,100,1,12.71,100,1,12.5,700,1,12.46,200,1,12.43,700,1,12.42,700,1,12.37,700,1,13.62,15,1,13.63,100,1,13.65,100,1,13.66,15,1,13.97,100,1,14.01,2,1,14.28,100,1,14.4,100,1,14.53,100,1,14.54,100,1,2,323730369
2025-07-17T16:01:11.821515043Z,2025-07-17T16:01:11.821349600Z,160,2,1108,A,A,14.690000000,100,0,324186233,130,165443,270509983,ARL,,13.04,2,1,13.03,100,1,13.02,100,1,12.73,100,1,12.71,100,1,12.5,700,1,12.46,200,1,12.43,700,1,12.42,700,1,12.37,700,1,13.62,15,1,13.63,100,1,13.65,100,1,13.66,15,1,13.97,100,1,14.01,2,1,14.28,100,1,14.4,100,1,14.53,100,1,14.54,100,1,2,324186233
2025-07-17T16:01:11.826399871Z,2025-07-17T16:01:11.826234488Z,160,2,1108,C,A,13.970000000,100,0,323599765,130,165383,270510142,ARL,,13.04,2,1,13.03,100,1,13.02,100,1,12.73,100,1,12.71,100,1,12.5,700,1,12.46,200,1,12.43,700,1,12.42,700,1,12.37,700,1,13.62,15,1,13.63,100,1,13.65,100,1,13.66,15,1,14.01,2,1,14.28,100,1,14.4,100,1,14.53,100,1,14.54,100,1,14.56,800,1,2,323599765
2025-07-17T16:01:11.826451447Z,2025-07-17T16:01:11.826286284Z,160,2,1108,A,A,13.900000000,100,0,324186721,130,165163,270510143,ARL,,13.04,2,1,13.03,100,1,13.02,100,1,12.73,100,1,12.71,100,1,12.5,700,1,12.46,200,1,12.43,700,1,12.42,700,1,12.37,700,1,13.62,15,1,13.63,100,1,13.65,100,1,13.66,15,1,13.9,100,1,14.01,2,1,14.28,100,1,14.4,100,1,14.53,100,1,14.54,100,1,2,324186721
2025-07-17T16:01:11.828630414Z,2025-07-17T16:01:11.828464891Z,160,2,1108,C,A,14.580000000,100,0,321309941,0,165523,270510182,ARL,,13.04,2,1,13.03,100,1,13.02,100,1,12.73,100,1,12.71,100,1,12.5,700,1,12.46,200,1,12.43,700,1,12.42,700,1,12.37,700,1,13.62,15,1,13.63,100,1,13.65,100,1,13.66,15,1,13.9,100,1,14.01,2,1,14.28,100,1,14.4,100,1,14.53,100,1,14.54,100,1,2,321309941
2025-07-17T16:01:11.828630414Z,2025-07-17T16:01:11.828464891Z,160,2,1108,A,A,14.430000000,100,0,324186781,130,165523,270510182,ARL,,13.04,2,1,13.03,100,1,13.02,100,1,12.73,100,1,12.71,100,1,12.5,700,1,12.46,200,1,12.43,700,1,12.42,700,1,12.37,700,1,13.62,15,1,13.63,100,1,13.65,100,1,13.66,15,1,13.9,100,1,14.01,2,1,14.28,100,1,14.4,100,1,14.43,100,1,14.53,100,1,2,324186781
2025-07-17T16:01:22.802518536Z,2025-07-17T16:01:22.802353061Z,160,2,1108,C,A,13.660000000,15,0,323720189,130,165475,270674903,ARL,,13.04,2,1,13.03,100,1,13.02,100,1,12.73,100,1,12.71,100,1,12.5,700,1,12.46,200,1,12.43,700,1,12.42,700,1,12.37,700,1,13.62,15,1,13.63,100,1,13.65,100,1,13.9,100,1,14.01,2,1,14.28,100,1,14.4,100,1,14.43,100,1,14.53,100,1,14.54,100,1,2,323720189
2025-07-17T16:01:32.804004639Z,2025-07-17T16:01:32.803839043Z,160,2,1108,A,A,13.600000000,15,0,324619361,130,165596,270824320,ARL,,13.04,2,1,13.03,100,1,13.02,100,1,12.73,100,1,12.71,100,1,12.5,700,1,12.46,200,1,12.43,700,1,12.42,700,1,12.37,700,1,13.6,15,1,13.62,15,1,13.63,100,1,13.65,100,1,13.9,100,1,14.01,2,1,14.28,100,1,14.4,100,1,14.43,100,1,14.53,100,1,2,324619361
2025-07-17T16:01:32.804274168Z,2025-07-17T16:01:32.804108576Z,160,2,1108,C,A,13.630000000,100,0,324186213,0,165592,270824323,ARL,,13.04,2,1,13.03,100,1,13.02,100,1,12.73,100,1,12.71,100,1,12.5,700,1,12.46,200,1,12.43,700,1,12.42,700,1,12.37,700,1,13.6,15,1,13.62,15,1,13.65,100,1,13.9,100,1,14.01,2,1,14.28,100,1,14.4,100,1,14.43,100,1,14.53,100,1,14.54,100,1,2,324186213
2025-07-17T16:01:32.804274168Z,2025-07-17T16:01:32.804108576Z,160,2,1108,A,A,13.610000000,100,0,324619369,130,165592,270824323,ARL,,13.04,2,1,13.03,100,1,13.02,100,1,12.73,100,1,12.71,100,1,12.5,700,1,12.46,200,1,12.43,700,1,12.42,700,1,12.37,700,1,13.6,15,1,13.61,100,1,13.62,15,1,13.65,100,1,13.9,100,1,14.01,2,1,14.28,100,1,14.4,100,1,14.43,100,1,14.53,100,1,2,324619369
2025-07-17T16:01:32.806299464Z,2025-07-17T16:01:32.806134020Z,160,2,1108,C,A,14.730000000,100,0,321500349,0,165444,270824400,ARL,,13.04,2,1,13.03,100,1,13.02,100,1,12.73,100,1,12.71,100,1,12.5,700,1,12.46,200,1,12.43,700,1,12.42,700,1,12.37,700,1,13.6,15,1,13.61,100,1,13.62,15,1,13.65,100,1,13.9,100,1,14.01,2,1,14.28,100,1,14.4,100,1,14.43,100,1,14.53,100,1,2,321500349
2025-07-17T16:01:32.806299464Z,2025-07-17T16:01:32.806134020Z,160,2,1108,A,A,14.570000000,100,0,324619409,130,165444,270824400,ARL,,13.04,2,1,13.03,100,1,13.02,100,1,12.73,100,1,12.71,100,1,12.5,700,1,12.46,200,1,12.43,700,1,12.42,700,1,12.37,700,1,13.6,15,1,13.61,100,1,13.62,15,1,13.65,100,1,13.9,100,1,14.01,2,1,14.28,100,1,14.4,100,1,14.43,100,1,14.53,100,1,2,324619409
2025-07-17T16:01:32.815913520Z,2025-07-17T16:01:32.815748258Z,160,2,1108,A,A,13.630000000,100,0,324619837,130,165262,270824657,ARL,,13.04,2,1,13.03,100,1,13.02,100,1,12.73,100,1,12.71,100,1,12.5,700,1,12.46,200,1,12.43,700,1,12.42,700,1,12.37,700,1,13.6,15,1,13.61,100,1,13.62,15,1,13.63,100,1,13.65,100,1,13.9,100,1,14.01,2,1,14.28,100,1,14.4,100,1,14.43,100,1,2,324619837
2025-07-17T16:01:32.822608966Z,2025-07-17T16:01:32.822443626Z,160,2,1108,C,A,13.650000000,100,0,324175569,130,165340,270824747,ARL,,13.04,2,1,13.03,100,1,13.02,100,1,12.73,100,1,12.71,100,1,12.5,700,1,12.46,200,1,12.43,700,1,12.42,700,1,12.37,700,1,13.6,15,1,13.61,100,1,13.62,15,1,13.63,100,1,13.9,100,1,14.01,2,1,14.28,100,1,14.4,100,1,14.43,100,1,14.53,100,1,2,324175569
2025-07-17T16:01:37.242690420Z,2025-07-17T16:01:37.242525208Z,160,2,1108,C,A,13.620000000,15,0,324161541,130,165212,270889017,ARL,,13.04,2,1,13.03,100,1,13.02,100,1,12.73,100,1,12.71,100,1,12.5,700,1,12.46,200,1,12.43,700,1,12.42,700,1,12.37,700,1,13.6,15,1,13.61,100,1,13.63,100,1,13.9,100,1,14.01,2,1,14.28,100,1,14.4,100,1,14.43,100,1,14.53,100,1,14.54,100,1,2,324161541
2025-07-17T16:01:40.605797765Z,2025-07-17T16:01:40.605632399Z,160,2,1108,A,A,13.610000000,100,0,324782841,130,165366,270946497,ARL,,13.04,2,1,13.03,100,1,13.02,100,1,12.73,100,1,12.71,100,1,12.5,700,1,12.46,200,1,12.43,700,1,12.42,700,1,12.37,700,1,13.6,15,1,13.61,200,1,13.63,100,1,13.9,100,1,14.01,2,1,14.28,100,1,14.4,100,1,14.43,100,1,14.53,100,1,14.54,100,1,2,324782841
2025-07-17T16:01:40.653738176Z,2025-07-17T16:01:40.653572805Z,160,2,1108,C,A,13.630000000,100,0,324619837,130,165371,270946779,ARL,,13.04,2,1,13.03,100,1,13.02,100,1,12.73,100,1,12.71,100,1,12.5,700,1,12.46,200,1,12.43,700,1,12.42,700,1,12.37,700,1,13.6,15,1,13.61,200,1,13.9,100,1,14.01,2,1,14.28,100,1,14.4,100,1,14.43,100,1,14.53,100,1,14.54,100,1,14.56,800,1,2,324619837
2025-07-17T16:01:47.565991684Z,2025-07-17T16:01:47.565825466Z,160,2,1108,A,A,13.570000000,15,0,324934601,128,166218,271062350,ARL,,13.04,2,1,13.03,100,1,13.02,100,1,12.73,100,1,12.71,100,1,12.5,700,1,12.46,200,1,12.43,700,1,12.42,700,1,12.37,700,1,13.57,15,1,13.6,15,1,13.61,200,1,13.9,100,1,14.01,2,1,14.28,100,1,14.4,100,1,14.43,100,1,14.53,100,1,14.54,100,1,2,324934601
2025-07-17T16:01:47.902969773Z,2025-07-17T16:01:47.902804446Z,160,2,1108,C,A,13.610000000,100,0,324619369,0,165327,271068098,ARL,,13.04,2,1,13.03,100,1,13.02,100,1,12.73,100,1,12.71,100,1,12.5,700,1,12.46,200,1,12.43,700,1,12.42,700,1,12.37,700,1,13.57,15,1,13.6,15,1,13.61,100,1,13.9,100,1,14.01,2,1,14.28,100,1,14.4,100,1,14.43,100,1,14.53,100,1,14.54,100,1,2,324619369
2025-07-17T16:01:47.902969773Z,2025-07-17T16:01:47.902804446Z,160,2,1108,A,A,13.580000000,100,0,324942229,130,165327,271068098,ARL,,13.04,2,1,13.03,100,1,13.02,100,1,12.73,100,1,12.71,100,1,12.5,700,1,12.46,200,1,12.43,700,1,12.42,700,1,12.37,700,1,13.57,15,1,13.58,100,1,13.6,15,1,13.61,100,1,13.9,100,1,14.01,2,1,14.28,100,1,14.4,100,1,14.43,100,1,14.53,100,1,2,324942229
2025-07-17T16:01:47.903711757Z,2025-07-17T16:01:47.903546622Z,160,2,1108,C,A,14.400000000,100,0,289726421,130,165135,271068105,ARL,,13.04,2,1,13.03,100,1,13.02,100,1,12.73,100,1,12.71,100,1,12.5,700,1,12.46,200,1,12.43,700,1,12.42,700,1,12.37,700,1,13.57,15,1,13.58,100,1,13.6,15,1,13.61,100,1,13.9,100,1,14.01,2,1,14.28,100,1,14.43,100,1,14.53,100,1,14.54,100,1,2,289726421
2025-07-17T16:01:47.903714323Z,2025-07-17T16:01:47.903548861Z,160,2,1108,C,A,14.690000000,100,0,324186233,0,165462,271068106,ARL,,13.04,2,1,13.03,100,1,13.02,100,1,12.73,100,1,12.71,100,1,12.5,700,1,12.46,200,1,12.43,700,1,12.42,700,1,12.37,700,1,13.57,15,1,13.58,100,1,13.6,15,1,13.61,100,1,13.9,100,1,14.01,2,1,14.28,100,1,14.43,100,1,14.53,100,1,14.54,100,1,2,324186233
2025-07-17T16:01:47.903714323Z,2025-07-17T16:01:47.903548861Z,160,2,1108,A,A,14.630000000,100,0,324942257,130,165462,271068106,ARL,,13.04,2,1,13.03,100,1,13.02,100,1,12.73,100,1,12.71,100,1,12.5,700,1,12.46,200,1,12.43,700,1,12.42,700,1,12.37,700,1,13.57,15,1,13.58,100,1,13.6,15,1,13.61,100,1,13.9,100,1,14.01,2,1,14.28,100,1,14.43,100,1,14.53,100,1,14.54,100,1,2,324942257
2025-07-17T16:01:47.904067686Z,2025-07-17T16:01:47.903902473Z,160,2,1108,A,A,14.190000000,100,0,324942273,130,165213,271068115,ARL,,13.04,2,1,13.03,100,1,13.02,100,1,12.73,100,1,12.71,100,1,12.5,700,1,12.46,200,1,12.43,700,1,12.42,700,1,12.37,700,1,13.57,15,1,13.58,100,1,13.6,15,1,13.61,100,1,13.9,100,1,14.01,2,1,14.19,100,1,14.28,100,1,14.43,100,1,14.53,100,1,2,324942273
2025-07-17T16:01:47.905355779Z,2025-07-17T16:01:47.905189816Z,160,2,1108,C,A,15.230000000,100,0,282776017,0,165963,271068134,ARL,,13.04,2,1,13.03,100,1,13.02,100,1,12.73,100,1,12.71,100,1,12.5,700,1,12.46,200,1,12.43,700,1,12.42,700,1,12.37,700,1,13.57,15,1,13.58,100,1,13.6,15,1,13.61,100,1,13.9,100,1,14.01,2,1,14.19,100,1,14.28,100,1,14.43,100,1,14.53,100,1,2,282776017
2025-07-17T16:01:47.905355779Z,2025-07-17T16:01:47.905189816Z,160,2,1108,A,A,14.940000000,100,0,324942277,130,165963,271068134,ARL,,13.04,2,1,13.03,100,1,13.02,100,1,12.73,100,1,12.71,100,1,12.5,700,1,12.46,200,1,12.43,700,1,12.42,700,1,12.37,700,1,13.57,15,1,13.58,100,1,13.6,15,1,13.61,100,1,13.9,100,1,14.01,2,1,14.19,100,1,14.28,100,1,14.43,100,1,14.53,100,1,2,324942277
2025-07-17T16:01:47.909479724Z,2025-07-17T16:01:47.909314303Z,160,2,1108,C,A,17.400000000,100,0,323599633,0,165421,271068173,ARL,,13.04,2,1,13.03,100,1,13.02,100,1,12.73,100,1,12.71,100,1,12.5,700,1,12.46,200,1,12.43,700,1,12.42,700,1,12.37,700,1,13.57,15,1,13.58,100,1,13.6,15,1,13.61,100,1,13.9,100,1,14.01,2,1,14.19,100,1,14.28,100,1,14.43,100,1,14.53,100,1,2,323599633
2025-07-17T16:01:47.909479724Z,2025-07-17T16:01:47.909314303Z,160,2,1108,A,A,17.250000000,100,0,324942361,130,165421,271068173,ARL,,13.04,2,1,13.03,100,1,13.02,100,1,12.73,100,1,12.71,100,1,12.5,700,1,12.46,200,1,12.43,700,1,12.42,700,1,12.37,700,1,13.57,15,1,13.58,100,1,13.6,15,1,13.61,100,1,13.9,100,1,14.01,2,1,14.19,100,1,14.28,100,1,14.43,100,1,14.53,100,1,2,324942361
2025-07-17T16:01:50.799100504Z,2025-07-17T16:01:50.798934838Z,160,2,1108,A,A,13.590000000,100,0,325022101,130,165666,271131418,ARL,,13.04,2,1,13.03,100,1,13.02,100,1,12.73,100,1,12.71,100,1,12.5,700,1,12.46,200,1,12.43,700,1,12.42,700,1,12.37,700,1,13.57,15,1,13.58,100,1,13.59,100,1,13.6,15,1,13.61,100,1,13.9,100,1,14.01,2,1,14.19,100,1,14.28,100,1,14.43,100,1,2,325022101
2025-07-17T16:01:50.805653961Z,2025-07-17T16:01:50.805488726Z,160,2,1108,C,A,13.610000000,100,0,324782841,130,165235,271131583,ARL,,13.04,2,1,13.03,100,1,13.02,100,1,12.73,100,1,12.71,100,1,12.5,700,1,12.46,200,1,12.43,700,1,12.42,700,1,12.37,700,1,13.57,15,1,13.58,100,1,13.59,100,1,13.6,15,1,13.9,100,1,14.01,2,1,14.19,100,1,14.28,100,1,14.43,100,1,14.53,100,1,2,324782841
2025-07-17T16:01:52.133063761Z,2025-07-17T16:01:52.132898568Z,160,2,1108,C,A,13.600000000,15,0,324619361,130,165193,271153294,ARL,,13.04,2,1,13.03,100,1,13.02,100,1,12.73,100,1,12.71,100,1,12.5,700,1,12.46,200,1,12.43,700,1,12.42,700,1,12.37,700,1,13.57,15,1,13.58,100,1,13.59,100,1,13.9,100,1,14.01,2,1,14.19,100,1,14.28,100,1,14.43,100,1,14.53,100,1,14.54,100,1,2,324619361
2025-07-17T16:01:53.137501962Z,2025-07-17T16:01:53.137336077Z,160,2,1108,A,A,13.550000000,15,0,325109165,130,165885,271200452,ARL,,13.04,2,1,13.03,100,1,13.02,100,1,12.73,100,1,12.71,100,1,12.5,700,1,12.46,200,1,12.43,700,1,12.42,700,1,12.37,700,1,13.55,15,1,13.57,15,1,13.58,100,1,13.59,100,1,13.9,100,1,14.01,2,1,14.19,100,1,14.28,100,1,14.43,100,1,14.53,100,1,2,325109165
2025-07-17T16:01:56.264154095Z,2025-07-17T16:01:56.263988198Z,160,2,1108,C,A,13.580000000,100,0,324942229,0,165897,271251019,ARL,,13.04,2,1,13.03,100,1,13.02,100,1,12.73,100,1,12.71,100,1,12.5,700,1,12.46,200,1,12.43,700,1,12.42,700,1,12.37,700,1,13.55,15,1,13.57,15,1,13.59,100,1,13.9,100,1,14.01,2,1,14.19,100,1,14.28,100,1,14.43,100,1,14.53,100,1,14.54,100,1,2,324942229
2025-07-17T16:01:56.264154095Z,2025-07-17T16:01:56.263988198Z,160,2,1108,A,A,13.560000000,100,0,325176181,130,165897,271251019,ARL,,13.04,2,1,13.03,100,1,13.02,100,1,12.73,100,1,12.71,100,1,12.5,700,1,12.46,200,1,12.43,700,1,12.42,700,1,12.37,700,1,13.55,15,1,13.56,100,1,13.57,15,1,13.59,100,1,13.9,100,1,14.01,2,1,14.19,100,1,14.28,100,1,14.43,100,1,14.53,100,1,2,325176181
2025-07-17T16:01:56.269623788Z,2025-07-17T16:01:56.269458197Z,160,2,1108,C,A,13.900000000,100,0,324186721,130,165591,271251357,ARL,,13.04,2,1,13.03,100,1,13.02,100,1,12.73,100,1,12.71,100,1,12.5,700,1,12.46,200,1,12.43,700,1,12.42,700,1,12.37,700,1,13.55,15,1,13.56,100,1,13.57,15,1,13.59,100,1,14.01,2,1,14.19,100,1,14.28,100,1,14.43,100,1,14.53,100,1,14.54,100,1,2,324186721
2025-07-17T16:01:56.269674232Z,2025-07-17T16:01:56.269508928Z,160,2,1108,A,A,13.830000000,100,0,325176373,130,165304,271251358,ARL,,13.04,2,1,13.03,100,1,13.02,100,1,12.73,100,1,12.71,100,1,12.5,700,1,12.46,200,1,12.43,700,1,12.42,700,1,12.37,700,1,13.55,15,1,13.56,100,1,13.57,15,1,13.59,100,1,13.83,100,1,14.01,2,1,14.19,100,1,14.28,100,1,14.43,100,1,14.53,100,1,2,325176373
2025-07-17T16:01:56.272340730Z,2025-07-17T16:01:56.272175169Z,160,2,1108,C,A,15.760000000,100,0,323599629,0,165561,271251490,ARL,,13.04,2,1,13.03,100,1,13.02,100,1,12.73,100,1,12.71,100,1,12.5,700,1,12.46,200,1,12.43,700,1,12.42,700,1,12.37,700,1,13.55,15,1,13.56,100,1,13.57,15,1,13.59,100,1,13.83,100,1,14.01,2,1,14.19,100,1,14.28,100,1,14.43,100,1,14.53,100,1,2,323599629
2025-07-17T16:01:56.272340730Z,2025-07-17T16:01:56.272175169Z,160,2,1108,A,A,15.600000000,100,0,325176677,130,165561,271251490,ARL,,13.04,2,1,13.03,100,1,13.02,100,1,12.73,100,1,12.71,100,1,12.5,700,1,12.46,200,1,12.43,700,1,12.42,700,1,12.37,700,1,13.55,15,1,13.56,100,1,13.57,15,1,13.59,100,1,13.83,100,1,14.01,2,1,14.19,100,1,14.28,100,1,14.43,100,1,14.53,100,1,2,325176677
2025-07-17T16:01:56.300889378Z,2025-07-17T16:01:56.300723805Z,160,2,1108,C,A,14.660000000,100,0,323599625,0,165573,271252044,ARL,,13.04,2,1,13.03,100,1,13.02,100,1,12.73,100,1,12.71,100,1,12.5,700,1,12.46,200,1,12.43,700,1,12.42,700,1,12.37,700,1,13.55,15,1,13.56,100,1,13.57,15,1,13.59,100,1,13.83,100,1,14.01,2,1,14.19,100,1,14.28,100,1,14.43,100,1,14.53,100,1,2,323599625
2025-07-17T16:01:56.300889378Z,2025-07-17T16:01:56.300723805Z,160,2,1108,A,A,14.510000000,100,0,325177757,130,165573,271252044,ARL,,13.04,2,1,13.03,100,1,13.02,100,1,12.73,100,1,12.71,100,1,12.5,700,1,12.46,200,1,12.43,700,1,12.42,700,1,12.37,700,1,13.55,15,1,13.56,100,1,13.57,15,1,13.59,100,1,13.83,100,1,14.01,2,1,14.19,100,1,14.28,100,1,14.43,100,1,14.51,100,1,2,325177757
2025-07-17T16:02:01.992544607Z,2025-07-17T16:02:01.992379223Z,160,2,1108,C,A,14.010000000,2,0,322898193,0,165384,271343251,ARL,,13.04,2,1,13.03,100,1,13.02,100,1,12.73,100,1,12.71,100,1,12.5,700,1,12.46,200,1,12.43,700,1,12.42,700,1,12.37,700,1,13.55,15,1,13.56,100,1,13.57,15,1,13.59,100,1,13.83,100,1,14.19,100,1,14.28,100,1,14.43,100,1,14.51,100,1,14.53,100,1,2,322898193
2025-07-17T16:02:01.992544607Z,2025-07-17T16:02:01.992379223Z,160,2,1108,A,A,13.920000000,2,0,325297093,130,165384,271343251,ARL,,13.04,2,1,13.03,100,1,13.02,100,1,12.73,100,1,12.71,100,1,12.5,700,1,12.46,200,1,12.43,700,1,12.42,700,1,12.37,700,1,13.55,15,1,13.56,100,1,13.57,15,1,13.59,100,1,13.83,100,1,13.92,2,1,14.19,100,1,14.28,100,1,14.43,100,1,14.51,100,1,2,325297093
2025-07-17T16:02:03.207720826Z,2025-07-17T16:02:03.207555626Z,160,2,1108,C,A,13.570000000,15,0,324934601,130,165200,271367066,ARL,,13.04,2,1,13.03,100,1,13.02,100,1,12.73,100,1,12.71,100,1,12.5,700,1,12.46,200,1,12.43,700,1,12.42,700,1,12.37,700,1,13.55,15,1,13.56,100,1,13.59,100,1,13.83,100,1,13.92,2,1,14.19,100,1,14.28,100,1,14.43,100,1,14.51,100,1,14.53,100,1,2,324934601
2025-07-17T16:02:04.212956339Z,2025-07-17T16:02:04.212791108Z,160,2,1108,A,A,13.530000000,15,0,325382429,130,165231,271415821,ARL,,13.04,2,1,13.03,100,1,13.02,100,1,12.73,100,1,12.71,100,1,12.5,700,1,12.46,200,1,12.43,700,1,12.42,700,1,12.37,700,1,13.53,15,1,13.55,15,1,13.56,100,1,13.59,100,1,13.83,100,1,13.92,2,1,14.19,100,1,14.28,100,1,14.43,100,1,14.51,100,1,2,325382429
2025-07-17T16:02:04.214348814Z,2025-07-17T16:02:04.214183279Z,160,2,1108,C,A,14.540000000,100,0,323775433,0,165535,271415834,ARL,,13.04,2,1,13.03,100,1,13.02,100,1,12.73,100,1,12.71,100,1,12.5,700,1,12.46,200,1,12.43,700,1,12.42,700,1,12.37,700,1,13.53,15,1,13.55,15,1,13.56,100,1,13.59,100,1,13.83,100,1,13.92,2,1,14.19,100,1,14.28,100,1,14.43,100,1,14.51,100,1,2,323775433
2025-07-17T16:02:04.214348814Z,2025-07-17T16:02:04.214183279Z,160,2,1108,A,A,14.430000000,100,0,325382437,130,165535,271415834,ARL,,13.04,2,1,13.03,100,1,13.02,100,1,12.73,100,1,12.71,100,1,12.5,700,1,12.46,200,1,12.43,700,1,12.42,700,1,12.37,700,1,13.53,15,1,13.55,15,1,13.56,100,1,13.59,100,1,13.83,100,1,13.92,2,1,14.19,100,1,14.28,100,1,14.43,200,1,14.51,100,1,2,325382437
2025-07-17T16:02:04.840132668Z,2025-07-17T16:02:04.839967173Z,160,2,1108,C,A,13.560000000,100,0,325176181,0,165495,271432190,ARL,,13.04,2,1,13.03,100,1,13.02,100,1,12.73,100,1,12.71,100,1,12.5,700,1,12.46,200,1,12.43,700,1,12.42,700,1,12.37,700,1,13.53,15,1,13.55,15,1,13.59,100,1,13.83,100,1,13.92,2,1,14.19,100,1,14.28,100,1,14.43,200,1,14.51,100,1,14.53,100,1,2,325176181
