ts_recv,ts_event,rtype,publisher_id,instrument_id,action,side,price,size,channel_id,order_id,flags,ts_in_delta,sequence,symbol,bid_px_00,bid_sz_00,bid_ct_00,bid_px_01,bid_sz_01,bid_ct_01,bid_px_02,bid_sz_02,bid_ct_02,bid_px_03,bid_sz_03,bid_ct_03,bid_px_04,bid_sz_04,bid_ct_04,bid_px_05,bid_sz_05,bid_ct_05,bid_px_06,bid_sz_06,bid_ct_06,bid_px_07,bid_sz_07,bid_ct_07,bid_px_08,bid_sz_08,bid_ct_08,bid_px_09,bid_sz_09,bid_ct_09,ask_px_00,ask_sz_00,ask_ct_00,ask_px_01,ask_sz_01,ask_ct_01,ask_px_02,ask_sz_02,ask_ct_02,ask_px_03,ask_sz_03,ask_ct_03,ask_px_04,ask_sz_04,ask_ct_04,ask_px_05,ask_sz_05,ask_ct_05,ask_px_06,ask_sz_06,ask_ct_06,ask_px_07,ask_sz_07,ask_ct_07,ask_px_08,ask_sz_08,ask_ct_08,ask_px_09,ask_sz_09,ask_ct_09,symbol,order_id
2025-07-17T16:09:52.679844338Z,2025-07-17T16:09:52.679678566Z,160,2,1108,C,A,15.900000000,100,0,334192405,0,165772,279109991,ARL,,13.11,100,1,13.01,2,1,12.98,200,1,12.86,100,1,12.73,100,1,12.71,100,1,12.5,700,1,12.49,200,1,12.46,100,1,12.43,700,1,13.67,15,1,13.68,100,1,13.7,15,1,13.9,2,1,14.01,100,1,14.28,100,1,14.46,100,1,14.48,700,1,14.56,800,1,14.6,700,1,2,334192405
2025-07-17T16:09:52.679844338Z,2025-07-17T16:09:52.679678566Z,160,2,1108,A,A,15.740000000,100,0,335220497,130,165772,279109991,ARL,,13.11,100,1,13.01,2,1,12.98,200,1,12.86,100,1,12.73,100,1,12.71,100,1,12.5,700,1,12.49,200,1,12.46,100,1,12.43,700,1,13.67,15,1,13.68,100,1,13.7,15,1,13.9,2,1,14.01,100,1,14.28,100,1,14.46,100,1,14.48,700,1,14.56,800,1,14.6,700,1,2,335220497
2025-07-17T16:09:52.679936826Z,2025-07-17T16:09:52.679769832Z,160,2,1108,C,A,14.790000000,100,0,334190353,0,166994,279109996,ARL,,13.11,100,1,13.01,2,1,12.98,200,1,12.86,100,1,12.73,100,1,12.71,100,1,12.5,700,1,12.49,200,1,12.46,100,1,12.43,700,1,13.67,15,1,13.68,100,1,13.7,15,1,13.9,2,1,14.01,100,1,14.28,100,1,14.46,100,1,14.48,700,1,14.56,800,1,14.6,700,1,2,334190353
2025-07-17T16:09:52.679936826Z,2025-07-17T16:09:52.679769832Z,160,2,1108,A,A,14.640000000,100,0,335220525,130,166994,279109996,ARL,,13.11,100,1,13.01,2,1,12.98,200,1,12.86,100,1,12.73,100,1,12.71,100,1,12.5,700,1,12.49,200,1,12.46,100,1,12.43,700,1,13.67,15,1,13.68,100,1,13.7,15,1,13.9,2,1,14.01,100,1,14.28,100,1,14.46,100,1,14.48,700,1,14.56,800,1,14.6,700,1,2,335220525
2025-07-17T16:09:52.680837736Z,2025-07-17T16:09:52.680672148Z,160,2,1108,C,A,15.360000000,100,0,333581441,0,165588,279110032,ARL,,13.11,100,1,13.01,2,1,12.98,200,1,12.86,100,1,12.73,100,1,12.71,100,1,12.5,700,1,12.49,200,1,12.46,100,1,12.43,700,1,13.67,15,1,13.68,100,1,13.7,15,1,13.9,2,1,14.01,100,1,14.28,100,1,14.46,100,1,14.48,700,1,14.56,800,1,14.6,700,1,2,333581441
2025-07-17T16:09:52.680837736Z,2025-07-17T16:09:52.680672148Z,160,2,1108,A,A,15.050000000,100,0,335220549,130,165588,279110032,ARL,,13.11,100,1,13.01,2,1,12.98,200,1,12.86,100,1,12.73,100,1,12.71,100,1,12.5,700,1,12.49,200,1,12.46,100,1,12.43,700,1,13.67,15,1,13.68,100,1,13.7,15,1,13.9,2,1,14.01,100,1,14.28,100,1,14.46,100,1,14.48,700,1,14.56,800,1,14.6,700,1,2,335220549
2025-07-17T16:09:52.682009938Z,2025-07-17T16:09:52.681844377Z,160,2,1108,C,A,14.610000000,100,0,334190189,130,165561,279110066,ARL,,13.11,100,1,13.01,2,1,12.98,200,1,12.86,100,1,12.73,100,1,12.71,100,1,12.5,700,1,12.49,200,1,12.46,100,1,12.43,700,1,13.67,15,1,13.68,100,1,13.7,15,1,13.9,2,1,14.01,100,1,14.28,100,1,14.46,100,1,14.48,700,1,14.56,800,1,14.6,700,1,2,334190189
2025-07-17T16:09:52.682127530Z,2025-07-17T16:09:52.681961200Z,160,2,1108,A,A,14.470000000,100,0,335220561,130,166330,279110068,ARL,,13.11,100,1,13.01,2,1,12.98,200,1,12.86,100,1,12.73,100,1,12.71,100,1,12.5,700,1,12.49,200,1,12.46,100,1,12.43,700,1,13.67,15,1,13.68,100,1,13.7,15,1,13.9,2,1,14.01,100,1,14.28,100,1,14.46,100,1,14.47,100,1,14.48,700,1,14.56,800,1,2,335220561
2025-07-17T16:09:52.683922707Z,2025-07-17T16:09:52.683757265Z,160,2,1108,C,A,14.790000000,100,0,334199009,0,165442,279110090,ARL,,13.11,100,1,13.01,2,1,12.98,200,1,12.86,100,1,12.73,100,1,12.71,100,1,12.5,700,1,12.49,200,1,12.46,100,1,12.43,700,1,13.67,15,1,13.68,100,1,13.7,15,1,13.9,2,1,14.01,100,1,14.28,100,1,14.46,100,1,14.47,100,1,14.48,700,1,14.56,800,1,2,334199009
2025-07-17T16:09:52.683922707Z,2025-07-17T16:09:52.683757265Z,160,2,1108,A,A,14.640000000,100,0,335220629,130,165442,279110090,ARL,,13.11,100,1,13.01,2,1,12.98,200,1,12.86,100,1,12.73,100,1,12.71,100,1,12.5,700,1,12.49,200,1,12.46,100,1,12.43,700,1,13.67,15,1,13.68,100,1,13.7,15,1,13.9,2,1,14.01,100,1,14.28,100,1,14.46,100,1,14.47,100,1,14.48,700,1,14.56,800,1,2,335220629
2025-07-17T16:10:04.521471804Z,2025-07-17T16:10:04.521306513Z,160,2,1108,C,A,13.670000000,15,0,335178437,130,165291,279306715,ARL,,13.11,100,1,13.01,2,1,12.98,200,1,12.86,100,1,12.73,100,1,12.71,100,1,12.5,700,1,12.49,200,1,12.46,100,1,12.43,700,1,13.68,100,1,13.7,15,1,13.9,2,1,14.01,100,1,14.28,100,1,14.46,100,1,14.47,100,1,14.48,700,1,14.56,800,1,14.6,700,1,2,335178437
2025-07-17T16:10:04.561854856Z,2025-07-17T16:10:04.561688313Z,160,2,1108,C,A,13.700000000,15,0,335003269,128,166543,279312083,ARL,,13.11,100,1,13.01,2,1,12.98,200,1,12.86,100,1,12.73,100,1,12.71,100,1,12.5,700,1,12.49,200,1,12.46,100,1,12.43,700,1,13.68,100,1,13.9,2,1,14.01,100,1,14.28,100,1,14.46,100,1,14.47,100,1,14.48,700,1,14.56,800,1,14.6,700,1,14.62,200,1,2,335003269
2025-07-17T16:10:32.822660498Z,2025-07-17T16:10:32.822495087Z,160,2,1108,A,A,13.650000000,15,0,335996705,130,165411,279705339,ARL,,13.11,100,1,13.01,2,1,12.98,200,1,12.86,100,1,12.73,100,1,12.71,100,1,12.5,700,1,12.49,200,1,12.46,100,1,12.43,700,1,13.65,15,1,13.68,100,1,13.9,2,1,14.01,100,1,14.28,100,1,14.46,100,1,14.47,100,1,14.48,700,1,14.56,800,1,14.6,700,1,2,335996705
2025-07-17T16:10:32.822923138Z,2025-07-17T16:10:32.822757517Z,160,2,1108,C,A,13.680000000,100,0,335220349,0,165621,279705347,ARL,,13.11,100,1,13.01,2,1,12.98,200,1,12.86,100,1,12.73,100,1,12.71,100,1,12.5,700,1,12.49,200,1,12.46,100,1,12.43,700,1,13.65,15,1,13.9,2,1,14.01,100,1,14.28,100,1,14.46,100,1,14.47,100,1,14.48,700,1,14.56,800,1,14.6,700,1,14.62,200,1,2,335220349
2025-07-17T16:10:32.822923138Z,2025-07-17T16:10:32.822757517Z,160,2,1108,A,A,13.660000000,100,0,335996709,130,165621,279705347,ARL,,13.11,100,1,13.01,2,1,12.98,200,1,12.86,100,1,12.73,100,1,12.71,100,1,12.5,700,1,12.49,200,1,12.46,100,1,12.43,700,1,13.65,15,1,13.66,100,1,13.9,2,1,14.01,100,1,14.28,100,1,14.46,100,1,14.47,100,1,14.48,700,1,14.56,800,1,14.6,700,1,2,335996709
2025-07-17T16:10:32.823656903Z,2025-07-17T16:10:32.823491276Z,160,2,1108,C,A,14.770000000,100,0,335003845,0,165627,279705362,ARL,,13.11,100,1,13.01,2,1,12.98,200,1,12.86,100,1,12.73,100,1,12.71,100,1,12.5,700,1,12.49,200,1,12.46,100,1,12.43,700,1,13.65,15,1,13.66,100,1,13.9,2,1,14.01,100,1,14.28,100,1,14.46,100,1,14.47,100,1,14.48,700,1,14.56,800,1,14.6,700,1,2,335003845
2025-07-17T16:10:32.823656903Z,2025-07-17T16:10:32.823491276Z,160,2,1108,A,A,14.720000000,100,0,335996725,130,165627,279705362,ARL,,13.11,100,1,13.01,2,1,12.98,200,1,12.86,100,1,12.73,100,1,12.71,100,1,12.5,700,1,12.49,200,1,12.46,100,1,12.43,700,1,13.65,15,1,13.66,100,1,13.9,2,1,14.01,100,1,14.28,100,1,14.46,100,1,14.47,100,1,14.48,700,1,14.56,800,1,14.6,700,1,2,335996725
2025-07-17T16:10:32.830200844Z,2025-07-17T16:10:32.830032662Z,160,2,1108,C,A,14.010000000,100,0,334593753,130,168182,279705485,ARL,,13.11,100,1,13.01,2,1,12.98,200,1,12.86,100,1,12.73,100,1,12.71,100,1,12.5,700,1,12.49,200,1,12.46,100,1,12.43,700,1,13.65,15,1,13.66,100,1,13.9,2,1,14.28,100,1,14.46,100,1,14.47,100,1,14.48,700,1,14.56,800,1,14.6,700,1,14.62,200,1,2,334593753
2025-07-17T16:10:32.830250720Z,2025-07-17T16:10:32.830085472Z,160,2,1108,A,A,13.930000000,100,0,335996777,130,165248,279705486,ARL,,13.11,100,1,13.01,2,1,12.98,200,1,12.86,100,1,12.73,100,1,12.71,100,1,12.5,700,1,12.49,200,1,12.46,100,1,12.43,700,1,13.65,15,1,13.66,100,1,13.9,2,1,13.93,100,1,14.28,100,1,14.46,100,1,14.47,100,1,14.48,700,1,14.56,800,1,14.6,700,1,2,335996777
2025-07-17T16:10:42.822354869Z,2025-07-17T16:10:42.822189504Z,160,2,1108,A,A,13.630000000,15,0,336161333,130,165365,279834760,ARL,,13.11,100,1,13.01,2,1,12.98,200,1,12.86,100,1,12.73,100,1,12.71,100,1,12.5,700,1,12.49,200,1,12.46,100,1,12.43,700,1,13.63,15,1,13.65,15,1,13.66,100,1,13.9,2,1,13.93,100,1,14.28,100,1,14.46,100,1,14.47,100,1,14.48,700,1,14.56,800,1,2,336161333
2025-07-17T16:10:42.822424663Z,2025-07-17T16:10:42.822258887Z,160,2,1108,C,A,13.660000000,100,0,335996709,0,165776,279834761,ARL,,13.11,100,1,13.01,2,1,12.98,200,1,12.86,100,1,12.73,100,1,12.71,100,1,12.5,700,1,12.49,200,1,12.46,100,1,12.43,700,1,13.63,15,1,13.65,15,1,13.9,2,1,13.93,100,1,14.28,100,1,14.46,100,1,14.47,100,1,14.48,700,1,14.56,800,1,14.6,700,1,2,335996709
2025-07-17T16:10:42.822424663Z,2025-07-17T16:10:42.822258887Z,160,2,1108,A,A,13.640000000,100,0,336161337,130,165776,279834761,ARL,,13.11,100,1,13.01,2,1,12.98,200,1,12.86,100,1,12.73,100,1,12.71,100,1,12.5,700,1,12.49,200,1,12.46,100,1,12.43,700,1,13.63,15,1,13.64,100,1,13.65,15,1,13.9,2,1,13.93,100,1,14.28,100,1,14.46,100,1,14.47,100,1,14.48,700,1,14.56,800,1,2,336161337
2025-07-17T16:10:42.823163929Z,2025-07-17T16:10:42.822998664Z,160,2,1108,C,A,14.460000000,100,0,331927161,130,165265,279834765,ARL,,13.11,100,1,13.01,2,1,12.98,200,1,12.86,100,1,12.73,100,1,12.71,100,1,12.5,700,1,12.49,200,1,12.46,100,1,12.43,700,1,13.63,15,1,13.64,100,1,13.65,15,1,13.9,2,1,13.93,100,1,14.28,100,1,14.47,100,1,14.48,700,1,14.56,800,1,14.6,700,1,2,331927161
2025-07-17T16:10:42.823517444Z,2025-07-17T16:10:42.823352130Z,160,2,1108,A,A,14.250000000,100,0,336161365,130,165314,279834767,ARL,,13.11,100,1,13.01,2,1,12.98,200,1,12.86,100,1,12.73,100,1,12.71,100,1,12.5,700,1,12.49,200,1,12.46,100,1,12.43,700,1,13.63,15,1,13.64,100,1,13.65,15,1,13.9,2,1,13.93,100,1,14.25,100,1,14.28,100,1,14.47,100,1,14.48,700,1,14.56,800,1,2,336161365
2025-07-17T16:10:46.534055942Z,2025-07-17T16:10:46.533890361Z,160,2,1108,C,A,14.620000000,100,0,334583349,0,165581,279921726,ARL,,13.11,100,1,13.01,2,1,12.98,200,1,12.86,100,1,12.73,100,1,12.71,100,1,12.5,700,1,12.49,200,1,12.46,100,1,12.43,700,1,13.63,15,1,13.64,100,1,13.65,15,1,13.9,2,1,13.93,100,1,14.25,100,1,14.28,100,1,14.47,100,1,14.48,700,1,14.56,800,1,2,334583349
2025-07-17T16:10:46.534055942Z,2025-07-17T16:10:46.533890361Z,160,2,1108,A,A,14.510000000,100,0,336259225,130,165581,279921726,ARL,,13.11,100,1,13.01,2,1,12.98,200,1,12.86,100,1,12.73,100,1,12.71,100,1,12.5,700,1,12.49,200,1,12.46,100,1,12.43,700,1,13.63,15,1,13.64,100,1,13.65,15,1,13.9,2,1,13.93,100,1,14.25,100,1,14.28,100,1,14.47,100,1,14.48,700,1,14.51,100,1,2,336259225
2025-07-17T16:10:46.538158874Z,2025-07-17T16:10:46.537992315Z,160,2,1108,C,A,13.650000000,15,0,335996705,128,166559,279921911,ARL,,13.11,100,1,13.01,2,1,12.98,200,1,12.86,100,1,12.73,100,1,12.71,100,1,12.5,700,1,12.49,200,1,12.46,100,1,12.43,700,1,13.63,15,1,13.64,100,1,13.9,2,1,13.93,100,1,14.25,100,1,14.28,100,1,14.47,100,1,14.48,700,1,14.51,100,1,14.56,800,1,2,335996705
2025-07-17T16:10:46.561246030Z,2025-07-17T16:10:46.561080616Z,160,2,1108,C,A,14.620000000,100,0,334583361,0,165414,279924883,ARL,,13.11,100,1,13.01,2,1,12.98,200,1,12.86,100,1,12.73,100,1,12.71,100,1,12.5,700,1,12.49,200,1,12.46,100,1,12.43,700,1,13.63,15,1,13.64,100,1,13.9,2,1,13.93,100,1,14.25,100,1,14.28,100,1,14.47,100,1,14.48,700,1,14.51,100,1,14.56,800,1,2,334583361
2025-07-17T16:10:46.561246030Z,2025-07-17T16:10:46.561080616Z,160,2,1108,A,A,14.510000000,100,0,336261905,130,165414,279924883,ARL,,13.11,100,1,13.01,2,1,12.98,200,1,12.86,100,1,12.73,100,1,12.71,100,1,12.5,700,1,12.49,200,1,12.46,100,1,12.43,700,1,13.63,15,1,13.64,100,1,13.9,2,1,13.93,100,1,14.25,100,1,14.28,100,1,14.47,100,1,14.48,700,1,14.51,200,1,14.56,800,1,2,336261905
2025-07-17T16:10:47.543404001Z,2025-07-17T16:10:47.543238729Z,160,2,1108,A,A,13.610000000,15,0,336278197,130,165272,279938097,ARL,,13.11,100,1,13.01,2,1,12.98,200,1,12.86,100,1,12.73,100,1,12.71,100,1,12.5,700,1,12.49,200,1,12.46,100,1,12.43,700,1,13.61,15,1,13.63,15,1,13.64,100,1,13.9,2,1,13.93,100,1,14.25,100,1,14.28,100,1,14.47,100,1,14.48,700,1,14.51,200,1,2,336278197
2025-07-17T16:10:48.657456395Z,2025-07-17T16:10:48.657290980Z,160,2,1108,C,A,13.640000000,100,0,336161337,0,165415,279952266,ARL,,13.11,100,1,13.01,2,1,12.98,200,1,12.86,100,1,12.73,100,1,12.71,100,1,12.5,700,1,12.49,200,1,12.46,100,1,12.43,700,1,13.61,15,1,13.63,15,1,13.9,2,1,13.93,100,1,14.25,100,1,14.28,100,1,14.47,100,1,14.48,700,1,14.51,200,1,14.56,800,1,2,336161337
2025-07-17T16:10:48.657456395Z,2025-07-17T16:10:48.657290980Z,160,2,1108,A,A,13.620000000,100,0,336295769,130,165415,279952266,ARL,,13.11,100,1,13.01,2,1,12.98,200,1,12.86,100,1,12.73,100,1,12.71,100,1,12.5,700,1,12.49,200,1,12.46,100,1,12.43,700,1,13.61,15,1,13.62,100,1,13.63,15,1,13.9,2,1,13.93,100,1,14.25,100,1,14.28,100,1,14.47,100,1,14.48,700,1,14.51,200,1,2,336295769
2025-07-17T16:10:48.658199425Z,2025-07-17T16:10:48.658033954Z,160,2,1108,C,A,14.720000000,100,0,335996725,0,165471,279952282,ARL,,13.11,100,1,13.01,2,1,12.98,200,1,12.86,100,1,12.73,100,1,12.71,100,1,12.5,700,1,12.49,200,1,12.46,100,1,12.43,700,1,13.61,15,1,13.62,100,1,13.63,15,1,13.9,2,1,13.93,100,1,14.25,100,1,14.28,100,1,14.47,100,1,14.48,700,1,14.51,200,1,2,335996725
2025-07-17T16:10:48.658199425Z,2025-07-17T16:10:48.658033954Z,160,2,1108,A,A,14.680000000,100,0,336295845,130,165471,279952282,ARL,,13.11,100,1,13.01,2,1,12.98,200,1,12.86,100,1,12.73,100,1,12.71,100,1,12.5,700,1,12.49,200,1,12.46,100,1,12.43,700,1,13.61,15,1,13.62,100,1,13.63,15,1,13.9,2,1,13.93,100,1,14.25,100,1,14.28,100,1,14.47,100,1,14.48,700,1,14.51,200,1,2,336295845
2025-07-17T16:10:51.059044292Z,2025-07-17T16:10:51.058878264Z,160,2,1108,C,A,13.610000000,15,0,336278197,128,166028,280001840,ARL,,13.11,100,1,13.01,2,1,12.98,200,1,12.86,100,1,12.73,100,1,12.71,100,1,12.5,700,1,12.49,200,1,12.46,100,1,12.43,700,1,13.62,100,1,13.63,15,1,13.9,2,1,13.93,100,1,14.25,100,1,14.28,100,1,14.47,100,1,14.48,700,1,14.51,200,1,14.56,800,1,2,336278197
2025-07-17T16:10:51.059183923Z,2025-07-17T16:10:51.059016199Z,160,2,1108,C,A,13.630000000,15,0,336161333,128,167724,280001873,ARL,,13.11,100,1,13.01,2,1,12.98,200,1,12.86,100,1,12.73,100,1,12.71,100,1,12.5,700,1,12.49,200,1,12.46,100,1,12.43,700,1,13.62,100,1,13.9,2,1,13.93,100,1,14.25,100,1,14.28,100,1,14.47,100,1,14.48,700,1,14.51,200,1,14.56,800,1,14.6,700,1,2,336161333
2025-07-17T16:10:51.059608753Z,2025-07-17T16:10:51.059443298Z,160,2,1108,C,A,13.620000000,100,0,336295769,130,165455,280001952,ARL,,13.11,100,1,13.01,2,1,12.98,200,1,12.86,100,1,12.73,100,1,12.71,100,1,12.5,700,1,12.49,200,1,12.46,100,1,12.43,700,1,13.9,2,1,13.93,100,1,14.25,100,1,14.28,100,1,14.47,100,1,14.48,700,1,14.51,200,1,14.56,800,1,14.6,700,1,14.64,200,1,2,336295769
2025-07-17T16:10:51.170710609Z,2025-07-17T16:10:51.170545251Z,160,2,1108,A,A,13.910000000,100,0,336351081,130,165358,280003702,ARL,,13.11,100,1,13.01,2,1,12.98,200,1,12.86,100,1,12.73,100,1,12.71,100,1,12.5,700,1,12.49,200,1,12.46,100,1,12.43,700,1,13.9,2,1,13.91,100,1,13.93,100,1,14.25,100,1,14.28,100,1,14.47,100,1,14.48,700,1,14.51,200,1,14.56,800,1,14.6,700,1,2,336351081
2025-07-17T16:10:52.958453641Z,2025-07-17T16:10:52.958288317Z,160,2,1108,A,A,13.600000000,15,0,336402845,130,165324,280050139,ARL,,13.11,100,1,13.01,2,1,12.98,200,1,12.86,100,1,12.73,100,1,12.71,100,1,12.5,700,1,12.49,200,1,12.46,100,1,12.43,700,1,13.6,15,1,13.9,2,1,13.91,100,1,13.93,100,1,14.25,100,1,14.28,100,1,14.47,100,1,14.48,700,1,14.51,200,1,14.56,800,1,2,336402845
2025-07-17T16:10:53.102037173Z,2025-07-17T16:10:53.101871639Z,160,2,1108,C,A,13.910000000,100,0,336351081,0,165534,280057228,ARL,,13.11,100,1,13.01,2,1,12.98,200,1,12.86,100,1,12.73,100,1,12.71,100,1,12.5,700,1,12.49,200,1,12.46,100,1,12.43,700,1,13.6,15,1,13.9,2,1,13.93,100,1,14.25,100,1,14.28,100,1,14.47,100,1,14.48,700,1,14.51,200,1,14.56,800,1,14.6,700,1,2,336351081
2025-07-17T16:10:53.102037173Z,2025-07-17T16:10:53.101871639Z,160,2,1108,A,A,13.610000000,100,0,336410125,130,165534,280057228,ARL,,13.11,100,1,13.01,2,1,12.98,200,1,12.86,100,1,12.73,100,1,12.71,100,1,12.5,700,1,12.49,200,1,12.46,100,1,12.43,700,1,13.6,15,1,13.61,100,1,13.9,2,1,13.93,100,1,14.25,100,1,14.28,100,1,14.47,100,1,14.48,700,1,14.51,200,1,14.56,800,1,2,336410125
2025-07-17T16:10:54.959307592Z,2025-07-17T16:10:54.959141873Z,160,2,1108,C,A,13.900000000,2,0,334804177,0,165719,280084546,ARL,,13.11,100,1,13.01,2,1,12.98,200,1,12.86,100,1,12.73,100,1,12.71,100,1,12.5,700,1,12.49,200,1,12.46,100,1,12.43,700,1,13.6,15,1,13.61,100,1,13.93,100,1,14.25,100,1,14.28,100,1,14.47,100,1,14.48,700,1,14.51,200,1,14.56,800,1,14.6,700,1,2,334804177
2025-07-17T16:10:54.959307592Z,2025-07-17T16:10:54.959141873Z,160,2,1108,A,A,13.820000000,2,0,336447325,130,165719,280084546,ARL,,13.11,100,1,13.01,2,1,12.98,200,1,12.86,100,1,12.73,100,1,12.71,100,1,12.5,700,1,12.49,200,1,12.46,100,1,12.43,700,1,13.6,15,1,13.61,100,1,13.82,2,1,13.93,100,1,14.25,100,1,14.28,100,1,14.47,100,1,14.48,700,1,14.51,200,1,14.56,800,1,2,336447325
2025-07-17T16:10:59.518035805Z,2025-07-17T16:10:59.517870358Z,160,2,1108,A,A,13.580000000,15,0,336555153,130,165447,280173685,ARL,,13.11,100,1,13.01,2,1,12.98,200,1,12.86,100,1,12.73,100,1,12.71,100,1,12.5,700,1,12.49,200,1,12.46,100,1,12.43,700,1,13.58,15,1,13.6,15,1,13.61,100,1,13.82,2,1,13.93,100,1,14.25,100,1,14.28,100,1,14.47,100,1,14.48,700,1,14.51,200,1,2,336555153
2025-07-17T16:11:00.215885294Z,2025-07-17T16:11:00.215719725Z,160,2,1108,C,A,13.610000000,100,0,336410125,0,165569,280184406,ARL,,13.11,100,1,13.01,2,1,12.98,200,1,12.86,100,1,12.73,100,1,12.71,100,1,12.5,700,1,12.49,200,1,12.46,100,1,12.43,700,1,13.58,15,1,13.6,15,1,13.82,2,1,13.93,100,1,14.25,100,1,14.28,100,1,14.47,100,1,14.48,700,1,14.51,200,1,14.56,800,1,2,336410125
2025-07-17T16:11:00.215885294Z,2025-07-17T16:11:00.215719725Z,160,2,1108,A,A,13.590000000,100,0,336567189,130,165569,280184406,ARL,,13.11,100,1,13.01,2,1,12.98,200,1,12.86,100,1,12.73,100,1,12.71,100,1,12.5,700,1,12.49,200,1,12.46,100,1,12.43,700,1,13.58,15,1,13.59,100,1,13.6,15,1,13.82,2,1,13.93,100,1,14.25,100,1,14.28,100,1,14.47,100,1,14.48,700,1,14.51,200,1,2,336567189
2025-07-17T16:11:00.216622121Z,2025-07-17T16:11:00.216456547Z,160,2,1108,C,A,14.680000000,100,0,336295845,0,165574,280184418,ARL,,13.11,100,1,13.01,2,1,12.98,200,1,12.86,100,1,12.73,100,1,12.71,100,1,12.5,700,1,12.49,200,1,12.46,100,1,12.43,700,1,13.58,15,1,13.59,100,1,13.6,15,1,13.82,2,1,13.93,100,1,14.25,100,1,14.28,100,1,14.47,100,1,14.48,700,1,14.51,200,1,2,336295845
2025-07-17T16:11:00.216622121Z,2025-07-17T16:11:00.216456547Z,160,2,1108,A,A,14.640000000,100,0,336567213,130,165574,280184418,ARL,,13.11,100,1,13.01,2,1,12.98,200,1,12.86,100,1,12.73,100,1,12.71,100,1,12.5,700,1,12.49,200,1,12.46,100,1,12.43,700,1,13.58,15,1,13.59,100,1,13.6,15,1,13.82,2,1,13.93,100,1,14.25,100,1,14.28,100,1,14.47,100,1,14.48,700,1,14.51,200,1,2,336567213
2025-07-17T16:11:00.228999377Z,2025-07-17T16:11:00.228833925Z,160,2,1108,C,A,13.930000000,100,0,335996777,130,165452,280184613,ARL,,13.11,100,1,13.01,2,1,12.98,200,1,12.86,100,1,12.73,100,1,12.71,100,1,12.5,700,1,12.49,200,1,12.46,100,1,12.43,700,1,13.58,15,1,13.59,100,1,13.6,15,1,13.82,2,1,14.25,100,1,14.28,100,1,14.47,100,1,14.48,700,1,14.51,200,1,14.56,800,1,2,335996777
2025-07-17T16:11:00.229051124Z,2025-07-17T16:11:00.228885790Z,160,2,1108,A,A,13.860000000,100,0,336567333,130,165334,280184614,ARL,,13.11,100,1,13.01,2,1,12.98,200,1,12.86,100,1,12.73,100,1,12.71,100,1,12.5,700,1,12.49,200,1,12.46,100,1,12.43,700,1,13.58,15,1,13.59,100,1,13.6,15,1,13.82,2,1,13.86,100,1,14.25,100,1,14.28,100,1,14.47,100,1,14.48,700,1,14.51,200,1,2,336567333
2025-07-17T16:11:00.313087129Z,2025-07-17T16:11:00.312921679Z,160,2,1108,C,A,17.420000000,100,0,335003849,0,165450,280188038,ARL,,13.11,100,1,13.01,2,1,12.98,200,1,12.86,100,1,12.73,100,1,12.71,100,1,12.5,700,1,12.49,200,1,12.46,100,1,12.43,700,1,13.58,15,1,13.59,100,1,13.6,15,1,13.82,2,1,13.86,100,1,14.25,100,1,14.28,100,1,14.47,100,1,14.48,700,1,14.51,200,1,2,335003849
2025-07-17T16:11:00.313087129Z,2025-07-17T16:11:00.312921679Z,160,2,1108,A,A,17.260000000,100,0,336570921,130,165450,280188038,ARL,,13.11,100,1,13.01,2,1,12.98,200,1,12.86,100,1,12.73,100,1,12.71,100,1,12.5,700,1,12.49,200,1,12.46,100,1,12.43,700,1,13.58,15,1,13.59,100,1,13.6,15,1,13.82,2,1,13.86,100,1,14.25,100,1,14.28,100,1,14.47,100,1,14.48,700,1,14.51,200,1,2,336570921
2025-07-17T16:11:00.366811541Z,2025-07-17T16:11:00.366645846Z,160,2,1108,A,A,13.620000000,1,0,336572049,130,165695,280189435,ARL,,13.11,100,1,13.01,2,1,12.98,200,1,12.86,100,1,12.73,100,1,12.71,100,1,12.5,700,1,12.49,200,1,12.46,100,1,12.43,700,1,13.58,15,1,13.59,100,1,13.6,15,1,13.62,1,1,13.82,2,1,13.86,100,1,14.25,100,1,14.28,100,1,14.47,100,1,14.48,700,1,2,336572049
2025-07-17T16:11:00.367374773Z,2025-07-17T16:11:00.367209243Z,160,2,1108,C,B,12.490000000,100,0,331942945,0,165530,280189439,ARL,,13.11,100,1,13.01,2,1,12.98,200,1,12.86,100,1,12.73,100,1,12.71,100,1,12.5,700,1,12.49,100,1,12.46,100,1,12.43,700,1,13.58,15,1,13.59,100,1,13.6,15,1,13.62,1,1,13.82,2,1,13.86,100,1,14.25,100,1,14.28,100,1,14.47,100,1,14.48,700,1,2,331942945
2025-07-17T16:11:00.367374773Z,2025-07-17T16:11:00.367209243Z,160,2,1108,A,B,12.360000000,100,0,336572057,130,165530,280189439,ARL,,13.11,100,1,13.01,2,1,12.98,200,1,12.86,100,1,12.73,100,1,12.71,100,1,12.5,700,1,12.49,100,1,12.46,100,1,12.43,700,1,13.58,15,1,13.59,100,1,13.6,15,1,13.62,1,1,13.82,2,1,13.86,100,1,14.25,100,1,14.28,100,1,14.47,100,1,14.48,700,1,2,336572057
2025-07-17T16:11:00.367485094Z,2025-07-17T16:11:00.367319059Z,160,2,1108,C,B,12.490000000,100,0,331942901,0,166035,280189441,ARL,,13.11,100,1,13.01,2,1,12.98,200,1,12.86,100,1,12.73,100,1,12.71,100,1,12.5,700,1,12.46,100,1,12.43,700,1,12.42,700,1,13.58,15,1,13.59,100,1,13.6,15,1,13.62,1,1,13.82,2,1,13.86,100,1,14.25,100,1,14.28,100,1,14.47,100,1,14.48,700,1,2,331942901
2025-07-17T16:11:00.367485094Z,2025-07-17T16:11:00.367319059Z,160,2,1108,A,B,12.360000000,100,0,336572069,130,166035,280189441,ARL,,13.11,100,1,13.01,2,1,12.98,200,1,12.86,100,1,12.73,100,1,12.71,100,1,12.5,700,1,12.46,100,1,12.43,700,1,12.42,700,1,13.58,15,1,13.59,100,1,13.6,15,1,13.62,1,1,13.82,2,1,13.86,100,1,14.25,100,1,14.28,100,1,14.47,100,1,14.48,700,1,2,336572069
2025-07-17T16:11:00.466868624Z,2025-07-17T16:11:00.466703632Z,160,2,1108,C,A,13.620000000,1,0,336572049,130,164992,280191783,ARL,,13.11,100,1,13.01,2,1,12.98,200,1,12.86,100,1,12.73,100,1,12.71,100,1,12.5,700,1,12.46,100,1,12.43,700,1,12.42,700,1,13.58,15,1,13.59,100,1,13.6,15,1,13.82,2,1,13.86,100,1,14.25,100,1,14.28,100,1,14.47,100,1,14.48,700,1,14.51,200,1,2,336572049
2025-07-17T16:11:06.626831799Z,2025-07-17T16:11:06.626666474Z,160,2,1108,A,A,14.270000000,700,0,336747457,130,165325,280342316,ARL,,13.11,100,1,13.01,2,1,12.98,200,1,12.86,100,1,12.73,100,1,12.71,100,1,12.5,700,1,12.46,100,1,12.43,700,1,12.42,700,1,13.58,15,1,13.59,100,1,13.6,15,1,13.82,2,1,13.86,100,1,14.25,100,1,14.27,700,1,14.28,100,1,14.47,100,1,14.48,700,1,2,336747457
2025-07-17T16:11:06.626906700Z,2025-07-17T16:11:06.626741446Z,160,2,1108,C,A,14.680000000,700,0,331929977,130,165254,280342318,ARL,,13.11,100,1,13.01,2,1,12.98,200,1,12.86,100,1,12.73,100,1,12.71,100,1,12.5,700,1,12.46,100,1,12.43,700,1,12.42,700,1,13.58,15,1,13.59,100,1,13.6,15,1,13.82,2,1,13.86,100,1,14.25,100,1,14.27,700,1,14.28,100,1,14.47,100,1,14.48,700,1,2,331929977
2025-07-17T16:11:08.308034538Z,2025-07-17T16:11:08.307868957Z,160,2,1108,C,A,13.600000000,15,0,336402845,130,165581,280374785,ARL,,13.11,100,1,13.01,2,1,12.98,200,1,12.86,100,1,12.73,100,1,12.71,100,1,12.5,700,1,12.46,100,1,12.43,700,1,12.42,700,1,13.58,15,1,13.59,100,1,13.82,2,1,13.86,100,1,14.25,100,1,14.27,700,1,14.28,100,1,14.47,100,1,14.48,700,1,14.51,200,1,2,336402845
2025-07-17T16:11:09.568536292Z,2025-07-17T16:11:09.568370995Z,160,2,1108,A,A,13.560000000,15,0,336816813,130,165297,280401189,ARL,,13.11,100,1,13.01,2,1,12.98,200,1,12.86,100,1,12.73,100,1,12.71,100,1,12.5,700,1,12.46,100,1,12.43,700,1,12.42,700,1,13.56,15,1,13.58,15,1,13.59,100,1,13.82,2,1,13.86,100,1,14.25,100,1,14.27,700,1,14.28,100,1,14.47,100,1,14.48,700,1,2,336816813
2025-07-17T16:11:10.341953971Z,2025-07-17T16:11:10.341788521Z,160,2,1108,C,A,13.590000000,100,0,336567189,0,165450,280411396,ARL,,13.11,100,1,13.01,2,1,12.98,200,1,12.86,100,1,12.73,100,1,12.71,100,1,12.5,700,1,12.46,100,1,12.43,700,1,12.42,700,1,13.56,15,1,13.58,15,1,13.82,2,1,13.86,100,1,14.25,100,1,14.27,700,1,14.28,100,1,14.47,100,1,14.48,700,1,14.51,200,1,2,336567189
2025-07-17T16:11:10.341953971Z,2025-07-17T16:11:10.341788521Z,160,2,1108,A,A,13.570000000,100,0,336828765,130,165450,280411396,ARL,,13.11,100,1,13.01,2,1,12.98,200,1,12.86,100,1,12.73,100,1,12.71,100,1,12.5,700,1,12.46,100,1,12.43,700,1,12.42,700,1,13.56,15,1,13.57,100,1,13.58,15,1,13.82,2,1,13.86,100,1,14.25,100,1,14.27,700,1,14.28,100,1,14.47,100,1,14.48,700,1,2,336828765
2025-07-17T16:11:14.610701450Z,2025-07-17T16:11:14.610535763Z,160,2,1108,C,A,13.580000000,15,0,336555153,130,165687,280482371,ARL,,13.11,100,1,13.01,2,1,12.98,200,1,12.86,100,1,12.73,100,1,12.71,100,1,12.5,700,1,12.46,100,1,12.43,700,1,12.42,700,1,13.56,15,1,13.57,100,1,13.82,2,1,13.86,100,1,14.25,100,1,14.27,700,1,14.28,100,1,14.47,100,1,14.48,700,1,14.51,200,1,2,336555153
2025-07-17T16:11:16.025458231Z,2025-07-17T16:11:16.025292936Z,160,2,1108,C,A,13.560000000,15,0,336816813,130,165295,280514282,ARL,,13.11,100,1,13.01,2,1,12.98,200,1,12.86,100,1,12.73,100,1,12.71,100,1,12.5,700,1,12.46,100,1,12.43,700,1,12.42,700,1,13.57,100,1,13.82,2,1,13.86,100,1,14.25,100,1,14.27,700,1,14.28,100,1,14.47,100,1,14.48,700,1,14.51,200,1,14.56,800,1,2,336816813
2025-07-17T16:11:50.026837358Z,2025-07-17T16:11:50.026672014Z,160,2,1108,A,A,13.550000000,15,0,337690189,130,165344,281078802,ARL,,13.11,100,1,13.01,2,1,12.98,200,1,12.86,100,1,12.73,100,1,12.71,100,1,12.5,700,1,12.46,100,1,12.43,700,1,12.42,700,1,13.55,15,1,13.57,100,1,13.82,2,1,13.86,100,1,14.25,100,1,14.27,700,1,14.28,100,1,14.47,100,1,14.48,700,1,14.51,200,1,2,337690189
2025-07-17T16:11:50.027004977Z,2025-07-17T16:11:50.026839463Z,160,2,1108,C,A,13.570000000,100,0,336828765,0,165514,281078803,ARL,,13.11,100,1,13.01,2,1,12.98,200,1,12.86,100,1,12.73,100,1,12.71,100,1,12.5,700,1,12.46,100,1,12.43,700,1,12.42,700,1,13.55,15,1,13.82,2,1,13.86,100,1,14.25,100,1,14.27,700,1,14.28,100,1,14.47,100,1,14.48,700,1,14.51,200,1,14.56,800,1,2,336828765
2025-07-17T16:11:50.027004977Z,2025-07-17T16:11:50.026839463Z,160,2,1108,A,A,13.560000000,100,0,337690193,130,165514,281078803,ARL,,13.11,100,1,13.01,2,1,12.98,200,1,12.86,100,1,12.73,100,1,12.71,100,1,12.5,700,1,12.46,100,1,12.43,700,1,12.42,700,1,13.55,15,1,13.56,100,1,13.82,2,1,13.86,100,1,14.25,100,1,14.27,700,1,14.28,100,1,14.47,100,1,14.48,700,1,14.51,200,1,2,337690193
2025-07-17T16:11:50.033010798Z,2025-07-17T16:11:50.032845393Z,160,2,1108,C,A,15.740000000,100,0,335220497,0,165405,281078903,ARL,,13.11,100,1,13.01,2,1,12.98,200,1,12.86,100,1,12.73,100,1,12.71,100,1,12.5,700,1,12.46,100,1,12.43,700,1,12.42,700,1,13.55,15,1,13.56,100,1,13.82,2,1,13.86,100,1,14.25,100,1,14.27,700,1,14.28,100,1,14.47,100,1,14.48,700,1,14.51,200,1,2,335220497
2025-07-17T16:11:50.033010798Z,2025-07-17T16:11:50.032845393Z,160,2,1108,A,A,15.600000000,100,0,337690641,130,165405,281078903,ARL,,13.11,100,1,13.01,2,1,12.98,200,1,12.86,100,1,12.73,100,1,12.71,100,1,12.5,700,1,12.46,100,1,12.43,700,1,12.42,700,1,13.55,15,1,13.56,100,1,13.82,2,1,13.86,100,1,14.25,100,1,14.27,700,1,14.28,100,1,14.47,100,1,14.48,700,1,14.51,200,1,2,337690641
2025-07-17T16:11:53.859909462Z,2025-07-17T16:11:53.859743991Z,160,2,1108,A,A,13.530000000,15,0,337772837,130,165471,281142794,ARL,,13.11,100,1,13.01,2,1,12.98,200,1,12.86,100,1,12.73,100,1,12.71,100,1,12.5,700,1,12.46,100,1,12.43,700,1,12.42,700,1,13.53,15,1,13.55,15,1,13.56,100,1,13.82,2,1,13.86,100,1,14.25,100,1,14.27,700,1,14.28,100,1,14.47,100,1,14.48,700,1,2,337772837
2025-07-17T16:11:54.662527332Z,2025-07-17T16:11:54.662361841Z,160,2,1108,C,A,13.560000000,100,0,337690193,0,165491,281156215,ARL,,13.11,100,1,13.01,2,1,12.98,200,1,12.86,100,1,12.73,100,1,12.71,100,1,12.5,700,1,12.46,100,1,12.43,700,1,12.42,700,1,13.53,15,1,13.55,15,1,13.82,2,1,13.86,100,1,14.25,100,1,14.27,700,1,14.28,100,1,14.47,100,1,14.48,700,1,14.51,200,1,2,337690193
2025-07-17T16:11:54.662527332Z,2025-07-17T16:11:54.662361841Z,160,2,1108,A,A,13.540000000,100,0,337790717,130,165491,281156215,ARL,,13.11,100,1,13.01,2,1,12.98,200,1,12.86,100,1,12.73,100,1,12.71,100,1,12.5,700,1,12.46,100,1,12.43,700,1,12.42,700,1,13.53,15,1,13.54,100,1,13.55,15,1,13.82,2,1,13.86,100,1,14.25,100,1,14.27,700,1,14.28,100,1,14.47,100,1,14.48,700,1,2,337790717
2025-07-17T16:11:54.663278200Z,2025-07-17T16:11:54.663112543Z,160,2,1108,C,A,14.640000000,100,0,336567213,0,165657,281156222,ARL,,13.11,100,1,13.01,2,1,12.98,200,1,12.86,100,1,12.73,100,1,12.71,100,1,12.5,700,1,12.46,100,1,12.43,700,1,12.42,700,1,13.53,15,1,13.54,100,1,13.55,15,1,13.82,2,1,13.86,100,1,14.25,100,1,14.27,700,1,14.28,100,1,14.47,100,1,14.48,700,1,2,336567213
2025-07-17T16:11:54.663278200Z,2025-07-17T16:11:54.663112543Z,160,2,1108,A,A,14.590000000,100,0,337790737,130,165657,281156222,ARL,,13.11,100,1,13.01,2,1,12.98,200,1,12.86,100,1,12.73,100,1,12.71,100,1,12.5,700,1,12.46,100,1,12.43,700,1,12.42,700,1,13.53,15,1,13.54,100,1,13.55,15,1,13.82,2,1,13.86,100,1,14.25,100,1,14.27,700,1,14.28,100,1,14.47,100,1,14.48,700,1,2,337790737
2025-07-17T16:11:54.664134026Z,2025-07-17T16:11:54.663968656Z,160,2,1108,C,A,14.640000000,100,0,335220525,0,165370,281156223,ARL,,13.11,100,1,13.01,2,1,12.98,200,1,12.86,100,1,12.73,100,1,12.71,100,1,12.5,700,1,12.46,100,1,12.43,700,1,12.42,700,1,13.53,15,1,13.54,100,1,13.55,15,1,13.82,2,1,13.86,100,1,14.25,100,1,14.27,700,1,14.28,100,1,14.47,100,1,14.48,700,1,2,335220525
2025-07-17T16:11:54.664134026Z,2025-07-17T16:11:54.663968656Z,160,2,1108,A,A,14.490000000,100,0,337790745,130,165370,281156223,ARL,,13.11,100,1,13.01,2,1,12.98,200,1,12.86,100,1,12.73,100,1,12.71,100,1,12.5,700,1,12.46,100,1,12.43,700,1,12.42,700,1,13.53,15,1,13.54,100,1,13.55,15,1,13.82,2,1,13.86,100,1,14.25,100,1,14.27,700,1,14.28,100,1,14.47,100,1,14.48,700,1,2,337790745
2025-07-17T16:11:54.666326600Z,2025-07-17T16:11:54.666160990Z,160,2,1108,C,A,14.470000000,100,0,335220561,0,165610,281156243,ARL,,13.11,100,1,13.01,2,1,12.98,200,1,12.86,100,1,12.73,100,1,12.71,100,1,12.5,700,1,12.46,100,1,12.43,700,1,12.42,700,1,13.53,15,1,13.54,100,1,13.55,15,1,13.82,2,1,13.86,100,1,14.25,100,1,14.27,700,1,14.28,100,1,14.48,700,1,14.49,100,1,2,335220561
2025-07-17T16:11:54.666326600Z,2025-07-17T16:11:54.666160990Z,160,2,1108,A,A,14.330000000,100,0,337790761,130,165610,281156243,ARL,,13.11,100,1,13.01,2,1,12.98,200,1,12.86,100,1,12.73,100,1,12.71,100,1,12.5,700,1,12.46,100,1,12.43,700,1,12.42,700,1,13.53,15,1,13.54,100,1,13.55,15,1,13.82,2,1,13.86,100,1,14.25,100,1,14.27,700,1,14.28,100,1,14.33,100,1,14.48,700,1,2,337790761
2025-07-17T16:11:54.667504546Z,2025-07-17T16:11:54.667339002Z,160,2,1108,C,A,14.640000000,100,0,335220629,0,165544,281156250,ARL,,13.11,100,1,13.01,2,1,12.98,200,1,12.86,100,1,12.73,100,1,12.71,100,1,12.5,700,1,12.46,100,1,12.43,700,1,12.42,700,1,13.53,15,1,13.54,100,1,13.55,15,1,13.82,2,1,13.86,100,1,14.25,100,1,14.27,700,1,14.28,100,1,14.33,100,1,14.48,700,1,2,335220629
2025-07-17T16:11:54.667504546Z,2025-07-17T16:11:54.667339002Z,160,2,1108,A,A,14.490000000,100,0,337790777,130,165544,281156250,ARL,,13.11,100,1,13.01,2,1,12.98,200,1,12.86,100,1,12.73,100,1,12.71,100,1,12.5,700,1,12.46,100,1,12.43,700,1,12.42,700,1,13.53,15,1,13.54,100,1,13.55,15,1,13.82,2,1,13.86,100,1,14.25,100,1,14.27,700,1,14.28,100,1,14.33,100,1,14.48,700,1,2,337790777
2025-07-17T16:11:59.382515678Z,2025-07-17T16:11:59.382350338Z,160,2,1108,C,A,13.550000000,15,0,337690189,130,165340,281270010,ARL,,13.11,100,1,13.01,2,1,12.98,200,1,12.86,100,1,12.73,100,1,12.71,100,1,12.5,700,1,12.46,100,1,12.43,700,1,12.42,700,1,13.53,15,1,13.54,100,1,13.82,2,1,13.86,100,1,14.25,100,1,14.27,700,1,14.28,100,1,14.33,100,1,14.48,700,1,14.49,200,1,2,337690189
2025-07-17T16:12:02.982078719Z,2025-07-17T16:12:02.981913204Z,160,2,1108,A,A,13.510000000,15,0,338041605,130,165515,281348152,ARL,,13.11,100,1,13.01,2,1,12.98,200,1,12.86,100,1,12.73,100,1,12.71,100,1,12.5,700,1,12.46,100,1,12.43,700,1,12.42,700,1,13.51,15,1,13.53,15,1,13.54,100,1,13.82,2,1,13.86,100,1,14.25,100,1,14.27,700,1,14.28,100,1,14.33,100,1,14.48,700,1,2,338041605
2025-07-17T16:12:03.064162605Z,2025-07-17T16:12:03.063997054Z,160,2,1108,C,A,13.540000000,100,0,337790717,0,165551,281351122,ARL,,13.11,100,1,13.01,2,1,12.98,200,1,12.86,100,1,12.73,100,1,12.71,100,1,12.5,700,1,12.46,100,1,12.43,700,1,12.42,700,1,13.51,15,1,13.53,15,1,13.82,2,1,13.86,100,1,14.25,100,1,14.27,700,1,14.28,100,1,14.33,100,1,14.48,700,1,14.49,200,1,2,337790717
2025-07-17T16:12:03.064162605Z,2025-07-17T16:12:03.063997054Z,160,2,1108,A,A,13.520000000,100,0,338044041,130,165551,281351122,ARL,,13.11,100,1,13.01,2,1,12.98,200,1,12.86,100,1,12.73,100,1,12.71,100,1,12.5,700,1,12.46,100,1,12.43,700,1,12.42,700,1,13.51,15,1,13.52,100,1,13.53,15,1,13.82,2,1,13.86,100,1,14.25,100,1,14.27,700,1,14.28,100,1,14.33,100,1,14.48,700,1,2,338044041
2025-07-17T16:12:03.068467146Z,2025-07-17T16:12:03.068301745Z,160,2,1108,C,B,13.010000000,2,0,332494213,0,165401,281351235,ARL,,13.11,100,1,12.98,200,1,12.86,100,1,12.73,100,1,12.71,100,1,12.5,700,1,12.46,100,1,12.43,700,1,12.42,700,1,12.37,700,1,13.51,15,1,13.52,100,1,13.53,15,1,13.82,2,1,13.86,100,1,14.25,100,1,14.27,700,1,14.28,100,1,14.33,100,1,14.48,700,1,2,332494213
2025-07-17T16:12:03.068467146Z,2025-07-17T16:12:03.068301745Z,160,2,1108,A,B,12.920000000,2,0,338044113,130,165401,281351235,ARL,,13.11,100,1,12.98,200,1,12.92,2,1,12.86,100,1,12.73,100,1,12.71,100,1,12.5,700,1,12.46,100,1,12.43,700,1,12.42,700,1,13.51,15,1,13.52,100,1,13.53,15,1,13.82,2,1,13.86,100,1,14.25,100,1,14.27,700,1,14.28,100,1,14.33,100,1,14.48,700,1,2,338044113
2025-07-17T16:12:03.075200038Z,2025-07-17T16:12:03.075034550Z,160,2,1108,C,A,13.860000000,100,0,336567333,130,165488,281351372,ARL,,13.11,100,1,12.98,200,1,12.92,2,1,12.86,100,1,12.73,100,1,12.71,100,1,12.5,700,1,12.46,100,1,12.43,700,1,12.42,700,1,13.51,15,1,13.52,100,1,13.53,15,1,13.82,2,1,14.25,100,1,14.27,700,1,14.28,100,1,14.33,100,1,14.48,700,1,14.49,200,1,2,336567333
2025-07-17T16:12:03.075260529Z,2025-07-17T16:12:03.075095341Z,160,2,1108,A,A,13.790000000,100,0,338044233,130,165188,281351373,ARL,,13.11,100,1,12.98,200,1,12.92,2,1,12.86,100,1,12.73,100,1,12.71,100,1,12.5,700,1,12.46,100,1,12.43,700,1,12.42,700,1,13.51,15,1,13.52,100,1,13.53,15,1,13.79,100,1,13.82,2,1,14.25,100,1,14.27,700,1,14.28,100,1,14.33,100,1,14.48,700,1,2,338044233
2025-07-17T16:12:06.775177637Z,2025-07-17T16:12:06.775011783Z,160,2,1108,C,A,14.510000000,100,0,336259225,0,165854,281422697,ARL,,13.11,100,1,12.98,200,1,12.92,2,1,12.86,100,1,12.73,100,1,12.71,100,1,12.5,700,1,12.46,100,1,12.43,700,1,12.42,700,1,13.51,15,1,13.52,100,1,13.53,15,1,13.79,100,1,13.82,2,1,14.25,100,1,14.27,700,1,14.28,100,1,14.33,100,1,14.48,700,1,2,336259225
2025-07-17T16:12:06.775177637Z,2025-07-17T16:12:06.775011783Z,160,2,1108,A,A,14.400000000,100,0,338139585,130,165854,281422697,ARL,,13.11,100,1,12.98,200,1,12.92,2,1,12.86,100,1,12.73,100,1,12.71,100,1,12.5,700,1,12.46,100,1,12.43,700,1,12.42,700,1,13.51,15,1,13.52,100,1,13.53,15,1,13.79,100,1,13.82,2,1,14.25,100,1,14.27,700,1,14.28,100,1,14.33,100,1,14.4,100,1,2,338139585
2025-07-17T16:12:06.775614536Z,2025-07-17T16:12:06.775449017Z,160,2,1108,C,A,14.510000000,100,0,336261905,0,165519,281422702,ARL,,13.11,100,1,12.98,200,1,12.92,2,1,12.86,100,1,12.73,100,1,12.71,100,1,12.5,700,1,12.46,100,1,12.43,700,1,12.42,700,1,13.51,15,1,13.52,100,1,13.53,15,1,13.79,100,1,13.82,2,1,14.25,100,1,14.27,700,1,14.28,100,1,14.33,100,1,14.4,100,1,2,336261905
2025-07-17T16:12:06.775614536Z,2025-07-17T16:12:06.775449017Z,160,2,1108,A,A,14.400000000,100,0,338139601,130,165519,281422702,ARL,,13.11,100,1,12.98,200,1,12.92,2,1,12.86,100,1,12.73,100,1,12.71,100,1,12.5,700,1,12.46,100,1,12.43,700,1,12.42,700,1,13.51,15,1,13.52,100,1,13.53,15,1,13.79,100,1,13.82,2,1,14.25,100,1,14.27,700,1,14.28,100,1,14.33,100,1,14.4,200,1,2,338139601
2025-07-17T16:12:06.779705717Z,2025-07-17T16:12:06.779540143Z,160,2,1108,C,A,13.530000000,15,0,337772837,130,165574,281422782,ARL,,13.11,100,1,12.98,200,1,12.92,2,1,12.86,100,1,12.73,100,1,12.71,100,1,12.5,700,1,12.46,100,1,12.43,700,1,12.42,700,1,13.51,15,1,13.52,100,1,13.79,100,1,13.82,2,1,14.25,100,1,14.27,700,1,14.28,100,1,14.33,100,1,14.4,200,1,14.48,700,1,2,337772837
2025-07-17T16:12:07.784698893Z,2025-07-17T16:12:07.784533539Z,160,2,1108,A,A,13.490000000,15,0,338167057,130,165354,281443568,ARL,,13.11,100,1,12.98,200,1,12.92,2,1,12.86,100,1,12.73,100,1,12.71,100,1,12.5,700,1,12.46,100,1,12.43,700,1,12.42,700,1,13.49,15,1,13.51,15,1,13.52,100,1,13.79,100,1,13.82,2,1,14.25,100,1,14.27,700,1,14.28,100,1,14.33,100,1,14.4,200,1,2,338167057
2025-07-17T16:12:08.585194585Z,2025-07-17T16:12:08.585029039Z,160,2,1108,C,A,13.520000000,100,0,338044041,0,165546,281451898,ARL,,13.11,100,1,12.98,200,1,12.92,2,1,12.86,100,1,12.73,100,1,12.71,100,1,12.5,700,1,12.46,100,1,12.43,700,1,12.42,700,1,13.49,15,1,13.51,15,1,13.79,100,1,13.82,2,1,14.25,100,1,14.27,700,1,14.28,100,1,14.33,100,1,14.4,200,1,14.48,700,1,2,338044041
2025-07-17T16:12:08.585194585Z,2025-07-17T16:12:08.585029039Z,160,2,1108,A,A,13.500000000,100,0,338180793,130,165546,281451898,ARL,,13.11,100,1,12.98,200,1,12.92,2,1,12.86,100,1,12.73,100,1,12.71,100,1,12.5,700,1,12.46,100,1,12.43,700,1,12.42,700,1,13.49,15,1,13.5,100,1,13.51,15,1,13.79,100,1,13.82,2,1,14.25,100,1,14.27,700,1,14.28,100,1,14.33,100,1,14.4,200,1,2,338180793
2025-07-17T16:12:08.585942049Z,2025-07-17T16:12:08.585776508Z,160,2,1108,C,A,14.590000000,100,0,337790737,0,165541,281451903,ARL,,13.11,100,1,12.98,200,1,12.92,2,1,12.86,100,1,12.73,100,1,12.71,100,1,12.5,700,1,12.46,100,1,12.43,700,1,12.42,700,1,13.49,15,1,13.5,100,1,13.51,15,1,13.79,100,1,13.82,2,1,14.25,100,1,14.27,700,1,14.28,100,1,14.33,100,1,14.4,200,1,2,337790737
2025-07-17T16:12:08.585942049Z,2025-07-17T16:12:08.585776508Z,160,2,1108,A,A,14.550000000,100,0,338180841,130,165541,281451903,ARL,,13.11,100,1,12.98,200,1,12.92,2,1,12.86,100,1,12.73,100,1,12.71,100,1,12.5,700,1,12.46,100,1,12.43,700,1,12.42,700,1,13.49,15,1,13.5,100,1,13.51,15,1,13.79,100,1,13.82,2,1,14.25,100,1,14.27,700,1,14.28,100,1,14.33,100,1,14.4,200,1,2,338180841
2025-07-17T16:12:18.789922022Z,2025-07-17T16:12:18.789756367Z,160,2,1108,C,A,13.820000000,2,0,336447325,0,165655,281613266,ARL,,13.11,100,1,12.98,200,1,12.92,2,1,12.86,100,1,12.73,100,1,12.71,100,1,12.5,700,1,12.46,100,1,12.43,700,1,12.42,700,1,13.49,15,1,13.5,100,1,13.51,15,1,13.79,100,1,14.25,100,1,14.27,700,1,14.28,100,1,14.33,100,1,14.4,200,1,14.48,700,1,2,336447325
2025-07-17T16:12:18.789922022Z,2025-07-17T16:12:18.789756367Z,160,2,1108,A,A,13.740000000,2,0,338371797,130,165655,281613266,ARL,,13.11,100,1,12.98,200,1,12.92,2,1,12.86,100,1,12.73,100,1,12.71,100,1,12.5,700,1,12.46,100,1,12.43,700,1,12.42,700,1,13.49,15,1,13.5,100,1,13.51,15,1,13.74,2,1,13.79,100,1,14.25,100,1,14.27,700,1,14.28,100,1,14.33,100,1,14.4,200,1,2,338371797
2025-07-17T16:12:19.370986404Z,2025-07-17T16:12:19.370820933Z,160,2,1108,A,A,14.270000000,700,0,338382329,130,165471,281622545,ARL,,13.11,100,1,12.98,200,1,12.92,2,1,12.86,100,1,12.73,100,1,12.71,100,1,12.5,700,1,12.46,100,1,12.43,700,1,12.42,700,1,13.49,15,1,13.5,100,1,13.51,15,1,13.74,2,1,13.79,100,1,14.25,100,1,14.27,1400,1,14.28,100,1,14.33,100,1,14.4,200,1,2,338382329
2025-07-17T16:12:19.371041049Z,2025-07-17T16:12:19.370875240Z,160,2,1108,C,A,14.600000000,700,0,282920685,130,165809,281622547,ARL,,13.11,100,1,12.98,200,1,12.92,2,1,12.86,100,1,12.73,100,1,12.71,100,1,12.5,700,1,12.46,100,1,12.43,700,1,12.42,700,1,13.49,15,1,13.5,100,1,13.51,15,1,13.74,2,1,13.79,100,1,14.25,100,1,14.27,1400,1,14.28,100,1,14.33,100,1,14.4,200,1,2,282920685
2025-07-17T16:12:19.696689718Z,2025-07-17T16:12:19.696521343Z,160,2,1108,C,A,13.490000000,15,0,338167057,128,168375,281630053,ARL,,13.11,100,1,12.98,200,1,12.92,2,1,12.86,100,1,12.73,100,1,12.71,100,1,12.5,700,1,12.46,100,1,12.43,700,1,12.42,700,1,13.5,100,1,13.51,15,1,13.74,2,1,13.79,100,1,14.25,100,1,14.27,1400,1,14.28,100,1,14.33,100,1,14.4,200,1,14.48,700,1,2,338167057
2025-07-17T16:12:19.711773364Z,2025-07-17T16:12:19.711591494Z,160,2,1108,C,A,13.510000000,15,0,338041605,128,181870,281634812,ARL,,13.11,100,1,12.98,200,1,12.92,2,1,12.86,100,1,12.73,100,1,12.71,100,1,12.5,700,1,12.46,100,1,12.43,700,1,12.42,700,1,13.5,100,1,13.74,2,1,13.79,100,1,14.25,100,1,14.27,1400,1,14.28,100,1,14.33,100,1,14.4,200,1,14.48,700,1,14.49,200,1,2,338041605
2025-07-17T16:12:32.761277424Z,2025-07-17T16:12:32.761112078Z,160,2,1108,A,A,13.480000000,15,0,338707945,130,165346,281880398,ARL,,13.11,100,1,12.98,200,1,12.92,2,1,12.86,100,1,12.73,100,1,12.71,100,1,12.5,700,1,12.46,100,1,12.43,700,1,12.42,700,1,13.48,15,1,13.5,100,1,13.74,2,1,13.79,100,1,14.25,100,1,14.27,1400,1,14.28,100,1,14.33,100,1,14.4,200,1,14.48,700,1,2,338707945
2025-07-17T16:12:32.761413202Z,2025-07-17T16:12:32.761246859Z,160,2,1108,C,A,13.500000000,100,0,338180793,0,166343,281880409,ARL,,13.11,100,1,12.98,200,1,12.92,2,1,12.86,100,1,12.73,100,1,12.71,100,1,12.5,700,1,12.46,100,1,12.43,700,1,12.42,700,1,13.48,15,1,13.74,2,1,13.79,100,1,14.25,100,1,14.27,1400,1,14.28,100,1,14.33,100,1,14.4,200,1,14.48,700,1,14.49,200,1,2,338180793
2025-07-17T16:12:32.761413202Z,2025-07-17T16:12:32.761246859Z,160,2,1108,A,A,13.490000000,100,0,338707949,130,166343,281880409,ARL,,13.11,100,1,12.98,200,1,12.92,2,1,12.86,100,1,12.73,100,1,12.71,100,1,12.5,700,1,12.46,100,1,12.43,700,1,12.42,700,1,13.48,15,1,13.49,100,1,13.74,2,1,13.79,100,1,14.25,100,1,14.27,1400,1,14.28,100,1,14.33,100,1,14.4,200,1,14.48,700,1,2,338707949
2025-07-17T16:12:32.779055996Z,2025-07-17T16:12:32.778890447Z,160,2,1108,C,A,15.120000000,100,0,296387089,0,165549,281880579,ARL,,13.11,100,1,12.98,200,1,12.92,2,1,12.86,100,1,12.73,100,1,12.71,100,1,12.5,700,1,12.46,100,1,12.43,700,1,12.42,700,1,13.48,15,1,13.49,100,1,13.74,2,1,13.79,100,1,14.25,100,1,14.27,1400,1,14.28,100,1,14.33,100,1,14.4,200,1,14.48,700,1,2,296387089
2025-07-17T16:12:32.779055996Z,2025-07-17T16:12:32.778890447Z,160,2,1108,A,A,14.840000000,100,0,338708241,130,165549,281880579,ARL,,13.11,100,1,12.98,200,1,12.92,2,1,12.86,100,1,12.73,100,1,12.71,100,1,12.5,700,1,12.46,100,1,12.43,700,1,12.42,700,1,13.48,15,1,13.49,100,1,13.74,2,1,13.79,100,1,14.25,100,1,14.27,1400,1,14.28,100,1,14.33,100,1,14.4,200,1,14.48,700,1,2,338708241
2025-07-17T16:12:32.804318005Z,2025-07-17T16:12:32.804152457Z,160,2,1108,A,A,15.380000000,100,0,338709513,130,165548,281880972,ARL,,13.11,100,1,12.98,200,1,12.92,2,1,12.86,100,1,12.73,100,1,12.71,100,1,12.5,700,1,12.46,100,1,12.43,700,1,12.42,700,1,13.48,15,1,13.49,100,1,13.74,2,1,13.79,100,1,14.25,100,1,14.27,1400,1,14.28,100,1,14.33,100,1,14.4,200,1,14.48,700,1,2,338709513
2025-07-17T16:12:32.804332586Z,2025-07-17T16:12:32.804166092Z,160,2,1108,C,A,15.660000000,100,0,326730513,130,166494,281880973,ARL,,13.11,100,1,12.98,200,1,12.92,2,1,12.86,100,1,12.73,100,1,12.71,100,1,12.5,700,1,12.46,100,1,12.43,700,1,12.42,700,1,13.48,15,1,13.49,100,1,13.74,2,1,13.79,100,1,14.25,100,1,14.27,1400,1,14.28,100,1,14.33,100,1,14.4,200,1,14.48,700,1,2,326730513
2025-07-17T16:12:40.993064296Z,2025-07-17T16:12:40.992898990Z,160,2,1108,C,A,13.490000000,100,0,338707949,130,165306,282007871,ARL,,13.11,100,1,12.98,200,1,12.92,2,1,12.86,100,1,12.73,100,1,12.71,100,1,12.5,700,1,12.46,100,1,12.43,700,1,12.42,700,1,13.48,15,1,13.74,2,1,13.79,100,1,14.25,100,1,14.27,1400,1,14.28,100,1,14.33,100,1,14.4,200,1,14.48,700,1,14.49,200,1,2,338707949
2025-07-17T16:12:40.993332664Z,2025-07-17T16:12:40.993167418Z,160,2,1108,C,A,14.270000000,700,0,338382329,130,165246,282007875,ARL,,13.11,100,1,12.98,200,1,12.92,2,1,12.86,100,1,12.73,100,1,12.71,100,1,12.5,700,1,12.46,100,1,12.43,700,1,12.42,700,1,13.48,15,1,13.74,2,1,13.79,100,1,14.25,100,1,14.27,700,1,14.28,100,1,14.33,100,1,14.4,200,1,14.48,700,1,14.49,200,1,2,338382329
2025-07-17T16:12:40.993333790Z,2025-07-17T16:12:40.993168470Z,160,2,1108,C,A,14.270000000,700,0,336747457,130,165320,282007876,ARL,,13.11,100,1,12.98,200,1,12.92,2,1,12.86,100,1,12.73,100,1,12.71,100,1,12.5,700,1,12.46,100,1,12.43,700,1,12.42,700,1,13.48,15,1,13.74,2,1,13.79,100,1,14.25,100,1,14.28,100,1,14.33,100,1,14.4,200,1,14.48,700,1,14.49,200,1,14.55,100,1,2,336747457
2025-07-17T16:12:40.993379626Z,2025-07-17T16:12:40.993214193Z,160,2,1108,A,A,14.540000000,700,0,338864169,130,165433,282007877,ARL,,13.11,100,1,12.98,200,1,12.92,2,1,12.86,100,1,12.73,100,1,12.71,100,1,12.5,700,1,12.46,100,1,12.43,700,1,12.42,700,1,13.48,15,1,13.74,2,1,13.79,100,1,14.25,100,1,14.28,100,1,14.33,100,1,14.4,200,1,14.48,700,1,14.49,200,1,14.54,700,1,2,338864169
2025-07-17T16:12:40.993393440Z,2025-07-17T16:12:40.993227993Z,160,2,1108,A,A,14.470000000,700,0,338864173,130,165447,282007878,ARL,,13.11,100,1,12.98,200,1,12.92,2,1,12.86,100,1,12.73,100,1,12.71,100,1,12.5,700,1,12.46,100,1,12.43,700,1,12.42,700,1,13.48,15,1,13.74,2,1,13.79,100,1,14.25,100,1,14.28,100,1,14.33,100,1,14.4,200,1,14.47,700,1,14.48,700,1,14.49,200,1,2,338864173
2025-07-17T16:12:40.993432115Z,2025-07-17T16:12:40.993266591Z,160,2,1108,A,A,15.710000000,100,0,338864177,130,165524,282007879,ARL,,13.11,100,1,12.98,200,1,12.92,2,1,12.86,100,1,12.73,100,1,12.71,100,1,12.5,700,1,12.46,100,1,12.43,700,1,12.42,700,1,13.48,15,1,13.74,2,1,13.79,100,1,14.25,100,1,14.28,100,1,14.33,100,1,14.4,200,1,14.47,700,1,14.48,700,1,14.49,200,1,2,338864177
2025-07-17T16:12:40.993445042Z,2025-07-17T16:12:40.993279810Z,160,2,1108,C,A,15.380000000,100,0,338709513,130,165232,282007880,ARL,,13.11,100,1,12.98,200,1,12.92,2,1,12.86,100,1,12.73,100,1,12.71,100,1,12.5,700,1,12.46,100,1,12.43,700,1,12.42,700,1,13.48,15,1,13.74,2,1,13.79,100,1,14.25,100,1,14.28,100,1,14.33,100,1,14.4,200,1,14.47,700,1,14.48,700,1,14.49,200,1,2,338709513
2025-07-17T16:12:40.993818130Z,2025-07-17T16:12:40.993652511Z,160,2,1108,C,A,14.550000000,100,0,338180841,0,165619,282007882,ARL,,13.11,100,1,12.98,200,1,12.92,2,1,12.86,100,1,12.73,100,1,12.71,100,1,12.5,700,1,12.46,100,1,12.43,700,1,12.42,700,1,13.48,15,1,13.74,2,1,13.79,100,1,14.25,100,1,14.28,100,1,14.33,100,1,14.4,200,1,14.47,700,1,14.48,700,1,14.49,200,1,2,338180841
2025-07-17T16:12:40.993818130Z,2025-07-17T16:12:40.993652511Z,160,2,1108,A,A,14.850000000,100,0,338864189,130,165619,282007882,ARL,,13.11,100,1,12.98,200,1,12.92,2,1,12.86,100,1,12.73,100,1,12.71,100,1,12.5,700,1,12.46,100,1,12.43,700,1,12.42,700,1,13.48,15,1,13.74,2,1,13.79,100,1,14.25,100,1,14.28,100,1,14.33,100,1,14.4,200,1,14.47,700,1,14.48,700,1,14.49,200,1,2,338864189
2025-07-17T16:12:40.994783297Z,2025-07-17T16:12:40.994617858Z,160,2,1108,C,A,14.490000000,100,0,337790745,0,165439,282007892,ARL,,13.11,100,1,12.98,200,1,12.92,2,1,12.86,100,1,12.73,100,1,12.71,100,1,12.5,700,1,12.46,100,1,12.43,700,1,12.42,700,1,13.48,15,1,13.74,2,1,13.79,100,1,14.25,100,1,14.28,100,1,14.33,100,1,14.4,200,1,14.47,700,1,14.48,700,1,14.49,100,1,2,337790745
2025-07-17T16:12:40.994783297Z,2025-07-17T16:12:40.994617858Z,160,2,1108,A,A,14.760000000,100,0,338864217,130,165439,282007892,ARL,,13.11,100,1,12.98,200,1,12.92,2,1,12.86,100,1,12.73,100,1,12.71,100,1,12.5,700,1,12.46,100,1,12.43,700,1,12.42,700,1,13.48,15,1,13.74,2,1,13.79,100,1,14.25,100,1,14.28,100,1,14.33,100,1,14.4,200,1,14.47,700,1,14.48,700,1,14.49,100,1,2,338864217
2025-07-17T16:12:40.995078856Z,2025-07-17T16:12:40.994913404Z,160,2,1108,C,A,14.840000000,100,0,338708241,0,165452,282007894,ARL,,13.11,100,1,12.98,200,1,12.92,2,1,12.86,100,1,12.73,100,1,12.71,100,1,12.5,700,1,12.46,100,1,12.43,700,1,12.42,700,1,13.48,15,1,13.74,2,1,13.79,100,1,14.25,100,1,14.28,100,1,14.33,100,1,14.4,200,1,14.47,700,1,14.48,700,1,14.49,100,1,2,338708241
2025-07-17T16:12:40.995078856Z,2025-07-17T16:12:40.994913404Z,160,2,1108,A,A,15.170000000,100,0,338864221,130,165452,282007894,ARL,,13.11,100,1,12.98,200,1,12.92,2,1,12.86,100,1,12.73,100,1,12.71,100,1,12.5,700,1,12.46,100,1,12.43,700,1,12.42,700,1,13.48,15,1,13.74,2,1,13.79,100,1,14.25,100,1,14.28,100,1,14.33,100,1,14.4,200,1,14.47,700,1,14.48,700,1,14.49,100,1,2,338864221
2025-07-17T16:12:40.995349303Z,2025-07-17T16:12:40.995183768Z,160,2,1108,C,A,15.600000000,100,0,337690641,0,165535,282007898,ARL,,13.11,100,1,12.98,200,1,12.92,2,1,12.86,100,1,12.73,100,1,12.71,100,1,12.5,700,1,12.46,100,1,12.43,700,1,12.42,700,1,13.48,15,1,13.74,2,1,13.79,100,1,14.25,100,1,14.28,100,1,14.33,100,1,14.4,200,1,14.47,700,1,14.48,700,1,14.49,100,1,2,337690641
2025-07-17T16:12:40.995349303Z,2025-07-17T16:12:40.995183768Z,160,2,1108,A,A,15.860000000,100,0,338864245,130,165535,282007898,ARL,,13.11,100,1,12.98,200,1,12.92,2,1,12.86,100,1,12.73,100,1,12.71,100,1,12.5,700,1,12.46,100,1,12.43,700,1,12.42,700,1,13.48,15,1,13.74,2,1,13.79,100,1,14.25,100,1,14.28,100,1,14.33,100,1,14.4,200,1,14.47,700,1,14.48,700,1,14.49,100,1,2,338864245
2025-07-17T16:12:40.996460080Z,2025-07-17T16:12:40.996294601Z,160,2,1108,C,A,17.260000000,100,0,336570921,0,165479,282007909,ARL,,13.11,100,1,12.98,200,1,12.92,2,1,12.86,100,1,12.73,100,1,12.71,100,1,12.5,700,1,12.46,100,1,12.43,700,1,12.42,700,1,13.48,15,1,13.74,2,1,13.79,100,1,14.25,100,1,14.28,100,1,14.33,100,1,14.4,200,1,14.47,700,1,14.48,700,1,14.49,100,1,2,336570921
2025-07-17T16:12:40.996460080Z,2025-07-17T16:12:40.996294601Z,160,2,1108,A,A,17.520000000,100,0,338864289,130,165479,282007909,ARL,,13.11,100,1,12.98,200,1,12.92,2,1,12.86,100,1,12.73,100,1,12.71,100,1,12.5,700,1,12.46,100,1,12.43,700,1,12.42,700,1,13.48,15,1,13.74,2,1,13.79,100,1,14.25,100,1,14.28,100,1,14.33,100,1,14.4,200,1,14.47,700,1,14.48,700,1,14.49,100,1,2,338864289
2025-07-17T16:12:40.997300700Z,2025-07-17T16:12:40.997135307Z,160,2,1108,C,A,14.330000000,100,0,337790761,130,165393,282007914,ARL,,13.11,100,1,12.98,200,1,12.92,2,1,12.86,100,1,12.73,100,1,12.71,100,1,12.5,700,1,12.46,100,1,12.43,700,1,12.42,700,1,13.48,15,1,13.74,2,1,13.79,100,1,14.25,100,1,14.28,100,1,14.4,200,1,14.47,700,1,14.48,700,1,14.49,100,1,14.54,700,1,2,337790761
2025-07-17T16:12:40.997422356Z,2025-07-17T16:12:40.997257014Z,160,2,1108,A,A,14.580000000,100,0,338864317,130,165342,282007916,ARL,,13.11,100,1,12.98,200,1,12.92,2,1,12.86,100,1,12.73,100,1,12.71,100,1,12.5,700,1,12.46,100,1,12.43,700,1,12.42,700,1,13.48,15,1,13.74,2,1,13.79,100,1,14.25,100,1,14.28,100,1,14.4,200,1,14.47,700,1,14.48,700,1,14.49,100,1,14.54,700,1,2,338864317
2025-07-17T16:12:41.004229622Z,2025-07-17T16:12:41.004063876Z,160,2,1108,C,A,14.490000000,100,0,337790777,0,165746,282007959,ARL,,13.11,100,1,12.98,200,1,12.92,2,1,12.86,100,1,12.73,100,1,12.71,100,1,12.5,700,1,12.46,100,1,12.43,700,1,12.42,700,1,13.48,15,1,13.74,2,1,13.79,100,1,14.25,100,1,14.28,100,1,14.4,200,1,14.47,700,1,14.48,700,1,14.54,700,1,14.56,800,1,2,337790777
2025-07-17T16:12:41.004229622Z,2025-07-17T16:12:41.004063876Z,160,2,1108,A,A,14.760000000,100,0,338864405,130,165746,282007959,ARL,,13.11,100,1,12.98,200,1,12.92,2,1,12.86,100,1,12.73,100,1,12.71,100,1,12.5,700,1,12.46,100,1,12.43,700,1,12.42,700,1,13.48,15,1,13.74,2,1,13.79,100,1,14.25,100,1,14.28,100,1,14.4,200,1,14.47,700,1,14.48,700,1,14.54,700,1,14.56,800,1,2,338864405
2025-07-17T16:12:41.005576053Z,2025-07-17T16:12:41.005406614Z,160,2,1108,A,A,13.490000000,100,0,338864581,128,169439,282008256,ARL,,13.11,100,1,12.98,200,1,12.92,2,1,12.86,100,1,12.73,100,1,12.71,100,1,12.5,700,1,12.46,100,1,12.43,700,1,12.42,700,1,13.48,15,1,13.49,100,1,13.74,2,1,13.79,100,1,14.25,100,1,14.28,100,1,14.4,200,1,14.47,700,1,14.48,700,1,14.54,700,1,2,338864581
2025-07-17T16:12:41.010638351Z,2025-07-17T16:12:41.010473041Z,160,2,1108,C,A,14.760000000,100,0,338864405,0,165310,282008884,ARL,,13.11,100,1,12.98,200,1,12.92,2,1,12.86,100,1,12.73,100,1,12.71,100,1,12.5,700,1,12.46,100,1,12.43,700,1,12.42,700,1,13.48,15,1,13.49,100,1,13.74,2,1,13.79,100,1,14.25,100,1,14.28,100,1,14.4,200,1,14.47,700,1,14.48,700,1,14.54,700,1,2,338864405
2025-07-17T16:12:41.010638351Z,2025-07-17T16:12:41.010473041Z,160,2,1108,A,A,14.440000000,100,0,338865133,130,165310,282008884,ARL,,13.11,100,1,12.98,200,1,12.92,2,1,12.86,100,1,12.73,100,1,12.71,100,1,12.5,700,1,12.46,100,1,12.43,700,1,12.42,700,1,13.48,15,1,13.49,100,1,13.74,2,1,13.79,100,1,14.25,100,1,14.28,100,1,14.4,200,1,14.44,100,1,14.47,700,1,14.48,700,1,2,338865133
2025-07-17T16:12:41.011160341Z,2025-07-17T16:12:41.010994859Z,160,2,1108,C,A,13.790000000,100,0,338044233,130,165482,282008914,ARL,,13.11,100,1,12.98,200,1,12.92,2,1,12.86,100,1,12.73,100,1,12.71,100,1,12.5,700,1,12.46,100,1,12.43,700,1,12.42,700,1,13.48,15,1,13.49,100,1,13.74,2,1,14.25,100,1,14.28,100,1,14.4,200,1,14.44,100,1,14.47,700,1,14.48,700,1,14.54,700,1,2,338044233
2025-07-17T16:12:41.011211986Z,2025-07-17T16:12:41.011046717Z,160,2,1108,A,A,14.060000000,100,0,338865141,130,165269,282008916,ARL,,13.11,100,1,12.98,200,1,12.92,2,1,12.86,100,1,12.73,100,1,12.71,100,1,12.5,700,1,12.46,100,1,12.43,700,1,12.42,700,1,13.48,15,1,13.49,100,1,13.74,2,1,14.06,100,1,14.25,100,1,14.28,100,1,14.4,200,1,14.44,100,1,14.47,700,1,14.48,700,1,2,338865141
2025-07-17T16:12:41.011555342Z,2025-07-17T16:12:41.011390077Z,160,2,1108,C,A,14.760000000,100,0,338864217,0,165265,282008942,ARL,,13.11,100,1,12.98,200,1,12.92,2,1,12.86,100,1,12.73,100,1,12.71,100,1,12.5,700,1,12.46,100,1,12.43,700,1,12.42,700,1,13.48,15,1,13.49,100,1,13.74,2,1,14.06,100,1,14.25,100,1,14.28,100,1,14.4,200,1,14.44,100,1,14.47,700,1,14.48,700,1,2,338864217
2025-07-17T16:12:41.011555342Z,2025-07-17T16:12:41.011390077Z,160,2,1108,A,A,14.440000000,100,0,338865165,130,165265,282008942,ARL,,13.11,100,1,12.98,200,1,12.92,2,1,12.86,100,1,12.73,100,1,12.71,100,1,12.5,700,1,12.46,100,1,12.43,700,1,12.42,700,1,13.48,15,1,13.49,100,1,13.74,2,1,14.06,100,1,14.25,100,1,14.28,100,1,14.4,200,1,14.44,200,1,14.47,700,1,14.48,700,1,2,338865165
2025-07-17T16:12:41.012044919Z,2025-07-17T16:12:41.011879795Z,160,2,1108,C,A,14.060000000,100,0,338865141,130,165124,282008953,ARL,,13.11,100,1,12.98,200,1,12.92,2,1,12.86,100,1,12.73,100,1,12.71,100,1,12.5,700,1,12.46,100,1,12.43,700,1,12.42,700,1,13.48,15,1,13.49,100,1,13.74,2,1,14.25,100,1,14.28,100,1,14.4,200,1,14.44,200,1,14.47,700,1,14.48,700,1,14.54,700,1,2,338865141
2025-07-17T16:12:41.012094494Z,2025-07-17T16:12:41.011929033Z,160,2,1108,A,A,13.760000000,100,0,338865177,130,165461,282008954,ARL,,13.11,100,1,12.98,200,1,12.92,2,1,12.86,100,1,12.73,100,1,12.71,100,1,12.5,700,1,12.46,100,1,12.43,700,1,12.42,700,1,13.48,15,1,13.49,100,1,13.74,2,1,13.76,100,1,14.25,100,1,14.28,100,1,14.4,200,1,14.44,200,1,14.47,700,1,14.48,700,1,2,338865177
2025-07-17T16:12:41.014974491Z,2025-07-17T16:12:41.014809197Z,160,2,1108,C,A,17.520000000,100,0,338864289,0,165294,282008990,ARL,,13.11,100,1,12.98,200,1,12.92,2,1,12.86,100,1,12.73,100,1,12.71,100,1,12.5,700,1,12.46,100,1,12.43,700,1,12.42,700,1,13.48,15,1,13.49,100,1,13.74,2,1,13.76,100,1,14.25,100,1,14.28,100,1,14.4,200,1,14.44,200,1,14.47,700,1,14.48,700,1,2,338864289
2025-07-17T16:12:41.014974491Z,2025-07-17T16:12:41.014809197Z,160,2,1108,A,A,17.140000000,100,0,338865253,130,165294,282008990,ARL,,13.11,100,1,12.98,200,1,12.92,2,1,12.86,100,1,12.73,100,1,12.71,100,1,12.5,700,1,12.46,100,1,12.43,700,1,12.42,700,1,13.48,15,1,13.49,100,1,13.74,2,1,13.76,100,1,14.25,100,1,14.28,100,1,14.4,200,1,14.44,200,1,14.47,700,1,14.48,700,1,2,338865253
2025-07-17T16:12:41.017837378Z,2025-07-17T16:12:41.017672033Z,160,2,1108,C,A,15.860000000,100,0,338864245,0,165345,282009053,ARL,,13.11,100,1,12.98,200,1,12.92,2,1,12.86,100,1,12.73,100,1,12.71,100,1,12.5,700,1,12.46,100,1,12.43,700,1,12.42,700,1,13.48,15,1,13.49,100,1,13.74,2,1,13.76,100,1,14.25,100,1,14.28,100,1,14.4,200,1,14.44,200,1,14.47,700,1,14.48,700,1,2,338864245
2025-07-17T16:12:41.017837378Z,2025-07-17T16:12:41.017672033Z,160,2,1108,A,A,15.520000000,100,0,338865301,130,165345,282009053,ARL,,13.11,100,1,12.98,200,1,12.92,2,1,12.86,100,1,12.73,100,1,12.71,100,1,12.5,700,1,12.46,100,1,12.43,700,1,12.42,700,1,13.48,15,1,13.49,100,1,13.74,2,1,13.76,100,1,14.25,100,1,14.28,100,1,14.4,200,1,14.44,200,1,14.47,700,1,14.48,700,1,2,338865301
2025-07-17T16:12:41.032270817Z,2025-07-17T16:12:41.032105565Z,160,2,1108,C,A,15.170000000,100,0,338864221,0,165252,282009412,ARL,,13.11,100,1,12.98,200,1,12.92,2,1,12.86,100,1,12.73,100,1,12.71,100,1,12.5,700,1,12.46,100,1,12.43,700,1,12.42,700,1,13.48,15,1,13.49,100,1,13.74,2,1,13.76,100,1,14.25,100,1,14.28,100,1,14.4,200,1,14.44,200,1,14.47,700,1,14.48,700,1,2,338864221
2025-07-17T16:12:41.032270817Z,2025-07-17T16:12:41.032105565Z,160,2,1108,A,A,14.840000000,100,0,338866081,130,165252,282009412,ARL,,13.11,100,1,12.98,200,1,12.92,2,1,12.86,100,1,12.73,100,1,12.71,100,1,12.5,700,1,12.46,100,1,12.43,700,1,12.42,700,1,13.48,15,1,13.49,100,1,13.74,2,1,13.76,100,1,14.25,100,1,14.28,100,1,14.4,200,1,14.44,200,1,14.47,700,1,14.48,700,1,2,338866081
2025-07-17T16:12:41.032312420Z,2025-07-17T16:12:41.032147083Z,160,2,1108,A,A,15.380000000,100,0,338866089,130,165337,282009414,ARL,,13.11,100,1,12.98,200,1,12.92,2,1,12.86,100,1,12.73,100,1,12.71,100,1,12.5,700,1,12.46,100,1,12.43,700,1,12.42,700,1,13.48,15,1,13.49,100,1,13.74,2,1,13.76,100,1,14.25,100,1,14.28,100,1,14.4,200,1,14.44,200,1,14.47,700,1,14.48,700,1,2,338866089
2025-07-17T16:12:41.032324438Z,2025-07-17T16:12:41.032159348Z,160,2,1108,C,A,15.710000000,100,0,338864177,130,165090,282009415,ARL,,13.11,100,1,12.98,200,1,12.92,2,1,12.86,100,1,12.73,100,1,12.71,100,1,12.5,700,1,12.46,100,1,12.43,700,1,12.42,700,1,13.48,15,1,13.49,100,1,13.74,2,1,13.76,100,1,14.25,100,1,14.28,100,1,14.4,200,1,14.44,200,1,14.47,700,1,14.48,700,1,2,338864177
2025-07-17T16:12:41.043406383Z,2025-07-17T16:12:41.043241012Z,160,2,1108,C,A,14.850000000,100,0,338864189,0,165371,282009482,ARL,,13.11,100,1,12.98,200,1,12.92,2,1,12.86,100,1,12.73,100,1,12.71,100,1,12.5,700,1,12.46,100,1,12.43,700,1,12.42,700,1,13.48,15,1,13.49,100,1,13.74,2,1,13.76,100,1,14.25,100,1,14.28,100,1,14.4,200,1,14.44,200,1,14.47,700,1,14.48,700,1,2,338864189
2025-07-17T16:12:41.043406383Z,2025-07-17T16:12:41.043241012Z,160,2,1108,A,A,14.540000000,100,0,338866245,130,165371,282009482,ARL,,13.11,100,1,12.98,200,1,12.92,2,1,12.86,100,1,12.73,100,1,12.71,100,1,12.5,700,1,12.46,100,1,12.43,700,1,12.42,700,1,13.48,15,1,13.49,100,1,13.74,2,1,13.76,100,1,14.25,100,1,14.28,100,1,14.4,200,1,14.44,200,1,14.47,700,1,14.48,700,1,2,338866245
2025-07-17T16:12:42.001347844Z,2025-07-17T16:12:42.001182016Z,160,2,1108,C,A,14.580000000,100,0,338864317,0,165828,282033913,ARL,,13.11,100,1,12.98,200,1,12.92,2,1,12.86,100,1,12.73,100,1,12.71,100,1,12.5,700,1,12.46,100,1,12.43,700,1,12.42,700,1,13.48,15,1,13.49,100,1,13.74,2,1,13.76,100,1,14.25,100,1,14.28,100,1,14.4,200,1,14.44,200,1,14.47,700,1,14.48,700,1,2,338864317
2025-07-17T16:12:42.001347844Z,2025-07-17T16:12:42.001182016Z,160,2,1108,A,A,14.280000000,100,0,338894329,130,165828,282033913,ARL,,13.11,100,1,12.98,200,1,12.92,2,1,12.86,100,1,12.73,100,1,12.71,100,1,12.5,700,1,12.46,100,1,12.43,700,1,12.42,700,1,13.48,15,1,13.49,100,1,13.74,2,1,13.76,100,1,14.25,100,1,14.28,200,1,14.4,200,1,14.44,200,1,14.47,700,1,14.48,700,1,2,338894329
2025-07-17T16:12:42.762154469Z,2025-07-17T16:12:42.761989222Z,160,2,1108,A,A,13.460000000,15,0,338904977,130,165247,282042242,ARL,,13.11,100,1,12.98,200,1,12.92,2,1,12.86,100,1,12.73,100,1,12.71,100,1,12.5,700,1,12.46,100,1,12.43,700,1,12.42,700,1,13.46,15,1,13.48,15,1,13.49,100,1,13.74,2,1,13.76,100,1,14.25,100,1,14.28,200,1,14.4,200,1,14.44,200,1,14.47,700,1,2,338904977
2025-07-17T16:12:43.022127902Z,2025-07-17T16:12:43.021951997Z,160,2,1108,C,A,13.490000000,100,0,338864581,0,175905,282057719,ARL,,13.11,100,1,12.98,200,1,12.92,2,1,12.86,100,1,12.73,100,1,12.71,100,1,12.5,700,1,12.46,100,1,12.43,700,1,12.42,700,1,13.46,15,1,13.48,15,1,13.74,2,1,13.76,100,1,14.25,100,1,14.28,200,1,14.4,200,1,14.44,200,1,14.47,700,1,14.48,700,1,2,338864581
2025-07-17T16:12:43.022127902Z,2025-07-17T16:12:43.021951997Z,160,2,1108,A,A,13.470000000,100,0,338918217,128,175905,282057719,ARL,,13.11,100,1,12.98,200,1,12.92,2,1,12.86,100,1,12.73,100,1,12.71,100,1,12.5,700,1,12.46,100,1,12.43,700,1,12.42,700,1,13.46,15,1,13.47,100,1,13.48,15,1,13.74,2,1,13.76,100,1,14.25,100,1,14.28,200,1,14.4,200,1,14.44,200,1,14.47,700,1,2,338918217
2025-07-17T16:12:43.022612177Z,2025-07-17T16:12:43.022444956Z,160,2,1108,A,A,15.690000000,100,0,338918553,128,167221,282058085,ARL,,13.11,100,1,12.98,200,1,12.92,2,1,12.86,100,1,12.73,100,1,12.71,100,1,12.5,700,1,12.46,100,1,12.43,700,1,12.42,700,1,13.46,15,1,13.47,100,1,13.48,15,1,13.74,2,1,13.76,100,1,14.25,100,1,14.28,200,1,14.4,200,1,14.44,200,1,14.47,700,1,2,338918553
2025-07-17T16:12:43.022627592Z,2025-07-17T16:12:43.022461725Z,160,2,1108,C,A,15.380000000,100,0,338866089,130,165867,282058088,ARL,,13.11,100,1,12.98,200,1,12.92,2,1,12.86,100,1,12.73,100,1,12.71,100,1,12.5,700,1,12.46,100,1,12.43,700,1,12.42,700,1,13.46,15,1,13.47,100,1,13.48,15,1,13.74,2,1,13.76,100,1,14.25,100,1,14.28,200,1,14.4,200,1,14.44,200,1,14.47,700,1,2,338866089
2025-07-17T16:12:43.049284355Z,2025-07-17T16:12:43.049119139Z,160,2,1108,A,A,15.360000000,100,0,338926929,130,165216,282065940,ARL,,13.11,100,1,12.98,200,1,12.92,2,1,12.86,100,1,12.73,100,1,12.71,100,1,12.5,700,1,12.46,100,1,12.43,700,1,12.42,700,1,13.46,15,1,13.47,100,1,13.48,15,1,13.74,2,1,13.76,100,1,14.25,100,1,14.28,200,1,14.4,200,1,14.44,200,1,14.47,700,1,2,338926929
2025-07-17T16:12:43.049298989Z,2025-07-17T16:12:43.049132842Z,160,2,1108,C,A,15.690000000,100,0,338918553,128,166147,282065943,ARL,,13.11,100,1,12.98,200,1,12.92,2,1,12.86,100,1,12.73,100,1,12.71,100,1,12.5,700,1,12.46,100,1,12.43,700,1,12.42,700,1,13.46,15,1,13.47,100,1,13.48,15,1,13.74,2,1,13.76,100,1,14.25,100,1,14.28,200,1,14.4,200,1,14.44,200,1,14.47,700,1,2,338918553
2025-07-17T16:12:43.154952375Z,2025-07-17T16:12:43.154787212Z,160,2,1108,A,A,14.270000000,100,0,338932853,130,165163,282073056,ARL,,13.11,100,1,12.98,200,1,12.92,2,1,12.86,100,1,12.73,100,1,12.71,100,1,12.5,700,1,12.46,100,1,12.43,700,1,12.42,700,1,13.46,15,1,13.47,100,1,13.48,15,1,13.74,2,1,13.76,100,1,14.25,100,1,14.27,100,1,14.28,200,1,14.4,200,1,14.44,200,1,2,338932853
2025-07-17T16:12:43.154965183Z,2025-07-17T16:12:43.154800020Z,160,2,1108,C,A,14.560000000,100,0,296391881,130,165163,282073058,ARL,,13.11,100,1,12.98,200,1,12.92,2,1,12.86,100,1,12.73,100,1,12.71,100,1,12.5,700,1,12.46,100,1,12.43,700,1,12.42,700,1,13.46,15,1,13.47,100,1,13.48,15,1,13.74,2,1,13.76,100,1,14.25,100,1,14.27,100,1,14.28,200,1,14.4,200,1,14.44,200,1,2,296391881
2025-07-17T16:12:43.915552526Z,2025-07-17T16:12:43.915387059Z,160,2,1108,C,A,14.280000000,100,0,302681357,130,165467,282085822,ARL,,13.11,100,1,12.98,200,1,12.92,2,1,12.86,100,1,12.73,100,1,12.71,100,1,12.5,700,1,12.46,100,1,12.43,700,1,12.42,700,1,13.46,15,1,13.47,100,1,13.48,15,1,13.74,2,1,13.76,100,1,14.25,100,1,14.27,100,1,14.28,100,1,14.4,200,1,14.44,200,1,2,302681357
2025-07-17T16:12:43.915555340Z,2025-07-17T16:12:43.915389642Z,160,2,1108,A,A,14.000000000,100,0,338945933,130,165698,282085823,ARL,,13.11,100,1,12.98,200,1,12.92,2,1,12.86,100,1,12.73,100,1,12.71,100,1,12.5,700,1,12.46,100,1,12.43,700,1,12.42,700,1,13.46,15,1,13.47,100,1,13.48,15,1,13.74,2,1,13.76,100,1,14,100,1,14.25,100,1,14.27,100,1,14.28,100,1,14.4,200,1,2,338945933
2025-07-17T16:12:50.729244449Z,2025-07-17T16:12:50.729079105Z,160,2,1108,C,A,13.460000000,15,0,338904977,130,165344,282168721,ARL,,13.11,100,1,12.98,200,1,12.92,2,1,12.86,100,1,12.73,100,1,12.71,100,1,12.5,700,1,12.46,100,1,12.43,700,1,12.42,700,1,13.47,100,1,13.48,15,1,13.74,2,1,13.76,100,1,14,100,1,14.25,100,1,14.27,100,1,14.28,100,1,14.4,200,1,14.44,200,1,2,338904977
2025-07-17T16:12:50.729418237Z,2025-07-17T16:12:50.729252907Z,160,2,1108,C,A,13.480000000,15,0,338707945,130,165330,282168744,ARL,,13.11,100,1,12.98,200,1,12.92,2,1,12.86,100,1,12.73,100,1,12.71,100,1,12.5,700,1,12.46,100,1,12.43,700,1,12.42,700,1,13.47,100,1,13.74,2,1,13.76,100,1,14,100,1,14.25,100,1,14.27,100,1,14.28,100,1,14.4,200,1,14.44,200,1,14.47,700,1,2,338707945
2025-07-17T16:12:50.729575741Z,2025-07-17T16:12:50.729409745Z,160,2,1108,A,A,13.470000000,96,0,339054149,130,165996,282168754,ARL,,13.11,100,1,12.98,200,1,12.92,2,1,12.86,100,1,12.73,100,1,12.71,100,1,12.5,700,1,12.46,100,1,12.43,700,1,12.42,700,1,13.47,196,1,13.74,2,1,13.76,100,1,14,100,1,14.25,100,1,14.27,100,1,14.28,100,1,14.4,200,1,14.44,200,1,14.47,700,1,2,339054149
2025-07-17T16:12:53.021914652Z,2025-07-17T16:12:53.021749348Z,160,2,1108,A,A,13.460000000,15,0,339096733,130,165304,282194154,ARL,,13.11,100,1,12.98,200,1,12.92,2,1,12.86,100,1,12.73,100,1,12.71,100,1,12.5,700,1,12.46,100,1,12.43,700,1,12.42,700,1,13.46,15,1,13.47,196,1,13.74,2,1,13.76,100,1,14,100,1,14.25,100,1,14.27,100,1,14.28,100,1,14.4,200,1,14.44,200,1,2,339096733
2025-07-17T16:12:53.021959141Z,2025-07-17T16:12:53.021793735Z,160,2,1108,C,A,13.470000000,100,0,338918217,130,165406,282194157,ARL,,13.11,100,1,12.98,200,1,12.92,2,1,12.86,100,1,12.73,100,1,12.71,100,1,12.5,700,1,12.46,100,1,12.43,700,1,12.42,700,1,13.46,15,1,13.47,96,1,13.74,2,1,13.76,100,1,14,100,1,14.25,100,1,14.27,100,1,14.28,100,1,14.4,200,1,14.44,200,1,2,338918217
2025-07-17T16:12:53.022230122Z,2025-07-17T16:12:53.022064745Z,160,2,1108,C,A,13.470000000,96,0,339054149,130,165377,282194159,ARL,,13.11,100,1,12.98,200,1,12.92,2,1,12.86,100,1,12.73,100,1,12.71,100,1,12.5,700,1,12.46,100,1,12.43,700,1,12.42,700,1,13.46,15,1,13.74,2,1,13.76,100,1,14,100,1,14.25,100,1,14.27,100,1,14.28,100,1,14.4,200,1,14.44,200,1,14.47,700,1,2,339054149
2025-07-17T16:12:53.022572023Z,2025-07-17T16:12:53.022406202Z,160,2,1108,A,A,15.690000000,100,0,339096757,130,165821,282194161,ARL,,13.11,100,1,12.98,200,1,12.92,2,1,12.86,100,1,12.73,100,1,12.71,100,1,12.5,700,1,12.46,100,1,12.43,700,1,12.42,700,1,13.46,15,1,13.74,2,1,13.76,100,1,14,100,1,14.25,100,1,14.27,100,1,14.28,100,1,14.4,200,1,14.44,200,1,14.47,700,1,2,339096757
2025-07-17T16:12:53.022584264Z,2025-07-17T16:12:53.022418950Z,160,2,1108,C,A,15.360000000,100,0,338926929,130,165314,282194162,ARL,,13.11,100,1,12.98,200,1,12.92,2,1,12.86,100,1,12.73,100,1,12.71,100,1,12.5,700,1,12.46,100,1,12.43,700,1,12.42,700,1,13.46,15,1,13.74,2,1,13.76,100,1,14,100,1,14.25,100,1,14.27,100,1,14.28,100,1,14.4,200,1,14.44,200,1,14.47,700,1,2,338926929
2025-07-17T16:12:53.022962940Z,2025-07-17T16:12:53.022797046Z,160,2,1108,C,A,14.540000000,100,0,338866245,0,165894,282194167,ARL,,13.11,100,1,12.98,200,1,12.92,2,1,12.86,100,1,12.73,100,1,12.71,100,1,12.5,700,1,12.46,100,1,12.43,700,1,12.42,700,1,13.46,15,1,13.74,2,1,13.76,100,1,14,100,1,14.25,100,1,14.27,100,1,14.28,100,1,14.4,200,1,14.44,200,1,14.47,700,1,2,338866245
2025-07-17T16:12:53.022962940Z,2025-07-17T16:12:53.022797046Z,160,2,1108,A,A,14.830000000,100,0,339096773,130,165894,282194167,ARL,,13.11,100,1,12.98,200,1,12.92,2,1,12.86,100,1,12.73,100,1,12.71,100,1,12.5,700,1,12.46,100,1,12.43,700,1,12.42,700,1,13.46,15,1,13.74,2,1,13.76,100,1,14,100,1,14.25,100,1,14.27,100,1,14.28,100,1,14.4,200,1,14.44,200,1,14.47,700,1,2,339096773
2025-07-17T16:12:53.023589530Z,2025-07-17T16:12:53.023423468Z,160,2,1108,C,A,14.440000000,100,0,338865165,0,166062,282194181,ARL,,13.11,100,1,12.98,200,1,12.92,2,1,12.86,100,1,12.73,100,1,12.71,100,1,12.5,700,1,12.46,100,1,12.43,700,1,12.42,700,1,13.46,15,1,13.74,2,1,13.76,100,1,14,100,1,14.25,100,1,14.27,100,1,14.28,100,1,14.4,200,1,14.44,100,1,14.47,700,1,2,338865165
2025-07-17T16:12:53.023589530Z,2025-07-17T16:12:53.023423468Z,160,2,1108,A,A,14.730000000,100,0,339096797,130,166062,282194181,ARL,,13.11,100,1,12.98,200,1,12.92,2,1,12.86,100,1,12.73,100,1,12.71,100,1,12.5,700,1,12.46,100,1,12.43,700,1,12.42,700,1,13.46,15,1,13.74,2,1,13.76,100,1,14,100,1,14.25,100,1,14.27,100,1,14.28,100,1,14.4,200,1,14.44,100,1,14.47,700,1,2,339096797
2025-07-17T16:12:53.024069153Z,2025-07-17T16:12:53.023903582Z,160,2,1108,C,A,17.140000000,100,0,338865253,0,165571,282194183,ARL,,13.11,100,1,12.98,200,1,12.92,2,1,12.86,100,1,12.73,100,1,12.71,100,1,12.5,700,1,12.46,100,1,12.43,700,1,12.42,700,1,13.46,15,1,13.74,2,1,13.76,100,1,14,100,1,14.25,100,1,14.27,100,1,14.28,100,1,14.4,200,1,14.44,100,1,14.47,700,1,2,338865253
2025-07-17T16:12:53.024069153Z,2025-07-17T16:12:53.023903582Z,160,2,1108,A,A,17.480000000,100,0,339096809,130,165571,282194183,ARL,,13.11,100,1,12.98,200,1,12.92,2,1,12.86,100,1,12.73,100,1,12.71,100,1,12.5,700,1,12.46,100,1,12.43,700,1,12.42,700,1,13.46,15,1,13.74,2,1,13.76,100,1,14,100,1,14.25,100,1,14.27,100,1,14.28,100,1,14.4,200,1,14.44,100,1,14.47,700,1,2,339096809
2025-07-17T16:12:53.025583784Z,2025-07-17T16:12:53.025418159Z,160,2,1108,C,A,14.840000000,100,0,338866081,0,165625,282194188,ARL,,13.11,100,1,12.98,200,1,12.92,2,1,12.86,100,1,12.73,100,1,12.71,100,1,12.5,700,1,12.46,100,1,12.43,700,1,12.42,700,1,13.46,15,1,13.74,2,1,13.76,100,1,14,100,1,14.25,100,1,14.27,100,1,14.28,100,1,14.4,200,1,14.44,100,1,14.47,700,1,2,338866081
2025-07-17T16:12:53.025583784Z,2025-07-17T16:12:53.025418159Z,160,2,1108,A,A,15.140000000,100,0,339096813,130,165625,282194188,ARL,,13.11,100,1,12.98,200,1,12.92,2,1,12.86,100,1,12.73,100,1,12.71,100,1,12.5,700,1,12.46,100,1,12.43,700,1,12.42,700,1,13.46,15,1,13.74,2,1,13.76,100,1,14,100,1,14.25,100,1,14.27,100,1,14.28,100,1,14.4,200,1,14.44,100,1,14.47,700,1,2,339096813
2025-07-17T16:12:53.025651983Z,2025-07-17T16:12:53.025486466Z,160,2,1108,C,A,14.440000000,100,0,338865133,0,165517,282194189,ARL,,13.11,100,1,12.98,200,1,12.92,2,1,12.86,100,1,12.73,100,1,12.71,100,1,12.5,700,1,12.46,100,1,12.43,700,1,12.42,700,1,13.46,15,1,13.74,2,1,13.76,100,1,14,100,1,14.25,100,1,14.27,100,1,14.28,100,1,14.4,200,1,14.47,700,1,14.48,700,1,2,338865133
2025-07-17T16:12:53.025651983Z,2025-07-17T16:12:53.025486466Z,160,2,1108,A,A,14.730000000,100,0,339096817,130,165517,282194189,ARL,,13.11,100,1,12.98,200,1,12.92,2,1,12.86,100,1,12.73,100,1,12.71,100,1,12.5,700,1,12.46,100,1,12.43,700,1,12.42,700,1,13.46,15,1,13.74,2,1,13.76,100,1,14,100,1,14.25,100,1,14.27,100,1,14.28,100,1,14.4,200,1,14.47,700,1,14.48,700,1,2,339096817
2025-07-17T16:12:53.027715026Z,2025-07-17T16:12:53.027549524Z,160,2,1108,C,A,14.280000000,100,0,338894329,130,165502,282194224,ARL,,13.11,100,1,12.98,200,1,12.92,2,1,12.86,100,1,12.73,100,1,12.71,100,1,12.5,700,1,12.46,100,1,12.43,700,1,12.42,700,1,13.46,15,1,13.74,2,1,13.76,100,1,14,100,1,14.25,100,1,14.27,100,1,14.4,200,1,14.47,700,1,14.48,700,1,14.54,700,1,2,338894329
2025-07-17T16:12:53.027866777Z,2025-07-17T16:12:53.027701439Z,160,2,1108,A,A,14.550000000,100,0,339096833,130,165338,282194226,ARL,,13.11,100,1,12.98,200,1,12.92,2,1,12.86,100,1,12.73,100,1,12.71,100,1,12.5,700,1,12.46,100,1,12.43,700,1,12.42,700,1,13.46,15,1,13.74,2,1,13.76,100,1,14,100,1,14.25,100,1,14.27,100,1,14.4,200,1,14.47,700,1,14.48,700,1,14.54,700,1,2,339096833
2025-07-17T16:12:53.027987030Z,2025-07-17T16:12:53.027821450Z,160,2,1108,C,A,15.520000000,100,0,338865301,0,165580,282194228,ARL,,13.11,100,1,12.98,200,1,12.92,2,1,12.86,100,1,12.73,100,1,12.71,100,1,12.5,700,1,12.46,100,1,12.43,700,1,12.42,700,1,13.46,15,1,13.74,2,1,13.76,100,1,14,100,1,14.25,100,1,14.27,100,1,14.4,200,1,14.47,700,1,14.48,700,1,14.54,700,1,2,338865301
2025-07-17T16:12:53.027987030Z,2025-07-17T16:12:53.027821450Z,160,2,1108,A,A,15.830000000,100,0,339096837,130,165580,282194228,ARL,,13.11,100,1,12.98,200,1,12.92,2,1,12.86,100,1,12.73,100,1,12.71,100,1,12.5,700,1,12.46,100,1,12.43,700,1,12.42,700,1,13.46,15,1,13.74,2,1,13.76,100,1,14,100,1,14.25,100,1,14.27,100,1,14.4,200,1,14.47,700,1,14.48,700,1,14.54,700,1,2,339096837
2025-07-17T16:12:53.033266537Z,2025-07-17T16:12:53.033101265Z,160,2,1108,C,A,13.760000000,100,0,338865177,130,165272,282194348,ARL,,13.11,100,1,12.98,200,1,12.92,2,1,12.86,100,1,12.73,100,1,12.71,100,1,12.5,700,1,12.46,100,1,12.43,700,1,12.42,700,1,13.46,15,1,13.74,2,1,14,100,1,14.25,100,1,14.27,100,1,14.4,200,1,14.47,700,1,14.48,700,1,14.54,700,1,14.55,100,1,2,338865177
2025-07-17T16:12:53.033302848Z,2025-07-17T16:12:53.033137644Z,160,2,1108,C,A,14.470000000,700,0,338864173,130,165204,282194349,ARL,,13.11,100,1,12.98,200,1,12.92,2,1,12.86,100,1,12.73,100,1,12.71,100,1,12.5,700,1,12.46,100,1,12.43,700,1,12.42,700,1,13.46,15,1,13.74,2,1,14,100,1,14.25,100,1,14.27,100,1,14.4,200,1,14.48,700,1,14.54,700,1,14.55,100,1,14.56,700,1,2,338864173
2025-07-17T16:12:53.033318818Z,2025-07-17T16:12:53.033153612Z,160,2,1108,A,A,14.040000000,100,0,339096893,130,165206,282194350,ARL,,13.11,100,1,12.98,200,1,12.92,2,1,12.86,100,1,12.73,100,1,12.71,100,1,12.5,700,1,12.46,100,1,12.43,700,1,12.42,700,1,13.46,15,1,13.74,2,1,14,100,1,14.04,100,1,14.25,100,1,14.27,100,1,14.4,200,1,14.48,700,1,14.54,700,1,14.55,100,1,2,339096893
2025-07-17T16:12:53.033349323Z,2025-07-17T16:12:53.033183560Z,160,2,1108,A,A,14.680000000,700,0,339096897,130,165763,282194351,ARL,,13.11,100,1,12.98,200,1,12.92,2,1,12.86,100,1,12.73,100,1,12.71,100,1,12.5,700,1,12.46,100,1,12.43,700,1,12.42,700,1,13.46,15,1,13.74,2,1,14,100,1,14.04,100,1,14.25,100,1,14.27,100,1,14.4,200,1,14.48,700,1,14.54,700,1,14.55,100,1,2,339096897
2025-07-17T16:12:53.033762072Z,2025-07-17T16:12:53.033596046Z,160,2,1108,C,A,13.740000000,2,0,338371797,0,166026,282194354,ARL,,13.11,100,1,12.98,200,1,12.92,2,1,12.86,100,1,12.73,100,1,12.71,100,1,12.5,700,1,12.46,100,1,12.43,700,1,12.42,700,1,13.46,15,1,14,100,1,14.04,100,1,14.25,100,1,14.27,100,1,14.4,200,1,14.48,700,1,14.54,700,1,14.55,100,1,14.56,700,1,2,338371797
2025-07-17T16:12:53.033762072Z,2025-07-17T16:12:53.033596046Z,160,2,1108,A,A,13.980000000,2,0,339096909,130,166026,282194354,ARL,,13.11,100,1,12.98,200,1,12.92,2,1,12.86,100,1,12.73,100,1,12.71,100,1,12.5,700,1,12.46,100,1,12.43,700,1,12.42,700,1,13.46,15,1,13.98,2,1,14,100,1,14.04,100,1,14.25,100,1,14.27,100,1,14.4,200,1,14.48,700,1,14.54,700,1,14.55,100,1,2,339096909
2025-07-17T16:12:53.034000646Z,2025-07-17T16:12:53.033835120Z,160,2,1108,C,A,14.250000000,100,0,336161365,130,165526,282194360,ARL,,13.11,100,1,12.98,200,1,12.92,2,1,12.86,100,1,12.73,100,1,12.71,100,1,12.5,700,1,12.46,100,1,12.43,700,1,12.42,700,1,13.46,15,1,13.98,2,1,14,100,1,14.04,100,1,14.27,100,1,14.4,200,1,14.48,700,1,14.54,700,1,14.55,100,1,14.56,700,1,2,336161365
2025-07-17T16:12:53.034142471Z,2025-07-17T16:12:53.033977054Z,160,2,1108,C,A,14.730000000,100,0,339096797,0,165417,282194361,ARL,,13.11,100,1,12.98,200,1,12.92,2,1,12.86,100,1,12.73,100,1,12.71,100,1,12.5,700,1,12.46,100,1,12.43,700,1,12.42,700,1,13.46,15,1,13.98,2,1,14,100,1,14.04,100,1,14.27,100,1,14.4,200,1,14.48,700,1,14.54,700,1,14.55,100,1,14.56,700,1,2,339096797
2025-07-17T16:12:53.034142471Z,2025-07-17T16:12:53.033977054Z,160,2,1108,A,A,14.960000000,100,0,339096917,130,165417,282194361,ARL,,13.11,100,1,12.98,200,1,12.92,2,1,12.86,100,1,12.73,100,1,12.71,100,1,12.5,700,1,12.46,100,1,12.43,700,1,12.42,700,1,13.46,15,1,13.98,2,1,14,100,1,14.04,100,1,14.27,100,1,14.4,200,1,14.48,700,1,14.54,700,1,14.55,100,1,14.56,700,1,2,339096917
2025-07-17T16:12:53.034178176Z,2025-07-17T16:12:53.034012618Z,160,2,1108,C,A,15.830000000,100,0,339096837,0,165558,282194362,ARL,,13.11,100,1,12.98,200,1,12.92,2,1,12.86,100,1,12.73,100,1,12.71,100,1,12.5,700,1,12.46,100,1,12.43,700,1,12.42,700,1,13.46,15,1,13.98,2,1,14,100,1,14.04,100,1,14.27,100,1,14.4,200,1,14.48,700,1,14.54,700,1,14.55,100,1,14.56,700,1,2,339096837
2025-07-17T16:12:53.034178176Z,2025-07-17T16:12:53.034012618Z,160,2,1108,A,A,16.080000000,100,0,339096921,130,165558,282194362,ARL,,13.11,100,1,12.98,200,1,12.92,2,1,12.86,100,1,12.73,100,1,12.71,100,1,12.5,700,1,12.46,100,1,12.43,700,1,12.42,700,1,13.46,15,1,13.98,2,1,14,100,1,14.04,100,1,14.27,100,1,14.4,200,1,14.48,700,1,14.54,700,1,14.55,100,1,14.56,700,1,2,339096921
2025-07-17T16:12:53.034353140Z,2025-07-17T16:12:53.034187864Z,160,2,1108,A,A,14.600000000,100,0,339096925,130,165276,282194365,ARL,,13.11,100,1,12.98,200,1,12.92,2,1,12.86,100,1,12.73,100,1,12.71,100,1,12.5,700,1,12.46,100,1,12.43,700,1,12.42,700,1,13.46,15,1,13.98,2,1,14,100,1,14.04,100,1,14.27,100,1,14.4,200,1,14.48,700,1,14.54,700,1,14.55,100,1,14.56,700,1,2,339096925
2025-07-17T16:12:53.035411748Z,2025-07-17T16:12:53.035246187Z,160,2,1108,C,A,15.050000000,100,0,335220549,0,165561,282194373,ARL,,13.11,100,1,12.98,200,1,12.92,2,1,12.86,100,1,12.73,100,1,12.71,100,1,12.5,700,1,12.46,100,1,12.43,700,1,12.42,700,1,13.46,15,1,13.98,2,1,14,100,1,14.04,100,1,14.27,100,1,14.4,200,1,14.48,700,1,14.54,700,1,14.55,100,1,14.56,700,1,2,335220549
2025-07-17T16:12:53.035411748Z,2025-07-17T16:12:53.035246187Z,160,2,1108,A,A,15.380000000,100,0,339096929,130,165561,282194373,ARL,,13.11,100,1,12.98,200,1,12.92,2,1,12.86,100,1,12.73,100,1,12.71,100,1,12.5,700,1,12.46,100,1,12.43,700,1,12.42,700,1,13.46,15,1,13.98,2,1,14,100,1,14.04,100,1,14.27,100,1,14.4,200,1,14.48,700,1,14.54,700,1,14.55,100,1,14.56,700,1,2,339096929
2025-07-17T16:12:53.036307382Z,2025-07-17T16:12:53.036142164Z,160,2,1108,C,A,17.480000000,100,0,339096809,0,165218,282194381,ARL,,13.11,100,1,12.98,200,1,12.92,2,1,12.86,100,1,12.73,100,1,12.71,100,1,12.5,700,1,12.46,100,1,12.43,700,1,12.42,700,1,13.46,15,1,13.98,2,1,14,100,1,14.04,100,1,14.27,100,1,14.4,200,1,14.48,700,1,14.54,700,1,14.55,100,1,14.56,700,1,2,339096809
2025-07-17T16:12:53.036307382Z,2025-07-17T16:12:53.036142164Z,160,2,1108,A,A,17.760000000,100,0,339096949,130,165218,282194381,ARL,,13.11,100,1,12.98,200,1,12.92,2,1,12.86,100,1,12.73,100,1,12.71,100,1,12.5,700,1,12.46,100,1,12.43,700,1,12.42,700,1,13.46,15,1,13.98,2,1,14,100,1,14.04,100,1,14.27,100,1,14.4,200,1,14.48,700,1,14.54,700,1,14.55,100,1,14.56,700,1,2,339096949
2025-07-17T16:12:53.040045217Z,2025-07-17T16:12:53.039879965Z,160,2,1108,C,A,14.730000000,100,0,339096817,0,165252,282194416,ARL,,13.11,100,1,12.98,200,1,12.92,2,1,12.86,100,1,12.73,100,1,12.71,100,1,12.5,700,1,12.46,100,1,12.43,700,1,12.42,700,1,13.46,15,1,13.98,2,1,14,100,1,14.04,100,1,14.27,100,1,14.4,200,1,14.48,700,1,14.54,700,1,14.55,100,1,14.56,700,1,2,339096817
2025-07-17T16:12:53.040045217Z,2025-07-17T16:12:53.039879965Z,160,2,1108,A,A,14.960000000,100,0,339096977,130,165252,282194416,ARL,,13.11,100,1,12.98,200,1,12.92,2,1,12.86,100,1,12.73,100,1,12.71,100,1,12.5,700,1,12.46,100,1,12.43,700,1,12.42,700,1,13.46,15,1,13.98,2,1,14,100,1,14.04,100,1,14.27,100,1,14.4,200,1,14.48,700,1,14.54,700,1,14.55,100,1,14.56,700,1,2,339096977
2025-07-17T16:12:53.043727225Z,2025-07-17T16:12:53.043562198Z,160,2,1108,C,A,14.040000000,100,0,339096893,130,165027,282194436,ARL,,13.11,100,1,12.98,200,1,12.92,2,1,12.86,100,1,12.73,100,1,12.71,100,1,12.5,700,1,12.46,100,1,12.43,700,1,12.42,700,1,13.46,15,1,13.98,2,1,14,100,1,14.27,100,1,14.4,200,1,14.48,700,1,14.54,700,1,14.55,100,1,14.56,700,1,14.6,100,1,2,339096893
2025-07-17T16:12:53.043775299Z,2025-07-17T16:12:53.043610101Z,160,2,1108,A,A,14.260000000,100,0,339097005,130,165198,282194438,ARL,,13.11,100,1,12.98,200,1,12.92,2,1,12.86,100,1,12.73,100,1,12.71,100,1,12.5,700,1,12.46,100,1,12.43,700,1,12.42,700,1,13.46,15,1,13.98,2,1,14,100,1,14.26,100,1,14.27,100,1,14.4,200,1,14.48,700,1,14.54,700,1,14.55,100,1,14.56,700,1,2,339097005
2025-07-17T16:12:53.073052597Z,2025-07-17T16:12:53.072887133Z,160,2,1108,C,A,14.830000000,100,0,339096773,0,165464,282194725,ARL,,13.11,100,1,12.98,200,1,12.92,2,1,12.86,100,1,12.73,100,1,12.71,100,1,12.5,700,1,12.46,100,1,12.43,700,1,12.42,700,1,13.46,15,1,13.98,2,1,14,100,1,14.26,100,1,14.27,100,1,14.4,200,1,14.48,700,1,14.54,700,1,14.55,100,1,14.56,700,1,2,339096773
2025-07-17T16:12:53.073052597Z,2025-07-17T16:12:53.072887133Z,160,2,1108,A,A,15.060000000,100,0,339097245,130,165464,282194725,ARL,,13.11,100,1,12.98,200,1,12.92,2,1,12.86,100,1,12.73,100,1,12.71,100,1,12.5,700,1,12.46,100,1,12.43,700,1,12.42,700,1,13.46,15,1,13.98,2,1,14,100,1,14.26,100,1,14.27,100,1,14.4,200,1,14.48,700,1,14.54,700,1,14.55,100,1,14.56,700,1,2,339097245
2025-07-17T16:12:53.332729487Z,2025-07-17T16:12:53.332564148Z,160,2,1108,C,A,14.000000000,100,0,338945933,130,165339,282196976,ARL,,13.11,100,1,12.98,200,1,12.92,2,1,12.86,100,1,12.73,100,1,12.71,100,1,12.5,700,1,12.46,100,1,12.43,700,1,12.42,700,1,13.46,15,1,13.98,2,1,14.26,100,1,14.27,100,1,14.4,200,1,14.48,700,1,14.54,700,1,14.55,100,1,14.56,700,1,14.6,100,1,2,338945933
2025-07-17T16:12:53.332730508Z,2025-07-17T16:12:53.332565150Z,160,2,1108,A,A,14.530000000,100,0,339100477,130,165358,282196977,ARL,,13.11,100,1,12.98,200,1,12.92,2,1,12.86,100,1,12.73,100,1,12.71,100,1,12.5,700,1,12.46,100,1,12.43,700,1,12.42,700,1,13.46,15,1,13.98,2,1,14.26,100,1,14.27,100,1,14.4,200,1,14.48,700,1,14.53,100,1,14.54,700,1,14.55,100,1,14.56,700,1,2,339100477
2025-07-17T16:12:53.587788615Z,2025-07-17T16:12:53.587623157Z,160,2,1108,A,A,14.810000000,100,0,339103269,130,165458,282200199,ARL,,13.11,100,1,12.98,200,1,12.92,2,1,12.86,100,1,12.73,100,1,12.71,100,1,12.5,700,1,12.46,100,1,12.43,700,1,12.42,700,1,13.46,15,1,13.98,2,1,14.26,100,1,14.27,100,1,14.4,200,1,14.48,700,1,14.53,100,1,14.54,700,1,14.55,100,1,14.56,700,1,2,339103269
2025-07-17T16:12:53.587810242Z,2025-07-17T16:12:53.587644886Z,160,2,1108,C,A,14.270000000,100,0,338932853,130,165356,282200200,ARL,,13.11,100,1,12.98,200,1,12.92,2,1,12.86,100,1,12.73,100,1,12.71,100,1,12.5,700,1,12.46,100,1,12.43,700,1,12.42,700,1,13.46,15,1,13.98,2,1,14.26,100,1,14.4,200,1,14.48,700,1,14.53,100,1,14.54,700,1,14.55,100,1,14.56,700,1,14.6,100,1,2,338932853
2025-07-17T16:12:54.015217279Z,2025-07-17T16:12:54.015051915Z,160,2,1108,A,A,13.470000000,100,0,339110853,130,165364,282207405,ARL,,13.11,100,1,12.98,200,1,12.92,2,1,12.86,100,1,12.73,100,1,12.71,100,1,12.5,700,1,12.46,100,1,12.43,700,1,12.42,700,1,13.46,15,1,13.47,100,1,13.98,2,1,14.26,100,1,14.4,200,1,14.48,700,1,14.53,100,1,14.54,700,1,14.55,100,1,14.56,700,1,2,339110853
2025-07-17T16:12:54.015951319Z,2025-07-17T16:12:54.015785325Z,160,2,1108,C,A,14.600000000,100,0,339096925,130,165994,282207428,ARL,,13.11,100,1,12.98,200,1,12.92,2,1,12.86,100,1,12.73,100,1,12.71,100,1,12.5,700,1,12.46,100,1,12.43,700,1,12.42,700,1,13.46,15,1,13.47,100,1,13.98,2,1,14.26,100,1,14.4,200,1,14.48,700,1,14.53,100,1,14.54,700,1,14.55,100,1,14.56,700,1,2,339096925
2025-07-17T16:12:54.015954059Z,2025-07-17T16:12:54.015788678Z,160,2,1108,C,A,15.060000000,100,0,339097245,0,165381,282207429,ARL,,13.11,100,1,12.98,200,1,12.92,2,1,12.86,100,1,12.73,100,1,12.71,100,1,12.5,700,1,12.46,100,1,12.43,700,1,12.42,700,1,13.46,15,1,13.47,100,1,13.98,2,1,14.26,100,1,14.4,200,1,14.48,700,1,14.53,100,1,14.54,700,1,14.55,100,1,14.56,700,1,2,339097245
2025-07-17T16:12:54.015954059Z,2025-07-17T16:12:54.015788678Z,160,2,1108,A,A,14.520000000,100,0,339110897,130,165381,282207429,ARL,,13.11,100,1,12.98,200,1,12.92,2,1,12.86,100,1,12.73,100,1,12.71,100,1,12.5,700,1,12.46,100,1,12.43,700,1,12.42,700,1,13.46,15,1,13.47,100,1,13.98,2,1,14.26,100,1,14.4,200,1,14.48,700,1,14.52,100,1,14.53,100,1,14.54,700,1,14.55,100,1,2,339110897
2025-07-17T16:12:54.016305036Z,2025-07-17T16:12:54.016139684Z,160,2,1108,A,A,14.070000000,100,0,339110909,130,165352,282207437,ARL,,13.11,100,1,12.98,200,1,12.92,2,1,12.86,100,1,12.73,100,1,12.71,100,1,12.5,700,1,12.46,100,1,12.43,700,1,12.42,700,1,13.46,15,1,13.47,100,1,13.98,2,1,14.07,100,1,14.26,100,1,14.4,200,1,14.48,700,1,14.52,100,1,14.53,100,1,14.54,700,1,2,339110909
2025-07-17T16:12:54.017154493Z,2025-07-17T16:12:54.016988897Z,160,2,1108,C,A,14.960000000,100,0,339096917,0,165596,282207488,ARL,,13.11,100,1,12.98,200,1,12.92,2,1,12.86,100,1,12.73,100,1,12.71,100,1,12.5,700,1,12.46,100,1,12.43,700,1,12.42,700,1,13.46,15,1,13.47,100,1,13.98,2,1,14.07,100,1,14.26,100,1,14.4,200,1,14.48,700,1,14.52,100,1,14.53,100,1,14.54,700,1,2,339096917
2025-07-17T16:12:54.017154493Z,2025-07-17T16:12:54.016988897Z,160,2,1108,A,A,14.420000000,100,0,339110981,130,165596,282207488,ARL,,13.11,100,1,12.98,200,1,12.92,2,1,12.86,100,1,12.73,100,1,12.71,100,1,12.5,700,1,12.46,100,1,12.43,700,1,12.42,700,1,13.46,15,1,13.47,100,1,13.98,2,1,14.07,100,1,14.26,100,1,14.4,200,1,14.42,100,1,14.48,700,1,14.52,100,1,14.53,100,1,2,339110981
2025-07-17T16:12:54.017381126Z,2025-07-17T16:12:54.017215883Z,160,2,1108,C,A,13.980000000,2,0,339096909,0,165243,282207495,ARL,,13.11,100,1,12.98,200,1,12.92,2,1,12.86,100,1,12.73,100,1,12.71,100,1,12.5,700,1,12.46,100,1,12.43,700,1,12.42,700,1,13.46,15,1,13.47,100,1,14.07,100,1,14.26,100,1,14.4,200,1,14.42,100,1,14.48,700,1,14.52,100,1,14.53,100,1,14.54,700,1,2,339096909
2025-07-17T16:12:54.017381126Z,2025-07-17T16:12:54.017215883Z,160,2,1108,A,A,13.730000000,2,0,339110993,130,165243,282207495,ARL,,13.11,100,1,12.98,200,1,12.92,2,1,12.86,100,1,12.73,100,1,12.71,100,1,12.5,700,1,12.46,100,1,12.43,700,1,12.42,700,1,13.46,15,1,13.47,100,1,13.73,2,1,14.07,100,1,14.26,100,1,14.4,200,1,14.42,100,1,14.48,700,1,14.52,100,1,14.53,100,1,2,339110993
2025-07-17T16:12:54.017787766Z,2025-07-17T16:12:54.017622232Z,160,2,1108,C,A,15.380000000,100,0,339096929,0,165534,282207502,ARL,,13.11,100,1,12.98,200,1,12.92,2,1,12.86,100,1,12.73,100,1,12.71,100,1,12.5,700,1,12.46,100,1,12.43,700,1,12.42,700,1,13.46,15,1,13.47,100,1,13.73,2,1,14.07,100,1,14.26,100,1,14.4,200,1,14.42,100,1,14.48,700,1,14.52,100,1,14.53,100,1,2,339096929
2025-07-17T16:12:54.017787766Z,2025-07-17T16:12:54.017622232Z,160,2,1108,A,A,14.820000000,100,0,339111005,130,165534,282207502,ARL,,13.11,100,1,12.98,200,1,12.92,2,1,12.86,100,1,12.73,100,1,12.71,100,1,12.5,700,1,12.46,100,1,12.43,700,1,12.42,700,1,13.46,15,1,13.47,100,1,13.73,2,1,14.07,100,1,14.26,100,1,14.4,200,1,14.42,100,1,14.48,700,1,14.52,100,1,14.53,100,1,2,339111005
2025-07-17T16:12:54.020179178Z,2025-07-17T16:12:54.020013940Z,160,2,1108,C,A,14.260000000,100,0,339097005,130,165238,282207539,ARL,,13.11,100,1,12.98,200,1,12.92,2,1,12.86,100,1,12.73,100,1,12.71,100,1,12.5,700,1,12.46,100,1,12.43,700,1,12.42,700,1,13.46,15,1,13.47,100,1,13.73,2,1,14.07,100,1,14.4,200,1,14.42,100,1,14.48,700,1,14.52,100,1,14.53,100,1,14.54,700,1,2,339097005
2025-07-17T16:12:54.020233019Z,2025-07-17T16:12:54.020067630Z,160,2,1108,A,A,13.740000000,100,0,339111029,130,165389,282207540,ARL,,13.11,100,1,12.98,200,1,12.92,2,1,12.86,100,1,12.73,100,1,12.71,100,1,12.5,700,1,12.46,100,1,12.43,700,1,12.42,700,1,13.46,15,1,13.47,100,1,13.73,2,1,13.74,100,1,14.07,100,1,14.4,200,1,14.42,100,1,14.48,700,1,14.52,100,1,14.53,100,1,2,339111029
2025-07-17T16:12:54.023027943Z,2025-07-17T16:12:54.022862493Z,160,2,1108,C,A,17.760000000,100,0,339096949,0,165450,282207651,ARL,,13.11,100,1,12.98,200,1,12.92,2,1,12.86,100,1,12.73,100,1,12.71,100,1,12.5,700,1,12.46,100,1,12.43,700,1,12.42,700,1,13.46,15,1,13.47,100,1,13.73,2,1,13.74,100,1,14.07,100,1,14.4,200,1,14.42,100,1,14.48,700,1,14.52,100,1,14.53,100,1,2,339096949
2025-07-17T16:12:54.023027943Z,2025-07-17T16:12:54.022862493Z,160,2,1108,A,A,17.110000000,100,0,339111097,130,165450,282207651,ARL,,13.11,100,1,12.98,200,1,12.92,2,1,12.86,100,1,12.73,100,1,12.71,100,1,12.5,700,1,12.46,100,1,12.43,700,1,12.42,700,1,13.46,15,1,13.47,100,1,13.73,2,1,13.74,100,1,14.07,100,1,14.4,200,1,14.42,100,1,14.48,700,1,14.52,100,1,14.53,100,1,2,339111097
2025-07-17T16:12:54.026187354Z,2025-07-17T16:12:54.026021681Z,160,2,1108,C,A,16.080000000,100,0,339096921,0,165673,282207700,ARL,,13.11,100,1,12.98,200,1,12.92,2,1,12.86,100,1,12.73,100,1,12.71,100,1,12.5,700,1,12.46,100,1,12.43,700,1,12.42,700,1,13.46,15,1,13.47,100,1,13.73,2,1,13.74,100,1,14.07,100,1,14.4,200,1,14.42,100,1,14.48,700,1,14.52,100,1,14.53,100,1,2,339096921
2025-07-17T16:12:54.026187354Z,2025-07-17T16:12:54.026021681Z,160,2,1108,A,A,15.500000000,100,0,339111149,130,165673,282207700,ARL,,13.11,100,1,12.98,200,1,12.92,2,1,12.86,100,1,12.73,100,1,12.71,100,1,12.5,700,1,12.46,100,1,12.43,700,1,12.42,700,1,13.46,15,1,13.47,100,1,13.73,2,1,13.74,100,1,14.07,100,1,14.4,200,1,14.42,100,1,14.48,700,1,14.52,100,1,14.53,100,1,2,339111149
2025-07-17T16:12:54.029232379Z,2025-07-17T16:12:54.029066847Z,160,2,1108,C,A,14.550000000,100,0,339096833,0,165532,282207737,ARL,,13.11,100,1,12.98,200,1,12.92,2,1,12.86,100,1,12.73,100,1,12.71,100,1,12.5,700,1,12.46,100,1,12.43,700,1,12.42,700,1,13.46,15,1,13.47,100,1,13.73,2,1,13.74,100,1,14.07,100,1,14.4,200,1,14.42,100,1,14.48,700,1,14.52,100,1,14.53,100,1,2,339096833
2025-07-17T16:12:54.029232379Z,2025-07-17T16:12:54.029066847Z,160,2,1108,A,A,14.260000000,100,0,339111189,130,165532,282207737,ARL,,13.11,100,1,12.98,200,1,12.92,2,1,12.86,100,1,12.73,100,1,12.71,100,1,12.5,700,1,12.46,100,1,12.43,700,1,12.42,700,1,13.46,15,1,13.47,100,1,13.73,2,1,13.74,100,1,14.07,100,1,14.26,100,1,14.4,200,1,14.42,100,1,14.48,700,1,14.52,100,1,2,339111189
2025-07-17T16:12:54.055257401Z,2025-07-17T16:12:54.055092122Z,160,2,1108,A,A,15.360000000,100,0,339112469,130,165279,282209385,ARL,,13.11,100,1,12.98,200,1,12.92,2,1,12.86,100,1,12.73,100,1,12.71,100,1,12.5,700,1,12.46,100,1,12.43,700,1,12.42,700,1,13.46,15,1,13.47,100,1,13.73,2,1,13.74,100,1,14.07,100,1,14.26,100,1,14.4,200,1,14.42,100,1,14.48,700,1,14.52,100,1,2,339112469
2025-07-17T16:12:54.055269406Z,2025-07-17T16:12:54.055104415Z,160,2,1108,C,A,15.690000000,100,0,339096757,130,164991,282209392,ARL,,13.11,100,1,12.98,200,1,12.92,2,1,12.86,100,1,12.73,100,1,12.71,100,1,12.5,700,1,12.46,100,1,12.43,700,1,12.42,700,1,13.46,15,1,13.47,100,1,13.73,2,1,13.74,100,1,14.07,100,1,14.26,100,1,14.4,200,1,14.42,100,1,14.48,700,1,14.52,100,1,2,339096757
2025-07-17T16:12:54.069779810Z,2025-07-17T16:12:54.069614114Z,160,2,1108,C,A,14.960000000,100,0,339096977,0,165696,282210148,ARL,,13.11,100,1,12.98,200,1,12.92,2,1,12.86,100,1,12.73,100,1,12.71,100,1,12.5,700,1,12.46,100,1,12.43,700,1,12.42,700,1,13.46,15,1,13.47,100,1,13.73,2,1,13.74,100,1,14.07,100,1,14.26,100,1,14.4,200,1,14.42,100,1,14.48,700,1,14.52,100,1,2,339096977
2025-07-17T16:12:54.069779810Z,2025-07-17T16:12:54.069614114Z,160,2,1108,A,A,14.420000000,100,0,339112945,130,165696,282210148,ARL,,13.11,100,1,12.98,200,1,12.92,2,1,12.86,100,1,12.73,100,1,12.71,100,1,12.5,700,1,12.46,100,1,12.43,700,1,12.42,700,1,13.46,15,1,13.47,100,1,13.73,2,1,13.74,100,1,14.07,100,1,14.26,100,1,14.4,200,1,14.42,200,1,14.48,700,1,14.52,100,1,2,339112945
2025-07-17T16:12:54.072881596Z,2025-07-17T16:12:54.072716256Z,160,2,1108,C,A,15.140000000,100,0,339096813,0,165340,282210181,ARL,,13.11,100,1,12.98,200,1,12.92,2,1,12.86,100,1,12.73,100,1,12.71,100,1,12.5,700,1,12.46,100,1,12.43,700,1,12.42,700,1,13.46,15,1,13.47,100,1,13.73,2,1,13.74,100,1,14.07,100,1,14.26,100,1,14.4,200,1,14.42,200,1,14.48,700,1,14.52,100,1,2,339096813
2025-07-17T16:12:54.072881596Z,2025-07-17T16:12:54.072716256Z,160,2,1108,A,A,14.820000000,100,0,339112981,130,165340,282210181,ARL,,13.11,100,1,12.98,200,1,12.92,2,1,12.86,100,1,12.73,100,1,12.71,100,1,12.5,700,1,12.46,100,1,12.43,700,1,12.42,700,1,13.46,15,1,13.47,100,1,13.73,2,1,13.74,100,1,14.07,100,1,14.26,100,1,14.4,200,1,14.42,200,1,14.48,700,1,14.52,100,1,2,339112981
2025-07-17T16:12:54.694796063Z,2025-07-17T16:12:54.694630780Z,160,2,1108,A,A,14.270000000,100,0,339126221,130,165283,282224916,ARL,,13.11,100,1,12.98,200,1,12.92,2,1,12.86,100,1,12.73,100,1,12.71,100,1,12.5,700,1,12.46,100,1,12.43,700,1,12.42,700,1,13.46,15,1,13.47,100,1,13.73,2,1,13.74,100,1,14.07,100,1,14.26,100,1,14.27,100,1,14.4,200,1,14.42,200,1,14.48,700,1,2,339126221
2025-07-17T16:12:54.694809520Z,2025-07-17T16:12:54.694644316Z,160,2,1108,C,A,14.810000000,100,0,339103269,130,165204,282224917,ARL,,13.11,100,1,12.98,200,1,12.92,2,1,12.86,100,1,12.73,100,1,12.71,100,1,12.5,700,1,12.46,100,1,12.43,700,1,12.42,700,1,13.46,15,1,13.47,100,1,13.73,2,1,13.74,100,1,14.07,100,1,14.26,100,1,14.27,100,1,14.4,200,1,14.42,200,1,14.48,700,1,2,339103269
2025-07-17T16:12:55.255327586Z,2025-07-17T16:12:55.255162003Z,160,2,1108,A,A,14.000000000,100,0,339133353,130,165583,282231441,ARL,,13.11,100,1,12.98,200,1,12.92,2,1,12.86,100,1,12.73,100,1,12.71,100,1,12.5,700,1,12.46,100,1,12.43,700,1,12.42,700,1,13.46,15,1,13.47,100,1,13.73,2,1,13.74,100,1,14,100,1,14.07,100,1,14.26,100,1,14.27,100,1,14.4,200,1,14.42,200,1,2,339133353
2025-07-17T16:12:55.255328269Z,2025-07-17T16:12:55.255163083Z,160,2,1108,C,A,14.530000000,100,0,339100477,130,165186,282231442,ARL,,13.11,100,1,12.98,200,1,12.92,2,1,12.86,100,1,12.73,100,1,12.71,100,1,12.5,700,1,12.46,100,1,12.43,700,1,12.42,700,1,13.46,15,1,13.47,100,1,13.73,2,1,13.74,100,1,14,100,1,14.07,100,1,14.26,100,1,14.27,100,1,14.4,200,1,14.42,200,1,2,339100477
2025-07-17T16:12:58.302183447Z,2025-07-17T16:12:58.302017238Z,160,2,1108,C,A,13.460000000,15,0,339096733,128,166209,282279351,ARL,,13.11,100,1,12.98,200,1,12.92,2,1,12.86,100,1,12.73,100,1,12.71,100,1,12.5,700,1,12.46,100,1,12.43,700,1,12.42,700,1,13.47,100,1,13.73,2,1,13.74,100,1,14,100,1,14.07,100,1,14.26,100,1,14.27,100,1,14.4,200,1,14.42,200,1,14.48,700,1,2,339096733
2025-07-17T16:12:58.420887746Z,2025-07-17T16:12:58.420710579Z,160,2,1108,C,A,13.470000000,100,0,339110853,128,177167,282288716,ARL,,13.11,100,1,12.98,200,1,12.92,2,1,12.86,100,1,12.73,100,1,12.71,100,1,12.5,700,1,12.46,100,1,12.43,700,1,12.42,700,1,13.73,2,1,13.74,100,1,14,100,1,14.07,100,1,14.26,100,1,14.27,100,1,14.4,200,1,14.42,200,1,14.48,700,1,14.52,100,1,2,339110853
2025-07-17T16:12:58.420950587Z,2025-07-17T16:12:58.420776003Z,160,2,1108,A,A,13.470000000,96,0,339201549,128,174584,282288757,ARL,,13.11,100,1,12.98,200,1,12.92,2,1,12.86,100,1,12.73,100,1,12.71,100,1,12.5,700,1,12.46,100,1,12.43,700,1,12.42,700,1,13.47,96,1,13.73,2,1,13.74,100,1,14,100,1,14.07,100,1,14.26,100,1,14.27,100,1,14.4,200,1,14.42,200,1,14.48,700,1,2,339201549
2025-07-17T16:12:58.421338553Z,2025-07-17T16:12:58.421165414Z,160,2,1108,C,A,13.470000000,96,0,339201549,130,173139,282289082,ARL,,13.11,100,1,12.98,200,1,12.92,2,1,12.86,100,1,12.73,100,1,12.71,100,1,12.5,700,1,12.46,100,1,12.43,700,1,12.42,700,1,13.73,2,1,13.74,100,1,14,100,1,14.07,100,1,14.26,100,1,14.27,100,1,14.4,200,1,14.42,200,1,14.48,700,1,14.52,100,1,2,339201549
2025-07-17T16:12:58.421379924Z,2025-07-17T16:12:58.421205027Z,160,2,1108,A,A,15.670000000,100,0,339202065,128,174897,282289111,ARL,,13.11,100,1,12.98,200,1,12.92,2,1,12.86,100,1,12.73,100,1,12.71,100,1,12.5,700,1,12.46,100,1,12.43,700,1,12.42,700,1,13.73,2,1,13.74,100,1,14,100,1,14.07,100,1,14.26,100,1,14.27,100,1,14.4,200,1,14.42,200,1,14.48,700,1,14.52,100,1,2,339202065
2025-07-17T16:12:58.421423275Z,2025-07-17T16:12:58.421248082Z,160,2,1108,C,A,15.360000000,100,0,339112469,128,175193,282289154,ARL,,13.11,100,1,12.98,200,1,12.92,2,1,12.86,100,1,12.73,100,1,12.71,100,1,12.5,700,1,12.46,100,1,12.43,700,1,12.42,700,1,13.73,2,1,13.74,100,1,14,100,1,14.07,100,1,14.26,100,1,14.27,100,1,14.4,200,1,14.42,200,1,14.48,700,1,14.52,100,1,2,339112469
2025-07-17T16:12:58.421756726Z,2025-07-17T16:12:58.421581692Z,160,2,1108,C,A,14.070000000,100,0,339110909,130,175034,282289338,ARL,,13.11,100,1,12.98,200,1,12.92,2,1,12.86,100,1,12.73,100,1,12.71,100,1,12.5,700,1,12.46,100,1,12.43,700,1,12.42,700,1,13.73,2,1,13.74,100,1,14,100,1,14.26,100,1,14.27,100,1,14.4,200,1,14.42,200,1,14.48,700,1,14.52,100,1,14.54,700,1,2,339110909
2025-07-17T16:12:58.422145785Z,2025-07-17T16:12:58.421969675Z,160,2,1108,A,A,14.350000000,100,0,339202733,128,176110,282289650,ARL,,13.11,100,1,12.98,200,1,12.92,2,1,12.86,100,1,12.73,100,1,12.71,100,1,12.5,700,1,12.46,100,1,12.43,700,1,12.42,700,1,13.73,2,1,13.74,100,1,14,100,1,14.26,100,1,14.27,100,1,14.35,100,1,14.4,200,1,14.42,200,1,14.48,700,1,14.52,100,1,2,339202733
2025-07-17T16:12:58.422247877Z,2025-07-17T16:12:58.422073305Z,160,2,1108,C,A,14.520000000,100,0,339110897,0,174572,282289747,ARL,,13.11,100,1,12.98,200,1,12.92,2,1,12.86,100,1,12.73,100,1,12.71,100,1,12.5,700,1,12.46,100,1,12.43,700,1,12.42,700,1,13.73,2,1,13.74,100,1,14,100,1,14.26,100,1,14.27,100,1,14.35,100,1,14.4,200,1,14.42,200,1,14.48,700,1,14.54,700,1,2,339110897
2025-07-17T16:12:58.422247877Z,2025-07-17T16:12:58.422073305Z,160,2,1108,A,A,14.810000000,100,0,339202805,128,174572,282289747,ARL,,13.11,100,1,12.98,200,1,12.92,2,1,12.86,100,1,12.73,100,1,12.71,100,1,12.5,700,1,12.46,100,1,12.43,700,1,12.42,700,1,13.73,2,1,13.74,100,1,14,100,1,14.26,100,1,14.27,100,1,14.35,100,1,14.4,200,1,14.42,200,1,14.48,700,1,14.54,700,1,2,339202805
2025-07-17T16:12:58.424958370Z,2025-07-17T16:12:58.424789366Z,160,2,1108,C,A,14.400000000,100,0,338139585,0,169004,282290622,ARL,,13.11,100,1,12.98,200,1,12.92,2,1,12.86,100,1,12.73,100,1,12.71,100,1,12.5,700,1,12.46,100,1,12.43,700,1,12.42,700,1,13.73,2,1,13.74,100,1,14,100,1,14.26,100,1,14.27,100,1,14.35,100,1,14.4,100,1,14.42,200,1,14.48,700,1,14.54,700,1,2,338139585
2025-07-17T16:12:58.424958370Z,2025-07-17T16:12:58.424789366Z,160,2,1108,A,A,14.570000000,100,0,339203693,128,169004,282290622,ARL,,13.11,100,1,12.98,200,1,12.92,2,1,12.86,100,1,12.73,100,1,12.71,100,1,12.5,700,1,12.46,100,1,12.43,700,1,12.42,700,1,13.73,2,1,13.74,100,1,14,100,1,14.26,100,1,14.27,100,1,14.35,100,1,14.4,100,1,14.42,200,1,14.48,700,1,14.54,700,1,2,339203693
2025-07-17T16:12:58.425450176Z,2025-07-17T16:12:58.425283932Z,160,2,1108,C,A,14.400000000,100,0,338139601,0,166244,282290769,ARL,,13.11,100,1,12.98,200,1,12.92,2,1,12.86,100,1,12.73,100,1,12.71,100,1,12.5,700,1,12.46,100,1,12.43,700,1,12.42,700,1,13.73,2,1,13.74,100,1,14,100,1,14.26,100,1,14.27,100,1,14.35,100,1,14.42,200,1,14.48,700,1,14.54,700,1,14.56,700,1,2,338139601
2025-07-17T16:12:58.425450176Z,2025-07-17T16:12:58.425283932Z,160,2,1108,A,A,14.570000000,100,0,339203897,128,166244,282290769,ARL,,13.11,100,1,12.98,200,1,12.92,2,1,12.86,100,1,12.73,100,1,12.71,100,1,12.5,700,1,12.46,100,1,12.43,700,1,12.42,700,1,13.73,2,1,13.74,100,1,14,100,1,14.26,100,1,14.27,100,1,14.35,100,1,14.42,200,1,14.48,700,1,14.54,700,1,14.56,700,1,2,339203897
2025-07-17T16:12:58.426423622Z,2025-07-17T16:12:58.426258092Z,160,2,1108,C,A,14.260000000,100,0,339111189,130,165530,282290946,ARL,,13.11,100,1,12.98,200,1,12.92,2,1,12.86,100,1,12.73,100,1,12.71,100,1,12.5,700,1,12.46,100,1,12.43,700,1,12.42,700,1,13.73,2,1,13.74,100,1,14,100,1,14.27,100,1,14.35,100,1,14.42,200,1,14.48,700,1,14.54,700,1,14.56,700,1,14.57,200,1,2,339111189
2025-07-17T16:12:58.426544477Z,2025-07-17T16:12:58.426378483Z,160,2,1108,A,A,14.530000000,100,0,339204077,130,165994,282290959,ARL,,13.11,100,1,12.98,200,1,12.92,2,1,12.86,100,1,12.73,100,1,12.71,100,1,12.5,700,1,12.46,100,1,12.43,700,1,12.42,700,1,13.73,2,1,13.74,100,1,14,100,1,14.27,100,1,14.35,100,1,14.42,200,1,14.48,700,1,14.53,100,1,14.54,700,1,14.56,700,1,2,339204077
2025-07-17T16:12:58.430830694Z,2025-07-17T16:12:58.430665639Z,160,2,1108,C,A,13.740000000,100,0,339111029,130,165055,282291933,ARL,,13.11,100,1,12.98,200,1,12.92,2,1,12.86,100,1,12.73,100,1,12.71,100,1,12.5,700,1,12.46,100,1,12.43,700,1,12.42,700,1,13.73,2,1,14,100,1,14.27,100,1,14.35,100,1,14.42,200,1,14.48,700,1,14.53,100,1,14.54,700,1,14.56,700,1,14.57,200,1,2,339111029
2025-07-17T16:12:58.430888526Z,2025-07-17T16:12:58.430720526Z,160,2,1108,A,A,14.010000000,100,0,339205213,128,168000,282291946,ARL,,13.11,100,1,12.98,200,1,12.92,2,1,12.86,100,1,12.73,100,1,12.71,100,1,12.5,700,1,12.46,100,1,12.43,700,1,12.42,700,1,13.73,2,1,14,100,1,14.01,100,1,14.27,100,1,14.35,100,1,14.42,200,1,14.48,700,1,14.53,100,1,14.54,700,1,14.56,700,1,2,339205213
2025-07-17T16:12:58.432901795Z,2025-07-17T16:12:58.432736189Z,160,2,1108,C,A,14.820000000,100,0,339111005,0,165606,282292390,ARL,,13.11,100,1,12.98,200,1,12.92,2,1,12.86,100,1,12.73,100,1,12.71,100,1,12.5,700,1,12.46,100,1,12.43,700,1,12.42,700,1,13.73,2,1,14,100,1,14.01,100,1,14.27,100,1,14.35,100,1,14.42,200,1,14.48,700,1,14.53,100,1,14.54,700,1,14.56,700,1,2,339111005
2025-07-17T16:12:58.432901795Z,2025-07-17T16:12:58.432736189Z,160,2,1108,A,A,15.380000000,100,0,339206141,130,165606,282292390,ARL,,13.11,100,1,12.98,200,1,12.92,2,1,12.86,100,1,12.73,100,1,12.71,100,1,12.5,700,1,12.46,100,1,12.43,700,1,12.42,700,1,13.73,2,1,14,100,1,14.01,100,1,14.27,100,1,14.35,100,1,14.42,200,1,14.48,700,1,14.53,100,1,14.54,700,1,14.56,700,1,2,339206141
2025-07-17T16:12:58.438073339Z,2025-07-17T16:12:58.437907652Z,160,2,1108,C,B,12.920000000,2,0,338044113,0,165687,282292938,ARL,,13.11,100,1,12.98,200,1,12.86,100,1,12.73,100,1,12.71,100,1,12.5,700,1,12.46,100,1,12.43,700,1,12.42,700,1,12.37,700,1,13.73,2,1,14,100,1,14.01,100,1,14.27,100,1,14.35,100,1,14.42,200,1,14.48,700,1,14.53,100,1,14.54,700,1,14.56,700,1,2,338044113
2025-07-17T16:12:58.438073339Z,2025-07-17T16:12:58.437907652Z,160,2,1108,A,B,13.020000000,2,0,339207125,130,165687,282292938,ARL,,13.11,100,1,13.02,2,1,12.98,200,1,12.86,100,1,12.73,100,1,12.71,100,1,12.5,700,1,12.46,100,1,12.43,700,1,12.42,700,1,13.73,2,1,14,100,1,14.01,100,1,14.27,100,1,14.35,100,1,14.42,200,1,14.48,700,1,14.53,100,1,14.54,700,1,14.56,700,1,2,339207125
2025-07-17T16:12:58.438076762Z,2025-07-17T16:12:58.437911392Z,160,2,1108,C,A,13.730000000,2,0,339110993,0,165370,282292939,ARL,,13.11,100,1,13.02,2,1,12.98,200,1,12.86,100,1,12.73,100,1,12.71,100,1,12.5,700,1,12.46,100,1,12.43,700,1,12.42,700,1,14,100,1,14.01,100,1,14.27,100,1,14.35,100,1,14.42,200,1,14.48,700,1,14.53,100,1,14.54,700,1,14.56,700,1,14.57,200,1,2,339110993
2025-07-17T16:12:58.438076762Z,2025-07-17T16:12:58.437911392Z,160,2,1108,A,A,13.980000000,2,0,339207129,130,165370,282292939,ARL,,13.11,100,1,13.02,2,1,12.98,200,1,12.86,100,1,12.73,100,1,12.71,100,1,12.5,700,1,12.46,100,1,12.43,700,1,12.42,700,1,13.98,2,1,14,100,1,14.01,100,1,14.27,100,1,14.35,100,1,14.42,200,1,14.48,700,1,14.53,100,1,14.54,700,1,14.56,700,1,2,339207129
2025-07-17T16:12:58.438843944Z,2025-07-17T16:12:58.438678961Z,160,2,1108,C,A,14.010000000,100,0,339205213,130,164983,282293023,ARL,,13.11,100,1,13.02,2,1,12.98,200,1,12.86,100,1,12.73,100,1,12.71,100,1,12.5,700,1,12.46,100,1,12.43,700,1,12.42,700,1,13.98,2,1,14,100,1,14.27,100,1,14.35,100,1,14.42,200,1,14.48,700,1,14.53,100,1,14.54,700,1,14.56,700,1,14.57,200,1,2,339205213
2025-07-17T16:12:58.438894336Z,2025-07-17T16:12:58.438728994Z,160,2,1108,A,A,14.240000000,100,0,339207197,130,165342,282293026,ARL,,13.11,100,1,13.02,2,1,12.98,200,1,12.86,100,1,12.73,100,1,12.71,100,1,12.5,700,1,12.46,100,1,12.43,700,1,12.42,700,1,13.98,2,1,14,100,1,14.24,100,1,14.27,100,1,14.35,100,1,14.42,200,1,14.48,700,1,14.53,100,1,14.54,700,1,14.56,700,1,2,339207197
2025-07-17T16:12:58.441834497Z,2025-07-17T16:12:58.441669159Z,160,2,1108,C,A,14.420000000,100,0,339110981,0,165338,282293191,ARL,,13.11,100,1,13.02,2,1,12.98,200,1,12.86,100,1,12.73,100,1,12.71,100,1,12.5,700,1,12.46,100,1,12.43,700,1,12.42,700,1,13.98,2,1,14,100,1,14.24,100,1,14.27,100,1,14.35,100,1,14.42,100,1,14.48,700,1,14.53,100,1,14.54,700,1,14.56,700,1,2,339110981
2025-07-17T16:12:58.441834497Z,2025-07-17T16:12:58.441669159Z,160,2,1108,A,A,14.960000000,100,0,339207505,130,165338,282293191,ARL,,13.11,100,1,13.02,2,1,12.98,200,1,12.86,100,1,12.73,100,1,12.71,100,1,12.5,700,1,12.46,100,1,12.43,700,1,12.42,700,1,13.98,2,1,14,100,1,14.24,100,1,14.27,100,1,14.35,100,1,14.42,100,1,14.48,700,1,14.53,100,1,14.54,700,1,14.56,700,1,2,339207505
2025-07-17T16:12:58.454376675Z,2025-07-17T16:12:58.454211242Z,160,2,1108,C,A,17.110000000,100,0,339111097,0,165433,282293811,ARL,,13.11,100,1,13.02,2,1,12.98,200,1,12.86,100,1,12.73,100,1,12.71,100,1,12.5,700,1,12.46,100,1,12.43,700,1,12.42,700,1,13.98,2,1,14,100,1,14.24,100,1,14.27,100,1,14.35,100,1,14.42,100,1,14.48,700,1,14.53,100,1,14.54,700,1,14.56,700,1,2,339111097
2025-07-17T16:12:58.454376675Z,2025-07-17T16:12:58.454211242Z,160,2,1108,A,A,17.760000000,100,0,339208377,130,165433,282293811,ARL,,13.11,100,1,13.02,2,1,12.98,200,1,12.86,100,1,12.73,100,1,12.71,100,1,12.5,700,1,12.46,100,1,12.43,700,1,12.42,700,1,13.98,2,1,14,100,1,14.24,100,1,14.27,100,1,14.35,100,1,14.42,100,1,14.48,700,1,14.53,100,1,14.54,700,1,14.56,700,1,2,339208377
2025-07-17T16:12:58.472292476Z,2025-07-17T16:12:58.472126777Z,160,2,1108,C,A,15.500000000,100,0,339111149,0,165699,282294411,ARL,,13.11,100,1,13.02,2,1,12.98,200,1,12.86,100,1,12.73,100,1,12.71,100,1,12.5,700,1,12.46,100,1,12.43,700,1,12.42,700,1,13.98,2,1,14,100,1,14.24,100,1,14.27,100,1,14.35,100,1,14.42,100,1,14.48,700,1,14.53,100,1,14.54,700,1,14.56,700,1,2,339111149
2025-07-17T16:12:58.472292476Z,2025-07-17T16:12:58.472126777Z,160,2,1108,A,A,16.080000000,100,0,339209241,130,165699,282294411,ARL,,13.11,100,1,13.02,2,1,12.98,200,1,12.86,100,1,12.73,100,1,12.71,100,1,12.5,700,1,12.46,100,1,12.43,700,1,12.42,700,1,13.98,2,1,14,100,1,14.24,100,1,14.27,100,1,14.35,100,1,14.42,100,1,14.48,700,1,14.53,100,1,14.54,700,1,14.56,700,1,2,339209241
2025-07-17T16:12:58.472624779Z,2025-07-17T16:12:58.472458830Z,160,2,1108,C,A,14.810000000,100,0,339202805,0,165949,282294423,ARL,,13.11,100,1,13.02,2,1,12.98,200,1,12.86,100,1,12.73,100,1,12.71,100,1,12.5,700,1,12.46,100,1,12.43,700,1,12.42,700,1,13.98,2,1,14,100,1,14.24,100,1,14.27,100,1,14.35,100,1,14.42,100,1,14.48,700,1,14.53,100,1,14.54,700,1,14.56,700,1,2,339202805
2025-07-17T16:12:58.472624779Z,2025-07-17T16:12:58.472458830Z,160,2,1108,A,A,15.040000000,100,0,339209257,130,165949,282294423,ARL,,13.11,100,1,13.02,2,1,12.98,200,1,12.86,100,1,12.73,100,1,12.71,100,1,12.5,700,1,12.46,100,1,12.43,700,1,12.42,700,1,13.98,2,1,14,100,1,14.24,100,1,14.27,100,1,14.35,100,1,14.42,100,1,14.48,700,1,14.53,100,1,14.54,700,1,14.56,700,1,2,339209257
2025-07-17T16:12:58.571845708Z,2025-07-17T16:12:58.571679985Z,160,2,1108,C,A,14.820000000,100,0,339112981,0,165723,282298942,ARL,,13.11,100,1,13.02,2,1,12.98,200,1,12.86,100,1,12.73,100,1,12.71,100,1,12.5,700,1,12.46,100,1,12.43,700,1,12.42,700,1,13.98,2,1,14,100,1,14.24,100,1,14.27,100,1,14.35,100,1,14.42,100,1,14.48,700,1,14.53,100,1,14.54,700,1,14.56,700,1,2,339112981
2025-07-17T16:12:58.571845708Z,2025-07-17T16:12:58.571679985Z,160,2,1108,A,A,15.380000000,100,0,339215205,130,165723,282298942,ARL,,13.11,100,1,13.02,2,1,12.98,200,1,12.86,100,1,12.73,100,1,12.71,100,1,12.5,700,1,12.46,100,1,12.43,700,1,12.42,700,1,13.98,2,1,14,100,1,14.24,100,1,14.27,100,1,14.35,100,1,14.42,100,1,14.48,700,1,14.53,100,1,14.54,700,1,14.56,700,1,2,339215205
2025-07-17T16:12:58.619404102Z,2025-07-17T16:12:58.619238614Z,160,2,1108,C,A,14.420000000,100,0,339112945,0,165488,282299781,ARL,,13.11,100,1,13.02,2,1,12.98,200,1,12.86,100,1,12.73,100,1,12.71,100,1,12.5,700,1,12.46,100,1,12.43,700,1,12.42,700,1,13.98,2,1,14,100,1,14.24,100,1,14.27,100,1,14.35,100,1,14.48,700,1,14.53,100,1,14.54,700,1,14.56,700,1,14.57,200,1,2,339112945
2025-07-17T16:12:58.619404102Z,2025-07-17T16:12:58.619238614Z,160,2,1108,A,A,14.960000000,100,0,339216161,130,165488,282299781,ARL,,13.11,100,1,13.02,2,1,12.98,200,1,12.86,100,1,12.73,100,1,12.71,100,1,12.5,700,1,12.46,100,1,12.43,700,1,12.42,700,1,13.98,2,1,14,100,1,14.24,100,1,14.27,100,1,14.35,100,1,14.48,700,1,14.53,100,1,14.54,700,1,14.56,700,1,14.57,200,1,2,339216161
2025-07-17T16:12:58.986093948Z,2025-07-17T16:12:58.985928594Z,160,2,1108,C,B,13.020000000,2,0,339207125,0,165354,282305386,ARL,,13.11,100,1,12.98,200,1,12.86,100,1,12.73,100,1,12.71,100,1,12.5,700,1,12.46,100,1,12.43,700,1,12.42,700,1,12.37,700,1,13.98,2,1,14,100,1,14.24,100,1,14.27,100,1,14.35,100,1,14.48,700,1,14.53,100,1,14.54,700,1,14.56,700,1,14.57,200,1,2,339207125
2025-07-17T16:12:58.986093948Z,2025-07-17T16:12:58.985928594Z,160,2,1108,A,B,12.860000000,2,0,339222617,130,165354,282305386,ARL,,13.11,100,1,12.98,200,1,12.86,102,1,12.73,100,1,12.71,100,1,12.5,700,1,12.46,100,1,12.43,700,1,12.42,700,1,12.37,700,1,13.98,2,1,14,100,1,14.24,100,1,14.27,100,1,14.35,100,1,14.48,700,1,14.53,100,1,14.54,700,1,14.56,700,1,14.57,200,1,2,339222617
2025-07-17T16:12:59.063108412Z,2025-07-17T16:12:59.062943193Z,160,2,1108,A,A,13.990000000,100,0,339224109,130,165219,282306400,ARL,,13.11,100,1,12.98,200,1,12.86,102,1,12.73,100,1,12.71,100,1,12.5,700,1,12.46,100,1,12.43,700,1,12.42,700,1,12.37,700,1,13.98,2,1,13.99,100,1,14,100,1,14.24,100,1,14.27,100,1,14.35,100,1,14.48,700,1,14.53,100,1,14.54,700,1,14.56,700,1,2,339224109
2025-07-17T16:12:59.082855570Z,2025-07-17T16:12:59.082690430Z,160,2,1108,C,A,14.000000000,100,0,339133353,130,165140,282307908,ARL,,13.11,100,1,12.98,200,1,12.86,102,1,12.73,100,1,12.71,100,1,12.5,700,1,12.46,100,1,12.43,700,1,12.42,700,1,12.37,700,1,13.98,2,1,13.99,100,1,14.24,100,1,14.27,100,1,14.35,100,1,14.48,700,1,14.53,100,1,14.54,700,1,14.56,700,1,14.57,200,1,2,339133353
2025-07-17T16:12:59.082856640Z,2025-07-17T16:12:59.082691385Z,160,2,1108,A,A,14.530000000,100,0,339225769,130,165255,282307909,ARL,,13.11,100,1,12.98,200,1,12.86,102,1,12.73,100,1,12.71,100,1,12.5,700,1,12.46,100,1,12.43,700,1,12.42,700,1,12.37,700,1,13.98,2,1,13.99,100,1,14.24,100,1,14.27,100,1,14.35,100,1,14.48,700,1,14.53,200,1,14.54,700,1,14.56,700,1,14.57,200,1,2,339225769
2025-07-17T16:12:59.088794570Z,2025-07-17T16:12:59.088629294Z,160,2,1108,A,A,14.810000000,100,0,339225885,130,165276,282308093,ARL,,13.11,100,1,12.98,200,1,12.86,102,1,12.73,100,1,12.71,100,1,12.5,700,1,12.46,100,1,12.43,700,1,12.42,700,1,12.37,700,1,13.98,2,1,13.99,100,1,14.24,100,1,14.27,100,1,14.35,100,1,14.48,700,1,14.53,200,1,14.54,700,1,14.56,700,1,14.57,200,1,2,339225885
2025-07-17T16:12:59.088808117Z,2025-07-17T16:12:59.088642718Z,160,2,1108,C,A,14.270000000,100,0,339126221,130,165399,282308094,ARL,,13.11,100,1,12.98,200,1,12.86,102,1,12.73,100,1,12.71,100,1,12.5,700,1,12.46,100,1,12.43,700,1,12.42,700,1,12.37,700,1,13.98,2,1,13.99,100,1,14.24,100,1,14.35,100,1,14.48,700,1,14.53,200,1,14.54,700,1,14.56,700,1,14.57,200,1,14.68,700,1,2,339126221
2025-07-17T16:12:59.092927842Z,2025-07-17T16:12:59.092762564Z,160,2,1108,C,A,14.350000000,100,0,339202733,130,165278,282308154,ARL,,13.11,100,1,12.98,200,1,12.86,102,1,12.73,100,1,12.71,100,1,12.5,700,1,12.46,100,1,12.43,700,1,12.42,700,1,12.37,700,1,13.98,2,1,13.99,100,1,14.24,100,1,14.48,700,1,14.53,200,1,14.54,700,1,14.56,700,1,14.57,200,1,14.68,700,1,14.81,100,1,2,339202733
2025-07-17T16:12:59.093278915Z,2025-07-17T16:12:59.093113488Z,160,2,1108,A,A,14.600000000,100,0,339226021,130,165427,282308163,ARL,,13.11,100,1,12.98,200,1,12.86,102,1,12.73,100,1,12.71,100,1,12.5,700,1,12.46,100,1,12.43,700,1,12.42,700,1,12.37,700,1,13.98,2,1,13.99,100,1,14.24,100,1,14.48,700,1,14.53,200,1,14.54,700,1,14.56,700,1,14.57,200,1,14.6,100,1,14.68,700,1,2,339226021
2025-07-17T16:12:59.430486012Z,2025-07-17T16:12:59.430320610Z,160,2,1108,C,A,14.530000000,100,0,339204077,0,165402,282313368,ARL,,13.11,100,1,12.98,200,1,12.86,102,1,12.73,100,1,12.71,100,1,12.5,700,1,12.46,100,1,12.43,700,1,12.42,700,1,12.37,700,1,13.98,2,1,13.99,100,1,14.24,100,1,14.48,700,1,14.53,100,1,14.54,700,1,14.56,700,1,14.57,200,1,14.6,100,1,14.68,700,1,2,339204077
2025-07-17T16:12:59.430486012Z,2025-07-17T16:12:59.430320610Z,160,2,1108,A,A,14.770000000,100,0,339232213,130,165402,282313368,ARL,,13.11,100,1,12.98,200,1,12.86,102,1,12.73,100,1,12.71,100,1,12.5,700,1,12.46,100,1,12.43,700,1,12.42,700,1,12.37,700,1,13.98,2,1,13.99,100,1,14.24,100,1,14.48,700,1,14.53,100,1,14.54,700,1,14.56,700,1,14.57,200,1,14.6,100,1,14.68,700,1,2,339232213
2025-07-17T16:13:04.825902166Z,2025-07-17T16:13:04.825736034Z,160,2,1108,A,A,13.660000000,15,0,339332865,128,166132,282392593,ARL,,13.11,100,1,12.98,200,1,12.86,102,1,12.73,100,1,12.71,100,1,12.5,700,1,12.46,100,1,12.43,700,1,12.42,700,1,12.37,700,1,13.66,15,1,13.98,2,1,13.99,100,1,14.24,100,1,14.48,700,1,14.53,100,1,14.54,700,1,14.56,700,1,14.57,200,1,14.6,100,1,2,339332865
2025-07-17T16:13:06.189275812Z,2025-07-17T16:13:06.189110140Z,160,2,1108,C,B,12.860000000,2,0,339222617,0,165672,282411935,ARL,,13.11,100,1,12.98,200,1,12.86,100,1,12.73,100,1,12.71,100,1,12.5,700,1,12.46,100,1,12.43,700,1,12.42,700,1,12.37,700,1,13.66,15,1,13.98,2,1,13.99,100,1,14.24,100,1,14.48,700,1,14.53,100,1,14.54,700,1,14.56,700,1,14.57,200,1,14.6,100,1,2,339222617
2025-07-17T16:13:06.189275812Z,2025-07-17T16:13:06.189110140Z,160,2,1108,A,B,12.960000000,2,0,339356397,130,165672,282411935,ARL,,13.11,100,1,12.98,200,1,12.96,2,1,12.86,100,1,12.73,100,1,12.71,100,1,12.5,700,1,12.46,100,1,12.43,700,1,12.42,700,1,13.66,15,1,13.98,2,1,13.99,100,1,14.24,100,1,14.48,700,1,14.53,100,1,14.54,700,1,14.56,700,1,14.57,200,1,14.6,100,1,2,339356397
2025-07-17T16:13:06.224898389Z,2025-07-17T16:13:06.224732787Z,160,2,1108,C,A,13.990000000,100,0,339224109,0,165602,282413599,ARL,,13.11,100,1,12.98,200,1,12.96,2,1,12.86,100,1,12.73,100,1,12.71,100,1,12.5,700,1,12.46,100,1,12.43,700,1,12.42,700,1,13.66,15,1,13.98,2,1,14.24,100,1,14.48,700,1,14.53,100,1,14.54,700,1,14.56,700,1,14.57,200,1,14.6,100,1,14.68,700,1,2,339224109
2025-07-17T16:13:06.224898389Z,2025-07-17T16:13:06.224732787Z,160,2,1108,A,A,13.670000000,100,0,339358233,130,165602,282413599,ARL,,13.11,100,1,12.98,200,1,12.96,2,1,12.86,100,1,12.73,100,1,12.71,100,1,12.5,700,1,12.46,100,1,12.43,700,1,12.42,700,1,13.66,15,1,13.67,100,1,13.98,2,1,14.24,100,1,14.48,700,1,14.53,100,1,14.54,700,1,14.56,700,1,14.57,200,1,14.6,100,1,2,339358233
2025-07-17T16:13:06.225642781Z,2025-07-17T16:13:06.225475518Z,160,2,1108,C,A,15.040000000,100,0,339209257,0,167263,282413677,ARL,,13.11,100,1,12.98,200,1,12.96,2,1,12.86,100,1,12.73,100,1,12.71,100,1,12.5,700,1,12.46,100,1,12.43,700,1,12.42,700,1,13.66,15,1,13.67,100,1,13.98,2,1,14.24,100,1,14.48,700,1,14.53,100,1,14.54,700,1,14.56,700,1,14.57,200,1,14.6,100,1,2,339209257
2025-07-17T16:13:06.225642781Z,2025-07-17T16:13:06.225475518Z,160,2,1108,A,A,14.730000000,100,0,339358293,0,167263,282413677,ARL,,13.11,100,1,12.98,200,1,12.96,2,1,12.86,100,1,12.73,100,1,12.71,100,1,12.5,700,1,12.46,100,1,12.43,700,1,12.42,700,1,13.66,15,1,13.67,100,1,13.98,2,1,14.24,100,1,14.48,700,1,14.53,100,1,14.54,700,1,14.56,700,1,14.57,200,1,14.6,100,1,2,339358293
2025-07-17T16:13:06.225642781Z,2025-07-17T16:13:06.225475906Z,160,2,1108,C,A,14.600000000,100,0,339226021,128,166875,282413678,ARL,,13.11,100,1,12.98,200,1,12.96,2,1,12.86,100,1,12.73,100,1,12.71,100,1,12.5,700,1,12.46,100,1,12.43,700,1,12.42,700,1,13.66,15,1,13.67,100,1,13.98,2,1,14.24,100,1,14.48,700,1,14.53,100,1,14.54,700,1,14.56,700,1,14.57,200,1,14.68,700,1,2,339226021
2025-07-17T16:13:06.225995297Z,2025-07-17T16:13:06.225829921Z,160,2,1108,A,A,14.280000000,100,0,339358333,130,165376,282413699,ARL,,13.11,100,1,12.98,200,1,12.96,2,1,12.86,100,1,12.73,100,1,12.71,100,1,12.5,700,1,12.46,100,1,12.43,700,1,12.42,700,1,13.66,15,1,13.67,100,1,13.98,2,1,14.24,100,1,14.28,100,1,14.48,700,1,14.53,100,1,14.54,700,1,14.56,700,1,14.57,200,1,2,339358333
2025-07-17T16:13:06.226789913Z,2025-07-17T16:13:06.226624084Z,160,2,1108,C,A,15.380000000,100,0,339206141,0,165829,282413738,ARL,,13.11,100,1,12.98,200,1,12.96,2,1,12.86,100,1,12.73,100,1,12.71,100,1,12.5,700,1,12.46,100,1,12.43,700,1,12.42,700,1,13.66,15,1,13.67,100,1,13.98,2,1,14.24,100,1,14.28,100,1,14.48,700,1,14.53,100,1,14.54,700,1,14.56,700,1,14.57,200,1,2,339206141
2025-07-17T16:13:06.226789913Z,2025-07-17T16:13:06.226624084Z,160,2,1108,A,A,15.040000000,100,0,339358349,130,165829,282413738,ARL,,13.11,100,1,12.98,200,1,12.96,2,1,12.86,100,1,12.73,100,1,12.71,100,1,12.5,700,1,12.46,100,1,12.43,700,1,12.42,700,1,13.66,15,1,13.67,100,1,13.98,2,1,14.24,100,1,14.28,100,1,14.48,700,1,14.53,100,1,14.54,700,1,14.56,700,1,14.57,200,1,2,339358349
2025-07-17T16:13:06.226882302Z,2025-07-17T16:13:06.226716697Z,160,2,1108,C,A,14.960000000,100,0,339207505,0,165605,282413745,ARL,,13.11,100,1,12.98,200,1,12.96,2,1,12.86,100,1,12.73,100,1,12.71,100,1,12.5,700,1,12.46,100,1,12.43,700,1,12.42,700,1,13.66,15,1,13.67,100,1,13.98,2,1,14.24,100,1,14.28,100,1,14.48,700,1,14.53,100,1,14.54,700,1,14.56,700,1,14.57,200,1,2,339207505
2025-07-17T16:13:06.226882302Z,2025-07-17T16:13:06.226716697Z,160,2,1108,A,A,14.630000000,100,0,339358353,130,165605,282413745,ARL,,13.11,100,1,12.98,200,1,12.96,2,1,12.86,100,1,12.73,100,1,12.71,100,1,12.5,700,1,12.46,100,1,12.43,700,1,12.42,700,1,13.66,15,1,13.67,100,1,13.98,2,1,14.24,100,1,14.28,100,1,14.48,700,1,14.53,100,1,14.54,700,1,14.56,700,1,14.57,200,1,2,339358353
2025-07-17T16:13:06.229858538Z,2025-07-17T16:13:06.229693020Z,160,2,1108,C,A,13.980000000,2,0,339207129,0,165518,282413801,ARL,,13.11,100,1,12.98,200,1,12.96,2,1,12.86,100,1,12.73,100,1,12.71,100,1,12.5,700,1,12.46,100,1,12.43,700,1,12.42,700,1,13.66,15,1,13.67,100,1,14.24,100,1,14.28,100,1,14.48,700,1,14.53,100,1,14.54,700,1,14.56,700,1,14.57,200,1,14.63,100,1,2,339207129
2025-07-17T16:13:06.229858538Z,2025-07-17T16:13:06.229693020Z,160,2,1108,A,A,13.810000000,2,0,339358409,130,165518,282413801,ARL,,13.11,100,1,12.98,200,1,12.96,2,1,12.86,100,1,12.73,100,1,12.71,100,1,12.5,700,1,12.46,100,1,12.43,700,1,12.42,700,1,13.66,15,1,13.67,100,1,13.81,2,1,14.24,100,1,14.28,100,1,14.48,700,1,14.53,100,1,14.54,700,1,14.56,700,1,14.57,200,1,2,339358409
2025-07-17T16:13:06.235594115Z,2025-07-17T16:13:06.235428434Z,160,2,1108,C,A,17.760000000,100,0,339208377,0,165681,282414050,ARL,,13.11,100,1,12.98,200,1,12.96,2,1,12.86,100,1,12.73,100,1,12.71,100,1,12.5,700,1,12.46,100,1,12.43,700,1,12.42,700,1,13.66,15,1,13.67,100,1,13.81,2,1,14.24,100,1,14.28,100,1,14.48,700,1,14.53,100,1,14.54,700,1,14.56,700,1,14.57,200,1,2,339208377
2025-07-17T16:13:06.235594115Z,2025-07-17T16:13:06.235428434Z,160,2,1108,A,A,17.370000000,100,0,339358609,130,165681,282414050,ARL,,13.11,100,1,12.98,200,1,12.96,2,1,12.86,100,1,12.73,100,1,12.71,100,1,12.5,700,1,12.46,100,1,12.43,700,1,12.42,700,1,13.66,15,1,13.67,100,1,13.81,2,1,14.24,100,1,14.28,100,1,14.48,700,1,14.53,100,1,14.54,700,1,14.56,700,1,14.57,200,1,2,339358609
2025-07-17T16:13:06.236567790Z,2025-07-17T16:13:06.236401579Z,160,2,1108,C,A,14.240000000,100,0,339207197,130,166211,282414131,ARL,,13.11,100,1,12.98,200,1,12.96,2,1,12.86,100,1,12.73,100,1,12.71,100,1,12.5,700,1,12.46,100,1,12.43,700,1,12.42,700,1,13.66,15,1,13.67,100,1,13.81,2,1,14.28,100,1,14.48,700,1,14.53,100,1,14.54,700,1,14.56,700,1,14.57,200,1,14.63,100,1,2,339207197
2025-07-17T16:13:06.236621535Z,2025-07-17T16:13:06.236456489Z,160,2,1108,A,A,13.940000000,100,0,339358741,130,165046,282414141,ARL,,13.11,100,1,12.98,200,1,12.96,2,1,12.86,100,1,12.73,100,1,12.71,100,1,12.5,700,1,12.46,100,1,12.43,700,1,12.42,700,1,13.66,15,1,13.67,100,1,13.81,2,1,13.94,100,1,14.28,100,1,14.48,700,1,14.53,100,1,14.54,700,1,14.56,700,1,14.57,200,1,2,339358741
2025-07-17T16:13:06.243909112Z,2025-07-17T16:13:06.243743642Z,160,2,1108,C,A,16.080000000,100,0,339209241,0,165470,282414340,ARL,,13.11,100,1,12.98,200,1,12.96,2,1,12.86,100,1,12.73,100,1,12.71,100,1,12.5,700,1,12.46,100,1,12.43,700,1,12.42,700,1,13.66,15,1,13.67,100,1,13.81,2,1,13.94,100,1,14.28,100,1,14.48,700,1,14.53,100,1,14.54,700,1,14.56,700,1,14.57,200,1,2,339209241
2025-07-17T16:13:06.243909112Z,2025-07-17T16:13:06.243743642Z,160,2,1108,A,A,15.730000000,100,0,339359077,130,165470,282414340,ARL,,13.11,100,1,12.98,200,1,12.96,2,1,12.86,100,1,12.73,100,1,12.71,100,1,12.5,700,1,12.46,100,1,12.43,700,1,12.42,700,1,13.66,15,1,13.67,100,1,13.81,2,1,13.94,100,1,14.28,100,1,14.48,700,1,14.53,100,1,14.54,700,1,14.56,700,1,14.57,200,1,2,339359077
2025-07-17T16:13:06.268052093Z,2025-07-17T16:13:06.267886189Z,160,2,1108,C,A,15.380000000,100,0,339215205,0,165904,282414570,ARL,,13.11,100,1,12.98,200,1,12.96,2,1,12.86,100,1,12.73,100,1,12.71,100,1,12.5,700,1,12.46,100,1,12.43,700,1,12.42,700,1,13.66,15,1,13.67,100,1,13.81,2,1,13.94,100,1,14.28,100,1,14.48,700,1,14.53,100,1,14.54,700,1,14.56,700,1,14.57,200,1,2,339215205
2025-07-17T16:13:06.268052093Z,2025-07-17T16:13:06.267886189Z,160,2,1108,A,A,15.040000000,100,0,339359357,130,165904,282414570,ARL,,13.11,100,1,12.98,200,1,12.96,2,1,12.86,100,1,12.73,100,1,12.71,100,1,12.5,700,1,12.46,100,1,12.43,700,1,12.42,700,1,13.66,15,1,13.67,100,1,13.81,2,1,13.94,100,1,14.28,100,1,14.48,700,1,14.53,100,1,14.54,700,1,14.56,700,1,14.57,200,1,2,339359357
2025-07-17T16:13:06.275886461Z,2025-07-17T16:13:06.275720866Z,160,2,1108,C,A,14.960000000,100,0,339216161,0,165595,282414642,ARL,,13.11,100,1,12.98,200,1,12.96,2,1,12.86,100,1,12.73,100,1,12.71,100,1,12.5,700,1,12.46,100,1,12.43,700,1,12.42,700,1,13.66,15,1,13.67,100,1,13.81,2,1,13.94,100,1,14.28,100,1,14.48,700,1,14.53,100,1,14.54,700,1,14.56,700,1,14.57,200,1,2,339216161
2025-07-17T16:13:06.275886461Z,2025-07-17T16:13:06.275720866Z,160,2,1108,A,A,14.630000000,100,0,339359401,130,165595,282414642,ARL,,13.11,100,1,12.98,200,1,12.96,2,1,12.86,100,1,12.73,100,1,12.71,100,1,12.5,700,1,12.46,100,1,12.43,700,1,12.42,700,1,13.66,15,1,13.67,100,1,13.81,2,1,13.94,100,1,14.28,100,1,14.48,700,1,14.53,100,1,14.54,700,1,14.56,700,1,14.57,200,1,2,339359401
2025-07-17T16:13:06.277048260Z,2025-07-17T16:13:06.276882863Z,160,2,1108,C,A,14.770000000,100,0,339232213,130,165397,282414659,ARL,,13.11,100,1,12.98,200,1,12.96,2,1,12.86,100,1,12.73,100,1,12.71,100,1,12.5,700,1,12.46,100,1,12.43,700,1,12.42,700,1,13.66,15,1,13.67,100,1,13.81,2,1,13.94,100,1,14.28,100,1,14.48,700,1,14.53,100,1,14.54,700,1,14.56,700,1,14.57,200,1,2,339232213
2025-07-17T16:13:06.277178914Z,2025-07-17T16:13:06.277013512Z,160,2,1108,A,A,14.460000000,100,0,339359421,130,165402,282414660,ARL,,13.11,100,1,12.98,200,1,12.96,2,1,12.86,100,1,12.73,100,1,12.71,100,1,12.5,700,1,12.46,100,1,12.43,700,1,12.42,700,1,13.66,15,1,13.67,100,1,13.81,2,1,13.94,100,1,14.28,100,1,14.46,100,1,14.48,700,1,14.53,100,1,14.54,700,1,14.56,700,1,2,339359421
2025-07-17T16:13:06.622659102Z,2025-07-17T16:13:06.622493734Z,160,2,1108,A,A,14.220000000,100,0,339365193,130,165368,282418746,ARL,,13.11,100,1,12.98,200,1,12.96,2,1,12.86,100,1,12.73,100,1,12.71,100,1,12.5,700,1,12.46,100,1,12.43,700,1,12.42,700,1,13.66,15,1,13.67,100,1,13.81,2,1,13.94,100,1,14.22,100,1,14.28,100,1,14.46,100,1,14.48,700,1,14.53,100,1,14.54,700,1,2,339365193
2025-07-17T16:13:06.663836744Z,2025-07-17T16:13:06.663671305Z,160,2,1108,C,A,14.530000000,100,0,339225769,130,165439,282418921,ARL,,13.11,100,1,12.98,200,1,12.96,2,1,12.86,100,1,12.73,100,1,12.71,100,1,12.5,700,1,12.46,100,1,12.43,700,1,12.42,700,1,13.66,15,1,13.67,100,1,13.81,2,1,13.94,100,1,14.22,100,1,14.28,100,1,14.46,100,1,14.48,700,1,14.54,700,1,14.56,700,1,2,339225769
2025-07-17T16:13:06.759791103Z,2025-07-17T16:13:06.759625628Z,160,2,1108,A,A,14.490000000,100,0,339366385,130,165475,282419471,ARL,,13.11,100,1,12.98,200,1,12.96,2,1,12.86,100,1,12.73,100,1,12.71,100,1,12.5,700,1,12.46,100,1,12.43,700,1,12.42,700,1,13.66,15,1,13.67,100,1,13.81,2,1,13.94,100,1,14.22,100,1,14.28,100,1,14.46,100,1,14.48,700,1,14.49,100,1,14.54,700,1,2,339366385
2025-07-17T16:13:06.759804641Z,2025-07-17T16:13:06.759638890Z,160,2,1108,C,A,14.810000000,100,0,339225885,130,165751,282419472,ARL,,13.11,100,1,12.98,200,1,12.96,2,1,12.86,100,1,12.73,100,1,12.71,100,1,12.5,700,1,12.46,100,1,12.43,700,1,12.42,700,1,13.66,15,1,13.67,100,1,13.81,2,1,13.94,100,1,14.22,100,1,14.28,100,1,14.46,100,1,14.48,700,1,14.49,100,1,14.54,700,1,2,339225885
2025-07-17T16:13:09.354048740Z,2025-07-17T16:13:09.353883614Z,160,2,1108,A,A,13.640000000,15,0,339425837,130,165126,282469242,ARL,,13.11,100,1,12.98,200,1,12.96,2,1,12.86,100,1,12.73,100,1,12.71,100,1,12.5,700,1,12.46,100,1,12.43,700,1,12.42,700,1,13.64,15,1,13.66,15,1,13.67,100,1,13.81,2,1,13.94,100,1,14.22,100,1,14.28,100,1,14.46,100,1,14.48,700,1,14.49,100,1,2,339425837
2025-07-17T16:13:09.368197659Z,2025-07-17T16:13:09.368030843Z,160,2,1108,C,A,13.670000000,100,0,339358233,0,166816,282470466,ARL,,13.11,100,1,12.98,200,1,12.96,2,1,12.86,100,1,12.73,100,1,12.71,100,1,12.5,700,1,12.46,100,1,12.43,700,1,12.42,700,1,13.64,15,1,13.66,15,1,13.81,2,1,13.94,100,1,14.22,100,1,14.28,100,1,14.46,100,1,14.48,700,1,14.49,100,1,14.54,700,1,2,339358233
2025-07-17T16:13:09.368197659Z,2025-07-17T16:13:09.368030843Z,160,2,1108,A,A,13.650000000,100,0,339427217,128,166816,282470466,ARL,,13.11,100,1,12.98,200,1,12.96,2,1,12.86,100,1,12.73,100,1,12.71,100,1,12.5,700,1,12.46,100,1,12.43,700,1,12.42,700,1,13.64,15,1,13.65,100,1,13.66,15,1,13.81,2,1,13.94,100,1,14.22,100,1,14.28,100,1,14.46,100,1,14.48,700,1,14.49,100,1,2,339427217
2025-07-17T16:13:14.046267875Z,2025-07-17T16:13:14.046102556Z,160,2,1108,C,A,13.660000000,15,0,339332865,130,165319,282563502,ARL,,13.11,100,1,12.98,200,1,12.96,2,1,12.86,100,1,12.73,100,1,12.71,100,1,12.5,700,1,12.46,100,1,12.43,700,1,12.42,700,1,13.64,15,1,13.65,100,1,13.81,2,1,13.94,100,1,14.22,100,1,14.28,100,1,14.46,100,1,14.48,700,1,14.49,100,1,14.54,700,1,2,339332865
2025-07-17T16:13:17.775210916Z,2025-07-17T16:13:17.775045316Z,160,2,1108,A,A,13.570000000,15,0,339610637,130,165600,282616566,ARL,,13.11,100,1,12.98,200,1,12.96,2,1,12.86,100,1,12.73,100,1,12.71,100,1,12.5,700,1,12.46,100,1,12.43,700,1,12.42,700,1,13.57,15,1,13.64,15,1,13.65,100,1,13.81,2,1,13.94,100,1,14.22,100,1,14.28,100,1,14.46,100,1,14.48,700,1,14.49,100,1,2,339610637
2025-07-17T16:13:19.781143691Z,2025-07-17T16:13:19.780978185Z,160,2,1108,C,A,13.650000000,100,0,339427217,0,165506,282644181,ARL,,13.11,100,1,12.98,200,1,12.96,2,1,12.86,100,1,12.73,100,1,12.71,100,1,12.5,700,1,12.46,100,1,12.43,700,1,12.42,700,1,13.57,15,1,13.64,15,1,13.81,2,1,13.94,100,1,14.22,100,1,14.28,100,1,14.46,100,1,14.48,700,1,14.49,100,1,14.54,700,1,2,339427217
2025-07-17T16:13:19.781143691Z,2025-07-17T16:13:19.780978185Z,160,2,1108,A,A,13.580000000,100,0,339641813,130,165506,282644181,ARL,,13.11,100,1,12.98,200,1,12.96,2,1,12.86,100,1,12.73,100,1,12.71,100,1,12.5,700,1,12.46,100,1,12.43,700,1,12.42,700,1,13.57,15,1,13.58,100,1,13.64,15,1,13.81,2,1,13.94,100,1,14.22,100,1,14.28,100,1,14.46,100,1,14.48,700,1,14.49,100,1,2,339641813
2025-07-17T16:13:19.781889805Z,2025-07-17T16:13:19.781723964Z,160,2,1108,C,A,14.730000000,100,0,339358293,0,165841,282644189,ARL,,13.11,100,1,12.98,200,1,12.96,2,1,12.86,100,1,12.73,100,1,12.71,100,1,12.5,700,1,12.46,100,1,12.43,700,1,12.42,700,1,13.57,15,1,13.58,100,1,13.64,15,1,13.81,2,1,13.94,100,1,14.22,100,1,14.28,100,1,14.46,100,1,14.48,700,1,14.49,100,1,2,339358293
2025-07-17T16:13:19.781889805Z,2025-07-17T16:13:19.781723964Z,160,2,1108,A,A,14.630000000,100,0,339641865,130,165841,282644189,ARL,,13.11,100,1,12.98,200,1,12.96,2,1,12.86,100,1,12.73,100,1,12.71,100,1,12.5,700,1,12.46,100,1,12.43,700,1,12.42,700,1,13.57,15,1,13.58,100,1,13.64,15,1,13.81,2,1,13.94,100,1,14.22,100,1,14.28,100,1,14.46,100,1,14.48,700,1,14.49,100,1,2,339641865
2025-07-17T16:13:19.789771458Z,2025-07-17T16:13:19.789606057Z,160,2,1108,C,A,13.940000000,100,0,339358741,130,165401,282644321,ARL,,13.11,100,1,12.98,200,1,12.96,2,1,12.86,100,1,12.73,100,1,12.71,100,1,12.5,700,1,12.46,100,1,12.43,700,1,12.42,700,1,13.57,15,1,13.58,100,1,13.64,15,1,13.81,2,1,14.22,100,1,14.28,100,1,14.46,100,1,14.48,700,1,14.49,100,1,14.54,700,1,2,339358741
2025-07-17T16:13:19.789822010Z,2025-07-17T16:13:19.789656689Z,160,2,1108,A,A,13.850000000,100,0,339642033,130,165321,282644322,ARL,,13.11,100,1,12.98,200,1,12.96,2,1,12.86,100,1,12.73,100,1,12.71,100,1,12.5,700,1,12.46,100,1,12.43,700,1,12.42,700,1,13.57,15,1,13.58,100,1,13.64,15,1,13.81,2,1,13.85,100,1,14.22,100,1,14.28,100,1,14.46,100,1,14.48,700,1,14.49,100,1,2,339642033
2025-07-17T16:13:19.863618706Z,2025-07-17T16:13:19.863452537Z,160,2,1108,C,A,13.570000000,15,0,339610637,130,166169,282645966,ARL,,13.11,100,1,12.98,200,1,12.96,2,1,12.86,100,1,12.73,100,1,12.71,100,1,12.5,700,1,12.46,100,1,12.43,700,1,12.42,700,1,13.58,100,1,13.64,15,1,13.81,2,1,13.85,100,1,14.22,100,1,14.28,100,1,14.46,100,1,14.48,700,1,14.49,100,1,14.54,700,1,2,339610637
2025-07-17T16:13:19.863790083Z,2025-07-17T16:13:19.863624798Z,160,2,1108,C,A,13.640000000,15,0,339425837,130,165285,282646001,ARL,,13.11,100,1,12.98,200,1,12.96,2,1,12.86,100,1,12.73,100,1,12.71,100,1,12.5,700,1,12.46,100,1,12.43,700,1,12.42,700,1,13.58,100,1,13.81,2,1,13.85,100,1,14.22,100,1,14.28,100,1,14.46,100,1,14.48,700,1,14.49,100,1,14.54,700,1,14.56,700,1,2,339425837
2025-07-17T16:13:19.863968792Z,2025-07-17T16:13:19.863803503Z,160,2,1108,A,A,13.580000000,96,0,339643285,130,165289,282646014,ARL,,13.11,100,1,12.98,200,1,12.96,2,1,12.86,100,1,12.73,100,1,12.71,100,1,12.5,700,1,12.46,100,1,12.43,700,1,12.42,700,1,13.58,196,1,13.81,2,1,13.85,100,1,14.22,100,1,14.28,100,1,14.46,100,1,14.48,700,1,14.49,100,1,14.54,700,1,14.56,700,1,2,339643285
2025-07-17T16:13:24.182625011Z,2025-07-17T16:13:24.182459676Z,160,2,1108,A,A,13.570000000,15,0,339710089,130,165335,282694909,ARL,,13.11,100,1,12.98,200,1,12.96,2,1,12.86,100,1,12.73,100,1,12.71,100,1,12.5,700,1,12.46,100,1,12.43,700,1,12.42,700,1,13.57,15,1,13.58,196,1,13.81,2,1,13.85,100,1,14.22,100,1,14.28,100,1,14.46,100,1,14.48,700,1,14.49,100,1,14.54,700,1,2,339710089
2025-07-17T16:13:24.182918202Z,2025-07-17T16:13:24.182753004Z,160,2,1108,C,A,13.580000000,96,0,339643285,130,165198,282694924,ARL,,13.11,100,1,12.98,200,1,12.96,2,1,12.86,100,1,12.73,100,1,12.71,100,1,12.5,700,1,12.46,100,1,12.43,700,1,12.42,700,1,13.57,15,1,13.58,100,1,13.81,2,1,13.85,100,1,14.22,100,1,14.28,100,1,14.46,100,1,14.48,700,1,14.49,100,1,14.54,700,1,2,339643285
2025-07-17T16:13:24.627374514Z,2025-07-17T16:13:24.627209125Z,160,2,1108,A,A,14.260000000,700,0,339716321,130,165389,282700118,ARL,,13.11,100,1,12.98,200,1,12.96,2,1,12.86,100,1,12.73,100,1,12.71,100,1,12.5,700,1,12.46,100,1,12.43,700,1,12.42,700,1,13.57,15,1,13.58,100,1,13.81,2,1,13.85,100,1,14.22,100,1,14.26,700,1,14.28,100,1,14.46,100,1,14.48,700,1,14.49,100,1,2,339716321
2025-07-17T16:13:24.627430447Z,2025-07-17T16:13:24.627265040Z,160,2,1108,C,A,14.680000000,700,0,339096897,130,165407,282700120,ARL,,13.11,100,1,12.98,200,1,12.96,2,1,12.86,100,1,12.73,100,1,12.71,100,1,12.5,700,1,12.46,100,1,12.43,700,1,12.42,700,1,13.57,15,1,13.58,100,1,13.81,2,1,13.85,100,1,14.22,100,1,14.26,700,1,14.28,100,1,14.46,100,1,14.48,700,1,14.49,100,1,2,339096897
2025-07-17T16:13:25.962717944Z,2025-07-17T16:13:25.962552288Z,160,2,1108,C,A,14.570000000,100,0,339203693,0,165656,282719507,ARL,,13.11,100,1,12.98,200,1,12.96,2,1,12.86,100,1,12.73,100,1,12.71,100,1,12.5,700,1,12.46,100,1,12.43,700,1,12.42,700,1,13.57,15,1,13.58,100,1,13.81,2,1,13.85,100,1,14.22,100,1,14.26,700,1,14.28,100,1,14.46,100,1,14.48,700,1,14.49,100,1,2,339203693
2025-07-17T16:13:25.962717944Z,2025-07-17T16:13:25.962552288Z,160,2,1108,A,A,14.460000000,100,0,339739285,130,165656,282719507,ARL,,13.11,100,1,12.98,200,1,12.96,2,1,12.86,100,1,12.73,100,1,12.71,100,1,12.5,700,1,12.46,100,1,12.43,700,1,12.42,700,1,13.57,15,1,13.58,100,1,13.81,2,1,13.85,100,1,14.22,100,1,14.26,700,1,14.28,100,1,14.46,200,1,14.48,700,1,14.49,100,1,2,339739285
2025-07-17T16:13:25.963209328Z,2025-07-17T16:13:25.963043858Z,160,2,1108,C,A,14.570000000,100,0,339203897,0,165470,282719515,ARL,,13.11,100,1,12.98,200,1,12.96,2,1,12.86,100,1,12.73,100,1,12.71,100,1,12.5,700,1,12.46,100,1,12.43,700,1,12.42,700,1,13.57,15,1,13.58,100,1,13.81,2,1,13.85,100,1,14.22,100,1,14.26,700,1,14.28,100,1,14.46,200,1,14.48,700,1,14.49,100,1,2,339203897
2025-07-17T16:13:25.963209328Z,2025-07-17T16:13:25.963043858Z,160,2,1108,A,A,14.460000000,100,0,339739297,130,165470,282719515,ARL,,13.11,100,1,12.98,200,1,12.96,2,1,12.86,100,1,12.73,100,1,12.71,100,1,12.5,700,1,12.46,100,1,12.43,700,1,12.42,700,1,13.57,15,1,13.58,100,1,13.81,2,1,13.85,100,1,14.22,100,1,14.26,700,1,14.28,100,1,14.46,300,1,14.48,700,1,14.49,100,1,2,339739297
2025-07-17T16:13:34.825229037Z,2025-07-17T16:13:34.825063658Z,160,2,1108,A,A,13.550000000,15,0,339897885,130,165379,282849136,ARL,,13.11,100,1,12.98,200,1,12.96,2,1,12.86,100,1,12.73,100,1,12.71,100,1,12.5,700,1,12.46,100,1,12.43,700,1,12.42,700,1,13.55,15,1,13.57,15,1,13.58,100,1,13.81,2,1,13.85,100,1,14.22,100,1,14.26,700,1,14.28,100,1,14.46,300,1,14.48,700,1,2,339897885
2025-07-17T16:13:36.525450545Z,2025-07-17T16:13:36.525285006Z,160,2,1108,C,A,13.580000000,100,0,339641813,0,165539,282880671,ARL,,13.11,100,1,12.98,200,1,12.96,2,1,12.86,100,1,12.73,100,1,12.71,100,1,12.5,700,1,12.46,100,1,12.43,700,1,12.42,700,1,13.55,15,1,13.57,15,1,13.81,2,1,13.85,100,1,14.22,100,1,14.26,700,1,14.28,100,1,14.46,300,1,14.48,700,1,14.49,100,1,2,339641813
2025-07-17T16:13:36.525450545Z,2025-07-17T16:13:36.525285006Z,160,2,1108,A,A,13.560000000,100,0,339937253,130,165539,282880671,ARL,,13.11,100,1,12.98,200,1,12.96,2,1,12.86,100,1,12.73,100,1,12.71,100,1,12.5,700,1,12.46,100,1,12.43,700,1,12.42,700,1,13.55,15,1,13.56,100,1,13.57,15,1,13.81,2,1,13.85,100,1,14.22,100,1,14.26,700,1,14.28,100,1,14.46,300,1,14.48,700,1,2,339937253
2025-07-17T16:13:36.528326337Z,2025-07-17T16:13:36.528160728Z,160,2,1108,C,A,17.370000000,100,0,339358609,0,165609,282880690,ARL,,13.11,100,1,12.98,200,1,12.96,2,1,12.86,100,1,12.73,100,1,12.71,100,1,12.5,700,1,12.46,100,1,12.43,700,1,12.42,700,1,13.55,15,1,13.56,100,1,13.57,15,1,13.81,2,1,13.85,100,1,14.22,100,1,14.26,700,1,14.28,100,1,14.46,300,1,14.48,700,1,2,339358609
2025-07-17T16:13:36.528326337Z,2025-07-17T16:13:36.528160728Z,160,2,1108,A,A,17.230000000,100,0,339937293,130,165609,282880690,ARL,,13.11,100,1,12.98,200,1,12.96,2,1,12.86,100,1,12.73,100,1,12.71,100,1,12.5,700,1,12.46,100,1,12.43,700,1,12.42,700,1,13.55,15,1,13.56,100,1,13.57,15,1,13.81,2,1,13.85,100,1,14.22,100,1,14.26,700,1,14.28,100,1,14.46,300,1,14.48,700,1,2,339937293
2025-07-17T16:13:40.166698198Z,2025-07-17T16:13:40.166532673Z,160,2,1108,C,A,13.570000000,15,0,339710089,130,165525,282934517,ARL,,13.11,100,1,12.98,200,1,12.96,2,1,12.86,100,1,12.73,100,1,12.71,100,1,12.5,700,1,12.46,100,1,12.43,700,1,12.42,700,1,13.55,15,1,13.56,100,1,13.81,2,1,13.85,100,1,14.22,100,1,14.26,700,1,14.28,100,1,14.46,300,1,14.48,700,1,14.49,100,1,2,339710089
2025-07-17T16:13:41.168681977Z,2025-07-17T16:13:41.168516592Z,160,2,1108,A,A,13.530000000,15,0,340027925,130,165385,282947373,ARL,,13.11,100,1,12.98,200,1,12.96,2,1,12.86,100,1,12.73,100,1,12.71,100,1,12.5,700,1,12.46,100,1,12.43,700,1,12.42,700,1,13.53,15,1,13.55,15,1,13.56,100,1,13.81,2,1,13.85,100,1,14.22,100,1,14.26,700,1,14.28,100,1,14.46,300,1,14.48,700,1,2,340027925
2025-07-17T16:13:41.810648775Z,2025-07-17T16:13:41.810482971Z,160,2,1108,C,A,13.560000000,100,0,339937253,0,165804,282959674,ARL,,13.11,100,1,12.98,200,1,12.96,2,1,12.86,100,1,12.73,100,1,12.71,100,1,12.5,700,1,12.46,100,1,12.43,700,1,12.42,700,1,13.53,15,1,13.55,15,1,13.81,2,1,13.85,100,1,14.22,100,1,14.26,700,1,14.28,100,1,14.46,300,1,14.48,700,1,14.49,100,1,2,339937253
2025-07-17T16:13:41.810648775Z,2025-07-17T16:13:41.810482971Z,160,2,1108,A,A,13.540000000,100,0,340046965,130,165804,282959674,ARL,,13.11,100,1,12.98,200,1,12.96,2,1,12.86,100,1,12.73,100,1,12.71,100,1,12.5,700,1,12.46,100,1,12.43,700,1,12.42,700,1,13.53,15,1,13.54,100,1,13.55,15,1,13.81,2,1,13.85,100,1,14.22,100,1,14.26,700,1,14.28,100,1,14.46,300,1,14.48,700,1,2,340046965
2025-07-17T16:13:41.811397213Z,2025-07-17T16:13:41.811231743Z,160,2,1108,C,A,14.630000000,100,0,339641865,0,165470,282959705,ARL,,13.11,100,1,12.98,200,1,12.96,2,1,12.86,100,1,12.73,100,1,12.71,100,1,12.5,700,1,12.46,100,1,12.43,700,1,12.42,700,1,13.53,15,1,13.54,100,1,13.55,15,1,13.81,2,1,13.85,100,1,14.22,100,1,14.26,700,1,14.28,100,1,14.46,300,1,14.48,700,1,2,339641865
2025-07-17T16:13:41.811397213Z,2025-07-17T16:13:41.811231743Z,160,2,1108,A,A,14.590000000,100,0,340047001,130,165470,282959705,ARL,,13.11,100,1,12.98,200,1,12.96,2,1,12.86,100,1,12.73,100,1,12.71,100,1,12.5,700,1,12.46,100,1,12.43,700,1,12.42,700,1,13.53,15,1,13.54,100,1,13.55,15,1,13.81,2,1,13.85,100,1,14.22,100,1,14.26,700,1,14.28,100,1,14.46,300,1,14.48,700,1,2,340047001
2025-07-17T16:13:41.846549822Z,2025-07-17T16:13:41.846384162Z,160,2,1108,C,A,15.730000000,100,0,339359077,0,165660,282960440,ARL,,13.11,100,1,12.98,200,1,12.96,2,1,12.86,100,1,12.73,100,1,12.71,100,1,12.5,700,1,12.46,100,1,12.43,700,1,12.42,700,1,13.53,15,1,13.54,100,1,13.55,15,1,13.81,2,1,13.85,100,1,14.22,100,1,14.26,700,1,14.28,100,1,14.46,300,1,14.48,700,1,2,339359077
2025-07-17T16:13:41.846549822Z,2025-07-17T16:13:41.846384162Z,160,2,1108,A,A,15.580000000,100,0,340047805,130,165660,282960440,ARL,,13.11,100,1,12.98,200,1,12.96,2,1,12.86,100,1,12.73,100,1,12.71,100,1,12.5,700,1,12.46,100,1,12.43,700,1,12.42,700,1,13.53,15,1,13.54,100,1,13.55,15,1,13.81,2,1,13.85,100,1,14.22,100,1,14.26,700,1,14.28,100,1,14.46,300,1,14.48,700,1,2,340047805
2025-07-17T16:13:53.138391930Z,2025-07-17T16:13:53.138226660Z,160,2,1108,C,A,13.530000000,15,0,340027925,130,165270,283090735,ARL,,13.11,100,1,12.98,200,1,12.96,2,1,12.86,100,1,12.73,100,1,12.71,100,1,12.5,700,1,12.46,100,1,12.43,700,1,12.42,700,1,13.54,100,1,13.55,15,1,13.81,2,1,13.85,100,1,14.22,100,1,14.26,700,1,14.28,100,1,14.46,300,1,14.48,700,1,14.49,100,1,2,340027925
2025-07-17T16:13:53.784302227Z,2025-07-17T16:13:53.784124590Z,160,2,1108,C,A,13.550000000,15,0,339897885,128,177637,283098338,ARL,,13.11,100,1,12.98,200,1,12.96,2,1,12.86,100,1,12.73,100,1,12.71,100,1,12.5,700,1,12.46,100,1,12.43,700,1,12.42,700,1,13.54,100,1,13.81,2,1,13.85,100,1,14.22,100,1,14.26,700,1,14.28,100,1,14.46,300,1,14.48,700,1,14.49,100,1,14.54,700,1,2,339897885
2025-07-17T16:14:06.190866982Z,2025-07-17T16:14:06.190701389Z,160,2,1108,C,A,13.810000000,2,0,339358409,0,165593,283262191,ARL,,13.11,100,1,12.98,200,1,12.96,2,1,12.86,100,1,12.73,100,1,12.71,100,1,12.5,700,1,12.46,100,1,12.43,700,1,12.42,700,1,13.54,100,1,13.85,100,1,14.22,100,1,14.26,700,1,14.28,100,1,14.46,300,1,14.48,700,1,14.49,100,1,14.54,700,1,14.56,700,1,2,339358409
2025-07-17T16:14:06.190866982Z,2025-07-17T16:14:06.190701389Z,160,2,1108,A,A,13.740000000,2,0,340449865,130,165593,283262191,ARL,,13.11,100,1,12.98,200,1,12.96,2,1,12.86,100,1,12.73,100,1,12.71,100,1,12.5,700,1,12.46,100,1,12.43,700,1,12.42,700,1,13.54,100,1,13.74,2,1,13.85,100,1,14.22,100,1,14.26,700,1,14.28,100,1,14.46,300,1,14.48,700,1,14.49,100,1,14.54,700,1,2,340449865
2025-07-17T16:14:10.827419207Z,2025-07-17T16:14:10.827253317Z,160,2,1108,A,A,13.510000000,15,0,340526285,130,165890,283315922,ARL,,13.11,100,1,12.98,200,1,12.96,2,1,12.86,100,1,12.73,100,1,12.71,100,1,12.5,700,1,12.46,100,1,12.43,700,1,12.42,700,1,13.51,15,1,13.54,100,1,13.74,2,1,13.85,100,1,14.22,100,1,14.26,700,1,14.28,100,1,14.46,300,1,14.48,700,1,14.49,100,1,2,340526285
2025-07-17T16:14:10.876894854Z,2025-07-17T16:14:10.876729278Z,160,2,1108,C,A,13.540000000,100,0,340046965,0,165576,283317356,ARL,,13.11,100,1,12.98,200,1,12.96,2,1,12.86,100,1,12.73,100,1,12.71,100,1,12.5,700,1,12.46,100,1,12.43,700,1,12.42,700,1,13.51,15,1,13.74,2,1,13.85,100,1,14.22,100,1,14.26,700,1,14.28,100,1,14.46,300,1,14.48,700,1,14.49,100,1,14.54,700,1,2,340046965
2025-07-17T16:14:10.876894854Z,2025-07-17T16:14:10.876729278Z,160,2,1108,A,A,13.520000000,100,0,340527921,130,165576,283317356,ARL,,13.11,100,1,12.98,200,1,12.96,2,1,12.86,100,1,12.73,100,1,12.71,100,1,12.5,700,1,12.46,100,1,12.43,700,1,12.42,700,1,13.51,15,1,13.52,100,1,13.74,2,1,13.85,100,1,14.22,100,1,14.26,700,1,14.28,100,1,14.46,300,1,14.48,700,1,14.49,100,1,2,340527921
2025-07-17T16:14:10.878601199Z,2025-07-17T16:14:10.878435316Z,160,2,1108,C,A,14.630000000,100,0,339358353,0,165883,283317367,ARL,,13.11,100,1,12.98,200,1,12.96,2,1,12.86,100,1,12.73,100,1,12.71,100,1,12.5,700,1,12.46,100,1,12.43,700,1,12.42,700,1,13.51,15,1,13.52,100,1,13.74,2,1,13.85,100,1,14.22,100,1,14.26,700,1,14.28,100,1,14.46,300,1,14.48,700,1,14.49,100,1,2,339358353
2025-07-17T16:14:10.878601199Z,2025-07-17T16:14:10.878435316Z,160,2,1108,A,A,14.470000000,100,0,340527969,130,165883,283317367,ARL,,13.11,100,1,12.98,200,1,12.96,2,1,12.86,100,1,12.73,100,1,12.71,100,1,12.5,700,1,12.46,100,1,12.43,700,1,12.42,700,1,13.51,15,1,13.52,100,1,13.74,2,1,13.85,100,1,14.22,100,1,14.26,700,1,14.28,100,1,14.46,300,1,14.47,100,1,14.48,700,1,2,340527969
2025-07-17T16:14:10.892679514Z,2025-07-17T16:14:10.892513823Z,160,2,1108,C,A,14.630000000,100,0,339359401,0,165691,283317451,ARL,,13.11,100,1,12.98,200,1,12.96,2,1,12.86,100,1,12.73,100,1,12.71,100,1,12.5,700,1,12.46,100,1,12.43,700,1,12.42,700,1,13.51,15,1,13.52,100,1,13.74,2,1,13.85,100,1,14.22,100,1,14.26,700,1,14.28,100,1,14.46,300,1,14.47,100,1,14.48,700,1,2,339359401
2025-07-17T16:14:10.892679514Z,2025-07-17T16:14:10.892513823Z,160,2,1108,A,A,14.470000000,100,0,340528121,130,165691,283317451,ARL,,13.11,100,1,12.98,200,1,12.96,2,1,12.86,100,1,12.73,100,1,12.71,100,1,12.5,700,1,12.46,100,1,12.43,700,1,12.42,700,1,13.51,15,1,13.52,100,1,13.74,2,1,13.85,100,1,14.22,100,1,14.26,700,1,14.28,100,1,14.46,300,1,14.47,200,1,14.48,700,1,2,340528121
2025-07-17T16:14:10.985507716Z,2025-07-17T16:14:10.985342000Z,160,2,1108,C,A,14.460000000,100,0,339359421,0,165716,283318181,ARL,,13.11,100,1,12.98,200,1,12.96,2,1,12.86,100,1,12.73,100,1,12.71,100,1,12.5,700,1,12.46,100,1,12.43,700,1,12.42,700,1,13.51,15,1,13.52,100,1,13.74,2,1,13.85,100,1,14.22,100,1,14.26,700,1,14.28,100,1,14.46,200,1,14.47,200,1,14.48,700,1,2,339359421
2025-07-17T16:14:10.985507716Z,2025-07-17T16:14:10.985342000Z,160,2,1108,A,A,14.310000000,100,0,340529021,130,165716,283318181,ARL,,13.11,100,1,12.98,200,1,12.96,2,1,12.86,100,1,12.73,100,1,12.71,100,1,12.5,700,1,12.46,100,1,12.43,700,1,12.42,700,1,13.51,15,1,13.52,100,1,13.74,2,1,13.85,100,1,14.22,100,1,14.26,700,1,14.28,100,1,14.31,100,1,14.46,200,1,14.47,200,1,2,340529021
2025-07-17T16:14:19.528488233Z,2025-07-17T16:14:19.528322793Z,160,2,1108,A,A,13.490000000,15,0,340664453,130,165440,283419160,ARL,,13.11,100,1,12.98,200,1,12.96,2,1,12.86,100,1,12.73,100,1,12.71,100,1,12.5,700,1,12.46,100,1,12.43,700,1,12.42,700,1,13.49,15,1,13.51,15,1,13.52,100,1,13.74,2,1,13.85,100,1,14.22,100,1,14.26,700,1,14.28,100,1,14.31,100,1,14.46,200,1,2,340664453
2025-07-17T16:14:21.306764970Z,2025-07-17T16:14:21.306599291Z,160,2,1108,C,A,13.520000000,100,0,340527921,0,165679,283454179,ARL,,13.11,100,1,12.98,200,1,12.96,2,1,12.86,100,1,12.73,100,1,12.71,100,1,12.5,700,1,12.46,100,1,12.43,700,1,12.42,700,1,13.49,15,1,13.51,15,1,13.74,2,1,13.85,100,1,14.22,100,1,14.26,700,1,14.28,100,1,14.31,100,1,14.46,200,1,14.47,200,1,2,340527921
2025-07-17T16:14:21.306764970Z,2025-07-17T16:14:21.306599291Z,160,2,1108,A,A,13.500000000,100,0,340704401,130,165679,283454179,ARL,,13.11,100,1,12.98,200,1,12.96,2,1,12.86,100,1,12.73,100,1,12.71,100,1,12.5,700,1,12.46,100,1,12.43,700,1,12.42,700,1,13.49,15,1,13.5,100,1,13.51,15,1,13.74,2,1,13.85,100,1,14.22,100,1,14.26,700,1,14.28,100,1,14.31,100,1,14.46,200,1,2,340704401
2025-07-17T16:14:21.307512009Z,2025-07-17T16:14:21.307346403Z,160,2,1108,C,A,14.590000000,100,0,340047001,0,165606,283454259,ARL,,13.11,100,1,12.98,200,1,12.96,2,1,12.86,100,1,12.73,100,1,12.71,100,1,12.5,700,1,12.46,100,1,12.43,700,1,12.42,700,1,13.49,15,1,13.5,100,1,13.51,15,1,13.74,2,1,13.85,100,1,14.22,100,1,14.26,700,1,14.28,100,1,14.31,100,1,14.46,200,1,2,340047001
2025-07-17T16:14:21.307512009Z,2025-07-17T16:14:21.307346403Z,160,2,1108,A,A,14.550000000,100,0,340704465,130,165606,283454259,ARL,,13.11,100,1,12.98,200,1,12.96,2,1,12.86,100,1,12.73,100,1,12.71,100,1,12.5,700,1,12.46,100,1,12.43,700,1,12.42,700,1,13.49,15,1,13.5,100,1,13.51,15,1,13.74,2,1,13.85,100,1,14.22,100,1,14.26,700,1,14.28,100,1,14.31,100,1,14.46,200,1,2,340704465
2025-07-17T16:14:21.317261991Z,2025-07-17T16:14:21.317096752Z,160,2,1108,C,A,13.850000000,100,0,339642033,130,165239,283454878,ARL,,13.11,100,1,12.98,200,1,12.96,2,1,12.86,100,1,12.73,100,1,12.71,100,1,12.5,700,1,12.46,100,1,12.43,700,1,12.42,700,1,13.49,15,1,13.5,100,1,13.51,15,1,13.74,2,1,14.22,100,1,14.26,700,1,14.28,100,1,14.31,100,1,14.46,200,1,14.47,200,1,2,339642033
2025-07-17T16:14:21.317314136Z,2025-07-17T16:14:21.317148983Z,160,2,1108,A,A,13.770000000,100,0,340705133,130,165153,283454882,ARL,,13.11,100,1,12.98,200,1,12.96,2,1,12.86,100,1,12.73,100,1,12.71,100,1,12.5,700,1,12.46,100,1,12.43,700,1,12.42,700,1,13.49,15,1,13.5,100,1,13.51,15,1,13.74,2,1,13.77,100,1,14.22,100,1,14.26,700,1,14.28,100,1,14.31,100,1,14.46,200,1,2,340705133
2025-07-17T16:14:21.343294261Z,2025-07-17T16:14:21.343129166Z,160,2,1108,A,A,15.390000000,100,0,340706373,130,165095,283455758,ARL,,13.11,100,1,12.98,200,1,12.96,2,1,12.86,100,1,12.73,100,1,12.71,100,1,12.5,700,1,12.46,100,1,12.43,700,1,12.42,700,1,13.49,15,1,13.5,100,1,13.51,15,1,13.74,2,1,13.77,100,1,14.22,100,1,14.26,700,1,14.28,100,1,14.31,100,1,14.46,200,1,2,340706373
2025-07-17T16:14:21.343307836Z,2025-07-17T16:14:21.343142096Z,160,2,1108,C,A,15.670000000,100,0,339202065,130,165740,283455759,ARL,,13.11,100,1,12.98,200,1,12.96,2,1,12.86,100,1,12.73,100,1,12.71,100,1,12.5,700,1,12.46,100,1,12.43,700,1,12.42,700,1,13.49,15,1,13.5,100,1,13.51,15,1,13.74,2,1,13.77,100,1,14.22,100,1,14.26,700,1,14.28,100,1,14.31,100,1,14.46,200,1,2,339202065
2025-07-17T16:14:36.523553349Z,2025-07-17T16:14:36.523382949Z,160,2,1108,C,A,13.490000000,15,0,340664453,128,170400,283655411,ARL,,13.11,100,1,12.98,200,1,12.96,2,1,12.86,100,1,12.73,100,1,12.71,100,1,12.5,700,1,12.46,100,1,12.43,700,1,12.42,700,1,13.5,100,1,13.51,15,1,13.74,2,1,13.77,100,1,14.22,100,1,14.26,700,1,14.28,100,1,14.31,100,1,14.46,200,1,14.47,200,1,2,340664453
2025-07-17T16:14:36.523730500Z,2025-07-17T16:14:36.523564373Z,160,2,1108,C,A,13.510000000,15,0,340526285,128,166127,283655455,ARL,,13.11,100,1,12.98,200,1,12.96,2,1,12.86,100,1,12.73,100,1,12.71,100,1,12.5,700,1,12.46,100,1,12.43,700,1,12.42,700,1,13.5,100,1,13.74,2,1,13.77,100,1,14.22,100,1,14.26,700,1,14.28,100,1,14.31,100,1,14.46,200,1,14.47,200,1,14.48,700,1,2,340526285
2025-07-17T16:14:36.523862340Z,2025-07-17T16:14:36.523696080Z,160,2,1108,A,A,13.500000000,99,0,340971661,128,166260,283655477,ARL,,13.11,100,1,12.98,200,1,12.96,2,1,12.86,100,1,12.73,100,1,12.71,100,1,12.5,700,1,12.46,100,1,12.43,700,1,12.42,700,1,13.5,199,1,13.74,2,1,13.77,100,1,14.22,100,1,14.26,700,1,14.28,100,1,14.31,100,1,14.46,200,1,14.47,200,1,14.48,700,1,2,340971661
2025-07-17T16:14:52.280593678Z,2025-07-17T16:14:52.280428336Z,160,2,1108,C,A,13.500000000,99,0,340971661,130,165342,283870929,ARL,,13.11,100,1,12.98,200,1,12.96,2,1,12.86,100,1,12.73,100,1,12.71,100,1,12.5,700,1,12.46,100,1,12.43,700,1,12.42,700,1,13.5,100,1,13.74,2,1,13.77,100,1,14.22,100,1,14.26,700,1,14.28,100,1,14.31,100,1,14.46,200,1,14.47,200,1,14.48,700,1,2,340971661
2025-07-17T16:14:52.297037125Z,2025-07-17T16:14:52.296871817Z,160,2,1108,A,A,13.480000000,15,0,341248825,130,165308,283871393,ARL,,13.11,100,1,12.98,200,1,12.96,2,1,12.86,100,1,12.73,100,1,12.71,100,1,12.5,700,1,12.46,100,1,12.43,700,1,12.42,700,1,13.48,15,1,13.5,100,1,13.74,2,1,13.77,100,1,14.22,100,1,14.26,700,1,14.28,100,1,14.31,100,1,14.46,200,1,14.47,200,1,2,341248825
2025-07-17T16:14:52.828721867Z,2025-07-17T16:14:52.828556785Z,160,2,1108,C,A,13.480000000,15,0,341248825,130,165082,283875146,ARL,,13.11,100,1,12.98,200,1,12.96,2,1,12.86,100,1,12.73,100,1,12.71,100,1,12.5,700,1,12.46,100,1,12.43,700,1,12.42,700,1,13.5,100,1,13.74,2,1,13.77,100,1,14.22,100,1,14.26,700,1,14.28,100,1,14.31,100,1,14.46,200,1,14.47,200,1,14.48,700,1,2,341248825
2025-07-17T16:14:52.829033713Z,2025-07-17T16:14:52.828868258Z,160,2,1108,A,A,13.500000000,99,0,341253573,130,165455,283875150,ARL,,13.11,100,1,12.98,200,1,12.96,2,1,12.86,100,1,12.73,100,1,12.71,100,1,12.5,700,1,12.46,100,1,12.43,700,1,12.42,700,1,13.5,199,1,13.74,2,1,13.77,100,1,14.22,100,1,14.26,700,1,14.28,100,1,14.31,100,1,14.46,200,1,14.47,200,1,14.48,700,1,2,341253573
2025-07-17T16:15:16.987369971Z,2025-07-17T16:15:16.987204735Z,160,2,1108,C,A,13.500000000,99,0,341253573,130,165236,284194889,ARL,,13.11,100,1,12.98,200,1,12.96,2,1,12.86,100,1,12.73,100,1,12.71,100,1,12.5,700,1,12.46,100,1,12.43,700,1,12.42,700,1,13.5,100,1,13.74,2,1,13.77,100,1,14.22,100,1,14.26,700,1,14.28,100,1,14.31,100,1,14.46,200,1,14.47,200,1,14.48,700,1,2,341253573
2025-07-17T16:15:16.987414675Z,2025-07-17T16:15:16.987249289Z,160,2,1108,C,A,13.500000000,100,0,340704401,130,165386,284194891,ARL,,13.11,100,1,12.98,200,1,12.96,2,1,12.86,100,1,12.73,100,1,12.71,100,1,12.5,700,1,12.46,100,1,12.43,700,1,12.42,700,1,13.74,2,1,13.77,100,1,14.22,100,1,14.26,700,1,14.28,100,1,14.31,100,1,14.46,200,1,14.47,200,1,14.48,700,1,14.49,100,1,2,340704401
2025-07-17T16:15:16.987689493Z,2025-07-17T16:15:16.987524101Z,160,2,1108,C,A,14.260000000,700,0,339716321,130,165392,284194901,ARL,,13.11,100,1,12.98,200,1,12.96,2,1,12.86,100,1,12.73,100,1,12.71,100,1,12.5,700,1,12.46,100,1,12.43,700,1,12.42,700,1,13.74,2,1,13.77,100,1,14.22,100,1,14.28,100,1,14.31,100,1,14.46,200,1,14.47,200,1,14.48,700,1,14.49,100,1,14.54,700,1,2,339716321
2025-07-17T16:15:16.987744468Z,2025-07-17T16:15:16.987579177Z,160,2,1108,A,A,14.460000000,700,0,341661841,130,165291,284194908,ARL,,13.11,100,1,12.98,200,1,12.96,2,1,12.86,100,1,12.73,100,1,12.71,100,1,12.5,700,1,12.46,100,1,12.43,700,1,12.42,700,1,13.74,2,1,13.77,100,1,14.22,100,1,14.28,100,1,14.31,100,1,14.46,900,1,14.47,200,1,14.48,700,1,14.49,100,1,14.54,700,1,2,341661841
2025-07-17T16:15:16.987772549Z,2025-07-17T16:15:16.987607468Z,160,2,1108,A,A,15.700000000,100,0,341661849,130,165081,284194910,ARL,,13.11,100,1,12.98,200,1,12.96,2,1,12.86,100,1,12.73,100,1,12.71,100,1,12.5,700,1,12.46,100,1,12.43,700,1,12.42,700,1,13.74,2,1,13.77,100,1,14.22,100,1,14.28,100,1,14.31,100,1,14.46,900,1,14.47,200,1,14.48,700,1,14.49,100,1,14.54,700,1,2,341661849
2025-07-17T16:15:16.987786087Z,2025-07-17T16:15:16.987620573Z,160,2,1108,C,A,15.390000000,100,0,340706373,130,165514,284194911,ARL,,13.11,100,1,12.98,200,1,12.96,2,1,12.86,100,1,12.73,100,1,12.71,100,1,12.5,700,1,12.46,100,1,12.43,700,1,12.42,700,1,13.74,2,1,13.77,100,1,14.22,100,1,14.28,100,1,14.31,100,1,14.46,900,1,14.47,200,1,14.48,700,1,14.49,100,1,14.54,700,1,2,340706373
2025-07-17T16:15:16.988145770Z,2025-07-17T16:15:16.987980299Z,160,2,1108,C,A,14.550000000,100,0,340704465,0,165471,284194935,ARL,,13.11,100,1,12.98,200,1,12.96,2,1,12.86,100,1,12.73,100,1,12.71,100,1,12.5,700,1,12.46,100,1,12.43,700,1,12.42,700,1,13.74,2,1,13.77,100,1,14.22,100,1,14.28,100,1,14.31,100,1,14.46,900,1,14.47,200,1,14.48,700,1,14.49,100,1,14.54,700,1,2,340704465
2025-07-17T16:15:16.988145770Z,2025-07-17T16:15:16.987980299Z,160,2,1108,A,A,14.600000000,100,0,341661869,130,165471,284194935,ARL,,13.11,100,1,12.98,200,1,12.96,2,1,12.86,100,1,12.73,100,1,12.71,100,1,12.5,700,1,12.46,100,1,12.43,700,1,12.42,700,1,13.74,2,1,13.77,100,1,14.22,100,1,14.28,100,1,14.31,100,1,14.46,900,1,14.47,200,1,14.48,700,1,14.49,100,1,14.54,700,1,2,341661869
2025-07-17T16:15:16.988410269Z,2025-07-17T16:15:16.988244795Z,160,2,1108,C,A,14.470000000,100,0,340527969,0,165474,284194952,ARL,,13.11,100,1,12.98,200,1,12.96,2,1,12.86,100,1,12.73,100,1,12.71,100,1,12.5,700,1,12.46,100,1,12.43,700,1,12.42,700,1,13.74,2,1,13.77,100,1,14.22,100,1,14.28,100,1,14.31,100,1,14.46,900,1,14.47,100,1,14.48,700,1,14.49,100,1,14.54,700,1,2,340527969
2025-07-17T16:15:16.988410269Z,2025-07-17T16:15:16.988244795Z,160,2,1108,A,A,14.740000000,100,0,341661877,130,165474,284194952,ARL,,13.11,100,1,12.98,200,1,12.96,2,1,12.86,100,1,12.73,100,1,12.71,100,1,12.5,700,1,12.46,100,1,12.43,700,1,12.42,700,1,13.74,2,1,13.77,100,1,14.22,100,1,14.28,100,1,14.31,100,1,14.46,900,1,14.47,100,1,14.48,700,1,14.49,100,1,14.54,700,1,2,341661877
2025-07-17T16:15:16.989313102Z,2025-07-17T16:15:16.989147294Z,160,2,1108,C,A,15.580000000,100,0,340047805,0,165808,284195117,ARL,,13.11,100,1,12.98,200,1,12.96,2,1,12.86,100,1,12.73,100,1,12.71,100,1,12.5,700,1,12.46,100,1,12.43,700,1,12.42,700,1,13.74,2,1,13.77,100,1,14.22,100,1,14.28,100,1,14.31,100,1,14.46,900,1,14.47,100,1,14.48,700,1,14.49,100,1,14.54,700,1,2,340047805
2025-07-17T16:15:16.989313102Z,2025-07-17T16:15:16.989147294Z,160,2,1108,A,A,15.840000000,100,0,341661893,130,165808,284195117,ARL,,13.11,100,1,12.98,200,1,12.96,2,1,12.86,100,1,12.73,100,1,12.71,100,1,12.5,700,1,12.46,100,1,12.43,700,1,12.42,700,1,13.74,2,1,13.77,100,1,14.22,100,1,14.28,100,1,14.31,100,1,14.46,900,1,14.47,100,1,14.48,700,1,14.49,100,1,14.54,700,1,2,341661893
2025-07-17T16:15:16.989763697Z,2025-07-17T16:15:16.989598095Z,160,2,1108,C,A,17.230000000,100,0,339937293,0,165602,284195176,ARL,,13.11,100,1,12.98,200,1,12.96,2,1,12.86,100,1,12.73,100,1,12.71,100,1,12.5,700,1,12.46,100,1,12.43,700,1,12.42,700,1,13.74,2,1,13.77,100,1,14.22,100,1,14.28,100,1,14.31,100,1,14.46,900,1,14.47,100,1,14.48,700,1,14.49,100,1,14.54,700,1,2,339937293
2025-07-17T16:15:16.989763697Z,2025-07-17T16:15:16.989598095Z,160,2,1108,A,A,17.490000000,100,0,341661901,130,165602,284195176,ARL,,13.11,100,1,12.98,200,1,12.96,2,1,12.86,100,1,12.73,100,1,12.71,100,1,12.5,700,1,12.46,100,1,12.43,700,1,12.42,700,1,13.74,2,1,13.77,100,1,14.22,100,1,14.28,100,1,14.31,100,1,14.46,900,1,14.47,100,1,14.48,700,1,14.49,100,1,14.54,700,1,2,341661901
2025-07-17T16:15:16.989886697Z,2025-07-17T16:15:16.989720957Z,160,2,1108,C,A,14.470000000,100,0,340528121,0,165740,284195185,ARL,,13.11,100,1,12.98,200,1,12.96,2,1,12.86,100,1,12.73,100,1,12.71,100,1,12.5,700,1,12.46,100,1,12.43,700,1,12.42,700,1,13.74,2,1,13.77,100,1,14.22,100,1,14.28,100,1,14.31,100,1,14.46,900,1,14.48,700,1,14.49,100,1,14.54,700,1,14.56,700,1,2,340528121
2025-07-17T16:15:16.989886697Z,2025-07-17T16:15:16.989720957Z,160,2,1108,A,A,14.740000000,100,0,341661905,130,165740,284195185,ARL,,13.11,100,1,12.98,200,1,12.96,2,1,12.86,100,1,12.73,100,1,12.71,100,1,12.5,700,1,12.46,100,1,12.43,700,1,12.42,700,1,13.74,2,1,13.77,100,1,14.22,100,1,14.28,100,1,14.31,100,1,14.46,900,1,14.48,700,1,14.49,100,1,14.54,700,1,14.56,700,1,2,341661905
2025-07-17T16:15:16.992804347Z,2025-07-17T16:15:16.992638952Z,160,2,1108,C,A,14.310000000,100,0,340529021,130,165395,284195309,ARL,,13.11,100,1,12.98,200,1,12.96,2,1,12.86,100,1,12.73,100,1,12.71,100,1,12.5,700,1,12.46,100,1,12.43,700,1,12.42,700,1,13.74,2,1,13.77,100,1,14.22,100,1,14.28,100,1,14.46,900,1,14.48,700,1,14.49,100,1,14.54,700,1,14.56,700,1,14.6,100,1,2,340529021
2025-07-17T16:15:16.992941967Z,2025-07-17T16:15:16.992776612Z,160,2,1108,A,A,14.560000000,100,0,341661985,130,165355,284195310,ARL,,13.11,100,1,12.98,200,1,12.96,2,1,12.86,100,1,12.73,100,1,12.71,100,1,12.5,700,1,12.46,100,1,12.43,700,1,12.42,700,1,13.74,2,1,13.77,100,1,14.22,100,1,14.28,100,1,14.46,900,1,14.48,700,1,14.49,100,1,14.54,700,1,14.56,800,1,14.6,100,1,2,341661985
2025-07-17T16:15:17.000588174Z,2025-07-17T16:15:17.000422944Z,160,2,1108,C,A,13.770000000,100,0,340705133,130,165230,284195454,ARL,,13.11,100,1,12.98,200,1,12.96,2,1,12.86,100,1,12.73,100,1,12.71,100,1,12.5,700,1,12.46,100,1,12.43,700,1,12.42,700,1,13.74,2,1,14.22,100,1,14.28,100,1,14.46,900,1,14.48,700,1,14.49,100,1,14.54,700,1,14.56,800,1,14.6,100,1,14.74,200,1,2,340705133
2025-07-17T16:15:17.000621056Z,2025-07-17T16:15:17.000456046Z,160,2,1108,C,A,14.460000000,700,0,341661841,130,165010,284195456,ARL,,13.11,100,1,12.98,200,1,12.96,2,1,12.86,100,1,12.73,100,1,12.71,100,1,12.5,700,1,12.46,100,1,12.43,700,1,12.42,700,1,13.74,2,1,14.22,100,1,14.28,100,1,14.46,200,1,14.48,700,1,14.49,100,1,14.54,700,1,14.56,800,1,14.6,100,1,14.74,200,1,2,341661841
2025-07-17T16:15:17.000640033Z,2025-07-17T16:15:17.000474862Z,160,2,1108,A,A,14.050000000,100,0,341662085,130,165171,284195458,ARL,,13.11,100,1,12.98,200,1,12.96,2,1,12.86,100,1,12.73,100,1,12.71,100,1,12.5,700,1,12.46,100,1,12.43,700,1,12.42,700,1,13.74,2,1,14.05,100,1,14.22,100,1,14.28,100,1,14.46,200,1,14.48,700,1,14.49,100,1,14.54,700,1,14.56,800,1,14.6,100,1,2,341662085
2025-07-17T16:15:17.001323406Z,2025-07-17T16:15:17.001158038Z,160,2,1108,C,A,14.280000000,100,0,339358333,130,165368,284195476,ARL,,13.11,100,1,12.98,200,1,12.96,2,1,12.86,100,1,12.73,100,1,12.71,100,1,12.5,700,1,12.46,100,1,12.43,700,1,12.42,700,1,13.74,2,1,14.05,100,1,14.22,100,1,14.46,200,1,14.48,700,1,14.49,100,1,14.54,700,1,14.56,800,1,14.6,100,1,14.74,200,1,2,339358333
2025-07-17T16:15:17.001687312Z,2025-07-17T16:15:17.001522171Z,160,2,1108,A,A,14.600000000,100,0,341662113,130,165141,284195477,ARL,,13.11,100,1,12.98,200,1,12.96,2,1,12.86,100,1,12.73,100,1,12.71,100,1,12.5,700,1,12.46,100,1,12.43,700,1,12.42,700,1,13.74,2,1,14.05,100,1,14.22,100,1,14.46,200,1,14.48,700,1,14.49,100,1,14.54,700,1,14.56,800,1,14.6,200,1,14.74,200,1,2,341662113
2025-07-17T16:15:17.002229963Z,2025-07-17T16:15:17.002064284Z,160,2,1108,C,A,14.740000000,100,0,341661905,0,165679,284195479,ARL,,13.11,100,1,12.98,200,1,12.96,2,1,12.86,100,1,12.73,100,1,12.71,100,1,12.5,700,1,12.46,100,1,12.43,700,1,12.42,700,1,13.74,2,1,14.05,100,1,14.22,100,1,14.46,200,1,14.48,700,1,14.49,100,1,14.54,700,1,14.56,800,1,14.6,200,1,14.74,100,1,2,341661905
2025-07-17T16:15:17.002229963Z,2025-07-17T16:15:17.002064284Z,160,2,1108,A,A,14.960000000,100,0,341662117,130,165679,284195479,ARL,,13.11,100,1,12.98,200,1,12.96,2,1,12.86,100,1,12.73,100,1,12.71,100,1,12.5,700,1,12.46,100,1,12.43,700,1,12.42,700,1,13.74,2,1,14.05,100,1,14.22,100,1,14.46,200,1,14.48,700,1,14.49,100,1,14.54,700,1,14.56,800,1,14.6,200,1,14.74,100,1,2,341662117
2025-07-17T16:15:17.002790290Z,2025-07-17T16:15:17.002625119Z,160,2,1108,C,A,17.490000000,100,0,341661901,0,165171,284195482,ARL,,13.11,100,1,12.98,200,1,12.96,2,1,12.86,100,1,12.73,100,1,12.71,100,1,12.5,700,1,12.46,100,1,12.43,700,1,12.42,700,1,13.74,2,1,14.05,100,1,14.22,100,1,14.46,200,1,14.48,700,1,14.49,100,1,14.54,700,1,14.56,800,1,14.6,200,1,14.74,100,1,2,341661901
2025-07-17T16:15:17.002790290Z,2025-07-17T16:15:17.002625119Z,160,2,1108,A,A,17.760000000,100,0,341662125,130,165171,284195482,ARL,,13.11,100,1,12.98,200,1,12.96,2,1,12.86,100,1,12.73,100,1,12.71,100,1,12.5,700,1,12.46,100,1,12.43,700,1,12.42,700,1,13.74,2,1,14.05,100,1,14.22,100,1,14.46,200,1,14.48,700,1,14.49,100,1,14.54,700,1,14.56,800,1,14.6,200,1,14.74,100,1,2,341662125
2025-07-17T16:15:17.003246802Z,2025-07-17T16:15:17.003081581Z,160,2,1108,C,A,14.740000000,100,0,341661877,0,165221,284195486,ARL,,13.11,100,1,12.98,200,1,12.96,2,1,12.86,100,1,12.73,100,1,12.71,100,1,12.5,700,1,12.46,100,1,12.43,700,1,12.42,700,1,13.74,2,1,14.05,100,1,14.22,100,1,14.46,200,1,14.48,700,1,14.49,100,1,14.54,700,1,14.56,800,1,14.6,200,1,14.96,100,1,2,341661877
2025-07-17T16:15:17.003246802Z,2025-07-17T16:15:17.003081581Z,160,2,1108,A,A,14.960000000,100,0,341662133,130,165221,284195486,ARL,,13.11,100,1,12.98,200,1,12.96,2,1,12.86,100,1,12.73,100,1,12.71,100,1,12.5,700,1,12.46,100,1,12.43,700,1,12.42,700,1,13.74,2,1,14.05,100,1,14.22,100,1,14.46,200,1,14.48,700,1,14.49,100,1,14.54,700,1,14.56,800,1,14.6,200,1,14.96,200,1,2,341662133
2025-07-17T16:15:17.003381863Z,2025-07-17T16:15:17.003216492Z,160,2,1108,C,A,15.840000000,100,0,341661893,0,165371,284195487,ARL,,13.11,100,1,12.98,200,1,12.96,2,1,12.86,100,1,12.73,100,1,12.71,100,1,12.5,700,1,12.46,100,1,12.43,700,1,12.42,700,1,13.74,2,1,14.05,100,1,14.22,100,1,14.46,200,1,14.48,700,1,14.49,100,1,14.54,700,1,14.56,800,1,14.6,200,1,14.96,200,1,2,341661893
2025-07-17T16:15:17.003381863Z,2025-07-17T16:15:17.003216492Z,160,2,1108,A,A,16.080000000,100,0,341662137,130,165371,284195487,ARL,,13.11,100,1,12.98,200,1,12.96,2,1,12.86,100,1,12.73,100,1,12.71,100,1,12.5,700,1,12.46,100,1,12.43,700,1,12.42,700,1,13.74,2,1,14.05,100,1,14.22,100,1,14.46,200,1,14.48,700,1,14.49,100,1,14.54,700,1,14.56,800,1,14.6,200,1,14.96,200,1,2,341662137
2025-07-17T16:15:17.003874553Z,2025-07-17T16:15:17.003708485Z,160,2,1108,C,A,15.040000000,100,0,339358349,0,166068,284195498,ARL,,13.11,100,1,12.98,200,1,12.96,2,1,12.86,100,1,12.73,100,1,12.71,100,1,12.5,700,1,12.46,100,1,12.43,700,1,12.42,700,1,13.74,2,1,14.05,100,1,14.22,100,1,14.46,200,1,14.48,700,1,14.49,100,1,14.54,700,1,14.56,800,1,14.6,200,1,14.96,200,1,2,339358349
2025-07-17T16:15:17.003874553Z,2025-07-17T16:15:17.003708485Z,160,2,1108,A,A,15.380000000,100,0,341662145,130,166068,284195498,ARL,,13.11,100,1,12.98,200,1,12.96,2,1,12.86,100,1,12.73,100,1,12.71,100,1,12.5,700,1,12.46,100,1,12.43,700,1,12.42,700,1,13.74,2,1,14.05,100,1,14.22,100,1,14.46,200,1,14.48,700,1,14.49,100,1,14.54,700,1,14.56,800,1,14.6,200,1,14.96,200,1,2,341662145
2025-07-17T16:15:17.003883470Z,2025-07-17T16:15:17.003717832Z,160,2,1108,C,A,15.040000000,100,0,339359357,0,165638,284195499,ARL,,13.11,100,1,12.98,200,1,12.96,2,1,12.86,100,1,12.73,100,1,12.71,100,1,12.5,700,1,12.46,100,1,12.43,700,1,12.42,700,1,13.74,2,1,14.05,100,1,14.22,100,1,14.46,200,1,14.48,700,1,14.49,100,1,14.54,700,1,14.56,800,1,14.6,200,1,14.96,200,1,2,339359357
2025-07-17T16:15:17.003883470Z,2025-07-17T16:15:17.003717832Z,160,2,1108,A,A,15.380000000,100,0,341662149,130,165638,284195499,ARL,,13.11,100,1,12.98,200,1,12.96,2,1,12.86,100,1,12.73,100,1,12.71,100,1,12.5,700,1,12.46,100,1,12.43,700,1,12.42,700,1,13.74,2,1,14.05,100,1,14.22,100,1,14.46,200,1,14.48,700,1,14.49,100,1,14.54,700,1,14.56,800,1,14.6,200,1,14.96,200,1,2,341662149
2025-07-17T16:15:17.019567564Z,2025-07-17T16:15:17.019402521Z,160,2,1108,C,A,14.050000000,100,0,341662085,130,165043,284195602,ARL,,13.11,100,1,12.98,200,1,12.96,2,1,12.86,100,1,12.73,100,1,12.71,100,1,12.5,700,1,12.46,100,1,12.43,700,1,12.42,700,1,13.74,2,1,14.22,100,1,14.46,200,1,14.48,700,1,14.49,100,1,14.54,700,1,14.56,800,1,14.6,200,1,14.96,200,1,15.3,100,1,2,341662085
2025-07-17T16:15:17.019617602Z,2025-07-17T16:15:17.019452245Z,160,2,1108,A,A,14.260000000,100,0,341662313,130,165357,284195603,ARL,,13.11,100,1,12.98,200,1,12.96,2,1,12.86,100,1,12.73,100,1,12.71,100,1,12.5,700,1,12.46,100,1,12.43,700,1,12.42,700,1,13.74,2,1,14.22,100,1,14.26,100,1,14.46,200,1,14.48,700,1,14.49,100,1,14.54,700,1,14.56,800,1,14.6,200,1,14.96,200,1,2,341662313
2025-07-17T16:15:17.037261626Z,2025-07-17T16:15:17.037096157Z,160,2,1108,C,A,14.600000000,100,0,341661869,0,165469,284195665,ARL,,13.11,100,1,12.98,200,1,12.96,2,1,12.86,100,1,12.73,100,1,12.71,100,1,12.5,700,1,12.46,100,1,12.43,700,1,12.42,700,1,13.74,2,1,14.22,100,1,14.26,100,1,14.46,200,1,14.48,700,1,14.49,100,1,14.54,700,1,14.56,800,1,14.6,100,1,14.96,200,1,2,341661869
2025-07-17T16:15:17.037261626Z,2025-07-17T16:15:17.037096157Z,160,2,1108,A,A,15.060000000,100,0,341662429,130,165469,284195665,ARL,,13.11,100,1,12.98,200,1,12.96,2,1,12.86,100,1,12.73,100,1,12.71,100,1,12.5,700,1,12.46,100,1,12.43,700,1,12.42,700,1,13.74,2,1,14.22,100,1,14.26,100,1,14.46,200,1,14.48,700,1,14.49,100,1,14.54,700,1,14.56,800,1,14.6,100,1,14.96,200,1,2,341662429
2025-07-17T16:15:17.049066370Z,2025-07-17T16:15:17.048901142Z,160,2,1108,A,A,13.750000000,100,0,341663101,130,165228,284196195,ARL,,13.11,100,1,12.98,200,1,12.96,2,1,12.86,100,1,12.73,100,1,12.71,100,1,12.5,700,1,12.46,100,1,12.43,700,1,12.42,700,1,13.74,2,1,13.75,100,1,14.22,100,1,14.26,100,1,14.46,200,1,14.48,700,1,14.49,100,1,14.54,700,1,14.56,800,1,14.6,100,1,2,341663101
2025-07-17T16:15:17.049108554Z,2025-07-17T16:15:17.048943087Z,160,2,1108,A,A,14.680000000,700,0,341663105,130,165467,284196196,ARL,,13.11,100,1,12.98,200,1,12.96,2,1,12.86,100,1,12.73,100,1,12.71,100,1,12.5,700,1,12.46,100,1,12.43,700,1,12.42,700,1,13.74,2,1,13.75,100,1,14.22,100,1,14.26,100,1,14.46,200,1,14.48,700,1,14.49,100,1,14.54,700,1,14.56,800,1,14.6,100,1,2,341663105
2025-07-17T16:15:17.050812161Z,2025-07-17T16:15:17.050646751Z,160,2,1108,C,A,14.960000000,100,0,341662133,0,165410,284196235,ARL,,13.11,100,1,12.98,200,1,12.96,2,1,12.86,100,1,12.73,100,1,12.71,100,1,12.5,700,1,12.46,100,1,12.43,700,1,12.42,700,1,13.74,2,1,13.75,100,1,14.22,100,1,14.26,100,1,14.46,200,1,14.48,700,1,14.49,100,1,14.54,700,1,14.56,800,1,14.6,100,1,2,341662133
2025-07-17T16:15:17.050812161Z,2025-07-17T16:15:17.050646751Z,160,2,1108,A,A,14.720000000,100,0,341663261,130,165410,284196235,ARL,,13.11,100,1,12.98,200,1,12.96,2,1,12.86,100,1,12.73,100,1,12.71,100,1,12.5,700,1,12.46,100,1,12.43,700,1,12.42,700,1,13.74,2,1,13.75,100,1,14.22,100,1,14.26,100,1,14.46,200,1,14.48,700,1,14.49,100,1,14.54,700,1,14.56,800,1,14.6,100,1,2,341663261
2025-07-17T16:15:17.051644859Z,2025-07-17T16:15:17.051479522Z,160,2,1108,C,A,17.760000000,100,0,341662125,0,165337,284196242,ARL,,13.11,100,1,12.98,200,1,12.96,2,1,12.86,100,1,12.73,100,1,12.71,100,1,12.5,700,1,12.46,100,1,12.43,700,1,12.42,700,1,13.74,2,1,13.75,100,1,14.22,100,1,14.26,100,1,14.46,200,1,14.48,700,1,14.49,100,1,14.54,700,1,14.56,800,1,14.6,100,1,2,341662125
2025-07-17T16:15:17.051644859Z,2025-07-17T16:15:17.051479522Z,160,2,1108,A,A,17.470000000,100,0,341663289,130,165337,284196242,ARL,,13.11,100,1,12.98,200,1,12.96,2,1,12.86,100,1,12.73,100,1,12.71,100,1,12.5,700,1,12.46,100,1,12.43,700,1,12.42,700,1,13.74,2,1,13.75,100,1,14.22,100,1,14.26,100,1,14.46,200,1,14.48,700,1,14.49,100,1,14.54,700,1,14.56,800,1,14.6,100,1,2,341663289
2025-07-17T16:15:17.054159307Z,2025-07-17T16:15:17.053993491Z,160,2,1108,C,A,16.080000000,100,0,341662137,0,165816,284196273,ARL,,13.11,100,1,12.98,200,1,12.96,2,1,12.86,100,1,12.73,100,1,12.71,100,1,12.5,700,1,12.46,100,1,12.43,700,1,12.42,700,1,13.74,2,1,13.75,100,1,14.22,100,1,14.26,100,1,14.46,200,1,14.48,700,1,14.49,100,1,14.54,700,1,14.56,800,1,14.6,100,1,2,341662137
2025-07-17T16:15:17.054159307Z,2025-07-17T16:15:17.053993491Z,160,2,1108,A,A,15.820000000,100,0,341663317,130,165816,284196273,ARL,,13.11,100,1,12.98,200,1,12.96,2,1,12.86,100,1,12.73,100,1,12.71,100,1,12.5,700,1,12.46,100,1,12.43,700,1,12.42,700,1,13.74,2,1,13.75,100,1,14.22,100,1,14.26,100,1,14.46,200,1,14.48,700,1,14.49,100,1,14.54,700,1,14.56,800,1,14.6,100,1,2,341663317
2025-07-17T16:15:17.059504149Z,2025-07-17T16:15:17.059338704Z,160,2,1108,C,A,14.260000000,100,0,341662313,130,165445,284196314,ARL,,13.11,100,1,12.98,200,1,12.96,2,1,12.86,100,1,12.73,100,1,12.71,100,1,12.5,700,1,12.46,100,1,12.43,700,1,12.42,700,1,13.74,2,1,13.75,100,1,14.22,100,1,14.46,200,1,14.48,700,1,14.49,100,1,14.54,700,1,14.56,800,1,14.6,100,1,14.68,700,1,2,341662313
2025-07-17T16:15:17.059552653Z,2025-07-17T16:15:17.059387360Z,160,2,1108,A,A,14.030000000,100,0,341663401,130,165293,284196315,ARL,,13.11,100,1,12.98,200,1,12.96,2,1,12.86,100,1,12.73,100,1,12.71,100,1,12.5,700,1,12.46,100,1,12.43,700,1,12.42,700,1,13.74,2,1,13.75,100,1,14.03,100,1,14.22,100,1,14.46,200,1,14.48,700,1,14.49,100,1,14.54,700,1,14.56,800,1,14.6,100,1,2,341663401
2025-07-17T16:15:17.084101480Z,2025-07-17T16:15:17.083936164Z,160,2,1108,C,A,14.960000000,100,0,341662117,0,165316,284196410,ARL,,13.11,100,1,12.98,200,1,12.96,2,1,12.86,100,1,12.73,100,1,12.71,100,1,12.5,700,1,12.46,100,1,12.43,700,1,12.42,700,1,13.74,2,1,13.75,100,1,14.03,100,1,14.22,100,1,14.46,200,1,14.48,700,1,14.49,100,1,14.54,700,1,14.56,800,1,14.6,100,1,2,341662117
2025-07-17T16:15:17.084101480Z,2025-07-17T16:15:17.083936164Z,160,2,1108,A,A,14.720000000,100,0,341663737,130,165316,284196410,ARL,,13.11,100,1,12.98,200,1,12.96,2,1,12.86,100,1,12.73,100,1,12.71,100,1,12.5,700,1,12.46,100,1,12.43,700,1,12.42,700,1,13.74,2,1,13.75,100,1,14.03,100,1,14.22,100,1,14.46,200,1,14.48,700,1,14.49,100,1,14.54,700,1,14.56,800,1,14.6,100,1,2,341663737
2025-07-17T16:15:17.087853488Z,2025-07-17T16:15:17.087688271Z,160,2,1108,C,A,15.060000000,100,0,341662429,0,165217,284196429,ARL,,13.11,100,1,12.98,200,1,12.96,2,1,12.86,100,1,12.73,100,1,12.71,100,1,12.5,700,1,12.46,100,1,12.43,700,1,12.42,700,1,13.74,2,1,13.75,100,1,14.03,100,1,14.22,100,1,14.46,200,1,14.48,700,1,14.49,100,1,14.54,700,1,14.56,800,1,14.6,100,1,2,341662429
2025-07-17T16:15:17.087853488Z,2025-07-17T16:15:17.087688271Z,160,2,1108,A,A,14.820000000,100,0,341663749,130,165217,284196429,ARL,,13.11,100,1,12.98,200,1,12.96,2,1,12.86,100,1,12.73,100,1,12.71,100,1,12.5,700,1,12.46,100,1,12.43,700,1,12.42,700,1,13.74,2,1,13.75,100,1,14.03,100,1,14.22,100,1,14.46,200,1,14.48,700,1,14.49,100,1,14.54,700,1,14.56,800,1,14.6,100,1,2,341663749
2025-07-17T16:15:17.643818240Z,2025-07-17T16:15:17.643653020Z,160,2,1108,C,A,14.600000000,100,0,341662113,130,165220,284202090,ARL,,13.11,100,1,12.98,200,1,12.96,2,1,12.86,100,1,12.73,100,1,12.71,100,1,12.5,700,1,12.46,100,1,12.43,700,1,12.42,700,1,13.74,2,1,13.75,100,1,14.03,100,1,14.22,100,1,14.46,200,1,14.48,700,1,14.49,100,1,14.54,700,1,14.56,800,1,14.68,700,1,2,341662113
2025-07-17T16:15:17.644168944Z,2025-07-17T16:15:17.644003726Z,160,2,1108,A,A,14.360000000,100,0,341671053,130,165218,284202091,ARL,,13.11,100,1,12.98,200,1,12.96,2,1,12.86,100,1,12.73,100,1,12.71,100,1,12.5,700,1,12.46,100,1,12.43,700,1,12.42,700,1,13.74,2,1,13.75,100,1,14.03,100,1,14.22,100,1,14.36,100,1,14.46,200,1,14.48,700,1,14.49,100,1,14.54,700,1,14.56,800,1,2,341671053
2025-07-17T16:15:35.999140348Z,2025-07-17T16:15:35.998974923Z,160,2,1108,C,B,12.360000000,100,0,336572057,0,165425,284480502,ARL,,13.11,100,1,12.98,200,1,12.96,2,1,12.86,100,1,12.73,100,1,12.71,100,1,12.5,700,1,12.46,100,1,12.43,700,1,12.42,700,1,13.74,2,1,13.75,100,1,14.03,100,1,14.22,100,1,14.36,100,1,14.46,200,1,14.48,700,1,14.49,100,1,14.54,700,1,14.56,800,1,2,336572057
2025-07-17T16:15:35.999140348Z,2025-07-17T16:15:35.998974923Z,160,2,1108,A,B,12.220000000,100,0,342029561,130,165425,284480502,ARL,,13.11,100,1,12.98,200,1,12.96,2,1,12.86,100,1,12.73,100,1,12.71,100,1,12.5,700,1,12.46,100,1,12.43,700,1,12.42,700,1,13.74,2,1,13.75,100,1,14.03,100,1,14.22,100,1,14.36,100,1,14.46,200,1,14.48,700,1,14.49,100,1,14.54,700,1,14.56,800,1,2,342029561
2025-07-17T16:15:35.999762137Z,2025-07-17T16:15:35.999596382Z,160,2,1108,C,B,12.360000000,100,0,336572069,0,165755,284480519,ARL,,13.11,100,1,12.98,200,1,12.96,2,1,12.86,100,1,12.73,100,1,12.71,100,1,12.5,700,1,12.46,100,1,12.43,700,1,12.42,700,1,13.74,2,1,13.75,100,1,14.03,100,1,14.22,100,1,14.36,100,1,14.46,200,1,14.48,700,1,14.49,100,1,14.54,700,1,14.56,800,1,2,336572069
2025-07-17T16:15:35.999762137Z,2025-07-17T16:15:35.999596382Z,160,2,1108,A,B,12.220000000,100,0,342029581,130,165755,284480519,ARL,,13.11,100,1,12.98,200,1,12.96,2,1,12.86,100,1,12.73,100,1,12.71,100,1,12.5,700,1,12.46,100,1,12.43,700,1,12.42,700,1,13.74,2,1,13.75,100,1,14.03,100,1,14.22,100,1,14.36,100,1,14.46,200,1,14.48,700,1,14.49,100,1,14.54,700,1,14.56,800,1,2,342029581
2025-07-17T16:16:30.787448429Z,2025-07-17T16:16:30.787282866Z,160,2,1108,C,B,12.960000000,2,0,339356397,0,165563,285308466,ARL,,13.11,100,1,12.98,200,1,12.86,100,1,12.73,100,1,12.71,100,1,12.5,700,1,12.46,100,1,12.43,700,1,12.42,700,1,12.37,700,1,13.74,2,1,13.75,100,1,14.03,100,1,14.22,100,1,14.36,100,1,14.46,200,1,14.48,700,1,14.49,100,1,14.54,700,1,14.56,800,1,2,339356397
2025-07-17T16:16:30.787448429Z,2025-07-17T16:16:30.787282866Z,160,2,1108,A,B,13.030000000,2,0,343084165,130,165563,285308466,ARL,,13.11,100,1,13.03,2,1,12.98,200,1,12.86,100,1,12.73,100,1,12.71,100,1,12.5,700,1,12.46,100,1,12.43,700,1,12.42,700,1,13.74,2,1,13.75,100,1,14.03,100,1,14.22,100,1,14.36,100,1,14.46,200,1,14.48,700,1,14.49,100,1,14.54,700,1,14.56,800,1,2,343084165
2025-07-17T16:17:22.832948558Z,2025-07-17T16:17:22.832783132Z,160,2,1108,A,A,13.470000000,15,0,344211173,130,165426,286207282,ARL,,13.11,100,1,13.03,2,1,12.98,200,1,12.86,100,1,12.73,100,1,12.71,100,1,12.5,700,1,12.46,100,1,12.43,700,1,12.42,700,1,13.47,15,1,13.74,2,1,13.75,100,1,14.03,100,1,14.22,100,1,14.36,100,1,14.46,200,1,14.48,700,1,14.49,100,1,14.54,700,1,2,344211173
2025-07-17T16:17:23.620456421Z,2025-07-17T16:17:23.620290881Z,160,2,1108,C,A,13.750000000,100,0,341663101,0,165540,286219821,ARL,,13.11,100,1,13.03,2,1,12.98,200,1,12.86,100,1,12.73,100,1,12.71,100,1,12.5,700,1,12.46,100,1,12.43,700,1,12.42,700,1,13.47,15,1,13.74,2,1,14.03,100,1,14.22,100,1,14.36,100,1,14.46,200,1,14.48,700,1,14.49,100,1,14.54,700,1,14.56,800,1,2,341663101
2025-07-17T16:17:23.620456421Z,2025-07-17T16:17:23.620290881Z,160,2,1108,A,A,13.480000000,100,0,344225341,130,165540,286219821,ARL,,13.11,100,1,13.03,2,1,12.98,200,1,12.86,100,1,12.73,100,1,12.71,100,1,12.5,700,1,12.46,100,1,12.43,700,1,12.42,700,1,13.47,15,1,13.48,100,1,13.74,2,1,14.03,100,1,14.22,100,1,14.36,100,1,14.46,200,1,14.48,700,1,14.49,100,1,14.54,700,1,2,344225341
2025-07-17T16:17:23.621199578Z,2025-07-17T16:17:23.621034171Z,160,2,1108,C,A,14.360000000,100,0,341671053,130,165407,286219868,ARL,,13.11,100,1,13.03,2,1,12.98,200,1,12.86,100,1,12.73,100,1,12.71,100,1,12.5,700,1,12.46,100,1,12.43,700,1,12.42,700,1,13.47,15,1,13.48,100,1,13.74,2,1,14.03,100,1,14.22,100,1,14.46,200,1,14.48,700,1,14.49,100,1,14.54,700,1,14.56,800,1,2,341671053
2025-07-17T16:17:23.621205573Z,2025-07-17T16:17:23.621040069Z,160,2,1108,C,A,14.820000000,100,0,341663749,0,165504,286219869,ARL,,13.11,100,1,13.03,2,1,12.98,200,1,12.86,100,1,12.73,100,1,12.71,100,1,12.5,700,1,12.46,100,1,12.43,700,1,12.42,700,1,13.47,15,1,13.48,100,1,13.74,2,1,14.03,100,1,14.22,100,1,14.46,200,1,14.48,700,1,14.49,100,1,14.54,700,1,14.56,800,1,2,341663749
2025-07-17T16:17:23.621205573Z,2025-07-17T16:17:23.621040069Z,160,2,1108,A,A,14.530000000,100,0,344225385,130,165504,286219869,ARL,,13.11,100,1,13.03,2,1,12.98,200,1,12.86,100,1,12.73,100,1,12.71,100,1,12.5,700,1,12.46,100,1,12.43,700,1,12.42,700,1,13.47,15,1,13.48,100,1,13.74,2,1,14.03,100,1,14.22,100,1,14.46,200,1,14.48,700,1,14.49,100,1,14.53,100,1,14.54,700,1,2,344225385
2025-07-17T16:17:23.621387062Z,2025-07-17T16:17:23.621221535Z,160,2,1108,C,A,15.820000000,100,0,341663317,0,165527,286219879,ARL,,13.11,100,1,13.03,2,1,12.98,200,1,12.86,100,1,12.73,100,1,12.71,100,1,12.5,700,1,12.46,100,1,12.43,700,1,12.42,700,1,13.47,15,1,13.48,100,1,13.74,2,1,14.03,100,1,14.22,100,1,14.46,200,1,14.48,700,1,14.49,100,1,14.53,100,1,14.54,700,1,2,341663317
2025-07-17T16:17:23.621387062Z,2025-07-17T16:17:23.621221535Z,160,2,1108,A,A,15.510000000,100,0,344225393,130,165527,286219879,ARL,,13.11,100,1,13.03,2,1,12.98,200,1,12.86,100,1,12.73,100,1,12.71,100,1,12.5,700,1,12.46,100,1,12.43,700,1,12.42,700,1,13.47,15,1,13.48,100,1,13.74,2,1,14.03,100,1,14.22,100,1,14.46,200,1,14.48,700,1,14.49,100,1,14.53,100,1,14.54,700,1,2,344225393
2025-07-17T16:17:23.621555609Z,2025-07-17T16:17:23.621389325Z,160,2,1108,A,A,14.080000000,100,0,344225397,130,166284,286219881,ARL,,13.11,100,1,13.03,2,1,12.98,200,1,12.86,100,1,12.73,100,1,12.71,100,1,12.5,700,1,12.46,100,1,12.43,700,1,12.42,700,1,13.47,15,1,13.48,100,1,13.74,2,1,14.03,100,1,14.08,100,1,14.22,100,1,14.46,200,1,14.48,700,1,14.49,100,1,14.53,100,1,2,344225397
2025-07-17T16:17:23.621978089Z,2025-07-17T16:17:23.621812403Z,160,2,1108,C,A,15.380000000,100,0,341662145,0,165686,286219887,ARL,,13.11,100,1,13.03,2,1,12.98,200,1,12.86,100,1,12.73,100,1,12.71,100,1,12.5,700,1,12.46,100,1,12.43,700,1,12.42,700,1,13.47,15,1,13.48,100,1,13.74,2,1,14.03,100,1,14.08,100,1,14.22,100,1,14.46,200,1,14.48,700,1,14.49,100,1,14.53,100,1,2,341662145
2025-07-17T16:17:23.621978089Z,2025-07-17T16:17:23.621812403Z,160,2,1108,A,A,14.830000000,100,0,344225405,130,165686,286219887,ARL,,13.11,100,1,13.03,2,1,12.98,200,1,12.86,100,1,12.73,100,1,12.71,100,1,12.5,700,1,12.46,100,1,12.43,700,1,12.42,700,1,13.47,15,1,13.48,100,1,13.74,2,1,14.03,100,1,14.08,100,1,14.22,100,1,14.46,200,1,14.48,700,1,14.49,100,1,14.53,100,1,2,344225405
2025-07-17T16:17:23.622834183Z,2025-07-17T16:17:23.622668656Z,160,2,1108,C,A,14.720000000,100,0,341663261,0,165527,286219894,ARL,,13.11,100,1,13.03,2,1,12.98,200,1,12.86,100,1,12.73,100,1,12.71,100,1,12.5,700,1,12.46,100,1,12.43,700,1,12.42,700,1,13.47,15,1,13.48,100,1,13.74,2,1,14.03,100,1,14.08,100,1,14.22,100,1,14.46,200,1,14.48,700,1,14.49,100,1,14.53,100,1,2,341663261
2025-07-17T16:17:23.622834183Z,2025-07-17T16:17:23.622668656Z,160,2,1108,A,A,14.430000000,100,0,344225449,130,165527,286219894,ARL,,13.11,100,1,13.03,2,1,12.98,200,1,12.86,100,1,12.73,100,1,12.71,100,1,12.5,700,1,12.46,100,1,12.43,700,1,12.42,700,1,13.47,15,1,13.48,100,1,13.74,2,1,14.03,100,1,14.08,100,1,14.22,100,1,14.43,100,1,14.46,200,1,14.48,700,1,14.49,100,1,2,344225449
2025-07-17T16:17:23.623011421Z,2025-07-17T16:17:23.622845856Z,160,2,1108,C,A,14.560000000,100,0,341661985,0,165565,286219895,ARL,,13.11,100,1,13.03,2,1,12.98,200,1,12.86,100,1,12.73,100,1,12.71,100,1,12.5,700,1,12.46,100,1,12.43,700,1,12.42,700,1,13.47,15,1,13.48,100,1,13.74,2,1,14.03,100,1,14.08,100,1,14.22,100,1,14.43,100,1,14.46,200,1,14.48,700,1,14.49,100,1,2,341661985
2025-07-17T16:17:23.623011421Z,2025-07-17T16:17:23.622845856Z,160,2,1108,A,A,14.270000000,100,0,344225453,130,165565,286219895,ARL,,13.11,100,1,13.03,2,1,12.98,200,1,12.86,100,1,12.73,100,1,12.71,100,1,12.5,700,1,12.46,100,1,12.43,700,1,12.42,700,1,13.47,15,1,13.48,100,1,13.74,2,1,14.03,100,1,14.08,100,1,14.22,100,1,14.27,100,1,14.43,100,1,14.46,200,1,14.48,700,1,2,344225453
2025-07-17T16:17:23.623052802Z,2025-07-17T16:17:23.622887237Z,160,2,1108,C,A,17.470000000,100,0,341663289,0,165565,286219896,ARL,,13.11,100,1,13.03,2,1,12.98,200,1,12.86,100,1,12.73,100,1,12.71,100,1,12.5,700,1,12.46,100,1,12.43,700,1,12.42,700,1,13.47,15,1,13.48,100,1,13.74,2,1,14.03,100,1,14.08,100,1,14.22,100,1,14.27,100,1,14.43,100,1,14.46,200,1,14.48,700,1,2,341663289
2025-07-17T16:17:23.623052802Z,2025-07-17T16:17:23.622887237Z,160,2,1108,A,A,17.120000000,100,0,344225457,130,165565,286219896,ARL,,13.11,100,1,13.03,2,1,12.98,200,1,12.86,100,1,12.73,100,1,12.71,100,1,12.5,700,1,12.46,100,1,12.43,700,1,12.42,700,1,13.47,15,1,13.48,100,1,13.74,2,1,14.03,100,1,14.08,100,1,14.22,100,1,14.27,100,1,14.43,100,1,14.46,200,1,14.48,700,1,2,344225457
2025-07-17T16:17:23.624578699Z,2025-07-17T16:17:23.624413295Z,160,2,1108,C,A,15.380000000,100,0,341662149,0,165404,286219909,ARL,,13.11,100,1,13.03,2,1,12.98,200,1,12.86,100,1,12.73,100,1,12.71,100,1,12.5,700,1,12.46,100,1,12.43,700,1,12.42,700,1,13.47,15,1,13.48,100,1,13.74,2,1,14.03,100,1,14.08,100,1,14.22,100,1,14.27,100,1,14.43,100,1,14.46,200,1,14.48,700,1,2,341662149
2025-07-17T16:17:23.624578699Z,2025-07-17T16:17:23.624413295Z,160,2,1108,A,A,14.830000000,100,0,344225485,130,165404,286219909,ARL,,13.11,100,1,13.03,2,1,12.98,200,1,12.86,100,1,12.73,100,1,12.71,100,1,12.5,700,1,12.46,100,1,12.43,700,1,12.42,700,1,13.47,15,1,13.48,100,1,13.74,2,1,14.03,100,1,14.08,100,1,14.22,100,1,14.27,100,1,14.43,100,1,14.46,200,1,14.48,700,1,2,344225485
2025-07-17T16:17:23.624638111Z,2025-07-17T16:17:23.624472504Z,160,2,1108,C,A,14.720000000,100,0,341663737,0,165607,286219911,ARL,,13.11,100,1,13.03,2,1,12.98,200,1,12.86,100,1,12.73,100,1,12.71,100,1,12.5,700,1,12.46,100,1,12.43,700,1,12.42,700,1,13.47,15,1,13.48,100,1,13.74,2,1,14.03,100,1,14.08,100,1,14.22,100,1,14.27,100,1,14.43,100,1,14.46,200,1,14.48,700,1,2,341663737
2025-07-17T16:17:23.624638111Z,2025-07-17T16:17:23.624472504Z,160,2,1108,A,A,14.430000000,100,0,344225489,130,165607,286219911,ARL,,13.11,100,1,13.03,2,1,12.98,200,1,12.86,100,1,12.73,100,1,12.71,100,1,12.5,700,1,12.46,100,1,12.43,700,1,12.42,700,1,13.47,15,1,13.48,100,1,13.74,2,1,14.03,100,1,14.08,100,1,14.22,100,1,14.27,100,1,14.43,200,1,14.46,200,1,14.48,700,1,2,344225489
2025-07-17T16:17:23.627653611Z,2025-07-17T16:17:23.627488304Z,160,2,1108,C,A,14.030000000,100,0,341663401,130,165307,286219940,ARL,,13.11,100,1,13.03,2,1,12.98,200,1,12.86,100,1,12.73,100,1,12.71,100,1,12.5,700,1,12.46,100,1,12.43,700,1,12.42,700,1,13.47,15,1,13.48,100,1,13.74,2,1,14.08,100,1,14.22,100,1,14.27,100,1,14.43,200,1,14.46,200,1,14.48,700,1,14.49,100,1,2,341663401
2025-07-17T16:17:23.627704598Z,2025-07-17T16:17:23.627539425Z,160,2,1108,A,A,13.750000000,100,0,344225533,130,165173,286219941,ARL,,13.11,100,1,13.03,2,1,12.98,200,1,12.86,100,1,12.73,100,1,12.71,100,1,12.5,700,1,12.46,100,1,12.43,700,1,12.42,700,1,13.47,15,1,13.48,100,1,13.74,2,1,13.75,100,1,14.08,100,1,14.22,100,1,14.27,100,1,14.43,200,1,14.46,200,1,14.48,700,1,2,344225533
2025-07-17T16:17:23.653807815Z,2025-07-17T16:17:23.653641816Z,160,2,1108,A,A,15.370000000,100,0,344225829,130,165999,286220138,ARL,,13.11,100,1,13.03,2,1,12.98,200,1,12.86,100,1,12.73,100,1,12.71,100,1,12.5,700,1,12.46,100,1,12.43,700,1,12.42,700,1,13.47,15,1,13.48,100,1,13.74,2,1,13.75,100,1,14.08,100,1,14.22,100,1,14.27,100,1,14.43,200,1,14.46,200,1,14.48,700,1,2,344225829
2025-07-17T16:17:23.653821034Z,2025-07-17T16:17:23.653655443Z,160,2,1108,C,A,15.700000000,100,0,341661849,130,165591,286220139,ARL,,13.11,100,1,13.03,2,1,12.98,200,1,12.86,100,1,12.73,100,1,12.71,100,1,12.5,700,1,12.46,100,1,12.43,700,1,12.42,700,1,13.47,15,1,13.48,100,1,13.74,2,1,13.75,100,1,14.08,100,1,14.22,100,1,14.27,100,1,14.43,200,1,14.46,200,1,14.48,700,1,2,341661849
2025-07-17T16:17:24.832340976Z,2025-07-17T16:17:24.832175508Z,160,2,1108,C,A,13.470000000,15,0,344211173,130,165468,286237340,ARL,,13.11,100,1,13.03,2,1,12.98,200,1,12.86,100,1,12.73,100,1,12.71,100,1,12.5,700,1,12.46,100,1,12.43,700,1,12.42,700,1,13.48,100,1,13.74,2,1,13.75,100,1,14.08,100,1,14.22,100,1,14.27,100,1,14.43,200,1,14.46,200,1,14.48,700,1,14.49,100,1,2,344211173
2025-07-17T16:17:26.823562625Z,2025-07-17T16:17:26.823396428Z,160,2,1108,C,A,13.480000000,100,0,344225341,130,166197,286261717,ARL,,13.11,100,1,13.03,2,1,12.98,200,1,12.86,100,1,12.73,100,1,12.71,100,1,12.5,700,1,12.46,100,1,12.43,700,1,12.42,700,1,13.74,2,1,13.75,100,1,14.08,100,1,14.22,100,1,14.27,100,1,14.43,200,1,14.46,200,1,14.48,700,1,14.49,100,1,14.53,100,1,2,344225341
2025-07-17T16:17:26.823923686Z,2025-07-17T16:17:26.823758552Z,160,2,1108,A,A,15.680000000,100,0,344280537,130,165134,286261727,ARL,,13.11,100,1,13.03,2,1,12.98,200,1,12.86,100,1,12.73,100,1,12.71,100,1,12.5,700,1,12.46,100,1,12.43,700,1,12.42,700,1,13.74,2,1,13.75,100,1,14.08,100,1,14.22,100,1,14.27,100,1,14.43,200,1,14.46,200,1,14.48,700,1,14.49,100,1,14.53,100,1,2,344280537
2025-07-17T16:17:26.823937553Z,2025-07-17T16:17:26.823771696Z,160,2,1108,C,A,15.370000000,100,0,344225829,130,165857,286261728,ARL,,13.11,100,1,13.03,2,1,12.98,200,1,12.86,100,1,12.73,100,1,12.71,100,1,12.5,700,1,12.46,100,1,12.43,700,1,12.42,700,1,13.74,2,1,13.75,100,1,14.08,100,1,14.22,100,1,14.27,100,1,14.43,200,1,14.46,200,1,14.48,700,1,14.49,100,1,14.53,100,1,2,344225829
2025-07-17T16:17:26.824304510Z,2025-07-17T16:17:26.824137854Z,160,2,1108,C,A,14.530000000,100,0,344225385,0,166656,286261743,ARL,,13.11,100,1,13.03,2,1,12.98,200,1,12.86,100,1,12.73,100,1,12.71,100,1,12.5,700,1,12.46,100,1,12.43,700,1,12.42,700,1,13.74,2,1,13.75,100,1,14.08,100,1,14.22,100,1,14.27,100,1,14.43,200,1,14.46,200,1,14.48,700,1,14.49,100,1,14.54,700,1,2,344225385
2025-07-17T16:17:26.824304510Z,2025-07-17T16:17:26.824137854Z,160,2,1108,A,A,14.580000000,100,0,344280577,0,166656,286261743,ARL,,13.11,100,1,13.03,2,1,12.98,200,1,12.86,100,1,12.73,100,1,12.71,100,1,12.5,700,1,12.46,100,1,12.43,700,1,12.42,700,1,13.74,2,1,13.75,100,1,14.08,100,1,14.22,100,1,14.27,100,1,14.43,200,1,14.46,200,1,14.48,700,1,14.49,100,1,14.54,700,1,2,344280577
2025-07-17T16:17:26.824304510Z,2025-07-17T16:17:26.824138799Z,160,2,1108,C,A,14.080000000,100,0,344225397,130,165711,286261744,ARL,,13.11,100,1,13.03,2,1,12.98,200,1,12.86,100,1,12.73,100,1,12.71,100,1,12.5,700,1,12.46,100,1,12.43,700,1,12.42,700,1,13.74,2,1,13.75,100,1,14.22,100,1,14.27,100,1,14.43,200,1,14.46,200,1,14.48,700,1,14.49,100,1,14.54,700,1,14.56,700,1,2,344225397
2025-07-17T16:17:26.824657956Z,2025-07-17T16:17:26.824492765Z,160,2,1108,A,A,14.360000000,100,0,344280617,130,165191,286261759,ARL,,13.11,100,1,13.03,2,1,12.98,200,1,12.86,100,1,12.73,100,1,12.71,100,1,12.5,700,1,12.46,100,1,12.43,700,1,12.42,700,1,13.74,2,1,13.75,100,1,14.22,100,1,14.27,100,1,14.36,100,1,14.43,200,1,14.46,200,1,14.48,700,1,14.49,100,1,14.54,700,1,2,344280617
2025-07-17T16:17:26.825988253Z,2025-07-17T16:17:26.825823014Z,160,2,1108,C,A,14.270000000,100,0,344225453,130,165239,286261769,ARL,,13.11,100,1,13.03,2,1,12.98,200,1,12.86,100,1,12.73,100,1,12.71,100,1,12.5,700,1,12.46,100,1,12.43,700,1,12.42,700,1,13.74,2,1,13.75,100,1,14.22,100,1,14.36,100,1,14.43,200,1,14.46,200,1,14.48,700,1,14.49,100,1,14.54,700,1,14.56,700,1,2,344225453
2025-07-17T16:17:26.826051208Z,2025-07-17T16:17:26.825885765Z,160,2,1108,C,A,14.430000000,100,0,344225449,0,165443,286261770,ARL,,13.11,100,1,13.03,2,1,12.98,200,1,12.86,100,1,12.73,100,1,12.71,100,1,12.5,700,1,12.46,100,1,12.43,700,1,12.42,700,1,13.74,2,1,13.75,100,1,14.22,100,1,14.36,100,1,14.43,100,1,14.46,200,1,14.48,700,1,14.49,100,1,14.54,700,1,14.56,700,1,2,344225449
2025-07-17T16:17:26.826051208Z,2025-07-17T16:17:26.825885765Z,160,2,1108,A,A,14.720000000,100,0,344280641,130,165443,286261770,ARL,,13.11,100,1,13.03,2,1,12.98,200,1,12.86,100,1,12.73,100,1,12.71,100,1,12.5,700,1,12.46,100,1,12.43,700,1,12.42,700,1,13.74,2,1,13.75,100,1,14.22,100,1,14.36,100,1,14.43,100,1,14.46,200,1,14.48,700,1,14.49,100,1,14.54,700,1,14.56,700,1,2,344280641
2025-07-17T16:17:26.826159189Z,2025-07-17T16:17:26.825993909Z,160,2,1108,A,A,14.540000000,100,0,344280645,130,165280,286261771,ARL,,13.11,100,1,13.03,2,1,12.98,200,1,12.86,100,1,12.73,100,1,12.71,100,1,12.5,700,1,12.46,100,1,12.43,700,1,12.42,700,1,13.74,2,1,13.75,100,1,14.22,100,1,14.36,100,1,14.43,100,1,14.46,200,1,14.48,700,1,14.49,100,1,14.54,800,1,14.56,700,1,2,344280645
2025-07-17T16:17:26.826294122Z,2025-07-17T16:17:26.826128663Z,160,2,1108,C,A,14.830000000,100,0,344225405,0,165459,286261775,ARL,,13.11,100,1,13.03,2,1,12.98,200,1,12.86,100,1,12.73,100,1,12.71,100,1,12.5,700,1,12.46,100,1,12.43,700,1,12.42,700,1,13.74,2,1,13.75,100,1,14.22,100,1,14.36,100,1,14.43,100,1,14.46,200,1,14.48,700,1,14.49,100,1,14.54,800,1,14.56,700,1,2,344225405
2025-07-17T16:17:26.826294122Z,2025-07-17T16:17:26.826128663Z,160,2,1108,A,A,15.130000000,100,0,344280653,130,165459,286261775,ARL,,13.11,100,1,13.03,2,1,12.98,200,1,12.86,100,1,12.73,100,1,12.71,100,1,12.5,700,1,12.46,100,1,12.43,700,1,12.42,700,1,13.74,2,1,13.75,100,1,14.22,100,1,14.36,100,1,14.43,100,1,14.46,200,1,14.48,700,1,14.49,100,1,14.54,800,1,14.56,700,1,2,344280653
2025-07-17T16:17:26.828538841Z,2025-07-17T16:17:26.828373551Z,160,2,1108,C,A,13.750000000,100,0,344225533,130,165290,286261785,ARL,,13.11,100,1,13.03,2,1,12.98,200,1,12.86,100,1,12.73,100,1,12.71,100,1,12.5,700,1,12.46,100,1,12.43,700,1,12.42,700,1,13.74,2,1,14.22,100,1,14.36,100,1,14.43,100,1,14.46,200,1,14.48,700,1,14.49,100,1,14.54,800,1,14.56,700,1,14.58,100,1,2,344225533
2025-07-17T16:17:26.828589142Z,2025-07-17T16:17:26.828423432Z,160,2,1108,A,A,14.030000000,100,0,344280689,130,165710,286261786,ARL,,13.11,100,1,13.03,2,1,12.98,200,1,12.86,100,1,12.73,100,1,12.71,100,1,12.5,700,1,12.46,100,1,12.43,700,1,12.42,700,1,13.74,2,1,14.03,100,1,14.22,100,1,14.36,100,1,14.43,100,1,14.46,200,1,14.48,700,1,14.49,100,1,14.54,800,1,14.56,700,1,2,344280689
2025-07-17T16:17:26.828846606Z,2025-07-17T16:17:26.828681062Z,160,2,1108,C,A,13.740000000,2,0,340449865,0,165544,286261788,ARL,,13.11,100,1,13.03,2,1,12.98,200,1,12.86,100,1,12.73,100,1,12.71,100,1,12.5,700,1,12.46,100,1,12.43,700,1,12.42,700,1,14.03,100,1,14.22,100,1,14.36,100,1,14.43,100,1,14.46,200,1,14.48,700,1,14.49,100,1,14.54,800,1,14.56,700,1,14.58,100,1,2,340449865
2025-07-17T16:17:26.828846606Z,2025-07-17T16:17:26.828681062Z,160,2,1108,A,A,13.970000000,2,0,344280721,130,165544,286261788,ARL,,13.11,100,1,13.03,2,1,12.98,200,1,12.86,100,1,12.73,100,1,12.71,100,1,12.5,700,1,12.46,100,1,12.43,700,1,12.42,700,1,13.97,2,1,14.03,100,1,14.22,100,1,14.36,100,1,14.43,100,1,14.46,200,1,14.48,700,1,14.49,100,1,14.54,800,1,14.56,700,1,2,344280721
2025-07-17T16:17:26.830066702Z,2025-07-17T16:17:26.829901530Z,160,2,1108,C,A,14.720000000,100,0,344280641,0,165172,286262023,ARL,,13.11,100,1,13.03,2,1,12.98,200,1,12.86,100,1,12.73,100,1,12.71,100,1,12.5,700,1,12.46,100,1,12.43,700,1,12.42,700,1,13.97,2,1,14.03,100,1,14.22,100,1,14.36,100,1,14.43,100,1,14.46,200,1,14.48,700,1,14.49,100,1,14.54,800,1,14.56,700,1,2,344280641
2025-07-17T16:17:26.830066702Z,2025-07-17T16:17:26.829901530Z,160,2,1108,A,A,14.960000000,100,0,344280825,130,165172,286262023,ARL,,13.11,100,1,13.03,2,1,12.98,200,1,12.86,100,1,12.73,100,1,12.71,100,1,12.5,700,1,12.46,100,1,12.43,700,1,12.42,700,1,13.97,2,1,14.03,100,1,14.22,100,1,14.36,100,1,14.43,100,1,14.46,200,1,14.48,700,1,14.49,100,1,14.54,800,1,14.56,700,1,2,344280825
2025-07-17T16:17:26.832026257Z,2025-07-17T16:17:26.831860798Z,160,2,1108,C,A,17.120000000,100,0,344225457,0,165459,286262118,ARL,,13.11,100,1,13.03,2,1,12.98,200,1,12.86,100,1,12.73,100,1,12.71,100,1,12.5,700,1,12.46,100,1,12.43,700,1,12.42,700,1,13.97,2,1,14.03,100,1,14.22,100,1,14.36,100,1,14.43,100,1,14.46,200,1,14.48,700,1,14.49,100,1,14.54,800,1,14.56,700,1,2,344225457
2025-07-17T16:17:26.832026257Z,2025-07-17T16:17:26.831860798Z,160,2,1108,A,A,17.760000000,100,0,344280917,130,165459,286262118,ARL,,13.11,100,1,13.03,2,1,12.98,200,1,12.86,100,1,12.73,100,1,12.71,100,1,12.5,700,1,12.46,100,1,12.43,700,1,12.42,700,1,13.97,2,1,14.03,100,1,14.22,100,1,14.36,100,1,14.43,100,1,14.46,200,1,14.48,700,1,14.49,100,1,14.54,800,1,14.56,700,1,2,344280917
2025-07-17T16:17:26.833194882Z,2025-07-17T16:17:26.833029512Z,160,2,1108,C,A,15.510000000,100,0,344225393,0,165370,286262137,ARL,,13.11,100,1,13.03,2,1,12.98,200,1,12.86,100,1,12.73,100,1,12.71,100,1,12.5,700,1,12.46,100,1,12.43,700,1,12.42,700,1,13.97,2,1,14.03,100,1,14.22,100,1,14.36,100,1,14.43,100,1,14.46,200,1,14.48,700,1,14.49,100,1,14.54,800,1,14.56,700,1,2,344225393
2025-07-17T16:17:26.833194882Z,2025-07-17T16:17:26.833029512Z,160,2,1108,A,A,16.080000000,100,0,344280941,130,165370,286262137,ARL,,13.11,100,1,13.03,2,1,12.98,200,1,12.86,100,1,12.73,100,1,12.71,100,1,12.5,700,1,12.46,100,1,12.43,700,1,12.42,700,1,13.97,2,1,14.03,100,1,14.22,100,1,14.36,100,1,14.43,100,1,14.46,200,1,14.48,700,1,14.49,100,1,14.54,800,1,14.56,700,1,2,344280941
2025-07-17T16:17:26.834911649Z,2025-07-17T16:17:26.834746475Z,160,2,1108,C,A,14.030000000,100,0,344280689,130,165174,286262165,ARL,,13.11,100,1,13.03,2,1,12.98,200,1,12.86,100,1,12.73,100,1,12.71,100,1,12.5,700,1,12.46,100,1,12.43,700,1,12.42,700,1,13.97,2,1,14.22,100,1,14.36,100,1,14.43,100,1,14.46,200,1,14.48,700,1,14.49,100,1,14.54,800,1,14.56,700,1,14.58,100,1,2,344280689
2025-07-17T16:17:26.834961494Z,2025-07-17T16:17:26.834796238Z,160,2,1108,A,A,14.250000000,100,0,344280953,130,165256,286262166,ARL,,13.11,100,1,13.03,2,1,12.98,200,1,12.86,100,1,12.73,100,1,12.71,100,1,12.5,700,1,12.46,100,1,12.43,700,1,12.42,700,1,13.97,2,1,14.22,100,1,14.25,100,1,14.36,100,1,14.43,100,1,14.46,200,1,14.48,700,1,14.49,100,1,14.54,800,1,14.56,700,1,2,344280953
2025-07-17T16:17:26.846567340Z,2025-07-17T16:17:26.846401696Z,160,2,1108,C,A,14.830000000,100,0,344225485,0,165644,286262231,ARL,,13.11,100,1,13.03,2,1,12.98,200,1,12.86,100,1,12.73,100,1,12.71,100,1,12.5,700,1,12.46,100,1,12.43,700,1,12.42,700,1,13.97,2,1,14.22,100,1,14.25,100,1,14.36,100,1,14.43,100,1,14.46,200,1,14.48,700,1,14.49,100,1,14.54,800,1,14.56,700,1,2,344225485
2025-07-17T16:17:26.846567340Z,2025-07-17T16:17:26.846401696Z,160,2,1108,A,A,15.380000000,100,0,344281229,130,165644,286262231,ARL,,13.11,100,1,13.03,2,1,12.98,200,1,12.86,100,1,12.73,100,1,12.71,100,1,12.5,700,1,12.46,100,1,12.43,700,1,12.42,700,1,13.97,2,1,14.22,100,1,14.25,100,1,14.36,100,1,14.43,100,1,14.46,200,1,14.48,700,1,14.49,100,1,14.54,800,1,14.56,700,1,2,344281229
2025-07-17T16:17:26.849670659Z,2025-07-17T16:17:26.849505109Z,160,2,1108,C,A,14.430000000,100,0,344225489,0,165550,286262262,ARL,,13.11,100,1,13.03,2,1,12.98,200,1,12.86,100,1,12.73,100,1,12.71,100,1,12.5,700,1,12.46,100,1,12.43,700,1,12.42,700,1,13.97,2,1,14.22,100,1,14.25,100,1,14.36,100,1,14.46,200,1,14.48,700,1,14.49,100,1,14.54,800,1,14.56,700,1,14.58,100,1,2,344225489
2025-07-17T16:17:26.849670659Z,2025-07-17T16:17:26.849505109Z,160,2,1108,A,A,14.960000000,100,0,344281257,130,165550,286262262,ARL,,13.11,100,1,13.03,2,1,12.98,200,1,12.86,100,1,12.73,100,1,12.71,100,1,12.5,700,1,12.46,100,1,12.43,700,1,12.42,700,1,13.97,2,1,14.22,100,1,14.25,100,1,14.36,100,1,14.46,200,1,14.48,700,1,14.49,100,1,14.54,800,1,14.56,700,1,14.58,100,1,2,344281257
2025-07-17T16:17:26.874430238Z,2025-07-17T16:17:26.874264677Z,160,2,1108,C,A,14.580000000,100,0,344280577,0,165561,286262413,ARL,,13.11,100,1,13.03,2,1,12.98,200,1,12.86,100,1,12.73,100,1,12.71,100,1,12.5,700,1,12.46,100,1,12.43,700,1,12.42,700,1,13.97,2,1,14.22,100,1,14.25,100,1,14.36,100,1,14.46,200,1,14.48,700,1,14.49,100,1,14.54,800,1,14.56,700,1,14.68,700,1,2,344280577
2025-07-17T16:17:26.874430238Z,2025-07-17T16:17:26.874264677Z,160,2,1108,A,A,15.050000000,100,0,344281457,130,165561,286262413,ARL,,13.11,100,1,13.03,2,1,12.98,200,1,12.86,100,1,12.73,100,1,12.71,100,1,12.5,700,1,12.46,100,1,12.43,700,1,12.42,700,1,13.97,2,1,14.22,100,1,14.25,100,1,14.36,100,1,14.46,200,1,14.48,700,1,14.49,100,1,14.54,800,1,14.56,700,1,14.68,700,1,2,344281457
2025-07-17T16:17:27.000782790Z,2025-07-17T16:17:27.000617575Z,160,2,1108,A,A,13.980000000,100,0,344283633,130,165215,286264622,ARL,,13.11,100,1,13.03,2,1,12.98,200,1,12.86,100,1,12.73,100,1,12.71,100,1,12.5,700,1,12.46,100,1,12.43,700,1,12.42,700,1,13.97,2,1,13.98,100,1,14.22,100,1,14.25,100,1,14.36,100,1,14.46,200,1,14.48,700,1,14.49,100,1,14.54,800,1,14.56,700,1,2,344283633
2025-07-17T16:17:27.204893988Z,2025-07-17T16:17:27.204728176Z,160,2,1108,C,A,14.220000000,100,0,339365193,130,165812,286267644,ARL,,13.11,100,1,13.03,2,1,12.98,200,1,12.86,100,1,12.73,100,1,12.71,100,1,12.5,700,1,12.46,100,1,12.43,700,1,12.42,700,1,13.97,2,1,13.98,100,1,14.25,100,1,14.36,100,1,14.46,200,1,14.48,700,1,14.49,100,1,14.54,800,1,14.56,700,1,14.68,700,1,2,339365193
2025-07-17T16:17:27.204895267Z,2025-07-17T16:17:27.204730160Z,160,2,1108,A,A,14.530000000,100,0,344288585,130,165107,286267645,ARL,,13.11,100,1,13.03,2,1,12.98,200,1,12.86,100,1,12.73,100,1,12.71,100,1,12.5,700,1,12.46,100,1,12.43,700,1,12.42,700,1,13.97,2,1,13.98,100,1,14.25,100,1,14.36,100,1,14.46,200,1,14.48,700,1,14.49,100,1,14.53,100,1,14.54,800,1,14.56,700,1,2,344288585
2025-07-17T16:17:27.381792167Z,2025-07-17T16:17:27.381626601Z,160,2,1108,A,A,14.810000000,100,0,344292849,130,165566,286271009,ARL,,13.11,100,1,13.03,2,1,12.98,200,1,12.86,100,1,12.73,100,1,12.71,100,1,12.5,700,1,12.46,100,1,12.43,700,1,12.42,700,1,13.97,2,1,13.98,100,1,14.25,100,1,14.36,100,1,14.46,200,1,14.48,700,1,14.49,100,1,14.53,100,1,14.54,800,1,14.56,700,1,2,344292849
2025-07-17T16:17:27.381809823Z,2025-07-17T16:17:27.381644366Z,160,2,1108,C,A,14.490000000,100,0,339366385,130,165457,286271010,ARL,,13.11,100,1,13.03,2,1,12.98,200,1,12.86,100,1,12.73,100,1,12.71,100,1,12.5,700,1,12.46,100,1,12.43,700,1,12.42,700,1,13.97,2,1,13.98,100,1,14.25,100,1,14.36,100,1,14.46,200,1,14.48,700,1,14.53,100,1,14.54,800,1,14.56,700,1,14.68,700,1,2,339366385
2025-07-17T16:17:27.443162448Z,2025-07-17T16:17:27.442997426Z,160,2,1108,C,A,14.360000000,100,0,344280617,130,165022,286271749,ARL,,13.11,100,1,13.03,2,1,12.98,200,1,12.86,100,1,12.73,100,1,12.71,100,1,12.5,700,1,12.46,100,1,12.43,700,1,12.42,700,1,13.97,2,1,13.98,100,1,14.25,100,1,14.46,200,1,14.48,700,1,14.53,100,1,14.54,800,1,14.56,700,1,14.68,700,1,14.81,100,1,2,344280617
2025-07-17T16:17:27.443512590Z,2025-07-17T16:17:27.443347265Z,160,2,1108,A,A,14.600000000,100,0,344294245,130,165325,286271751,ARL,,13.11,100,1,13.03,2,1,12.98,200,1,12.86,100,1,12.73,100,1,12.71,100,1,12.5,700,1,12.46,100,1,12.43,700,1,12.42,700,1,13.97,2,1,13.98,100,1,14.25,100,1,14.46,200,1,14.48,700,1,14.53,100,1,14.54,800,1,14.56,700,1,14.6,100,1,14.68,700,1,2,344294245
2025-07-17T16:17:27.829055288Z,2025-07-17T16:17:27.828890080Z,160,2,1108,C,A,14.540000000,100,0,344280645,0,165208,286275353,ARL,,13.11,100,1,13.03,2,1,12.98,200,1,12.86,100,1,12.73,100,1,12.71,100,1,12.5,700,1,12.46,100,1,12.43,700,1,12.42,700,1,13.97,2,1,13.98,100,1,14.25,100,1,14.46,200,1,14.48,700,1,14.53,100,1,14.54,700,1,14.56,700,1,14.6,100,1,14.68,700,1,2,344280645
2025-07-17T16:17:27.829055288Z,2025-07-17T16:17:27.828890080Z,160,2,1108,A,A,14.770000000,100,0,344300085,130,165208,286275353,ARL,,13.11,100,1,13.03,2,1,12.98,200,1,12.86,100,1,12.73,100,1,12.71,100,1,12.5,700,1,12.46,100,1,12.43,700,1,12.42,700,1,13.97,2,1,13.98,100,1,14.25,100,1,14.46,200,1,14.48,700,1,14.53,100,1,14.54,700,1,14.56,700,1,14.6,100,1,14.68,700,1,2,344300085
2025-07-17T16:17:39.514690751Z,2025-07-17T16:17:39.514525397Z,160,2,1108,A,A,13.470000000,15,0,344587533,130,165354,286508705,ARL,,13.11,100,1,13.03,2,1,12.98,200,1,12.86,100,1,12.73,100,1,12.71,100,1,12.5,700,1,12.46,100,1,12.43,700,1,12.42,700,1,13.47,15,1,13.97,2,1,13.98,100,1,14.25,100,1,14.46,200,1,14.48,700,1,14.53,100,1,14.54,700,1,14.56,700,1,14.6,100,1,2,344587533
2025-07-17T16:17:39.829017289Z,2025-07-17T16:17:39.828851797Z,160,2,1108,C,A,14.460000000,100,0,339739285,0,165492,286513833,ARL,,13.11,100,1,13.03,2,1,12.98,200,1,12.86,100,1,12.73,100,1,12.71,100,1,12.5,700,1,12.46,100,1,12.43,700,1,12.42,700,1,13.47,15,1,13.97,2,1,13.98,100,1,14.25,100,1,14.46,100,1,14.48,700,1,14.53,100,1,14.54,700,1,14.56,700,1,14.6,100,1,2,339739285
2025-07-17T16:17:39.829017289Z,2025-07-17T16:17:39.828851797Z,160,2,1108,A,A,14.350000000,100,0,344593405,130,165492,286513833,ARL,,13.11,100,1,13.03,2,1,12.98,200,1,12.86,100,1,12.73,100,1,12.71,100,1,12.5,700,1,12.46,100,1,12.43,700,1,12.42,700,1,13.47,15,1,13.97,2,1,13.98,100,1,14.25,100,1,14.35,100,1,14.46,100,1,14.48,700,1,14.53,100,1,14.54,700,1,14.56,700,1,2,344593405
2025-07-17T16:17:39.829247357Z,2025-07-17T16:17:39.829081898Z,160,2,1108,C,A,14.460000000,100,0,339739297,0,165459,286513835,ARL,,13.11,100,1,13.03,2,1,12.98,200,1,12.86,100,1,12.73,100,1,12.71,100,1,12.5,700,1,12.46,100,1,12.43,700,1,12.42,700,1,13.47,15,1,13.97,2,1,13.98,100,1,14.25,100,1,14.35,100,1,14.48,700,1,14.53,100,1,14.54,700,1,14.56,700,1,14.6,100,1,2,339739297
2025-07-17T16:17:39.829247357Z,2025-07-17T16:17:39.829081898Z,160,2,1108,A,A,14.350000000,100,0,344593409,130,165459,286513835,ARL,,13.11,100,1,13.03,2,1,12.98,200,1,12.86,100,1,12.73,100,1,12.71,100,1,12.5,700,1,12.46,100,1,12.43,700,1,12.42,700,1,13.47,15,1,13.97,2,1,13.98,100,1,14.25,100,1,14.35,200,1,14.48,700,1,14.53,100,1,14.54,700,1,14.56,700,1,14.6,100,1,2,344593409
2025-07-17T16:17:40.321326768Z,2025-07-17T16:17:40.321161439Z,160,2,1108,C,A,13.980000000,100,0,344283633,0,165329,286524785,ARL,,13.11,100,1,13.03,2,1,12.98,200,1,12.86,100,1,12.73,100,1,12.71,100,1,12.5,700,1,12.46,100,1,12.43,700,1,12.42,700,1,13.47,15,1,13.97,2,1,14.25,100,1,14.35,200,1,14.48,700,1,14.53,100,1,14.54,700,1,14.56,700,1,14.6,100,1,14.68,700,1,2,344283633
2025-07-17T16:17:40.321326768Z,2025-07-17T16:17:40.321161439Z,160,2,1108,A,A,13.480000000,100,0,344607833,130,165329,286524785,ARL,,13.11,100,1,13.03,2,1,12.98,200,1,12.86,100,1,12.73,100,1,12.71,100,1,12.5,700,1,12.46,100,1,12.43,700,1,12.42,700,1,13.47,15,1,13.48,100,1,13.97,2,1,14.25,100,1,14.35,200,1,14.48,700,1,14.53,100,1,14.54,700,1,14.56,700,1,14.6,100,1,2,344607833
2025-07-17T16:17:40.322064038Z,2025-07-17T16:17:40.321898765Z,160,2,1108,C,A,14.600000000,100,0,344294245,130,165273,286524815,ARL,,13.11,100,1,13.03,2,1,12.98,200,1,12.86,100,1,12.73,100,1,12.71,100,1,12.5,700,1,12.46,100,1,12.43,700,1,12.42,700,1,13.47,15,1,13.48,100,1,13.97,2,1,14.25,100,1,14.35,200,1,14.48,700,1,14.53,100,1,14.54,700,1,14.56,700,1,14.68,700,1,2,344294245
2025-07-17T16:17:40.322069742Z,2025-07-17T16:17:40.321903984Z,160,2,1108,C,A,15.050000000,100,0,344281457,0,165758,286524817,ARL,,13.11,100,1,13.03,2,1,12.98,200,1,12.86,100,1,12.73,100,1,12.71,100,1,12.5,700,1,12.46,100,1,12.43,700,1,12.42,700,1,13.47,15,1,13.48,100,1,13.97,2,1,14.25,100,1,14.35,200,1,14.48,700,1,14.53,100,1,14.54,700,1,14.56,700,1,14.68,700,1,2,344281457
2025-07-17T16:17:40.322069742Z,2025-07-17T16:17:40.321903984Z,160,2,1108,A,A,14.530000000,100,0,344607889,130,165758,286524817,ARL,,13.11,100,1,13.03,2,1,12.98,200,1,12.86,100,1,12.73,100,1,12.71,100,1,12.5,700,1,12.46,100,1,12.43,700,1,12.42,700,1,13.47,15,1,13.48,100,1,13.97,2,1,14.25,100,1,14.35,200,1,14.48,700,1,14.53,200,1,14.54,700,1,14.56,700,1,14.68,700,1,2,344607889
2025-07-17T16:17:40.322416015Z,2025-07-17T16:17:40.322250847Z,160,2,1108,A,A,14.080000000,100,0,344607893,130,165168,286524822,ARL,,13.11,100,1,13.03,2,1,12.98,200,1,12.86,100,1,12.73,100,1,12.71,100,1,12.5,700,1,12.46,100,1,12.43,700,1,12.42,700,1,13.47,15,1,13.48,100,1,13.97,2,1,14.08,100,1,14.25,100,1,14.35,200,1,14.48,700,1,14.53,200,1,14.54,700,1,14.56,700,1,2,344607893
2025-07-17T16:17:40.329180897Z,2025-07-17T16:17:40.329015669Z,160,2,1108,C,A,14.250000000,100,0,344280953,130,165228,286524967,ARL,,13.11,100,1,13.03,2,1,12.98,200,1,12.86,100,1,12.73,100,1,12.71,100,1,12.5,700,1,12.46,100,1,12.43,700,1,12.42,700,1,13.47,15,1,13.48,100,1,13.97,2,1,14.08,100,1,14.35,200,1,14.48,700,1,14.53,200,1,14.54,700,1,14.56,700,1,14.68,700,1,2,344280953
2025-07-17T16:17:40.329233157Z,2025-07-17T16:17:40.329067996Z,160,2,1108,A,A,13.750000000,100,0,344608193,130,165161,286524969,ARL,,13.11,100,1,13.03,2,1,12.98,200,1,12.86,100,1,12.73,100,1,12.71,100,1,12.5,700,1,12.46,100,1,12.43,700,1,12.42,700,1,13.47,15,1,13.48,100,1,13.75,100,1,13.97,2,1,14.08,100,1,14.35,200,1,14.48,700,1,14.53,200,1,14.54,700,1,14.56,700,1,2,344608193
2025-07-17T16:17:40.330448099Z,2025-07-17T16:17:40.330282519Z,160,2,1108,C,A,15.130000000,100,0,344280653,0,165580,286524982,ARL,,13.11,100,1,13.03,2,1,12.98,200,1,12.86,100,1,12.73,100,1,12.71,100,1,12.5,700,1,12.46,100,1,12.43,700,1,12.42,700,1,13.47,15,1,13.48,100,1,13.75,100,1,13.97,2,1,14.08,100,1,14.35,200,1,14.48,700,1,14.53,200,1,14.54,700,1,14.56,700,1,2,344280653
2025-07-17T16:17:40.330448099Z,2025-07-17T16:17:40.330282519Z,160,2,1108,A,A,14.830000000,100,0,344608205,130,165580,286524982,ARL,,13.11,100,1,13.03,2,1,12.98,200,1,12.86,100,1,12.73,100,1,12.71,100,1,12.5,700,1,12.46,100,1,12.43,700,1,12.42,700,1,13.47,15,1,13.48,100,1,13.75,100,1,13.97,2,1,14.08,100,1,14.35,200,1,14.48,700,1,14.53,200,1,14.54,700,1,14.56,700,1,2,344608205
2025-07-17T16:17:40.331429414Z,2025-07-17T16:17:40.331264268Z,160,2,1108,C,A,14.770000000,100,0,344300085,130,165146,286524998,ARL,,13.11,100,1,13.03,2,1,12.98,200,1,12.86,100,1,12.73,100,1,12.71,100,1,12.5,700,1,12.46,100,1,12.43,700,1,12.42,700,1,13.47,15,1,13.48,100,1,13.75,100,1,13.97,2,1,14.08,100,1,14.35,200,1,14.48,700,1,14.53,200,1,14.54,700,1,14.56,700,1,2,344300085
2025-07-17T16:17:40.331551656Z,2025-07-17T16:17:40.331386492Z,160,2,1108,A,A,14.270000000,100,0,344608225,130,165164,286525005,ARL,,13.11,100,1,13.03,2,1,12.98,200,1,12.86,100,1,12.73,100,1,12.71,100,1,12.5,700,1,12.46,100,1,12.43,700,1,12.42,700,1,13.47,15,1,13.48,100,1,13.75,100,1,13.97,2,1,14.08,100,1,14.27,100,1,14.35,200,1,14.48,700,1,14.53,200,1,14.54,700,1,2,344608225
