ts_recv,ts_event,rtype,publisher_id,instrument_id,action,side,price,size,channel_id,order_id,flags,ts_in_delta,sequence,symbol,bid_px_00,bid_sz_00,bid_ct_00,bid_px_01,bid_sz_01,bid_ct_01,bid_px_02,bid_sz_02,bid_ct_02,bid_px_03,bid_sz_03,bid_ct_03,bid_px_04,bid_sz_04,bid_ct_04,bid_px_05,bid_sz_05,bid_ct_05,bid_px_06,bid_sz_06,bid_ct_06,bid_px_07,bid_sz_07,bid_ct_07,bid_px_08,bid_sz_08,bid_ct_08,bid_px_09,bid_sz_09,bid_ct_09,ask_px_00,ask_sz_00,ask_ct_00,ask_px_01,ask_sz_01,ask_ct_01,ask_px_02,ask_sz_02,ask_ct_02,ask_px_03,ask_sz_03,ask_ct_03,ask_px_04,ask_sz_04,ask_ct_04,ask_px_05,ask_sz_05,ask_ct_05,ask_px_06,ask_sz_06,ask_ct_06,ask_px_07,ask_sz_07,ask_ct_07,ask_px_08,ask_sz_08,ask_ct_08,ask_px_09,ask_sz_09,ask_ct_09,symbol,order_id
2025-07-17T16:02:04.840132668Z,2025-07-17T16:02:04.839967173Z,160,2,1108,A,A,13.540000000,100,0,325400045,130,165495,271432190,ARL,,13.04,2,1,13.03,100,1,13.02,100,1,12.73,100,1,12.71,100,1,12.5,700,1,12.46,200,1,12.43,700,1,12.42,700,1,12.37,700,1,13.53,15,1,13.54,100,1,13.55,15,1,13.59,100,1,13.83,100,1,13.92,2,1,14.19,100,1,14.28,100,1,14.43,200,1,14.51,100,1,2,325400045
2025-07-17T16:02:04.840171240Z,2025-07-17T16:02:04.840006082Z,160,2,1108,A,A,14.270000000,700,0,325400053,130,165158,271432192,ARL,,13.04,2,1,13.03,100,1,13.02,100,1,12.73,100,1,12.71,100,1,12.5,700,1,12.46,200,1,12.43,700,1,12.42,700,1,12.37,700,1,13.53,15,1,13.54,100,1,13.55,15,1,13.59,100,1,13.83,100,1,13.92,2,1,14.19,100,1,14.27,700,1,14.28,100,1,14.43,200,1,2,325400053
2025-07-17T16:02:04.840210880Z,2025-07-17T16:02:04.840045694Z,160,2,1108,C,A,14.680000000,700,0,283592941,130,165186,271432193,ARL,,13.04,2,1,13.03,100,1,13.02,100,1,12.73,100,1,12.71,100,1,12.5,700,1,12.46,200,1,12.43,700,1,12.42,700,1,12.37,700,1,13.53,15,1,13.54,100,1,13.55,15,1,13.59,100,1,13.83,100,1,13.92,2,1,14.19,100,1,14.27,700,1,14.28,100,1,14.43,200,1,2,283592941
2025-07-17T16:02:04.840877603Z,2025-07-17T16:02:04.840711803Z,160,2,1108,C,A,14.630000000,100,0,324942257,0,165800,271432231,ARL,,13.04,2,1,13.03,100,1,13.02,100,1,12.73,100,1,12.71,100,1,12.5,700,1,12.46,200,1,12.43,700,1,12.42,700,1,12.37,700,1,13.53,15,1,13.54,100,1,13.55,15,1,13.59,100,1,13.83,100,1,13.92,2,1,14.19,100,1,14.27,700,1,14.28,100,1,14.43,200,1,2,324942257
2025-07-17T16:02:04.840877603Z,2025-07-17T16:02:04.840711803Z,160,2,1108,A,A,14.590000000,100,0,325400105,130,165800,271432231,ARL,,13.04,2,1,13.03,100,1,13.02,100,1,12.73,100,1,12.71,100,1,12.5,700,1,12.46,200,1,12.43,700,1,12.42,700,1,12.37,700,1,13.53,15,1,13.54,100,1,13.55,15,1,13.59,100,1,13.83,100,1,13.92,2,1,14.19,100,1,14.27,700,1,14.28,100,1,14.43,200,1,2,325400105
2025-07-17T16:02:11.249291142Z,2025-07-17T16:02:11.249125653Z,160,2,1108,C,A,14.530000000,100,0,323775457,0,165489,271526467,ARL,,13.04,2,1,13.03,100,1,13.02,100,1,12.73,100,1,12.71,100,1,12.5,700,1,12.46,200,1,12.43,700,1,12.42,700,1,12.37,700,1,13.53,15,1,13.54,100,1,13.55,15,1,13.59,100,1,13.83,100,1,13.92,2,1,14.19,100,1,14.27,700,1,14.28,100,1,14.43,200,1,2,323775457
2025-07-17T16:02:11.249291142Z,2025-07-17T16:02:11.249125653Z,160,2,1108,A,A,14.420000000,100,0,325520705,130,165489,271526467,ARL,,13.04,2,1,13.03,100,1,13.02,100,1,12.73,100,1,12.71,100,1,12.5,700,1,12.46,200,1,12.43,700,1,12.42,700,1,12.37,700,1,13.53,15,1,13.54,100,1,13.55,15,1,13.59,100,1,13.83,100,1,13.92,2,1,14.19,100,1,14.27,700,1,14.28,100,1,14.42,100,1,2,325520705
2025-07-17T16:02:15.062774661Z,2025-07-17T16:02:15.062605521Z,160,2,1108,C,A,13.530000000,15,0,325382429,128,169140,271576282,ARL,,13.04,2,1,13.03,100,1,13.02,100,1,12.73,100,1,12.71,100,1,12.5,700,1,12.46,200,1,12.43,700,1,12.42,700,1,12.37,700,1,13.54,100,1,13.55,15,1,13.59,100,1,13.83,100,1,13.92,2,1,14.19,100,1,14.27,700,1,14.28,100,1,14.42,100,1,14.43,200,1,2,325382429
2025-07-17T16:02:15.068449048Z,2025-07-17T16:02:15.068283706Z,160,2,1108,C,A,13.550000000,15,0,325109165,130,165342,271577104,ARL,,13.04,2,1,13.03,100,1,13.02,100,1,12.73,100,1,12.71,100,1,12.5,700,1,12.46,200,1,12.43,700,1,12.42,700,1,12.37,700,1,13.54,100,1,13.59,100,1,13.83,100,1,13.92,2,1,14.19,100,1,14.27,700,1,14.28,100,1,14.42,100,1,14.43,200,1,14.51,100,1,2,325109165
2025-07-17T16:02:20.635028489Z,2025-07-17T16:02:20.634863301Z,160,2,1108,C,A,13.540000000,100,0,325400045,130,165188,271675842,ARL,,13.04,2,1,13.03,100,1,13.02,100,1,12.73,100,1,12.71,100,1,12.5,700,1,12.46,200,1,12.43,700,1,12.42,700,1,12.37,700,1,13.59,100,1,13.83,100,1,13.92,2,1,14.19,100,1,14.27,700,1,14.28,100,1,14.42,100,1,14.43,200,1,14.51,100,1,14.56,800,1,2,325400045
2025-07-17T16:02:20.635782472Z,2025-07-17T16:02:20.635616654Z,160,2,1108,C,A,14.590000000,100,0,325400105,0,165818,271675858,ARL,,13.04,2,1,13.03,100,1,13.02,100,1,12.73,100,1,12.71,100,1,12.5,700,1,12.46,200,1,12.43,700,1,12.42,700,1,12.37,700,1,13.59,100,1,13.83,100,1,13.92,2,1,14.19,100,1,14.27,700,1,14.28,100,1,14.42,100,1,14.43,200,1,14.51,100,1,14.56,800,1,2,325400105
2025-07-17T16:02:20.635782472Z,2025-07-17T16:02:20.635616654Z,160,2,1108,A,A,14.640000000,100,0,325714169,130,165818,271675858,ARL,,13.04,2,1,13.03,100,1,13.02,100,1,12.73,100,1,12.71,100,1,12.5,700,1,12.46,200,1,12.43,700,1,12.42,700,1,12.37,700,1,13.59,100,1,13.83,100,1,13.92,2,1,14.19,100,1,14.27,700,1,14.28,100,1,14.42,100,1,14.43,200,1,14.51,100,1,14.56,800,1,2,325714169
2025-07-17T16:02:20.650466751Z,2025-07-17T16:02:20.650301212Z,160,2,1108,C,A,13.590000000,100,0,325022101,130,165539,271676032,ARL,,13.04,2,1,13.03,100,1,13.02,100,1,12.73,100,1,12.71,100,1,12.5,700,1,12.46,200,1,12.43,700,1,12.42,700,1,12.37,700,1,13.83,100,1,13.92,2,1,14.19,100,1,14.27,700,1,14.28,100,1,14.42,100,1,14.43,200,1,14.51,100,1,14.56,800,1,14.57,100,1,2,325022101
2025-07-17T16:02:20.650501448Z,2025-07-17T16:02:20.650335946Z,160,2,1108,C,A,14.270000000,700,0,325400053,130,165502,271676033,ARL,,13.04,2,1,13.03,100,1,13.02,100,1,12.73,100,1,12.71,100,1,12.5,700,1,12.46,200,1,12.43,700,1,12.42,700,1,12.37,700,1,13.83,100,1,13.92,2,1,14.19,100,1,14.28,100,1,14.42,100,1,14.43,200,1,14.51,100,1,14.56,800,1,14.57,100,1,14.6,700,1,2,325400053
2025-07-17T16:02:20.650546483Z,2025-07-17T16:02:20.650381040Z,160,2,1108,A,A,14.530000000,700,0,325714545,130,165443,271676035,ARL,,13.04,2,1,13.03,100,1,13.02,100,1,12.73,100,1,12.71,100,1,12.5,700,1,12.46,200,1,12.43,700,1,12.42,700,1,12.37,700,1,13.83,100,1,13.92,2,1,14.19,100,1,14.28,100,1,14.42,100,1,14.43,200,1,14.51,100,1,14.53,700,1,14.56,800,1,14.57,100,1,2,325714545
2025-07-17T16:02:20.651186537Z,2025-07-17T16:02:20.651020858Z,160,2,1108,C,A,14.420000000,100,0,325520705,0,165679,271676048,ARL,,13.04,2,1,13.03,100,1,13.02,100,1,12.73,100,1,12.71,100,1,12.5,700,1,12.46,200,1,12.43,700,1,12.42,700,1,12.37,700,1,13.83,100,1,13.92,2,1,14.19,100,1,14.28,100,1,14.43,200,1,14.51,100,1,14.53,700,1,14.56,800,1,14.57,100,1,14.6,700,1,2,325520705
2025-07-17T16:02:20.651186537Z,2025-07-17T16:02:20.651020858Z,160,2,1108,A,A,14.730000000,100,0,325714577,130,165679,271676048,ARL,,13.04,2,1,13.03,100,1,13.02,100,1,12.73,100,1,12.71,100,1,12.5,700,1,12.46,200,1,12.43,700,1,12.42,700,1,12.37,700,1,13.83,100,1,13.92,2,1,14.19,100,1,14.28,100,1,14.43,200,1,14.51,100,1,14.53,700,1,14.56,800,1,14.57,100,1,14.6,700,1,2,325714577
2025-07-17T16:02:20.651201182Z,2025-07-17T16:02:20.651035000Z,160,2,1108,C,A,14.190000000,100,0,324942273,130,166182,271676049,ARL,,13.04,2,1,13.03,100,1,13.02,100,1,12.73,100,1,12.71,100,1,12.5,700,1,12.46,200,1,12.43,700,1,12.42,700,1,12.37,700,1,13.83,100,1,13.92,2,1,14.28,100,1,14.43,200,1,14.51,100,1,14.53,700,1,14.56,800,1,14.57,100,1,14.6,700,1,14.64,100,1,2,324942273
2025-07-17T16:02:20.651459317Z,2025-07-17T16:02:20.651293729Z,160,2,1108,C,A,17.250000000,100,0,324942361,0,165588,271676055,ARL,,13.04,2,1,13.03,100,1,13.02,100,1,12.73,100,1,12.71,100,1,12.5,700,1,12.46,200,1,12.43,700,1,12.42,700,1,12.37,700,1,13.83,100,1,13.92,2,1,14.28,100,1,14.43,200,1,14.51,100,1,14.53,700,1,14.56,800,1,14.57,100,1,14.6,700,1,14.64,100,1,2,324942361
2025-07-17T16:02:20.651459317Z,2025-07-17T16:02:20.651293729Z,160,2,1108,A,A,17.570000000,100,0,325714589,130,165588,271676055,ARL,,13.04,2,1,13.03,100,1,13.02,100,1,12.73,100,1,12.71,100,1,12.5,700,1,12.46,200,1,12.43,700,1,12.42,700,1,12.37,700,1,13.83,100,1,13.92,2,1,14.28,100,1,14.43,200,1,14.51,100,1,14.53,700,1,14.56,800,1,14.57,100,1,14.6,700,1,14.64,100,1,2,325714589
2025-07-17T16:02:20.651558948Z,2025-07-17T16:02:20.651393708Z,160,2,1108,A,A,14.450000000,100,0,325714601,130,165240,271676057,ARL,,13.04,2,1,13.03,100,1,13.02,100,1,12.73,100,1,12.71,100,1,12.5,700,1,12.46,200,1,12.43,700,1,12.42,700,1,12.37,700,1,13.83,100,1,13.92,2,1,14.28,100,1,14.43,200,1,14.45,100,1,14.51,100,1,14.53,700,1,14.56,800,1,14.57,100,1,14.6,700,1,2,325714601
2025-07-17T16:02:20.651787813Z,2025-07-17T16:02:20.651618897Z,160,2,1108,C,A,14.430000000,100,0,325382437,0,168916,271676089,ARL,,13.04,2,1,13.03,100,1,13.02,100,1,12.73,100,1,12.71,100,1,12.5,700,1,12.46,200,1,12.43,700,1,12.42,700,1,12.37,700,1,13.83,100,1,13.92,2,1,14.28,100,1,14.43,100,1,14.45,100,1,14.51,100,1,14.53,700,1,14.56,800,1,14.57,100,1,14.6,700,1,2,325382437
2025-07-17T16:02:20.651787813Z,2025-07-17T16:02:20.651618897Z,160,2,1108,A,A,14.730000000,100,0,325714613,128,168916,271676089,ARL,,13.04,2,1,13.03,100,1,13.02,100,1,12.73,100,1,12.71,100,1,12.5,700,1,12.46,200,1,12.43,700,1,12.42,700,1,12.37,700,1,13.83,100,1,13.92,2,1,14.28,100,1,14.43,100,1,14.45,100,1,14.51,100,1,14.53,700,1,14.56,800,1,14.57,100,1,14.6,700,1,2,325714613
2025-07-17T16:02:20.652021618Z,2025-07-17T16:02:20.651854531Z,160,2,1108,C,A,14.570000000,100,0,324619409,0,167087,271676104,ARL,,13.04,2,1,13.03,100,1,13.02,100,1,12.73,100,1,12.71,100,1,12.5,700,1,12.46,200,1,12.43,700,1,12.42,700,1,12.37,700,1,13.83,100,1,13.92,2,1,14.28,100,1,14.43,100,1,14.45,100,1,14.51,100,1,14.53,700,1,14.56,800,1,14.6,700,1,14.64,100,1,2,324619409
2025-07-17T16:02:20.652021618Z,2025-07-17T16:02:20.651854531Z,160,2,1108,A,A,14.800000000,100,0,325714629,130,167087,271676104,ARL,,13.04,2,1,13.03,100,1,13.02,100,1,12.73,100,1,12.71,100,1,12.5,700,1,12.46,200,1,12.43,700,1,12.42,700,1,12.37,700,1,13.83,100,1,13.92,2,1,14.28,100,1,14.43,100,1,14.45,100,1,14.51,100,1,14.53,700,1,14.56,800,1,14.6,700,1,14.64,100,1,2,325714629
2025-07-17T16:02:20.652097288Z,2025-07-17T16:02:20.651932129Z,160,2,1108,C,A,14.430000000,100,0,324186781,130,165159,271676110,ARL,,13.04,2,1,13.03,100,1,13.02,100,1,12.73,100,1,12.71,100,1,12.5,700,1,12.46,200,1,12.43,700,1,12.42,700,1,12.37,700,1,13.83,100,1,13.92,2,1,14.28,100,1,14.45,100,1,14.51,100,1,14.53,700,1,14.56,800,1,14.6,700,1,14.64,100,1,14.68,700,1,2,324186781
2025-07-17T16:02:20.652160470Z,2025-07-17T16:02:20.651994883Z,160,2,1108,C,A,15.600000000,100,0,325176677,0,165587,271676111,ARL,,13.04,2,1,13.03,100,1,13.02,100,1,12.73,100,1,12.71,100,1,12.5,700,1,12.46,200,1,12.43,700,1,12.42,700,1,12.37,700,1,13.83,100,1,13.92,2,1,14.28,100,1,14.45,100,1,14.51,100,1,14.53,700,1,14.56,800,1,14.6,700,1,14.64,100,1,14.68,700,1,2,325176677
2025-07-17T16:02:20.652160470Z,2025-07-17T16:02:20.651994883Z,160,2,1108,A,A,15.910000000,100,0,325714633,130,165587,271676111,ARL,,13.04,2,1,13.03,100,1,13.02,100,1,12.73,100,1,12.71,100,1,12.5,700,1,12.46,200,1,12.43,700,1,12.42,700,1,12.37,700,1,13.83,100,1,13.92,2,1,14.28,100,1,14.45,100,1,14.51,100,1,14.53,700,1,14.56,800,1,14.6,700,1,14.64,100,1,14.68,700,1,2,325714633
2025-07-17T16:02:20.652259931Z,2025-07-17T16:02:20.652094426Z,160,2,1108,A,A,14.630000000,100,0,325714653,130,165505,271676118,ARL,,13.04,2,1,13.03,100,1,13.02,100,1,12.73,100,1,12.71,100,1,12.5,700,1,12.46,200,1,12.43,700,1,12.42,700,1,12.37,700,1,13.83,100,1,13.92,2,1,14.28,100,1,14.45,100,1,14.51,100,1,14.53,700,1,14.56,800,1,14.6,700,1,14.63,100,1,14.64,100,1,2,325714653
2025-07-17T16:02:20.653626391Z,2025-07-17T16:02:20.653460814Z,160,2,1108,A,B,13.270000000,10,0,325714717,130,165577,271676147,ARL,,13.27,10,1,13.04,2,1,13.03,100,1,13.02,100,1,12.73,100,1,12.71,100,1,12.5,700,1,12.46,200,1,12.43,700,1,12.42,700,1,13.83,100,1,13.92,2,1,14.28,100,1,14.45,100,1,14.51,100,1,14.53,700,1,14.56,800,1,14.6,700,1,14.63,100,1,14.64,100,1,2,325714717
2025-07-17T16:02:20.653627232Z,2025-07-17T16:02:20.653461966Z,160,2,1108,A,A,13.830000000,15,0,325714721,130,165266,271676148,ARL,,13.27,10,1,13.04,2,1,13.03,100,1,13.02,100,1,12.73,100,1,12.71,100,1,12.5,700,1,12.46,200,1,12.43,700,1,12.42,700,1,13.83,115,1,13.92,2,1,14.28,100,1,14.45,100,1,14.51,100,1,14.53,700,1,14.56,800,1,14.6,700,1,14.63,100,1,14.64,100,1,2,325714721
2025-07-17T16:02:20.653886896Z,2025-07-17T16:02:20.653721185Z,160,2,1108,C,B,13.020000000,100,0,320485385,0,165711,271676153,ARL,,13.27,10,1,13.04,2,1,13.03,100,1,12.73,100,1,12.71,100,1,12.5,700,1,12.46,200,1,12.43,700,1,12.42,700,1,12.37,700,1,13.83,115,1,13.92,2,1,14.28,100,1,14.45,100,1,14.51,100,1,14.53,700,1,14.56,800,1,14.6,700,1,14.63,100,1,14.64,100,1,2,320485385
2025-07-17T16:02:20.653886896Z,2025-07-17T16:02:20.653721185Z,160,2,1108,A,B,13.260000000,100,0,325714729,130,165711,271676153,ARL,,13.27,10,1,13.26,100,1,13.04,2,1,13.03,100,1,12.73,100,1,12.71,100,1,12.5,700,1,12.46,200,1,12.43,700,1,12.42,700,1,13.83,115,1,13.92,2,1,14.28,100,1,14.45,100,1,14.51,100,1,14.53,700,1,14.56,800,1,14.6,700,1,14.63,100,1,14.64,100,1,2,325714729
2025-07-17T16:02:20.655277066Z,2025-07-17T16:02:20.655111649Z,160,2,1108,C,B,13.040000000,2,0,293594281,0,165417,271676165,ARL,,13.27,10,1,13.26,100,1,13.03,100,1,12.73,100,1,12.71,100,1,12.5,700,1,12.46,200,1,12.43,700,1,12.42,700,1,12.37,700,1,13.83,115,1,13.92,2,1,14.28,100,1,14.45,100,1,14.51,100,1,14.53,700,1,14.56,800,1,14.6,700,1,14.63,100,1,14.64,100,1,2,293594281
2025-07-17T16:02:20.655277066Z,2025-07-17T16:02:20.655111649Z,160,2,1108,A,B,12.910000000,2,0,325714741,130,165417,271676165,ARL,,13.27,10,1,13.26,100,1,13.03,100,1,12.91,2,1,12.73,100,1,12.71,100,1,12.5,700,1,12.46,200,1,12.43,700,1,12.42,700,1,13.83,115,1,13.92,2,1,14.28,100,1,14.45,100,1,14.51,100,1,14.53,700,1,14.56,800,1,14.6,700,1,14.63,100,1,14.64,100,1,2,325714741
2025-07-17T16:02:20.663374576Z,2025-07-17T16:02:20.663209235Z,160,2,1108,C,A,13.830000000,100,0,325176373,130,165341,271676274,ARL,,13.27,10,1,13.26,100,1,13.03,100,1,12.91,2,1,12.73,100,1,12.71,100,1,12.5,700,1,12.46,200,1,12.43,700,1,12.42,700,1,13.83,15,1,13.92,2,1,14.28,100,1,14.45,100,1,14.51,100,1,14.53,700,1,14.56,800,1,14.6,700,1,14.63,100,1,14.64,100,1,2,325176373
2025-07-17T16:02:20.663406861Z,2025-07-17T16:02:20.663241882Z,160,2,1108,C,A,14.530000000,700,0,325714545,130,164979,271676275,ARL,,13.27,10,1,13.26,100,1,13.03,100,1,12.91,2,1,12.73,100,1,12.71,100,1,12.5,700,1,12.46,200,1,12.43,700,1,12.42,700,1,13.83,15,1,13.92,2,1,14.28,100,1,14.45,100,1,14.51,100,1,14.56,800,1,14.6,700,1,14.63,100,1,14.64,100,1,14.68,700,1,2,325714545
2025-07-17T16:02:20.663426974Z,2025-07-17T16:02:20.663261632Z,160,2,1108,A,A,14.110000000,100,0,325714905,130,165342,271676276,ARL,,13.27,10,1,13.26,100,1,13.03,100,1,12.91,2,1,12.73,100,1,12.71,100,1,12.5,700,1,12.46,200,1,12.43,700,1,12.42,700,1,13.83,15,1,13.92,2,1,14.11,100,1,14.28,100,1,14.45,100,1,14.51,100,1,14.56,800,1,14.6,700,1,14.63,100,1,14.64,100,1,2,325714905
2025-07-17T16:02:20.663559466Z,2025-07-17T16:02:20.663394059Z,160,2,1108,A,A,15.940000000,100,0,325714909,130,165407,271676277,ARL,,13.27,10,1,13.26,100,1,13.03,100,1,12.91,2,1,12.73,100,1,12.71,100,1,12.5,700,1,12.46,200,1,12.43,700,1,12.42,700,1,13.83,15,1,13.92,2,1,14.11,100,1,14.28,100,1,14.45,100,1,14.51,100,1,14.56,800,1,14.6,700,1,14.63,100,1,14.64,100,1,2,325714909
2025-07-17T16:02:20.663572634Z,2025-07-17T16:02:20.663407337Z,160,2,1108,C,A,15.590000000,100,0,323730697,130,165297,271676278,ARL,,13.27,10,1,13.26,100,1,13.03,100,1,12.91,2,1,12.73,100,1,12.71,100,1,12.5,700,1,12.46,200,1,12.43,700,1,12.42,700,1,13.83,15,1,13.92,2,1,14.11,100,1,14.28,100,1,14.45,100,1,14.51,100,1,14.56,800,1,14.6,700,1,14.63,100,1,14.64,100,1,2,323730697
2025-07-17T16:02:20.664956400Z,2025-07-17T16:02:20.664790768Z,160,2,1108,C,A,17.570000000,100,0,325714589,0,165632,271676310,ARL,,13.27,10,1,13.26,100,1,13.03,100,1,12.91,2,1,12.73,100,1,12.71,100,1,12.5,700,1,12.46,200,1,12.43,700,1,12.42,700,1,13.83,15,1,13.92,2,1,14.11,100,1,14.28,100,1,14.45,100,1,14.51,100,1,14.56,800,1,14.6,700,1,14.63,100,1,14.64,100,1,2,325714589
2025-07-17T16:02:20.664956400Z,2025-07-17T16:02:20.664790768Z,160,2,1108,A,A,17.760000000,100,0,325714949,130,165632,271676310,ARL,,13.27,10,1,13.26,100,1,13.03,100,1,12.91,2,1,12.73,100,1,12.71,100,1,12.5,700,1,12.46,200,1,12.43,700,1,12.42,700,1,13.83,15,1,13.92,2,1,14.11,100,1,14.28,100,1,14.45,100,1,14.51,100,1,14.56,800,1,14.6,700,1,14.63,100,1,14.64,100,1,2,325714949
2025-07-17T16:02:20.665129279Z,2025-07-17T16:02:20.664963386Z,160,2,1108,C,A,14.800000000,100,0,325714629,0,165893,271676320,ARL,,13.27,10,1,13.26,100,1,13.03,100,1,12.91,2,1,12.73,100,1,12.71,100,1,12.5,700,1,12.46,200,1,12.43,700,1,12.42,700,1,13.83,15,1,13.92,2,1,14.11,100,1,14.28,100,1,14.45,100,1,14.51,100,1,14.56,800,1,14.6,700,1,14.63,100,1,14.64,100,1,2,325714629
2025-07-17T16:02:20.665129279Z,2025-07-17T16:02:20.664963386Z,160,2,1108,A,A,14.960000000,100,0,325714953,130,165893,271676320,ARL,,13.27,10,1,13.26,100,1,13.03,100,1,12.91,2,1,12.73,100,1,12.71,100,1,12.5,700,1,12.46,200,1,12.43,700,1,12.42,700,1,13.83,15,1,13.92,2,1,14.11,100,1,14.28,100,1,14.45,100,1,14.51,100,1,14.56,800,1,14.6,700,1,14.63,100,1,14.64,100,1,2,325714953
2025-07-17T16:02:20.665200392Z,2025-07-17T16:02:20.665034825Z,160,2,1108,C,A,15.910000000,100,0,325714633,0,165567,271676330,ARL,,13.27,10,1,13.26,100,1,13.03,100,1,12.91,2,1,12.73,100,1,12.71,100,1,12.5,700,1,12.46,200,1,12.43,700,1,12.42,700,1,13.83,15,1,13.92,2,1,14.11,100,1,14.28,100,1,14.45,100,1,14.51,100,1,14.56,800,1,14.6,700,1,14.63,100,1,14.64,100,1,2,325714633
2025-07-17T16:02:20.665200392Z,2025-07-17T16:02:20.665034825Z,160,2,1108,A,A,16.080000000,100,0,325714957,130,165567,271676330,ARL,,13.27,10,1,13.26,100,1,13.03,100,1,12.91,2,1,12.73,100,1,12.71,100,1,12.5,700,1,12.46,200,1,12.43,700,1,12.42,700,1,13.83,15,1,13.92,2,1,14.11,100,1,14.28,100,1,14.45,100,1,14.51,100,1,14.56,800,1,14.6,700,1,14.63,100,1,14.64,100,1,2,325714957
2025-07-17T16:02:20.665457595Z,2025-07-17T16:02:20.665292049Z,160,2,1108,C,A,14.940000000,100,0,324942277,0,165546,271676355,ARL,,13.27,10,1,13.26,100,1,13.03,100,1,12.91,2,1,12.73,100,1,12.71,100,1,12.5,700,1,12.46,200,1,12.43,700,1,12.42,700,1,13.83,15,1,13.92,2,1,14.11,100,1,14.28,100,1,14.45,100,1,14.51,100,1,14.56,800,1,14.6,700,1,14.63,100,1,14.64,100,1,2,324942277
2025-07-17T16:02:20.665457595Z,2025-07-17T16:02:20.665292049Z,160,2,1108,A,A,15.380000000,100,0,325714965,130,165546,271676355,ARL,,13.27,10,1,13.26,100,1,13.03,100,1,12.91,2,1,12.73,100,1,12.71,100,1,12.5,700,1,12.46,200,1,12.43,700,1,12.42,700,1,13.83,15,1,13.92,2,1,14.11,100,1,14.28,100,1,14.45,100,1,14.51,100,1,14.56,800,1,14.6,700,1,14.63,100,1,14.64,100,1,2,325714965
2025-07-17T16:02:20.669701452Z,2025-07-17T16:02:20.669536385Z,160,2,1108,C,A,14.110000000,100,0,325714905,130,165067,271676398,ARL,,13.27,10,1,13.26,100,1,13.03,100,1,12.91,2,1,12.73,100,1,12.71,100,1,12.5,700,1,12.46,200,1,12.43,700,1,12.42,700,1,13.83,15,1,13.92,2,1,14.28,100,1,14.45,100,1,14.51,100,1,14.56,800,1,14.6,700,1,14.63,100,1,14.64,100,1,14.68,700,1,2,325714905
2025-07-17T16:02:20.669748954Z,2025-07-17T16:02:20.669583810Z,160,2,1108,A,A,14.260000000,100,0,325715045,130,165144,271676399,ARL,,13.27,10,1,13.26,100,1,13.03,100,1,12.91,2,1,12.73,100,1,12.71,100,1,12.5,700,1,12.46,200,1,12.43,700,1,12.42,700,1,13.83,15,1,13.92,2,1,14.26,100,1,14.28,100,1,14.45,100,1,14.51,100,1,14.56,800,1,14.6,700,1,14.63,100,1,14.64,100,1,2,325715045
2025-07-17T16:02:20.669752979Z,2025-07-17T16:02:20.669587514Z,160,2,1108,C,A,14.510000000,100,0,325177757,0,165465,271676400,ARL,,13.27,10,1,13.26,100,1,13.03,100,1,12.91,2,1,12.73,100,1,12.71,100,1,12.5,700,1,12.46,200,1,12.43,700,1,12.42,700,1,13.83,15,1,13.92,2,1,14.26,100,1,14.28,100,1,14.45,100,1,14.56,800,1,14.6,700,1,14.63,100,1,14.64,100,1,14.68,700,1,2,325177757
2025-07-17T16:02:20.669752979Z,2025-07-17T16:02:20.669587514Z,160,2,1108,A,A,14.960000000,100,0,325715053,130,165465,271676400,ARL,,13.27,10,1,13.26,100,1,13.03,100,1,12.91,2,1,12.73,100,1,12.71,100,1,12.5,700,1,12.46,200,1,12.43,700,1,12.42,700,1,13.83,15,1,13.92,2,1,14.26,100,1,14.28,100,1,14.45,100,1,14.56,800,1,14.6,700,1,14.63,100,1,14.64,100,1,14.68,700,1,2,325715053
2025-07-17T16:02:20.685252049Z,2025-07-17T16:02:20.685086585Z,160,2,1108,C,A,14.640000000,100,0,325714169,0,165464,271676621,ARL,,13.27,10,1,13.26,100,1,13.03,100,1,12.91,2,1,12.73,100,1,12.71,100,1,12.5,700,1,12.46,200,1,12.43,700,1,12.42,700,1,13.83,15,1,13.92,2,1,14.26,100,1,14.28,100,1,14.45,100,1,14.56,800,1,14.6,700,1,14.63,100,1,14.68,700,1,14.73,200,1,2,325714169
2025-07-17T16:02:20.685252049Z,2025-07-17T16:02:20.685086585Z,160,2,1108,A,A,15.060000000,100,0,325715113,130,165464,271676621,ARL,,13.27,10,1,13.26,100,1,13.03,100,1,12.91,2,1,12.73,100,1,12.71,100,1,12.5,700,1,12.46,200,1,12.43,700,1,12.42,700,1,13.83,15,1,13.92,2,1,14.26,100,1,14.28,100,1,14.45,100,1,14.56,800,1,14.6,700,1,14.63,100,1,14.68,700,1,14.73,200,1,2,325715113
2025-07-17T16:02:20.832112637Z,2025-07-17T16:02:20.831947250Z,160,2,1108,A,A,14.680000000,700,0,325716945,130,165387,271678584,ARL,,13.27,10,1,13.26,100,1,13.03,100,1,12.91,2,1,12.73,100,1,12.71,100,1,12.5,700,1,12.46,200,1,12.43,700,1,12.42,700,1,13.83,15,1,13.92,2,1,14.26,100,1,14.28,100,1,14.45,100,1,14.56,800,1,14.6,700,1,14.63,100,1,14.68,1400,1,14.73,200,1,2,325716945
2025-07-17T16:02:20.936787418Z,2025-07-17T16:02:20.936622241Z,160,2,1108,C,B,13.260000000,100,0,325714729,130,165177,271679553,ARL,,13.27,10,1,13.03,100,1,12.91,2,1,12.73,100,1,12.71,100,1,12.5,700,1,12.46,200,1,12.43,700,1,12.42,700,1,12.37,700,1,13.83,15,1,13.92,2,1,14.26,100,1,14.28,100,1,14.45,100,1,14.56,800,1,14.6,700,1,14.63,100,1,14.68,1400,1,14.73,200,1,2,325714729
2025-07-17T16:02:20.936837611Z,2025-07-17T16:02:20.936672130Z,160,2,1108,A,A,13.910000000,5,0,325718477,130,165481,271679555,ARL,,13.27,10,1,13.03,100,1,12.91,2,1,12.73,100,1,12.71,100,1,12.5,700,1,12.46,200,1,12.43,700,1,12.42,700,1,12.37,700,1,13.83,15,1,13.91,5,1,13.92,2,1,14.26,100,1,14.28,100,1,14.45,100,1,14.56,800,1,14.6,700,1,14.63,100,1,14.68,1400,1,2,325718477
2025-07-17T16:02:20.936999211Z,2025-07-17T16:02:20.936833988Z,160,2,1108,A,A,13.840000000,100,0,325718485,130,165223,271679558,ARL,,13.27,10,1,13.03,100,1,12.91,2,1,12.73,100,1,12.71,100,1,12.5,700,1,12.46,200,1,12.43,700,1,12.42,700,1,12.37,700,1,13.83,15,1,13.84,100,1,13.91,5,1,13.92,2,1,14.26,100,1,14.28,100,1,14.45,100,1,14.56,800,1,14.6,700,1,14.63,100,1,2,325718485
2025-07-17T16:02:20.937744264Z,2025-07-17T16:02:20.937578907Z,160,2,1108,C,A,15.060000000,100,0,325715113,0,165357,271679565,ARL,,13.27,10,1,13.03,100,1,12.91,2,1,12.73,100,1,12.71,100,1,12.5,700,1,12.46,200,1,12.43,700,1,12.42,700,1,12.37,700,1,13.83,15,1,13.84,100,1,13.91,5,1,13.92,2,1,14.26,100,1,14.28,100,1,14.45,100,1,14.56,800,1,14.6,700,1,14.63,100,1,2,325715113
2025-07-17T16:02:20.937744264Z,2025-07-17T16:02:20.937578907Z,160,2,1108,A,A,14.910000000,100,0,325718509,130,165357,271679565,ARL,,13.27,10,1,13.03,100,1,12.91,2,1,12.73,100,1,12.71,100,1,12.5,700,1,12.46,200,1,12.43,700,1,12.42,700,1,12.37,700,1,13.83,15,1,13.84,100,1,13.91,5,1,13.92,2,1,14.26,100,1,14.28,100,1,14.45,100,1,14.56,800,1,14.6,700,1,14.63,100,1,2,325718509
2025-07-17T16:02:20.937901293Z,2025-07-17T16:02:20.937736247Z,160,2,1108,C,A,13.910000000,5,0,325718477,130,165046,271679567,ARL,,13.27,10,1,13.03,100,1,12.91,2,1,12.73,100,1,12.71,100,1,12.5,700,1,12.46,200,1,12.43,700,1,12.42,700,1,12.37,700,1,13.83,15,1,13.84,100,1,13.92,2,1,14.26,100,1,14.28,100,1,14.45,100,1,14.56,800,1,14.6,700,1,14.63,100,1,14.68,1400,1,2,325718477
2025-07-17T16:02:20.938093286Z,2025-07-17T16:02:20.937927380Z,160,2,1108,C,A,14.960000000,100,0,325715053,0,165906,271679569,ARL,,13.27,10,1,13.03,100,1,12.91,2,1,12.73,100,1,12.71,100,1,12.5,700,1,12.46,200,1,12.43,700,1,12.42,700,1,12.37,700,1,13.83,15,1,13.84,100,1,13.92,2,1,14.26,100,1,14.28,100,1,14.45,100,1,14.56,800,1,14.6,700,1,14.63,100,1,14.68,1400,1,2,325715053
2025-07-17T16:02:20.938093286Z,2025-07-17T16:02:20.937927380Z,160,2,1108,A,A,14.810000000,100,0,325718517,130,165906,271679569,ARL,,13.27,10,1,13.03,100,1,12.91,2,1,12.73,100,1,12.71,100,1,12.5,700,1,12.46,200,1,12.43,700,1,12.42,700,1,12.37,700,1,13.83,15,1,13.84,100,1,13.92,2,1,14.26,100,1,14.28,100,1,14.45,100,1,14.56,800,1,14.6,700,1,14.63,100,1,14.68,1400,1,2,325718517
2025-07-17T16:02:20.938297839Z,2025-07-17T16:02:20.938132716Z,160,2,1108,C,A,16.080000000,100,0,325714957,0,165123,271679571,ARL,,13.27,10,1,13.03,100,1,12.91,2,1,12.73,100,1,12.71,100,1,12.5,700,1,12.46,200,1,12.43,700,1,12.42,700,1,12.37,700,1,13.83,15,1,13.84,100,1,13.92,2,1,14.26,100,1,14.28,100,1,14.45,100,1,14.56,800,1,14.6,700,1,14.63,100,1,14.68,1400,1,2,325714957
2025-07-17T16:02:20.938297839Z,2025-07-17T16:02:20.938132716Z,160,2,1108,A,A,15.920000000,100,0,325718525,130,165123,271679571,ARL,,13.27,10,1,13.03,100,1,12.91,2,1,12.73,100,1,12.71,100,1,12.5,700,1,12.46,200,1,12.43,700,1,12.42,700,1,12.37,700,1,13.83,15,1,13.84,100,1,13.92,2,1,14.26,100,1,14.28,100,1,14.45,100,1,14.56,800,1,14.6,700,1,14.63,100,1,14.68,1400,1,2,325718525
2025-07-17T16:02:20.938616654Z,2025-07-17T16:02:20.938451331Z,160,2,1108,C,A,14.960000000,100,0,325714953,0,165323,271679575,ARL,,13.27,10,1,13.03,100,1,12.91,2,1,12.73,100,1,12.71,100,1,12.5,700,1,12.46,200,1,12.43,700,1,12.42,700,1,12.37,700,1,13.83,15,1,13.84,100,1,13.92,2,1,14.26,100,1,14.28,100,1,14.45,100,1,14.56,800,1,14.6,700,1,14.63,100,1,14.68,1400,1,2,325714953
2025-07-17T16:02:20.938616654Z,2025-07-17T16:02:20.938451331Z,160,2,1108,A,A,14.810000000,100,0,325718549,130,165323,271679575,ARL,,13.27,10,1,13.03,100,1,12.91,2,1,12.73,100,1,12.71,100,1,12.5,700,1,12.46,200,1,12.43,700,1,12.42,700,1,12.37,700,1,13.83,15,1,13.84,100,1,13.92,2,1,14.26,100,1,14.28,100,1,14.45,100,1,14.56,800,1,14.6,700,1,14.63,100,1,14.68,1400,1,2,325718549
2025-07-17T16:02:20.938889819Z,2025-07-17T16:02:20.938724516Z,160,2,1108,C,A,17.760000000,100,0,325714949,0,165303,271679576,ARL,,13.27,10,1,13.03,100,1,12.91,2,1,12.73,100,1,12.71,100,1,12.5,700,1,12.46,200,1,12.43,700,1,12.42,700,1,12.37,700,1,13.83,15,1,13.84,100,1,13.92,2,1,14.26,100,1,14.28,100,1,14.45,100,1,14.56,800,1,14.6,700,1,14.63,100,1,14.68,1400,1,2,325714949
2025-07-17T16:02:20.938889819Z,2025-07-17T16:02:20.938724516Z,160,2,1108,A,A,17.580000000,100,0,325718557,130,165303,271679576,ARL,,13.27,10,1,13.03,100,1,12.91,2,1,12.73,100,1,12.71,100,1,12.5,700,1,12.46,200,1,12.43,700,1,12.42,700,1,12.37,700,1,13.83,15,1,13.84,100,1,13.92,2,1,14.26,100,1,14.28,100,1,14.45,100,1,14.56,800,1,14.6,700,1,14.63,100,1,14.68,1400,1,2,325718557
2025-07-17T16:02:20.939554686Z,2025-07-17T16:02:20.939389367Z,160,2,1108,A,B,13.020000000,100,0,325718561,130,165319,271679578,ARL,,13.27,10,1,13.03,100,1,13.02,100,1,12.91,2,1,12.73,100,1,12.71,100,1,12.5,700,1,12.46,200,1,12.43,700,1,12.42,700,1,13.83,15,1,13.84,100,1,13.92,2,1,14.26,100,1,14.28,100,1,14.45,100,1,14.56,800,1,14.6,700,1,14.63,100,1,14.68,1400,1,2,325718561
2025-07-17T16:02:20.946406202Z,2025-07-17T16:02:20.946240970Z,160,2,1108,C,A,14.260000000,100,0,325715045,130,165232,271679616,ARL,,13.27,10,1,13.03,100,1,13.02,100,1,12.91,2,1,12.73,100,1,12.71,100,1,12.5,700,1,12.46,200,1,12.43,700,1,12.42,700,1,13.83,15,1,13.84,100,1,13.92,2,1,14.28,100,1,14.45,100,1,14.56,800,1,14.6,700,1,14.63,100,1,14.68,1400,1,14.73,200,1,2,325715045
2025-07-17T16:02:20.946456786Z,2025-07-17T16:02:20.946291345Z,160,2,1108,A,A,14.120000000,100,0,325718637,130,165441,271679617,ARL,,13.27,10,1,13.03,100,1,13.02,100,1,12.91,2,1,12.73,100,1,12.71,100,1,12.5,700,1,12.46,200,1,12.43,700,1,12.42,700,1,13.83,15,1,13.84,100,1,13.92,2,1,14.12,100,1,14.28,100,1,14.45,100,1,14.56,800,1,14.6,700,1,14.63,100,1,14.68,1400,1,2,325718637
2025-07-17T16:02:20.957051613Z,2025-07-17T16:02:20.956886401Z,160,2,1108,C,B,13.020000000,100,0,325718561,0,165212,271679685,ARL,,13.27,10,1,13.03,100,1,12.91,2,1,12.73,100,1,12.71,100,1,12.5,700,1,12.46,200,1,12.43,700,1,12.42,700,1,12.37,700,1,13.83,15,1,13.84,100,1,13.92,2,1,14.12,100,1,14.28,100,1,14.45,100,1,14.56,800,1,14.6,700,1,14.63,100,1,14.68,1400,1,2,325718561
2025-07-17T16:02:20.957051613Z,2025-07-17T16:02:20.956886401Z,160,2,1108,A,B,13.260000000,100,0,325718821,130,165212,271679685,ARL,,13.27,10,1,13.26,100,1,13.03,100,1,12.91,2,1,12.73,100,1,12.71,100,1,12.5,700,1,12.46,200,1,12.43,700,1,12.42,700,1,13.83,15,1,13.84,100,1,13.92,2,1,14.12,100,1,14.28,100,1,14.45,100,1,14.56,800,1,14.6,700,1,14.63,100,1,14.68,1400,1,2,325718821
2025-07-17T16:02:20.957089143Z,2025-07-17T16:02:20.956923753Z,160,2,1108,A,B,13.120000000,100,0,325718833,130,165390,271679686,ARL,,13.27,10,1,13.26,100,1,13.12,100,1,13.03,100,1,12.91,2,1,12.73,100,1,12.71,100,1,12.5,700,1,12.46,200,1,12.43,700,1,13.83,15,1,13.84,100,1,13.92,2,1,14.12,100,1,14.28,100,1,14.45,100,1,14.56,800,1,14.6,700,1,14.63,100,1,14.68,1400,1,2,325718833
2025-07-17T16:02:20.957090484Z,2025-07-17T16:02:20.956925447Z,160,2,1108,A,B,13.120000000,100,0,325718837,130,165037,271679687,ARL,,13.27,10,1,13.26,100,1,13.12,200,1,13.03,100,1,12.91,2,1,12.73,100,1,12.71,100,1,12.5,700,1,12.46,200,1,12.43,700,1,13.83,15,1,13.84,100,1,13.92,2,1,14.12,100,1,14.28,100,1,14.45,100,1,14.56,800,1,14.6,700,1,14.63,100,1,14.68,1400,1,2,325718837
2025-07-17T16:02:20.988655870Z,2025-07-17T16:02:20.988490644Z,160,2,1108,A,A,13.980000000,100,0,325719353,130,165226,271679923,ARL,,13.27,10,1,13.26,100,1,13.12,200,1,13.03,100,1,12.91,2,1,12.73,100,1,12.71,100,1,12.5,700,1,12.46,200,1,12.43,700,1,13.83,15,1,13.84,100,1,13.92,2,1,13.98,100,1,14.12,100,1,14.28,100,1,14.45,100,1,14.56,800,1,14.6,700,1,14.63,100,1,2,325719353
2025-07-17T16:02:20.988656944Z,2025-07-17T16:02:20.988491826Z,160,2,1108,A,A,13.980000000,100,0,325719357,130,165118,271679924,ARL,,13.27,10,1,13.26,100,1,13.12,200,1,13.03,100,1,12.91,2,1,12.73,100,1,12.71,100,1,12.5,700,1,12.46,200,1,12.43,700,1,13.83,15,1,13.84,100,1,13.92,2,1,13.98,200,1,14.12,100,1,14.28,100,1,14.45,100,1,14.56,800,1,14.6,700,1,14.63,100,1,2,325719357
2025-07-17T16:02:30.805193695Z,2025-07-17T16:02:30.805028316Z,160,2,1108,C,B,13.270000000,10,0,325714717,130,165379,271818376,ARL,,13.26,100,1,13.12,200,1,13.03,100,1,12.91,2,1,12.73,100,1,12.71,100,1,12.5,700,1,12.46,200,1,12.43,700,1,12.42,700,1,13.83,15,1,13.84,100,1,13.92,2,1,13.98,200,1,14.12,100,1,14.28,100,1,14.45,100,1,14.56,800,1,14.6,700,1,14.63,100,1,2,325714717
2025-07-17T16:02:34.987171397Z,2025-07-17T16:02:34.987005787Z,160,2,1108,C,B,12.910000000,2,0,325714741,0,165610,271871706,ARL,,13.26,100,1,13.12,200,1,13.03,100,1,12.73,100,1,12.71,100,1,12.5,700,1,12.46,200,1,12.43,700,1,12.42,700,1,12.37,700,1,13.83,15,1,13.84,100,1,13.92,2,1,13.98,200,1,14.12,100,1,14.28,100,1,14.45,100,1,14.56,800,1,14.6,700,1,14.63,100,1,2,325714741
2025-07-17T16:02:34.987171397Z,2025-07-17T16:02:34.987005787Z,160,2,1108,A,B,13.000000000,2,0,325967705,130,165610,271871706,ARL,,13.26,100,1,13.12,200,1,13.03,100,1,13,2,1,12.73,100,1,12.71,100,1,12.5,700,1,12.46,200,1,12.43,700,1,12.42,700,1,13.83,15,1,13.84,100,1,13.92,2,1,13.98,200,1,14.12,100,1,14.28,100,1,14.45,100,1,14.56,800,1,14.6,700,1,14.63,100,1,2,325967705
2025-07-17T16:02:39.809464961Z,2025-07-17T16:02:39.809299504Z,160,2,1108,A,A,13.790000000,15,0,326077141,130,165457,271952021,ARL,,13.26,100,1,13.12,200,1,13.03,100,1,13,2,1,12.73,100,1,12.71,100,1,12.5,700,1,12.46,200,1,12.43,700,1,12.42,700,1,13.79,15,1,13.83,15,1,13.84,100,1,13.92,2,1,13.98,200,1,14.12,100,1,14.28,100,1,14.45,100,1,14.56,800,1,14.6,700,1,2,326077141
2025-07-17T16:02:40.007472020Z,2025-07-17T16:02:40.007306432Z,160,2,1108,C,A,13.840000000,100,0,325718485,0,165588,271957331,ARL,,13.26,100,1,13.12,200,1,13.03,100,1,13,2,1,12.73,100,1,12.71,100,1,12.5,700,1,12.46,200,1,12.43,700,1,12.42,700,1,13.79,15,1,13.83,15,1,13.92,2,1,13.98,200,1,14.12,100,1,14.28,100,1,14.45,100,1,14.56,800,1,14.6,700,1,14.63,100,1,2,325718485
2025-07-17T16:02:40.007472020Z,2025-07-17T16:02:40.007306432Z,160,2,1108,A,A,13.800000000,100,0,326082329,130,165588,271957331,ARL,,13.26,100,1,13.12,200,1,13.03,100,1,13,2,1,12.73,100,1,12.71,100,1,12.5,700,1,12.46,200,1,12.43,700,1,12.42,700,1,13.79,15,1,13.8,100,1,13.83,15,1,13.92,2,1,13.98,200,1,14.12,100,1,14.28,100,1,14.45,100,1,14.56,800,1,14.6,700,1,2,326082329
2025-07-17T16:02:40.008213654Z,2025-07-17T16:02:40.008048023Z,160,2,1108,C,A,14.910000000,100,0,325718509,0,165631,271957349,ARL,,13.26,100,1,13.12,200,1,13.03,100,1,13,2,1,12.73,100,1,12.71,100,1,12.5,700,1,12.46,200,1,12.43,700,1,12.42,700,1,13.79,15,1,13.8,100,1,13.83,15,1,13.92,2,1,13.98,200,1,14.12,100,1,14.28,100,1,14.45,100,1,14.56,800,1,14.6,700,1,2,325718509
2025-07-17T16:02:40.008213654Z,2025-07-17T16:02:40.008048023Z,160,2,1108,A,A,14.870000000,100,0,326082353,130,165631,271957349,ARL,,13.26,100,1,13.12,200,1,13.03,100,1,13,2,1,12.73,100,1,12.71,100,1,12.5,700,1,12.46,200,1,12.43,700,1,12.42,700,1,13.79,15,1,13.8,100,1,13.83,15,1,13.92,2,1,13.98,200,1,14.12,100,1,14.28,100,1,14.45,100,1,14.56,800,1,14.6,700,1,2,326082353
2025-07-17T16:02:40.795014471Z,2025-07-17T16:02:40.794847674Z,160,2,1108,C,A,13.790000000,15,0,326077141,130,166797,271972417,ARL,,13.26,100,1,13.12,200,1,13.03,100,1,13,2,1,12.73,100,1,12.71,100,1,12.5,700,1,12.46,200,1,12.43,700,1,12.42,700,1,13.8,100,1,13.83,15,1,13.92,2,1,13.98,200,1,14.12,100,1,14.28,100,1,14.45,100,1,14.56,800,1,14.6,700,1,14.63,100,1,2,326077141
2025-07-17T16:02:40.806305895Z,2025-07-17T16:02:40.806140621Z,160,2,1108,C,A,13.830000000,15,0,325714721,130,165274,271973288,ARL,,13.26,100,1,13.12,200,1,13.03,100,1,13,2,1,12.73,100,1,12.71,100,1,12.5,700,1,12.46,200,1,12.43,700,1,12.42,700,1,13.8,100,1,13.92,2,1,13.98,200,1,14.12,100,1,14.28,100,1,14.45,100,1,14.56,800,1,14.6,700,1,14.63,100,1,14.68,1400,1,2,325714721
2025-07-17T16:02:43.841852430Z,2025-07-17T16:02:43.841686908Z,160,2,1108,C,B,13.260000000,100,0,325718821,130,165522,272014658,ARL,,13.12,200,1,13.03,100,1,13,2,1,12.73,100,1,12.71,100,1,12.5,700,1,12.46,200,1,12.43,700,1,12.42,700,1,12.37,700,1,13.8,100,1,13.92,2,1,13.98,200,1,14.12,100,1,14.28,100,1,14.45,100,1,14.56,800,1,14.6,700,1,14.63,100,1,14.68,1400,1,2,325718821
2025-07-17T16:02:43.841912053Z,2025-07-17T16:02:43.841746626Z,160,2,1108,A,A,13.900000000,4,0,326158809,130,165427,272014659,ARL,,13.12,200,1,13.03,100,1,13,2,1,12.73,100,1,12.71,100,1,12.5,700,1,12.46,200,1,12.43,700,1,12.42,700,1,12.37,700,1,13.8,100,1,13.9,4,1,13.92,2,1,13.98,200,1,14.12,100,1,14.28,100,1,14.45,100,1,14.56,800,1,14.6,700,1,14.63,100,1,2,326158809
2025-07-17T16:02:43.842295427Z,2025-07-17T16:02:43.842130114Z,160,2,1108,C,A,13.800000000,100,0,326082329,130,165313,272014661,ARL,,13.12,200,1,13.03,100,1,13,2,1,12.73,100,1,12.71,100,1,12.5,700,1,12.46,200,1,12.43,700,1,12.42,700,1,12.37,700,1,13.9,4,1,13.92,2,1,13.98,200,1,14.12,100,1,14.28,100,1,14.45,100,1,14.56,800,1,14.6,700,1,14.63,100,1,14.68,1400,1,2,326082329
2025-07-17T16:02:43.843036936Z,2025-07-17T16:02:43.842871428Z,160,2,1108,C,A,14.870000000,100,0,326082353,0,165508,272014673,ARL,,13.12,200,1,13.03,100,1,13,2,1,12.73,100,1,12.71,100,1,12.5,700,1,12.46,200,1,12.43,700,1,12.42,700,1,12.37,700,1,13.9,4,1,13.92,2,1,13.98,200,1,14.12,100,1,14.28,100,1,14.45,100,1,14.56,800,1,14.6,700,1,14.63,100,1,14.68,1400,1,2,326082353
2025-07-17T16:02:43.843036936Z,2025-07-17T16:02:43.842871428Z,160,2,1108,A,A,14.920000000,100,0,326158869,130,165508,272014673,ARL,,13.12,200,1,13.03,100,1,13,2,1,12.73,100,1,12.71,100,1,12.5,700,1,12.46,200,1,12.43,700,1,12.42,700,1,12.37,700,1,13.9,4,1,13.92,2,1,13.98,200,1,14.12,100,1,14.28,100,1,14.45,100,1,14.56,800,1,14.6,700,1,14.63,100,1,14.68,1400,1,2,326158869
2025-07-17T16:02:43.843106749Z,2025-07-17T16:02:43.842941514Z,160,2,1108,A,B,13.110000000,100,0,326158877,130,165235,272014674,ARL,,13.12,200,1,13.11,100,1,13.03,100,1,13,2,1,12.73,100,1,12.71,100,1,12.5,700,1,12.46,200,1,12.43,700,1,12.42,700,1,13.9,4,1,13.92,2,1,13.98,200,1,14.12,100,1,14.28,100,1,14.45,100,1,14.56,800,1,14.6,700,1,14.63,100,1,14.68,1400,1,2,326158877
2025-07-17T16:02:43.843109026Z,2025-07-17T16:02:43.842943173Z,160,2,1108,C,A,14.810000000,100,0,325718549,0,165853,272014675,ARL,,13.12,200,1,13.11,100,1,13.03,100,1,13,2,1,12.73,100,1,12.71,100,1,12.5,700,1,12.46,200,1,12.43,700,1,12.42,700,1,13.9,4,1,13.92,2,1,13.98,200,1,14.12,100,1,14.28,100,1,14.45,100,1,14.56,800,1,14.6,700,1,14.63,100,1,14.68,1400,1,2,325718549
2025-07-17T16:02:43.843109026Z,2025-07-17T16:02:43.842943173Z,160,2,1108,A,A,14.960000000,100,0,326158881,130,165853,272014675,ARL,,13.12,200,1,13.11,100,1,13.03,100,1,13,2,1,12.73,100,1,12.71,100,1,12.5,700,1,12.46,200,1,12.43,700,1,12.42,700,1,13.9,4,1,13.92,2,1,13.98,200,1,14.12,100,1,14.28,100,1,14.45,100,1,14.56,800,1,14.6,700,1,14.63,100,1,14.68,1400,1,2,326158881
2025-07-17T16:02:43.843204692Z,2025-07-17T16:02:43.843039530Z,160,2,1108,C,A,13.900000000,4,0,326158809,130,165162,272014681,ARL,,13.12,200,1,13.11,100,1,13.03,100,1,13,2,1,12.73,100,1,12.71,100,1,12.5,700,1,12.46,200,1,12.43,700,1,12.42,700,1,13.92,2,1,13.98,200,1,14.12,100,1,14.28,100,1,14.45,100,1,14.56,800,1,14.6,700,1,14.63,100,1,14.68,1400,1,14.73,200,1,2,326158809
2025-07-17T16:02:43.843956820Z,2025-07-17T16:02:43.843791297Z,160,2,1108,C,A,17.580000000,100,0,325718557,0,165523,272014689,ARL,,13.12,200,1,13.11,100,1,13.03,100,1,13,2,1,12.73,100,1,12.71,100,1,12.5,700,1,12.46,200,1,12.43,700,1,12.42,700,1,13.92,2,1,13.98,200,1,14.12,100,1,14.28,100,1,14.45,100,1,14.56,800,1,14.6,700,1,14.63,100,1,14.68,1400,1,14.73,200,1,2,325718557
2025-07-17T16:02:43.843956820Z,2025-07-17T16:02:43.843791297Z,160,2,1108,A,A,17.760000000,100,0,326158953,130,165523,272014689,ARL,,13.12,200,1,13.11,100,1,13.03,100,1,13,2,1,12.73,100,1,12.71,100,1,12.5,700,1,12.46,200,1,12.43,700,1,12.42,700,1,13.92,2,1,13.98,200,1,14.12,100,1,14.28,100,1,14.45,100,1,14.56,800,1,14.6,700,1,14.63,100,1,14.68,1400,1,14.73,200,1,2,326158953
2025-07-17T16:02:43.844653014Z,2025-07-17T16:02:43.844487204Z,160,2,1108,C,A,15.920000000,100,0,325718525,0,165810,272014697,ARL,,13.12,200,1,13.11,100,1,13.03,100,1,13,2,1,12.73,100,1,12.71,100,1,12.5,700,1,12.46,200,1,12.43,700,1,12.42,700,1,13.92,2,1,13.98,200,1,14.12,100,1,14.28,100,1,14.45,100,1,14.56,800,1,14.6,700,1,14.63,100,1,14.68,1400,1,14.73,200,1,2,325718525
2025-07-17T16:02:43.844653014Z,2025-07-17T16:02:43.844487204Z,160,2,1108,A,A,16.080000000,100,0,326158989,130,165810,272014697,ARL,,13.12,200,1,13.11,100,1,13.03,100,1,13,2,1,12.73,100,1,12.71,100,1,12.5,700,1,12.46,200,1,12.43,700,1,12.42,700,1,13.92,2,1,13.98,200,1,14.12,100,1,14.28,100,1,14.45,100,1,14.56,800,1,14.6,700,1,14.63,100,1,14.68,1400,1,14.73,200,1,2,326158989
2025-07-17T16:02:43.844801951Z,2025-07-17T16:02:43.844636465Z,160,2,1108,C,A,14.810000000,100,0,325718517,0,165486,272014698,ARL,,13.12,200,1,13.11,100,1,13.03,100,1,13,2,1,12.73,100,1,12.71,100,1,12.5,700,1,12.46,200,1,12.43,700,1,12.42,700,1,13.92,2,1,13.98,200,1,14.12,100,1,14.28,100,1,14.45,100,1,14.56,800,1,14.6,700,1,14.63,100,1,14.68,1400,1,14.73,200,1,2,325718517
2025-07-17T16:02:43.844801951Z,2025-07-17T16:02:43.844636465Z,160,2,1108,A,A,14.960000000,100,0,326158997,130,165486,272014698,ARL,,13.12,200,1,13.11,100,1,13.03,100,1,13,2,1,12.73,100,1,12.71,100,1,12.5,700,1,12.46,200,1,12.43,700,1,12.42,700,1,13.92,2,1,13.98,200,1,14.12,100,1,14.28,100,1,14.45,100,1,14.56,800,1,14.6,700,1,14.63,100,1,14.68,1400,1,14.73,200,1,2,326158997
2025-07-17T16:02:43.847026795Z,2025-07-17T16:02:43.846861336Z,160,2,1108,C,A,13.920000000,2,0,325297093,0,165459,272014713,ARL,,13.12,200,1,13.11,100,1,13.03,100,1,13,2,1,12.73,100,1,12.71,100,1,12.5,700,1,12.46,200,1,12.43,700,1,12.42,700,1,13.98,200,1,14.12,100,1,14.28,100,1,14.45,100,1,14.56,800,1,14.6,700,1,14.63,100,1,14.68,1400,1,14.73,200,1,14.92,100,1,2,325297093
2025-07-17T16:02:43.847026795Z,2025-07-17T16:02:43.846861336Z,160,2,1108,A,A,14.030000000,2,0,326159041,130,165459,272014713,ARL,,13.12,200,1,13.11,100,1,13.03,100,1,13,2,1,12.73,100,1,12.71,100,1,12.5,700,1,12.46,200,1,12.43,700,1,12.42,700,1,13.98,200,1,14.03,2,1,14.12,100,1,14.28,100,1,14.45,100,1,14.56,800,1,14.6,700,1,14.63,100,1,14.68,1400,1,14.73,200,1,2,326159041
2025-07-17T16:02:43.847832258Z,2025-07-17T16:02:43.847666979Z,160,2,1108,C,A,14.730000000,100,0,325714613,0,165279,272014721,ARL,,13.12,200,1,13.11,100,1,13.03,100,1,13,2,1,12.73,100,1,12.71,100,1,12.5,700,1,12.46,200,1,12.43,700,1,12.42,700,1,13.98,200,1,14.03,2,1,14.12,100,1,14.28,100,1,14.45,100,1,14.56,800,1,14.6,700,1,14.63,100,1,14.68,1400,1,14.73,100,1,2,325714613
2025-07-17T16:02:43.847832258Z,2025-07-17T16:02:43.847666979Z,160,2,1108,A,A,14.870000000,100,0,326159049,130,165279,272014721,ARL,,13.12,200,1,13.11,100,1,13.03,100,1,13,2,1,12.73,100,1,12.71,100,1,12.5,700,1,12.46,200,1,12.43,700,1,12.42,700,1,13.98,200,1,14.03,2,1,14.12,100,1,14.28,100,1,14.45,100,1,14.56,800,1,14.6,700,1,14.63,100,1,14.68,1400,1,14.73,100,1,2,326159049
2025-07-17T16:02:43.848147198Z,2025-07-17T16:02:43.847981726Z,160,2,1108,C,A,14.730000000,100,0,325714577,0,165472,272014724,ARL,,13.12,200,1,13.11,100,1,13.03,100,1,13,2,1,12.73,100,1,12.71,100,1,12.5,700,1,12.46,200,1,12.43,700,1,12.42,700,1,13.98,200,1,14.03,2,1,14.12,100,1,14.28,100,1,14.45,100,1,14.56,800,1,14.6,700,1,14.63,100,1,14.68,1400,1,14.87,100,1,2,325714577
2025-07-17T16:02:43.848147198Z,2025-07-17T16:02:43.847981726Z,160,2,1108,A,A,14.870000000,100,0,326159061,130,165472,272014724,ARL,,13.12,200,1,13.11,100,1,13.03,100,1,13,2,1,12.73,100,1,12.71,100,1,12.5,700,1,12.46,200,1,12.43,700,1,12.42,700,1,13.98,200,1,14.03,2,1,14.12,100,1,14.28,100,1,14.45,100,1,14.56,800,1,14.6,700,1,14.63,100,1,14.68,1400,1,14.87,200,1,2,326159061
2025-07-17T16:02:43.860199647Z,2025-07-17T16:02:43.860034354Z,160,2,1108,C,A,14.120000000,100,0,325718637,130,165293,272014788,ARL,,13.12,200,1,13.11,100,1,13.03,100,1,13,2,1,12.73,100,1,12.71,100,1,12.5,700,1,12.46,200,1,12.43,700,1,12.42,700,1,13.98,200,1,14.03,2,1,14.28,100,1,14.45,100,1,14.56,800,1,14.6,700,1,14.63,100,1,14.68,1400,1,14.87,200,1,14.92,100,1,2,325718637
2025-07-17T16:02:43.860252446Z,2025-07-17T16:02:43.860087215Z,160,2,1108,A,A,14.260000000,100,0,326159201,130,165231,272014789,ARL,,13.12,200,1,13.11,100,1,13.03,100,1,13,2,1,12.73,100,1,12.71,100,1,12.5,700,1,12.46,200,1,12.43,700,1,12.42,700,1,13.98,200,1,14.03,2,1,14.26,100,1,14.28,100,1,14.45,100,1,14.56,800,1,14.6,700,1,14.63,100,1,14.68,1400,1,14.87,200,1,2,326159201
2025-07-17T16:02:43.893176312Z,2025-07-17T16:02:43.893011012Z,160,2,1108,C,A,14.920000000,100,0,326158869,0,165300,272014986,ARL,,13.12,200,1,13.11,100,1,13.03,100,1,13,2,1,12.73,100,1,12.71,100,1,12.5,700,1,12.46,200,1,12.43,700,1,12.42,700,1,13.98,200,1,14.03,2,1,14.26,100,1,14.28,100,1,14.45,100,1,14.56,800,1,14.6,700,1,14.63,100,1,14.68,1400,1,14.87,200,1,2,326158869
2025-07-17T16:02:43.893176312Z,2025-07-17T16:02:43.893011012Z,160,2,1108,A,A,15.060000000,100,0,326159425,130,165300,272014986,ARL,,13.12,200,1,13.11,100,1,13.03,100,1,13,2,1,12.73,100,1,12.71,100,1,12.5,700,1,12.46,200,1,12.43,700,1,12.42,700,1,13.98,200,1,14.03,2,1,14.26,100,1,14.28,100,1,14.45,100,1,14.56,800,1,14.6,700,1,14.63,100,1,14.68,1400,1,14.87,200,1,2,326159425
2025-07-17T16:02:43.946967137Z,2025-07-17T16:02:43.946801538Z,160,2,1108,C,A,14.630000000,100,0,325714653,0,165599,272015584,ARL,,13.12,200,1,13.11,100,1,13.03,100,1,13,2,1,12.73,100,1,12.71,100,1,12.5,700,1,12.46,200,1,12.43,700,1,12.42,700,1,13.98,200,1,14.03,2,1,14.26,100,1,14.28,100,1,14.45,100,1,14.56,800,1,14.6,700,1,14.68,1400,1,14.87,200,1,14.96,200,1,2,325714653
2025-07-17T16:02:43.946967137Z,2025-07-17T16:02:43.946801538Z,160,2,1108,A,A,14.770000000,100,0,326160141,130,165599,272015584,ARL,,13.12,200,1,13.11,100,1,13.03,100,1,13,2,1,12.73,100,1,12.71,100,1,12.5,700,1,12.46,200,1,12.43,700,1,12.42,700,1,13.98,200,1,14.03,2,1,14.26,100,1,14.28,100,1,14.45,100,1,14.56,800,1,14.6,700,1,14.68,1400,1,14.77,100,1,14.87,200,1,2,326160141
2025-07-17T16:02:44.664219784Z,2025-07-17T16:02:44.664054457Z,160,2,1108,A,A,13.990000000,100,0,326167529,130,165327,272021808,ARL,,13.12,200,1,13.11,100,1,13.03,100,1,13,2,1,12.73,100,1,12.71,100,1,12.5,700,1,12.46,200,1,12.43,700,1,12.42,700,1,13.98,200,1,13.99,100,1,14.03,2,1,14.26,100,1,14.28,100,1,14.45,100,1,14.56,800,1,14.6,700,1,14.68,1400,1,14.77,100,1,2,326167529
2025-07-17T16:03:02.985987598Z,2025-07-17T16:03:02.985818199Z,160,2,1108,C,A,14.870000000,100,0,326159049,0,169399,272331833,ARL,,13.12,200,1,13.11,100,1,13.03,100,1,13,2,1,12.73,100,1,12.71,100,1,12.5,700,1,12.46,200,1,12.43,700,1,12.42,700,1,13.98,200,1,13.99,100,1,14.03,2,1,14.26,100,1,14.28,100,1,14.45,100,1,14.56,800,1,14.6,700,1,14.68,1400,1,14.77,100,1,2,326159049
2025-07-17T16:03:02.985987598Z,2025-07-17T16:03:02.985818199Z,160,2,1108,A,A,14.700000000,100,0,326551237,128,169399,272331833,ARL,,13.12,200,1,13.11,100,1,13.03,100,1,13,2,1,12.73,100,1,12.71,100,1,12.5,700,1,12.46,200,1,12.43,700,1,12.42,700,1,13.98,200,1,13.99,100,1,14.03,2,1,14.26,100,1,14.28,100,1,14.45,100,1,14.56,800,1,14.6,700,1,14.68,1400,1,14.7,100,1,2,326551237
2025-07-17T16:03:02.987969729Z,2025-07-17T16:03:02.987797728Z,160,2,1108,C,A,14.870000000,100,0,326159061,0,172001,272332718,ARL,,13.12,200,1,13.11,100,1,13.03,100,1,13,2,1,12.73,100,1,12.71,100,1,12.5,700,1,12.46,200,1,12.43,700,1,12.42,700,1,13.98,200,1,13.99,100,1,14.03,2,1,14.26,100,1,14.28,100,1,14.45,100,1,14.56,800,1,14.6,700,1,14.68,1400,1,14.7,100,1,2,326159061
2025-07-17T16:03:02.987969729Z,2025-07-17T16:03:02.987797728Z,160,2,1108,A,A,14.700000000,100,0,326551829,128,172001,272332718,ARL,,13.12,200,1,13.11,100,1,13.03,100,1,13,2,1,12.73,100,1,12.71,100,1,12.5,700,1,12.46,200,1,12.43,700,1,12.42,700,1,13.98,200,1,13.99,100,1,14.03,2,1,14.26,100,1,14.28,100,1,14.45,100,1,14.56,800,1,14.6,700,1,14.68,1400,1,14.7,200,1,2,326551829
2025-07-17T16:03:10.807446975Z,2025-07-17T16:03:10.807281669Z,160,2,1108,A,A,13.720000000,15,0,326729677,130,165306,272474575,ARL,,13.12,200,1,13.11,100,1,13.03,100,1,13,2,1,12.73,100,1,12.71,100,1,12.5,700,1,12.46,200,1,12.43,700,1,12.42,700,1,13.72,15,1,13.98,200,1,13.99,100,1,14.03,2,1,14.26,100,1,14.28,100,1,14.45,100,1,14.56,800,1,14.6,700,1,14.68,1400,1,2,326729677
2025-07-17T16:03:10.807714421Z,2025-07-17T16:03:10.807548848Z,160,2,1108,C,A,13.990000000,100,0,326167529,0,165573,272474576,ARL,,13.12,200,1,13.11,100,1,13.03,100,1,13,2,1,12.73,100,1,12.71,100,1,12.5,700,1,12.46,200,1,12.43,700,1,12.42,700,1,13.72,15,1,13.98,200,1,14.03,2,1,14.26,100,1,14.28,100,1,14.45,100,1,14.56,800,1,14.6,700,1,14.68,1400,1,14.7,200,1,2,326167529
2025-07-17T16:03:10.807714421Z,2025-07-17T16:03:10.807548848Z,160,2,1108,A,A,13.730000000,100,0,326729685,130,165573,272474576,ARL,,13.12,200,1,13.11,100,1,13.03,100,1,13,2,1,12.73,100,1,12.71,100,1,12.5,700,1,12.46,200,1,12.43,700,1,12.42,700,1,13.72,15,1,13.73,100,1,13.98,200,1,14.03,2,1,14.26,100,1,14.28,100,1,14.45,100,1,14.56,800,1,14.6,700,1,14.68,1400,1,2,326729685
2025-07-17T16:03:10.808457278Z,2025-07-17T16:03:10.808290914Z,160,2,1108,C,A,15.060000000,100,0,326159425,0,166364,272474580,ARL,,13.12,200,1,13.11,100,1,13.03,100,1,13,2,1,12.73,100,1,12.71,100,1,12.5,700,1,12.46,200,1,12.43,700,1,12.42,700,1,13.72,15,1,13.73,100,1,13.98,200,1,14.03,2,1,14.26,100,1,14.28,100,1,14.45,100,1,14.56,800,1,14.6,700,1,14.68,1400,1,2,326159425
2025-07-17T16:03:10.808457278Z,2025-07-17T16:03:10.808290914Z,160,2,1108,A,A,14.790000000,100,0,326729705,128,166364,272474580,ARL,,13.12,200,1,13.11,100,1,13.03,100,1,13,2,1,12.73,100,1,12.71,100,1,12.5,700,1,12.46,200,1,12.43,700,1,12.42,700,1,13.72,15,1,13.73,100,1,13.98,200,1,14.03,2,1,14.26,100,1,14.28,100,1,14.45,100,1,14.56,800,1,14.6,700,1,14.68,1400,1,2,326729705
2025-07-17T16:03:10.809707274Z,2025-07-17T16:03:10.809541651Z,160,2,1108,C,A,14.960000000,100,0,326158881,0,165623,272474585,ARL,,13.12,200,1,13.11,100,1,13.03,100,1,13,2,1,12.73,100,1,12.71,100,1,12.5,700,1,12.46,200,1,12.43,700,1,12.42,700,1,13.72,15,1,13.73,100,1,13.98,200,1,14.03,2,1,14.26,100,1,14.28,100,1,14.45,100,1,14.56,800,1,14.6,700,1,14.68,1400,1,2,326158881
2025-07-17T16:03:10.809707274Z,2025-07-17T16:03:10.809541651Z,160,2,1108,A,A,14.700000000,100,0,326729721,130,165623,272474585,ARL,,13.12,200,1,13.11,100,1,13.03,100,1,13,2,1,12.73,100,1,12.71,100,1,12.5,700,1,12.46,200,1,12.43,700,1,12.42,700,1,13.72,15,1,13.73,100,1,13.98,200,1,14.03,2,1,14.26,100,1,14.28,100,1,14.45,100,1,14.56,800,1,14.6,700,1,14.68,1400,1,2,326729721
2025-07-17T16:03:10.809936821Z,2025-07-17T16:03:10.809771527Z,160,2,1108,C,A,14.770000000,100,0,326160141,130,165294,272474594,ARL,,13.12,200,1,13.11,100,1,13.03,100,1,13,2,1,12.73,100,1,12.71,100,1,12.5,700,1,12.46,200,1,12.43,700,1,12.42,700,1,13.72,15,1,13.73,100,1,13.98,200,1,14.03,2,1,14.26,100,1,14.28,100,1,14.45,100,1,14.56,800,1,14.6,700,1,14.68,1400,1,2,326160141
2025-07-17T16:03:10.809963577Z,2025-07-17T16:03:10.809798084Z,160,2,1108,C,A,17.760000000,100,0,326158953,0,165493,272474595,ARL,,13.12,200,1,13.11,100,1,13.03,100,1,13,2,1,12.73,100,1,12.71,100,1,12.5,700,1,12.46,200,1,12.43,700,1,12.42,700,1,13.72,15,1,13.73,100,1,13.98,200,1,14.03,2,1,14.26,100,1,14.28,100,1,14.45,100,1,14.56,800,1,14.6,700,1,14.68,1400,1,2,326158953
2025-07-17T16:03:10.809963577Z,2025-07-17T16:03:10.809798084Z,160,2,1108,A,A,17.440000000,100,0,326729725,130,165493,272474595,ARL,,13.12,200,1,13.11,100,1,13.03,100,1,13,2,1,12.73,100,1,12.71,100,1,12.5,700,1,12.46,200,1,12.43,700,1,12.42,700,1,13.72,15,1,13.73,100,1,13.98,200,1,14.03,2,1,14.26,100,1,14.28,100,1,14.45,100,1,14.56,800,1,14.6,700,1,14.68,1400,1,2,326729725
2025-07-17T16:03:10.810059442Z,2025-07-17T16:03:10.809894317Z,160,2,1108,A,A,14.520000000,100,0,326729729,130,165125,272474597,ARL,,13.12,200,1,13.11,100,1,13.03,100,1,13,2,1,12.73,100,1,12.71,100,1,12.5,700,1,12.46,200,1,12.43,700,1,12.42,700,1,13.72,15,1,13.73,100,1,13.98,200,1,14.03,2,1,14.26,100,1,14.28,100,1,14.45,100,1,14.52,100,1,14.56,800,1,14.6,700,1,2,326729729
2025-07-17T16:03:10.810478524Z,2025-07-17T16:03:10.810312923Z,160,2,1108,C,A,16.080000000,100,0,326158989,0,165601,272474600,ARL,,13.12,200,1,13.11,100,1,13.03,100,1,13,2,1,12.73,100,1,12.71,100,1,12.5,700,1,12.46,200,1,12.43,700,1,12.42,700,1,13.72,15,1,13.73,100,1,13.98,200,1,14.03,2,1,14.26,100,1,14.28,100,1,14.45,100,1,14.52,100,1,14.56,800,1,14.6,700,1,2,326158989
2025-07-17T16:03:10.810478524Z,2025-07-17T16:03:10.810312923Z,160,2,1108,A,A,15.790000000,100,0,326729733,130,165601,272474600,ARL,,13.12,200,1,13.11,100,1,13.03,100,1,13,2,1,12.73,100,1,12.71,100,1,12.5,700,1,12.46,200,1,12.43,700,1,12.42,700,1,13.72,15,1,13.73,100,1,13.98,200,1,14.03,2,1,14.26,100,1,14.28,100,1,14.45,100,1,14.52,100,1,14.56,800,1,14.6,700,1,2,326729733
2025-07-17T16:03:10.814646270Z,2025-07-17T16:03:10.814480532Z,160,2,1108,C,A,14.960000000,100,0,326158997,0,165738,272474635,ARL,,13.12,200,1,13.11,100,1,13.03,100,1,13,2,1,12.73,100,1,12.71,100,1,12.5,700,1,12.46,200,1,12.43,700,1,12.42,700,1,13.72,15,1,13.73,100,1,13.98,200,1,14.03,2,1,14.26,100,1,14.28,100,1,14.45,100,1,14.52,100,1,14.56,800,1,14.6,700,1,2,326158997
2025-07-17T16:03:10.814646270Z,2025-07-17T16:03:10.814480532Z,160,2,1108,A,A,14.700000000,100,0,326729821,130,165738,272474635,ARL,,13.12,200,1,13.11,100,1,13.03,100,1,13,2,1,12.73,100,1,12.71,100,1,12.5,700,1,12.46,200,1,12.43,700,1,12.42,700,1,13.72,15,1,13.73,100,1,13.98,200,1,14.03,2,1,14.26,100,1,14.28,100,1,14.45,100,1,14.52,100,1,14.56,800,1,14.6,700,1,2,326729821
2025-07-17T16:03:10.817866066Z,2025-07-17T16:03:10.817700664Z,160,2,1108,C,A,14.260000000,100,0,326159201,130,165402,272474675,ARL,,13.12,200,1,13.11,100,1,13.03,100,1,13,2,1,12.73,100,1,12.71,100,1,12.5,700,1,12.46,200,1,12.43,700,1,12.42,700,1,13.72,15,1,13.73,100,1,13.98,200,1,14.03,2,1,14.28,100,1,14.45,100,1,14.52,100,1,14.56,800,1,14.6,700,1,14.68,1400,1,2,326159201
2025-07-17T16:03:10.817919970Z,2025-07-17T16:03:10.817754737Z,160,2,1108,A,A,14.000000000,100,0,326729929,130,165233,272474676,ARL,,13.12,200,1,13.11,100,1,13.03,100,1,13,2,1,12.73,100,1,12.71,100,1,12.5,700,1,12.46,200,1,12.43,700,1,12.42,700,1,13.72,15,1,13.73,100,1,13.98,200,1,14,100,1,14.03,2,1,14.28,100,1,14.45,100,1,14.52,100,1,14.56,800,1,14.6,700,1,2,326729929
2025-07-17T16:03:10.843337845Z,2025-07-17T16:03:10.843172549Z,160,2,1108,A,A,15.660000000,100,0,326730513,130,165296,272474826,ARL,,13.12,200,1,13.11,100,1,13.03,100,1,13,2,1,12.73,100,1,12.71,100,1,12.5,700,1,12.46,200,1,12.43,700,1,12.42,700,1,13.72,15,1,13.73,100,1,13.98,200,1,14,100,1,14.03,2,1,14.28,100,1,14.45,100,1,14.52,100,1,14.56,800,1,14.6,700,1,2,326730513
2025-07-17T16:03:10.843350160Z,2025-07-17T16:03:10.843184785Z,160,2,1108,C,A,15.940000000,100,0,325714909,130,165375,272474827,ARL,,13.12,200,1,13.11,100,1,13.03,100,1,13,2,1,12.73,100,1,12.71,100,1,12.5,700,1,12.46,200,1,12.43,700,1,12.42,700,1,13.72,15,1,13.73,100,1,13.98,200,1,14,100,1,14.03,2,1,14.28,100,1,14.45,100,1,14.52,100,1,14.56,800,1,14.6,700,1,2,325714909
2025-07-17T16:03:10.843615537Z,2025-07-17T16:03:10.843448998Z,160,2,1108,C,A,13.980000000,100,0,325719357,0,166539,272474828,ARL,,13.12,200,1,13.11,100,1,13.03,100,1,13,2,1,12.73,100,1,12.71,100,1,12.5,700,1,12.46,200,1,12.43,700,1,12.42,700,1,13.72,15,1,13.73,100,1,13.98,100,1,14,100,1,14.03,2,1,14.28,100,1,14.45,100,1,14.52,100,1,14.56,800,1,14.6,700,1,2,325719357
2025-07-17T16:03:10.843615537Z,2025-07-17T16:03:10.843449402Z,160,2,1108,C,A,13.980000000,100,0,325719353,130,166135,272474829,ARL,,13.12,200,1,13.11,100,1,13.03,100,1,13,2,1,12.73,100,1,12.71,100,1,12.5,700,1,12.46,200,1,12.43,700,1,12.42,700,1,13.72,15,1,13.73,100,1,14,100,1,14.03,2,1,14.28,100,1,14.45,100,1,14.52,100,1,14.56,800,1,14.6,700,1,14.68,1400,1,2,325719353
2025-07-17T16:03:10.843628246Z,2025-07-17T16:03:10.843462898Z,160,2,1108,A,A,13.870000000,100,0,326730517,130,165348,272474830,ARL,,13.12,200,1,13.11,100,1,13.03,100,1,13,2,1,12.73,100,1,12.71,100,1,12.5,700,1,12.46,200,1,12.43,700,1,12.42,700,1,13.72,15,1,13.73,100,1,13.87,100,1,14,100,1,14.03,2,1,14.28,100,1,14.45,100,1,14.52,100,1,14.56,800,1,14.6,700,1,2,326730517
2025-07-17T16:03:10.843629633Z,2025-07-17T16:03:10.843464369Z,160,2,1108,A,A,13.870000000,100,0,326730521,130,165264,272474831,ARL,,13.12,200,1,13.11,100,1,13.03,100,1,13,2,1,12.73,100,1,12.71,100,1,12.5,700,1,12.46,200,1,12.43,700,1,12.42,700,1,13.72,15,1,13.73,100,1,13.87,200,1,14,100,1,14.03,2,1,14.28,100,1,14.45,100,1,14.52,100,1,14.56,800,1,14.6,700,1,2,326730521
2025-07-17T16:03:16.348189077Z,2025-07-17T16:03:16.348023740Z,160,2,1108,A,A,13.690000000,15,0,326835877,130,165337,272557172,ARL,,13.12,200,1,13.11,100,1,13.03,100,1,13,2,1,12.73,100,1,12.71,100,1,12.5,700,1,12.46,200,1,12.43,700,1,12.42,700,1,13.69,15,1,13.72,15,1,13.73,100,1,13.87,200,1,14,100,1,14.03,2,1,14.28,100,1,14.45,100,1,14.52,100,1,14.56,800,1,2,326835877
2025-07-17T16:03:16.348468824Z,2025-07-17T16:03:16.348302787Z,160,2,1108,C,A,14.700000000,100,0,326551829,0,166037,272557230,ARL,,13.12,200,1,13.11,100,1,13.03,100,1,13,2,1,12.73,100,1,12.71,100,1,12.5,700,1,12.46,200,1,12.43,700,1,12.42,700,1,13.69,15,1,13.72,15,1,13.73,100,1,13.87,200,1,14,100,1,14.03,2,1,14.28,100,1,14.45,100,1,14.52,100,1,14.56,800,1,2,326551829
2025-07-17T16:03:16.348468824Z,2025-07-17T16:03:16.348302787Z,160,2,1108,A,A,14.580000000,100,0,326835885,130,166037,272557230,ARL,,13.12,200,1,13.11,100,1,13.03,100,1,13,2,1,12.73,100,1,12.71,100,1,12.5,700,1,12.46,200,1,12.43,700,1,12.42,700,1,13.69,15,1,13.72,15,1,13.73,100,1,13.87,200,1,14,100,1,14.03,2,1,14.28,100,1,14.45,100,1,14.52,100,1,14.56,800,1,2,326835885
2025-07-17T16:03:16.349679949Z,2025-07-17T16:03:16.349513354Z,160,2,1108,C,A,14.700000000,100,0,326551237,0,166595,272557430,ARL,,13.12,200,1,13.11,100,1,13.03,100,1,13,2,1,12.73,100,1,12.71,100,1,12.5,700,1,12.46,200,1,12.43,700,1,12.42,700,1,13.69,15,1,13.72,15,1,13.73,100,1,13.87,200,1,14,100,1,14.03,2,1,14.28,100,1,14.45,100,1,14.52,100,1,14.56,800,1,2,326551237
2025-07-17T16:03:16.349679949Z,2025-07-17T16:03:16.349513354Z,160,2,1108,A,A,14.580000000,100,0,326836085,130,166595,272557430,ARL,,13.12,200,1,13.11,100,1,13.03,100,1,13,2,1,12.73,100,1,12.71,100,1,12.5,700,1,12.46,200,1,12.43,700,1,12.42,700,1,13.69,15,1,13.72,15,1,13.73,100,1,13.87,200,1,14,100,1,14.03,2,1,14.28,100,1,14.45,100,1,14.52,100,1,14.56,800,1,2,326836085
2025-07-17T16:03:16.352011831Z,2025-07-17T16:03:16.351845457Z,160,2,1108,C,A,13.730000000,100,0,326729685,0,166374,272557789,ARL,,13.12,200,1,13.11,100,1,13.03,100,1,13,2,1,12.73,100,1,12.71,100,1,12.5,700,1,12.46,200,1,12.43,700,1,12.42,700,1,13.69,15,1,13.72,15,1,13.87,200,1,14,100,1,14.03,2,1,14.28,100,1,14.45,100,1,14.52,100,1,14.56,800,1,14.58,200,1,2,326729685
2025-07-17T16:03:16.352011831Z,2025-07-17T16:03:16.351845457Z,160,2,1108,A,A,13.700000000,100,0,326836533,130,166374,272557789,ARL,,13.12,200,1,13.11,100,1,13.03,100,1,13,2,1,12.73,100,1,12.71,100,1,12.5,700,1,12.46,200,1,12.43,700,1,12.42,700,1,13.69,15,1,13.7,100,1,13.72,15,1,13.87,200,1,14,100,1,14.03,2,1,14.28,100,1,14.45,100,1,14.52,100,1,14.56,800,1,2,326836533
2025-07-17T16:03:16.365985162Z,2025-07-17T16:03:16.365819243Z,160,2,1108,C,A,15.380000000,100,0,325714965,0,165919,272559024,ARL,,13.12,200,1,13.11,100,1,13.03,100,1,13,2,1,12.73,100,1,12.71,100,1,12.5,700,1,12.46,200,1,12.43,700,1,12.42,700,1,13.69,15,1,13.7,100,1,13.72,15,1,13.87,200,1,14,100,1,14.03,2,1,14.28,100,1,14.45,100,1,14.52,100,1,14.56,800,1,2,325714965
2025-07-17T16:03:16.365985162Z,2025-07-17T16:03:16.365819243Z,160,2,1108,A,A,15.070000000,100,0,326837501,130,165919,272559024,ARL,,13.12,200,1,13.11,100,1,13.03,100,1,13,2,1,12.73,100,1,12.71,100,1,12.5,700,1,12.46,200,1,12.43,700,1,12.42,700,1,13.69,15,1,13.7,100,1,13.72,15,1,13.87,200,1,14,100,1,14.03,2,1,14.28,100,1,14.45,100,1,14.52,100,1,14.56,800,1,2,326837501
2025-07-17T16:03:18.804325078Z,2025-07-17T16:03:18.804159952Z,160,2,1108,C,A,13.690000000,15,0,326835877,130,165126,272609485,ARL,,13.12,200,1,13.11,100,1,13.03,100,1,13,2,1,12.73,100,1,12.71,100,1,12.5,700,1,12.46,200,1,12.43,700,1,12.42,700,1,13.7,100,1,13.72,15,1,13.87,200,1,14,100,1,14.03,2,1,14.28,100,1,14.45,100,1,14.52,100,1,14.56,800,1,14.58,200,1,2,326835877
2025-07-17T16:03:18.804367560Z,2025-07-17T16:03:18.804202246Z,160,2,1108,C,A,13.700000000,100,0,326836533,130,165314,272609486,ARL,,13.12,200,1,13.11,100,1,13.03,100,1,13,2,1,12.73,100,1,12.71,100,1,12.5,700,1,12.46,200,1,12.43,700,1,12.42,700,1,13.72,15,1,13.87,200,1,14,100,1,14.03,2,1,14.28,100,1,14.45,100,1,14.52,100,1,14.56,800,1,14.58,200,1,14.6,700,1,2,326836533
2025-07-17T16:03:18.805099118Z,2025-07-17T16:03:18.804933488Z,160,2,1108,C,A,14.790000000,100,0,326729705,0,165630,272609510,ARL,,13.12,200,1,13.11,100,1,13.03,100,1,13,2,1,12.73,100,1,12.71,100,1,12.5,700,1,12.46,200,1,12.43,700,1,12.42,700,1,13.72,15,1,13.87,200,1,14,100,1,14.03,2,1,14.28,100,1,14.45,100,1,14.52,100,1,14.56,800,1,14.58,200,1,14.6,700,1,2,326729705
2025-07-17T16:03:18.805099118Z,2025-07-17T16:03:18.804933488Z,160,2,1108,A,A,14.950000000,100,0,326892717,130,165630,272609510,ARL,,13.12,200,1,13.11,100,1,13.03,100,1,13,2,1,12.73,100,1,12.71,100,1,12.5,700,1,12.46,200,1,12.43,700,1,12.42,700,1,13.72,15,1,13.87,200,1,14,100,1,14.03,2,1,14.28,100,1,14.45,100,1,14.52,100,1,14.56,800,1,14.58,200,1,14.6,700,1,2,326892717
2025-07-17T16:03:18.805291629Z,2025-07-17T16:03:18.805126035Z,160,2,1108,C,A,14.700000000,100,0,326729721,0,165594,272609526,ARL,,13.12,200,1,13.11,100,1,13.03,100,1,13,2,1,12.73,100,1,12.71,100,1,12.5,700,1,12.46,200,1,12.43,700,1,12.42,700,1,13.72,15,1,13.87,200,1,14,100,1,14.03,2,1,14.28,100,1,14.45,100,1,14.52,100,1,14.56,800,1,14.58,200,1,14.6,700,1,2,326729721
2025-07-17T16:03:18.805291629Z,2025-07-17T16:03:18.805126035Z,160,2,1108,A,A,14.850000000,100,0,326892721,130,165594,272609526,ARL,,13.12,200,1,13.11,100,1,13.03,100,1,13,2,1,12.73,100,1,12.71,100,1,12.5,700,1,12.46,200,1,12.43,700,1,12.42,700,1,13.72,15,1,13.87,200,1,14,100,1,14.03,2,1,14.28,100,1,14.45,100,1,14.52,100,1,14.56,800,1,14.58,200,1,14.6,700,1,2,326892721
2025-07-17T16:03:18.805449089Z,2025-07-17T16:03:18.805283236Z,160,2,1108,C,A,13.720000000,15,0,326729677,130,165853,272609541,ARL,,13.12,200,1,13.11,100,1,13.03,100,1,13,2,1,12.73,100,1,12.71,100,1,12.5,700,1,12.46,200,1,12.43,700,1,12.42,700,1,13.87,200,1,14,100,1,14.03,2,1,14.28,100,1,14.45,100,1,14.52,100,1,14.56,800,1,14.58,200,1,14.6,700,1,14.68,1400,1,2,326729677
2025-07-17T16:03:18.806535903Z,2025-07-17T16:03:18.806370373Z,160,2,1108,C,A,14.580000000,100,0,326835885,0,165530,272609577,ARL,,13.12,200,1,13.11,100,1,13.03,100,1,13,2,1,12.73,100,1,12.71,100,1,12.5,700,1,12.46,200,1,12.43,700,1,12.42,700,1,13.87,200,1,14,100,1,14.03,2,1,14.28,100,1,14.45,100,1,14.52,100,1,14.56,800,1,14.58,100,1,14.6,700,1,14.68,1400,1,2,326835885
2025-07-17T16:03:18.806535903Z,2025-07-17T16:03:18.806370373Z,160,2,1108,A,A,14.760000000,100,0,326892817,130,165530,272609577,ARL,,13.12,200,1,13.11,100,1,13.03,100,1,13,2,1,12.73,100,1,12.71,100,1,12.5,700,1,12.46,200,1,12.43,700,1,12.42,700,1,13.87,200,1,14,100,1,14.03,2,1,14.28,100,1,14.45,100,1,14.52,100,1,14.56,800,1,14.58,100,1,14.6,700,1,14.68,1400,1,2,326892817
2025-07-17T16:03:18.806802589Z,2025-07-17T16:03:18.806637004Z,160,2,1108,C,A,14.580000000,100,0,326836085,0,165585,272609583,ARL,,13.12,200,1,13.11,100,1,13.03,100,1,13,2,1,12.73,100,1,12.71,100,1,12.5,700,1,12.46,200,1,12.43,700,1,12.42,700,1,13.87,200,1,14,100,1,14.03,2,1,14.28,100,1,14.45,100,1,14.52,100,1,14.56,800,1,14.6,700,1,14.68,1400,1,14.7,100,1,2,326836085
2025-07-17T16:03:18.806802589Z,2025-07-17T16:03:18.806637004Z,160,2,1108,A,A,14.760000000,100,0,326892825,130,165585,272609583,ARL,,13.12,200,1,13.11,100,1,13.03,100,1,13,2,1,12.73,100,1,12.71,100,1,12.5,700,1,12.46,200,1,12.43,700,1,12.42,700,1,13.87,200,1,14,100,1,14.03,2,1,14.28,100,1,14.45,100,1,14.52,100,1,14.56,800,1,14.6,700,1,14.68,1400,1,14.7,100,1,2,326892825
2025-07-17T16:03:18.809706334Z,2025-07-17T16:03:18.809540733Z,160,2,1108,C,A,14.520000000,100,0,326729729,0,165601,272609656,ARL,,13.12,200,1,13.11,100,1,13.03,100,1,13,2,1,12.73,100,1,12.71,100,1,12.5,700,1,12.46,200,1,12.43,700,1,12.42,700,1,13.87,200,1,14,100,1,14.03,2,1,14.28,100,1,14.45,100,1,14.56,800,1,14.6,700,1,14.68,1400,1,14.7,100,1,14.76,200,1,2,326729729
2025-07-17T16:03:18.809706334Z,2025-07-17T16:03:18.809540733Z,160,2,1108,A,A,14.660000000,100,0,326892885,130,165601,272609656,ARL,,13.12,200,1,13.11,100,1,13.03,100,1,13,2,1,12.73,100,1,12.71,100,1,12.5,700,1,12.46,200,1,12.43,700,1,12.42,700,1,13.87,200,1,14,100,1,14.03,2,1,14.28,100,1,14.45,100,1,14.56,800,1,14.6,700,1,14.66,100,1,14.68,1400,1,14.7,100,1,2,326892885
2025-07-17T16:03:18.809848665Z,2025-07-17T16:03:18.809683187Z,160,2,1108,C,A,15.790000000,100,0,326729733,0,165478,272609658,ARL,,13.12,200,1,13.11,100,1,13.03,100,1,13,2,1,12.73,100,1,12.71,100,1,12.5,700,1,12.46,200,1,12.43,700,1,12.42,700,1,13.87,200,1,14,100,1,14.03,2,1,14.28,100,1,14.45,100,1,14.56,800,1,14.6,700,1,14.66,100,1,14.68,1400,1,14.7,100,1,2,326729733
2025-07-17T16:03:18.809848665Z,2025-07-17T16:03:18.809683187Z,160,2,1108,A,A,15.960000000,100,0,326892889,130,165478,272609658,ARL,,13.12,200,1,13.11,100,1,13.03,100,1,13,2,1,12.73,100,1,12.71,100,1,12.5,700,1,12.46,200,1,12.43,700,1,12.42,700,1,13.87,200,1,14,100,1,14.03,2,1,14.28,100,1,14.45,100,1,14.56,800,1,14.6,700,1,14.66,100,1,14.68,1400,1,14.7,100,1,2,326892889
2025-07-17T16:03:18.812107206Z,2025-07-17T16:03:18.811941680Z,160,2,1108,C,A,17.440000000,100,0,326729725,0,165526,272609679,ARL,,13.12,200,1,13.11,100,1,13.03,100,1,13,2,1,12.73,100,1,12.71,100,1,12.5,700,1,12.46,200,1,12.43,700,1,12.42,700,1,13.87,200,1,14,100,1,14.03,2,1,14.28,100,1,14.45,100,1,14.56,800,1,14.6,700,1,14.66,100,1,14.68,1400,1,14.7,100,1,2,326729725
2025-07-17T16:03:18.812107206Z,2025-07-17T16:03:18.811941680Z,160,2,1108,A,A,17.620000000,100,0,326892921,130,165526,272609679,ARL,,13.12,200,1,13.11,100,1,13.03,100,1,13,2,1,12.73,100,1,12.71,100,1,12.5,700,1,12.46,200,1,12.43,700,1,12.42,700,1,13.87,200,1,14,100,1,14.03,2,1,14.28,100,1,14.45,100,1,14.56,800,1,14.6,700,1,14.66,100,1,14.68,1400,1,14.7,100,1,2,326892921
2025-07-17T16:03:18.818245629Z,2025-07-17T16:03:18.818080239Z,160,2,1108,C,A,14.000000000,100,0,326729929,130,165390,272609768,ARL,,13.12,200,1,13.11,100,1,13.03,100,1,13,2,1,12.73,100,1,12.71,100,1,12.5,700,1,12.46,200,1,12.43,700,1,12.42,700,1,13.87,200,1,14.03,2,1,14.28,100,1,14.45,100,1,14.56,800,1,14.6,700,1,14.66,100,1,14.68,1400,1,14.7,100,1,14.76,200,1,2,326729929
2025-07-17T16:03:18.818301143Z,2025-07-17T16:03:18.818135688Z,160,2,1108,A,A,14.150000000,100,0,326893213,130,165455,272609769,ARL,,13.12,200,1,13.11,100,1,13.03,100,1,13,2,1,12.73,100,1,12.71,100,1,12.5,700,1,12.46,200,1,12.43,700,1,12.42,700,1,13.87,200,1,14.03,2,1,14.15,100,1,14.28,100,1,14.45,100,1,14.56,800,1,14.6,700,1,14.66,100,1,14.68,1400,1,14.7,100,1,2,326893213
2025-07-17T16:03:18.868420503Z,2025-07-17T16:03:18.868254768Z,160,2,1108,C,A,14.700000000,100,0,326729821,0,165735,272610397,ARL,,13.12,200,1,13.11,100,1,13.03,100,1,13,2,1,12.73,100,1,12.71,100,1,12.5,700,1,12.46,200,1,12.43,700,1,12.42,700,1,13.87,200,1,14.03,2,1,14.15,100,1,14.28,100,1,14.45,100,1,14.56,800,1,14.6,700,1,14.66,100,1,14.68,1400,1,14.76,200,1,2,326729821
2025-07-17T16:03:18.868420503Z,2025-07-17T16:03:18.868254768Z,160,2,1108,A,A,14.850000000,100,0,326893961,130,165735,272610397,ARL,,13.12,200,1,13.11,100,1,13.03,100,1,13,2,1,12.73,100,1,12.71,100,1,12.5,700,1,12.46,200,1,12.43,700,1,12.42,700,1,13.87,200,1,14.03,2,1,14.15,100,1,14.28,100,1,14.45,100,1,14.56,800,1,14.6,700,1,14.66,100,1,14.68,1400,1,14.76,200,1,2,326893961
2025-07-17T16:03:19.191219507Z,2025-07-17T16:03:19.191054306Z,160,2,1108,A,A,13.880000000,100,0,326899125,130,165201,272614303,ARL,,13.12,200,1,13.11,100,1,13.03,100,1,13,2,1,12.73,100,1,12.71,100,1,12.5,700,1,12.46,200,1,12.43,700,1,12.42,700,1,13.87,200,1,13.88,100,1,14.03,2,1,14.15,100,1,14.28,100,1,14.45,100,1,14.56,800,1,14.6,700,1,14.66,100,1,14.68,1400,1,2,326899125
2025-07-17T16:03:27.436323951Z,2025-07-17T16:03:27.436158395Z,160,2,1108,A,A,14.250000000,53,0,327112281,130,165556,272788767,ARL,,13.12,200,1,13.11,100,1,13.03,100,1,13,2,1,12.73,100,1,12.71,100,1,12.5,700,1,12.46,200,1,12.43,700,1,12.42,700,1,13.87,200,1,13.88,100,1,14.03,2,1,14.15,100,1,14.25,53,1,14.28,100,1,14.45,100,1,14.56,800,1,14.6,700,1,14.66,100,1,2,327112281
2025-07-17T16:03:27.436880768Z,2025-07-17T16:03:27.436715001Z,160,2,1108,C,B,12.230000000,100,0,291964745,0,165767,272788774,ARL,,13.12,200,1,13.11,100,1,13.03,100,1,13,2,1,12.73,100,1,12.71,100,1,12.5,700,1,12.46,200,1,12.43,700,1,12.42,700,1,13.87,200,1,13.88,100,1,14.03,2,1,14.15,100,1,14.25,53,1,14.28,100,1,14.45,100,1,14.56,800,1,14.6,700,1,14.66,100,1,2,291964745
2025-07-17T16:03:27.436880768Z,2025-07-17T16:03:27.436715001Z,160,2,1108,A,B,12.100000000,100,0,327112289,130,165767,272788774,ARL,,13.12,200,1,13.11,100,1,13.03,100,1,13,2,1,12.73,100,1,12.71,100,1,12.5,700,1,12.46,200,1,12.43,700,1,12.42,700,1,13.87,200,1,13.88,100,1,14.03,2,1,14.15,100,1,14.25,53,1,14.28,100,1,14.45,100,1,14.56,800,1,14.6,700,1,14.66,100,1,2,327112289
2025-07-17T16:03:27.438566971Z,2025-07-17T16:03:27.438400828Z,160,2,1108,C,B,12.340000000,100,0,285586113,0,166143,272788792,ARL,,13.12,200,1,13.11,100,1,13.03,100,1,13,2,1,12.73,100,1,12.71,100,1,12.5,700,1,12.46,200,1,12.43,700,1,12.42,700,1,13.87,200,1,13.88,100,1,14.03,2,1,14.15,100,1,14.25,53,1,14.28,100,1,14.45,100,1,14.56,800,1,14.6,700,1,14.66,100,1,2,285586113
2025-07-17T16:03:27.438566971Z,2025-07-17T16:03:27.438400828Z,160,2,1108,A,B,12.200000000,100,0,327112385,130,166143,272788792,ARL,,13.12,200,1,13.11,100,1,13.03,100,1,13,2,1,12.73,100,1,12.71,100,1,12.5,700,1,12.46,200,1,12.43,700,1,12.42,700,1,13.87,200,1,13.88,100,1,14.03,2,1,14.15,100,1,14.25,53,1,14.28,100,1,14.45,100,1,14.56,800,1,14.6,700,1,14.66,100,1,2,327112385
2025-07-17T16:03:27.438603564Z,2025-07-17T16:03:27.438437969Z,160,2,1108,C,B,12.340000000,100,0,285586189,0,165595,272788793,ARL,,13.12,200,1,13.11,100,1,13.03,100,1,13,2,1,12.73,100,1,12.71,100,1,12.5,700,1,12.46,200,1,12.43,700,1,12.42,700,1,13.87,200,1,13.88,100,1,14.03,2,1,14.15,100,1,14.25,53,1,14.28,100,1,14.45,100,1,14.56,800,1,14.6,700,1,14.66,100,1,2,285586189
2025-07-17T16:03:27.438603564Z,2025-07-17T16:03:27.438437969Z,160,2,1108,A,B,12.200000000,100,0,327112393,130,165595,272788793,ARL,,13.12,200,1,13.11,100,1,13.03,100,1,13,2,1,12.73,100,1,12.71,100,1,12.5,700,1,12.46,200,1,12.43,700,1,12.42,700,1,13.87,200,1,13.88,100,1,14.03,2,1,14.15,100,1,14.25,53,1,14.28,100,1,14.45,100,1,14.56,800,1,14.6,700,1,14.66,100,1,2,327112393
2025-07-17T16:03:27.454010355Z,2025-07-17T16:03:27.453845141Z,160,2,1108,C,B,13.030000000,100,0,285586293,130,165214,272788897,ARL,,13.12,200,1,13.11,100,1,13,2,1,12.73,100,1,12.71,100,1,12.5,700,1,12.46,200,1,12.43,700,1,12.42,700,1,12.37,700,1,13.87,200,1,13.88,100,1,14.03,2,1,14.15,100,1,14.25,53,1,14.28,100,1,14.45,100,1,14.56,800,1,14.6,700,1,14.66,100,1,2,285586293
2025-07-17T16:03:27.454059719Z,2025-07-17T16:03:27.453894425Z,160,2,1108,A,B,12.950000000,100,0,327112565,130,165294,272788898,ARL,,13.12,200,1,13.11,100,1,13,2,1,12.95,100,1,12.73,100,1,12.71,100,1,12.5,700,1,12.46,200,1,12.43,700,1,12.42,700,1,13.87,200,1,13.88,100,1,14.03,2,1,14.15,100,1,14.25,53,1,14.28,100,1,14.45,100,1,14.56,800,1,14.6,700,1,14.66,100,1,2,327112565
2025-07-17T16:03:27.454892321Z,2025-07-17T16:03:27.454726901Z,160,2,1108,C,B,12.950000000,100,0,327112565,130,165420,272788942,ARL,,13.12,200,1,13.11,100,1,13,2,1,12.73,100,1,12.71,100,1,12.5,700,1,12.46,200,1,12.43,700,1,12.42,700,1,12.37,700,1,13.87,200,1,13.88,100,1,14.03,2,1,14.15,100,1,14.25,53,1,14.28,100,1,14.45,100,1,14.56,800,1,14.6,700,1,14.66,100,1,2,327112565
2025-07-17T16:03:27.454939600Z,2025-07-17T16:03:27.454773691Z,160,2,1108,A,B,12.860000000,100,0,327112577,130,165909,272788943,ARL,,13.12,200,1,13.11,100,1,13,2,1,12.86,100,1,12.73,100,1,12.71,100,1,12.5,700,1,12.46,200,1,12.43,700,1,12.42,700,1,13.87,200,1,13.88,100,1,14.03,2,1,14.15,100,1,14.25,53,1,14.28,100,1,14.45,100,1,14.56,800,1,14.6,700,1,14.66,100,1,2,327112577
2025-07-17T16:03:27.517751270Z,2025-07-17T16:03:27.517585374Z,160,2,1108,C,B,12.460000000,100,0,285587281,130,165896,272790695,ARL,,13.12,200,1,13.11,100,1,13,2,1,12.86,100,1,12.73,100,1,12.71,100,1,12.5,700,1,12.46,100,1,12.43,700,1,12.42,700,1,13.87,200,1,13.88,100,1,14.03,2,1,14.15,100,1,14.25,53,1,14.28,100,1,14.45,100,1,14.56,800,1,14.6,700,1,14.66,100,1,2,285587281
2025-07-17T16:03:27.517864675Z,2025-07-17T16:03:27.517699408Z,160,2,1108,A,B,12.330000000,100,0,327114465,130,165267,272790696,ARL,,13.12,200,1,13.11,100,1,13,2,1,12.86,100,1,12.73,100,1,12.71,100,1,12.5,700,1,12.46,100,1,12.43,700,1,12.42,700,1,13.87,200,1,13.88,100,1,14.03,2,1,14.15,100,1,14.25,53,1,14.28,100,1,14.45,100,1,14.56,800,1,14.6,700,1,14.66,100,1,2,327114465
2025-07-17T16:03:27.536343943Z,2025-07-17T16:03:27.536178718Z,160,2,1108,C,A,14.250000000,53,0,327112281,130,165225,272791410,ARL,,13.12,200,1,13.11,100,1,13,2,1,12.86,100,1,12.73,100,1,12.71,100,1,12.5,700,1,12.46,100,1,12.43,700,1,12.42,700,1,13.87,200,1,13.88,100,1,14.03,2,1,14.15,100,1,14.28,100,1,14.45,100,1,14.56,800,1,14.6,700,1,14.66,100,1,14.68,1400,1,2,327112281
2025-07-17T16:03:56.548348047Z,2025-07-17T16:03:56.548182793Z,160,2,1108,A,A,13.800000000,15,0,327675057,130,165254,273208310,ARL,,13.12,200,1,13.11,100,1,13,2,1,12.86,100,1,12.73,100,1,12.71,100,1,12.5,700,1,12.46,100,1,12.43,700,1,12.42,700,1,13.8,15,1,13.87,200,1,13.88,100,1,14.03,2,1,14.15,100,1,14.28,100,1,14.45,100,1,14.56,800,1,14.6,700,1,14.66,100,1,2,327675057
2025-07-17T16:03:56.548611716Z,2025-07-17T16:03:56.548446336Z,160,2,1108,C,A,13.880000000,100,0,326899125,0,165380,273208316,ARL,,13.12,200,1,13.11,100,1,13,2,1,12.86,100,1,12.73,100,1,12.71,100,1,12.5,700,1,12.46,100,1,12.43,700,1,12.42,700,1,13.8,15,1,13.87,200,1,14.03,2,1,14.15,100,1,14.28,100,1,14.45,100,1,14.56,800,1,14.6,700,1,14.66,100,1,14.68,1400,1,2,326899125
2025-07-17T16:03:56.548611716Z,2025-07-17T16:03:56.548446336Z,160,2,1108,A,A,13.810000000,100,0,327675065,130,165380,273208316,ARL,,13.12,200,1,13.11,100,1,13,2,1,12.86,100,1,12.73,100,1,12.71,100,1,12.5,700,1,12.46,100,1,12.43,700,1,12.42,700,1,13.8,15,1,13.81,100,1,13.87,200,1,14.03,2,1,14.15,100,1,14.28,100,1,14.45,100,1,14.56,800,1,14.6,700,1,14.66,100,1,2,327675065
2025-07-17T16:03:56.549354405Z,2025-07-17T16:03:56.549188993Z,160,2,1108,C,A,14.950000000,100,0,326892717,0,165412,273208325,ARL,,13.12,200,1,13.11,100,1,13,2,1,12.86,100,1,12.73,100,1,12.71,100,1,12.5,700,1,12.46,100,1,12.43,700,1,12.42,700,1,13.8,15,1,13.81,100,1,13.87,200,1,14.03,2,1,14.15,100,1,14.28,100,1,14.45,100,1,14.56,800,1,14.6,700,1,14.66,100,1,2,326892717
2025-07-17T16:03:56.549354405Z,2025-07-17T16:03:56.549188993Z,160,2,1108,A,A,14.880000000,100,0,327675093,130,165412,273208325,ARL,,13.12,200,1,13.11,100,1,13,2,1,12.86,100,1,12.73,100,1,12.71,100,1,12.5,700,1,12.46,100,1,12.43,700,1,12.42,700,1,13.8,15,1,13.81,100,1,13.87,200,1,14.03,2,1,14.15,100,1,14.28,100,1,14.45,100,1,14.56,800,1,14.6,700,1,14.66,100,1,2,327675093
2025-07-17T16:04:06.233858611Z,2025-07-17T16:04:06.233692491Z,160,2,1108,C,A,14.760000000,100,0,326892825,0,166120,273345719,ARL,,13.12,200,1,13.11,100,1,13,2,1,12.86,100,1,12.73,100,1,12.71,100,1,12.5,700,1,12.46,100,1,12.43,700,1,12.42,700,1,13.8,15,1,13.81,100,1,13.87,200,1,14.03,2,1,14.15,100,1,14.28,100,1,14.45,100,1,14.56,800,1,14.6,700,1,14.66,100,1,2,326892825
2025-07-17T16:04:06.233858611Z,2025-07-17T16:04:06.233692491Z,160,2,1108,A,A,14.640000000,100,0,327856297,130,166120,273345719,ARL,,13.12,200,1,13.11,100,1,13,2,1,12.86,100,1,12.73,100,1,12.71,100,1,12.5,700,1,12.46,100,1,12.43,700,1,12.42,700,1,13.8,15,1,13.81,100,1,13.87,200,1,14.03,2,1,14.15,100,1,14.28,100,1,14.45,100,1,14.56,800,1,14.6,700,1,14.64,100,1,2,327856297
2025-07-17T16:04:06.234600198Z,2025-07-17T16:04:06.234433294Z,160,2,1108,C,A,14.760000000,100,0,326892817,0,166904,273345721,ARL,,13.12,200,1,13.11,100,1,13,2,1,12.86,100,1,12.73,100,1,12.71,100,1,12.5,700,1,12.46,100,1,12.43,700,1,12.42,700,1,13.8,15,1,13.81,100,1,13.87,200,1,14.03,2,1,14.15,100,1,14.28,100,1,14.45,100,1,14.56,800,1,14.6,700,1,14.64,100,1,2,326892817
2025-07-17T16:04:06.234600198Z,2025-07-17T16:04:06.234433294Z,160,2,1108,A,A,14.640000000,100,0,327856309,130,166904,273345721,ARL,,13.12,200,1,13.11,100,1,13,2,1,12.86,100,1,12.73,100,1,12.71,100,1,12.5,700,1,12.46,100,1,12.43,700,1,12.42,700,1,13.8,15,1,13.81,100,1,13.87,200,1,14.03,2,1,14.15,100,1,14.28,100,1,14.45,100,1,14.56,800,1,14.6,700,1,14.64,200,1,2,327856309
2025-07-17T16:04:06.510914101Z,2025-07-17T16:04:06.510748731Z,160,2,1108,A,A,13.720000000,15,0,327863853,130,165370,273352664,ARL,,13.12,200,1,13.11,100,1,13,2,1,12.86,100,1,12.73,100,1,12.71,100,1,12.5,700,1,12.46,100,1,12.43,700,1,12.42,700,1,13.72,15,1,13.8,15,1,13.81,100,1,13.87,200,1,14.03,2,1,14.15,100,1,14.28,100,1,14.45,100,1,14.56,800,1,14.6,700,1,2,327863853
2025-07-17T16:04:06.512413102Z,2025-07-17T16:04:06.512244746Z,160,2,1108,C,A,13.810000000,100,0,327675065,0,168356,273352888,ARL,,13.12,200,1,13.11,100,1,13,2,1,12.86,100,1,12.73,100,1,12.71,100,1,12.5,700,1,12.46,100,1,12.43,700,1,12.42,700,1,13.72,15,1,13.8,15,1,13.87,200,1,14.03,2,1,14.15,100,1,14.28,100,1,14.45,100,1,14.56,800,1,14.6,700,1,14.64,200,1,2,327675065
2025-07-17T16:04:06.512413102Z,2025-07-17T16:04:06.512244746Z,160,2,1108,A,A,13.730000000,100,0,327864137,128,168356,273352888,ARL,,13.12,200,1,13.11,100,1,13,2,1,12.86,100,1,12.73,100,1,12.71,100,1,12.5,700,1,12.46,100,1,12.43,700,1,12.42,700,1,13.72,15,1,13.73,100,1,13.8,15,1,13.87,200,1,14.03,2,1,14.15,100,1,14.28,100,1,14.45,100,1,14.56,800,1,14.6,700,1,2,327864137
2025-07-17T16:04:06.513675299Z,2025-07-17T16:04:06.513497276Z,160,2,1108,C,A,14.880000000,100,0,327675093,0,178023,273353923,ARL,,13.12,200,1,13.11,100,1,13,2,1,12.86,100,1,12.73,100,1,12.71,100,1,12.5,700,1,12.46,100,1,12.43,700,1,12.42,700,1,13.72,15,1,13.73,100,1,13.8,15,1,13.87,200,1,14.03,2,1,14.15,100,1,14.28,100,1,14.45,100,1,14.56,800,1,14.6,700,1,2,327675093
2025-07-17T16:04:06.513675299Z,2025-07-17T16:04:06.513497276Z,160,2,1108,A,A,14.790000000,100,0,327864893,128,178023,273353923,ARL,,13.12,200,1,13.11,100,1,13,2,1,12.86,100,1,12.73,100,1,12.71,100,1,12.5,700,1,12.46,100,1,12.43,700,1,12.42,700,1,13.72,15,1,13.73,100,1,13.8,15,1,13.87,200,1,14.03,2,1,14.15,100,1,14.28,100,1,14.45,100,1,14.56,800,1,14.6,700,1,2,327864893
2025-07-17T16:04:06.522853161Z,2025-07-17T16:04:06.522687474Z,160,2,1108,C,A,14.850000000,100,0,326892721,0,165687,273357758,ARL,,13.12,200,1,13.11,100,1,13,2,1,12.86,100,1,12.73,100,1,12.71,100,1,12.5,700,1,12.46,100,1,12.43,700,1,12.42,700,1,13.72,15,1,13.73,100,1,13.8,15,1,13.87,200,1,14.03,2,1,14.15,100,1,14.28,100,1,14.45,100,1,14.56,800,1,14.6,700,1,2,326892721
2025-07-17T16:04:06.522853161Z,2025-07-17T16:04:06.522687474Z,160,2,1108,A,A,14.700000000,100,0,327868421,130,165687,273357758,ARL,,13.12,200,1,13.11,100,1,13,2,1,12.86,100,1,12.73,100,1,12.71,100,1,12.5,700,1,12.46,100,1,12.43,700,1,12.42,700,1,13.72,15,1,13.73,100,1,13.8,15,1,13.87,200,1,14.03,2,1,14.15,100,1,14.28,100,1,14.45,100,1,14.56,800,1,14.6,700,1,2,327868421
2025-07-17T16:04:06.525550815Z,2025-07-17T16:04:06.525385108Z,160,2,1108,C,A,14.150000000,100,0,326893213,130,165707,273358260,ARL,,13.12,200,1,13.11,100,1,13,2,1,12.86,100,1,12.73,100,1,12.71,100,1,12.5,700,1,12.46,100,1,12.43,700,1,12.42,700,1,13.72,15,1,13.73,100,1,13.8,15,1,13.87,200,1,14.03,2,1,14.28,100,1,14.45,100,1,14.56,800,1,14.6,700,1,14.64,200,1,2,326893213
2025-07-17T16:04:06.525608746Z,2025-07-17T16:04:06.525442486Z,160,2,1108,A,A,14.000000000,100,0,327869193,128,166260,273358273,ARL,,13.12,200,1,13.11,100,1,13,2,1,12.86,100,1,12.73,100,1,12.71,100,1,12.5,700,1,12.46,100,1,12.43,700,1,12.42,700,1,13.72,15,1,13.73,100,1,13.8,15,1,13.87,200,1,14,100,1,14.03,2,1,14.28,100,1,14.45,100,1,14.56,800,1,14.6,700,1,2,327869193
2025-07-17T16:04:06.528210755Z,2025-07-17T16:04:06.528043934Z,160,2,1108,C,A,14.660000000,100,0,326892885,130,166821,273358598,ARL,,13.12,200,1,13.11,100,1,13,2,1,12.86,100,1,12.73,100,1,12.71,100,1,12.5,700,1,12.46,100,1,12.43,700,1,12.42,700,1,13.72,15,1,13.73,100,1,13.8,15,1,13.87,200,1,14,100,1,14.03,2,1,14.28,100,1,14.45,100,1,14.56,800,1,14.6,700,1,2,326892885
2025-07-17T16:04:06.528329048Z,2025-07-17T16:04:06.528161631Z,160,2,1108,A,A,14.520000000,100,0,327869529,128,167417,273358642,ARL,,13.12,200,1,13.11,100,1,13,2,1,12.86,100,1,12.73,100,1,12.71,100,1,12.5,700,1,12.46,100,1,12.43,700,1,12.42,700,1,13.72,15,1,13.73,100,1,13.8,15,1,13.87,200,1,14,100,1,14.03,2,1,14.28,100,1,14.45,100,1,14.52,100,1,14.56,800,1,2,327869529
2025-07-17T16:04:06.543480312Z,2025-07-17T16:04:06.543314706Z,160,2,1108,C,A,17.620000000,100,0,326892921,0,165606,273359491,ARL,,13.12,200,1,13.11,100,1,13,2,1,12.86,100,1,12.73,100,1,12.71,100,1,12.5,700,1,12.46,100,1,12.43,700,1,12.42,700,1,13.72,15,1,13.73,100,1,13.8,15,1,13.87,200,1,14,100,1,14.03,2,1,14.28,100,1,14.45,100,1,14.52,100,1,14.56,800,1,2,326892921
2025-07-17T16:04:06.543480312Z,2025-07-17T16:04:06.543314706Z,160,2,1108,A,A,17.440000000,100,0,327870217,130,165606,273359491,ARL,,13.12,200,1,13.11,100,1,13,2,1,12.86,100,1,12.73,100,1,12.71,100,1,12.5,700,1,12.46,100,1,12.43,700,1,12.42,700,1,13.72,15,1,13.73,100,1,13.8,15,1,13.87,200,1,14,100,1,14.03,2,1,14.28,100,1,14.45,100,1,14.52,100,1,14.56,800,1,2,327870217
2025-07-17T16:04:06.548945239Z,2025-07-17T16:04:06.548778200Z,160,2,1108,C,A,15.960000000,100,0,326892889,0,167039,273359672,ARL,,13.12,200,1,13.11,100,1,13,2,1,12.86,100,1,12.73,100,1,12.71,100,1,12.5,700,1,12.46,100,1,12.43,700,1,12.42,700,1,13.72,15,1,13.73,100,1,13.8,15,1,13.87,200,1,14,100,1,14.03,2,1,14.28,100,1,14.45,100,1,14.52,100,1,14.56,800,1,2,326892889
2025-07-17T16:04:06.548945239Z,2025-07-17T16:04:06.548778200Z,160,2,1108,A,A,15.790000000,100,0,327870361,130,167039,273359672,ARL,,13.12,200,1,13.11,100,1,13,2,1,12.86,100,1,12.73,100,1,12.71,100,1,12.5,700,1,12.46,100,1,12.43,700,1,12.42,700,1,13.72,15,1,13.73,100,1,13.8,15,1,13.87,200,1,14,100,1,14.03,2,1,14.28,100,1,14.45,100,1,14.52,100,1,14.56,800,1,2,327870361
2025-07-17T16:04:06.648109829Z,2025-07-17T16:04:06.647944313Z,160,2,1108,C,A,14.850000000,100,0,326893961,0,165516,273361957,ARL,,13.12,200,1,13.11,100,1,13,2,1,12.86,100,1,12.73,100,1,12.71,100,1,12.5,700,1,12.46,100,1,12.43,700,1,12.42,700,1,13.72,15,1,13.73,100,1,13.8,15,1,13.87,200,1,14,100,1,14.03,2,1,14.28,100,1,14.45,100,1,14.52,100,1,14.56,800,1,2,326893961
2025-07-17T16:04:06.648109829Z,2025-07-17T16:04:06.647944313Z,160,2,1108,A,A,14.700000000,100,0,327873009,130,165516,273361957,ARL,,13.12,200,1,13.11,100,1,13,2,1,12.86,100,1,12.73,100,1,12.71,100,1,12.5,700,1,12.46,100,1,12.43,700,1,12.42,700,1,13.72,15,1,13.73,100,1,13.8,15,1,13.87,200,1,14,100,1,14.03,2,1,14.28,100,1,14.45,100,1,14.52,100,1,14.56,800,1,2,327873009
2025-07-17T16:04:06.805500523Z,2025-07-17T16:04:06.805335354Z,160,2,1108,C,A,13.720000000,15,0,327863853,130,165169,273364089,ARL,,13.12,200,1,13.11,100,1,13,2,1,12.86,100,1,12.73,100,1,12.71,100,1,12.5,700,1,12.46,100,1,12.43,700,1,12.42,700,1,13.73,100,1,13.8,15,1,13.87,200,1,14,100,1,14.03,2,1,14.28,100,1,14.45,100,1,14.52,100,1,14.56,800,1,14.6,700,1,2,327863853
2025-07-17T16:04:06.806217584Z,2025-07-17T16:04:06.806052396Z,160,2,1108,C,A,13.800000000,15,0,327675057,130,165188,273364090,ARL,,13.12,200,1,13.11,100,1,13,2,1,12.86,100,1,12.73,100,1,12.71,100,1,12.5,700,1,12.46,100,1,12.43,700,1,12.42,700,1,13.73,100,1,13.87,200,1,14,100,1,14.03,2,1,14.28,100,1,14.45,100,1,14.52,100,1,14.56,800,1,14.6,700,1,14.64,200,1,2,327675057
2025-07-17T16:04:21.277142662Z,2025-07-17T16:04:21.276976977Z,160,2,1108,A,A,13.770000000,100,0,328239293,130,165685,273687857,ARL,,13.12,200,1,13.11,100,1,13,2,1,12.86,100,1,12.73,100,1,12.71,100,1,12.5,700,1,12.46,100,1,12.43,700,1,12.42,700,1,13.73,100,1,13.77,100,1,13.87,200,1,14,100,1,14.03,2,1,14.28,100,1,14.45,100,1,14.52,100,1,14.56,800,1,14.6,700,1,2,328239293
2025-07-17T16:04:27.791055146Z,2025-07-17T16:04:27.790889618Z,160,2,1108,C,A,14.030000000,2,0,326159041,0,165528,273775264,ARL,,13.12,200,1,13.11,100,1,13,2,1,12.86,100,1,12.73,100,1,12.71,100,1,12.5,700,1,12.46,100,1,12.43,700,1,12.42,700,1,13.73,100,1,13.77,100,1,13.87,200,1,14,100,1,14.28,100,1,14.45,100,1,14.52,100,1,14.56,800,1,14.6,700,1,14.64,200,1,2,326159041
2025-07-17T16:04:27.791055146Z,2025-07-17T16:04:27.790889618Z,160,2,1108,A,A,13.940000000,2,0,328351217,130,165528,273775264,ARL,,13.12,200,1,13.11,100,1,13,2,1,12.86,100,1,12.73,100,1,12.71,100,1,12.5,700,1,12.46,100,1,12.43,700,1,12.42,700,1,13.73,100,1,13.77,100,1,13.87,200,1,13.94,2,1,14,100,1,14.28,100,1,14.45,100,1,14.52,100,1,14.56,800,1,14.6,700,1,2,328351217
2025-07-17T16:04:31.232053154Z,2025-07-17T16:04:31.231887784Z,160,2,1108,A,A,13.680000000,15,0,328437797,130,165370,273846737,ARL,,13.12,200,1,13.11,100,1,13,2,1,12.86,100,1,12.73,100,1,12.71,100,1,12.5,700,1,12.46,100,1,12.43,700,1,12.42,700,1,13.68,15,1,13.73,100,1,13.77,100,1,13.87,200,1,13.94,2,1,14,100,1,14.28,100,1,14.45,100,1,14.52,100,1,14.56,800,1,2,328437797
2025-07-17T16:04:31.232606440Z,2025-07-17T16:04:31.232440773Z,160,2,1108,A,A,13.720000000,100,0,328437805,130,165667,273846745,ARL,,13.12,200,1,13.11,100,1,13,2,1,12.86,100,1,12.73,100,1,12.71,100,1,12.5,700,1,12.46,100,1,12.43,700,1,12.42,700,1,13.68,15,1,13.72,100,1,13.73,100,1,13.77,100,1,13.87,200,1,13.94,2,1,14,100,1,14.28,100,1,14.45,100,1,14.52,100,1,2,328437805
2025-07-17T16:04:31.246681162Z,2025-07-17T16:04:31.246515467Z,160,2,1108,C,A,13.770000000,100,0,328239293,130,165695,273847000,ARL,,13.12,200,1,13.11,100,1,13,2,1,12.86,100,1,12.73,100,1,12.71,100,1,12.5,700,1,12.46,100,1,12.43,700,1,12.42,700,1,13.68,15,1,13.72,100,1,13.73,100,1,13.87,200,1,13.94,2,1,14,100,1,14.28,100,1,14.45,100,1,14.52,100,1,14.56,800,1,2,328239293
2025-07-17T16:04:32.836802111Z,2025-07-17T16:04:32.836635838Z,160,2,1108,C,A,13.730000000,100,0,327864137,0,166273,273882084,ARL,,13.12,200,1,13.11,100,1,13,2,1,12.86,100,1,12.73,100,1,12.71,100,1,12.5,700,1,12.46,100,1,12.43,700,1,12.42,700,1,13.68,15,1,13.72,100,1,13.87,200,1,13.94,2,1,14,100,1,14.28,100,1,14.45,100,1,14.52,100,1,14.56,800,1,14.6,700,1,2,327864137
2025-07-17T16:04:32.836802111Z,2025-07-17T16:04:32.836635838Z,160,2,1108,A,A,13.690000000,100,0,328489153,130,166273,273882084,ARL,,13.12,200,1,13.11,100,1,13,2,1,12.86,100,1,12.73,100,1,12.71,100,1,12.5,700,1,12.46,100,1,12.43,700,1,12.42,700,1,13.68,15,1,13.69,100,1,13.72,100,1,13.87,200,1,13.94,2,1,14,100,1,14.28,100,1,14.45,100,1,14.52,100,1,14.56,800,1,2,328489153
2025-07-17T16:04:32.837165431Z,2025-07-17T16:04:32.837000154Z,160,2,1108,C,B,13.120000000,100,0,325718833,130,165277,273882201,ARL,,13.12,100,1,13.11,100,1,13,2,1,12.86,100,1,12.73,100,1,12.71,100,1,12.5,700,1,12.46,100,1,12.43,700,1,12.42,700,1,13.68,15,1,13.69,100,1,13.72,100,1,13.87,200,1,13.94,2,1,14,100,1,14.28,100,1,14.45,100,1,14.52,100,1,14.56,800,1,2,325718833
2025-07-17T16:04:32.837169083Z,2025-07-17T16:04:32.837002825Z,160,2,1108,C,B,13.120000000,100,0,325718837,128,166258,273882202,ARL,,13.11,100,1,13,2,1,12.86,100,1,12.73,100,1,12.71,100,1,12.5,700,1,12.46,100,1,12.43,700,1,12.42,700,1,12.37,700,1,13.68,15,1,13.69,100,1,13.72,100,1,13.87,200,1,13.94,2,1,14,100,1,14.28,100,1,14.45,100,1,14.52,100,1,14.56,800,1,2,325718837
2025-07-17T16:04:32.837179568Z,2025-07-17T16:04:32.837013456Z,160,2,1108,A,B,12.980000000,100,0,328489377,130,166112,273882207,ARL,,13.11,100,1,13,2,1,12.98,100,1,12.86,100,1,12.73,100,1,12.71,100,1,12.5,700,1,12.46,100,1,12.43,700,1,12.42,700,1,13.68,15,1,13.69,100,1,13.72,100,1,13.87,200,1,13.94,2,1,14,100,1,14.28,100,1,14.45,100,1,14.52,100,1,14.56,800,1,2,328489377
2025-07-17T16:04:32.837181582Z,2025-07-17T16:04:32.837016087Z,160,2,1108,A,B,12.980000000,100,0,328489385,130,165495,273882208,ARL,,13.11,100,1,13,2,1,12.98,200,1,12.86,100,1,12.73,100,1,12.71,100,1,12.5,700,1,12.46,100,1,12.43,700,1,12.42,700,1,13.68,15,1,13.69,100,1,13.72,100,1,13.87,200,1,13.94,2,1,14,100,1,14.28,100,1,14.45,100,1,14.52,100,1,14.56,800,1,2,328489385
2025-07-17T16:04:32.837536434Z,2025-07-17T16:04:32.837369811Z,160,2,1108,C,A,14.790000000,100,0,327864893,0,166623,273882286,ARL,,13.11,100,1,13,2,1,12.98,200,1,12.86,100,1,12.73,100,1,12.71,100,1,12.5,700,1,12.46,100,1,12.43,700,1,12.42,700,1,13.68,15,1,13.69,100,1,13.72,100,1,13.87,200,1,13.94,2,1,14,100,1,14.28,100,1,14.45,100,1,14.52,100,1,14.56,800,1,2,327864893
2025-07-17T16:04:32.837536434Z,2025-07-17T16:04:32.837369811Z,160,2,1108,A,A,14.750000000,100,0,328489481,128,166623,273882286,ARL,,13.11,100,1,13,2,1,12.98,200,1,12.86,100,1,12.73,100,1,12.71,100,1,12.5,700,1,12.46,100,1,12.43,700,1,12.42,700,1,13.68,15,1,13.69,100,1,13.72,100,1,13.87,200,1,13.94,2,1,14,100,1,14.28,100,1,14.45,100,1,14.52,100,1,14.56,800,1,2,328489481
2025-07-17T16:04:36.810717146Z,2025-07-17T16:04:36.810551890Z,160,2,1108,A,A,13.650000000,15,0,328603377,130,165256,273963456,ARL,,13.11,100,1,13,2,1,12.98,200,1,12.86,100,1,12.73,100,1,12.71,100,1,12.5,700,1,12.46,100,1,12.43,700,1,12.42,700,1,13.65,15,1,13.68,15,1,13.69,100,1,13.72,100,1,13.87,200,1,13.94,2,1,14,100,1,14.28,100,1,14.45,100,1,14.52,100,1,2,328603377
2025-07-17T16:04:37.026937493Z,2025-07-17T16:04:37.026771973Z,160,2,1108,A,A,13.690000000,100,0,328606289,130,165520,273965417,ARL,,13.11,100,1,13,2,1,12.98,200,1,12.86,100,1,12.73,100,1,12.71,100,1,12.5,700,1,12.46,100,1,12.43,700,1,12.42,700,1,13.65,15,1,13.68,15,1,13.69,200,1,13.72,100,1,13.87,200,1,13.94,2,1,14,100,1,14.28,100,1,14.45,100,1,14.52,100,1,2,328606289
2025-07-17T16:04:37.033554557Z,2025-07-17T16:04:37.033389265Z,160,2,1108,C,A,13.720000000,100,0,328437805,130,165292,273965562,ARL,,13.11,100,1,13,2,1,12.98,200,1,12.86,100,1,12.73,100,1,12.71,100,1,12.5,700,1,12.46,100,1,12.43,700,1,12.42,700,1,13.65,15,1,13.68,15,1,13.69,200,1,13.87,200,1,13.94,2,1,14,100,1,14.28,100,1,14.45,100,1,14.52,100,1,14.56,800,1,2,328437805
2025-07-17T16:04:37.542961161Z,2025-07-17T16:04:37.542795711Z,160,2,1108,C,A,13.690000000,100,0,328489153,0,165450,273971021,ARL,,13.11,100,1,13,2,1,12.98,200,1,12.86,100,1,12.73,100,1,12.71,100,1,12.5,700,1,12.46,100,1,12.43,700,1,12.42,700,1,13.65,15,1,13.68,15,1,13.69,100,1,13.87,200,1,13.94,2,1,14,100,1,14.28,100,1,14.45,100,1,14.52,100,1,14.56,800,1,2,328489153
2025-07-17T16:04:37.542961161Z,2025-07-17T16:04:37.542795711Z,160,2,1108,A,A,13.660000000,100,0,328614509,130,165450,273971021,ARL,,13.11,100,1,13,2,1,12.98,200,1,12.86,100,1,12.73,100,1,12.71,100,1,12.5,700,1,12.46,100,1,12.43,700,1,12.42,700,1,13.65,15,1,13.66,100,1,13.68,15,1,13.69,100,1,13.87,200,1,13.94,2,1,14,100,1,14.28,100,1,14.45,100,1,14.52,100,1,2,328614509
2025-07-17T16:04:37.543230680Z,2025-07-17T16:04:37.543063240Z,160,2,1108,C,A,13.870000000,100,0,326730517,0,167440,273971035,ARL,,13.11,100,1,13,2,1,12.98,200,1,12.86,100,1,12.73,100,1,12.71,100,1,12.5,700,1,12.46,100,1,12.43,700,1,12.42,700,1,13.65,15,1,13.66,100,1,13.68,15,1,13.69,100,1,13.87,100,1,13.94,2,1,14,100,1,14.28,100,1,14.45,100,1,14.52,100,1,2,326730517
2025-07-17T16:04:37.543230680Z,2025-07-17T16:04:37.543064690Z,160,2,1108,C,A,13.870000000,100,0,326730521,130,165990,273971037,ARL,,13.11,100,1,13,2,1,12.98,200,1,12.86,100,1,12.73,100,1,12.71,100,1,12.5,700,1,12.46,100,1,12.43,700,1,12.42,700,1,13.65,15,1,13.66,100,1,13.68,15,1,13.69,100,1,13.94,2,1,14,100,1,14.28,100,1,14.45,100,1,14.52,100,1,14.56,800,1,2,326730521
2025-07-17T16:04:37.543242390Z,2025-07-17T16:04:37.543077174Z,160,2,1108,A,A,13.800000000,100,0,328614525,130,165216,273971040,ARL,,13.11,100,1,13,2,1,12.98,200,1,12.86,100,1,12.73,100,1,12.71,100,1,12.5,700,1,12.46,100,1,12.43,700,1,12.42,700,1,13.65,15,1,13.66,100,1,13.68,15,1,13.69,100,1,13.8,100,1,13.94,2,1,14,100,1,14.28,100,1,14.45,100,1,14.52,100,1,2,328614525
2025-07-17T16:04:37.543244193Z,2025-07-17T16:04:37.543078532Z,160,2,1108,A,A,13.800000000,100,0,328614529,130,165661,273971041,ARL,,13.11,100,1,13,2,1,12.98,200,1,12.86,100,1,12.73,100,1,12.71,100,1,12.5,700,1,12.46,100,1,12.43,700,1,12.42,700,1,13.65,15,1,13.66,100,1,13.68,15,1,13.69,100,1,13.8,200,1,13.94,2,1,14,100,1,14.28,100,1,14.45,100,1,14.52,100,1,2,328614529
2025-07-17T16:04:37.549684713Z,2025-07-17T16:04:37.549519006Z,160,2,1108,C,A,14.000000000,100,0,327869193,130,165707,273973481,ARL,,13.11,100,1,13,2,1,12.98,200,1,12.86,100,1,12.73,100,1,12.71,100,1,12.5,700,1,12.46,100,1,12.43,700,1,12.42,700,1,13.65,15,1,13.66,100,1,13.68,15,1,13.69,100,1,13.8,200,1,13.94,2,1,14.28,100,1,14.45,100,1,14.52,100,1,14.56,800,1,2,327869193
2025-07-17T16:04:37.549735824Z,2025-07-17T16:04:37.549570649Z,160,2,1108,A,A,13.930000000,100,0,328616925,130,165175,273973485,ARL,,13.11,100,1,13,2,1,12.98,200,1,12.86,100,1,12.73,100,1,12.71,100,1,12.5,700,1,12.46,100,1,12.43,700,1,12.42,700,1,13.65,15,1,13.66,100,1,13.68,15,1,13.69,100,1,13.8,200,1,13.93,100,1,13.94,2,1,14.28,100,1,14.45,100,1,14.52,100,1,2,328616925
2025-07-17T16:04:44.524526545Z,2025-07-17T16:04:44.524360626Z,160,2,1108,C,A,13.680000000,15,0,328437797,130,165919,274066152,ARL,,13.11,100,1,13,2,1,12.98,200,1,12.86,100,1,12.73,100,1,12.71,100,1,12.5,700,1,12.46,100,1,12.43,700,1,12.42,700,1,13.65,15,1,13.66,100,1,13.69,100,1,13.8,200,1,13.93,100,1,13.94,2,1,14.28,100,1,14.45,100,1,14.52,100,1,14.56,800,1,2,328437797
2025-07-17T16:04:45.528000143Z,2025-07-17T16:04:45.527835033Z,160,2,1108,A,A,13.630000000,15,0,328780565,130,165110,274088918,ARL,,13.11,100,1,13,2,1,12.98,200,1,12.86,100,1,12.73,100,1,12.71,100,1,12.5,700,1,12.46,100,1,12.43,700,1,12.42,700,1,13.63,15,1,13.65,15,1,13.66,100,1,13.69,100,1,13.8,200,1,13.93,100,1,13.94,2,1,14.28,100,1,14.45,100,1,14.52,100,1,2,328780565
2025-07-17T16:04:45.528629613Z,2025-07-17T16:04:45.528464092Z,160,2,1108,C,A,14.640000000,100,0,327856309,0,165521,274088922,ARL,,13.11,100,1,13,2,1,12.98,200,1,12.86,100,1,12.73,100,1,12.71,100,1,12.5,700,1,12.46,100,1,12.43,700,1,12.42,700,1,13.63,15,1,13.65,15,1,13.66,100,1,13.69,100,1,13.8,200,1,13.93,100,1,13.94,2,1,14.28,100,1,14.45,100,1,14.52,100,1,2,327856309
2025-07-17T16:04:45.528629613Z,2025-07-17T16:04:45.528464092Z,160,2,1108,A,A,14.520000000,100,0,328780577,130,165521,274088922,ARL,,13.11,100,1,13,2,1,12.98,200,1,12.86,100,1,12.73,100,1,12.71,100,1,12.5,700,1,12.46,100,1,12.43,700,1,12.42,700,1,13.63,15,1,13.65,15,1,13.66,100,1,13.69,100,1,13.8,200,1,13.93,100,1,13.94,2,1,14.28,100,1,14.45,100,1,14.52,200,1,2,328780577
2025-07-17T16:04:45.530418278Z,2025-07-17T16:04:45.530252804Z,160,2,1108,C,A,14.640000000,100,0,327856297,0,165474,274088937,ARL,,13.11,100,1,13,2,1,12.98,200,1,12.86,100,1,12.73,100,1,12.71,100,1,12.5,700,1,12.46,100,1,12.43,700,1,12.42,700,1,13.63,15,1,13.65,15,1,13.66,100,1,13.69,100,1,13.8,200,1,13.93,100,1,13.94,2,1,14.28,100,1,14.45,100,1,14.52,200,1,2,327856297
2025-07-17T16:04:45.530418278Z,2025-07-17T16:04:45.530252804Z,160,2,1108,A,A,14.520000000,100,0,328780597,130,165474,274088937,ARL,,13.11,100,1,13,2,1,12.98,200,1,12.86,100,1,12.73,100,1,12.71,100,1,12.5,700,1,12.46,100,1,12.43,700,1,12.42,700,1,13.63,15,1,13.65,15,1,13.66,100,1,13.69,100,1,13.8,200,1,13.93,100,1,13.94,2,1,14.28,100,1,14.45,100,1,14.52,300,1,2,328780597
2025-07-17T16:04:45.533067029Z,2025-07-17T16:04:45.532901874Z,160,2,1108,C,A,13.660000000,100,0,328614509,0,165155,274088955,ARL,,13.11,100,1,13,2,1,12.98,200,1,12.86,100,1,12.73,100,1,12.71,100,1,12.5,700,1,12.46,100,1,12.43,700,1,12.42,700,1,13.63,15,1,13.65,15,1,13.69,100,1,13.8,200,1,13.93,100,1,13.94,2,1,14.28,100,1,14.45,100,1,14.52,300,1,14.56,800,1,2,328614509
2025-07-17T16:04:45.533067029Z,2025-07-17T16:04:45.532901874Z,160,2,1108,A,A,13.640000000,100,0,328780669,130,165155,274088955,ARL,,13.11,100,1,13,2,1,12.98,200,1,12.86,100,1,12.73,100,1,12.71,100,1,12.5,700,1,12.46,100,1,12.43,700,1,12.42,700,1,13.63,15,1,13.64,100,1,13.65,15,1,13.69,100,1,13.8,200,1,13.93,100,1,13.94,2,1,14.28,100,1,14.45,100,1,14.52,300,1,2,328780669
2025-07-17T16:04:45.533804768Z,2025-07-17T16:04:45.533639142Z,160,2,1108,C,A,14.750000000,100,0,328489481,0,165626,274088957,ARL,,13.11,100,1,13,2,1,12.98,200,1,12.86,100,1,12.73,100,1,12.71,100,1,12.5,700,1,12.46,100,1,12.43,700,1,12.42,700,1,13.63,15,1,13.64,100,1,13.65,15,1,13.69,100,1,13.8,200,1,13.93,100,1,13.94,2,1,14.28,100,1,14.45,100,1,14.52,300,1,2,328489481
2025-07-17T16:04:45.533804768Z,2025-07-17T16:04:45.533639142Z,160,2,1108,A,A,14.700000000,100,0,328780685,130,165626,274088957,ARL,,13.11,100,1,13,2,1,12.98,200,1,12.86,100,1,12.73,100,1,12.71,100,1,12.5,700,1,12.46,100,1,12.43,700,1,12.42,700,1,13.63,15,1,13.64,100,1,13.65,15,1,13.69,100,1,13.8,200,1,13.93,100,1,13.94,2,1,14.28,100,1,14.45,100,1,14.52,300,1,2,328780685
2025-07-17T16:04:45.533870711Z,2025-07-17T16:04:45.533705428Z,160,2,1108,A,A,13.670000000,100,0,328780689,130,165283,274088959,ARL,,13.11,100,1,13,2,1,12.98,200,1,12.86,100,1,12.73,100,1,12.71,100,1,12.5,700,1,12.46,100,1,12.43,700,1,12.42,700,1,13.63,15,1,13.64,100,1,13.65,15,1,13.67,100,1,13.69,100,1,13.8,200,1,13.93,100,1,13.94,2,1,14.28,100,1,14.45,100,1,2,328780689
2025-07-17T16:04:45.563137443Z,2025-07-17T16:04:45.562972204Z,160,2,1108,C,A,13.690000000,100,0,328606289,130,165239,274089319,ARL,,13.11,100,1,13,2,1,12.98,200,1,12.86,100,1,12.73,100,1,12.71,100,1,12.5,700,1,12.46,100,1,12.43,700,1,12.42,700,1,13.63,15,1,13.64,100,1,13.65,15,1,13.67,100,1,13.8,200,1,13.93,100,1,13.94,2,1,14.28,100,1,14.45,100,1,14.52,300,1,2,328606289
2025-07-17T16:04:56.809749973Z,2025-07-17T16:04:56.809584701Z,160,2,1108,C,A,13.650000000,15,0,328603377,130,165272,274293432,ARL,,13.11,100,1,13,2,1,12.98,200,1,12.86,100,1,12.73,100,1,12.71,100,1,12.5,700,1,12.46,100,1,12.43,700,1,12.42,700,1,13.63,15,1,13.64,100,1,13.67,100,1,13.8,200,1,13.93,100,1,13.94,2,1,14.28,100,1,14.45,100,1,14.52,300,1,14.56,800,1,2,328603377
2025-07-17T16:04:57.827079009Z,2025-07-17T16:04:57.826913717Z,160,2,1108,A,A,13.610000000,15,0,329068341,130,165292,274310244,ARL,,13.11,100,1,13,2,1,12.98,200,1,12.86,100,1,12.73,100,1,12.71,100,1,12.5,700,1,12.46,100,1,12.43,700,1,12.42,700,1,13.61,15,1,13.63,15,1,13.64,100,1,13.67,100,1,13.8,200,1,13.93,100,1,13.94,2,1,14.28,100,1,14.45,100,1,14.52,300,1,2,329068341
2025-07-17T16:04:57.970616610Z,2025-07-17T16:04:57.970451236Z,160,2,1108,C,A,13.640000000,100,0,328780669,0,165374,274316281,ARL,,13.11,100,1,13,2,1,12.98,200,1,12.86,100,1,12.73,100,1,12.71,100,1,12.5,700,1,12.46,100,1,12.43,700,1,12.42,700,1,13.61,15,1,13.63,15,1,13.67,100,1,13.8,200,1,13.93,100,1,13.94,2,1,14.28,100,1,14.45,100,1,14.52,300,1,14.56,800,1,2,328780669
2025-07-17T16:04:57.970616610Z,2025-07-17T16:04:57.970451236Z,160,2,1108,A,A,13.620000000,100,0,329074609,130,165374,274316281,ARL,,13.11,100,1,13,2,1,12.98,200,1,12.86,100,1,12.73,100,1,12.71,100,1,12.5,700,1,12.46,100,1,12.43,700,1,12.42,700,1,13.61,15,1,13.62,100,1,13.63,15,1,13.67,100,1,13.8,200,1,13.93,100,1,13.94,2,1,14.28,100,1,14.45,100,1,14.52,300,1,2,329074609
2025-07-17T16:04:57.971360344Z,2025-07-17T16:04:57.971193734Z,160,2,1108,C,A,14.450000000,100,0,325714601,128,166610,274316507,ARL,,13.11,100,1,13,2,1,12.98,200,1,12.86,100,1,12.73,100,1,12.71,100,1,12.5,700,1,12.46,100,1,12.43,700,1,12.42,700,1,13.61,15,1,13.62,100,1,13.63,15,1,13.67,100,1,13.8,200,1,13.93,100,1,13.94,2,1,14.28,100,1,14.52,300,1,14.56,800,1,2,325714601
2025-07-17T16:04:57.971717511Z,2025-07-17T16:04:57.971552262Z,160,2,1108,A,A,14.230000000,100,0,329074833,130,165249,274316527,ARL,,13.11,100,1,13,2,1,12.98,200,1,12.86,100,1,12.73,100,1,12.71,100,1,12.5,700,1,12.46,100,1,12.43,700,1,12.42,700,1,13.61,15,1,13.62,100,1,13.63,15,1,13.67,100,1,13.8,200,1,13.93,100,1,13.94,2,1,14.23,100,1,14.28,100,1,14.52,300,1,2,329074833
2025-07-17T16:04:57.992131878Z,2025-07-17T16:04:57.991966904Z,160,2,1108,C,A,13.610000000,15,0,329068341,130,164974,274318490,ARL,,13.11,100,1,13,2,1,12.98,200,1,12.86,100,1,12.73,100,1,12.71,100,1,12.5,700,1,12.46,100,1,12.43,700,1,12.42,700,1,13.62,100,1,13.63,15,1,13.67,100,1,13.8,200,1,13.93,100,1,13.94,2,1,14.23,100,1,14.28,100,1,14.52,300,1,14.56,800,1,2,329068341
2025-07-17T16:04:57.993141438Z,2025-07-17T16:04:57.992976406Z,160,2,1108,C,A,13.620000000,100,0,329074609,130,165032,274318579,ARL,,13.11,100,1,13,2,1,12.98,200,1,12.86,100,1,12.73,100,1,12.71,100,1,12.5,700,1,12.46,100,1,12.43,700,1,12.42,700,1,13.63,15,1,13.67,100,1,13.8,200,1,13.93,100,1,13.94,2,1,14.23,100,1,14.28,100,1,14.52,300,1,14.56,800,1,14.6,700,1,2,329074609
2025-07-17T16:04:57.993309561Z,2025-07-17T16:04:57.993143873Z,160,2,1108,C,A,13.630000000,15,0,328780565,130,165688,274318603,ARL,,13.11,100,1,13,2,1,12.98,200,1,12.86,100,1,12.73,100,1,12.71,100,1,12.5,700,1,12.46,100,1,12.43,700,1,12.42,700,1,13.67,100,1,13.8,200,1,13.93,100,1,13.94,2,1,14.23,100,1,14.28,100,1,14.52,300,1,14.56,800,1,14.6,700,1,14.68,1400,1,2,328780565
2025-07-17T16:04:58.002259715Z,2025-07-17T16:04:58.002094377Z,160,2,1108,C,A,13.670000000,100,0,328780689,130,165338,274319058,ARL,,13.11,100,1,13,2,1,12.98,200,1,12.86,100,1,12.73,100,1,12.71,100,1,12.5,700,1,12.46,100,1,12.43,700,1,12.42,700,1,13.8,200,1,13.93,100,1,13.94,2,1,14.23,100,1,14.28,100,1,14.52,300,1,14.56,800,1,14.6,700,1,14.68,1400,1,14.7,300,1,2,328780689
2025-07-17T16:04:58.002989430Z,2025-07-17T16:04:58.002823841Z,160,2,1108,C,A,14.700000000,100,0,328780685,0,165589,274319069,ARL,,13.11,100,1,13,2,1,12.98,200,1,12.86,100,1,12.73,100,1,12.71,100,1,12.5,700,1,12.46,100,1,12.43,700,1,12.42,700,1,13.8,200,1,13.93,100,1,13.94,2,1,14.23,100,1,14.28,100,1,14.52,300,1,14.56,800,1,14.6,700,1,14.68,1400,1,14.7,200,1,2,328780685
2025-07-17T16:04:58.002989430Z,2025-07-17T16:04:58.002823841Z,160,2,1108,A,A,14.870000000,100,0,329078553,130,165589,274319069,ARL,,13.11,100,1,13,2,1,12.98,200,1,12.86,100,1,12.73,100,1,12.71,100,1,12.5,700,1,12.46,100,1,12.43,700,1,12.42,700,1,13.8,200,1,13.93,100,1,13.94,2,1,14.23,100,1,14.28,100,1,14.52,300,1,14.56,800,1,14.6,700,1,14.68,1400,1,14.7,200,1,2,329078553
2025-07-17T16:04:58.013904697Z,2025-07-17T16:04:58.013739242Z,160,2,1108,C,A,13.930000000,100,0,328616925,130,165455,274319298,ARL,,13.11,100,1,13,2,1,12.98,200,1,12.86,100,1,12.73,100,1,12.71,100,1,12.5,700,1,12.46,100,1,12.43,700,1,12.42,700,1,13.8,200,1,13.94,2,1,14.23,100,1,14.28,100,1,14.52,300,1,14.56,800,1,14.6,700,1,14.68,1400,1,14.7,200,1,14.87,100,1,2,328616925
2025-07-17T16:04:58.013959233Z,2025-07-17T16:04:58.013793974Z,160,2,1108,A,A,14.080000000,100,0,329078953,130,165259,274319304,ARL,,13.11,100,1,13,2,1,12.98,200,1,12.86,100,1,12.73,100,1,12.71,100,1,12.5,700,1,12.46,100,1,12.43,700,1,12.42,700,1,13.8,200,1,13.94,2,1,14.08,100,1,14.23,100,1,14.28,100,1,14.52,300,1,14.56,800,1,14.6,700,1,14.68,1400,1,14.7,200,1,2,329078953
2025-07-17T16:04:58.536617917Z,2025-07-17T16:04:58.536452621Z,160,2,1108,A,A,13.810000000,100,0,329088265,130,165296,274326535,ARL,,13.11,100,1,13,2,1,12.98,200,1,12.86,100,1,12.73,100,1,12.71,100,1,12.5,700,1,12.46,100,1,12.43,700,1,12.42,700,1,13.8,200,1,13.81,100,1,13.94,2,1,14.08,100,1,14.23,100,1,14.28,100,1,14.52,300,1,14.56,800,1,14.6,700,1,14.68,1400,1,2,329088265
2025-07-17T16:05:46.594131664Z,2025-07-17T16:05:46.593966383Z,160,2,1108,A,A,13.760000000,100,0,330066537,130,165281,275083968,ARL,,13.11,100,1,13,2,1,12.98,200,1,12.86,100,1,12.73,100,1,12.71,100,1,12.5,700,1,12.46,100,1,12.43,700,1,12.42,700,1,13.76,100,1,13.8,200,1,13.81,100,1,13.94,2,1,14.08,100,1,14.23,100,1,14.28,100,1,14.52,300,1,14.56,800,1,14.6,700,1,2,330066537
2025-07-17T16:05:46.594871336Z,2025-07-17T16:05:46.594705962Z,160,2,1108,C,A,14.870000000,100,0,329078553,0,165374,275083970,ARL,,13.11,100,1,13,2,1,12.98,200,1,12.86,100,1,12.73,100,1,12.71,100,1,12.5,700,1,12.46,100,1,12.43,700,1,12.42,700,1,13.76,100,1,13.8,200,1,13.81,100,1,13.94,2,1,14.08,100,1,14.23,100,1,14.28,100,1,14.52,300,1,14.56,800,1,14.6,700,1,2,329078553
2025-07-17T16:05:46.594871336Z,2025-07-17T16:05:46.594705962Z,160,2,1108,A,A,14.830000000,100,0,330066553,130,165374,275083970,ARL,,13.11,100,1,13,2,1,12.98,200,1,12.86,100,1,12.73,100,1,12.71,100,1,12.5,700,1,12.46,100,1,12.43,700,1,12.42,700,1,13.76,100,1,13.8,200,1,13.81,100,1,13.94,2,1,14.08,100,1,14.23,100,1,14.28,100,1,14.52,300,1,14.56,800,1,14.6,700,1,2,330066553
2025-07-17T16:05:46.996003552Z,2025-07-17T16:05:46.995837526Z,160,2,1108,C,A,13.810000000,100,0,329088265,0,166026,275092978,ARL,,13.11,100,1,13,2,1,12.98,200,1,12.86,100,1,12.73,100,1,12.71,100,1,12.5,700,1,12.46,100,1,12.43,700,1,12.42,700,1,13.76,100,1,13.8,200,1,13.94,2,1,14.08,100,1,14.23,100,1,14.28,100,1,14.52,300,1,14.56,800,1,14.6,700,1,14.68,1400,1,2,329088265
2025-07-17T16:05:46.996003552Z,2025-07-17T16:05:46.995837526Z,160,2,1108,A,A,13.770000000,100,0,330075425,130,166026,275092978,ARL,,13.11,100,1,13,2,1,12.98,200,1,12.86,100,1,12.73,100,1,12.71,100,1,12.5,700,1,12.46,100,1,12.43,700,1,12.42,700,1,13.76,100,1,13.77,100,1,13.8,200,1,13.94,2,1,14.08,100,1,14.23,100,1,14.28,100,1,14.52,300,1,14.56,800,1,14.6,700,1,2,330075425
2025-07-17T16:05:50.680333151Z,2025-07-17T16:05:50.680167632Z,160,2,1108,A,A,13.680000000,15,0,330143813,130,165519,275152014,ARL,,13.11,100,1,13,2,1,12.98,200,1,12.86,100,1,12.73,100,1,12.71,100,1,12.5,700,1,12.46,100,1,12.43,700,1,12.42,700,1,13.68,15,1,13.76,100,1,13.77,100,1,13.8,200,1,13.94,2,1,14.08,100,1,14.23,100,1,14.28,100,1,14.52,300,1,14.56,800,1,2,330143813
2025-07-17T16:05:50.697170320Z,2025-07-17T16:05:50.697005084Z,160,2,1108,A,A,13.720000000,100,0,330144301,130,165236,275152383,ARL,,13.11,100,1,13,2,1,12.98,200,1,12.86,100,1,12.73,100,1,12.71,100,1,12.5,700,1,12.46,100,1,12.43,700,1,12.42,700,1,13.68,15,1,13.72,100,1,13.76,100,1,13.77,100,1,13.8,200,1,13.94,2,1,14.08,100,1,14.23,100,1,14.28,100,1,14.52,300,1,2,330144301
2025-07-17T16:05:50.697905372Z,2025-07-17T16:05:50.697739933Z,160,2,1108,C,A,14.830000000,100,0,330066553,0,165439,275152385,ARL,,13.11,100,1,13,2,1,12.98,200,1,12.86,100,1,12.73,100,1,12.71,100,1,12.5,700,1,12.46,100,1,12.43,700,1,12.42,700,1,13.68,15,1,13.72,100,1,13.76,100,1,13.77,100,1,13.8,200,1,13.94,2,1,14.08,100,1,14.23,100,1,14.28,100,1,14.52,300,1,2,330066553
2025-07-17T16:05:50.697905372Z,2025-07-17T16:05:50.697739933Z,160,2,1108,A,A,14.780000000,100,0,330144321,130,165439,275152385,ARL,,13.11,100,1,13,2,1,12.98,200,1,12.86,100,1,12.73,100,1,12.71,100,1,12.5,700,1,12.46,100,1,12.43,700,1,12.42,700,1,13.68,15,1,13.72,100,1,13.76,100,1,13.77,100,1,13.8,200,1,13.94,2,1,14.08,100,1,14.23,100,1,14.28,100,1,14.52,300,1,2,330144321
2025-07-17T16:05:50.704531748Z,2025-07-17T16:05:50.704366332Z,160,2,1108,C,A,13.760000000,100,0,330066537,130,165416,275152443,ARL,,13.11,100,1,13,2,1,12.98,200,1,12.86,100,1,12.73,100,1,12.71,100,1,12.5,700,1,12.46,100,1,12.43,700,1,12.42,700,1,13.68,15,1,13.72,100,1,13.77,100,1,13.8,200,1,13.94,2,1,14.08,100,1,14.23,100,1,14.28,100,1,14.52,300,1,14.56,800,1,2,330066537
2025-07-17T16:05:50.708879311Z,2025-07-17T16:05:50.708714027Z,160,2,1108,C,A,14.080000000,100,0,329078953,130,165284,275152465,ARL,,13.11,100,1,13,2,1,12.98,200,1,12.86,100,1,12.73,100,1,12.71,100,1,12.5,700,1,12.46,100,1,12.43,700,1,12.42,700,1,13.68,15,1,13.72,100,1,13.77,100,1,13.8,200,1,13.94,2,1,14.23,100,1,14.28,100,1,14.52,300,1,14.56,800,1,14.6,700,1,2,329078953
2025-07-17T16:05:50.708931189Z,2025-07-17T16:05:50.708766050Z,160,2,1108,A,A,13.990000000,100,0,330144513,130,165139,275152466,ARL,,13.11,100,1,13,2,1,12.98,200,1,12.86,100,1,12.73,100,1,12.71,100,1,12.5,700,1,12.46,100,1,12.43,700,1,12.42,700,1,13.68,15,1,13.72,100,1,13.77,100,1,13.8,200,1,13.94,2,1,13.99,100,1,14.23,100,1,14.28,100,1,14.52,300,1,14.56,800,1,2,330144513
2025-07-17T16:05:50.913476268Z,2025-07-17T16:05:50.913310799Z,160,2,1108,C,A,13.770000000,100,0,330075425,0,165469,275159685,ARL,,13.11,100,1,13,2,1,12.98,200,1,12.86,100,1,12.73,100,1,12.71,100,1,12.5,700,1,12.46,100,1,12.43,700,1,12.42,700,1,13.68,15,1,13.72,100,1,13.8,200,1,13.94,2,1,13.99,100,1,14.23,100,1,14.28,100,1,14.52,300,1,14.56,800,1,14.6,700,1,2,330075425
2025-07-17T16:05:50.913476268Z,2025-07-17T16:05:50.913310799Z,160,2,1108,A,A,13.690000000,100,0,330151389,130,165469,275159685,ARL,,13.11,100,1,13,2,1,12.98,200,1,12.86,100,1,12.73,100,1,12.71,100,1,12.5,700,1,12.46,100,1,12.43,700,1,12.42,700,1,13.68,15,1,13.69,100,1,13.72,100,1,13.8,200,1,13.94,2,1,13.99,100,1,14.23,100,1,14.28,100,1,14.52,300,1,14.56,800,1,2,330151389
2025-07-17T16:05:59.704955970Z,2025-07-17T16:05:59.704790753Z,160,2,1108,A,A,13.640000000,15,0,330357473,130,165217,275325555,ARL,,13.11,100,1,13,2,1,12.98,200,1,12.86,100,1,12.73,100,1,12.71,100,1,12.5,700,1,12.46,100,1,12.43,700,1,12.42,700,1,13.64,15,1,13.68,15,1,13.69,100,1,13.72,100,1,13.8,200,1,13.94,2,1,13.99,100,1,14.23,100,1,14.28,100,1,14.52,300,1,2,330357473
2025-07-17T16:05:59.715090662Z,2025-07-17T16:05:59.714925412Z,160,2,1108,A,A,13.680000000,100,0,330357633,130,165250,275325807,ARL,,13.11,100,1,13,2,1,12.98,200,1,12.86,100,1,12.73,100,1,12.71,100,1,12.5,700,1,12.46,100,1,12.43,700,1,12.42,700,1,13.64,15,1,13.68,115,1,13.69,100,1,13.72,100,1,13.8,200,1,13.94,2,1,13.99,100,1,14.23,100,1,14.28,100,1,14.52,300,1,2,330357633
2025-07-17T16:05:59.722895750Z,2025-07-17T16:05:59.722730507Z,160,2,1108,C,A,13.720000000,100,0,330144301,130,165243,275325854,ARL,,13.11,100,1,13,2,1,12.98,200,1,12.86,100,1,12.73,100,1,12.71,100,1,12.5,700,1,12.46,100,1,12.43,700,1,12.42,700,1,13.64,15,1,13.68,115,1,13.69,100,1,13.8,200,1,13.94,2,1,13.99,100,1,14.23,100,1,14.28,100,1,14.52,300,1,14.56,800,1,2,330144301
2025-07-17T16:05:59.802762087Z,2025-07-17T16:05:59.802596747Z,160,2,1108,C,A,13.690000000,100,0,330151389,0,165340,275327082,ARL,,13.11,100,1,13,2,1,12.98,200,1,12.86,100,1,12.73,100,1,12.71,100,1,12.5,700,1,12.46,100,1,12.43,700,1,12.42,700,1,13.64,15,1,13.68,115,1,13.8,200,1,13.94,2,1,13.99,100,1,14.23,100,1,14.28,100,1,14.52,300,1,14.56,800,1,14.6,700,1,2,330151389
2025-07-17T16:05:59.802762087Z,2025-07-17T16:05:59.802596747Z,160,2,1108,A,A,13.650000000,100,0,330359197,130,165340,275327082,ARL,,13.11,100,1,13,2,1,12.98,200,1,12.86,100,1,12.73,100,1,12.71,100,1,12.5,700,1,12.46,100,1,12.43,700,1,12.42,700,1,13.64,15,1,13.65,100,1,13.68,115,1,13.8,200,1,13.94,2,1,13.99,100,1,14.23,100,1,14.28,100,1,14.52,300,1,14.56,800,1,2,330359197
2025-07-17T16:05:59.803504658Z,2025-07-17T16:05:59.803338996Z,160,2,1108,C,A,14.780000000,100,0,330144321,0,165662,275327093,ARL,,13.11,100,1,13,2,1,12.98,200,1,12.86,100,1,12.73,100,1,12.71,100,1,12.5,700,1,12.46,100,1,12.43,700,1,12.42,700,1,13.64,15,1,13.65,100,1,13.68,115,1,13.8,200,1,13.94,2,1,13.99,100,1,14.23,100,1,14.28,100,1,14.52,300,1,14.56,800,1,2,330144321
2025-07-17T16:05:59.803504658Z,2025-07-17T16:05:59.803338996Z,160,2,1108,A,A,14.710000000,100,0,330359225,130,165662,275327093,ARL,,13.11,100,1,13,2,1,12.98,200,1,12.86,100,1,12.73,100,1,12.71,100,1,12.5,700,1,12.46,100,1,12.43,700,1,12.42,700,1,13.64,15,1,13.65,100,1,13.68,115,1,13.8,200,1,13.94,2,1,13.99,100,1,14.23,100,1,14.28,100,1,14.52,300,1,14.56,800,1,2,330359225
2025-07-17T16:05:59.827787837Z,2025-07-17T16:05:59.827622529Z,160,2,1108,C,A,13.990000000,100,0,330144513,130,165308,275327416,ARL,,13.11,100,1,13,2,1,12.98,200,1,12.86,100,1,12.73,100,1,12.71,100,1,12.5,700,1,12.46,100,1,12.43,700,1,12.42,700,1,13.64,15,1,13.65,100,1,13.68,115,1,13.8,200,1,13.94,2,1,14.23,100,1,14.28,100,1,14.52,300,1,14.56,800,1,14.6,700,1,2,330144513
2025-07-17T16:05:59.827839802Z,2025-07-17T16:05:59.827674437Z,160,2,1108,A,A,13.920000000,100,0,330359625,130,165365,275327417,ARL,,13.11,100,1,13,2,1,12.98,200,1,12.86,100,1,12.73,100,1,12.71,100,1,12.5,700,1,12.46,100,1,12.43,700,1,12.42,700,1,13.64,15,1,13.65,100,1,13.68,115,1,13.8,200,1,13.92,100,1,13.94,2,1,14.23,100,1,14.28,100,1,14.52,300,1,14.56,800,1,2,330359625
2025-07-17T16:06:02.724446337Z,2025-07-17T16:06:02.724280161Z,160,2,1108,C,A,13.680000000,15,0,330143813,128,166176,275430576,ARL,,13.11,100,1,13,2,1,12.98,200,1,12.86,100,1,12.73,100,1,12.71,100,1,12.5,700,1,12.46,100,1,12.43,700,1,12.42,700,1,13.64,15,1,13.65,100,1,13.68,100,1,13.8,200,1,13.92,100,1,13.94,2,1,14.23,100,1,14.28,100,1,14.52,300,1,14.56,800,1,2,330143813
2025-07-17T16:06:03.729377770Z,2025-07-17T16:06:03.729212428Z,160,2,1108,A,A,13.620000000,15,0,330577045,130,165342,275517342,ARL,,13.11,100,1,13,2,1,12.98,200,1,12.86,100,1,12.73,100,1,12.71,100,1,12.5,700,1,12.46,100,1,12.43,700,1,12.42,700,1,13.62,15,1,13.64,15,1,13.65,100,1,13.68,100,1,13.8,200,1,13.92,100,1,13.94,2,1,14.23,100,1,14.28,100,1,14.52,300,1,2,330577045
2025-07-17T16:06:03.738497645Z,2025-07-17T16:06:03.738332427Z,160,2,1108,A,A,13.650000000,100,0,330577773,130,165218,275517997,ARL,,13.11,100,1,13,2,1,12.98,200,1,12.86,100,1,12.73,100,1,12.71,100,1,12.5,700,1,12.46,100,1,12.43,700,1,12.42,700,1,13.62,15,1,13.64,15,1,13.65,200,1,13.68,100,1,13.8,200,1,13.92,100,1,13.94,2,1,14.23,100,1,14.28,100,1,14.52,300,1,2,330577773
2025-07-17T16:06:03.747495669Z,2025-07-17T16:06:03.747330178Z,160,2,1108,C,A,13.680000000,100,0,330357633,130,165491,275518621,ARL,,13.11,100,1,13,2,1,12.98,200,1,12.86,100,1,12.73,100,1,12.71,100,1,12.5,700,1,12.46,100,1,12.43,700,1,12.42,700,1,13.62,15,1,13.64,15,1,13.65,200,1,13.8,200,1,13.92,100,1,13.94,2,1,14.23,100,1,14.28,100,1,14.52,300,1,14.56,800,1,2,330357633
2025-07-17T16:06:03.887274670Z,2025-07-17T16:06:03.887107153Z,160,2,1108,C,A,13.650000000,100,0,330359197,0,167517,275532429,ARL,,13.11,100,1,13,2,1,12.98,200,1,12.86,100,1,12.73,100,1,12.71,100,1,12.5,700,1,12.46,100,1,12.43,700,1,12.42,700,1,13.62,15,1,13.64,15,1,13.65,100,1,13.8,200,1,13.92,100,1,13.94,2,1,14.23,100,1,14.28,100,1,14.52,300,1,14.56,800,1,2,330359197
2025-07-17T16:06:03.887274670Z,2025-07-17T16:06:03.887107153Z,160,2,1108,A,A,13.630000000,100,0,330592465,130,167517,275532429,ARL,,13.11,100,1,13,2,1,12.98,200,1,12.86,100,1,12.73,100,1,12.71,100,1,12.5,700,1,12.46,100,1,12.43,700,1,12.42,700,1,13.62,15,1,13.63,100,1,13.64,15,1,13.65,100,1,13.8,200,1,13.92,100,1,13.94,2,1,14.23,100,1,14.28,100,1,14.52,300,1,2,330592465
2025-07-17T16:06:07.510050758Z,2025-07-17T16:06:07.509885114Z,160,2,1108,C,A,13.640000000,15,0,330357473,130,165644,275647392,ARL,,13.11,100,1,13,2,1,12.98,200,1,12.86,100,1,12.73,100,1,12.71,100,1,12.5,700,1,12.46,100,1,12.43,700,1,12.42,700,1,13.62,15,1,13.63,100,1,13.65,100,1,13.8,200,1,13.92,100,1,13.94,2,1,14.23,100,1,14.28,100,1,14.52,300,1,14.56,800,1,2,330357473
2025-07-17T16:06:09.885143909Z,2025-07-17T16:06:09.884978592Z,160,2,1108,A,A,13.600000000,15,0,330788421,130,165317,275699092,ARL,,13.11,100,1,13,2,1,12.98,200,1,12.86,100,1,12.73,100,1,12.71,100,1,12.5,700,1,12.46,100,1,12.43,700,1,12.42,700,1,13.6,15,1,13.62,15,1,13.63,100,1,13.65,100,1,13.8,200,1,13.92,100,1,13.94,2,1,14.23,100,1,14.28,100,1,14.52,300,1,2,330788421
2025-07-17T16:06:09.967608061Z,2025-07-17T16:06:09.967442600Z,160,2,1108,C,A,13.630000000,100,0,330592465,0,165461,275700261,ARL,,13.11,100,1,13,2,1,12.98,200,1,12.86,100,1,12.73,100,1,12.71,100,1,12.5,700,1,12.46,100,1,12.43,700,1,12.42,700,1,13.6,15,1,13.62,15,1,13.65,100,1,13.8,200,1,13.92,100,1,13.94,2,1,14.23,100,1,14.28,100,1,14.52,300,1,14.56,800,1,2,330592465
2025-07-17T16:06:09.967608061Z,2025-07-17T16:06:09.967442600Z,160,2,1108,A,A,13.610000000,100,0,330789481,130,165461,275700261,ARL,,13.11,100,1,13,2,1,12.98,200,1,12.86,100,1,12.73,100,1,12.71,100,1,12.5,700,1,12.46,100,1,12.43,700,1,12.42,700,1,13.6,15,1,13.61,100,1,13.62,15,1,13.65,100,1,13.8,200,1,13.92,100,1,13.94,2,1,14.23,100,1,14.28,100,1,14.52,300,1,2,330789481
2025-07-17T16:06:09.968352066Z,2025-07-17T16:06:09.968186617Z,160,2,1108,C,A,14.710000000,100,0,330359225,0,165449,275700270,ARL,,13.11,100,1,13,2,1,12.98,200,1,12.86,100,1,12.73,100,1,12.71,100,1,12.5,700,1,12.46,100,1,12.43,700,1,12.42,700,1,13.6,15,1,13.61,100,1,13.62,15,1,13.65,100,1,13.8,200,1,13.92,100,1,13.94,2,1,14.23,100,1,14.28,100,1,14.52,300,1,2,330359225
2025-07-17T16:06:09.968352066Z,2025-07-17T16:06:09.968186617Z,160,2,1108,A,A,14.670000000,100,0,330789501,130,165449,275700270,ARL,,13.11,100,1,13,2,1,12.98,200,1,12.86,100,1,12.73,100,1,12.71,100,1,12.5,700,1,12.46,100,1,12.43,700,1,12.42,700,1,13.6,15,1,13.61,100,1,13.62,15,1,13.65,100,1,13.8,200,1,13.92,100,1,13.94,2,1,14.23,100,1,14.28,100,1,14.52,300,1,2,330789501
2025-07-17T16:06:09.970040686Z,2025-07-17T16:06:09.969875190Z,160,2,1108,C,A,17.440000000,100,0,327870217,0,165496,275700282,ARL,,13.11,100,1,13,2,1,12.98,200,1,12.86,100,1,12.73,100,1,12.71,100,1,12.5,700,1,12.46,100,1,12.43,700,1,12.42,700,1,13.6,15,1,13.61,100,1,13.62,15,1,13.65,100,1,13.8,200,1,13.92,100,1,13.94,2,1,14.23,100,1,14.28,100,1,14.52,300,1,2,327870217
2025-07-17T16:06:09.970040686Z,2025-07-17T16:06:09.969875190Z,160,2,1108,A,A,17.290000000,100,0,330789509,130,165496,275700282,ARL,,13.11,100,1,13,2,1,12.98,200,1,12.86,100,1,12.73,100,1,12.71,100,1,12.5,700,1,12.46,100,1,12.43,700,1,12.42,700,1,13.6,15,1,13.61,100,1,13.62,15,1,13.65,100,1,13.8,200,1,13.92,100,1,13.94,2,1,14.23,100,1,14.28,100,1,14.52,300,1,2,330789509
2025-07-17T16:06:20.470889851Z,2025-07-17T16:06:20.470724464Z,160,2,1108,A,A,13.630000000,100,0,331018065,130,165387,275896138,ARL,,13.11,100,1,13,2,1,12.98,200,1,12.86,100,1,12.73,100,1,12.71,100,1,12.5,700,1,12.46,100,1,12.43,700,1,12.42,700,1,13.6,15,1,13.61,100,1,13.62,15,1,13.63,100,1,13.65,100,1,13.8,200,1,13.92,100,1,13.94,2,1,14.23,100,1,14.28,100,1,2,331018065
2025-07-17T16:06:20.477598578Z,2025-07-17T16:06:20.477432988Z,160,2,1108,C,A,13.650000000,100,0,330577773,130,165590,275896242,ARL,,13.11,100,1,13,2,1,12.98,200,1,12.86,100,1,12.73,100,1,12.71,100,1,12.5,700,1,12.46,100,1,12.43,700,1,12.42,700,1,13.6,15,1,13.61,100,1,13.62,15,1,13.63,100,1,13.8,200,1,13.92,100,1,13.94,2,1,14.23,100,1,14.28,100,1,14.52,300,1,2,330577773
2025-07-17T16:06:20.811164178Z,2025-07-17T16:06:20.810998706Z,160,2,1108,C,A,13.620000000,15,0,330577045,130,165472,275900161,ARL,,13.11,100,1,13,2,1,12.98,200,1,12.86,100,1,12.73,100,1,12.71,100,1,12.5,700,1,12.46,100,1,12.43,700,1,12.42,700,1,13.6,15,1,13.61,100,1,13.63,100,1,13.8,200,1,13.92,100,1,13.94,2,1,14.23,100,1,14.28,100,1,14.52,300,1,14.56,800,1,2,330577045
2025-07-17T16:06:22.151222819Z,2025-07-17T16:06:22.151057292Z,160,2,1108,A,A,13.580000000,15,0,331050981,130,165527,275926927,ARL,,13.11,100,1,13,2,1,12.98,200,1,12.86,100,1,12.73,100,1,12.71,100,1,12.5,700,1,12.46,100,1,12.43,700,1,12.42,700,1,13.58,15,1,13.6,15,1,13.61,100,1,13.63,100,1,13.8,200,1,13.92,100,1,13.94,2,1,14.23,100,1,14.28,100,1,14.52,300,1,2,331050981
2025-07-17T16:06:22.151491832Z,2025-07-17T16:06:22.151326300Z,160,2,1108,C,A,13.610000000,100,0,330789481,0,165532,275926940,ARL,,13.11,100,1,13,2,1,12.98,200,1,12.86,100,1,12.73,100,1,12.71,100,1,12.5,700,1,12.46,100,1,12.43,700,1,12.42,700,1,13.58,15,1,13.6,15,1,13.63,100,1,13.8,200,1,13.92,100,1,13.94,2,1,14.23,100,1,14.28,100,1,14.52,300,1,14.56,800,1,2,330789481
2025-07-17T16:06:22.151491832Z,2025-07-17T16:06:22.151326300Z,160,2,1108,A,A,13.590000000,100,0,331050989,130,165532,275926940,ARL,,13.11,100,1,13,2,1,12.98,200,1,12.86,100,1,12.73,100,1,12.71,100,1,12.5,700,1,12.46,100,1,12.43,700,1,12.42,700,1,13.58,15,1,13.59,100,1,13.6,15,1,13.63,100,1,13.8,200,1,13.92,100,1,13.94,2,1,14.23,100,1,14.28,100,1,14.52,300,1,2,331050989
2025-07-17T16:06:22.151761329Z,2025-07-17T16:06:22.151595415Z,160,2,1108,C,A,13.800000000,100,0,328614525,0,165914,275926966,ARL,,13.11,100,1,13,2,1,12.98,200,1,12.86,100,1,12.73,100,1,12.71,100,1,12.5,700,1,12.46,100,1,12.43,700,1,12.42,700,1,13.58,15,1,13.59,100,1,13.6,15,1,13.63,100,1,13.8,100,1,13.92,100,1,13.94,2,1,14.23,100,1,14.28,100,1,14.52,300,1,2,328614525
2025-07-17T16:06:22.151761329Z,2025-07-17T16:06:22.151595781Z,160,2,1108,C,A,13.800000000,100,0,328614529,130,165548,275926967,ARL,,13.11,100,1,13,2,1,12.98,200,1,12.86,100,1,12.73,100,1,12.71,100,1,12.5,700,1,12.46,100,1,12.43,700,1,12.42,700,1,13.58,15,1,13.59,100,1,13.6,15,1,13.63,100,1,13.92,100,1,13.94,2,1,14.23,100,1,14.28,100,1,14.52,300,1,14.56,800,1,2,328614529
2025-07-17T16:06:22.153148893Z,2025-07-17T16:06:22.152983326Z,160,2,1108,C,A,15.790000000,100,0,327870361,0,165567,275927034,ARL,,13.11,100,1,13,2,1,12.98,200,1,12.86,100,1,12.73,100,1,12.71,100,1,12.5,700,1,12.46,100,1,12.43,700,1,12.42,700,1,13.58,15,1,13.59,100,1,13.6,15,1,13.63,100,1,13.92,100,1,13.94,2,1,14.23,100,1,14.28,100,1,14.52,300,1,14.56,800,1,2,327870361
2025-07-17T16:06:22.153148893Z,2025-07-17T16:06:22.152983326Z,160,2,1108,A,A,15.630000000,100,0,331051145,130,165567,275927034,ARL,,13.11,100,1,13,2,1,12.98,200,1,12.86,100,1,12.73,100,1,12.71,100,1,12.5,700,1,12.46,100,1,12.43,700,1,12.42,700,1,13.58,15,1,13.59,100,1,13.6,15,1,13.63,100,1,13.92,100,1,13.94,2,1,14.23,100,1,14.28,100,1,14.52,300,1,14.56,800,1,2,331051145
2025-07-17T16:06:22.153916169Z,2025-07-17T16:06:22.153749481Z,160,2,1108,C,A,14.700000000,100,0,327868421,0,166688,275927046,ARL,,13.11,100,1,13,2,1,12.98,200,1,12.86,100,1,12.73,100,1,12.71,100,1,12.5,700,1,12.46,100,1,12.43,700,1,12.42,700,1,13.58,15,1,13.59,100,1,13.6,15,1,13.63,100,1,13.92,100,1,13.94,2,1,14.23,100,1,14.28,100,1,14.52,300,1,14.56,800,1,2,327868421
2025-07-17T16:06:22.153916169Z,2025-07-17T16:06:22.153749481Z,160,2,1108,A,A,14.550000000,100,0,331051173,130,166688,275927046,ARL,,13.11,100,1,13,2,1,12.98,200,1,12.86,100,1,12.73,100,1,12.71,100,1,12.5,700,1,12.46,100,1,12.43,700,1,12.42,700,1,13.58,15,1,13.59,100,1,13.6,15,1,13.63,100,1,13.92,100,1,13.94,2,1,14.23,100,1,14.28,100,1,14.52,300,1,14.55,100,1,2,331051173
2025-07-17T16:06:22.156070698Z,2025-07-17T16:06:22.155905240Z,160,2,1108,C,A,14.520000000,100,0,327869529,0,165458,275927117,ARL,,13.11,100,1,13,2,1,12.98,200,1,12.86,100,1,12.73,100,1,12.71,100,1,12.5,700,1,12.46,100,1,12.43,700,1,12.42,700,1,13.58,15,1,13.59,100,1,13.6,15,1,13.63,100,1,13.92,100,1,13.94,2,1,14.23,100,1,14.28,100,1,14.52,200,1,14.55,100,1,2,327869529
2025-07-17T16:06:22.156070698Z,2025-07-17T16:06:22.155905240Z,160,2,1108,A,A,14.380000000,100,0,331051369,130,165458,275927117,ARL,,13.11,100,1,13,2,1,12.98,200,1,12.86,100,1,12.73,100,1,12.71,100,1,12.5,700,1,12.46,100,1,12.43,700,1,12.42,700,1,13.58,15,1,13.59,100,1,13.6,15,1,13.63,100,1,13.92,100,1,13.94,2,1,14.23,100,1,14.28,100,1,14.38,100,1,14.52,200,1,2,331051369
2025-07-17T16:06:22.178044675Z,2025-07-17T16:06:22.177879233Z,160,2,1108,C,A,14.700000000,100,0,327873009,0,165442,275927444,ARL,,13.11,100,1,13,2,1,12.98,200,1,12.86,100,1,12.73,100,1,12.71,100,1,12.5,700,1,12.46,100,1,12.43,700,1,12.42,700,1,13.58,15,1,13.59,100,1,13.6,15,1,13.63,100,1,13.92,100,1,13.94,2,1,14.23,100,1,14.28,100,1,14.38,100,1,14.52,200,1,2,327873009
2025-07-17T16:06:22.178044675Z,2025-07-17T16:06:22.177879233Z,160,2,1108,A,A,14.550000000,100,0,331052197,130,165442,275927444,ARL,,13.11,100,1,13,2,1,12.98,200,1,12.86,100,1,12.73,100,1,12.71,100,1,12.5,700,1,12.46,100,1,12.43,700,1,12.42,700,1,13.58,15,1,13.59,100,1,13.6,15,1,13.63,100,1,13.92,100,1,13.94,2,1,14.23,100,1,14.28,100,1,14.38,100,1,14.52,200,1,2,331052197
2025-07-17T16:06:24.519511128Z,2025-07-17T16:06:24.519345743Z,160,2,1108,A,A,13.600000000,100,0,331104725,130,165385,275968354,ARL,,13.11,100,1,13,2,1,12.98,200,1,12.86,100,1,12.73,100,1,12.71,100,1,12.5,700,1,12.46,100,1,12.43,700,1,12.42,700,1,13.58,15,1,13.59,100,1,13.6,115,1,13.63,100,1,13.92,100,1,13.94,2,1,14.23,100,1,14.28,100,1,14.38,100,1,14.52,200,1,2,331104725
2025-07-17T16:06:24.526359716Z,2025-07-17T16:06:24.526194457Z,160,2,1108,C,A,13.630000000,100,0,331018065,130,165259,275968393,ARL,,13.11,100,1,13,2,1,12.98,200,1,12.86,100,1,12.73,100,1,12.71,100,1,12.5,700,1,12.46,100,1,12.43,700,1,12.42,700,1,13.58,15,1,13.59,100,1,13.6,115,1,13.92,100,1,13.94,2,1,14.23,100,1,14.28,100,1,14.38,100,1,14.52,200,1,14.55,200,1,2,331018065
2025-07-17T16:06:26.610345800Z,2025-07-17T16:06:26.610180184Z,160,2,1108,C,A,13.940000000,2,0,328351217,0,165616,276013080,ARL,,13.11,100,1,13,2,1,12.98,200,1,12.86,100,1,12.73,100,1,12.71,100,1,12.5,700,1,12.46,100,1,12.43,700,1,12.42,700,1,13.58,15,1,13.59,100,1,13.6,115,1,13.92,100,1,14.23,100,1,14.28,100,1,14.38,100,1,14.52,200,1,14.55,200,1,14.56,800,1,2,328351217
2025-07-17T16:06:26.610345800Z,2025-07-17T16:06:26.610180184Z,160,2,1108,A,A,13.850000000,2,0,331155889,130,165616,276013080,ARL,,13.11,100,1,13,2,1,12.98,200,1,12.86,100,1,12.73,100,1,12.71,100,1,12.5,700,1,12.46,100,1,12.43,700,1,12.42,700,1,13.58,15,1,13.59,100,1,13.6,115,1,13.85,2,1,13.92,100,1,14.23,100,1,14.28,100,1,14.38,100,1,14.52,200,1,14.55,200,1,2,331155889
2025-07-17T16:06:30.625877214Z,2025-07-17T16:06:30.625711923Z,160,2,1108,A,A,14.270000000,700,0,331257169,130,165291,276103282,ARL,,13.11,100,1,13,2,1,12.98,200,1,12.86,100,1,12.73,100,1,12.71,100,1,12.5,700,1,12.46,100,1,12.43,700,1,12.42,700,1,13.58,15,1,13.59,100,1,13.6,115,1,13.85,2,1,13.92,100,1,14.23,100,1,14.27,700,1,14.28,100,1,14.38,100,1,14.52,200,1,2,331257169
2025-07-17T16:06:30.625956307Z,2025-07-17T16:06:30.625790910Z,160,2,1108,C,A,14.680000000,700,0,325716945,130,165397,276103283,ARL,,13.11,100,1,13,2,1,12.98,200,1,12.86,100,1,12.73,100,1,12.71,100,1,12.5,700,1,12.46,100,1,12.43,700,1,12.42,700,1,13.58,15,1,13.59,100,1,13.6,115,1,13.85,2,1,13.92,100,1,14.23,100,1,14.27,700,1,14.28,100,1,14.38,100,1,14.52,200,1,2,325716945
2025-07-17T16:06:31.127827805Z,2025-07-17T16:06:31.127662311Z,160,2,1108,A,A,14.480000000,700,0,331272997,130,165494,276118990,ARL,,13.11,100,1,13,2,1,12.98,200,1,12.86,100,1,12.73,100,1,12.71,100,1,12.5,700,1,12.46,100,1,12.43,700,1,12.42,700,1,13.58,15,1,13.59,100,1,13.6,115,1,13.85,2,1,13.92,100,1,14.23,100,1,14.27,700,1,14.28,100,1,14.38,100,1,14.48,700,1,2,331272997
2025-07-17T16:06:31.128581831Z,2025-07-17T16:06:31.128416336Z,160,2,1108,C,A,14.680000000,700,0,289932801,130,165495,276119017,ARL,,13.11,100,1,13,2,1,12.98,200,1,12.86,100,1,12.73,100,1,12.71,100,1,12.5,700,1,12.46,100,1,12.43,700,1,12.42,700,1,13.58,15,1,13.59,100,1,13.6,115,1,13.85,2,1,13.92,100,1,14.23,100,1,14.27,700,1,14.28,100,1,14.38,100,1,14.48,700,1,2,289932801
2025-07-17T16:06:31.990649229Z,2025-07-17T16:06:31.990483799Z,160,2,1108,C,A,13.600000000,15,0,330788421,130,165430,276135226,ARL,,13.11,100,1,13,2,1,12.98,200,1,12.86,100,1,12.73,100,1,12.71,100,1,12.5,700,1,12.46,100,1,12.43,700,1,12.42,700,1,13.58,15,1,13.59,100,1,13.6,100,1,13.85,2,1,13.92,100,1,14.23,100,1,14.27,700,1,14.28,100,1,14.38,100,1,14.48,700,1,2,330788421
2025-07-17T16:06:42.812807096Z,2025-07-17T16:06:42.812641697Z,160,2,1108,A,A,13.560000000,15,0,331488089,130,165399,276276783,ARL,,13.11,100,1,13,2,1,12.98,200,1,12.86,100,1,12.73,100,1,12.71,100,1,12.5,700,1,12.46,100,1,12.43,700,1,12.42,700,1,13.56,15,1,13.58,15,1,13.59,100,1,13.6,100,1,13.85,2,1,13.92,100,1,14.23,100,1,14.27,700,1,14.28,100,1,14.38,100,1,2,331488089
2025-07-17T16:06:43.012965957Z,2025-07-17T16:06:43.012799164Z,160,2,1108,C,A,13.590000000,100,0,331050989,0,166793,276279311,ARL,,13.11,100,1,13,2,1,12.98,200,1,12.86,100,1,12.73,100,1,12.71,100,1,12.5,700,1,12.46,100,1,12.43,700,1,12.42,700,1,13.56,15,1,13.58,15,1,13.6,100,1,13.85,2,1,13.92,100,1,14.23,100,1,14.27,700,1,14.28,100,1,14.38,100,1,14.48,700,1,2,331050989
2025-07-17T16:06:43.012965957Z,2025-07-17T16:06:43.012799164Z,160,2,1108,A,A,13.570000000,100,0,331491049,128,166793,276279311,ARL,,13.11,100,1,13,2,1,12.98,200,1,12.86,100,1,12.73,100,1,12.71,100,1,12.5,700,1,12.46,100,1,12.43,700,1,12.42,700,1,13.56,15,1,13.57,100,1,13.58,15,1,13.6,100,1,13.85,2,1,13.92,100,1,14.23,100,1,14.27,700,1,14.28,100,1,14.38,100,1,2,331491049
2025-07-17T16:06:43.013716205Z,2025-07-17T16:06:43.013550575Z,160,2,1108,C,A,14.670000000,100,0,330789501,0,165630,276279331,ARL,,13.11,100,1,13,2,1,12.98,200,1,12.86,100,1,12.73,100,1,12.71,100,1,12.5,700,1,12.46,100,1,12.43,700,1,12.42,700,1,13.56,15,1,13.57,100,1,13.58,15,1,13.6,100,1,13.85,2,1,13.92,100,1,14.23,100,1,14.27,700,1,14.28,100,1,14.38,100,1,2,330789501
2025-07-17T16:06:43.013716205Z,2025-07-17T16:06:43.013550575Z,160,2,1108,A,A,14.620000000,100,0,331491077,130,165630,276279331,ARL,,13.11,100,1,13,2,1,12.98,200,1,12.86,100,1,12.73,100,1,12.71,100,1,12.5,700,1,12.46,100,1,12.43,700,1,12.42,700,1,13.56,15,1,13.57,100,1,13.58,15,1,13.6,100,1,13.85,2,1,13.92,100,1,14.23,100,1,14.27,700,1,14.28,100,1,14.38,100,1,2,331491077
2025-07-17T16:06:43.024656023Z,2025-07-17T16:06:43.024490355Z,160,2,1108,C,A,13.920000000,100,0,330359625,130,165668,276279620,ARL,,13.11,100,1,13,2,1,12.98,200,1,12.86,100,1,12.73,100,1,12.71,100,1,12.5,700,1,12.46,100,1,12.43,700,1,12.42,700,1,13.56,15,1,13.57,100,1,13.58,15,1,13.6,100,1,13.85,2,1,14.23,100,1,14.27,700,1,14.28,100,1,14.38,100,1,14.48,700,1,2,330359625
2025-07-17T16:06:43.024708304Z,2025-07-17T16:06:43.024543099Z,160,2,1108,A,A,13.840000000,100,0,331491269,130,165205,276279621,ARL,,13.11,100,1,13,2,1,12.98,200,1,12.86,100,1,12.73,100,1,12.71,100,1,12.5,700,1,12.46,100,1,12.43,700,1,12.42,700,1,13.56,15,1,13.57,100,1,13.58,15,1,13.6,100,1,13.84,100,1,13.85,2,1,14.23,100,1,14.27,700,1,14.28,100,1,14.38,100,1,2,331491269
2025-07-17T16:06:49.613941821Z,2025-07-17T16:06:49.613776144Z,160,2,1108,C,A,13.580000000,15,0,331050981,130,165677,276382302,ARL,,13.11,100,1,13,2,1,12.98,200,1,12.86,100,1,12.73,100,1,12.71,100,1,12.5,700,1,12.46,100,1,12.43,700,1,12.42,700,1,13.56,15,1,13.57,100,1,13.6,100,1,13.84,100,1,13.85,2,1,14.23,100,1,14.27,700,1,14.28,100,1,14.38,100,1,14.48,700,1,2,331050981
2025-07-17T16:06:50.618669843Z,2025-07-17T16:06:50.618504506Z,160,2,1108,A,A,13.540000000,15,0,331666961,130,165337,276408477,ARL,,13.11,100,1,13,2,1,12.98,200,1,12.86,100,1,12.73,100,1,12.71,100,1,12.5,700,1,12.46,100,1,12.43,700,1,12.42,700,1,13.54,15,1,13.56,15,1,13.57,100,1,13.6,100,1,13.84,100,1,13.85,2,1,14.23,100,1,14.27,700,1,14.28,100,1,14.38,100,1,2,331666961
2025-07-17T16:06:50.626438205Z,2025-07-17T16:06:50.626272828Z,160,2,1108,A,A,13.580000000,100,0,331667121,130,165377,276408566,ARL,,13.11,100,1,13,2,1,12.98,200,1,12.86,100,1,12.73,100,1,12.71,100,1,12.5,700,1,12.46,100,1,12.43,700,1,12.42,700,1,13.54,15,1,13.56,15,1,13.57,100,1,13.58,100,1,13.6,100,1,13.84,100,1,13.85,2,1,14.23,100,1,14.27,700,1,14.28,100,1,2,331667121
2025-07-17T16:06:50.633113557Z,2025-07-17T16:06:50.632947998Z,160,2,1108,C,A,13.600000000,100,0,331104725,130,165559,276408644,ARL,,13.11,100,1,13,2,1,12.98,200,1,12.86,100,1,12.73,100,1,12.71,100,1,12.5,700,1,12.46,100,1,12.43,700,1,12.42,700,1,13.54,15,1,13.56,15,1,13.57,100,1,13.58,100,1,13.84,100,1,13.85,2,1,14.23,100,1,14.27,700,1,14.28,100,1,14.38,100,1,2,331104725
2025-07-17T16:06:51.754576322Z,2025-07-17T16:06:51.754410704Z,160,2,1108,C,A,13.570000000,100,0,331491049,0,165618,276428315,ARL,,13.11,100,1,13,2,1,12.98,200,1,12.86,100,1,12.73,100,1,12.71,100,1,12.5,700,1,12.46,100,1,12.43,700,1,12.42,700,1,13.54,15,1,13.56,15,1,13.58,100,1,13.84,100,1,13.85,2,1,14.23,100,1,14.27,700,1,14.28,100,1,14.38,100,1,14.48,700,1,2,331491049
2025-07-17T16:06:51.754576322Z,2025-07-17T16:06:51.754410704Z,160,2,1108,A,A,13.550000000,100,0,331694265,130,165618,276428315,ARL,,13.11,100,1,13,2,1,12.98,200,1,12.86,100,1,12.73,100,1,12.71,100,1,12.5,700,1,12.46,100,1,12.43,700,1,12.42,700,1,13.54,15,1,13.55,100,1,13.56,15,1,13.58,100,1,13.84,100,1,13.85,2,1,14.23,100,1,14.27,700,1,14.28,100,1,14.38,100,1,2,331694265
2025-07-17T16:06:51.757403109Z,2025-07-17T16:06:51.757237300Z,160,2,1108,C,B,13.000000000,2,0,325967705,0,165809,276428333,ARL,,13.11,100,1,12.98,200,1,12.86,100,1,12.73,100,1,12.71,100,1,12.5,700,1,12.46,100,1,12.43,700,1,12.42,700,1,12.37,700,1,13.54,15,1,13.55,100,1,13.56,15,1,13.58,100,1,13.84,100,1,13.85,2,1,14.23,100,1,14.27,700,1,14.28,100,1,14.38,100,1,2,325967705
2025-07-17T16:06:51.757403109Z,2025-07-17T16:06:51.757237300Z,160,2,1108,A,B,12.900000000,2,0,331694297,130,165809,276428333,ARL,,13.11,100,1,12.98,200,1,12.9,2,1,12.86,100,1,12.73,100,1,12.71,100,1,12.5,700,1,12.46,100,1,12.43,700,1,12.42,700,1,13.54,15,1,13.55,100,1,13.56,15,1,13.58,100,1,13.84,100,1,13.85,2,1,14.23,100,1,14.27,700,1,14.28,100,1,14.38,100,1,2,331694297
2025-07-17T16:06:55.056300861Z,2025-07-17T16:06:55.056135380Z,160,2,1108,C,A,13.540000000,15,0,331666961,130,165481,276516227,ARL,,13.11,100,1,12.98,200,1,12.9,2,1,12.86,100,1,12.73,100,1,12.71,100,1,12.5,700,1,12.46,100,1,12.43,700,1,12.42,700,1,13.55,100,1,13.56,15,1,13.58,100,1,13.84,100,1,13.85,2,1,14.23,100,1,14.27,700,1,14.28,100,1,14.38,100,1,14.48,700,1,2,331666961
2025-07-17T16:06:55.056466231Z,2025-07-17T16:06:55.056301001Z,160,2,1108,C,A,13.560000000,15,0,331488089,130,165230,276516239,ARL,,13.11,100,1,12.98,200,1,12.9,2,1,12.86,100,1,12.73,100,1,12.71,100,1,12.5,700,1,12.46,100,1,12.43,700,1,12.42,700,1,13.55,100,1,13.58,100,1,13.84,100,1,13.85,2,1,14.23,100,1,14.27,700,1,14.28,100,1,14.38,100,1,14.48,700,1,14.52,200,1,2,331488089
2025-07-17T16:07:00.010995558Z,2025-07-17T16:07:00.010829521Z,160,2,1108,C,A,13.550000000,100,0,331694265,130,166037,276611719,ARL,,13.11,100,1,12.98,200,1,12.9,2,1,12.86,100,1,12.73,100,1,12.71,100,1,12.5,700,1,12.46,100,1,12.43,700,1,12.42,700,1,13.58,100,1,13.84,100,1,13.85,2,1,14.23,100,1,14.27,700,1,14.28,100,1,14.38,100,1,14.48,700,1,14.52,200,1,14.55,200,1,2,331694265
2025-07-17T16:07:00.023849180Z,2025-07-17T16:07:00.023683961Z,160,2,1108,C,A,13.580000000,100,0,331667121,130,165219,276613073,ARL,,13.11,100,1,12.98,200,1,12.9,2,1,12.86,100,1,12.73,100,1,12.71,100,1,12.5,700,1,12.46,100,1,12.43,700,1,12.42,700,1,13.84,100,1,13.85,2,1,14.23,100,1,14.27,700,1,14.28,100,1,14.38,100,1,14.48,700,1,14.52,200,1,14.55,200,1,14.56,800,1,2,331667121
2025-07-17T16:07:00.023917543Z,2025-07-17T16:07:00.023752163Z,160,2,1108,C,A,14.270000000,700,0,331257169,130,165380,276613077,ARL,,13.11,100,1,12.98,200,1,12.9,2,1,12.86,100,1,12.73,100,1,12.71,100,1,12.5,700,1,12.46,100,1,12.43,700,1,12.42,700,1,13.84,100,1,13.85,2,1,14.23,100,1,14.28,100,1,14.38,100,1,14.48,700,1,14.52,200,1,14.55,200,1,14.56,800,1,14.6,700,1,2,331257169
2025-07-17T16:07:00.023980805Z,2025-07-17T16:07:00.023815326Z,160,2,1108,A,A,14.510000000,700,0,331926981,130,165479,276613078,ARL,,13.11,100,1,12.98,200,1,12.9,2,1,12.86,100,1,12.73,100,1,12.71,100,1,12.5,700,1,12.46,100,1,12.43,700,1,12.42,700,1,13.84,100,1,13.85,2,1,14.23,100,1,14.28,100,1,14.38,100,1,14.48,700,1,14.51,700,1,14.52,200,1,14.55,200,1,14.56,800,1,2,331926981
2025-07-17T16:07:00.024590283Z,2025-07-17T16:07:00.024424816Z,160,2,1108,C,A,14.620000000,100,0,331491077,0,165467,276613110,ARL,,13.11,100,1,12.98,200,1,12.9,2,1,12.86,100,1,12.73,100,1,12.71,100,1,12.5,700,1,12.46,100,1,12.43,700,1,12.42,700,1,13.84,100,1,13.85,2,1,14.23,100,1,14.28,100,1,14.38,100,1,14.48,700,1,14.51,700,1,14.52,200,1,14.55,200,1,14.56,800,1,2,331491077
2025-07-17T16:07:00.024590283Z,2025-07-17T16:07:00.024424816Z,160,2,1108,A,A,14.880000000,100,0,331927017,130,165467,276613110,ARL,,13.11,100,1,12.98,200,1,12.9,2,1,12.86,100,1,12.73,100,1,12.71,100,1,12.5,700,1,12.46,100,1,12.43,700,1,12.42,700,1,13.84,100,1,13.85,2,1,14.23,100,1,14.28,100,1,14.38,100,1,14.48,700,1,14.51,700,1,14.52,200,1,14.55,200,1,14.56,800,1,2,331927017
2025-07-17T16:07:00.025231164Z,2025-07-17T16:07:00.025064913Z,160,2,1108,C,A,14.230000000,100,0,329074833,130,166251,276613157,ARL,,13.11,100,1,12.98,200,1,12.9,2,1,12.86,100,1,12.73,100,1,12.71,100,1,12.5,700,1,12.46,100,1,12.43,700,1,12.42,700,1,13.84,100,1,13.85,2,1,14.28,100,1,14.38,100,1,14.48,700,1,14.51,700,1,14.52,200,1,14.55,200,1,14.56,800,1,14.6,700,1,2,329074833
2025-07-17T16:07:00.025587549Z,2025-07-17T16:07:00.025422082Z,160,2,1108,A,A,14.460000000,100,0,331927161,130,165467,276613175,ARL,,13.11,100,1,12.98,200,1,12.9,2,1,12.86,100,1,12.73,100,1,12.71,100,1,12.5,700,1,12.46,100,1,12.43,700,1,12.42,700,1,13.84,100,1,13.85,2,1,14.28,100,1,14.38,100,1,14.46,100,1,14.48,700,1,14.51,700,1,14.52,200,1,14.55,200,1,14.56,800,1,2,331927161
2025-07-17T16:07:00.025793260Z,2025-07-17T16:07:00.025628157Z,160,2,1108,A,A,13.590000000,100,0,331927177,130,165103,276613194,ARL,,13.11,100,1,12.98,200,1,12.9,2,1,12.86,100,1,12.73,100,1,12.71,100,1,12.5,700,1,12.46,100,1,12.43,700,1,12.42,700,1,13.59,100,1,13.84,100,1,13.85,2,1,14.28,100,1,14.38,100,1,14.46,100,1,14.48,700,1,14.51,700,1,14.52,200,1,14.55,200,1,2,331927177
2025-07-17T16:07:00.026998695Z,2025-07-17T16:07:00.026833761Z,160,2,1108,C,A,13.590000000,100,0,331927177,130,164934,276613224,ARL,,13.11,100,1,12.98,200,1,12.9,2,1,12.86,100,1,12.73,100,1,12.71,100,1,12.5,700,1,12.46,100,1,12.43,700,1,12.42,700,1,13.84,100,1,13.85,2,1,14.28,100,1,14.38,100,1,14.46,100,1,14.48,700,1,14.51,700,1,14.52,200,1,14.55,200,1,14.56,800,1,2,331927177
2025-07-17T16:07:00.032762182Z,2025-07-17T16:07:00.032596898Z,160,2,1108,C,A,14.380000000,100,0,331051369,130,165284,276613329,ARL,,13.11,100,1,12.98,200,1,12.9,2,1,12.86,100,1,12.73,100,1,12.71,100,1,12.5,700,1,12.46,100,1,12.43,700,1,12.42,700,1,13.84,100,1,13.85,2,1,14.28,100,1,14.46,100,1,14.48,700,1,14.51,700,1,14.52,200,1,14.55,200,1,14.56,800,1,14.6,700,1,2,331051369
2025-07-17T16:07:00.032876947Z,2025-07-17T16:07:00.032711777Z,160,2,1108,A,A,14.630000000,100,0,331927477,130,165170,276613336,ARL,,13.11,100,1,12.98,200,1,12.9,2,1,12.86,100,1,12.73,100,1,12.71,100,1,12.5,700,1,12.46,100,1,12.43,700,1,12.42,700,1,13.84,100,1,13.85,2,1,14.28,100,1,14.46,100,1,14.48,700,1,14.51,700,1,14.52,200,1,14.55,200,1,14.56,800,1,14.6,700,1,2,331927477
2025-07-17T16:07:00.045525047Z,2025-07-17T16:07:00.045359807Z,160,2,1108,C,A,13.840000000,100,0,331491269,130,165240,276613663,ARL,,13.11,100,1,12.98,200,1,12.9,2,1,12.86,100,1,12.73,100,1,12.71,100,1,12.5,700,1,12.46,100,1,12.43,700,1,12.42,700,1,13.85,2,1,14.28,100,1,14.46,100,1,14.48,700,1,14.51,700,1,14.52,200,1,14.55,200,1,14.56,800,1,14.6,700,1,14.63,100,1,2,331491269
2025-07-17T16:07:00.045559272Z,2025-07-17T16:07:00.045394317Z,160,2,1108,C,A,14.510000000,700,0,331926981,130,164955,276613664,ARL,,13.11,100,1,12.98,200,1,12.9,2,1,12.86,100,1,12.73,100,1,12.71,100,1,12.5,700,1,12.46,100,1,12.43,700,1,12.42,700,1,13.85,2,1,14.28,100,1,14.46,100,1,14.48,700,1,14.52,200,1,14.55,200,1,14.56,800,1,14.6,700,1,14.63,100,1,14.88,100,1,2,331926981
2025-07-17T16:07:00.045574786Z,2025-07-17T16:07:00.045409635Z,160,2,1108,A,A,14.090000000,100,0,331927857,130,165151,276613665,ARL,,13.11,100,1,12.98,200,1,12.9,2,1,12.86,100,1,12.73,100,1,12.71,100,1,12.5,700,1,12.46,100,1,12.43,700,1,12.42,700,1,13.85,2,1,14.09,100,1,14.28,100,1,14.46,100,1,14.48,700,1,14.52,200,1,14.55,200,1,14.56,800,1,14.6,700,1,14.63,100,1,2,331927857
2025-07-17T16:07:00.046838602Z,2025-07-17T16:07:00.046672908Z,160,2,1108,C,A,14.090000000,100,0,331927857,130,165694,276613680,ARL,,13.11,100,1,12.98,200,1,12.9,2,1,12.86,100,1,12.73,100,1,12.71,100,1,12.5,700,1,12.46,100,1,12.43,700,1,12.42,700,1,13.85,2,1,14.28,100,1,14.46,100,1,14.48,700,1,14.52,200,1,14.55,200,1,14.56,800,1,14.6,700,1,14.63,100,1,14.88,100,1,2,331927857
2025-07-17T16:07:00.046887005Z,2025-07-17T16:07:00.046721624Z,160,2,1108,A,A,13.860000000,100,0,331927877,130,165381,276613681,ARL,,13.11,100,1,12.98,200,1,12.9,2,1,12.86,100,1,12.73,100,1,12.71,100,1,12.5,700,1,12.46,100,1,12.43,700,1,12.42,700,1,13.85,2,1,13.86,100,1,14.28,100,1,14.46,100,1,14.48,700,1,14.52,200,1,14.55,200,1,14.56,800,1,14.6,700,1,14.63,100,1,2,331927877
2025-07-17T16:07:00.047708936Z,2025-07-17T16:07:00.047544064Z,160,2,1108,C,A,13.860000000,100,0,331927877,130,164872,276613692,ARL,,13.11,100,1,12.98,200,1,12.9,2,1,12.86,100,1,12.73,100,1,12.71,100,1,12.5,700,1,12.46,100,1,12.43,700,1,12.42,700,1,13.85,2,1,14.28,100,1,14.46,100,1,14.48,700,1,14.52,200,1,14.55,200,1,14.56,800,1,14.6,700,1,14.63,100,1,14.88,100,1,2,331927877
2025-07-17T16:07:00.047755498Z,2025-07-17T16:07:00.047590313Z,160,2,1108,A,A,14.120000000,100,0,331927921,130,165185,276613693,ARL,,13.11,100,1,12.98,200,1,12.9,2,1,12.86,100,1,12.73,100,1,12.71,100,1,12.5,700,1,12.46,100,1,12.43,700,1,12.42,700,1,13.85,2,1,14.12,100,1,14.28,100,1,14.46,100,1,14.48,700,1,14.52,200,1,14.55,200,1,14.56,800,1,14.6,700,1,14.63,100,1,2,331927921
2025-07-17T16:07:00.053448670Z,2025-07-17T16:07:00.053283700Z,160,2,1108,C,A,14.120000000,100,0,331927921,130,164970,276613731,ARL,,13.11,100,1,12.98,200,1,12.9,2,1,12.86,100,1,12.73,100,1,12.71,100,1,12.5,700,1,12.46,100,1,12.43,700,1,12.42,700,1,13.85,2,1,14.28,100,1,14.46,100,1,14.48,700,1,14.52,200,1,14.55,200,1,14.56,800,1,14.6,700,1,14.63,100,1,14.88,100,1,2,331927921
2025-07-17T16:07:00.053495095Z,2025-07-17T16:07:00.053329959Z,160,2,1108,A,A,14.260000000,100,0,331928009,130,165136,276613732,ARL,,13.11,100,1,12.98,200,1,12.9,2,1,12.86,100,1,12.73,100,1,12.71,100,1,12.5,700,1,12.46,100,1,12.43,700,1,12.42,700,1,13.85,2,1,14.26,100,1,14.28,100,1,14.46,100,1,14.48,700,1,14.52,200,1,14.55,200,1,14.56,800,1,14.6,700,1,14.63,100,1,2,331928009
2025-07-17T16:07:00.057809857Z,2025-07-17T16:07:00.057644427Z,160,2,1108,C,A,14.550000000,100,0,331052197,0,165430,276613800,ARL,,13.11,100,1,12.98,200,1,12.9,2,1,12.86,100,1,12.73,100,1,12.71,100,1,12.5,700,1,12.46,100,1,12.43,700,1,12.42,700,1,13.85,2,1,14.26,100,1,14.28,100,1,14.46,100,1,14.48,700,1,14.52,200,1,14.55,100,1,14.56,800,1,14.6,700,1,14.63,100,1,2,331052197
2025-07-17T16:07:00.057809857Z,2025-07-17T16:07:00.057644427Z,160,2,1108,A,A,14.960000000,100,0,331928129,130,165430,276613800,ARL,,13.11,100,1,12.98,200,1,12.9,2,1,12.86,100,1,12.73,100,1,12.71,100,1,12.5,700,1,12.46,100,1,12.43,700,1,12.42,700,1,13.85,2,1,14.26,100,1,14.28,100,1,14.46,100,1,14.48,700,1,14.52,200,1,14.55,100,1,14.56,800,1,14.6,700,1,14.63,100,1,2,331928129
2025-07-17T16:07:00.070490835Z,2025-07-17T16:07:00.070325784Z,160,2,1108,C,A,14.260000000,100,0,331928009,130,165051,276614087,ARL,,13.11,100,1,12.98,200,1,12.9,2,1,12.86,100,1,12.73,100,1,12.71,100,1,12.5,700,1,12.46,100,1,12.43,700,1,12.42,700,1,13.85,2,1,14.28,100,1,14.46,100,1,14.48,700,1,14.52,200,1,14.55,100,1,14.56,800,1,14.6,700,1,14.63,100,1,14.88,100,1,2,331928009
2025-07-17T16:07:00.070539222Z,2025-07-17T16:07:00.070373975Z,160,2,1108,A,A,14.140000000,100,0,331929033,130,165247,276614089,ARL,,13.11,100,1,12.98,200,1,12.9,2,1,12.86,100,1,12.73,100,1,12.71,100,1,12.5,700,1,12.46,100,1,12.43,700,1,12.42,700,1,13.85,2,1,14.14,100,1,14.28,100,1,14.46,100,1,14.48,700,1,14.52,200,1,14.55,100,1,14.56,800,1,14.6,700,1,14.63,100,1,2,331929033
2025-07-17T16:07:00.071359350Z,2025-07-17T16:07:00.071194493Z,160,2,1108,C,A,14.140000000,100,0,331929033,130,164857,276614094,ARL,,13.11,100,1,12.98,200,1,12.9,2,1,12.86,100,1,12.73,100,1,12.71,100,1,12.5,700,1,12.46,100,1,12.43,700,1,12.42,700,1,13.85,2,1,14.28,100,1,14.46,100,1,14.48,700,1,14.52,200,1,14.55,100,1,14.56,800,1,14.6,700,1,14.63,100,1,14.88,100,1,2,331929033
2025-07-17T16:07:00.071405105Z,2025-07-17T16:07:00.071239867Z,160,2,1108,A,A,14.260000000,100,0,331929041,130,165238,276614095,ARL,,13.11,100,1,12.98,200,1,12.9,2,1,12.86,100,1,12.73,100,1,12.71,100,1,12.5,700,1,12.46,100,1,12.43,700,1,12.42,700,1,13.85,2,1,14.26,100,1,14.28,100,1,14.46,100,1,14.48,700,1,14.52,200,1,14.55,100,1,14.56,800,1,14.6,700,1,14.63,100,1,2,331929041
2025-07-17T16:07:00.074580946Z,2025-07-17T16:07:00.074415631Z,160,2,1108,C,A,14.880000000,100,0,331927017,0,165315,276614119,ARL,,13.11,100,1,12.98,200,1,12.9,2,1,12.86,100,1,12.73,100,1,12.71,100,1,12.5,700,1,12.46,100,1,12.43,700,1,12.42,700,1,13.85,2,1,14.26,100,1,14.28,100,1,14.46,100,1,14.48,700,1,14.52,200,1,14.55,100,1,14.56,800,1,14.6,700,1,14.63,100,1,2,331927017
2025-07-17T16:07:00.074580946Z,2025-07-17T16:07:00.074415631Z,160,2,1108,A,A,15.060000000,100,0,331929065,130,165315,276614119,ARL,,13.11,100,1,12.98,200,1,12.9,2,1,12.86,100,1,12.73,100,1,12.71,100,1,12.5,700,1,12.46,100,1,12.43,700,1,12.42,700,1,13.85,2,1,14.26,100,1,14.28,100,1,14.46,100,1,14.48,700,1,14.52,200,1,14.55,100,1,14.56,800,1,14.6,700,1,14.63,100,1,2,331929065
2025-07-17T16:07:00.085131263Z,2025-07-17T16:07:00.084965637Z,160,2,1108,C,A,15.070000000,100,0,326837501,0,165626,276614295,ARL,,13.11,100,1,12.98,200,1,12.9,2,1,12.86,100,1,12.73,100,1,12.71,100,1,12.5,700,1,12.46,100,1,12.43,700,1,12.42,700,1,13.85,2,1,14.26,100,1,14.28,100,1,14.46,100,1,14.48,700,1,14.52,200,1,14.55,100,1,14.56,800,1,14.6,700,1,14.63,100,1,2,326837501
2025-07-17T16:07:00.085131263Z,2025-07-17T16:07:00.084965637Z,160,2,1108,A,A,15.380000000,100,0,331929445,130,165626,276614295,ARL,,13.11,100,1,12.98,200,1,12.9,2,1,12.86,100,1,12.73,100,1,12.71,100,1,12.5,700,1,12.46,100,1,12.43,700,1,12.42,700,1,13.85,2,1,14.26,100,1,14.28,100,1,14.46,100,1,14.48,700,1,14.52,200,1,14.55,100,1,14.56,800,1,14.6,700,1,14.63,100,1,2,331929445
2025-07-17T16:07:00.090359757Z,2025-07-17T16:07:00.090194106Z,160,2,1108,C,A,14.550000000,100,0,331051173,0,165651,276614378,ARL,,13.11,100,1,12.98,200,1,12.9,2,1,12.86,100,1,12.73,100,1,12.71,100,1,12.5,700,1,12.46,100,1,12.43,700,1,12.42,700,1,13.85,2,1,14.26,100,1,14.28,100,1,14.46,100,1,14.48,700,1,14.52,200,1,14.56,800,1,14.6,700,1,14.63,100,1,14.96,100,1,2,331051173
2025-07-17T16:07:00.090359757Z,2025-07-17T16:07:00.090194106Z,160,2,1108,A,A,14.960000000,100,0,331929633,130,165651,276614378,ARL,,13.11,100,1,12.98,200,1,12.9,2,1,12.86,100,1,12.73,100,1,12.71,100,1,12.5,700,1,12.46,100,1,12.43,700,1,12.42,700,1,13.85,2,1,14.26,100,1,14.28,100,1,14.46,100,1,14.48,700,1,14.52,200,1,14.56,800,1,14.6,700,1,14.63,100,1,14.96,200,1,2,331929633
2025-07-17T16:07:00.102092147Z,2025-07-17T16:07:00.101927028Z,160,2,1108,A,A,14.680000000,700,0,331929977,130,165119,276614699,ARL,,13.11,100,1,12.98,200,1,12.9,2,1,12.86,100,1,12.73,100,1,12.71,100,1,12.5,700,1,12.46,100,1,12.43,700,1,12.42,700,1,13.85,2,1,14.26,100,1,14.28,100,1,14.46,100,1,14.48,700,1,14.52,200,1,14.56,800,1,14.6,700,1,14.63,100,1,14.68,700,1,2,331929977
2025-07-17T16:07:00.287582448Z,2025-07-17T16:07:00.287416733Z,160,2,1108,C,A,17.290000000,100,0,330789509,0,165715,276617288,ARL,,13.11,100,1,12.98,200,1,12.9,2,1,12.86,100,1,12.73,100,1,12.71,100,1,12.5,700,1,12.46,100,1,12.43,700,1,12.42,700,1,13.85,2,1,14.26,100,1,14.28,100,1,14.46,100,1,14.48,700,1,14.52,200,1,14.56,800,1,14.6,700,1,14.63,100,1,14.68,700,1,2,330789509
2025-07-17T16:07:00.287582448Z,2025-07-17T16:07:00.287416733Z,160,2,1108,A,A,17.760000000,100,0,331934277,130,165715,276617288,ARL,,13.11,100,1,12.98,200,1,12.9,2,1,12.86,100,1,12.73,100,1,12.71,100,1,12.5,700,1,12.46,100,1,12.43,700,1,12.42,700,1,13.85,2,1,14.26,100,1,14.28,100,1,14.46,100,1,14.48,700,1,14.52,200,1,14.56,800,1,14.6,700,1,14.63,100,1,14.68,700,1,2,331934277
2025-07-17T16:07:00.293620434Z,2025-07-17T16:07:00.293454856Z,160,2,1108,C,A,15.630000000,100,0,331051145,0,165578,276617317,ARL,,13.11,100,1,12.98,200,1,12.9,2,1,12.86,100,1,12.73,100,1,12.71,100,1,12.5,700,1,12.46,100,1,12.43,700,1,12.42,700,1,13.85,2,1,14.26,100,1,14.28,100,1,14.46,100,1,14.48,700,1,14.52,200,1,14.56,800,1,14.6,700,1,14.63,100,1,14.68,700,1,2,331051145
2025-07-17T16:07:00.293620434Z,2025-07-17T16:07:00.293454856Z,160,2,1108,A,A,16.080000000,100,0,331934377,130,165578,276617317,ARL,,13.11,100,1,12.98,200,1,12.9,2,1,12.86,100,1,12.73,100,1,12.71,100,1,12.5,700,1,12.46,100,1,12.43,700,1,12.42,700,1,13.85,2,1,14.26,100,1,14.28,100,1,14.46,100,1,14.48,700,1,14.52,200,1,14.56,800,1,14.6,700,1,14.63,100,1,14.68,700,1,2,331934377
2025-07-17T16:07:00.494657495Z,2025-07-17T16:07:00.494492099Z,160,2,1108,A,A,13.860000000,100,0,331942821,130,165396,276622423,ARL,,13.11,100,1,12.98,200,1,12.9,2,1,12.86,100,1,12.73,100,1,12.71,100,1,12.5,700,1,12.46,100,1,12.43,700,1,12.42,700,1,13.85,2,1,13.86,100,1,14.26,100,1,14.28,100,1,14.46,100,1,14.48,700,1,14.52,200,1,14.56,800,1,14.6,700,1,14.63,100,1,2,331942821
2025-07-17T16:07:00.495318245Z,2025-07-17T16:07:00.495152219Z,160,2,1108,C,B,12.360000000,100,0,288723817,0,166026,276622452,ARL,,13.11,100,1,12.98,200,1,12.9,2,1,12.86,100,1,12.73,100,1,12.71,100,1,12.5,700,1,12.46,100,1,12.43,700,1,12.42,700,1,13.85,2,1,13.86,100,1,14.26,100,1,14.28,100,1,14.46,100,1,14.48,700,1,14.52,200,1,14.56,800,1,14.6,700,1,14.63,100,1,2,288723817
2025-07-17T16:07:00.495318245Z,2025-07-17T16:07:00.495152219Z,160,2,1108,A,B,12.490000000,100,0,331942901,130,166026,276622452,ARL,,13.11,100,1,12.98,200,1,12.9,2,1,12.86,100,1,12.73,100,1,12.71,100,1,12.5,700,1,12.49,100,1,12.46,100,1,12.43,700,1,13.85,2,1,13.86,100,1,14.26,100,1,14.28,100,1,14.46,100,1,14.48,700,1,14.52,200,1,14.56,800,1,14.6,700,1,14.63,100,1,2,331942901
2025-07-17T16:07:00.495398644Z,2025-07-17T16:07:00.495233001Z,160,2,1108,C,A,15.060000000,100,0,331929065,0,165643,276622455,ARL,,13.11,100,1,12.98,200,1,12.9,2,1,12.86,100,1,12.73,100,1,12.71,100,1,12.5,700,1,12.49,100,1,12.46,100,1,12.43,700,1,13.85,2,1,13.86,100,1,14.26,100,1,14.28,100,1,14.46,100,1,14.48,700,1,14.52,200,1,14.56,800,1,14.6,700,1,14.63,100,1,2,331929065
2025-07-17T16:07:00.495398644Z,2025-07-17T16:07:00.495233001Z,160,2,1108,A,A,14.930000000,100,0,331942913,130,165643,276622455,ARL,,13.11,100,1,12.98,200,1,12.9,2,1,12.86,100,1,12.73,100,1,12.71,100,1,12.5,700,1,12.49,100,1,12.46,100,1,12.43,700,1,13.85,2,1,13.86,100,1,14.26,100,1,14.28,100,1,14.46,100,1,14.48,700,1,14.52,200,1,14.56,800,1,14.6,700,1,14.63,100,1,2,331942913
2025-07-17T16:07:00.495989598Z,2025-07-17T16:07:00.495823953Z,160,2,1108,C,B,12.360000000,100,0,288723813,0,165645,276622469,ARL,,13.11,100,1,12.98,200,1,12.9,2,1,12.86,100,1,12.73,100,1,12.71,100,1,12.5,700,1,12.49,100,1,12.46,100,1,12.43,700,1,13.85,2,1,13.86,100,1,14.26,100,1,14.28,100,1,14.46,100,1,14.48,700,1,14.52,200,1,14.56,800,1,14.6,700,1,14.63,100,1,2,288723813
2025-07-17T16:07:00.495989598Z,2025-07-17T16:07:00.495823953Z,160,2,1108,A,B,12.490000000,100,0,331942945,130,165645,276622469,ARL,,13.11,100,1,12.98,200,1,12.9,2,1,12.86,100,1,12.73,100,1,12.71,100,1,12.5,700,1,12.49,200,1,12.46,100,1,12.43,700,1,13.85,2,1,13.86,100,1,14.26,100,1,14.28,100,1,14.46,100,1,14.48,700,1,14.52,200,1,14.56,800,1,14.6,700,1,14.63,100,1,2,331942945
2025-07-17T16:07:00.496483460Z,2025-07-17T16:07:00.496317847Z,160,2,1108,C,A,17.760000000,100,0,331934277,0,165613,276622478,ARL,,13.11,100,1,12.98,200,1,12.9,2,1,12.86,100,1,12.73,100,1,12.71,100,1,12.5,700,1,12.49,200,1,12.46,100,1,12.43,700,1,13.85,2,1,13.86,100,1,14.26,100,1,14.28,100,1,14.46,100,1,14.48,700,1,14.52,200,1,14.56,800,1,14.6,700,1,14.63,100,1,2,331934277
2025-07-17T16:07:00.496483460Z,2025-07-17T16:07:00.496317847Z,160,2,1108,A,A,17.610000000,100,0,331942981,130,165613,276622478,ARL,,13.11,100,1,12.98,200,1,12.9,2,1,12.86,100,1,12.73,100,1,12.71,100,1,12.5,700,1,12.49,200,1,12.46,100,1,12.43,700,1,13.85,2,1,13.86,100,1,14.26,100,1,14.28,100,1,14.46,100,1,14.48,700,1,14.52,200,1,14.56,800,1,14.6,700,1,14.63,100,1,2,331942981
2025-07-17T16:07:00.499666149Z,2025-07-17T16:07:00.499501052Z,160,2,1108,C,A,14.260000000,100,0,331929041,130,165097,276622569,ARL,,13.11,100,1,12.98,200,1,12.9,2,1,12.86,100,1,12.73,100,1,12.71,100,1,12.5,700,1,12.49,200,1,12.46,100,1,12.43,700,1,13.85,2,1,13.86,100,1,14.28,100,1,14.46,100,1,14.48,700,1,14.52,200,1,14.56,800,1,14.6,700,1,14.63,100,1,14.68,700,1,2,331929041
2025-07-17T16:07:00.499714918Z,2025-07-17T16:07:00.499549738Z,160,2,1108,A,A,14.140000000,100,0,331943133,130,165180,276622571,ARL,,13.11,100,1,12.98,200,1,12.9,2,1,12.86,100,1,12.73,100,1,12.71,100,1,12.5,700,1,12.49,200,1,12.46,100,1,12.43,700,1,13.85,2,1,13.86,100,1,14.14,100,1,14.28,100,1,14.46,100,1,14.48,700,1,14.52,200,1,14.56,800,1,14.6,700,1,14.63,100,1,2,331943133
2025-07-17T16:07:22.814941809Z,2025-07-17T16:07:22.814776694Z,160,2,1108,A,A,13.690000000,15,0,332385317,130,165115,276946179,ARL,,13.11,100,1,12.98,200,1,12.9,2,1,12.86,100,1,12.73,100,1,12.71,100,1,12.5,700,1,12.49,200,1,12.46,100,1,12.43,700,1,13.69,15,1,13.85,2,1,13.86,100,1,14.14,100,1,14.28,100,1,14.46,100,1,14.48,700,1,14.52,200,1,14.56,800,1,14.6,700,1,2,332385317
2025-07-17T16:07:22.815057507Z,2025-07-17T16:07:22.814891345Z,160,2,1108,C,A,13.860000000,100,0,331942821,0,166162,276946183,ARL,,13.11,100,1,12.98,200,1,12.9,2,1,12.86,100,1,12.73,100,1,12.71,100,1,12.5,700,1,12.49,200,1,12.46,100,1,12.43,700,1,13.69,15,1,13.85,2,1,14.14,100,1,14.28,100,1,14.46,100,1,14.48,700,1,14.52,200,1,14.56,800,1,14.6,700,1,14.63,100,1,2,331942821
2025-07-17T16:07:22.815057507Z,2025-07-17T16:07:22.814891345Z,160,2,1108,A,A,13.700000000,100,0,332385325,130,166162,276946183,ARL,,13.11,100,1,12.98,200,1,12.9,2,1,12.86,100,1,12.73,100,1,12.71,100,1,12.5,700,1,12.49,200,1,12.46,100,1,12.43,700,1,13.69,15,1,13.7,100,1,13.85,2,1,14.14,100,1,14.28,100,1,14.46,100,1,14.48,700,1,14.52,200,1,14.56,800,1,14.6,700,1,2,332385325
2025-07-17T16:07:22.815790890Z,2025-07-17T16:07:22.815625345Z,160,2,1108,C,A,14.930000000,100,0,331942913,0,165545,276946264,ARL,,13.11,100,1,12.98,200,1,12.9,2,1,12.86,100,1,12.73,100,1,12.71,100,1,12.5,700,1,12.49,200,1,12.46,100,1,12.43,700,1,13.69,15,1,13.7,100,1,13.85,2,1,14.14,100,1,14.28,100,1,14.46,100,1,14.48,700,1,14.52,200,1,14.56,800,1,14.6,700,1,2,331942913
2025-07-17T16:07:22.815790890Z,2025-07-17T16:07:22.815625345Z,160,2,1108,A,A,14.760000000,100,0,332385501,130,165545,276946264,ARL,,13.11,100,1,12.98,200,1,12.9,2,1,12.86,100,1,12.73,100,1,12.71,100,1,12.5,700,1,12.49,200,1,12.46,100,1,12.43,700,1,13.69,15,1,13.7,100,1,13.85,2,1,14.14,100,1,14.28,100,1,14.46,100,1,14.48,700,1,14.52,200,1,14.56,800,1,14.6,700,1,2,332385501
2025-07-17T16:07:22.817507809Z,2025-07-17T16:07:22.817341789Z,160,2,1108,C,A,14.960000000,100,0,331929633,0,166020,276946309,ARL,,13.11,100,1,12.98,200,1,12.9,2,1,12.86,100,1,12.73,100,1,12.71,100,1,12.5,700,1,12.49,200,1,12.46,100,1,12.43,700,1,13.69,15,1,13.7,100,1,13.85,2,1,14.14,100,1,14.28,100,1,14.46,100,1,14.48,700,1,14.52,200,1,14.56,800,1,14.6,700,1,2,331929633
2025-07-17T16:07:22.817507809Z,2025-07-17T16:07:22.817341789Z,160,2,1108,A,A,14.660000000,100,0,332385565,130,166020,276946309,ARL,,13.11,100,1,12.98,200,1,12.9,2,1,12.86,100,1,12.73,100,1,12.71,100,1,12.5,700,1,12.49,200,1,12.46,100,1,12.43,700,1,13.69,15,1,13.7,100,1,13.85,2,1,14.14,100,1,14.28,100,1,14.46,100,1,14.48,700,1,14.52,200,1,14.56,800,1,14.6,700,1,2,332385565
2025-07-17T16:07:22.817624699Z,2025-07-17T16:07:22.817459170Z,160,2,1108,C,A,15.380000000,100,0,331929445,0,165529,276946313,ARL,,13.11,100,1,12.98,200,1,12.9,2,1,12.86,100,1,12.73,100,1,12.71,100,1,12.5,700,1,12.49,200,1,12.46,100,1,12.43,700,1,13.69,15,1,13.7,100,1,13.85,2,1,14.14,100,1,14.28,100,1,14.46,100,1,14.48,700,1,14.52,200,1,14.56,800,1,14.6,700,1,2,331929445
2025-07-17T16:07:22.817624699Z,2025-07-17T16:07:22.817459170Z,160,2,1108,A,A,15.070000000,100,0,332385569,130,165529,276946313,ARL,,13.11,100,1,12.98,200,1,12.9,2,1,12.86,100,1,12.73,100,1,12.71,100,1,12.5,700,1,12.49,200,1,12.46,100,1,12.43,700,1,13.69,15,1,13.7,100,1,13.85,2,1,14.14,100,1,14.28,100,1,14.46,100,1,14.48,700,1,14.52,200,1,14.56,800,1,14.6,700,1,2,332385569
2025-07-17T16:07:22.818565766Z,2025-07-17T16:07:22.818400003Z,160,2,1108,C,A,16.080000000,100,0,331934377,0,165763,276946327,ARL,,13.11,100,1,12.98,200,1,12.9,2,1,12.86,100,1,12.73,100,1,12.71,100,1,12.5,700,1,12.49,200,1,12.46,100,1,12.43,700,1,13.69,15,1,13.7,100,1,13.85,2,1,14.14,100,1,14.28,100,1,14.46,100,1,14.48,700,1,14.52,200,1,14.56,800,1,14.6,700,1,2,331934377
2025-07-17T16:07:22.818565766Z,2025-07-17T16:07:22.818400003Z,160,2,1108,A,A,15.760000000,100,0,332385585,130,165763,276946327,ARL,,13.11,100,1,12.98,200,1,12.9,2,1,12.86,100,1,12.73,100,1,12.71,100,1,12.5,700,1,12.49,200,1,12.46,100,1,12.43,700,1,13.69,15,1,13.7,100,1,13.85,2,1,14.14,100,1,14.28,100,1,14.46,100,1,14.48,700,1,14.52,200,1,14.56,800,1,14.6,700,1,2,332385585
2025-07-17T16:07:22.819710983Z,2025-07-17T16:07:22.819545360Z,160,2,1108,C,A,17.610000000,100,0,331942981,0,165623,276946336,ARL,,13.11,100,1,12.98,200,1,12.9,2,1,12.86,100,1,12.73,100,1,12.71,100,1,12.5,700,1,12.49,200,1,12.46,100,1,12.43,700,1,13.69,15,1,13.7,100,1,13.85,2,1,14.14,100,1,14.28,100,1,14.46,100,1,14.48,700,1,14.52,200,1,14.56,800,1,14.6,700,1,2,331942981
2025-07-17T16:07:22.819710983Z,2025-07-17T16:07:22.819545360Z,160,2,1108,A,A,17.400000000,100,0,332385593,130,165623,276946336,ARL,,13.11,100,1,12.98,200,1,12.9,2,1,12.86,100,1,12.73,100,1,12.71,100,1,12.5,700,1,12.49,200,1,12.46,100,1,12.43,700,1,13.69,15,1,13.7,100,1,13.85,2,1,14.14,100,1,14.28,100,1,14.46,100,1,14.48,700,1,14.52,200,1,14.56,800,1,14.6,700,1,2,332385593
2025-07-17T16:07:22.819772408Z,2025-07-17T16:07:22.819606945Z,160,2,1108,C,A,14.630000000,100,0,331927477,0,165463,276946337,ARL,,13.11,100,1,12.98,200,1,12.9,2,1,12.86,100,1,12.73,100,1,12.71,100,1,12.5,700,1,12.49,200,1,12.46,100,1,12.43,700,1,13.69,15,1,13.7,100,1,13.85,2,1,14.14,100,1,14.28,100,1,14.46,100,1,14.48,700,1,14.52,200,1,14.56,800,1,14.6,700,1,2,331927477
2025-07-17T16:07:22.819772408Z,2025-07-17T16:07:22.819606945Z,160,2,1108,A,A,14.490000000,100,0,332385597,130,165463,276946337,ARL,,13.11,100,1,12.98,200,1,12.9,2,1,12.86,100,1,12.73,100,1,12.71,100,1,12.5,700,1,12.49,200,1,12.46,100,1,12.43,700,1,13.69,15,1,13.7,100,1,13.85,2,1,14.14,100,1,14.28,100,1,14.46,100,1,14.48,700,1,14.49,100,1,14.52,200,1,14.56,800,1,2,332385597
2025-07-17T16:07:22.821165451Z,2025-07-17T16:07:22.821000003Z,160,2,1108,C,A,14.140000000,100,0,331943133,130,165448,276946343,ARL,,13.11,100,1,12.98,200,1,12.9,2,1,12.86,100,1,12.73,100,1,12.71,100,1,12.5,700,1,12.49,200,1,12.46,100,1,12.43,700,1,13.69,15,1,13.7,100,1,13.85,2,1,14.28,100,1,14.46,100,1,14.48,700,1,14.49,100,1,14.52,200,1,14.56,800,1,14.6,700,1,2,331943133
2025-07-17T16:07:22.821218207Z,2025-07-17T16:07:22.821052982Z,160,2,1108,A,A,13.970000000,100,0,332385613,130,165225,276946344,ARL,,13.11,100,1,12.98,200,1,12.9,2,1,12.86,100,1,12.73,100,1,12.71,100,1,12.5,700,1,12.49,200,1,12.46,100,1,12.43,700,1,13.69,15,1,13.7,100,1,13.85,2,1,13.97,100,1,14.28,100,1,14.46,100,1,14.48,700,1,14.49,100,1,14.52,200,1,14.56,800,1,2,332385613
2025-07-17T16:07:22.832119220Z,2025-07-17T16:07:22.831949887Z,160,2,1108,C,A,14.960000000,100,0,331928129,0,169333,276946801,ARL,,13.11,100,1,12.98,200,1,12.9,2,1,12.86,100,1,12.73,100,1,12.71,100,1,12.5,700,1,12.49,200,1,12.46,100,1,12.43,700,1,13.69,15,1,13.7,100,1,13.85,2,1,13.97,100,1,14.28,100,1,14.46,100,1,14.48,700,1,14.49,100,1,14.52,200,1,14.56,800,1,2,331928129
2025-07-17T16:07:22.832119220Z,2025-07-17T16:07:22.831949887Z,160,2,1108,A,A,14.660000000,100,0,332386121,128,169333,276946801,ARL,,13.11,100,1,12.98,200,1,12.9,2,1,12.86,100,1,12.73,100,1,12.71,100,1,12.5,700,1,12.49,200,1,12.46,100,1,12.43,700,1,13.69,15,1,13.7,100,1,13.85,2,1,13.97,100,1,14.28,100,1,14.46,100,1,14.48,700,1,14.49,100,1,14.52,200,1,14.56,800,1,2,332386121
2025-07-17T16:07:28.273823608Z,2025-07-17T16:07:28.273658191Z,160,2,1108,C,A,13.690000000,15,0,332385317,130,165417,277012951,ARL,,13.11,100,1,12.98,200,1,12.9,2,1,12.86,100,1,12.73,100,1,12.71,100,1,12.5,700,1,12.49,200,1,12.46,100,1,12.43,700,1,13.7,100,1,13.85,2,1,13.97,100,1,14.28,100,1,14.46,100,1,14.48,700,1,14.49,100,1,14.52,200,1,14.56,800,1,14.6,700,1,2,332385317
2025-07-17T16:07:28.700981149Z,2025-07-17T16:07:28.700815737Z,160,2,1108,C,A,13.700000000,100,0,332385325,130,165412,277019711,ARL,,13.11,100,1,12.98,200,1,12.9,2,1,12.86,100,1,12.73,100,1,12.71,100,1,12.5,700,1,12.49,200,1,12.46,100,1,12.43,700,1,13.85,2,1,13.97,100,1,14.28,100,1,14.46,100,1,14.48,700,1,14.49,100,1,14.52,200,1,14.56,800,1,14.6,700,1,14.66,200,1,2,332385325
2025-07-17T16:07:28.701396669Z,2025-07-17T16:07:28.701230409Z,160,2,1108,C,B,12.900000000,2,0,331694297,0,166260,277019718,ARL,,13.11,100,1,12.98,200,1,12.86,100,1,12.73,100,1,12.71,100,1,12.5,700,1,12.49,200,1,12.46,100,1,12.43,700,1,12.42,700,1,13.85,2,1,13.97,100,1,14.28,100,1,14.46,100,1,14.48,700,1,14.49,100,1,14.52,200,1,14.56,800,1,14.6,700,1,14.66,200,1,2,331694297
2025-07-17T16:07:28.701396669Z,2025-07-17T16:07:28.701230409Z,160,2,1108,A,B,13.010000000,2,0,332494213,130,166260,277019718,ARL,,13.11,100,1,13.01,2,1,12.98,200,1,12.86,100,1,12.73,100,1,12.71,100,1,12.5,700,1,12.49,200,1,12.46,100,1,12.43,700,1,13.85,2,1,13.97,100,1,14.28,100,1,14.46,100,1,14.48,700,1,14.49,100,1,14.52,200,1,14.56,800,1,14.6,700,1,14.66,200,1,2,332494213
2025-07-17T16:07:28.701713232Z,2025-07-17T16:07:28.701547540Z,160,2,1108,C,A,14.760000000,100,0,332385501,0,165692,277019720,ARL,,13.11,100,1,13.01,2,1,12.98,200,1,12.86,100,1,12.73,100,1,12.71,100,1,12.5,700,1,12.49,200,1,12.46,100,1,12.43,700,1,13.85,2,1,13.97,100,1,14.28,100,1,14.46,100,1,14.48,700,1,14.49,100,1,14.52,200,1,14.56,800,1,14.6,700,1,14.66,200,1,2,332385501
2025-07-17T16:07:28.701713232Z,2025-07-17T16:07:28.701547540Z,160,2,1108,A,A,14.820000000,100,0,332494229,130,165692,277019720,ARL,,13.11,100,1,13.01,2,1,12.98,200,1,12.86,100,1,12.73,100,1,12.71,100,1,12.5,700,1,12.49,200,1,12.46,100,1,12.43,700,1,13.85,2,1,13.97,100,1,14.28,100,1,14.46,100,1,14.48,700,1,14.49,100,1,14.52,200,1,14.56,800,1,14.6,700,1,14.66,200,1,2,332494229
2025-07-17T16:07:28.702166297Z,2025-07-17T16:07:28.702000772Z,160,2,1108,C,A,15.760000000,100,0,332385585,0,165525,277019722,ARL,,13.11,100,1,13.01,2,1,12.98,200,1,12.86,100,1,12.73,100,1,12.71,100,1,12.5,700,1,12.49,200,1,12.46,100,1,12.43,700,1,13.85,2,1,13.97,100,1,14.28,100,1,14.46,100,1,14.48,700,1,14.49,100,1,14.52,200,1,14.56,800,1,14.6,700,1,14.66,200,1,2,332385585
2025-07-17T16:07:28.702166297Z,2025-07-17T16:07:28.702000772Z,160,2,1108,A,A,16.010000000,100,0,332494245,130,165525,277019722,ARL,,13.11,100,1,13.01,2,1,12.98,200,1,12.86,100,1,12.73,100,1,12.71,100,1,12.5,700,1,12.49,200,1,12.46,100,1,12.43,700,1,13.85,2,1,13.97,100,1,14.28,100,1,14.46,100,1,14.48,700,1,14.49,100,1,14.52,200,1,14.56,800,1,14.6,700,1,14.66,200,1,2,332494245
2025-07-17T16:07:28.702642020Z,2025-07-17T16:07:28.702476699Z,160,2,1108,C,A,14.660000000,100,0,332386121,0,165321,277019729,ARL,,13.11,100,1,13.01,2,1,12.98,200,1,12.86,100,1,12.73,100,1,12.71,100,1,12.5,700,1,12.49,200,1,12.46,100,1,12.43,700,1,13.85,2,1,13.97,100,1,14.28,100,1,14.46,100,1,14.48,700,1,14.49,100,1,14.52,200,1,14.56,800,1,14.6,700,1,14.66,100,1,2,332386121
2025-07-17T16:07:28.702642020Z,2025-07-17T16:07:28.702476699Z,160,2,1108,A,A,14.950000000,100,0,332494281,130,165321,277019729,ARL,,13.11,100,1,13.01,2,1,12.98,200,1,12.86,100,1,12.73,100,1,12.71,100,1,12.5,700,1,12.49,200,1,12.46,100,1,12.43,700,1,13.85,2,1,13.97,100,1,14.28,100,1,14.46,100,1,14.48,700,1,14.49,100,1,14.52,200,1,14.56,800,1,14.6,700,1,14.66,100,1,2,332494281
2025-07-17T16:07:28.703523092Z,2025-07-17T16:07:28.703357714Z,160,2,1108,C,A,14.660000000,100,0,332385565,0,165378,277019733,ARL,,13.11,100,1,13.01,2,1,12.98,200,1,12.86,100,1,12.73,100,1,12.71,100,1,12.5,700,1,12.49,200,1,12.46,100,1,12.43,700,1,13.85,2,1,13.97,100,1,14.28,100,1,14.46,100,1,14.48,700,1,14.49,100,1,14.52,200,1,14.56,800,1,14.6,700,1,14.68,700,1,2,332385565
2025-07-17T16:07:28.703523092Z,2025-07-17T16:07:28.703357714Z,160,2,1108,A,A,14.950000000,100,0,332494285,130,165378,277019733,ARL,,13.11,100,1,13.01,2,1,12.98,200,1,12.86,100,1,12.73,100,1,12.71,100,1,12.5,700,1,12.49,200,1,12.46,100,1,12.43,700,1,13.85,2,1,13.97,100,1,14.28,100,1,14.46,100,1,14.48,700,1,14.49,100,1,14.52,200,1,14.56,800,1,14.6,700,1,14.68,700,1,2,332494285
2025-07-17T16:07:28.703920336Z,2025-07-17T16:07:28.703754662Z,160,2,1108,C,A,15.070000000,100,0,332385569,0,165674,277019735,ARL,,13.11,100,1,13.01,2,1,12.98,200,1,12.86,100,1,12.73,100,1,12.71,100,1,12.5,700,1,12.49,200,1,12.46,100,1,12.43,700,1,13.85,2,1,13.97,100,1,14.28,100,1,14.46,100,1,14.48,700,1,14.49,100,1,14.52,200,1,14.56,800,1,14.6,700,1,14.68,700,1,2,332385569
2025-07-17T16:07:28.703920336Z,2025-07-17T16:07:28.703754662Z,160,2,1108,A,A,15.370000000,100,0,332494289,130,165674,277019735,ARL,,13.11,100,1,13.01,2,1,12.98,200,1,12.86,100,1,12.73,100,1,12.71,100,1,12.5,700,1,12.49,200,1,12.46,100,1,12.43,700,1,13.85,2,1,13.97,100,1,14.28,100,1,14.46,100,1,14.48,700,1,14.49,100,1,14.52,200,1,14.56,800,1,14.6,700,1,14.68,700,1,2,332494289
2025-07-17T16:07:28.704198103Z,2025-07-17T16:07:28.704032725Z,160,2,1108,C,A,17.400000000,100,0,332385593,0,165378,277019738,ARL,,13.11,100,1,13.01,2,1,12.98,200,1,12.86,100,1,12.73,100,1,12.71,100,1,12.5,700,1,12.49,200,1,12.46,100,1,12.43,700,1,13.85,2,1,13.97,100,1,14.28,100,1,14.46,100,1,14.48,700,1,14.49,100,1,14.52,200,1,14.56,800,1,14.6,700,1,14.68,700,1,2,332385593
2025-07-17T16:07:28.704198103Z,2025-07-17T16:07:28.704032725Z,160,2,1108,A,A,17.750000000,100,0,332494297,130,165378,277019738,ARL,,13.11,100,1,13.01,2,1,12.98,200,1,12.86,100,1,12.73,100,1,12.71,100,1,12.5,700,1,12.49,200,1,12.46,100,1,12.43,700,1,13.85,2,1,13.97,100,1,14.28,100,1,14.46,100,1,14.48,700,1,14.49,100,1,14.52,200,1,14.56,800,1,14.6,700,1,14.68,700,1,2,332494297
2025-07-17T16:07:28.724201840Z,2025-07-17T16:07:28.724036175Z,160,2,1108,C,A,13.970000000,100,0,332385613,130,165665,277019926,ARL,,13.11,100,1,13.01,2,1,12.98,200,1,12.86,100,1,12.73,100,1,12.71,100,1,12.5,700,1,12.49,200,1,12.46,100,1,12.43,700,1,13.85,2,1,14.28,100,1,14.46,100,1,14.48,700,1,14.49,100,1,14.52,200,1,14.56,800,1,14.6,700,1,14.68,700,1,14.82,100,1,2,332385613
2025-07-17T16:07:28.724250835Z,2025-07-17T16:07:28.724085453Z,160,2,1108,A,A,14.200000000,100,0,332494893,130,165382,277019929,ARL,,13.11,100,1,13.01,2,1,12.98,200,1,12.86,100,1,12.73,100,1,12.71,100,1,12.5,700,1,12.49,200,1,12.46,100,1,12.43,700,1,13.85,2,1,14.2,100,1,14.28,100,1,14.46,100,1,14.48,700,1,14.49,100,1,14.52,200,1,14.56,800,1,14.6,700,1,14.68,700,1,2,332494893
2025-07-17T16:07:28.751828120Z,2025-07-17T16:07:28.751662660Z,160,2,1108,C,A,14.820000000,100,0,332494229,0,165460,277020284,ARL,,13.11,100,1,13.01,2,1,12.98,200,1,12.86,100,1,12.73,100,1,12.71,100,1,12.5,700,1,12.49,200,1,12.46,100,1,12.43,700,1,13.85,2,1,14.2,100,1,14.28,100,1,14.46,100,1,14.48,700,1,14.49,100,1,14.52,200,1,14.56,800,1,14.6,700,1,14.68,700,1,2,332494229
2025-07-17T16:07:28.751828120Z,2025-07-17T16:07:28.751662660Z,160,2,1108,A,A,15.050000000,100,0,332495781,130,165460,277020284,ARL,,13.11,100,1,13.01,2,1,12.98,200,1,12.86,100,1,12.73,100,1,12.71,100,1,12.5,700,1,12.49,200,1,12.46,100,1,12.43,700,1,13.85,2,1,14.2,100,1,14.28,100,1,14.46,100,1,14.48,700,1,14.49,100,1,14.52,200,1,14.56,800,1,14.6,700,1,14.68,700,1,2,332495781
2025-07-17T16:07:28.831160987Z,2025-07-17T16:07:28.830995364Z,160,2,1108,C,A,14.490000000,100,0,332385597,130,165623,277021007,ARL,,13.11,100,1,13.01,2,1,12.98,200,1,12.86,100,1,12.73,100,1,12.71,100,1,12.5,700,1,12.49,200,1,12.46,100,1,12.43,700,1,13.85,2,1,14.2,100,1,14.28,100,1,14.46,100,1,14.48,700,1,14.52,200,1,14.56,800,1,14.6,700,1,14.68,700,1,14.95,200,1,2,332385597
2025-07-17T16:07:28.831291377Z,2025-07-17T16:07:28.831125667Z,160,2,1108,A,A,14.770000000,100,0,332497653,130,165710,277021012,ARL,,13.11,100,1,13.01,2,1,12.98,200,1,12.86,100,1,12.73,100,1,12.71,100,1,12.5,700,1,12.49,200,1,12.46,100,1,12.43,700,1,13.85,2,1,14.2,100,1,14.28,100,1,14.46,100,1,14.48,700,1,14.52,200,1,14.56,800,1,14.6,700,1,14.68,700,1,14.77,100,1,2,332497653
2025-07-17T16:07:29.214667270Z,2025-07-17T16:07:29.214500816Z,160,2,1108,A,A,13.860000000,100,0,332508813,128,166454,277029015,ARL,,13.11,100,1,13.01,2,1,12.98,200,1,12.86,100,1,12.73,100,1,12.71,100,1,12.5,700,1,12.49,200,1,12.46,100,1,12.43,700,1,13.85,2,1,13.86,100,1,14.2,100,1,14.28,100,1,14.46,100,1,14.48,700,1,14.52,200,1,14.56,800,1,14.6,700,1,14.68,700,1,2,332508813
2025-07-17T16:07:29.215458844Z,2025-07-17T16:07:29.215292291Z,160,2,1108,C,A,15.050000000,100,0,332495781,0,166553,277029273,ARL,,13.11,100,1,13.01,2,1,12.98,200,1,12.86,100,1,12.73,100,1,12.71,100,1,12.5,700,1,12.49,200,1,12.46,100,1,12.43,700,1,13.85,2,1,13.86,100,1,14.2,100,1,14.28,100,1,14.46,100,1,14.48,700,1,14.52,200,1,14.56,800,1,14.6,700,1,14.68,700,1,2,332495781
2025-07-17T16:07:29.215458844Z,2025-07-17T16:07:29.215292291Z,160,2,1108,A,A,14.930000000,100,0,332508997,128,166553,277029273,ARL,,13.11,100,1,13.01,2,1,12.98,200,1,12.86,100,1,12.73,100,1,12.71,100,1,12.5,700,1,12.49,200,1,12.46,100,1,12.43,700,1,13.85,2,1,13.86,100,1,14.2,100,1,14.28,100,1,14.46,100,1,14.48,700,1,14.52,200,1,14.56,800,1,14.6,700,1,14.68,700,1,2,332508997
2025-07-17T16:08:20.816252850Z,2025-07-17T16:08:20.816087447Z,160,2,1108,A,A,13.680000000,15,0,333436357,130,165403,277732167,ARL,,13.11,100,1,13.01,2,1,12.98,200,1,12.86,100,1,12.73,100,1,12.71,100,1,12.5,700,1,12.49,200,1,12.46,100,1,12.43,700,1,13.68,15,1,13.85,2,1,13.86,100,1,14.2,100,1,14.28,100,1,14.46,100,1,14.48,700,1,14.52,200,1,14.56,800,1,14.6,700,1,2,333436357
2025-07-17T16:08:20.816366205Z,2025-07-17T16:08:20.816200644Z,160,2,1108,C,A,13.860000000,100,0,332508813,0,165561,277732170,ARL,,13.11,100,1,13.01,2,1,12.98,200,1,12.86,100,1,12.73,100,1,12.71,100,1,12.5,700,1,12.49,200,1,12.46,100,1,12.43,700,1,13.68,15,1,13.85,2,1,14.2,100,1,14.28,100,1,14.46,100,1,14.48,700,1,14.52,200,1,14.56,800,1,14.6,700,1,14.68,700,1,2,332508813
2025-07-17T16:08:20.816366205Z,2025-07-17T16:08:20.816200644Z,160,2,1108,A,A,13.690000000,100,0,333436361,130,165561,277732170,ARL,,13.11,100,1,13.01,2,1,12.98,200,1,12.86,100,1,12.73,100,1,12.71,100,1,12.5,700,1,12.49,200,1,12.46,100,1,12.43,700,1,13.68,15,1,13.69,100,1,13.85,2,1,14.2,100,1,14.28,100,1,14.46,100,1,14.48,700,1,14.52,200,1,14.56,800,1,14.6,700,1,2,333436361
2025-07-17T16:08:20.817097587Z,2025-07-17T16:08:20.816932150Z,160,2,1108,C,A,14.930000000,100,0,332508997,0,165437,277732194,ARL,,13.11,100,1,13.01,2,1,12.98,200,1,12.86,100,1,12.73,100,1,12.71,100,1,12.5,700,1,12.49,200,1,12.46,100,1,12.43,700,1,13.68,15,1,13.69,100,1,13.85,2,1,14.2,100,1,14.28,100,1,14.46,100,1,14.48,700,1,14.52,200,1,14.56,800,1,14.6,700,1,2,332508997
2025-07-17T16:08:20.817097587Z,2025-07-17T16:08:20.816932150Z,160,2,1108,A,A,14.750000000,100,0,333436397,130,165437,277732194,ARL,,13.11,100,1,13.01,2,1,12.98,200,1,12.86,100,1,12.73,100,1,12.71,100,1,12.5,700,1,12.49,200,1,12.46,100,1,12.43,700,1,13.68,15,1,13.69,100,1,13.85,2,1,14.2,100,1,14.28,100,1,14.46,100,1,14.48,700,1,14.52,200,1,14.56,800,1,14.6,700,1,2,333436397
2025-07-17T16:08:20.818725102Z,2025-07-17T16:08:20.818559377Z,160,2,1108,C,A,15.370000000,100,0,332494289,0,165725,277732213,ARL,,13.11,100,1,13.01,2,1,12.98,200,1,12.86,100,1,12.73,100,1,12.71,100,1,12.5,700,1,12.49,200,1,12.46,100,1,12.43,700,1,13.68,15,1,13.69,100,1,13.85,2,1,14.2,100,1,14.28,100,1,14.46,100,1,14.48,700,1,14.52,200,1,14.56,800,1,14.6,700,1,2,332494289
2025-07-17T16:08:20.818725102Z,2025-07-17T16:08:20.818559377Z,160,2,1108,A,A,15.060000000,100,0,333436421,130,165725,277732213,ARL,,13.11,100,1,13.01,2,1,12.98,200,1,12.86,100,1,12.73,100,1,12.71,100,1,12.5,700,1,12.49,200,1,12.46,100,1,12.43,700,1,13.68,15,1,13.69,100,1,13.85,2,1,14.2,100,1,14.28,100,1,14.46,100,1,14.48,700,1,14.52,200,1,14.56,800,1,14.6,700,1,2,333436421
2025-07-17T16:08:20.819130820Z,2025-07-17T16:08:20.818965359Z,160,2,1108,C,A,14.950000000,100,0,332494285,0,165461,277732216,ARL,,13.11,100,1,13.01,2,1,12.98,200,1,12.86,100,1,12.73,100,1,12.71,100,1,12.5,700,1,12.49,200,1,12.46,100,1,12.43,700,1,13.68,15,1,13.69,100,1,13.85,2,1,14.2,100,1,14.28,100,1,14.46,100,1,14.48,700,1,14.52,200,1,14.56,800,1,14.6,700,1,2,332494285
2025-07-17T16:08:20.819130820Z,2025-07-17T16:08:20.818965359Z,160,2,1108,A,A,14.650000000,100,0,333436425,130,165461,277732216,ARL,,13.11,100,1,13.01,2,1,12.98,200,1,12.86,100,1,12.73,100,1,12.71,100,1,12.5,700,1,12.49,200,1,12.46,100,1,12.43,700,1,13.68,15,1,13.69,100,1,13.85,2,1,14.2,100,1,14.28,100,1,14.46,100,1,14.48,700,1,14.52,200,1,14.56,800,1,14.6,700,1,2,333436425
2025-07-17T16:08:20.819767091Z,2025-07-17T16:08:20.819601669Z,160,2,1108,C,A,17.750000000,100,0,332494297,0,165422,277732221,ARL,,13.11,100,1,13.01,2,1,12.98,200,1,12.86,100,1,12.73,100,1,12.71,100,1,12.5,700,1,12.49,200,1,12.46,100,1,12.43,700,1,13.68,15,1,13.69,100,1,13.85,2,1,14.2,100,1,14.28,100,1,14.46,100,1,14.48,700,1,14.52,200,1,14.56,800,1,14.6,700,1,2,332494297
2025-07-17T16:08:20.819767091Z,2025-07-17T16:08:20.819601669Z,160,2,1108,A,A,17.390000000,100,0,333436441,130,165422,277732221,ARL,,13.11,100,1,13.01,2,1,12.98,200,1,12.86,100,1,12.73,100,1,12.71,100,1,12.5,700,1,12.49,200,1,12.46,100,1,12.43,700,1,13.68,15,1,13.69,100,1,13.85,2,1,14.2,100,1,14.28,100,1,14.46,100,1,14.48,700,1,14.52,200,1,14.56,800,1,14.6,700,1,2,333436441
2025-07-17T16:08:20.820666169Z,2025-07-17T16:08:20.820500575Z,160,2,1108,C,A,16.010000000,100,0,332494245,0,165594,277732228,ARL,,13.11,100,1,13.01,2,1,12.98,200,1,12.86,100,1,12.73,100,1,12.71,100,1,12.5,700,1,12.49,200,1,12.46,100,1,12.43,700,1,13.68,15,1,13.69,100,1,13.85,2,1,14.2,100,1,14.28,100,1,14.46,100,1,14.48,700,1,14.52,200,1,14.56,800,1,14.6,700,1,2,332494245
2025-07-17T16:08:20.820666169Z,2025-07-17T16:08:20.820500575Z,160,2,1108,A,A,15.750000000,100,0,333436449,130,165594,277732228,ARL,,13.11,100,1,13.01,2,1,12.98,200,1,12.86,100,1,12.73,100,1,12.71,100,1,12.5,700,1,12.49,200,1,12.46,100,1,12.43,700,1,13.68,15,1,13.69,100,1,13.85,2,1,14.2,100,1,14.28,100,1,14.46,100,1,14.48,700,1,14.52,200,1,14.56,800,1,14.6,700,1,2,333436449
2025-07-17T16:08:20.822089544Z,2025-07-17T16:08:20.821924168Z,160,2,1108,C,A,14.200000000,100,0,332494893,130,165376,277732239,ARL,,13.11,100,1,13.01,2,1,12.98,200,1,12.86,100,1,12.73,100,1,12.71,100,1,12.5,700,1,12.49,200,1,12.46,100,1,12.43,700,1,13.68,15,1,13.69,100,1,13.85,2,1,14.28,100,1,14.46,100,1,14.48,700,1,14.52,200,1,14.56,800,1,14.6,700,1,14.65,100,1,2,332494893
2025-07-17T16:08:20.822139541Z,2025-07-17T16:08:20.821974299Z,160,2,1108,A,A,13.960000000,100,0,333436473,130,165242,277732240,ARL,,13.11,100,1,13.01,2,1,12.98,200,1,12.86,100,1,12.73,100,1,12.71,100,1,12.5,700,1,12.49,200,1,12.46,100,1,12.43,700,1,13.68,15,1,13.69,100,1,13.85,2,1,13.96,100,1,14.28,100,1,14.46,100,1,14.48,700,1,14.52,200,1,14.56,800,1,14.6,700,1,2,333436473
2025-07-17T16:08:20.830110499Z,2025-07-17T16:08:20.829945074Z,160,2,1108,C,A,14.950000000,100,0,332494281,0,165425,277732299,ARL,,13.11,100,1,13.01,2,1,12.98,200,1,12.86,100,1,12.73,100,1,12.71,100,1,12.5,700,1,12.49,200,1,12.46,100,1,12.43,700,1,13.68,15,1,13.69,100,1,13.85,2,1,13.96,100,1,14.28,100,1,14.46,100,1,14.48,700,1,14.52,200,1,14.56,800,1,14.6,700,1,2,332494281
2025-07-17T16:08:20.830110499Z,2025-07-17T16:08:20.829945074Z,160,2,1108,A,A,14.650000000,100,0,333436589,130,165425,277732299,ARL,,13.11,100,1,13.01,2,1,12.98,200,1,12.86,100,1,12.73,100,1,12.71,100,1,12.5,700,1,12.49,200,1,12.46,100,1,12.43,700,1,13.68,15,1,13.69,100,1,13.85,2,1,13.96,100,1,14.28,100,1,14.46,100,1,14.48,700,1,14.52,200,1,14.56,800,1,14.6,700,1,2,333436589
2025-07-17T16:08:20.966229266Z,2025-07-17T16:08:20.966063681Z,160,2,1108,C,A,14.770000000,100,0,332497653,0,165585,277733304,ARL,,13.11,100,1,13.01,2,1,12.98,200,1,12.86,100,1,12.73,100,1,12.71,100,1,12.5,700,1,12.49,200,1,12.46,100,1,12.43,700,1,13.68,15,1,13.69,100,1,13.85,2,1,13.96,100,1,14.28,100,1,14.46,100,1,14.48,700,1,14.52,200,1,14.56,800,1,14.6,700,1,2,332497653
2025-07-17T16:08:20.966229266Z,2025-07-17T16:08:20.966063681Z,160,2,1108,A,A,14.480000000,100,0,333438545,130,165585,277733304,ARL,,13.11,100,1,13.01,2,1,12.98,200,1,12.86,100,1,12.73,100,1,12.71,100,1,12.5,700,1,12.49,200,1,12.46,100,1,12.43,700,1,13.68,15,1,13.69,100,1,13.85,2,1,13.96,100,1,14.28,100,1,14.46,100,1,14.48,800,1,14.52,200,1,14.56,800,1,14.6,700,1,2,333438545
2025-07-17T16:08:22.998168186Z,2025-07-17T16:08:22.998002821Z,160,2,1108,C,A,13.680000000,15,0,333436357,130,165365,277766492,ARL,,13.11,100,1,13.01,2,1,12.98,200,1,12.86,100,1,12.73,100,1,12.71,100,1,12.5,700,1,12.49,200,1,12.46,100,1,12.43,700,1,13.69,100,1,13.85,2,1,13.96,100,1,14.28,100,1,14.46,100,1,14.48,800,1,14.52,200,1,14.56,800,1,14.6,700,1,14.65,200,1,2,333436357
2025-07-17T16:08:27.482509684Z,2025-07-17T16:08:27.482344236Z,160,2,1108,C,A,13.690000000,100,0,333436361,130,165448,277841171,ARL,,13.11,100,1,13.01,2,1,12.98,200,1,12.86,100,1,12.73,100,1,12.71,100,1,12.5,700,1,12.49,200,1,12.46,100,1,12.43,700,1,13.85,2,1,13.96,100,1,14.28,100,1,14.46,100,1,14.48,800,1,14.52,200,1,14.56,800,1,14.6,700,1,14.65,200,1,14.68,700,1,2,333436361
2025-07-17T16:08:27.483241007Z,2025-07-17T16:08:27.483075481Z,160,2,1108,C,A,14.750000000,100,0,333436397,0,165526,277841175,ARL,,13.11,100,1,13.01,2,1,12.98,200,1,12.86,100,1,12.73,100,1,12.71,100,1,12.5,700,1,12.49,200,1,12.46,100,1,12.43,700,1,13.85,2,1,13.96,100,1,14.28,100,1,14.46,100,1,14.48,800,1,14.52,200,1,14.56,800,1,14.6,700,1,14.65,200,1,14.68,700,1,2,333436397
2025-07-17T16:08:27.483241007Z,2025-07-17T16:08:27.483075481Z,160,2,1108,A,A,14.990000000,100,0,333581389,130,165526,277841175,ARL,,13.11,100,1,13.01,2,1,12.98,200,1,12.86,100,1,12.73,100,1,12.71,100,1,12.5,700,1,12.49,200,1,12.46,100,1,12.43,700,1,13.85,2,1,13.96,100,1,14.28,100,1,14.46,100,1,14.48,800,1,14.52,200,1,14.56,800,1,14.6,700,1,14.65,200,1,14.68,700,1,2,333581389
2025-07-17T16:08:27.483585892Z,2025-07-17T16:08:27.483420069Z,160,2,1108,C,A,14.520000000,100,0,328780577,0,165823,277841178,ARL,,13.11,100,1,13.01,2,1,12.98,200,1,12.86,100,1,12.73,100,1,12.71,100,1,12.5,700,1,12.49,200,1,12.46,100,1,12.43,700,1,13.85,2,1,13.96,100,1,14.28,100,1,14.46,100,1,14.48,800,1,14.52,100,1,14.56,800,1,14.6,700,1,14.65,200,1,14.68,700,1,2,328780577
2025-07-17T16:08:27.483585892Z,2025-07-17T16:08:27.483420069Z,160,2,1108,A,A,14.740000000,100,0,333581393,130,165823,277841178,ARL,,13.11,100,1,13.01,2,1,12.98,200,1,12.86,100,1,12.73,100,1,12.71,100,1,12.5,700,1,12.49,200,1,12.46,100,1,12.43,700,1,13.85,2,1,13.96,100,1,14.28,100,1,14.46,100,1,14.48,800,1,14.52,100,1,14.56,800,1,14.6,700,1,14.65,200,1,14.68,700,1,2,333581393
2025-07-17T16:08:27.484079224Z,2025-07-17T16:08:27.483913735Z,160,2,1108,C,A,14.650000000,100,0,333436589,0,165489,277841218,ARL,,13.11,100,1,13.01,2,1,12.98,200,1,12.86,100,1,12.73,100,1,12.71,100,1,12.5,700,1,12.49,200,1,12.46,100,1,12.43,700,1,13.85,2,1,13.96,100,1,14.28,100,1,14.46,100,1,14.48,800,1,14.52,100,1,14.56,800,1,14.6,700,1,14.65,100,1,14.68,700,1,2,333436589
2025-07-17T16:08:27.484079224Z,2025-07-17T16:08:27.483913735Z,160,2,1108,A,A,14.940000000,100,0,333581409,130,165489,277841218,ARL,,13.11,100,1,13.01,2,1,12.98,200,1,12.86,100,1,12.73,100,1,12.71,100,1,12.5,700,1,12.49,200,1,12.46,100,1,12.43,700,1,13.85,2,1,13.96,100,1,14.28,100,1,14.46,100,1,14.48,800,1,14.52,100,1,14.56,800,1,14.6,700,1,14.65,100,1,14.68,700,1,2,333581409
2025-07-17T16:08:27.484859188Z,2025-07-17T16:08:27.484693568Z,160,2,1108,C,A,17.390000000,100,0,333436441,0,165620,277841226,ARL,,13.11,100,1,13.01,2,1,12.98,200,1,12.86,100,1,12.73,100,1,12.71,100,1,12.5,700,1,12.49,200,1,12.46,100,1,12.43,700,1,13.85,2,1,13.96,100,1,14.28,100,1,14.46,100,1,14.48,800,1,14.52,100,1,14.56,800,1,14.6,700,1,14.65,100,1,14.68,700,1,2,333436441
2025-07-17T16:08:27.484859188Z,2025-07-17T16:08:27.484693568Z,160,2,1108,A,A,17.730000000,100,0,333581425,130,165620,277841226,ARL,,13.11,100,1,13.01,2,1,12.98,200,1,12.86,100,1,12.73,100,1,12.71,100,1,12.5,700,1,12.49,200,1,12.46,100,1,12.43,700,1,13.85,2,1,13.96,100,1,14.28,100,1,14.46,100,1,14.48,800,1,14.52,100,1,14.56,800,1,14.6,700,1,14.65,100,1,14.68,700,1,2,333581425
2025-07-17T16:08:27.484965957Z,2025-07-17T16:08:27.484800296Z,160,2,1108,C,A,14.650000000,100,0,333436425,0,165661,277841228,ARL,,13.11,100,1,13.01,2,1,12.98,200,1,12.86,100,1,12.73,100,1,12.71,100,1,12.5,700,1,12.49,200,1,12.46,100,1,12.43,700,1,13.85,2,1,13.96,100,1,14.28,100,1,14.46,100,1,14.48,800,1,14.52,100,1,14.56,800,1,14.6,700,1,14.68,700,1,14.74,100,1,2,333436425
2025-07-17T16:08:27.484965957Z,2025-07-17T16:08:27.484800296Z,160,2,1108,A,A,14.940000000,100,0,333581429,130,165661,277841228,ARL,,13.11,100,1,13.01,2,1,12.98,200,1,12.86,100,1,12.73,100,1,12.71,100,1,12.5,700,1,12.49,200,1,12.46,100,1,12.43,700,1,13.85,2,1,13.96,100,1,14.28,100,1,14.46,100,1,14.48,800,1,14.52,100,1,14.56,800,1,14.6,700,1,14.68,700,1,14.74,100,1,2,333581429
2025-07-17T16:08:27.484978859Z,2025-07-17T16:08:27.484813280Z,160,2,1108,C,A,15.750000000,100,0,333436449,0,165579,277841229,ARL,,13.11,100,1,13.01,2,1,12.98,200,1,12.86,100,1,12.73,100,1,12.71,100,1,12.5,700,1,12.49,200,1,12.46,100,1,12.43,700,1,13.85,2,1,13.96,100,1,14.28,100,1,14.46,100,1,14.48,800,1,14.52,100,1,14.56,800,1,14.6,700,1,14.68,700,1,14.74,100,1,2,333436449
2025-07-17T16:08:27.484978859Z,2025-07-17T16:08:27.484813280Z,160,2,1108,A,A,16.060000000,100,0,333581433,130,165579,277841229,ARL,,13.11,100,1,13.01,2,1,12.98,200,1,12.86,100,1,12.73,100,1,12.71,100,1,12.5,700,1,12.49,200,1,12.46,100,1,12.43,700,1,13.85,2,1,13.96,100,1,14.28,100,1,14.46,100,1,14.48,800,1,14.52,100,1,14.56,800,1,14.6,700,1,14.68,700,1,14.74,100,1,2,333581433
2025-07-17T16:08:27.485352204Z,2025-07-17T16:08:27.485186411Z,160,2,1108,C,A,15.060000000,100,0,333436421,0,165793,277841231,ARL,,13.11,100,1,13.01,2,1,12.98,200,1,12.86,100,1,12.73,100,1,12.71,100,1,12.5,700,1,12.49,200,1,12.46,100,1,12.43,700,1,13.85,2,1,13.96,100,1,14.28,100,1,14.46,100,1,14.48,800,1,14.52,100,1,14.56,800,1,14.6,700,1,14.68,700,1,14.74,100,1,2,333436421
2025-07-17T16:08:27.485352204Z,2025-07-17T16:08:27.485186411Z,160,2,1108,A,A,15.360000000,100,0,333581441,130,165793,277841231,ARL,,13.11,100,1,13.01,2,1,12.98,200,1,12.86,100,1,12.73,100,1,12.71,100,1,12.5,700,1,12.49,200,1,12.46,100,1,12.43,700,1,13.85,2,1,13.96,100,1,14.28,100,1,14.46,100,1,14.48,800,1,14.52,100,1,14.56,800,1,14.6,700,1,14.68,700,1,14.74,100,1,2,333581441
2025-07-17T16:08:27.487263276Z,2025-07-17T16:08:27.487097702Z,160,2,1108,C,A,14.520000000,100,0,328780597,0,165574,277841319,ARL,,13.11,100,1,13.01,2,1,12.98,200,1,12.86,100,1,12.73,100,1,12.71,100,1,12.5,700,1,12.49,200,1,12.46,100,1,12.43,700,1,13.85,2,1,13.96,100,1,14.28,100,1,14.46,100,1,14.48,800,1,14.56,800,1,14.6,700,1,14.68,700,1,14.74,100,1,14.94,200,1,2,328780597
2025-07-17T16:08:27.487263276Z,2025-07-17T16:08:27.487097702Z,160,2,1108,A,A,14.740000000,100,0,333581481,130,165574,277841319,ARL,,13.11,100,1,13.01,2,1,12.98,200,1,12.86,100,1,12.73,100,1,12.71,100,1,12.5,700,1,12.49,200,1,12.46,100,1,12.43,700,1,13.85,2,1,13.96,100,1,14.28,100,1,14.46,100,1,14.48,800,1,14.56,800,1,14.6,700,1,14.68,700,1,14.74,200,1,14.94,200,1,2,333581481
2025-07-17T16:08:27.492258906Z,2025-07-17T16:08:27.492093401Z,160,2,1108,C,A,14.480000000,100,0,333438545,130,165505,277841396,ARL,,13.11,100,1,13.01,2,1,12.98,200,1,12.86,100,1,12.73,100,1,12.71,100,1,12.5,700,1,12.49,200,1,12.46,100,1,12.43,700,1,13.85,2,1,13.96,100,1,14.28,100,1,14.46,100,1,14.48,700,1,14.56,800,1,14.6,700,1,14.68,700,1,14.74,200,1,14.94,200,1,2,333438545
2025-07-17T16:08:27.492385750Z,2025-07-17T16:08:27.492220454Z,160,2,1108,A,A,14.750000000,100,0,333581569,130,165296,277841397,ARL,,13.11,100,1,13.01,2,1,12.98,200,1,12.86,100,1,12.73,100,1,12.71,100,1,12.5,700,1,12.49,200,1,12.46,100,1,12.43,700,1,13.85,2,1,13.96,100,1,14.28,100,1,14.46,100,1,14.48,700,1,14.56,800,1,14.6,700,1,14.68,700,1,14.74,200,1,14.75,100,1,2,333581569
2025-07-17T16:08:27.496936122Z,2025-07-17T16:08:27.496770678Z,160,2,1108,C,A,13.960000000,100,0,333436473,130,165444,277841427,ARL,,13.11,100,1,13.01,2,1,12.98,200,1,12.86,100,1,12.73,100,1,12.71,100,1,12.5,700,1,12.49,200,1,12.46,100,1,12.43,700,1,13.85,2,1,14.28,100,1,14.46,100,1,14.48,700,1,14.56,800,1,14.6,700,1,14.68,700,1,14.74,200,1,14.75,100,1,14.94,200,1,2,333436473
2025-07-17T16:08:27.496987832Z,2025-07-17T16:08:27.496822540Z,160,2,1108,A,A,14.190000000,100,0,333581625,130,165292,277841428,ARL,,13.11,100,1,13.01,2,1,12.98,200,1,12.86,100,1,12.73,100,1,12.71,100,1,12.5,700,1,12.49,200,1,12.46,100,1,12.43,700,1,13.85,2,1,14.19,100,1,14.28,100,1,14.46,100,1,14.48,700,1,14.56,800,1,14.6,700,1,14.68,700,1,14.74,200,1,14.75,100,1,2,333581625
2025-07-17T16:08:27.501093618Z,2025-07-17T16:08:27.500928061Z,160,2,1108,C,A,13.850000000,2,0,331155889,0,165557,277841469,ARL,,13.11,100,1,13.01,2,1,12.98,200,1,12.86,100,1,12.73,100,1,12.71,100,1,12.5,700,1,12.49,200,1,12.46,100,1,12.43,700,1,14.19,100,1,14.28,100,1,14.46,100,1,14.48,700,1,14.56,800,1,14.6,700,1,14.68,700,1,14.74,200,1,14.75,100,1,14.94,200,1,2,331155889
2025-07-17T16:08:27.501093618Z,2025-07-17T16:08:27.500928061Z,160,2,1108,A,A,13.980000000,2,0,333581677,130,165557,277841469,ARL,,13.11,100,1,13.01,2,1,12.98,200,1,12.86,100,1,12.73,100,1,12.71,100,1,12.5,700,1,12.49,200,1,12.46,100,1,12.43,700,1,13.98,2,1,14.19,100,1,14.28,100,1,14.46,100,1,14.48,700,1,14.56,800,1,14.6,700,1,14.68,700,1,14.74,200,1,14.75,100,1,2,333581677
2025-07-17T16:08:27.516614373Z,2025-07-17T16:08:27.516449334Z,160,2,1108,C,A,14.190000000,100,0,333581625,130,165039,277841551,ARL,,13.11,100,1,13.01,2,1,12.98,200,1,12.86,100,1,12.73,100,1,12.71,100,1,12.5,700,1,12.49,200,1,12.46,100,1,12.43,700,1,13.98,2,1,14.28,100,1,14.46,100,1,14.48,700,1,14.56,800,1,14.6,700,1,14.68,700,1,14.74,200,1,14.75,100,1,14.94,200,1,2,333581625
2025-07-17T16:08:27.516662099Z,2025-07-17T16:08:27.516496962Z,160,2,1108,A,A,14.260000000,100,0,333581765,130,165137,277841552,ARL,,13.11,100,1,13.01,2,1,12.98,200,1,12.86,100,1,12.73,100,1,12.71,100,1,12.5,700,1,12.49,200,1,12.46,100,1,12.43,700,1,13.98,2,1,14.26,100,1,14.28,100,1,14.46,100,1,14.48,700,1,14.56,800,1,14.6,700,1,14.68,700,1,14.74,200,1,14.75,100,1,2,333581765
2025-07-17T16:08:27.533938450Z,2025-07-17T16:08:27.533773259Z,160,2,1108,C,A,14.990000000,100,0,333581389,0,165191,277841588,ARL,,13.11,100,1,13.01,2,1,12.98,200,1,12.86,100,1,12.73,100,1,12.71,100,1,12.5,700,1,12.49,200,1,12.46,100,1,12.43,700,1,13.98,2,1,14.26,100,1,14.28,100,1,14.46,100,1,14.48,700,1,14.56,800,1,14.6,700,1,14.68,700,1,14.74,200,1,14.75,100,1,2,333581389
2025-07-17T16:08:27.533938450Z,2025-07-17T16:08:27.533773259Z,160,2,1108,A,A,15.040000000,100,0,333581845,130,165191,277841588,ARL,,13.11,100,1,13.01,2,1,12.98,200,1,12.86,100,1,12.73,100,1,12.71,100,1,12.5,700,1,12.49,200,1,12.46,100,1,12.43,700,1,13.98,2,1,14.26,100,1,14.28,100,1,14.46,100,1,14.48,700,1,14.56,800,1,14.6,700,1,14.68,700,1,14.74,200,1,14.75,100,1,2,333581845
2025-07-17T16:08:27.987678739Z,2025-07-17T16:08:27.987513451Z,160,2,1108,A,A,13.990000000,100,0,333590057,130,165288,277846288,ARL,,13.11,100,1,13.01,2,1,12.98,200,1,12.86,100,1,12.73,100,1,12.71,100,1,12.5,700,1,12.49,200,1,12.46,100,1,12.43,700,1,13.98,2,1,13.99,100,1,14.26,100,1,14.28,100,1,14.46,100,1,14.48,700,1,14.56,800,1,14.6,700,1,14.68,700,1,14.74,200,1,2,333590057
2025-07-17T16:08:58.024979382Z,2025-07-17T16:08:58.024814068Z,160,2,1108,A,A,13.810000000,15,0,334141429,130,165314,278261182,ARL,,13.11,100,1,13.01,2,1,12.98,200,1,12.86,100,1,12.73,100,1,12.71,100,1,12.5,700,1,12.49,200,1,12.46,100,1,12.43,700,1,13.81,15,1,13.98,2,1,13.99,100,1,14.26,100,1,14.28,100,1,14.46,100,1,14.48,700,1,14.56,800,1,14.6,700,1,14.68,700,1,2,334141429
2025-07-17T16:09:00.222675234Z,2025-07-17T16:09:00.222509491Z,160,2,1108,C,A,13.990000000,100,0,333590057,0,165743,278295684,ARL,,13.11,100,1,13.01,2,1,12.98,200,1,12.86,100,1,12.73,100,1,12.71,100,1,12.5,700,1,12.49,200,1,12.46,100,1,12.43,700,1,13.81,15,1,13.98,2,1,14.26,100,1,14.28,100,1,14.46,100,1,14.48,700,1,14.56,800,1,14.6,700,1,14.68,700,1,14.74,200,1,2,333590057
2025-07-17T16:09:00.222675234Z,2025-07-17T16:09:00.222509491Z,160,2,1108,A,A,13.820000000,100,0,334189729,130,165743,278295684,ARL,,13.11,100,1,13.01,2,1,12.98,200,1,12.86,100,1,12.73,100,1,12.71,100,1,12.5,700,1,12.49,200,1,12.46,100,1,12.43,700,1,13.81,15,1,13.82,100,1,13.98,2,1,14.26,100,1,14.28,100,1,14.46,100,1,14.48,700,1,14.56,800,1,14.6,700,1,14.68,700,1,2,334189729
2025-07-17T16:09:00.223436757Z,2025-07-17T16:09:00.223269382Z,160,2,1108,C,A,15.040000000,100,0,333581845,0,167375,278295848,ARL,,13.11,100,1,13.01,2,1,12.98,200,1,12.86,100,1,12.73,100,1,12.71,100,1,12.5,700,1,12.49,200,1,12.46,100,1,12.43,700,1,13.81,15,1,13.82,100,1,13.98,2,1,14.26,100,1,14.28,100,1,14.46,100,1,14.48,700,1,14.56,800,1,14.6,700,1,14.68,700,1,2,333581845
2025-07-17T16:09:00.223436757Z,2025-07-17T16:09:00.223269382Z,160,2,1108,A,A,14.890000000,100,0,334189777,128,167375,278295848,ARL,,13.11,100,1,13.01,2,1,12.98,200,1,12.86,100,1,12.73,100,1,12.71,100,1,12.5,700,1,12.49,200,1,12.46,100,1,12.43,700,1,13.81,15,1,13.82,100,1,13.98,2,1,14.26,100,1,14.28,100,1,14.46,100,1,14.48,700,1,14.56,800,1,14.6,700,1,14.68,700,1,2,334189777
2025-07-17T16:09:00.226504346Z,2025-07-17T16:09:00.226338384Z,160,2,1108,C,A,14.750000000,100,0,333581569,0,165962,278296281,ARL,,13.11,100,1,13.01,2,1,12.98,200,1,12.86,100,1,12.73,100,1,12.71,100,1,12.5,700,1,12.49,200,1,12.46,100,1,12.43,700,1,13.81,15,1,13.82,100,1,13.98,2,1,14.26,100,1,14.28,100,1,14.46,100,1,14.48,700,1,14.56,800,1,14.6,700,1,14.68,700,1,2,333581569
2025-07-17T16:09:00.226504346Z,2025-07-17T16:09:00.226338384Z,160,2,1108,A,A,14.610000000,100,0,334190189,130,165962,278296281,ARL,,13.11,100,1,13.01,2,1,12.98,200,1,12.86,100,1,12.73,100,1,12.71,100,1,12.5,700,1,12.49,200,1,12.46,100,1,12.43,700,1,13.81,15,1,13.82,100,1,13.98,2,1,14.26,100,1,14.28,100,1,14.46,100,1,14.48,700,1,14.56,800,1,14.6,700,1,14.61,100,1,2,334190189
2025-07-17T16:09:00.227929061Z,2025-07-17T16:09:00.227763275Z,160,2,1108,C,A,14.260000000,100,0,333581765,130,165786,278296402,ARL,,13.11,100,1,13.01,2,1,12.98,200,1,12.86,100,1,12.73,100,1,12.71,100,1,12.5,700,1,12.49,200,1,12.46,100,1,12.43,700,1,13.81,15,1,13.82,100,1,13.98,2,1,14.28,100,1,14.46,100,1,14.48,700,1,14.56,800,1,14.6,700,1,14.61,100,1,14.68,700,1,2,333581765
2025-07-17T16:09:00.227983483Z,2025-07-17T16:09:00.227818153Z,160,2,1108,A,A,14.100000000,100,0,334190225,130,165330,278296411,ARL,,13.11,100,1,13.01,2,1,12.98,200,1,12.86,100,1,12.73,100,1,12.71,100,1,12.5,700,1,12.49,200,1,12.46,100,1,12.43,700,1,13.81,15,1,13.82,100,1,13.98,2,1,14.1,100,1,14.28,100,1,14.46,100,1,14.48,700,1,14.56,800,1,14.6,700,1,14.61,100,1,2,334190225
2025-07-17T16:09:00.232908882Z,2025-07-17T16:09:00.232743323Z,160,2,1108,C,A,14.940000000,100,0,333581429,0,165559,278296544,ARL,,13.11,100,1,13.01,2,1,12.98,200,1,12.86,100,1,12.73,100,1,12.71,100,1,12.5,700,1,12.49,200,1,12.46,100,1,12.43,700,1,13.81,15,1,13.82,100,1,13.98,2,1,14.1,100,1,14.28,100,1,14.46,100,1,14.48,700,1,14.56,800,1,14.6,700,1,14.61,100,1,2,333581429
2025-07-17T16:09:00.232908882Z,2025-07-17T16:09:00.232743323Z,160,2,1108,A,A,14.790000000,100,0,334190353,130,165559,278296544,ARL,,13.11,100,1,13.01,2,1,12.98,200,1,12.86,100,1,12.73,100,1,12.71,100,1,12.5,700,1,12.49,200,1,12.46,100,1,12.43,700,1,13.81,15,1,13.82,100,1,13.98,2,1,14.1,100,1,14.28,100,1,14.46,100,1,14.48,700,1,14.56,800,1,14.6,700,1,14.61,100,1,2,334190353
2025-07-17T16:09:00.326293286Z,2025-07-17T16:09:00.326127587Z,160,2,1108,C,A,17.730000000,100,0,333581425,0,165699,278298302,ARL,,13.11,100,1,13.01,2,1,12.98,200,1,12.86,100,1,12.73,100,1,12.71,100,1,12.5,700,1,12.49,200,1,12.46,100,1,12.43,700,1,13.81,15,1,13.82,100,1,13.98,2,1,14.1,100,1,14.28,100,1,14.46,100,1,14.48,700,1,14.56,800,1,14.6,700,1,14.61,100,1,2,333581425
2025-07-17T16:09:00.326293286Z,2025-07-17T16:09:00.326127587Z,160,2,1108,A,A,17.560000000,100,0,334192253,130,165699,278298302,ARL,,13.11,100,1,13.01,2,1,12.98,200,1,12.86,100,1,12.73,100,1,12.71,100,1,12.5,700,1,12.49,200,1,12.46,100,1,12.43,700,1,13.81,15,1,13.82,100,1,13.98,2,1,14.1,100,1,14.28,100,1,14.46,100,1,14.48,700,1,14.56,800,1,14.6,700,1,14.61,100,1,2,334192253
2025-07-17T16:09:00.335607827Z,2025-07-17T16:09:00.335442266Z,160,2,1108,C,A,16.060000000,100,0,333581433,0,165561,278298372,ARL,,13.11,100,1,13.01,2,1,12.98,200,1,12.86,100,1,12.73,100,1,12.71,100,1,12.5,700,1,12.49,200,1,12.46,100,1,12.43,700,1,13.81,15,1,13.82,100,1,13.98,2,1,14.1,100,1,14.28,100,1,14.46,100,1,14.48,700,1,14.56,800,1,14.6,700,1,14.61,100,1,2,333581433
2025-07-17T16:09:00.335607827Z,2025-07-17T16:09:00.335442266Z,160,2,1108,A,A,15.900000000,100,0,334192405,130,165561,278298372,ARL,,13.11,100,1,13.01,2,1,12.98,200,1,12.86,100,1,12.73,100,1,12.71,100,1,12.5,700,1,12.49,200,1,12.46,100,1,12.43,700,1,13.81,15,1,13.82,100,1,13.98,2,1,14.1,100,1,14.28,100,1,14.46,100,1,14.48,700,1,14.56,800,1,14.6,700,1,14.61,100,1,2,334192405
2025-07-17T16:09:00.695776010Z,2025-07-17T16:09:00.695610142Z,160,2,1108,C,A,14.940000000,100,0,333581409,0,165868,278304343,ARL,,13.11,100,1,13.01,2,1,12.98,200,1,12.86,100,1,12.73,100,1,12.71,100,1,12.5,700,1,12.49,200,1,12.46,100,1,12.43,700,1,13.81,15,1,13.82,100,1,13.98,2,1,14.1,100,1,14.28,100,1,14.46,100,1,14.48,700,1,14.56,800,1,14.6,700,1,14.61,100,1,2,333581409
2025-07-17T16:09:00.695776010Z,2025-07-17T16:09:00.695610142Z,160,2,1108,A,A,14.790000000,100,0,334199009,130,165868,278304343,ARL,,13.11,100,1,13.01,2,1,12.98,200,1,12.86,100,1,12.73,100,1,12.71,100,1,12.5,700,1,12.49,200,1,12.46,100,1,12.43,700,1,13.81,15,1,13.82,100,1,13.98,2,1,14.1,100,1,14.28,100,1,14.46,100,1,14.48,700,1,14.56,800,1,14.6,700,1,14.61,100,1,2,334199009
2025-07-17T16:09:08.719690693Z,2025-07-17T16:09:08.719524374Z,160,2,1108,A,A,13.750000000,15,0,334366613,130,166319,278436950,ARL,,13.11,100,1,13.01,2,1,12.98,200,1,12.86,100,1,12.73,100,1,12.71,100,1,12.5,700,1,12.49,200,1,12.46,100,1,12.43,700,1,13.75,15,1,13.81,15,1,13.82,100,1,13.98,2,1,14.1,100,1,14.28,100,1,14.46,100,1,14.48,700,1,14.56,800,1,14.6,700,1,2,334366613
2025-07-17T16:09:08.719871410Z,2025-07-17T16:09:08.719706070Z,160,2,1108,C,A,13.820000000,100,0,334189729,0,165340,278436967,ARL,,13.11,100,1,13.01,2,1,12.98,200,1,12.86,100,1,12.73,100,1,12.71,100,1,12.5,700,1,12.49,200,1,12.46,100,1,12.43,700,1,13.75,15,1,13.81,15,1,13.98,2,1,14.1,100,1,14.28,100,1,14.46,100,1,14.48,700,1,14.56,800,1,14.6,700,1,14.61,100,1,2,334189729
2025-07-17T16:09:08.719871410Z,2025-07-17T16:09:08.719706070Z,160,2,1108,A,A,13.760000000,100,0,334366617,130,165340,278436967,ARL,,13.11,100,1,13.01,2,1,12.98,200,1,12.86,100,1,12.73,100,1,12.71,100,1,12.5,700,1,12.49,200,1,12.46,100,1,12.43,700,1,13.75,15,1,13.76,100,1,13.81,15,1,13.98,2,1,14.1,100,1,14.28,100,1,14.46,100,1,14.48,700,1,14.56,800,1,14.6,700,1,2,334366617
2025-07-17T16:09:08.720607932Z,2025-07-17T16:09:08.720442245Z,160,2,1108,C,A,14.890000000,100,0,334189777,0,165687,278436994,ARL,,13.11,100,1,13.01,2,1,12.98,200,1,12.86,100,1,12.73,100,1,12.71,100,1,12.5,700,1,12.49,200,1,12.46,100,1,12.43,700,1,13.75,15,1,13.76,100,1,13.81,15,1,13.98,2,1,14.1,100,1,14.28,100,1,14.46,100,1,14.48,700,1,14.56,800,1,14.6,700,1,2,334189777
2025-07-17T16:09:08.720607932Z,2025-07-17T16:09:08.720442245Z,160,2,1108,A,A,14.830000000,100,0,334366645,130,165687,278436994,ARL,,13.11,100,1,13.01,2,1,12.98,200,1,12.86,100,1,12.73,100,1,12.71,100,1,12.5,700,1,12.49,200,1,12.46,100,1,12.43,700,1,13.75,15,1,13.76,100,1,13.81,15,1,13.98,2,1,14.1,100,1,14.28,100,1,14.46,100,1,14.48,700,1,14.56,800,1,14.6,700,1,2,334366645
2025-07-17T16:09:18.819300735Z,2025-07-17T16:09:18.819135505Z,160,2,1108,C,A,13.810000000,15,0,334141429,130,165230,278596985,ARL,,13.11,100,1,13.01,2,1,12.98,200,1,12.86,100,1,12.73,100,1,12.71,100,1,12.5,700,1,12.49,200,1,12.46,100,1,12.43,700,1,13.75,15,1,13.76,100,1,13.98,2,1,14.1,100,1,14.28,100,1,14.46,100,1,14.48,700,1,14.56,800,1,14.6,700,1,14.61,100,1,2,334141429
2025-07-17T16:09:19.927205023Z,2025-07-17T16:09:19.927039122Z,160,2,1108,A,A,13.730000000,15,0,334583329,130,165901,278621672,ARL,,13.11,100,1,13.01,2,1,12.98,200,1,12.86,100,1,12.73,100,1,12.71,100,1,12.5,700,1,12.49,200,1,12.46,100,1,12.43,700,1,13.73,15,1,13.75,15,1,13.76,100,1,13.98,2,1,14.1,100,1,14.28,100,1,14.46,100,1,14.48,700,1,14.56,800,1,14.6,700,1,2,334583329
2025-07-17T16:09:19.927910703Z,2025-07-17T16:09:19.927745104Z,160,2,1108,C,A,14.740000000,100,0,333581393,0,165599,278621693,ARL,,13.11,100,1,13.01,2,1,12.98,200,1,12.86,100,1,12.73,100,1,12.71,100,1,12.5,700,1,12.49,200,1,12.46,100,1,12.43,700,1,13.73,15,1,13.75,15,1,13.76,100,1,13.98,2,1,14.1,100,1,14.28,100,1,14.46,100,1,14.48,700,1,14.56,800,1,14.6,700,1,2,333581393
2025-07-17T16:09:19.927910703Z,2025-07-17T16:09:19.927745104Z,160,2,1108,A,A,14.620000000,100,0,334583349,130,165599,278621693,ARL,,13.11,100,1,13.01,2,1,12.98,200,1,12.86,100,1,12.73,100,1,12.71,100,1,12.5,700,1,12.49,200,1,12.46,100,1,12.43,700,1,13.73,15,1,13.75,15,1,13.76,100,1,13.98,2,1,14.1,100,1,14.28,100,1,14.46,100,1,14.48,700,1,14.56,800,1,14.6,700,1,2,334583349
2025-07-17T16:09:19.928319369Z,2025-07-17T16:09:19.928153837Z,160,2,1108,C,A,14.740000000,100,0,333581481,0,165532,278621695,ARL,,13.11,100,1,13.01,2,1,12.98,200,1,12.86,100,1,12.73,100,1,12.71,100,1,12.5,700,1,12.49,200,1,12.46,100,1,12.43,700,1,13.73,15,1,13.75,15,1,13.76,100,1,13.98,2,1,14.1,100,1,14.28,100,1,14.46,100,1,14.48,700,1,14.56,800,1,14.6,700,1,2,333581481
2025-07-17T16:09:19.928319369Z,2025-07-17T16:09:19.928153837Z,160,2,1108,A,A,14.620000000,100,0,334583361,130,165532,278621695,ARL,,13.11,100,1,13.01,2,1,12.98,200,1,12.86,100,1,12.73,100,1,12.71,100,1,12.5,700,1,12.49,200,1,12.46,100,1,12.43,700,1,13.73,15,1,13.75,15,1,13.76,100,1,13.98,2,1,14.1,100,1,14.28,100,1,14.46,100,1,14.48,700,1,14.56,800,1,14.6,700,1,2,334583361
2025-07-17T16:09:20.284861075Z,2025-07-17T16:09:20.284695585Z,160,2,1108,C,A,13.760000000,100,0,334366617,0,165490,278629057,ARL,,13.11,100,1,13.01,2,1,12.98,200,1,12.86,100,1,12.73,100,1,12.71,100,1,12.5,700,1,12.49,200,1,12.46,100,1,12.43,700,1,13.73,15,1,13.75,15,1,13.98,2,1,14.1,100,1,14.28,100,1,14.46,100,1,14.48,700,1,14.56,800,1,14.6,700,1,14.61,100,1,2,334366617
2025-07-17T16:09:20.284861075Z,2025-07-17T16:09:20.284695585Z,160,2,1108,A,A,13.740000000,100,0,334593569,130,165490,278629057,ARL,,13.11,100,1,13.01,2,1,12.98,200,1,12.86,100,1,12.73,100,1,12.71,100,1,12.5,700,1,12.49,200,1,12.46,100,1,12.43,700,1,13.73,15,1,13.74,100,1,13.75,15,1,13.98,2,1,14.1,100,1,14.28,100,1,14.46,100,1,14.48,700,1,14.56,800,1,14.6,700,1,2,334593569
2025-07-17T16:09:20.293271620Z,2025-07-17T16:09:20.293106270Z,160,2,1108,C,A,14.100000000,100,0,334190225,130,165350,278629219,ARL,,13.11,100,1,13.01,2,1,12.98,200,1,12.86,100,1,12.73,100,1,12.71,100,1,12.5,700,1,12.49,200,1,12.46,100,1,12.43,700,1,13.73,15,1,13.74,100,1,13.75,15,1,13.98,2,1,14.28,100,1,14.46,100,1,14.48,700,1,14.56,800,1,14.6,700,1,14.61,100,1,2,334190225
2025-07-17T16:09:20.293326641Z,2025-07-17T16:09:20.293161454Z,160,2,1108,A,A,14.010000000,100,0,334593753,130,165187,278629220,ARL,,13.11,100,1,13.01,2,1,12.98,200,1,12.86,100,1,12.73,100,1,12.71,100,1,12.5,700,1,12.49,200,1,12.46,100,1,12.43,700,1,13.73,15,1,13.74,100,1,13.75,15,1,13.98,2,1,14.01,100,1,14.28,100,1,14.46,100,1,14.48,700,1,14.56,800,1,14.6,700,1,2,334593753
2025-07-17T16:09:20.818813935Z,2025-07-17T16:09:20.818648795Z,160,2,1108,C,A,13.730000000,15,0,334583329,130,165140,278640667,ARL,,13.11,100,1,13.01,2,1,12.98,200,1,12.86,100,1,12.73,100,1,12.71,100,1,12.5,700,1,12.49,200,1,12.46,100,1,12.43,700,1,13.74,100,1,13.75,15,1,13.98,2,1,14.01,100,1,14.28,100,1,14.46,100,1,14.48,700,1,14.56,800,1,14.6,700,1,14.61,100,1,2,334583329
2025-07-17T16:09:20.818926356Z,2025-07-17T16:09:20.818761228Z,160,2,1108,C,A,13.750000000,15,0,334366613,130,165128,278640670,ARL,,13.11,100,1,13.01,2,1,12.98,200,1,12.86,100,1,12.73,100,1,12.71,100,1,12.5,700,1,12.49,200,1,12.46,100,1,12.43,700,1,13.74,100,1,13.98,2,1,14.01,100,1,14.28,100,1,14.46,100,1,14.48,700,1,14.56,800,1,14.6,700,1,14.61,100,1,14.62,200,1,2,334366613
2025-07-17T16:09:28.986122432Z,2025-07-17T16:09:28.985956629Z,160,2,1108,C,A,13.980000000,2,0,333581677,0,165803,278784943,ARL,,13.11,100,1,13.01,2,1,12.98,200,1,12.86,100,1,12.73,100,1,12.71,100,1,12.5,700,1,12.49,200,1,12.46,100,1,12.43,700,1,13.74,100,1,14.01,100,1,14.28,100,1,14.46,100,1,14.48,700,1,14.56,800,1,14.6,700,1,14.61,100,1,14.62,200,1,14.68,700,1,2,333581677
2025-07-17T16:09:28.986122432Z,2025-07-17T16:09:28.985956629Z,160,2,1108,A,A,13.900000000,2,0,334804177,130,165803,278784943,ARL,,13.11,100,1,13.01,2,1,12.98,200,1,12.86,100,1,12.73,100,1,12.71,100,1,12.5,700,1,12.49,200,1,12.46,100,1,12.43,700,1,13.74,100,1,13.9,2,1,14.01,100,1,14.28,100,1,14.46,100,1,14.48,700,1,14.56,800,1,14.6,700,1,14.61,100,1,14.62,200,1,2,334804177
2025-07-17T16:09:40.821687905Z,2025-07-17T16:09:40.821522565Z,160,2,1108,A,A,13.700000000,15,0,335003269,130,165340,278938091,ARL,,13.11,100,1,13.01,2,1,12.98,200,1,12.86,100,1,12.73,100,1,12.71,100,1,12.5,700,1,12.49,200,1,12.46,100,1,12.43,700,1,13.7,15,1,13.74,100,1,13.9,2,1,14.01,100,1,14.28,100,1,14.46,100,1,14.48,700,1,14.56,800,1,14.6,700,1,14.61,100,1,2,335003269
2025-07-17T16:09:40.853604577Z,2025-07-17T16:09:40.853439053Z,160,2,1108,C,A,13.740000000,100,0,334593569,0,165524,278938747,ARL,,13.11,100,1,13.01,2,1,12.98,200,1,12.86,100,1,12.73,100,1,12.71,100,1,12.5,700,1,12.49,200,1,12.46,100,1,12.43,700,1,13.7,15,1,13.9,2,1,14.01,100,1,14.28,100,1,14.46,100,1,14.48,700,1,14.56,800,1,14.6,700,1,14.61,100,1,14.62,200,1,2,334593569
2025-07-17T16:09:40.853604577Z,2025-07-17T16:09:40.853439053Z,160,2,1108,A,A,13.710000000,100,0,335003813,130,165524,278938747,ARL,,13.11,100,1,13.01,2,1,12.98,200,1,12.86,100,1,12.73,100,1,12.71,100,1,12.5,700,1,12.49,200,1,12.46,100,1,12.43,700,1,13.7,15,1,13.71,100,1,13.9,2,1,14.01,100,1,14.28,100,1,14.46,100,1,14.48,700,1,14.56,800,1,14.6,700,1,14.61,100,1,2,335003813
2025-07-17T16:09:40.854356022Z,2025-07-17T16:09:40.854190408Z,160,2,1108,C,A,14.830000000,100,0,334366645,0,165614,278938765,ARL,,13.11,100,1,13.01,2,1,12.98,200,1,12.86,100,1,12.73,100,1,12.71,100,1,12.5,700,1,12.49,200,1,12.46,100,1,12.43,700,1,13.7,15,1,13.71,100,1,13.9,2,1,14.01,100,1,14.28,100,1,14.46,100,1,14.48,700,1,14.56,800,1,14.6,700,1,14.61,100,1,2,334366645
2025-07-17T16:09:40.854356022Z,2025-07-17T16:09:40.854190408Z,160,2,1108,A,A,14.770000000,100,0,335003845,130,165614,278938765,ARL,,13.11,100,1,13.01,2,1,12.98,200,1,12.86,100,1,12.73,100,1,12.71,100,1,12.5,700,1,12.49,200,1,12.46,100,1,12.43,700,1,13.7,15,1,13.71,100,1,13.9,2,1,14.01,100,1,14.28,100,1,14.46,100,1,14.48,700,1,14.56,800,1,14.6,700,1,14.61,100,1,2,335003845
2025-07-17T16:09:40.855724422Z,2025-07-17T16:09:40.855558831Z,160,2,1108,C,A,17.560000000,100,0,334192253,0,165591,278938788,ARL,,13.11,100,1,13.01,2,1,12.98,200,1,12.86,100,1,12.73,100,1,12.71,100,1,12.5,700,1,12.49,200,1,12.46,100,1,12.43,700,1,13.7,15,1,13.71,100,1,13.9,2,1,14.01,100,1,14.28,100,1,14.46,100,1,14.48,700,1,14.56,800,1,14.6,700,1,14.61,100,1,2,334192253
2025-07-17T16:09:40.855724422Z,2025-07-17T16:09:40.855558831Z,160,2,1108,A,A,17.420000000,100,0,335003849,130,165591,278938788,ARL,,13.11,100,1,13.01,2,1,12.98,200,1,12.86,100,1,12.73,100,1,12.71,100,1,12.5,700,1,12.49,200,1,12.46,100,1,12.43,700,1,13.7,15,1,13.71,100,1,13.9,2,1,14.01,100,1,14.28,100,1,14.46,100,1,14.48,700,1,14.56,800,1,14.6,700,1,14.61,100,1,2,335003849
2025-07-17T16:09:50.820949131Z,2025-07-17T16:09:50.820783486Z,160,2,1108,A,A,13.670000000,15,0,335178437,130,165645,279081140,ARL,,13.11,100,1,13.01,2,1,12.98,200,1,12.86,100,1,12.73,100,1,12.71,100,1,12.5,700,1,12.49,200,1,12.46,100,1,12.43,700,1,13.67,15,1,13.7,15,1,13.71,100,1,13.9,2,1,14.01,100,1,14.28,100,1,14.46,100,1,14.48,700,1,14.56,800,1,14.6,700,1,2,335178437
2025-07-17T16:09:52.678777358Z,2025-07-17T16:09:52.678611805Z,160,2,1108,C,A,13.710000000,100,0,335003813,0,165553,279109959,ARL,,13.11,100,1,13.01,2,1,12.98,200,1,12.86,100,1,12.73,100,1,12.71,100,1,12.5,700,1,12.49,200,1,12.46,100,1,12.43,700,1,13.67,15,1,13.7,15,1,13.9,2,1,14.01,100,1,14.28,100,1,14.46,100,1,14.48,700,1,14.56,800,1,14.6,700,1,14.61,100,1,2,335003813
2025-07-17T16:09:52.678777358Z,2025-07-17T16:09:52.678611805Z,160,2,1108,A,A,13.680000000,100,0,335220349,130,165553,279109959,ARL,,13.11,100,1,13.01,2,1,12.98,200,1,12.86,100,1,12.73,100,1,12.71,100,1,12.5,700,1,12.49,200,1,12.46,100,1,12.43,700,1,13.67,15,1,13.68,100,1,13.7,15,1,13.9,2,1,14.01,100,1,14.28,100,1,14.46,100,1,14.48,700,1,14.56,800,1,14.6,700,1,2,335220349
